Workbook

Sheet Base Cedis DW87
N1: VENTA | Q1: COSTO
A2: CONCAT1 | B2: CONCAT2 | C2: No. SF | D2: Nombre SF | E2: Cedis | F2: Destino | G2: Condicion de Expedicion | H2: Nombre Destino | I2: No. de material | J2: Nombre de material | K2: PV | L2: Inicio de vigencia | M2: Fin de vigencia | N2: Importe MP | O2: Importe Flete | P2: UM Venta | Q2: Importe Costo | R2: UM Costo | S2: Validacion 1 | T2: Validacion 2
A3: =CONCATENATE(C3,E3,F3,I3) | B3: =CONCATENATE(C3,E3,I3) | C3: 900000552 | D3: =IFERROR(VLOOKUP(C3,TRAOPE!$G:$H,2,0),"") | E3: DW87 | F3: D010 | G3: =IFERROR(VLOOKUP(A3,Flete!$A:$E,5,0),"") | H3: =IFERROR(VLOOKUP(F3,TRAOPE!$AA:$AB,2,0),"") | I3: 10052402 | J3: =IFERROR(VLOOKUP(I3,Materiales!$A:$H,8,0),"") | K3: =IFERROR(VLOOKUP(I3,Materiales!$A:$G,7,0),"") | L3: 20260901 | M3: 99991231 | N3: 78.41 | O3: =IFERROR(VLOOKUP(A3,Flete!$A:$J,10,0),"") | P3: TN | Q3: =IFERROR(IFERROR(VLOOKUP(A3,TRAOPE!$A:$U,21,0),VLOOKUP(B3,TRAOPE!$A:$U,21,0)),"") | R3: =IFERROR(IFERROR(VLOOKUP(A3,TRAOPE!$A:$W,23,0),VLOOKUP(B3,TRAOPE!$A:$W,23,0)),"") | S3: =IF(AND(P3="TN",R3="TN"),N3+N(O3),IF(G3&""="1",N(K3)*N3,(N3+N(O3))*N(K3))) | T3: =IF(Q3="","",Q3-S3)
A4: =CONCATENATE(C4,E4,F4,I4) | B4: =CONCATENATE(C4,E4,I4) | C4: 900000552 | D4: =IFERROR(VLOOKUP(C4,TRAOPE!$G:$H,2,0),"") | E4: DW87 | F4: D010 | G4: =IFERROR(VLOOKUP(A4,Flete!$A:$E,5,0),"") | H4: =IFERROR(VLOOKUP(F4,TRAOPE!$AA:$AB,2,0),"") | I4: 10052405 | J4: =IFERROR(VLOOKUP(I4,Materiales!$A:$H,8,0),"") | K4: =IFERROR(VLOOKUP(I4,Materiales!$A:$G,7,0),"") | L4: 20230517 | M4: 20250120 | N4: 65.69 | O4: =IFERROR(VLOOKUP(A4,Flete!$A:$J,10,0),"") | P4: TN | Q4: =IFERROR(IFERROR(VLOOKUP(A4,TRAOPE!$A:$U,21,0),VLOOKUP(B4,TRAOPE!$A:$U,21,0)),"") | R4: =IFERROR(IFERROR(VLOOKUP(A4,TRAOPE!$A:$W,23,0),VLOOKUP(B4,TRAOPE!$A:$W,23,0)),"") | S4: =IF(AND(P4="TN",R4="TN"),N4+N(O4),IF(G4&""="1",N(K4)*N4,(N4+N(O4))*N(K4))) | T4: =IF(Q4="","",Q4-S4)
A5: =CONCATENATE(C5,E5,F5,I5) | B5: =CONCATENATE(C5,E5,I5) | C5: 900000552 | D5: =IFERROR(VLOOKUP(C5,TRAOPE!$G:$H,2,0),"") | E5: DW87 | F5: D010 | G5: =IFERROR(VLOOKUP(A5,Flete!$A:$E,5,0),"") | H5: =IFERROR(VLOOKUP(F5,TRAOPE!$AA:$AB,2,0),"") | I5: 10052407 | J5: =IFERROR(VLOOKUP(I5,Materiales!$A:$H,8,0),"") | K5: =IFERROR(VLOOKUP(I5,Materiales!$A:$G,7,0),"") | L5: 20241201 | M5: 99991231 | N5: 65.48 | O5: =IFERROR(VLOOKUP(A5,Flete!$A:$J,10,0),"") | P5: TN | Q5: =IFERROR(IFERROR(VLOOKUP(A5,TRAOPE!$A:$U,21,0),VLOOKUP(B5,TRAOPE!$A:$U,21,0)),"") | R5: =IFERROR(IFERROR(VLOOKUP(A5,TRAOPE!$A:$W,23,0),VLOOKUP(B5,TRAOPE!$A:$W,23,0)),"") | S5: =IF(AND(P5="TN",R5="TN"),N5+N(O5),IF(G5&""="1",N(K5)*N5,(N5+N(O5))*N(K5))) | T5: =IF(Q5="","",Q5-S5)
A6: =CONCATENATE(C6,E6,F6,I6) | B6: =CONCATENATE(C6,E6,I6) | C6: 900000552 | D6: =IFERROR(VLOOKUP(C6,TRAOPE!$G:$H,2,0),"") | E6: DW87 | F6: D010 | G6: =IFERROR(VLOOKUP(A6,Flete!$A:$E,5,0),"") | H6: =IFERROR(VLOOKUP(F6,TRAOPE!$AA:$AB,2,0),"") | I6: 10190637 | J6: =IFERROR(VLOOKUP(I6,Materiales!$A:$H,8,0),"") | K6: =IFERROR(VLOOKUP(I6,Materiales!$A:$G,7,0),"") | L6: 20241201 | M6: 99991231 | N6: 77.01 | O6: =IFERROR(VLOOKUP(A6,Flete!$A:$J,10,0),"") | P6: TN | Q6: =IFERROR(IFERROR(VLOOKUP(A6,TRAOPE!$A:$U,21,0),VLOOKUP(B6,TRAOPE!$A:$U,21,0)),"") | R6: =IFERROR(IFERROR(VLOOKUP(A6,TRAOPE!$A:$W,23,0),VLOOKUP(B6,TRAOPE!$A:$W,23,0)),"") | S6: =IF(AND(P6="TN",R6="TN"),N6+N(O6),IF(G6&""="1",N(K6)*N6,(N6+N(O6))*N(K6))) | T6: =IF(Q6="","",Q6-S6)
A7: =CONCATENATE(C7,E7,F7,I7) | B7: =CONCATENATE(C7,E7,I7) | C7: 900000552 | D7: =IFERROR(VLOOKUP(C7,TRAOPE!$G:$H,2,0),"") | E7: DW87 | F7: D010 | G7: =IFERROR(VLOOKUP(A7,Flete!$A:$E,5,0),"") | H7: =IFERROR(VLOOKUP(F7,TRAOPE!$AA:$AB,2,0),"") | I7: 10262751 | J7: =IFERROR(VLOOKUP(I7,Materiales!$A:$H,8,0),"") | K7: =IFERROR(VLOOKUP(I7,Materiales!$A:$G,7,0),"") | L7: 20241201 | M7: 99991231 | N7: 75.88 | O7: =IFERROR(VLOOKUP(A7,Flete!$A:$J,10,0),"") | P7: TN | Q7: =IFERROR(IFERROR(VLOOKUP(A7,TRAOPE!$A:$U,21,0),VLOOKUP(B7,TRAOPE!$A:$U,21,0)),"") | R7: =IFERROR(IFERROR(VLOOKUP(A7,TRAOPE!$A:$W,23,0),VLOOKUP(B7,TRAOPE!$A:$W,23,0)),"") | S7: =IF(AND(P7="TN",R7="TN"),N7+N(O7),IF(G7&""="1",N(K7)*N7,(N7+N(O7))*N(K7))) | T7: =IF(Q7="","",Q7-S7)
A8: =CONCATENATE(C8,E8,F8,I8) | B8: =CONCATENATE(C8,E8,I8) | C8: 900000552 | D8: =IFERROR(VLOOKUP(C8,TRAOPE!$G:$H,2,0),"") | E8: DW87 | F8: D010 | G8: =IFERROR(VLOOKUP(A8,Flete!$A:$E,5,0),"") | H8: =IFERROR(VLOOKUP(F8,TRAOPE!$AA:$AB,2,0),"") | I8: 10270431 | J8: =IFERROR(VLOOKUP(I8,Materiales!$A:$H,8,0),"") | K8: =IFERROR(VLOOKUP(I8,Materiales!$A:$G,7,0),"") | L8: 20250827 | M8: 99991231 | N8: 78.2 | O8: =IFERROR(VLOOKUP(A8,Flete!$A:$J,10,0),"") | P8: TN | Q8: =IFERROR(IFERROR(VLOOKUP(A8,TRAOPE!$A:$U,21,0),VLOOKUP(B8,TRAOPE!$A:$U,21,0)),"") | R8: =IFERROR(IFERROR(VLOOKUP(A8,TRAOPE!$A:$W,23,0),VLOOKUP(B8,TRAOPE!$A:$W,23,0)),"") | S8: =IF(AND(P8="TN",R8="TN"),N8+N(O8),IF(G8&""="1",N(K8)*N8,(N8+N(O8))*N(K8))) | T8: =IF(Q8="","",Q8-S8)
A9: =CONCATENATE(C9,E9,F9,I9) | B9: =CONCATENATE(C9,E9,I9) | C9: 900002747 | D9: =IFERROR(VLOOKUP(C9,TRAOPE!$G:$H,2,0),"") | E9: DW87 | F9: D010 | G9: =IFERROR(VLOOKUP(A9,Flete!$A:$E,5,0),"") | H9: =IFERROR(VLOOKUP(F9,TRAOPE!$AA:$AB,2,0),"") | I9: 10052402 | J9: =IFERROR(VLOOKUP(I9,Materiales!$A:$H,8,0),"") | K9: =IFERROR(VLOOKUP(I9,Materiales!$A:$G,7,0),"") | L9: 20210620 | M9: 20251031 | N9: 49.06 | O9: =IFERROR(VLOOKUP(A9,Flete!$A:$J,10,0),"") | P9: TN | Q9: =IFERROR(IFERROR(VLOOKUP(A9,TRAOPE!$A:$U,21,0),VLOOKUP(B9,TRAOPE!$A:$U,21,0)),"") | R9: =IFERROR(IFERROR(VLOOKUP(A9,TRAOPE!$A:$W,23,0),VLOOKUP(B9,TRAOPE!$A:$W,23,0)),"") | S9: =IF(AND(P9="TN",R9="TN"),N9+N(O9),IF(G9&""="1",N(K9)*N9,(N9+N(O9))*N(K9))) | T9: =IF(Q9="","",Q9-S9)
A10: =CONCATENATE(C10,E10,F10,I10) | B10: =CONCATENATE(C10,E10,I10) | C10: 900002747 | D10: =IFERROR(VLOOKUP(C10,TRAOPE!$G:$H,2,0),"") | E10: DW87 | F10: D010 | G10: =IFERROR(VLOOKUP(A10,Flete!$A:$E,5,0),"") | H10: =IFERROR(VLOOKUP(F10,TRAOPE!$AA:$AB,2,0),"") | I10: 10052405 | J10: =IFERROR(VLOOKUP(I10,Materiales!$A:$H,8,0),"") | K10: =IFERROR(VLOOKUP(I10,Materiales!$A:$G,7,0),"") | L10: 20210620 | M10: 20251031 | N10: 62.14 | O10: =IFERROR(VLOOKUP(A10,Flete!$A:$J,10,0),"") | P10: TN | Q10: =IFERROR(IFERROR(VLOOKUP(A10,TRAOPE!$A:$U,21,0),VLOOKUP(B10,TRAOPE!$A:$U,21,0)),"") | R10: =IFERROR(IFERROR(VLOOKUP(A10,TRAOPE!$A:$W,23,0),VLOOKUP(B10,TRAOPE!$A:$W,23,0)),"") | S10: =IF(AND(P10="TN",R10="TN"),N10+N(O10),IF(G10&""="1",N(K10)*N10,(N10+N(O10))*N(K10))) | T10: =IF(Q10="","",Q10-S10)
A11: =CONCATENATE(C11,E11,F11,I11) | B11: =CONCATENATE(C11,E11,I11) | C11: 900002747 | D11: =IFERROR(VLOOKUP(C11,TRAOPE!$G:$H,2,0),"") | E11: DW87 | F11: D010 | G11: =IFERROR(VLOOKUP(A11,Flete!$A:$E,5,0),"") | H11: =IFERROR(VLOOKUP(F11,TRAOPE!$AA:$AB,2,0),"") | I11: 10052407 | J11: =IFERROR(VLOOKUP(I11,Materiales!$A:$H,8,0),"") | K11: =IFERROR(VLOOKUP(I11,Materiales!$A:$G,7,0),"") | L11: 20210620 | M11: 20251031 | N11: 56.75 | O11: =IFERROR(VLOOKUP(A11,Flete!$A:$J,10,0),"") | P11: TN | Q11: =IFERROR(IFERROR(VLOOKUP(A11,TRAOPE!$A:$U,21,0),VLOOKUP(B11,TRAOPE!$A:$U,21,0)),"") | R11: =IFERROR(IFERROR(VLOOKUP(A11,TRAOPE!$A:$W,23,0),VLOOKUP(B11,TRAOPE!$A:$W,23,0)),"") | S11: =IF(AND(P11="TN",R11="TN"),N11+N(O11),IF(G11&""="1",N(K11)*N11,(N11+N(O11))*N(K11))) | T11: =IF(Q11="","",Q11-S11)
A12: =CONCATENATE(C12,E12,F12,I12) | B12: =CONCATENATE(C12,E12,I12) | C12: 900002747 | D12: =IFERROR(VLOOKUP(C12,TRAOPE!$G:$H,2,0),"") | E12: DW87 | F12: D010 | G12: =IFERROR(VLOOKUP(A12,Flete!$A:$E,5,0),"") | H12: =IFERROR(VLOOKUP(F12,TRAOPE!$AA:$AB,2,0),"") | I12: 10190637 | J12: =IFERROR(VLOOKUP(I12,Materiales!$A:$H,8,0),"") | K12: =IFERROR(VLOOKUP(I12,Materiales!$A:$G,7,0),"") | L12: 20210620 | M12: 20251031 | N12: 64.9 | O12: =IFERROR(VLOOKUP(A12,Flete!$A:$J,10,0),"") | P12: TN | Q12: =IFERROR(IFERROR(VLOOKUP(A12,TRAOPE!$A:$U,21,0),VLOOKUP(B12,TRAOPE!$A:$U,21,0)),"") | R12: =IFERROR(IFERROR(VLOOKUP(A12,TRAOPE!$A:$W,23,0),VLOOKUP(B12,TRAOPE!$A:$W,23,0)),"") | S12: =IF(AND(P12="TN",R12="TN"),N12+N(O12),IF(G12&""="1",N(K12)*N12,(N12+N(O12))*N(K12))) | T12: =IF(Q12="","",Q12-S12)
A13: =CONCATENATE(C13,E13,F13,I13) | B13: =CONCATENATE(C13,E13,I13) | C13: 900005959 | D13: =IFERROR(VLOOKUP(C13,TRAOPE!$G:$H,2,0),"") | E13: DW87 | F13: D031 | G13: =IFERROR(VLOOKUP(A13,Flete!$A:$E,5,0),"") | H13: =IFERROR(VLOOKUP(F13,TRAOPE!$AA:$AB,2,0),"") | I13: 10000191 | J13: =IFERROR(VLOOKUP(I13,Materiales!$A:$H,8,0),"") | K13: =IFERROR(VLOOKUP(I13,Materiales!$A:$G,7,0),"") | L13: 20210620 | M13: 20251031 | N13: 108.4 | O13: =IFERROR(VLOOKUP(A13,Flete!$A:$J,10,0),"") | P13: TN | Q13: =IFERROR(IFERROR(VLOOKUP(A13,TRAOPE!$A:$U,21,0),VLOOKUP(B13,TRAOPE!$A:$U,21,0)),"") | R13: =IFERROR(IFERROR(VLOOKUP(A13,TRAOPE!$A:$W,23,0),VLOOKUP(B13,TRAOPE!$A:$W,23,0)),"") | S13: =IF(AND(P13="TN",R13="TN"),N13+N(O13),IF(G13&""="1",N(K13)*N13,(N13+N(O13))*N(K13))) | T13: =IF(Q13="","",Q13-S13)
A14: =CONCATENATE(C14,E14,F14,I14) | B14: =CONCATENATE(C14,E14,I14) | C14: 900005959 | D14: =IFERROR(VLOOKUP(C14,TRAOPE!$G:$H,2,0),"") | E14: DW87 | F14: D031 | G14: =IFERROR(VLOOKUP(A14,Flete!$A:$E,5,0),"") | H14: =IFERROR(VLOOKUP(F14,TRAOPE!$AA:$AB,2,0),"") | I14: 10000523 | J14: =IFERROR(VLOOKUP(I14,Materiales!$A:$H,8,0),"") | K14: =IFERROR(VLOOKUP(I14,Materiales!$A:$G,7,0),"") | L14: 20210620 | M14: 20251031 | N14: 109.18 | O14: =IFERROR(VLOOKUP(A14,Flete!$A:$J,10,0),"") | P14: TN | Q14: =IFERROR(IFERROR(VLOOKUP(A14,TRAOPE!$A:$U,21,0),VLOOKUP(B14,TRAOPE!$A:$U,21,0)),"") | R14: =IFERROR(IFERROR(VLOOKUP(A14,TRAOPE!$A:$W,23,0),VLOOKUP(B14,TRAOPE!$A:$W,23,0)),"") | S14: =IF(AND(P14="TN",R14="TN"),N14+N(O14),IF(G14&""="1",N(K14)*N14,(N14+N(O14))*N(K14))) | T14: =IF(Q14="","",Q14-S14)
... A46: =CONCATENATE(C46,E46,F46,I46) | B46: =CONCATENATE(C46,E46,I46) | C46: 900009376 | D46: =IFERROR(VLOOKUP(C46,TRAOPE!$G:$H,2,0),"") | E46: DW87 | F46: D010 | G46: =IFERROR(VLOOKUP(A46,Flete!$A:$E,5,0),"") | H46: =IFERROR(VLOOKUP(F46,TRAOPE!$AA:$AB,2,0),"") | I46: 10262751 | J46: =IFERROR(VLOOKUP(I46,Materiales!$A:$H,8,0),"") | K46: =IFERROR(VLOOKUP(I46,Materiales!$A:$G,7,0),"") | L46: 20260101 | M46: 99991231 | N46: 84.72 | O46: =IFERROR(VLOOKUP(A46,Flete!$A:$J,10,0),"") | P46: TN | Q46: =IFERROR(IFERROR(VLOOKUP(A46,TRAOPE!$A:$U,21,0),VLOOKUP(B46,TRAOPE!$A:$U,21,0)),"") | R46: =IFERROR(IFERROR(VLOOKUP(A46,TRAOPE!$A:$W,23,0),VLOOKUP(B46,TRAOPE!$A:$W,23,0)),"") | S46: =IF(AND(P46="TN",R46="TN"),N46+N(O46),IF(G46&""="1",N(K46)*N46,(N46+N(O46))*N(K46))) | T46: =IF(Q46="","",Q46-S46)

Sheet MP
A1: No. SF | B1: Cedis | C1: Destino | D1: No. Material | E1: Nombre Material | F1: Importe MP | G1: Moneda | H1: Cantidad | I1: UM | J1: C | K1: Inicio Vigencia | L1: Fin Vigencia
A2: 900000552 | B2: DW87 | C2: D010 | D2: 10052402 | F2: 78.41 | I2: TN | K2: 20260901 | L2: 99991231
A3: 900000552 | B3: DW87 | C3: D010 | D3: 10052405 | F3: 65.69 | I3: TN | K3: 20230517 | L3: 20250120
A4: 900000552 | B4: DW87 | C4: D010 | D4: 10052407 | F4: 65.48 | I4: TN | K4: 20241201 | L4: 99991231
A5: 900000552 | B5: DW87 | C5: D010 | D5: 10190637 | F5: 77.01 | I5: TN | K5: 20241201 | L5: 99991231
A6: 900000552 | B6: DW87 | C6: D010 | D6: 10262751 | F6: 75.88 | I6: TN | K6: 20241201 | L6: 99991231
A7: 900000552 | B7: DW87 | C7: D010 | D7: 10270431 | F7: 78.2 | I7: TN | K7: 20250827 | L7: 99991231
A8: 900002747 | B8: DW87 | C8: D010 | D8: 10052402 | F8: 49.06 | I8: TN | K8: 20210620 | L8: 20251031
A9: 900002747 | B9: DW87 | C9: D010 | D9: 10052405 | F9: 62.14 | I9: TN | K9: 20210620 | L9: 20251031
A10: 900002747 | B10: DW87 | C10: D010 | D10: 10052407 | F10: 56.75 | I10: TN | K10: 20210620 | L10: 20251031
A11: 900002747 | B11: DW87 | C11: D010 | D11: 10190637 | F11: 64.9 | I11: TN | K11: 20210620 | L11: 20251031
A12: 900005959 | B12: DW87 | C12: D031 | D12: 10000191 | F12: 108.4 | I12: TN | K12: 20210620 | L12: 20251031
A13: 900005959 | B13: DW87 | C13: D031 | D13: 10000523 | F13: 109.18 | I13: TN | K13: 20210620 | L13: 20251031
... A45: 900009376 | B45: DW87 | C45: D010 | D45: 10262751 | F45: 84.72 | I45: TN | K45: 20260101 | L45: 99991231

Sheet Flete
A1: Concat1 | B1: No. SF | C1: Cedis | D1: Destino | E1: Cond. Exp. | F1: Material | H1: Nombre Material | J1: Importe Flete | K1: Moneda | L1: Cantidad | M1: UM | N1: C | P1: Inicio Vigencia | Q1: Fin Vigencia
A2: 900000552DW87D01010052402 | B2: 900000552 | C2: DW87 | D2: D010 | E2: 4 | F2: 10052402 | J2: 40.61 | M2: TN | P2: 20241201 | Q2: 99991231
A3: 900000552DW87D01010052405 | B3: 900000552 | C3: DW87 | D3: D010 | E3: 4 | F3: 10052405 | J3: 36.49 | M3: TN | P3: 20230517 | Q3: 20250120
A4: 900000552DW87D01010052407 | B4: 900000552 | C4: DW87 | D4: D010 | E4: 4 | F4: 10052407 | J4: 39.34 | M4: TN | P4: 20241201 | Q4: 99991231
A5: 900000552DW87D01010190637 | B5: 900000552 | C5: DW87 | D5: D010 | E5: 4 | F5: 10190637 | J5: 40.61 | M5: TN | P5: 20241201 | Q5: 99991231
A6: 900000552DW87D01010262751 | B6: 900000552 | C6: DW87 | D6: D010 | E6: 4 | F6: 10262751 | J6: 41.74 | M6: TN | P6: 20241201 | Q6: 99991231
A7: 900000552DW87D01010270431 | B7: 900000552 | C7: DW87 | D7: D010 | E7: 4 | F7: 10270431 | J7: 41.24 | M7: TN | P7: 20250827 | Q7: 99991231
A8: 900002747DW87D01010052402 | B8: 900002747 | C8: DW87 | D8: D010 | E8: 4 | F8: 10052402 | J8: 26.32 | M8: TN | P8: 20210620 | Q8: 20251031
A9: 900002747DW87D01010052405 | B9: 900002747 | C9: DW87 | D9: D010 | E9: 4 | F9: 10052405 | J9: 27.03 | M9: TN | P9: 20210620 | Q9: 20251031
A10: 900002747DW87D01010052407 | B10: 900002747 | C10: DW87 | D10: D010 | E10: 4 | F10: 10052407 | J10: 26.49 | M10: TN | P10: 20210620 | Q10: 20251031
A11: 900002747DW87D01010190637 | B11: 900002747 | C11: DW87 | D11: D010 | E11: 4 | F11: 10190637 | J11: 27.68 | M11: TN | P11: 20210620 | Q11: 20251031
A12: 900005959DW87D03110000191 | B12: 900005959 | C12: DW87 | D12: D031 | E12: 4 | F12: 10000191 | J12: 74.04 | M12: TN | P12: 20210620 | Q12: 20251031
A13: 900005959DW87D03110000523 | B13: 900005959 | C13: DW87 | D13: D031 | E13: 4 | F13: 10000523 | J13: 74.57 | M13: TN | P13: 20210620 | Q13: 20251031
... A45: 900009376DW87D01010262751 | B45: 900009376 | C45: DW87 | D45: D010 | E45: 4 | F45: 10262751 | J45: 45.83 | M45: TN | P45: 20260101 | Q45: 99991231

Sheet Materiales
A1: Material | B1: TpMt | C1: Denom | D1: UMA | E1: Contador | F1: UMB | G1: PV | H1: Nombre Material
A2: 10000001 | B2: ZFER | C2: 1000 | D2: M3 | E2: 1000 | F2: TN | G2: 1262 | H2: GRAVA ANDESITA 10 MM (3/8")
A3: 10000003 | B3: ZFER | C3: 1000 | D3: M3 | E3: 1000 | F3: TN | G3: 1443 | H3: GRAVA CALIZA 10 MM (3/8")
A4: 10000006 | B4: ZFER | C4: 1000 | D4: M3 | E4: 1000 | F4: TN | G4: 1490 | H4: GRAVA RIO 10 MM (3/8")
A5: 10000007 | B5: ZFER | C5: 1000 | D5: M3 | E5: 1000 | F5: TN | G5: 1488 | H5: GRAVA BASALTO 13 MM (1/2")
A6: 10000008 | B6: ZFER | C6: 1000 | D6: M3 | E6: 1000 | F6: TN | G6: 1358 | H6: GRAVA CALIZA 13 MM (1/2")
A7: 10000011 | B7: ZFER | C7: 1000 | D7: M3 | E7: 1000 | F7: TN | G7: 1323 | H7: GRAVA ANDESITA 20 MM (3/4")
A8: 10000013 | B8: ZFER | C8: 1000 | D8: M3 | E8: 1000 | F8: TN | G8: 1514 | H8: GRAVA BASALTO 20 MM (3/4")
A9: 10000014 | B9: ZFER | C9: 1000 | D9: M3 | E9: 1000 | F9: TN | G9: 1400 | H9: GRAVA CALIZA 20 MM (3/4")
A10: 10000015 | B10: ZFER | C10: 1000 | D10: M3 | E10: 1000 | F10: TN | G10: 1410 | H10: GRAVA GRANITO 20 MM (3/4")
A11: 10000017 | B11: ZFER | C11: 1000 | D11: M3 | E11: 1000 | F11: TN | G11: 1475 | H11: GRAVA RIOLITA 20 MM (3/4")
A12: 10000019 | B12: ZFER | C12: 1000 | D12: M3 | E12: 1000 | F12: TN | G12: 1515 | H12: GRAVA RIO 20 MM (3/4")
A13: 10000020 | B13: ZFER | C13: 1000 | D13: M3 | E13: 1 | F13: TN | G13: 1 | H13: GRAVA MAQUILA 40MM (1 1/2")
... A2291: 10268770 | B2291: ZFE3 | C2291: 1000 | D2291: M3 | E2291: 1000 | F2291: TN | G2291: 1240 | H2291: MP GRAVA TRIT CALIZA 40MM 1 1/2" - ESP
A2292: 10268901 | B2292: ZFE3 | C2292: 1000 | D2292: M3 | E2292: 1000 | G2292: 1560 | H2292: MP GRAVA ANDESITA GRIS 3/4" - CAPADA
A2293: 10267983 | C2293: 1000 | G2293: 1800 | H2293: ESCORIA ALTO HORNO 3/4
A2294: 10268996 | C2294: 1000 | G2294: 1329 | H2294: GRAVA TRITURADA CALIZA 40 MM - 11/2"
A2295: 10269072 | C2295: 1000 | G2295: 1700 | H2295: BASE HIDRÁULICA SCREEN
A2296: 10269225 | B2296: ZFE3 | C2296: 1000 | D2296: M3 | E2296: 1000 | G2296: 1289 | H2296: MP ARENA CALIZA LAVADA MALLA 4 - DELTA I
A2297: 10269245 | B2297: ZFE3 | C2297: 1000 | D2297: M3 | E2297: 1000 | G2297: 1410 | H2297: MP GRAVA TRITURADA CALIZA 3/8 - 10MM
A2298: 10269246 | B2298: ZFE3 | C2298: 1000 | D2298: M3 | E2298: 1000 | G2298: 1400 | H2298: MP GRAVA TRITURADA CALIZA 1 1/2 - 40MM
A2299: 10269247 | B2299: ZFE3 | C2299: 1000 | D2299: M3 | E2299: 1000 | G2299: 1560 | H2299: MP ARENA TRIT CALIZA M-4
A2300: 10270431 | B2300: ZFE3 | C2300: 1000 | D2300: M3 | E2300: 1000 | G2300: 1423 | H2300: MP GRAVA RIOLITA 13 MM - 1/2"
A2301: 10270898 | B2301: ZFE3 | C2301: 1000 | D2301: M3 | E2301: 1000 | G2301: 1551 | H2301: MP BASE H. TRIT. BASALTO 1 1/2" A FINOS
A2302: 10270911 | B2302: ZFE3 | C2302: 1000 | D2302: M3 | E2302: 1000 | G2302: 1360 | H2302: MP GRAVA TRIT. BASALTO 40 MM - 1 1/2"
A2303: 10270912 | B2303: ZFE3 | C2303: 1000 | D2303: M3 | E2303: 1000 | G2303: 1589 | H2303: MP ARENA TRIT. BASALTO MALLA 4
A2304: 10270913 | B2304: ZFE3 | C2304: 1000 | D2304: M3 | E2304: 1000 | G2304: 1395 | H2304: MP GRAVA TRIT. BASALTO 20 MM - 3/4
A2305: 10270914 | B2305: ZFE3 | C2305: 1000 | D2305: M3 | E2305: 1000 | G2305: 1623 | H2305: MP ARENA ANDESITA BC
A2306: 10270824 | B2306: M3 | C2306: 1000 | D2306: M3 | E2306: 10007640 | G2306: 1325 | H2306: MP ARENA TRITURADA CALIZA MALLA 5
A2307: 10270825 | B2307: M3 | C2307: 1000 | D2307: M3 | E2307: 10000003 | G2307: 1242 | H2307: MP GRAVA TRITURADA CALIZA 10MM (3/8”)
... A2319: 10272527 | B2319: ZFE3 | C2319: 1000 | D2319: M3 | E2319: 1000 | G2319: 1620 | H2319: CNC - NO CLASIFICADO
A2320: 10000332 | C2320: 1000 | D2320: M3 | E2320: 1000 | G2320: 800 | H2320: Grava Triturada Pomez - Jal 20 mm - 3/4"
A2321: 10273001 | B2321: ZFE3 | C2321: 1000 | D2321: M3 | E2321: 1000 | G2321: 1688 | H2321: MP ARENA TRIT. BASALTO MALLA 4
A2322: 10273002 | B2322: ZFE3 | C2322: 1000 | D2322: M3 | E2322: 1000 | G2322: 1466 | H2322: MP GRAVA TRIT. BASALTO 20 MM - 3/4"
A2323: 10273351 | B2323: ZFE3 | C2323: 1000 | D2323: M3 | E2323: 1000 | G2323: 1612 | H2323: MP ARENA TRIT. CALIZA MALLA 4
A2324: 10273352 | B2324: ZFE3 | C2324: 1000 | D2324: M3 | E2324: 1000 | G2324: 1492 | H2324: MP GRAVA TRIT. CALIZA 20 MM - 3/4"
A2325: 10271724 | B2325: ZFE3 | C2325: 1000 | D2325: M3 | E2325: 1000 | G2325: 1900 | H2325: MP RESIDUO DE CONCRETO
A2326: 10000677 | C2326: 1000 | D2326: M3 | G2326: 1164 | H2326: Grava Triturada Caliza 20 mm - 3/4"
A2327: 10274190 | B2327: ZFE3 | C2327: 1000 | D2327: M3 | E2327: 1000 | G2327: 1800 | H2327: MP BASE HIDRAULICA ANDESITA 70-30
A2328: 10274601 | B2328: ZFE3 | C2328: 1000 | D2328: M3 | E2328: 1000 | G2328: 1447 | H2328: MP ARENA BASALTO N° 4
...

Sheet TRAOPE
A1: Concat1 | B1: Contrato_Pos | C1: Doc. Compras | D1: Pos | E1: Org.compras | F1: Grp-Compr. | G1: Ship From | H1: Nombre SF | I1: Proveedor | J1: Nombre Prov | K1: Cond. Pago | L1: Descr. Cond Pago | M1: Material | N1: Descripción | O1: Centro | P1: Descripción Centro | Q1: In.perído validez | R1: Fin perído validez | S1: Válido de | T1: Validez a | U1: Precio neto pedido | V1: Moneda | W1: UM Precio Pedido | X1: Importe Condición | Y1: Moneda KONP | Z1: UM Ctd Base | AA1: Destino | AB1: Nombre Destino | AC1: Cuenta de mayor | AD1: Centro de costo | AE1: Cond. Exp. | AF1: Descr. Cond. Exp. | AG1: Peso Vol. | AH1: UMB | AI1: Ind. Oblig. Conf. Ped. | AJ1: Ctrl-Conf. | AK1: IVA | AL1: Modif_Date | AM1: Ruta
A2: 900006091DW87D01010052405 | B2: 4600068499-20 | C2: 4600068499 | D2: 20 | E2: MXPO | F2: MXL | G2: 900006091 | H2: SF TC- ED TECNOASFALTOS | I2: 5075126 | J2: TECNOASFALTOS Y TERRACERIAS SA DE | K2: N30 | L2: (AP) NAFIN 30 Dias | M2: 10052405 | N2: Grava Riolita 40 MM (1 1/2") | O2: DW87 | P2: MX-CED. HERMOSILLO | Q2: 20230918 | R2: 20281231 | S2: 20260501 | T2: 20301231 | U2: 252 | V2: MXN | W2: M3 | X2: 59.46 | Y2: MXN | Z2: M3 | AA2: D010 | AB2: PD0212 HERMOSILLO CENTRO | AC2: 56103637 | AD2: 6644501540 | AE2: 4 | AF2: ENTREGA DIRECTA | AG2: 1.48 | AH2: M3 | AI2: X | AJ2: 4 | AK2: V4 | AL2: 20260605 | AM2: DW87-900006091-D010-10052405-4
A3: 900008950DW87D01010262751 | B3: 4600070225-40 | C3: 4600070225 | D3: 40 | E3: MXPO | F3: MXL | G3: 900008950 | H3: SF TC-ED MAQ Y AGGS GALA | I3: 5094000 | J3: MAQUINARIA Y AGREGADOS GALA SA DE C | K3: Z09 | L3: (AP) 90 Dias | M3: 10262751 | N3: MP GRAVA RIOLITA 40 MM 1 1/2" | O3: DW87 | P3: MX-CED. HERMOSILLO | Q3: 20240909 | R3: 20291231 | S3: 20260501 | T3: 20301231 | U3: 210 | V3: MXN | W3: M3 | X3: 60 | Y3: MXN | Z3: M3 | AA3: D010 | AB3: PD0212 HERMOSILLO CENTRO | AC3: 56103637 | AD3: 6644501540 | AE3: 4 | AF3: ENTREGA DIRECTA | AG3: 1.44 | AH3: M3 | AI3: X | AJ3: 4 | AK3: V4 | AL3: 20260605 | AM3: DW87-900008950-D010-10262751-4
A4: 900006091DW87D01010260230 | B4: 4600068499-40 | C4: 4600068499 | D4: 40 | E4: MXPO | F4: MXL | G4: 900006091 | H4: SF TC- ED TECNOASFALTOS | I4: 5075126 | J4: TECNOASFALTOS Y TERRACERIAS SA DE | K4: N30 | L4: (AP) NAFIN 30 Dias | M4: 10260230 | N4: GRAVA 3/4 CLASIF. RIOLITA 20 MM | O4: DW87 | P4: MX-CED. HERMOSILLO | Q4: 20230918 | R4: 20281231 | S4: 20260501 | T4: 20301231 | U4: 203.79 | V4: MXN | W4: M3 | X4: 59.46 | Y4: MXN | Z4: M3 | AA4: D010 | AB4: PD0212 HERMOSILLO CENTRO | AC4: 56103637 | AD4: 6644501540 | AE4: 4 | AF4: ENTREGA DIRECTA | AG4: 1.524 | AH4: M3 | AI4: X | AJ4: 4 | AK4: V4 | AL4: 20260605 | AM4: DW87-900006091-D010-10260230-4
A5: 900008950DW87D01010261150 | B5: 4600070225-30 | C5: 4600070225 | D5: 30 | E5: MXPO | F5: MXL | G5: 900008950 | H5: SF TC-ED MAQ Y AGGS GALA | I5: 5094000 | J5: MAQUINARIA Y AGREGADOS GALA SA DE C | K5: Z09 | L5: (AP) 90 Dias | M5: 10261150 | N5: GRAVA RIOLITA 10 MM (3/8) | O5: DW87 | P5: MX-CED. HERMOSILLO | Q5: 20240909 | R5: 20291231 | S5: 20260501 | T5: 20301231 | U5: 240 | V5: MXN | W5: M3 | X5: 60 | Y5: MXN | Z5: M3 | AA5: D010 | AB5: PD0212 HERMOSILLO CENTRO | AC5: 56103637 | AD5: 6644501540 | AE5: 4 | AF5: ENTREGA DIRECTA | AG5: 1.497 | AH5: M3 | AI5: X | AJ5: 4 | AK5: V4 | AL5: 20260605 | AM5: DW87-900008950-D010-10261150-4
A6: 900006091DW87D01010260168 | B6: 4600068499-50 | C6: 4600068499 | D6: 50 | E6: MXPO | F6: MXL | G6: 900006091 | H6: SF TC- ED TECNOASFALTOS | I6: 5075126 | J6: TECNOASFALTOS Y TERRACERIAS SA DE | K6: N30 | L6: (AP) NAFIN 30 Dias | M6: 10260168 | N6: ARENA MALLA 4 - RIO | O6: DW87 | P6: MX-CED. HERMOSILLO | Q6: 20230918 | R6: 20281231 | S6: 20260501 | T6: 20301231 | U6: 188.93 | V6: MXN | W6: M3 | X6: 59.46 | Y6: MXN | Z6: M3 | AA6: D010 | AB6: PD0212 HERMOSILLO CENTRO | AC6: 56103638 | AD6: 6644501540 | AE6: 4 | AF6: ENTREGA DIRECTA | AG6: 1.566 | AH6: M3 | AI6: X | AJ6: 4 | AK6: V4 | AL6: 20260605 | AM6: DW87-900006091-D010-10260168-4
A7: 900008950DW87D01010260332 | B7: 4600070225-20 | C7: 4600070225 | D7: 20 | E7: MXPO | F7: MXL | G7: 900008950 | H7: SF TC-ED MAQ Y AGGS GALA | I7: 5094000 | J7: MAQUINARIA Y AGREGADOS GALA SA DE C | K7: Z09 | L7: (AP) 90 Dias | M7: 10260332 | N7: GRAVA CLASIFICADA RIOLITA 20 MM (3/4") | O7: DW87 | P7: MX-CED. HERMOSILLO | Q7: 20240909 | R7: 20291231 | S7: 20260501 | T7: 20301231 | U7: 210 | V7: MXN | W7: M3 | X7: 60 | Y7: MXN | Z7: M3 | AA7: D010 | AB7: PD0212 HERMOSILLO CENTRO | AC7: 56103637 | AD7: 6644501540 | AE7: 4 | AF7: ENTREGA DIRECTA | AG7: 1.473 | AH7: M3 | AI7: X | AJ7: 4 | AK7: V4 | AL7: 20260605 | AM7: DW87-900008950-D010-10260332-4
A8: 900008950DW87D01010260231 | B8: 4600070225-10 | C8: 4600070225 | D8: 10 | E8: MXPO | F8: MXL | G8: 900008950 | H8: SF TC-ED MAQ Y AGGS GALA | I8: 5094000 | J8: MAQUINARIA Y AGREGADOS GALA SA DE C | K8: Z09 | L8: (AP) 90 Dias | M8: 10260231 | N8: ARENA DE RIO MALLA 4# | O8: DW87 | P8: MX-CED. HERMOSILLO | Q8: 20240909 | R8: 20291231 | S8: 20260501 | T8: 20301231 | U8: 160 | V8: MXN | W8: M3 | X8: 60 | Y8: MXN | Z8: M3 | AA8: D010 | AB8: PD0212 HERMOSILLO CENTRO | AC8: 56103638 | AD8: 6644501540 | AE8: 4 | AF8: ENTREGA DIRECTA | AG8: 1.544 | AH8: M3 | AI8: X | AJ8: 4 | AK8: V4 | AL8: 20260605 | AM8: DW87-900008950-D010-10260231-4
A9: 900007894DW87D06510209776 | B9: 4600055598-20 | C9: 4600055598 | D9: 20 | E9: MXPO | F9: MXL | G9: 900007894 | H9: SF TC-ED DYCUSA CANANEA | I9: 5002035 | J9: DESARROLLO Y CONSTRUCCIONES URBANAS | K9: Z09 | L9: (AP) 90 Dias | M9: 10209776 | N9: ARENA CRIBADA RIOLITA N° 4 | O9: DW87 | P9: MX-CED. HERMOSILLO | Q9: 20221025 | R9: 20271231 | U9: 300 | V9: MXN | W9: M3 | AA9: D065 | AB9: PD0447 PLANTA OTAY 2 | AC9: 56103638 | AD9: 6644501540 | AE9: 4 | AF9: ENTREGA DIRECTA | AG9: 1.582 | AH9: M3 | AI9: X | AJ9: 4 | AK9: V4 | AL9: 20230920 | AM9: DW87-900007894-D065-10209776-4
A10: 900007768DW87D01010052405 | B10: 4600055078-40 | C10: 4600055078 | D10: 40 | E10: MXPO | F10: MXL | G10: 900007768 | H10: SF TC-ED GOMOSA | I10: 5083069 | J10: GOMO DESARROLLOS Y MATERIALES S DE | K10: Z09 | L10: (AP) 90 Dias | M10: 10052405 | N10: Grava Riolita 40 MM (1 1/2") | O10: DW87 | P10: MX-CED. HERMOSILLO | Q10: 20220901 | R10: 20291231 | S10: 20260401 | T10: 20301231 | U10: 196.67 | V10: MXN | W10: M3 | X10: 66.67 | Y10: MXN | Z10: M3 | AA10: D010 | AB10: PD0212 HERMOSILLO CENTRO | AC10: 56103637 | AD10: 6644501540 | AE10: 4 | AF10: ENTREGA DIRECTA | AG10: 1.48 | AH10: M3 | AI10: X | AJ10: 4 | AK10: V4 | AL10: 20260414 | AM10: DW87-900007768-D010-10052405-4
A11: 900007768DW87D01010221751 | B11: 4600055078-20 | C11: 4600055078 | D11: 20 | E11: MXPO | F11: MXL | G11: 900007768 | H11: SF TC-ED GOMOSA | I11: 5083069 | J11: GOMO DESARROLLOS Y MATERIALES S DE | K11: Z09 | L11: (AP) 90 Dias | M11: 10221751 | N11: GRAVA RIOLITA 20MM (¾) | O11: DW87 | P11: MX-CED. HERMOSILLO | Q11: 20220901 | R11: 20291231 | S11: 20260401 | T11: 20301231 | U11: 196.67 | V11: MXN | W11: M3 | X11: 66.67 | Y11: MXN | Z11: M3 | AA11: D010 | AB11: PD0212 HERMOSILLO CENTRO | AC11: 56103637 | AD11: 6644501540 | AE11: 4 | AF11: ENTREGA DIRECTA | AG11: 1.499 | AH11: M3 | AI11: X | AJ11: 4 | AK11: V4 | AL11: 20260414 | AM11: DW87-900007768-D010-10221751-4
A12: 900007768DW87D01010052402 | B12: 4600055078-30 | C12: 4600055078 | D12: 30 | E12: MXPO | F12: MXL | G12: 900007768 | H12: SF TC-ED GOMOSA | I12: 5083069 | J12: GOMO DESARROLLOS Y MATERIALES S DE | K12: Z09 | L12: (AP) 90 Dias | M12: 10052402 | N12: Grava Riolita 10 MM (3/8") | O12: DW87 | P12: MX-CED. HERMOSILLO | Q12: 20220901 | R12: 20291231 | S12: 20260401 | T12: 20301231 | U12: 266.67 | V12: MXN | W12: M3 | X12: 66.67 | Y12: MXN | Z12: M3 | AA12: D010 | AB12: PD0212 HERMOSILLO CENTRO | AC12: 56103637 | AD12: 6644501540 | AE12: 4 | AF12: ENTREGA DIRECTA | AG12: 1.52 | AH12: M3 | AI12: X | AJ12: 4 | AK12: V4 | AL12: 20260414 | AM12: DW87-900007768-D010-10052402-4
A13: 900007768DW87D01010221750 | B13: 4600055078-10 | C13: 4600055078 | D13: 10 | E13: MXPO | F13: MXL | G13: 900007768 | H13: SF TC-ED GOMOSA | I13: 5083069 | J13: GOMO DESARROLLOS Y MATERIALES S DE | K13: Z09 | L13: (AP) 90 Dias | M13: 10221750 | N13: ARENA DE RIO MALLA 4” | O13: DW87 | P13: MX-CED. HERMOSILLO | Q13: 20220901 | R13: 20291231 | S13: 20260401 | T13: 20301231 | U13: 186.67 | V13: MXN | W13: M3 | X13: 66.67 | Y13: MXN | Z13: M3 | AA13: D010 | AB13: PD0212 HERMOSILLO CENTRO | AC13: 56103638 | AD13: 6644501540 | AE13: 4 | AF13: ENTREGA DIRECTA | AG13: 1.651 | AH13: M3 | AI13: X | AJ13: 4 | AK13: V4 | AL13: 20260414 | AM13: DW87-900007768-D010-10221750-4
A14: 900000552DW87D01010270431 | B14: 4600051557-60 | C14: 4600051557 | D14: 60 | E14: MXPO | F14: MXL | G14: 900000552 | H14: SF TC-ED -PRODUCTOS PETREOS DE SONO | I14: 5001601 | J14: PRODUCTOS PETREOS DE SONORA SA DE | K14: Z03 | L14: (AP) 15 Dias | M14: 10270431 | N14: MP GRAVA RIOLITA 13 MM - 1/2" | O14: DW87 | P14: MX-CED. HERMOSILLO | Q14: 20210712 | R14: 20281231 | S14: 20250827 | T14: 20301231 | U14: 169.96 | V14: MXN | W14: M3 | X14: 58.68 | Y14: MXN | Z14: M3 | AA14: D010 | AB14: PD0212 HERMOSILLO CENTRO | AC14: 56103637 | AD14: 6644501540 | AE14: 4 | AF14: ENTREGA DIRECTA | AG14: 1.423 | AH14: M3 | AI14: X | AJ14: 4 | AK14: V4 | AL14: 20250902 | AM14: DW87-900000552-D010-10270431-4
A15: 900009376DW87D01010052407 | B15: 4600071745-20 | C15: 4600071745 | D15: 20 | E15: MXPO | F15: MXL | G15: 900009376 | H15: SF TC-ED MAT PETREOS TEPEYAC | I15: 5097166 | J15: MATERIALES PETREOS DEL TEPEYAC SA D | K15: Z03 | L15: (AP) 15 Dias | M15: 10052407 | N15: Arena Triturada Rio Malla 4 | O15: DW87 | P15: MX-CED. HERMOSILLO | Q15: 20251028 | R15: 20301231 | S15: 20260101 | T15: 20301231 | U15: 180 | V15: MXN | W15: M3 | X15: 66 | Y15: MXN | Z15: M3 | AA15: D010 | AB15: PD0212 HERMOSILLO CENTRO | AC15: 56103638 | AD15: 6644501540 | AE15: 4 | AF15: ENTREGA DIRECTA | AG15: 1.51 | AH15: M3 | AI15: X | AJ15: 4 | AK15: V4 | AL15: 20260122 | AM15: DW87-900009376-D010-10052407-4
A16: 900009376DW87D01010262751 | B16: 4600071745-40 | C16: 4600071745 | D16: 40 | E16: MXPO | F16: MXL | G16: 900009376 | H16: SF TC-ED MAT PETREOS TEPEYAC | I16: 5097166 | J16: MATERIALES PETREOS DEL TEPEYAC SA D | K16: Z03 | L16: (AP) 15 Dias | M16: 10262751 | N16: MP GRAVA RIOLITA 40 MM 1 1/2" | O16: DW87 | P16: MX-CED. HERMOSILLO | Q16: 20251028 | R16: 20301231 | S16: 20260101 | T16: 20301231 | U16: 188 | V16: MXN | W16: M3 | X16: 66 | Y16: MXN | Z16: M3 | AA16: D010 | AB16: PD0212 HERMOSILLO CENTRO | AC16: 56103637 | AD16: 6644501540 | AE16: 4 | AF16: ENTREGA DIRECTA | AG16: 1.44 | AH16: M3 | AI16: X | AJ16: 4 | AK16: V4 | AL16: 20260122 | AM16: DW87-900009376-D010-10262751-4
A17: 900009376DW87D01010190637 | B17: 4600071745-30 | C17: 4600071745 | D17: 30 | E17: MXPO | F17: MXL | G17: 900009376 | H17: SF TC-ED MAT PETREOS TEPEYAC | I17: 5097166 | J17: MATERIALES PETREOS DEL TEPEYAC SA D | K17: Z03 | L17: (AP) 15 Dias | M17: 10190637 | N17: GRAVA CLASIFICADA RIOLITA 20 MM (3/4") | O17: DW87 | P17: MX-CED. HERMOSILLO | Q17: 20251028 | R17: 20301231 | S17: 20260101 | T17: 20301231 | U17: 188 | V17: MXN | W17: M3 | X17: 66 | Y17: MXN | Z17: M3 | AA17: D010 | AB17: PD0212 HERMOSILLO CENTRO | AC17: 56103637 | AD17: 6644501540 | AE17: 4 | AF17: ENTREGA DIRECTA | AG17: 1.445 | AH17: M3 | AI17: X | AJ17: 4 | AK17: V4 | AL17: 20260122 | AM17: DW87-900009376-D010-10190637-4
A18: 900009376DW87D01010052402 | B18: 4600071745-10 | C18: 4600071745 | D18: 10 | E18: MXPO | F18: MXL | G18: 900009376 | H18: SF TC-ED MAT PETREOS TEPEYAC | I18: 5097166 | J18: MATERIALES PETREOS DEL TEPEYAC SA D | K18: Z03 | L18: (AP) 15 Dias | M18: 10052402 | N18: Grava Riolita 10 MM (3/8") | O18: DW87 | P18: MX-CED. HERMOSILLO | Q18: 20251028 | R18: 20301231 | S18: 20260101 | T18: 20301231 | U18: 200 | V18: MXN | W18: M3 | X18: 66 | Y18: MXN | Z18: M3 | AA18: D010 | AB18: PD0212 HERMOSILLO CENTRO | AC18: 56103637 | AD18: 6644501540 | AE18: 4 | AF18: ENTREGA DIRECTA | AG18: 1.52 | AH18: M3 | AI18: X | AJ18: 4 | AK18: V4 | AL18: 20260122 | AM18: DW87-900009376-D010-10052402-4
A19: 900007421DW87D06510209775 | B19: 4600052595-20 | C19: 4600052595 | D19: 20 | E19: MXPO | F19: MXL | G19: 900007421 | H19: SF TC-ED Q&M LOS ALISOS | I19: 5047567 | J19: Q&M CONCRETOS SA DE CV | K19: Z03 | L19: (AP) 15 Dias | M19: 10209775 | N19: GRAVA TRITURADA BASALTO DE ARROYO 20 MM | O19: DW87 | P19: MX-CED. HERMOSILLO | Q19: 20211129 | R19: 20261231 | S19: 20220701 | T19: 20271231 | U19: 390 | V19: MXN | W19: M3 | X19: 100 | Y19: MXN | Z19: M3 | AA19: D065 | AB19: PD0447 PLANTA OTAY 2 | AC19: 56103637 | AD19: 6644501540 | AE19: 4 | AF19: ENTREGA DIRECTA | AG19: 1.43 | AH19: M3 | AI19: X | AJ19: 4 | AK19: V4 | AL19: 20230920 | AM19: DW87-900007421-D065-10209775-4
A20: 900007420DW87D06510209776 | B20: 4600052594-20 | C20: 4600052594 | D20: 20 | E20: MXPO | F20: MXL | G20: 900007420 | H20: SF TC-ED Q&M EMILIANO ZAPATA | I20: 5047567 | J20: Q&M CONCRETOS SA DE CV | K20: Z03 | L20: (AP) 15 Dias | M20: 10209776 | N20: ARENA CRIBADA RIOLITA N° 4 | O20: DW87 | P20: MX-CED. HERMOSILLO | Q20: 20211129 | R20: 20261231 | S20: 20220701 | T20: 20271231 | U20: 300 | V20: MXN | W20: M3 | X20: 100 | Y20: MXN | Z20: M3 | AA20: D065 | AB20: PD0447 PLANTA OTAY 2 | AC20: 56103638 | AD20: 6644501540 | AE20: 4 | AF20: ENTREGA DIRECTA | AG20: 1.582 | AH20: M3 | AI20: X | AJ20: 4 | AK20: V4 | AL20: 20230920 | AM20: DW87-900007420-D065-10209776-4
A21: 900007894DW87D06510209775 | B21: 4600055598-10 | C21: 4600055598 | D21: 10 | E21: MXPO | F21: MXL | G21: 900007894 | H21: SF TC-ED DYCUSA CANANEA | I21: 5002035 | J21: DESARROLLO Y CONSTRUCCIONES URBANAS | K21: Z09 | L21: (AP) 90 Dias | M21: 10209775 | N21: GRAVA TRITURADA BASALTO DE ARROYO 20 MM | O21: DW87 | P21: MX-CED. HERMOSILLO | Q21: 20221025 | R21: 20271231 | U21: 390 | V21: MXN | W21: M3 | AA21: D065 | AB21: PD0447 PLANTA OTAY 2 | AC21: 56103637 | AD21: 6644501540 | AE21: 4 | AF21: ENTREGA DIRECTA | AG21: 1.43 | AH21: M3 | AI21: X | AJ21: 4 | AK21: V4 | AL21: 20230920 | AM21: DW87-900007894-D065-10209775-4
A22: 900002747DW87D01010052402 | B22: 4600050715-20 | C22: 4600050715 | D22: 20 | E22: MXPO | F22: MXL | G22: 900002747 | H22: SF TC-ED -PRODUCTOS PETREOS ESPECIA | I22: 5001601 | J22: PRODUCTOS PETREOS DE SONORA SA DE | K22: Z03 | L22: (AP) 15 Dias | M22: 10052402 | N22: Grava Riolita 10 MM (3/8") | O22: DW87 | P22: MX-CED. HERMOSILLO | Q22: 20210712 | R22: 20261231 | S22: 20210712 | T22: 20261231 | U22: 114.57 | V22: MXN | W22: M3 | X22: 40 | Y22: MXN | Z22: M3 | AA22: D010 | AB22: PD0212 HERMOSILLO CENTRO | AC22: 56103637 | AD22: 6644501540 | AE22: 4 | AF22: ENTREGA DIRECTA | AG22: 1.52 | AH22: M3 | AI22: X | AJ22: 4 | AK22: V4 | AL22: 20260108 | AM22: DW87-900002747-D010-10052402-4
A23: 900007702DW87D06510209776 | B23: 4600054881-20 | C23: 4600054881 | D23: 20 | E23: MXPO | F23: MXL | G23: 900007702 | H23: SF TC - CEBREROS | I23: 5083830 | J23: CEBRERO AMADOR CHRISTIAN ARIEL | K23: Z09 | L23: (AP) 90 Dias | M23: 10209776 | N23: ARENA CRIBADA RIOLITA N° 4 | O23: DW87 | P23: MX-CED. HERMOSILLO | Q23: 20220801 | R23: 20271231 | S23: 20220801 | T23: 20271231 | U23: 550 | V23: MXN | W23: M3 | X23: 300 | Y23: MXN | Z23: M3 | AA23: D065 | AB23: PD0447 PLANTA OTAY 2 | AC23: 56103638 | AD23: 6644501540 | AE23: 4 | AF23: ENTREGA DIRECTA | AG23: 1.582 | AH23: M3 | AI23: X | AJ23: 4 | AK23: V4 | AL23: 20230920 | AM23: DW87-900007702-D065-10209776-4
A24: 900002747DW87D01010052405 | B24: 4600050715-40 | C24: 4600050715 | D24: 40 | E24: MXPO | F24: MXL | G24: 900002747 | H24: SF TC-ED -PRODUCTOS PETREOS ESPECIA | I24: 5001601 | J24: PRODUCTOS PETREOS DE SONORA SA DE | K24: Z03 | L24: (AP) 15 Dias | M24: 10052405 | N24: Grava Riolita 40 MM (1 1/2") | O24: DW87 | P24: MX-CED. HERMOSILLO | Q24: 20210712 | R24: 20261231 | S24: 20210712 | T24: 20261231 | U24: 131.96 | V24: MXN | W24: M3 | X24: 40 | Y24: MXN | Z24: M3 | AA24: D010 | AB24: PD0212 HERMOSILLO CENTRO | AC24: 56103637 | AD24: 6644501540 | AE24: 4 | AF24: ENTREGA DIRECTA | AG24: 1.48 | AH24: M3 | AI24: X | AJ24: 4 | AK24: V4 | AL24: 20260108 | AM24: DW87-900002747-D010-10052405-4
A25: 900007701DW87D06510209776 | B25: 4600054880-20 | C25: 4600054880 | D25: 20 | E25: MXPO | F25: MXL | G25: 900007701 | H25: SF TC -ED CEBREROS | I25: 5083830 | J25: CEBRERO AMADOR CHRISTIAN ARIEL | K25: Z09 | L25: (AP) 90 Dias | M25: 10209776 | N25: ARENA CRIBADA RIOLITA N° 4 | O25: DW87 | P25: MX-CED. HERMOSILLO | Q25: 20220801 | R25: 20271231 | S25: 20220801 | T25: 20271231 | U25: 300 | V25: MXN | W25: M3 | X25: 150 | Y25: MXN | Z25: M3 | AA25: D065 | AB25: PD0447 PLANTA OTAY 2 | AC25: 56103638 | AD25: 6644501540 | AE25: 4 | AF25: ENTREGA DIRECTA | AG25: 1.582 | AH25: M3 | AI25: X | AJ25: 4 | AK25: V4 | AL25: 20230920 | AM25: DW87-900007701-D065-10209776-4
A26: 900002747DW87D01010052407 | B26: 4600050715-30 | C26: 4600050715 | D26: 30 | E26: MXPO | F26: MXL | G26: 900002747 | H26: SF TC-ED -PRODUCTOS PETREOS ESPECIA | I26: 5001601 | J26: PRODUCTOS PETREOS DE SONORA SA DE | K26: Z03 | L26: (AP) 15 Dias | M26: 10052407 | N26: Arena Triturada Rio Malla 4 | O26: DW87 | P26: MX-CED. HERMOSILLO | Q26: 20210712 | R26: 20261231 | S26: 20210712 | T26: 20261231 | U26: 125.69 | V26: MXN | W26: M3 | X26: 40 | Y26: MXN | Z26: M3 | AA26: D010 | AB26: PD0212 HERMOSILLO CENTRO | AC26: 56103638 | AD26: 6644501540 | AE26: 4 | AF26: ENTREGA DIRECTA | AG26: 1.51 | AH26: M3 | AI26: X | AJ26: 4 | AK26: V4 | AL26: 20260108 | AM26: DW87-900002747-D010-10052407-4
A27: 900007421DW87D06510052402 | B27: 4600052595-30 | C27: 4600052595 | D27: 30 | E27: MXPO | F27: MXL | G27: 900007421 | H27: SF TC-ED Q&M LOS ALISOS | I27: 5047567 | J27: Q&M CONCRETOS SA DE CV | K27: Z03 | L27: (AP) 15 Dias | M27: 10052402 | N27: Grava Riolita 10 MM (3/8") | O27: DW87 | P27: MX-CED. HERMOSILLO | Q27: 20211129 | R27: 20261231 | S27: 20220701 | T27: 20271231 | U27: 555 | V27: MXN | W27: M3 | X27: 300 | Y27: MXN | Z27: M3 | AA27: D065 | AB27: PD0447 PLANTA OTAY 2 | AC27: 56103637 | AD27: 6644501540 | AE27: 4 | AF27: ENTREGA DIRECTA | AG27: 1.52 | AH27: M3 | AI27: X | AJ27: 4 | AK27: V4 | AL27: 20230920 | AM27: DW87-900007421-D065-10052402-4
A28: 900007701DW87D06510209775 | B28: 4600054880-10 | C28: 4600054880 | D28: 10 | E28: MXPO | F28: MXL | G28: 900007701 | H28: SF TC -ED CEBREROS | I28: 5083830 | J28: CEBRERO AMADOR CHRISTIAN ARIEL | K28: Z09 | L28: (AP) 90 Dias | M28: 10209775 | N28: GRAVA TRITURADA BASALTO DE ARROYO 20 MM | O28: DW87 | P28: MX-CED. HERMOSILLO | Q28: 20220801 | R28: 20271231 | S28: 20220801 | T28: 20271231 | U28: 370 | V28: MXN | W28: M3 | X28: 150 | Y28: MXN | Z28: M3 | AA28: D065 | AB28: PD0447 PLANTA OTAY 2 | AC28: 56103637 | AD28: 6644501540 | AE28: 4 | AF28: ENTREGA DIRECTA | AG28: 1.43 | AH28: M3 | AI28: X | AJ28: 4 | AK28: V4 | AL28: 20230920 | AM28: DW87-900007701-D065-10209775-4
A29: 900007702DW87D06510209775 | B29: 4600054881-10 | C29: 4600054881 | D29: 10 | E29: MXPO | F29: MXL | G29: 900007702 | H29: SF TC - CEBREROS | I29: 5083830 | J29: CEBRERO AMADOR CHRISTIAN ARIEL | K29: Z09 | L29: (AP) 90 Dias | M29: 10209775 | N29: GRAVA TRITURADA BASALTO DE ARROYO 20 MM | O29: DW87 | P29: MX-CED. HERMOSILLO | Q29: 20220801 | R29: 20271231 | S29: 20220801 | T29: 20271231 | U29: 550 | V29: MXN | W29: M3 | X29: 300 | Y29: MXN | Z29: M3 | AA29: D065 | AB29: PD0447 PLANTA OTAY 2 | AC29: 56103637 | AD29: 6644501540 | AE29: 4 | AF29: ENTREGA DIRECTA | AG29: 1.43 | AH29: M3 | AI29: X | AJ29: 4 | AK29: V4 | AL29: 20230920 | AM29: DW87-900007702-D065-10209775-4
A30: 900002747DW87D01010190637 | B30: 4600050715-10 | C30: 4600050715 | D30: 10 | E30: MXPO | F30: MXL | G30: 900002747 | H30: SF TC-ED -PRODUCTOS PETREOS ESPECIA | I30: 5001601 | J30: PRODUCTOS PETREOS DE SONORA SA DE | K30: Z03 | L30: (AP) 15 Dias | M30: 10190637 | N30: GRAVA CLASIFICADA RIOLITA 20 MM (3/4") | O30: DW87 | P30: MX-CED. HERMOSILLO | Q30: 20210712 | R30: 20261231 | S30: 20210712 | T30: 20261231 | U30: 133.78 | V30: MXN | W30: M3 | X30: 40 | Y30: MXN | Z30: M3 | AA30: D010 | AB30: PD0212 HERMOSILLO CENTRO | AC30: 56103637 | AD30: 6644501540 | AE30: 4 | AF30: ENTREGA DIRECTA | AG30: 1.445 | AH30: M3 | AI30: X | AJ30: 4 | AK30: V4 | AL30: 20260108 | AM30: DW87-900002747-D010-10190637-4
A31: 900000552DW87D01010052407 | B31: 4600051557-20 | C31: 4600051557 | D31: 20 | E31: MXPO | F31: MXL | G31: 900000552 | H31: SF TC-ED -PRODUCTOS PETREOS DE SONO | I31: 5001601 | J31: PRODUCTOS PETREOS DE SONORA SA DE | K31: Z03 | L31: (AP) 15 Dias | M31: 10052407 | N31: Arena Triturada Rio Malla 4 | O31: DW87 | P31: MX-CED. HERMOSILLO | Q31: 20210712 | R31: 20281231 | S31: 20241201 | T31: 20301231 | U31: 158.28 | V31: MXN | W31: M3 | X31: 59.4 | Y31: MXN | Z31: M3 | AA31: D010 | AB31: PD0212 HERMOSILLO CENTRO | AC31: 56103638 | AD31: 6644501540 | AE31: 4 | AF31: ENTREGA DIRECTA | AG31: 1.51 | AH31: M3 | AI31: X | AJ31: 4 | AK31: V1 | AL31: 20250121 | AM31: DW87-900000552-D010-10052407-4
A32: 900000552DW87D01010052402 | B32: 4600051557-30 | C32: 4600051557 | D32: 30 | E32: MXPO | F32: MXL | G32: 900000552 | H32: SF TC-ED -PRODUCTOS PETREOS DE SONO | I32: 5001601 | J32: PRODUCTOS PETREOS DE SONORA SA DE | K32: Z03 | L32: (AP) 15 Dias | M32: 10052402 | N32: Grava Riolita 10 MM (3/8") | O32: DW87 | P32: MX-CED. HERMOSILLO | Q32: 20210712 | R32: 20281231 | S32: 20241201 | T32: 20301231 | U32: 173.94 | V32: MXN | W32: M3 | X32: 61.73 | Y32: MXN | Z32: M3 | AA32: D010 | AB32: PD0212 HERMOSILLO CENTRO | AC32: 56103637 | AD32: 6644501540 | AE32: 4 | AF32: ENTREGA DIRECTA | AG32: 1.52 | AH32: M3 | AI32: X | AJ32: 4 | AK32: V1 | AL32: 20250121 | AM32: DW87-900000552-D010-10052402-4
A33: 900000552DW87D01010262751 | B33: 4600051557-50 | C33: 4600051557 | D33: 50 | E33: MXPO | F33: MXL | G33: 900000552 | H33: SF TC-ED -PRODUCTOS PETREOS DE SONO | I33: 5001601 | J33: PRODUCTOS PETREOS DE SONORA SA DE | K33: Z03 | L33: (AP) 15 Dias | M33: 10262751 | N33: MP GRAVA RIOLITA 40 MM 1 1/2" | O33: DW87 | P33: MX-CED. HERMOSILLO | Q33: 20210712 | R33: 20281231 | S33: 20241201 | T33: 20301231 | U33: 169.37 | V33: MXN | W33: M3 | X33: 60.11 | Y33: MXN | Z33: M3 | AA33: D010 | AB33: PD0212 HERMOSILLO CENTRO | AC33: 56103637 | AD33: 6644501540 | AE33: 4 | AF33: ENTREGA DIRECTA | AG33: 1.44 | AH33: M3 | AI33: X | AJ33: 4 | AK33: V1 | AL33: 20250121 | AM33: DW87-900000552-D010-10262751-4
A34: 900000552DW87D01010190637 | B34: 4600051557-40 | C34: 4600051557 | D34: 40 | E34: MXPO | F34: MXL | G34: 900000552 | H34: SF TC-ED -PRODUCTOS PETREOS DE SONO | I34: 5001601 | J34: PRODUCTOS PETREOS DE SONORA SA DE | K34: Z03 | L34: (AP) 15 Dias | M34: 10190637 | N34: GRAVA CLASIFICADA RIOLITA 20 MM (3/4") | O34: DW87 | P34: MX-CED. HERMOSILLO | Q34: 20210712 | R34: 20281231 | S34: 20241201 | T34: 20301231 | U34: 169.96 | V34: MXN | W34: M3 | X34: 58.68 | Y34: MXN | Z34: M3 | AA34: D010 | AB34: PD0212 HERMOSILLO CENTRO | AC34: 56103637 | AD34: 6644501540 | AE34: 4 | AF34: ENTREGA DIRECTA | AG34: 1.445 | AH34: M3 | AI34: X | AJ34: 4 | AK34: V1 | AL34: 20250121 | AM34: DW87-900000552-D010-10190637-4
