Workbook

Sheet Base Cedis DW81
N1: VENTA | Q1: COSTO
A2: CONCAT1 | B2: CONCAT2 | C2: No. SF | D2: Nombre SF | E2: Cedis | F2: Destino | G2: Condicion de Expedicion | H2: Nombre Destino | I2: No. de material | J2: Nombre de material | K2: PV | L2: Inicio de vigencia | M2: Fin de vigencia | N2: Importe MP | O2: Importe Flete | P2: UM Venta | Q2: Importe Costo | R2: UM Costo | S2: Validacion 1 | T2: Validacion 2
A3: =CONCATENATE(C3,E3,F3,I3) | B3: =CONCATENATE(C3,E3,I3) | C3: 900000007 | D3: =IFERROR(VLOOKUP(C3,TRAOPE!$G:$H,2,0),"") | E3: DW81 | F3: D148 | G3: =IFERROR(VLOOKUP(A3,Flete!$A:$E,5,0),"") | H3: =IFERROR(VLOOKUP(F3,TRAOPE!$AA:$AB,2,0),"") | I3: 10000404 | J3: =IFERROR(VLOOKUP(I3,Materiales!$A:$H,8,0),"") | K3: =IFERROR(VLOOKUP(I3,Materiales!$A:$G,7,0),"") | L3: 20241018 | M3: 99991231 | N3: 178 | O3: =IFERROR(VLOOKUP(A3,Flete!$A:$J,10,0),"") | P3: TN | Q3: =IFERROR(IFERROR(VLOOKUP(A3,TRAOPE!$A:$U,21,0),VLOOKUP(B3,TRAOPE!$A:$U,21,0)),"") | R3: =IFERROR(IFERROR(VLOOKUP(A3,TRAOPE!$A:$W,23,0),VLOOKUP(B3,TRAOPE!$A:$W,23,0)),"") | S3: =IF(AND(P3="TN",R3="TN"),N3+N(O3),IF(G3&""="1",N(K3)*N3,(N3+N(O3))*N(K3))) | T3: =IF(Q3="","",Q3-S3)
A4: =CONCATENATE(C4,E4,F4,I4) | B4: =CONCATENATE(C4,E4,I4) | C4: 900000007 | D4: =IFERROR(VLOOKUP(C4,TRAOPE!$G:$H,2,0),"") | E4: DW81 | F4: D148 | G4: =IFERROR(VLOOKUP(A4,Flete!$A:$E,5,0),"") | H4: =IFERROR(VLOOKUP(F4,TRAOPE!$AA:$AB,2,0),"") | I4: 10000572 | J4: =IFERROR(VLOOKUP(I4,Materiales!$A:$H,8,0),"") | K4: =IFERROR(VLOOKUP(I4,Materiales!$A:$G,7,0),"") | L4: 20241018 | M4: 99991231 | N4: 178 | O4: =IFERROR(VLOOKUP(A4,Flete!$A:$J,10,0),"") | P4: TN | Q4: =IFERROR(IFERROR(VLOOKUP(A4,TRAOPE!$A:$U,21,0),VLOOKUP(B4,TRAOPE!$A:$U,21,0)),"") | R4: =IFERROR(IFERROR(VLOOKUP(A4,TRAOPE!$A:$W,23,0),VLOOKUP(B4,TRAOPE!$A:$W,23,0)),"") | S4: =IF(AND(P4="TN",R4="TN"),N4+N(O4),IF(G4&""="1",N(K4)*N4,(N4+N(O4))*N(K4))) | T4: =IF(Q4="","",Q4-S4)
A5: =CONCATENATE(C5,E5,F5,I5) | B5: =CONCATENATE(C5,E5,I5) | C5: 900000007 | D5: =IFERROR(VLOOKUP(C5,TRAOPE!$G:$H,2,0),"") | E5: DW81 | F5: D149 | G5: =IFERROR(VLOOKUP(A5,Flete!$A:$E,5,0),"") | H5: =IFERROR(VLOOKUP(F5,TRAOPE!$AA:$AB,2,0),"") | I5: 10000404 | J5: =IFERROR(VLOOKUP(I5,Materiales!$A:$H,8,0),"") | K5: =IFERROR(VLOOKUP(I5,Materiales!$A:$G,7,0),"") | L5: 20240513 | M5: 99991231 | N5: 186 | O5: =IFERROR(VLOOKUP(A5,Flete!$A:$J,10,0),"") | P5: TN | Q5: =IFERROR(IFERROR(VLOOKUP(A5,TRAOPE!$A:$U,21,0),VLOOKUP(B5,TRAOPE!$A:$U,21,0)),"") | R5: =IFERROR(IFERROR(VLOOKUP(A5,TRAOPE!$A:$W,23,0),VLOOKUP(B5,TRAOPE!$A:$W,23,0)),"") | S5: =IF(AND(P5="TN",R5="TN"),N5+N(O5),IF(G5&""="1",N(K5)*N5,(N5+N(O5))*N(K5))) | T5: =IF(Q5="","",Q5-S5)
A6: =CONCATENATE(C6,E6,F6,I6) | B6: =CONCATENATE(C6,E6,I6) | C6: 900000007 | D6: =IFERROR(VLOOKUP(C6,TRAOPE!$G:$H,2,0),"") | E6: DW81 | F6: D149 | G6: =IFERROR(VLOOKUP(A6,Flete!$A:$E,5,0),"") | H6: =IFERROR(VLOOKUP(F6,TRAOPE!$AA:$AB,2,0),"") | I6: 10000572 | J6: =IFERROR(VLOOKUP(I6,Materiales!$A:$H,8,0),"") | K6: =IFERROR(VLOOKUP(I6,Materiales!$A:$G,7,0),"") | L6: 20240513 | M6: 99991231 | N6: 186 | O6: =IFERROR(VLOOKUP(A6,Flete!$A:$J,10,0),"") | P6: TN | Q6: =IFERROR(IFERROR(VLOOKUP(A6,TRAOPE!$A:$U,21,0),VLOOKUP(B6,TRAOPE!$A:$U,21,0)),"") | R6: =IFERROR(IFERROR(VLOOKUP(A6,TRAOPE!$A:$W,23,0),VLOOKUP(B6,TRAOPE!$A:$W,23,0)),"") | S6: =IF(AND(P6="TN",R6="TN"),N6+N(O6),IF(G6&""="1",N(K6)*N6,(N6+N(O6))*N(K6))) | T6: =IF(Q6="","",Q6-S6)
A7: =CONCATENATE(C7,E7,F7,I7) | B7: =CONCATENATE(C7,E7,I7) | C7: 900000007 | D7: =IFERROR(VLOOKUP(C7,TRAOPE!$G:$H,2,0),"") | E7: DW81 | F7: D171 | G7: =IFERROR(VLOOKUP(A7,Flete!$A:$E,5,0),"") | H7: =IFERROR(VLOOKUP(F7,TRAOPE!$AA:$AB,2,0),"") | I7: 10000404 | J7: =IFERROR(VLOOKUP(I7,Materiales!$A:$H,8,0),"") | K7: =IFERROR(VLOOKUP(I7,Materiales!$A:$G,7,0),"") | L7: 20240513 | M7: 99991231 | N7: 186 | O7: =IFERROR(VLOOKUP(A7,Flete!$A:$J,10,0),"") | P7: TN | Q7: =IFERROR(IFERROR(VLOOKUP(A7,TRAOPE!$A:$U,21,0),VLOOKUP(B7,TRAOPE!$A:$U,21,0)),"") | R7: =IFERROR(IFERROR(VLOOKUP(A7,TRAOPE!$A:$W,23,0),VLOOKUP(B7,TRAOPE!$A:$W,23,0)),"") | S7: =IF(AND(P7="TN",R7="TN"),N7+N(O7),IF(G7&""="1",N(K7)*N7,(N7+N(O7))*N(K7))) | T7: =IF(Q7="","",Q7-S7)
A8: =CONCATENATE(C8,E8,F8,I8) | B8: =CONCATENATE(C8,E8,I8) | C8: 900000007 | D8: =IFERROR(VLOOKUP(C8,TRAOPE!$G:$H,2,0),"") | E8: DW81 | F8: D171 | G8: =IFERROR(VLOOKUP(A8,Flete!$A:$E,5,0),"") | H8: =IFERROR(VLOOKUP(F8,TRAOPE!$AA:$AB,2,0),"") | I8: 10000572 | J8: =IFERROR(VLOOKUP(I8,Materiales!$A:$H,8,0),"") | K8: =IFERROR(VLOOKUP(I8,Materiales!$A:$G,7,0),"") | L8: 20240513 | M8: 99991231 | N8: 186 | O8: =IFERROR(VLOOKUP(A8,Flete!$A:$J,10,0),"") | P8: TN | Q8: =IFERROR(IFERROR(VLOOKUP(A8,TRAOPE!$A:$U,21,0),VLOOKUP(B8,TRAOPE!$A:$U,21,0)),"") | R8: =IFERROR(IFERROR(VLOOKUP(A8,TRAOPE!$A:$W,23,0),VLOOKUP(B8,TRAOPE!$A:$W,23,0)),"") | S8: =IF(AND(P8="TN",R8="TN"),N8+N(O8),IF(G8&""="1",N(K8)*N8,(N8+N(O8))*N(K8))) | T8: =IF(Q8="","",Q8-S8)
A9: =CONCATENATE(C9,E9,F9,I9) | B9: =CONCATENATE(C9,E9,I9) | C9: 900000052 | D9: =IFERROR(VLOOKUP(C9,TRAOPE!$G:$H,2,0),"") | E9: DW81 | F9: D148 | G9: =IFERROR(VLOOKUP(A9,Flete!$A:$E,5,0),"") | H9: =IFERROR(VLOOKUP(F9,TRAOPE!$AA:$AB,2,0),"") | I9: 10000572 | J9: =IFERROR(VLOOKUP(I9,Materiales!$A:$H,8,0),"") | K9: =IFERROR(VLOOKUP(I9,Materiales!$A:$G,7,0),"") | L9: 20210620 | M9: 20251031 | N9: 93.18 | O9: =IFERROR(VLOOKUP(A9,Flete!$A:$J,10,0),"") | P9: TN | Q9: =IFERROR(IFERROR(VLOOKUP(A9,TRAOPE!$A:$U,21,0),VLOOKUP(B9,TRAOPE!$A:$U,21,0)),"") | R9: =IFERROR(IFERROR(VLOOKUP(A9,TRAOPE!$A:$W,23,0),VLOOKUP(B9,TRAOPE!$A:$W,23,0)),"") | S9: =IF(AND(P9="TN",R9="TN"),N9+N(O9),IF(G9&""="1",N(K9)*N9,(N9+N(O9))*N(K9))) | T9: =IF(Q9="","",Q9-S9)
A10: =CONCATENATE(C10,E10,F10,I10) | B10: =CONCATENATE(C10,E10,I10) | C10: 900000052 | D10: =IFERROR(VLOOKUP(C10,TRAOPE!$G:$H,2,0),"") | E10: DW81 | F10: D149 | G10: =IFERROR(VLOOKUP(A10,Flete!$A:$E,5,0),"") | H10: =IFERROR(VLOOKUP(F10,TRAOPE!$AA:$AB,2,0),"") | I10: 10000404 | J10: =IFERROR(VLOOKUP(I10,Materiales!$A:$H,8,0),"") | K10: =IFERROR(VLOOKUP(I10,Materiales!$A:$G,7,0),"") | L10: 20210620 | M10: 20251031 | N10: 78.34 | O10: =IFERROR(VLOOKUP(A10,Flete!$A:$J,10,0),"") | P10: TN | Q10: =IFERROR(IFERROR(VLOOKUP(A10,TRAOPE!$A:$U,21,0),VLOOKUP(B10,TRAOPE!$A:$U,21,0)),"") | R10: =IFERROR(IFERROR(VLOOKUP(A10,TRAOPE!$A:$W,23,0),VLOOKUP(B10,TRAOPE!$A:$W,23,0)),"") | S10: =IF(AND(P10="TN",R10="TN"),N10+N(O10),IF(G10&""="1",N(K10)*N10,(N10+N(O10))*N(K10))) | T10: =IF(Q10="","",Q10-S10)
A11: =CONCATENATE(C11,E11,F11,I11) | B11: =CONCATENATE(C11,E11,I11) | C11: 900000052 | D11: =IFERROR(VLOOKUP(C11,TRAOPE!$G:$H,2,0),"") | E11: DW81 | F11: D149 | G11: =IFERROR(VLOOKUP(A11,Flete!$A:$E,5,0),"") | H11: =IFERROR(VLOOKUP(F11,TRAOPE!$AA:$AB,2,0),"") | I11: 10000572 | J11: =IFERROR(VLOOKUP(I11,Materiales!$A:$H,8,0),"") | K11: =IFERROR(VLOOKUP(I11,Materiales!$A:$G,7,0),"") | L11: 20210620 | M11: 20251031 | N11: 85.28 | O11: =IFERROR(VLOOKUP(A11,Flete!$A:$J,10,0),"") | P11: TN | Q11: =IFERROR(IFERROR(VLOOKUP(A11,TRAOPE!$A:$U,21,0),VLOOKUP(B11,TRAOPE!$A:$U,21,0)),"") | R11: =IFERROR(IFERROR(VLOOKUP(A11,TRAOPE!$A:$W,23,0),VLOOKUP(B11,TRAOPE!$A:$W,23,0)),"") | S11: =IF(AND(P11="TN",R11="TN"),N11+N(O11),IF(G11&""="1",N(K11)*N11,(N11+N(O11))*N(K11))) | T11: =IF(Q11="","",Q11-S11)
A12: =CONCATENATE(C12,E12,F12,I12) | B12: =CONCATENATE(C12,E12,I12) | C12: 900000106 | D12: =IFERROR(VLOOKUP(C12,TRAOPE!$G:$H,2,0),"") | E12: DW81 | F12: D165 | G12: =IFERROR(VLOOKUP(A12,Flete!$A:$E,5,0),"") | H12: =IFERROR(VLOOKUP(F12,TRAOPE!$AA:$AB,2,0),"") | I12: 10028438 | J12: =IFERROR(VLOOKUP(I12,Materiales!$A:$H,8,0),"") | K12: =IFERROR(VLOOKUP(I12,Materiales!$A:$G,7,0),"") | L12: 20210620 | M12: 20251031 | N12: 2325 | O12: =IFERROR(VLOOKUP(A12,Flete!$A:$J,10,0),"") | P12: TN | Q12: =IFERROR(IFERROR(VLOOKUP(A12,TRAOPE!$A:$U,21,0),VLOOKUP(B12,TRAOPE!$A:$U,21,0)),"") | R12: =IFERROR(IFERROR(VLOOKUP(A12,TRAOPE!$A:$W,23,0),VLOOKUP(B12,TRAOPE!$A:$W,23,0)),"") | S12: =IF(AND(P12="TN",R12="TN"),N12+N(O12),IF(G12&""="1",N(K12)*N12,(N12+N(O12))*N(K12))) | T12: =IF(Q12="","",Q12-S12)
A13: =CONCATENATE(C13,E13,F13,I13) | B13: =CONCATENATE(C13,E13,I13) | C13: 900000106 | D13: =IFERROR(VLOOKUP(C13,TRAOPE!$G:$H,2,0),"") | E13: DW81 | F13: D169 | G13: =IFERROR(VLOOKUP(A13,Flete!$A:$E,5,0),"") | H13: =IFERROR(VLOOKUP(F13,TRAOPE!$AA:$AB,2,0),"") | I13: 10028438 | J13: =IFERROR(VLOOKUP(I13,Materiales!$A:$H,8,0),"") | K13: =IFERROR(VLOOKUP(I13,Materiales!$A:$G,7,0),"") | L13: 20210620 | M13: 20251031 | N13: 2110 | O13: =IFERROR(VLOOKUP(A13,Flete!$A:$J,10,0),"") | P13: TN | Q13: =IFERROR(IFERROR(VLOOKUP(A13,TRAOPE!$A:$U,21,0),VLOOKUP(B13,TRAOPE!$A:$U,21,0)),"") | R13: =IFERROR(IFERROR(VLOOKUP(A13,TRAOPE!$A:$W,23,0),VLOOKUP(B13,TRAOPE!$A:$W,23,0)),"") | S13: =IF(AND(P13="TN",R13="TN"),N13+N(O13),IF(G13&""="1",N(K13)*N13,(N13+N(O13))*N(K13))) | T13: =IF(Q13="","",Q13-S13)
A14: =CONCATENATE(C14,E14,F14,I14) | B14: =CONCATENATE(C14,E14,I14) | C14: 900000106 | D14: =IFERROR(VLOOKUP(C14,TRAOPE!$G:$H,2,0),"") | E14: DW81 | F14: D192 | G14: =IFERROR(VLOOKUP(A14,Flete!$A:$E,5,0),"") | H14: =IFERROR(VLOOKUP(F14,TRAOPE!$AA:$AB,2,0),"") | I14: 10028438 | J14: =IFERROR(VLOOKUP(I14,Materiales!$A:$H,8,0),"") | K14: =IFERROR(VLOOKUP(I14,Materiales!$A:$G,7,0),"") | L14: 20210620 | M14: 20251031 | N14: 2111 | O14: =IFERROR(VLOOKUP(A14,Flete!$A:$J,10,0),"") | P14: TN | Q14: =IFERROR(IFERROR(VLOOKUP(A14,TRAOPE!$A:$U,21,0),VLOOKUP(B14,TRAOPE!$A:$U,21,0)),"") | R14: =IFERROR(IFERROR(VLOOKUP(A14,TRAOPE!$A:$W,23,0),VLOOKUP(B14,TRAOPE!$A:$W,23,0)),"") | S14: =IF(AND(P14="TN",R14="TN"),N14+N(O14),IF(G14&""="1",N(K14)*N14,(N14+N(O14))*N(K14))) | T14: =IF(Q14="","",Q14-S14)
... A175: =CONCATENATE(C175,E175,F175,I175) | B175: =CONCATENATE(C175,E175,I175) | C175: 900009416 | D175: =IFERROR(VLOOKUP(C175,TRAOPE!$G:$H,2,0),"") | E175: DW81 | F175: D149 | G175: =IFERROR(VLOOKUP(A175,Flete!$A:$E,5,0),"") | H175: =IFERROR(VLOOKUP(F175,TRAOPE!$AA:$AB,2,0),"") | I175: 10273352 | J175: =IFERROR(VLOOKUP(I175,Materiales!$A:$H,8,0),"") | K175: =IFERROR(VLOOKUP(I175,Materiales!$A:$G,7,0),"") | L175: 20251217 | M175: 99991231 | N175: 350 | O175: =IFERROR(VLOOKUP(A175,Flete!$A:$J,10,0),"") | P175: TN | Q175: =IFERROR(IFERROR(VLOOKUP(A175,TRAOPE!$A:$U,21,0),VLOOKUP(B175,TRAOPE!$A:$U,21,0)),"") | R175: =IFERROR(IFERROR(VLOOKUP(A175,TRAOPE!$A:$W,23,0),VLOOKUP(B175,TRAOPE!$A:$W,23,0)),"") | S175: =IF(AND(P175="TN",R175="TN"),N175+N(O175),IF(G175&""="1",N(K175)*N175,(N175+N(O175))*N(K175))) | T175: =IF(Q175="","",Q175-S175)

Sheet MP
A1: No. SF | B1: Cedis | C1: Destino | D1: No. Material | E1: Nombre Material | F1: Importe MP | G1: Moneda | H1: Cantidad | I1: UM | J1: C | K1: Inicio Vigencia | L1: Fin Vigencia
A2: 900000007 | B2: DW81 | C2: D148 | D2: 10000404 | F2: 178 | I2: TN | K2: 20241018 | L2: 99991231
A3: 900000007 | B3: DW81 | C3: D148 | D3: 10000572 | F3: 178 | I3: TN | K3: 20241018 | L3: 99991231
A4: 900000007 | B4: DW81 | C4: D149 | D4: 10000404 | F4: 186 | I4: TN | K4: 20240513 | L4: 99991231
A5: 900000007 | B5: DW81 | C5: D149 | D5: 10000572 | F5: 186 | I5: TN | K5: 20240513 | L5: 99991231
A6: 900000007 | B6: DW81 | C6: D171 | D6: 10000404 | F6: 186 | I6: TN | K6: 20240513 | L6: 99991231
A7: 900000007 | B7: DW81 | C7: D171 | D7: 10000572 | F7: 186 | I7: TN | K7: 20240513 | L7: 99991231
A8: 900000052 | B8: DW81 | C8: D148 | D8: 10000572 | F8: 93.18 | I8: TN | K8: 20210620 | L8: 20251031
A9: 900000052 | B9: DW81 | C9: D149 | D9: 10000404 | F9: 78.34 | I9: TN | K9: 20210620 | L9: 20251031
A10: 900000052 | B10: DW81 | C10: D149 | D10: 10000572 | F10: 85.28 | I10: TN | K10: 20210620 | L10: 20251031
A11: 900000106 | B11: DW81 | C11: D165 | D11: 10028438 | F11: 2325 | I11: TN | K11: 20210620 | L11: 20251031
A12: 900000106 | B12: DW81 | C12: D169 | D12: 10028438 | F12: 2110 | I12: TN | K12: 20210620 | L12: 20251031
A13: 900000106 | B13: DW81 | C13: D192 | D13: 10028438 | F13: 2111 | I13: TN | K13: 20210620 | L13: 20251031
... A174: 900009416 | B174: DW81 | C174: D149 | D174: 10273352 | F174: 350 | I174: TN | K174: 20251217 | L174: 99991231

Sheet Flete
A1: Concat1 | B1: No. SF | C1: Cedis | D1: Destino | E1: Cond. Exp. | F1: Material | H1: Nombre Material | J1: Importe Flete | K1: Moneda | L1: Cantidad | M1: UM | N1: C | P1: Inicio Vigencia | Q1: Fin Vigencia
A2: 900000007DW81D14810000404 | B2: 900000007 | C2: DW81 | D2: D148 | E2: 4 | F2: 10000404 | J2: 47 | M2: TN | P2: 20241018 | Q2: 99991231
A3: 900000007DW81D14810000572 | B3: 900000007 | C3: DW81 | D3: D148 | E3: 4 | F3: 10000572 | J3: 47 | M3: TN | P3: 20241018 | Q3: 99991231
A4: 900000007DW81D14910000404 | B4: 900000007 | C4: DW81 | D4: D149 | E4: 4 | F4: 10000404 | J4: 280 | M4: TN | P4: 20240513 | Q4: 99991231
A5: 900000007DW81D14910000572 | B5: 900000007 | C5: DW81 | D5: D149 | E5: 4 | F5: 10000572 | J5: 280 | M5: TN | P5: 20240513 | Q5: 99991231
A6: 900000007DW81D17110000404 | B6: 900000007 | C6: DW81 | D6: D171 | E6: 4 | F6: 10000404 | J6: 262 | M6: TN | P6: 20240513 | Q6: 99991231
A7: 900000007DW81D17110000572 | B7: 900000007 | C7: DW81 | D7: D171 | E7: 4 | F7: 10000572 | J7: 262 | M7: TN | P7: 20240513 | Q7: 99991231
A8: 900000052DW81D14810000572 | B8: 900000052 | C8: DW81 | D8: D148 | E8: 4 | F8: 10000572 | J8: 50 | M8: TN | P8: 20210620 | Q8: 20251031
A9: 900000052DW81D14910000404 | B9: 900000052 | C9: DW81 | D9: D149 | E9: 4 | F9: 10000404 | J9: 240.28 | M9: TN | P9: 20210620 | Q9: 20251031
A10: 900000052DW81D14910000572 | B10: 900000052 | C10: DW81 | D10: D149 | E10: 4 | F10: 10000572 | J10: 214.72 | M10: TN | P10: 20210620 | Q10: 20251031
A11: 900000106DW81D16510028438 | B11: 900000106 | C11: DW81 | D11: D165 | E11: 4 | F11: 10028438 | J11: 300 | M11: TN | P11: 20210620 | Q11: 20251031
A12: 900000106DW81D16910028438 | B12: 900000106 | C12: DW81 | D12: D169 | E12: 4 | F12: 10028438 | J12: 220 | M12: TN | P12: 20210620 | Q12: 20251031
A13: 900000106DW81D19210028438 | B13: 900000106 | C13: DW81 | D13: D192 | E13: 4 | F13: 10028438 | J13: 220 | M13: TN | P13: 20210620 | Q13: 20251031
... A170: 900009416DW81D14910273352 | B170: 900009416 | C170: DW81 | D170: D149 | E170: 4 | F170: 10273352 | J170: 50 | M170: TN | P170: 20251217 | Q170: 99991231

Sheet Materiales
A1: Material | B1: TpMt | C1: Denom | D1: UMA | E1: Contador | F1: UMB | G1: PV | H1: Nombre Material
A2: 10000001 | B2: ZFER | C2: 1000 | D2: M3 | E2: 1000 | F2: TN | G2: 1262 | H2: GRAVA ANDESITA 10 MM (3/8")
A3: 10000003 | B3: ZFER | C3: 1000 | D3: M3 | E3: 1000 | F3: TN | G3: 1443 | H3: GRAVA CALIZA 10 MM (3/8")
A4: 10000006 | B4: ZFER | C4: 1000 | D4: M3 | E4: 1000 | F4: TN | G4: 1490 | H4: GRAVA RIO 10 MM (3/8")
A5: 10000007 | B5: ZFER | C5: 1000 | D5: M3 | E5: 1000 | F5: TN | G5: 1488 | H5: GRAVA BASALTO 13 MM (1/2")
A6: 10000008 | B6: ZFER | C6: 1000 | D6: M3 | E6: 1000 | F6: TN | G6: 1358 | H6: GRAVA CALIZA 13 MM (1/2")
A7: 10000011 | B7: ZFER | C7: 1000 | D7: M3 | E7: 1000 | F7: TN | G7: 1323 | H7: GRAVA ANDESITA 20 MM (3/4")
A8: 10000013 | B8: ZFER | C8: 1000 | D8: M3 | E8: 1000 | F8: TN | G8: 1514 | H8: GRAVA BASALTO 20 MM (3/4")
A9: 10000014 | B9: ZFER | C9: 1000 | D9: M3 | E9: 1000 | F9: TN | G9: 1400 | H9: GRAVA CALIZA 20 MM (3/4")
A10: 10000015 | B10: ZFER | C10: 1000 | D10: M3 | E10: 1000 | F10: TN | G10: 1410 | H10: GRAVA GRANITO 20 MM (3/4")
A11: 10000017 | B11: ZFER | C11: 1000 | D11: M3 | E11: 1000 | F11: TN | G11: 1475 | H11: GRAVA RIOLITA 20 MM (3/4")
A12: 10000019 | B12: ZFER | C12: 1000 | D12: M3 | E12: 1000 | F12: TN | G12: 1515 | H12: GRAVA RIO 20 MM (3/4")
A13: 10000020 | B13: ZFER | C13: 1000 | D13: M3 | E13: 1 | F13: TN | G13: 1 | H13: GRAVA MAQUILA 40MM (1 1/2")
... A2291: 10268770 | B2291: ZFE3 | C2291: 1000 | D2291: M3 | E2291: 1000 | F2291: TN | G2291: 1240 | H2291: MP GRAVA TRIT CALIZA 40MM 1 1/2" - ESP
A2292: 10268901 | B2292: ZFE3 | C2292: 1000 | D2292: M3 | E2292: 1000 | G2292: 1560 | H2292: MP GRAVA ANDESITA GRIS 3/4" - CAPADA
A2293: 10267983 | C2293: 1000 | G2293: 1800 | H2293: ESCORIA ALTO HORNO 3/4
A2294: 10268996 | C2294: 1000 | G2294: 1329 | H2294: GRAVA TRITURADA CALIZA 40 MM - 11/2"
A2295: 10269072 | C2295: 1000 | G2295: 1700 | H2295: BASE HIDRÁULICA SCREEN
A2296: 10269225 | B2296: ZFE3 | C2296: 1000 | D2296: M3 | E2296: 1000 | G2296: 1289 | H2296: MP ARENA CALIZA LAVADA MALLA 4 - DELTA I
A2297: 10269245 | B2297: ZFE3 | C2297: 1000 | D2297: M3 | E2297: 1000 | G2297: 1410 | H2297: MP GRAVA TRITURADA CALIZA 3/8 - 10MM
A2298: 10269246 | B2298: ZFE3 | C2298: 1000 | D2298: M3 | E2298: 1000 | G2298: 1400 | H2298: MP GRAVA TRITURADA CALIZA 1 1/2 - 40MM
A2299: 10269247 | B2299: ZFE3 | C2299: 1000 | D2299: M3 | E2299: 1000 | G2299: 1560 | H2299: MP ARENA TRIT CALIZA M-4
A2300: 10270431 | B2300: ZFE3 | C2300: 1000 | D2300: M3 | E2300: 1000 | G2300: 1423 | H2300: MP GRAVA RIOLITA 13 MM - 1/2"
A2301: 10270898 | B2301: ZFE3 | C2301: 1000 | D2301: M3 | E2301: 1000 | G2301: 1551 | H2301: MP BASE H. TRIT. BASALTO 1 1/2" A FINOS
A2302: 10270911 | B2302: ZFE3 | C2302: 1000 | D2302: M3 | E2302: 1000 | G2302: 1360 | H2302: MP GRAVA TRIT. BASALTO 40 MM - 1 1/2"
A2303: 10270912 | B2303: ZFE3 | C2303: 1000 | D2303: M3 | E2303: 1000 | G2303: 1589 | H2303: MP ARENA TRIT. BASALTO MALLA 4
A2304: 10270913 | B2304: ZFE3 | C2304: 1000 | D2304: M3 | E2304: 1000 | G2304: 1395 | H2304: MP GRAVA TRIT. BASALTO 20 MM - 3/4
A2305: 10270914 | B2305: ZFE3 | C2305: 1000 | D2305: M3 | E2305: 1000 | G2305: 1623 | H2305: MP ARENA ANDESITA BC
A2306: 10270824 | B2306: M3 | C2306: 1000 | D2306: M3 | E2306: 10007640 | G2306: 1325 | H2306: MP ARENA TRITURADA CALIZA MALLA 5
A2307: 10270825 | B2307: M3 | C2307: 1000 | D2307: M3 | E2307: 10000003 | G2307: 1242 | H2307: MP GRAVA TRITURADA CALIZA 10MM (3/8”)
... A2319: 10272527 | B2319: ZFE3 | C2319: 1000 | D2319: M3 | E2319: 1000 | G2319: 1620 | H2319: CNC - NO CLASIFICADO
A2320: 10000332 | C2320: 1000 | D2320: M3 | E2320: 1000 | G2320: 800 | H2320: Grava Triturada Pomez - Jal 20 mm - 3/4"
A2321: 10273001 | B2321: ZFE3 | C2321: 1000 | D2321: M3 | E2321: 1000 | G2321: 1688 | H2321: MP ARENA TRIT. BASALTO MALLA 4
A2322: 10273002 | B2322: ZFE3 | C2322: 1000 | D2322: M3 | E2322: 1000 | G2322: 1466 | H2322: MP GRAVA TRIT. BASALTO 20 MM - 3/4"
A2323: 10273351 | B2323: ZFE3 | C2323: 1000 | D2323: M3 | E2323: 1000 | G2323: 1612 | H2323: MP ARENA TRIT. CALIZA MALLA 4
A2324: 10273352 | B2324: ZFE3 | C2324: 1000 | D2324: M3 | E2324: 1000 | G2324: 1492 | H2324: MP GRAVA TRIT. CALIZA 20 MM - 3/4"
A2325: 10271724 | B2325: ZFE3 | C2325: 1000 | D2325: M3 | E2325: 1000 | G2325: 1900 | H2325: MP RESIDUO DE CONCRETO
A2326: 10000677 | C2326: 1000 | D2326: M3 | G2326: 1164 | H2326: Grava Triturada Caliza 20 mm - 3/4"
A2327: 10274190 | B2327: ZFE3 | C2327: 1000 | D2327: M3 | E2327: 1000 | G2327: 1800 | H2327: MP BASE HIDRAULICA ANDESITA 70-30
A2328: 10274601 | B2328: ZFE3 | C2328: 1000 | D2328: M3 | E2328: 1000 | G2328: 1447 | H2328: MP ARENA BASALTO N° 4
...

Sheet TRAOPE
A1: Concat1 | B1: Contrato_Pos | C1: Doc. Compras | D1: Pos | E1: Org.compras | F1: Grp-Compr. | G1: Ship From | H1: Nombre SF | I1: Proveedor | J1: Nombre Prov | K1: Cond. Pago | L1: Descr. Cond Pago | M1: Material | N1: Descripción | O1: Centro | P1: Descripción Centro | Q1: In.perído validez | R1: Fin perído validez | S1: Válido de | T1: Validez a | U1: Precio neto pedido | V1: Moneda | W1: UM Precio Pedido | X1: Importe Condición | Y1: Moneda KONP | Z1: UM Ctd Base | AA1: Destino | AB1: Nombre Destino | AC1: Cuenta de mayor | AD1: Centro de costo | AE1: Cond. Exp. | AF1: Descr. Cond. Exp. | AG1: Peso Vol. | AH1: UMB | AI1: Ind. Oblig. Conf. Ped. | AJ1: Ctrl-Conf. | AK1: IVA | AL1: Modif_Date | AM1: Ruta
A2: 900007996DW81D17110000430 | B2: 4600056243-20 | C2: 4600056243 | D2: 20 | E2: MXPO | F2: MXL | G2: 900007996 | H2: SF TC-ED-SIGLO 21 | I2: 5087794 | J2: TRITURACION SIGLO 21 SA DE CV | K2: Z09 | L2: (AP) 90 Dias | M2: 10000430 | N2: Grava Triturada Caliza 20 mm - 3/4" | O2: DW81 | P2: MX-CED. SALTILLO | Q2: 20230928 | R2: 20281231 | S2: 20230105 | T2: 20271231 | U2: 430 | V2: MXN | W2: M3 | X2: 160 | Y2: MXN | Z2: M3 | AA2: D171 | AB2: PD0016 PIEDRAS NEGRAS | AC2: 56103637 | AD2: 6644381540 | AE2: 4 | AF2: ENTREGA DIRECTA | AG2: 1.5 | AH2: M3 | AI2: X | AJ2: 4 | AK2: V1 | AL2: 20230920 | AM2: DW81-900007996-D171-10000430-4
A3: 900007997DW81D14910000460 | B3: 4600056094-10 | C3: 4600056094 | D3: 10 | E3: MXPO | F3: MXL | G3: 900007997 | H3: SF TC-ED-ABC DEL NORTE | I3: 5086160 | J3: AGREGADOS BLOCK Y CONCRETOS DEL NOR | K3: N90 | L3: (AP) NAFIN 90 Dias | M3: 10000460 | N3: Grava Clasificada Río 20 mm - 3/4" | O3: DW81 | P3: MX-CED. SALTILLO | Q3: 20230104 | R3: 20271231 | S3: 20230104 | T3: 20271231 | U3: 295 | V3: MXN | W3: TN | X3: 95 | Y3: MXN | Z3: TN | AA3: D149 | AB3: PD051 ACUÑA | AC3: 56103637 | AD3: 6644381540 | AE3: 4 | AF3: ENTREGA DIRECTA | AG3: 1 | AH3: TO | AI3: X | AJ3: 4 | AK3: V4 | AL3: 20230920 | AM3: DW81-900007997-D149-10000460-4
A4: 900008694DW81D17110000572 | B4: 4600069205-50 | C4: 4600069205 | D4: 50 | E4: MXPO | F4: MXL | G4: 900008694 | H4: SF TC-ED TRICABA | I4: 5092353 | J4: TRICABA DE SABINAS SA DE CV | K4: N90 | L4: (AP) NAFIN 90 Dias | M4: 10000572 | N4: Arena Triturada Caliza Malla 4 | O4: DW81 | P4: MX-CED. SALTILLO | Q4: 20240229 | R4: 20291231 | S4: 20250301 | T4: 20301231 | U4: 431 | V4: MXN | W4: TN | X4: 232 | Y4: MXN | Z4: TN | AA4: D171 | AB4: PD0016 PIEDRAS NEGRAS | AC4: 56103638 | AD4: 6644381540 | AE4: 4 | AF4: ENTREGA DIRECTA | AG4: 1 | AH4: TO | AI4: X | AJ4: 4 | AK4: V4 | AL4: 20250408 | AM4: DW81-900008694-D171-10000572-4
A5: 900008694DW81D14910000404 | B5: 4600069205-20 | C5: 4600069205 | D5: 20 | E5: MXPO | F5: MXL | G5: 900008694 | H5: SF TC-ED TRICABA | I5: 5092353 | J5: TRICABA DE SABINAS SA DE CV | K5: N90 | L5: (AP) NAFIN 90 Dias | M5: 10000404 | N5: Grava Triturada Caliza 20 mm - 3/4" | O5: DW81 | P5: MX-CED. SALTILLO | Q5: 20240229 | R5: 20291231 | S5: 20250301 | T5: 20301231 | U5: 481 | V5: MXN | W5: TN | X5: 289 | Y5: MXN | Z5: TN | AA5: D149 | AB5: PD051 ACUÑA | AC5: 56103637 | AD5: 6644381540 | AE5: 4 | AF5: ENTREGA DIRECTA | AG5: 1 | AH5: TO | AI5: X | AJ5: 4 | AK5: V4 | AL5: 20250408 | AM5: DW81-900008694-D149-10000404-4
A6: 900008694DW81D17110000404 | B6: 4600069205-60 | C6: 4600069205 | D6: 60 | E6: MXPO | F6: MXL | G6: 900008694 | H6: SF TC-ED TRICABA | I6: 5092353 | J6: TRICABA DE SABINAS SA DE CV | K6: N90 | L6: (AP) NAFIN 90 Dias | M6: 10000404 | N6: Grava Triturada Caliza 20 mm - 3/4" | O6: DW81 | P6: MX-CED. SALTILLO | Q6: 20240229 | R6: 20291231 | S6: 20250301 | T6: 20301231 | U6: 416 | V6: MXN | W6: TN | X6: 232 | Y6: MXN | Z6: TN | AA6: D171 | AB6: PD0016 PIEDRAS NEGRAS | AC6: 56103637 | AD6: 6644381540 | AE6: 4 | AF6: ENTREGA DIRECTA | AG6: 1 | AH6: TO | AI6: X | AJ6: 4 | AK6: V4 | AL6: 20250408 | AM6: DW81-900008694-D171-10000404-4
A7: 900007997DW81D14910000166 | B7: 4600056094-20 | C7: 4600056094 | D7: 20 | E7: MXPO | F7: MXL | G7: 900007997 | H7: SF TC-ED-ABC DEL NORTE | I7: 5086160 | J7: AGREGADOS BLOCK Y CONCRETOS DEL NOR | K7: N90 | L7: (AP) NAFIN 90 Dias | M7: 10000166 | N7: Arena Clasificada Río Malla 4 | O7: DW81 | P7: MX-CED. SALTILLO | Q7: 20230104 | R7: 20271231 | S7: 20230104 | T7: 20271231 | U7: 295 | V7: MXN | W7: TN | X7: 95 | Y7: MXN | Z7: TN | AA7: D149 | AB7: PD051 ACUÑA | AC7: 56103638 | AD7: 6644381540 | AE7: 4 | AF7: ENTREGA DIRECTA | AG7: 1 | AH7: TO | AI7: X | AJ7: 4 | AK7: V4 | AL7: 20230920 | AM7: DW81-900007997-D149-10000166-4
A8: 900007996DW81D17110132162 | B8: 4600056243-10 | C8: 4600056243 | D8: 10 | E8: MXPO | F8: MXL | G8: 900007996 | H8: SF TC-ED-SIGLO 21 | I8: 5087794 | J8: TRITURACION SIGLO 21 SA DE CV | K8: Z09 | L8: (AP) 90 Dias | M8: 10132162 | N8: ARENA TRITURADA CALIZA MALLA 4 | O8: DW81 | P8: MX-CED. SALTILLO | Q8: 20230928 | R8: 20281231 | S8: 20230105 | T8: 20271231 | U8: 460 | V8: MXN | W8: M3 | X8: 160 | Y8: MXN | Z8: M3 | AA8: D171 | AB8: PD0016 PIEDRAS NEGRAS | AC8: 56103638 | AD8: 6644381867 | AE8: 4 | AF8: ENTREGA DIRECTA | AG8: 1.608 | AH8: M3 | AI8: X | AJ8: 4 | AK8: V1 | AL8: 20230920 | AM8: DW81-900007996-D171-10132162-4
A9: 900009416DW81D14910273352 | B9: 4600071871-20 | C9: 4600071871 | D9: 20 | E9: MXPO | F9: MXL | G9: 900009416 | H9: SF TC-ED ARIM DEL NORTE | I9: 5095598 | J9: DESARROLLOS ARIM DEL NORTE SA DE CV | K9: Z09 | L9: (AP) 90 Dias | M9: 10273352 | N9: MP GRAVA TRIT. CALIZA 20 MM - 3/4" | O9: DW81 | P9: MX-CED. SALTILLO | Q9: 20251217 | R9: 20301231 | S9: 20251217 | T9: 20301231 | U9: 400 | V9: MXN | W9: TN | X9: 50 | Y9: MXN | Z9: TN | AA9: D149 | AB9: PD051 ACUÑA | AC9: 56103637 | AD9: 6644381540 | AE9: 4 | AF9: ENTREGA DIRECTA | AG9: 1 | AH9: TO | AI9: X | AJ9: 4 | AK9: V1 | AL9: 20251224 | AM9: DW81-900009416-D149-10273352-4
A10: 900009416DW81D14910273351 | B10: 4600071871-10 | C10: 4600071871 | D10: 10 | E10: MXPO | F10: MXL | G10: 900009416 | H10: SF TC-ED ARIM DEL NORTE | I10: 5095598 | J10: DESARROLLOS ARIM DEL NORTE SA DE CV | K10: Z09 | L10: (AP) 90 Dias | M10: 10273351 | N10: MP ARENA TRIT. CALIZA MALLA 4 | O10: DW81 | P10: MX-CED. SALTILLO | Q10: 20251217 | R10: 20301231 | S10: 20251217 | T10: 20301231 | U10: 415 | V10: MXN | W10: TN | X10: 50 | Y10: MXN | Z10: TN | AA10: D149 | AB10: PD051 ACUÑA | AC10: 56103638 | AD10: 6644381540 | AE10: 4 | AF10: ENTREGA DIRECTA | AG10: 1 | AH10: TO | AI10: X | AJ10: 4 | AK10: V1 | AL10: 20251224 | AM10: DW81-900009416-D149-10273351-4
A11: 900009082DW81D14910000572 | B11: 4600070692-30 | C11: 4600070692 | D11: 30 | E11: MXPO | F11: MXL | G11: 900009082 | H11: SF TC-ED TRAYMAQ | I11: 5094852 | J11: TRAYMAQ AGREGADOS SA DE CV | K11: Z09 | L11: (AP) 90 Dias | M11: 10000572 | N11: Arena Triturada Caliza Malla 4 | O11: DW81 | P11: MX-CED. SALTILLO | Q11: 20241223 | R11: 20291231 | S11: 20241223 | T11: 20291231 | U11: 475 | V11: MXN | W11: TN | X11: 125 | Y11: MXN | Z11: TN | AA11: D149 | AB11: PD051 ACUÑA | AC11: 56103638 | AD11: 6644381540 | AE11: 4 | AF11: ENTREGA DIRECTA | AG11: 1 | AH11: TO | AI11: X | AJ11: 4 | AK11: V4 | AL11: 20241227 | AM11: DW81-900009082-D149-10000572-4
A12: 900009082DW81D17110000404 | B12: 4600070692-20 | C12: 4600070692 | D12: 20 | E12: MXPO | F12: MXL | G12: 900009082 | H12: SF TC-ED TRAYMAQ | I12: 5094852 | J12: TRAYMAQ AGREGADOS SA DE CV | K12: Z09 | L12: (AP) 90 Dias | M12: 10000404 | N12: Grava Triturada Caliza 20 mm - 3/4" | O12: DW81 | P12: MX-CED. SALTILLO | Q12: 20241223 | R12: 20291231 | S12: 20241223 | T12: 20291231 | U12: 350 | V12: MXN | W12: TN | X12: 1 | Y12: MXN | Z12: TN | AA12: D171 | AB12: PD0016 PIEDRAS NEGRAS | AC12: 56103637 | AD12: 6644381540 | AE12: 4 | AF12: ENTREGA DIRECTA | AG12: 1 | AH12: TO | AI12: X | AJ12: 4 | AK12: V4 | AL12: 20241227 | AM12: DW81-900009082-D171-10000404-4
A13: 900009082DW81D14910000404 | B13: 4600070692-40 | C13: 4600070692 | D13: 40 | E13: MXPO | F13: MXL | G13: 900009082 | H13: SF TC-ED TRAYMAQ | I13: 5094852 | J13: TRAYMAQ AGREGADOS SA DE CV | K13: Z09 | L13: (AP) 90 Dias | M13: 10000404 | N13: Grava Triturada Caliza 20 mm - 3/4" | O13: DW81 | P13: MX-CED. SALTILLO | Q13: 20241223 | R13: 20291231 | S13: 20241223 | T13: 20291231 | U13: 475 | V13: MXN | W13: TN | X13: 125 | Y13: MXN | Z13: TN | AA13: D149 | AB13: PD051 ACUÑA | AC13: 56103637 | AD13: 6644381540 | AE13: 4 | AF13: ENTREGA DIRECTA | AG13: 1 | AH13: TO | AI13: X | AJ13: 4 | AK13: V4 | AL13: 20241227 | AM13: DW81-900009082-D149-10000404-4
... A87: 900007998DW81D17110000404 | B87: 4600068584-10 | C87: 4600068584 | D87: 10 | E87: MXPO | F87: MXL | G87: 900007998 | H87: SF TC-ED-MATERIALES AMEZCUA | I87: 5086022 | J87: MATERIALES RENE AMEZCUA SA DE CV | K87: N90 | L87: (AP) NAFIN 90 Dias | M87: 10000404 | N87: Grava Triturada Caliza 20 mm - 3/4" | O87: DW81 | P87: MX-CED. SALTILLO | Q87: 20231006 | R87: 20291231 | S87: 20231006 | T87: 20281231 | U87: 458 | V87: MXN | W87: TN | X87: 295 | Y87: MXN | Z87: TN | AA87: D171 | AB87: PD0016 PIEDRAS NEGRAS | AC87: 56103637 | AD87: 6644381540 | AE87: 4 | AF87: ENTREGA DIRECTA | AG87: 1 | AH87: TO | AI87: X | AJ87: 4 | AK87: V4 | AL87: 20231009 | AM87: DW81-900007998-D171-10000404-4
A88: 900004125DW8110002043 | B88: 4600050389-10 | C88: 4600050389 | D88: 10 | E88: MXPO | F88: MXL | G88: 900004125 | H88: TC-GRANIX | I88: 5017518 | J88: GRANIX SA DE CCV | K88: N120 | L88: (AP) NAFIN 120 Dias | M88: 10002043 | N88: Arena Triturada Granito Malla 4 | O88: DW81 | P88: MX-CED. SALTILLO | Q88: 20210801 | R88: 20261231 | S88: 20210801 | T88: 20271231 | U88: 101.07 | V88: MXN | W88: TN | X88: 0 | Y88: MXN | Z88: TN | AC88: 56103638 | AD88: 6644381540 | AE88: 1 | AF88: ENTREGADO | AG88: 1 | AH88: TO | AI88: X | AJ88: 4 | AK88: V4 | AL88: 20230920 | AM88: DW81-900004125-10002043
A89: 900004601DW8110002043 | B89: 4600050348-10 | C89: 4600050348 | D89: 10 | E89: MXPO | F89: MXL | G89: 900004601 | H89: SF TEXLAMP | I89: 5010129 | J89: TEXLAMP S.A. DE C.V. | K89: N90 | L89: (AP) NAFIN 90 Dias | M89: 10002043 | N89: Arena Triturada Granito Malla 4 | O89: DW81 | P89: MX-CED. SALTILLO | Q89: 20210801 | R89: 20261231 | S89: 20210727 | T89: 20261231 | U89: 92.2 | V89: MXN | W89: TN | X89: 0 | Y89: MXN | Z89: TN | AC89: 56103638 | AD89: 6644381540 | AE89: 1 | AF89: ENTREGADO | AG89: 1 | AH89: TO | AI89: X | AJ89: 4 | AK89: V4 | AL89: 20260108 | AM89: DW81-900004601-10002043
A90: 900004125DW8110067274 | B90: 4600050389-30 | C90: 4600050389 | D90: 30 | E90: MXPO | F90: MXL | G90: 900004125 | H90: TC-GRANIX | I90: 5017518 | J90: GRANIX SA DE CCV | K90: N120 | L90: (AP) NAFIN 120 Dias | M90: 10067274 | N90: GRAVA TRITURADA GRANITO 40 MM -1 1/2" | O90: DW81 | P90: MX-CED. SALTILLO | Q90: 20210801 | R90: 20261231 | S90: 20220101 | T90: 20271231 | U90: 419.2 | V90: MXN | W90: TN | X90: 0 | Y90: MXN | Z90: TN | AC90: 56103637 | AD90: 6644381540 | AE90: 1 | AF90: ENTREGADO | AG90: 1 | AH90: TO | AI90: X | AJ90: 4 | AK90: V4 | AL90: 20230920 | AM90: DW81-900004125-10067274
A91: 900004125DW8110067273 | B91: 4600050389-20 | C91: 4600050389 | D91: 20 | E91: MXPO | F91: MXL | G91: 900004125 | H91: TC-GRANIX | I91: 5017518 | J91: GRANIX SA DE CCV | K91: N120 | L91: (AP) NAFIN 120 Dias | M91: 10067273 | N91: GRAVA TRITURADA GRANITO 20 MM - 3/4" | O91: DW81 | P91: MX-CED. SALTILLO | Q91: 20210801 | R91: 20261231 | S91: 20220101 | T91: 20271231 | U91: 433.61 | V91: MXN | W91: TN | X91: 0 | Y91: MXN | Z91: TN | AC91: 56103637 | AD91: 6644381540 | AE91: 1 | AF91: ENTREGADO | AG91: 1 | AH91: TO | AI91: X | AJ91: 4 | AK91: V4 | AL91: 20230920 | AM91: DW81-900004125-10067273
A92: 900008694DW81D14910000572 | B92: 4600069205-10 | C92: 4600069205 | D92: 10 | E92: MXPO | F92: MXL | G92: 900008694 | H92: SF TC-ED TRICABA | I92: 5092353 | J92: TRICABA DE SABINAS SA DE CV | K92: N90 | L92: (AP) NAFIN 90 Dias | M92: 10000572 | N92: Arena Triturada Caliza Malla 4 | O92: DW81 | P92: MX-CED. SALTILLO | Q92: 20240229 | R92: 20291231 | S92: 20250301 | T92: 20301231 | U92: 485 | V92: MXN | W92: TN | X92: 289 | Y92: MXN | Z92: TN | AA92: D149 | AB92: PD051 ACUÑA | AC92: 56103638 | AD92: 6644381540 | AE92: 4 | AF92: ENTREGA DIRECTA | AG92: 1 | AH92: TO | AI92: X | AJ92: 4 | AK92: V4 | AL92: 20250402 | AM92: DW81-900008694-D149-10000572-4
A93: 900000007DW81D17110000404 | B93: 4600069516-50 | C93: 4600069516 | D93: 50 | E93: MXPO | F93: MXL | G93: 900000007 | H93: TC-ED-CONTRISSA | I93: 5001240 | J93: CONTRISSA | K93: N90 | L93: (AP) NAFIN 90 Dias | M93: 10000404 | N93: Grava Triturada Caliza 20 mm - 3/4" | O93: DW81 | P93: MX-CED. SALTILLO | Q93: 20240513 | R93: 20291231 | S93: 20240513 | T93: 20291231 | U93: 448 | V93: MXN | W93: TN | X93: 262 | Y93: MXN | Z93: TN | AA93: D171 | AB93: PD0016 PIEDRAS NEGRAS | AC93: 56103637 | AD93: 6644381540 | AE93: 4 | AF93: ENTREGA DIRECTA | AG93: 1 | AH93: TO | AI93: X | AJ93: 4 | AK93: V4 | AL93: 20240516 | AM93: DW81-900000007-D171-10000404-4
A94: 900002741DW81D17110000407 | B94: 4600050343-720 | C94: 4600050343 | D94: 720 | E94: MXPO | F94: MXL | G94: 900002741 | H94: TC-ED-TRITURADOS GRAMOL SA DE CV | I94: 5005459 | J94: TRITURADOS GRAMOL SA DE CV | K94: Z04 | L94: (AP) 30 Dias | M94: 10000407 | N94: Grava Triturada Caliza 10 mm - 3/8" | O94: DW81 | P94: MX-CED. SALTILLO | Q94: 20210801 | R94: 20291231 | S94: 20240220 | T94: 20291231 | U94: 1005.91 | V94: MXN | W94: TN | X94: 875 | Y94: MXN | Z94: TN | AA94: D171 | AB94: PD0016 PIEDRAS NEGRAS | AC94: 56103637 | AD94: 6644381540 | AE94: 4 | AF94: ENTREGA DIRECTA | AG94: 1 | AH94: TO | AI94: X | AJ94: 4 | AK94: V4 | AL94: 20240221 | AM94: DW81-900002741-D171-10000407-4
A95: 900002741DW81D17110000404 | B95: 4600050343-730 | C95: 4600050343 | D95: 730 | E95: MXPO | F95: MXL | G95: 900002741 | H95: TC-ED-TRITURADOS GRAMOL SA DE CV | I95: 5005459 | J95: TRITURADOS GRAMOL SA DE CV | K95: Z04 | L95: (AP) 30 Dias | M95: 10000404 | N95: Grava Triturada Caliza 20 mm - 3/4" | O95: DW81 | P95: MX-CED. SALTILLO | Q95: 20210801 | R95: 20291231 | S95: 20240220 | T95: 20291231 | U95: 1005.91 | V95: MXN | W95: TN | X95: 875 | Y95: MXN | Z95: TN | AA95: D171 | AB95: PD0016 PIEDRAS NEGRAS | AC95: 56103637 | AD95: 6644381540 | AE95: 4 | AF95: ENTREGA DIRECTA | AG95: 1 | AH95: TO | AI95: X | AJ95: 4 | AK95: V4 | AL95: 20240221 | AM95: DW81-900002741-D171-10000404-4
A96: 900002741DW81D17110087726 | B96: 4600050343-760 | C96: 4600050343 | D96: 760 | E96: MXPO | F96: MXL | G96: 900002741 | H96: TC-ED-TRITURADOS GRAMOL SA DE CV | I96: 5005459 | J96: TRITURADOS GRAMOL SA DE CV | K96: Z04 | L96: (AP) 30 Dias | M96: 10087726 | N96: BASE HIDRAULICA CALIZA 50% EQ. ARENA SCT | O96: DW81 | P96: MX-CED. SALTILLO | Q96: 20210801 | R96: 20291231 | S96: 20240220 | T96: 20291231 | U96: 1005.91 | V96: MXN | W96: TN | X96: 875 | Y96: MXN | Z96: TN | AA96: D171 | AB96: PD0016 PIEDRAS NEGRAS | AC96: 56103590 | AD96: 6644381540 | AE96: 4 | AF96: ENTREGA DIRECTA | AG96: 1 | AH96: TO | AI96: X | AJ96: 4 | AK96: V4 | AL96: 20240331 | AM96: DW81-900002741-D171-10087726-4
A97: 900002741DW81D17110000141 | B97: 4600050343-750 | C97: 4600050343 | D97: 750 | E97: MXPO | F97: MXL | G97: 900002741 | H97: TC-ED-TRITURADOS GRAMOL SA DE CV | I97: 5005459 | J97: TRITURADOS GRAMOL SA DE CV | K97: Z04 | L97: (AP) 30 Dias | M97: 10000141 | N97: Grava Triturada Caliza 40 mm - 1 1/2" | O97: DW81 | P97: MX-CED. SALTILLO | Q97: 20210801 | R97: 20291231 | S97: 20240220 | T97: 20291231 | U97: 1005.91 | V97: MXN | W97: TN | X97: 875 | Y97: MXN | Z97: TN | AA97: D171 | AB97: PD0016 PIEDRAS NEGRAS | AC97: 56103637 | AD97: 6644381540 | AE97: 4 | AF97: ENTREGA DIRECTA | AG97: 1 | AH97: TO | AI97: X | AJ97: 4 | AK97: V4 | AL97: 20240221 | AM97: DW81-900002741-D171-10000141-4
A98: 900002741DW81D17110000402 | B98: 4600050343-740 | C98: 4600050343 | D98: 740 | E98: MXPO | F98: MXL | G98: 900002741 | H98: TC-ED-TRITURADOS GRAMOL SA DE CV | I98: 5005459 | J98: TRITURADOS GRAMOL SA DE CV | K98: Z04 | L98: (AP) 30 Dias | M98: 10000402 | N98: Arena Triturada Caliza Malla 4 | O98: DW81 | P98: MX-CED. SALTILLO | Q98: 20210801 | R98: 20291231 | S98: 20240220 | T98: 20291231 | U98: 1007.08 | V98: MXN | W98: TN | X98: 875 | Y98: MXN | Z98: TN | AA98: D171 | AB98: PD0016 PIEDRAS NEGRAS | AC98: 56103638 | AD98: 6644381540 | AE98: 4 | AF98: ENTREGA DIRECTA | AG98: 1 | AH98: TO | AI98: X | AJ98: 4 | AK98: V4 | AL98: 20240221 | AM98: DW81-900002741-D171-10000402-4
A99: 900001790DW81D14910000572 | B99: 4600028594-30 | C99: 4600028594 | D99: 30 | E99: MXPO | F99: M02 | G99: 900001790 | H99: TC-ED-GRUPO CONCRETOS | I99: 5007120 | J99: GRUPO CONCRETOS SA DE CV | K99: Z04 | L99: (AP) 30 Dias | M99: 10000572 | N99: Arena Triturada Caliza Malla 4 | O99: DW81 | P99: MX-CED. SALTILLO | Q99: 20141203 | R99: 20271231 | S99: 20230601 | T99: 20271231 | U99: 350 | V99: MXN | W99: TN | X99: 170 | Y99: MXN | Z99: TN | AA99: D149 | AB99: PD051 ACUÑA | AC99: 56103638 | AD99: 6644381540 | AE99: 4 | AF99: ENTREGA DIRECTA | AG99: 1 | AH99: TO | AI99: X | AJ99: 4 | AK99: V4 | AL99: 20230920 | AM99: DW81-900001790-D149-10000572-4
A100: 900001790DW81D14910000430 | B100: 4600028594-40 | C100: 4600028594 | D100: 40 | E100: MXPO | F100: M02 | G100: 900001790 | H100: TC-ED-GRUPO CONCRETOS | I100: 5007120 | J100: GRUPO CONCRETOS SA DE CV | K100: Z04 | L100: (AP) 30 Dias | M100: 10000430 | N100: Grava Triturada Caliza 20 mm - 3/4" | O100: DW81 | P100: MX-CED. SALTILLO | Q100: 20141203 | R100: 20271231 | S100: 20230601 | T100: 20271231 | U100: 350 | V100: MXN | W100: TN | X100: 170 | Y100: MXN | Z100: TN | AA100: D149 | AB100: PD051 ACUÑA | AC100: 56103637 | AD100: 6644381540 | AE100: 4 | AF100: ENTREGA DIRECTA | AG100: 1 | AH100: TO | AI100: X | AJ100: 4 | AK100: V4 | AL100: 20230920 | AM100: DW81-900001790-D149-10000430-4
A101: 900003849DW81D17110000404 | B101: 4600050345-80 | C101: 4600050345 | D101: 80 | E101: MXPO | F101: MXL | G101: 900003849 | H101: TC-ED ARTURO MONCADA | I101: 5054193 | J101: MONCADA CANTU ARTURO | K101: N90 | L101: (AP) NAFIN 90 Dias | M101: 10000404 | N101: Grava Triturada Caliza 20 mm - 3/4" | O101: DW81 | P101: MX-CED. SALTILLO | Q101: 20210801 | R101: 20291231 | S101: 20250301 | T101: 20301231 | U101: 464.92 | V101: MXN | W101: TN | X101: 321.78 | Y101: MXN | Z101: TN | AA101: D171 | AB101: PD0016 PIEDRAS NEGRAS | AC101: 56103637 | AD101: 6644381540 | AE101: 4 | AF101: ENTREGA DIRECTA | AG101: 1 | AH101: TO | AI101: X | AJ101: 4 | AK101: V4 | AL101: 20250408 | AM101: DW81-900003849-D171-10000404-4
A102: 900003849DW81D17110000624 | B102: 4600050345-100 | C102: 4600050345 | D102: 100 | E102: MXPO | F102: MXL | G102: 900003849 | H102: TC-ED ARTURO MONCADA | I102: 5054193 | J102: MONCADA CANTU ARTURO | K102: N90 | L102: (AP) NAFIN 90 Dias | M102: 10000624 | N102: Grava Triturada Caliza 40 mm - 1 1/2" | O102: DW81 | P102: MX-CED. SALTILLO | Q102: 20210801 | R102: 20291231 | S102: 20250301 | T102: 20301231 | U102: 464.92 | V102: MXN | W102: TN | X102: 321.78 | Y102: MXN | Z102: TN | AA102: D171 | AB102: PD0016 PIEDRAS NEGRAS | AC102: 56103637 | AD102: 6644381540 | AE102: 4 | AF102: ENTREGA DIRECTA | AG102: 1 | AH102: TO | AI102: X | AJ102: 4 | AK102: V4 | AL102: 20250408 | AM102: DW81-900003849-D171-10000624-4
A103: 900003849DW81D17110000572 | B103: 4600050345-90 | C103: 4600050345 | D103: 90 | E103: MXPO | F103: MXL | G103: 900003849 | H103: TC-ED ARTURO MONCADA | I103: 5054193 | J103: MONCADA CANTU ARTURO | K103: N90 | L103: (AP) NAFIN 90 Dias | M103: 10000572 | N103: Arena Triturada Caliza Malla 4 | O103: DW81 | P103: MX-CED. SALTILLO | Q103: 20210801 | R103: 20291231 | S103: 20250301 | T103: 20301231 | U103: 464.92 | V103: MXN | W103: TN | X103: 315.23 | Y103: MXN | Z103: TN | AA103: D171 | AB103: PD0016 PIEDRAS NEGRAS | AC103: 56103638 | AD103: 6644381540 | AE103: 4 | AF103: ENTREGA DIRECTA | AG103: 1 | AH103: TO | AI103: X | AJ103: 4 | AK103: V4 | AL103: 20250408 | AM103: DW81-900003849-D171-10000572-4
... A115: 900007998DW81D14910000572 | B115: 4600068584-60 | C115: 4600068584 | D115: 60 | E115: MXPO | F115: MXL | G115: 900007998 | H115: SF TC-ED-MATERIALES AMEZCUA | I115: 5086022 | J115: MATERIALES RENE AMEZCUA SA DE CV | K115: N90 | L115: (AP) NAFIN 90 Dias | M115: 10000572 | N115: Arena Triturada Caliza Malla 4 | O115: DW81 | P115: MX-CED. SALTILLO | Q115: 20231006 | R115: 20291231 | S115: 20240508 | T115: 20291231 | U115: 548 | V115: MXN | W115: TN | X115: 360 | Y115: MXN | Z115: TN | AA115: D149 | AB115: PD051 ACUÑA | AC115: 56103638 | AD115: 6644381540 | AE115: 4 | AF115: ENTREGA DIRECTA | AG115: 1 | AH115: TO | AI115: X | AJ115: 4 | AK115: V4 | AL115: 20240514 | AM115: DW81-900007998-D149-10000572-4
