Workbook

Sheet Base Cedis DW96
N1: VENTA | Q1: COSTO
A2: CONCAT1 | B2: CONCAT2 | C2: No. SF | D2: Nombre SF | E2: Cedis | F2: Destino | G2: Condicion de Expedicion | H2: Nombre Destino | I2: No. de material | J2: Nombre de material | K2: PV | L2: Inicio de vigencia | M2: Fin de vigencia | N2: Importe MP | O2: Importe Flete | P2: UM Venta | Q2: Importe Costo | R2: UM Costo | S2: Validacion 1 | T2: Validacion 2
A3: =CONCATENATE(C3,E3,F3,I3) | B3: =CONCATENATE(C3,E3,I3) | C3: 900000010 | D3: =IFERROR(VLOOKUP(C3,TRAOPE!$G:$H,2,0),"") | E3: DW96 | F3: D182 | G3: =IFERROR(VLOOKUP(A3,Flete!$A:$E,5,0),"") | H3: =IFERROR(VLOOKUP(F3,TRAOPE!$AA:$AB,2,0),"") | I3: 10000445 | J3: =IFERROR(VLOOKUP(I3,Materiales!$A:$H,8,0),"") | K3: =IFERROR(VLOOKUP(I3,Materiales!$A:$G,7,0),"") | L3: 20210801 | M3: 20250615 | N3: 122.98 | O3: =IFERROR(VLOOKUP(A3,Flete!$A:$J,10,0),"") | P3: TN | Q3: =IFERROR(IFERROR(VLOOKUP(A3,TRAOPE!$A:$U,21,0),VLOOKUP(B3,TRAOPE!$A:$U,21,0)),"") | R3: =IFERROR(IFERROR(VLOOKUP(A3,TRAOPE!$A:$W,23,0),VLOOKUP(B3,TRAOPE!$A:$W,23,0)),"") | S3: =IF(AND(P3="TN",R3="TN"),N3+N(O3),IF(G3&""="1",N(K3)*N3,(N3+N(O3))*N(K3))) | T3: =IF(Q3="","",Q3-S3)
A4: =CONCATENATE(C4,E4,F4,I4) | B4: =CONCATENATE(C4,E4,I4) | C4: 900002648 | D4: =IFERROR(VLOOKUP(C4,TRAOPE!$G:$H,2,0),"") | E4: DW96 | F4: D182 | G4: =IFERROR(VLOOKUP(A4,Flete!$A:$E,5,0),"") | H4: =IFERROR(VLOOKUP(F4,TRAOPE!$AA:$AB,2,0),"") | I4: 10000735 | J4: =IFERROR(VLOOKUP(I4,Materiales!$A:$H,8,0),"") | K4: =IFERROR(VLOOKUP(I4,Materiales!$A:$G,7,0),"") | L4: 20220516 | M4: 99991231 | N4: 175 | O4: =IFERROR(VLOOKUP(A4,Flete!$A:$J,10,0),"") | P4: TN | Q4: =IFERROR(IFERROR(VLOOKUP(A4,TRAOPE!$A:$U,21,0),VLOOKUP(B4,TRAOPE!$A:$U,21,0)),"") | R4: =IFERROR(IFERROR(VLOOKUP(A4,TRAOPE!$A:$W,23,0),VLOOKUP(B4,TRAOPE!$A:$W,23,0)),"") | S4: =IF(AND(P4="TN",R4="TN"),N4+N(O4),IF(G4&""="1",N(K4)*N4,(N4+N(O4))*N(K4))) | T4: =IF(Q4="","",Q4-S4)
A5: =CONCATENATE(C5,E5,F5,I5) | B5: =CONCATENATE(C5,E5,I5) | C5: 900002648 | D5: =IFERROR(VLOOKUP(C5,TRAOPE!$G:$H,2,0),"") | E5: DW96 | F5: D182 | G5: =IFERROR(VLOOKUP(A5,Flete!$A:$E,5,0),"") | H5: =IFERROR(VLOOKUP(F5,TRAOPE!$AA:$AB,2,0),"") | I5: 10087696 | J5: =IFERROR(VLOOKUP(I5,Materiales!$A:$H,8,0),"") | K5: =IFERROR(VLOOKUP(I5,Materiales!$A:$G,7,0),"") | L5: 20220516 | M5: 99991231 | N5: 165 | O5: =IFERROR(VLOOKUP(A5,Flete!$A:$J,10,0),"") | P5: TN | Q5: =IFERROR(IFERROR(VLOOKUP(A5,TRAOPE!$A:$U,21,0),VLOOKUP(B5,TRAOPE!$A:$U,21,0)),"") | R5: =IFERROR(IFERROR(VLOOKUP(A5,TRAOPE!$A:$W,23,0),VLOOKUP(B5,TRAOPE!$A:$W,23,0)),"") | S5: =IF(AND(P5="TN",R5="TN"),N5+N(O5),IF(G5&""="1",N(K5)*N5,(N5+N(O5))*N(K5))) | T5: =IF(Q5="","",Q5-S5)
A6: =CONCATENATE(C6,E6,F6,I6) | B6: =CONCATENATE(C6,E6,I6) | C6: 900002648 | D6: =IFERROR(VLOOKUP(C6,TRAOPE!$G:$H,2,0),"") | E6: DW96 | F6: D182 | G6: =IFERROR(VLOOKUP(A6,Flete!$A:$E,5,0),"") | H6: =IFERROR(VLOOKUP(F6,TRAOPE!$AA:$AB,2,0),"") | I6: 10098596 | J6: =IFERROR(VLOOKUP(I6,Materiales!$A:$H,8,0),"") | K6: =IFERROR(VLOOKUP(I6,Materiales!$A:$G,7,0),"") | L6: 20220516 | M6: 99991231 | N6: 180 | O6: =IFERROR(VLOOKUP(A6,Flete!$A:$J,10,0),"") | P6: TN | Q6: =IFERROR(IFERROR(VLOOKUP(A6,TRAOPE!$A:$U,21,0),VLOOKUP(B6,TRAOPE!$A:$U,21,0)),"") | R6: =IFERROR(IFERROR(VLOOKUP(A6,TRAOPE!$A:$W,23,0),VLOOKUP(B6,TRAOPE!$A:$W,23,0)),"") | S6: =IF(AND(P6="TN",R6="TN"),N6+N(O6),IF(G6&""="1",N(K6)*N6,(N6+N(O6))*N(K6))) | T6: =IF(Q6="","",Q6-S6)
A7: =CONCATENATE(C7,E7,F7,I7) | B7: =CONCATENATE(C7,E7,I7) | C7: 900002648 | D7: =IFERROR(VLOOKUP(C7,TRAOPE!$G:$H,2,0),"") | E7: DW96 | F7: D182 | G7: =IFERROR(VLOOKUP(A7,Flete!$A:$E,5,0),"") | H7: =IFERROR(VLOOKUP(F7,TRAOPE!$AA:$AB,2,0),"") | I7: 10112080 | J7: =IFERROR(VLOOKUP(I7,Materiales!$A:$H,8,0),"") | K7: =IFERROR(VLOOKUP(I7,Materiales!$A:$G,7,0),"") | L7: 20220516 | M7: 99991231 | N7: 170 | O7: =IFERROR(VLOOKUP(A7,Flete!$A:$J,10,0),"") | P7: TN | Q7: =IFERROR(IFERROR(VLOOKUP(A7,TRAOPE!$A:$U,21,0),VLOOKUP(B7,TRAOPE!$A:$U,21,0)),"") | R7: =IFERROR(IFERROR(VLOOKUP(A7,TRAOPE!$A:$W,23,0),VLOOKUP(B7,TRAOPE!$A:$W,23,0)),"") | S7: =IF(AND(P7="TN",R7="TN"),N7+N(O7),IF(G7&""="1",N(K7)*N7,(N7+N(O7))*N(K7))) | T7: =IF(Q7="","",Q7-S7)
A8: =CONCATENATE(C8,E8,F8,I8) | B8: =CONCATENATE(C8,E8,I8) | C8: 900002648 | D8: =IFERROR(VLOOKUP(C8,TRAOPE!$G:$H,2,0),"") | E8: DW96 | F8: DW96 | G8: =IFERROR(VLOOKUP(A8,Flete!$A:$E,5,0),"") | H8: =IFERROR(VLOOKUP(F8,TRAOPE!$AA:$AB,2,0),"") | I8: 10000735 | J8: =IFERROR(VLOOKUP(I8,Materiales!$A:$H,8,0),"") | K8: =IFERROR(VLOOKUP(I8,Materiales!$A:$G,7,0),"") | L8: 20210801 | M8: 20250615 | N8: 156.03 | O8: =IFERROR(VLOOKUP(A8,Flete!$A:$J,10,0),"") | P8: TN | Q8: =IFERROR(IFERROR(VLOOKUP(A8,TRAOPE!$A:$U,21,0),VLOOKUP(B8,TRAOPE!$A:$U,21,0)),"") | R8: =IFERROR(IFERROR(VLOOKUP(A8,TRAOPE!$A:$W,23,0),VLOOKUP(B8,TRAOPE!$A:$W,23,0)),"") | S8: =IF(AND(P8="TN",R8="TN"),N8+N(O8),IF(G8&""="1",N(K8)*N8,(N8+N(O8))*N(K8))) | T8: =IF(Q8="","",Q8-S8)
A9: =CONCATENATE(C9,E9,F9,I9) | B9: =CONCATENATE(C9,E9,I9) | C9: 900002648 | D9: =IFERROR(VLOOKUP(C9,TRAOPE!$G:$H,2,0),"") | E9: DW96 | F9: DW96 | G9: =IFERROR(VLOOKUP(A9,Flete!$A:$E,5,0),"") | H9: =IFERROR(VLOOKUP(F9,TRAOPE!$AA:$AB,2,0),"") | I9: 10087696 | J9: =IFERROR(VLOOKUP(I9,Materiales!$A:$H,8,0),"") | K9: =IFERROR(VLOOKUP(I9,Materiales!$A:$G,7,0),"") | L9: 20210801 | M9: 20250615 | N9: 137.74 | O9: =IFERROR(VLOOKUP(A9,Flete!$A:$J,10,0),"") | P9: TN | Q9: =IFERROR(IFERROR(VLOOKUP(A9,TRAOPE!$A:$U,21,0),VLOOKUP(B9,TRAOPE!$A:$U,21,0)),"") | R9: =IFERROR(IFERROR(VLOOKUP(A9,TRAOPE!$A:$W,23,0),VLOOKUP(B9,TRAOPE!$A:$W,23,0)),"") | S9: =IF(AND(P9="TN",R9="TN"),N9+N(O9),IF(G9&""="1",N(K9)*N9,(N9+N(O9))*N(K9))) | T9: =IF(Q9="","",Q9-S9)
A10: =CONCATENATE(C10,E10,F10,I10) | B10: =CONCATENATE(C10,E10,I10) | C10: 900002648 | D10: =IFERROR(VLOOKUP(C10,TRAOPE!$G:$H,2,0),"") | E10: DW96 | F10: DW96 | G10: =IFERROR(VLOOKUP(A10,Flete!$A:$E,5,0),"") | H10: =IFERROR(VLOOKUP(F10,TRAOPE!$AA:$AB,2,0),"") | I10: 10098596 | J10: =IFERROR(VLOOKUP(I10,Materiales!$A:$H,8,0),"") | K10: =IFERROR(VLOOKUP(I10,Materiales!$A:$G,7,0),"") | L10: 20210801 | M10: 20250615 | N10: 149.6 | O10: =IFERROR(VLOOKUP(A10,Flete!$A:$J,10,0),"") | P10: TN | Q10: =IFERROR(IFERROR(VLOOKUP(A10,TRAOPE!$A:$U,21,0),VLOOKUP(B10,TRAOPE!$A:$U,21,0)),"") | R10: =IFERROR(IFERROR(VLOOKUP(A10,TRAOPE!$A:$W,23,0),VLOOKUP(B10,TRAOPE!$A:$W,23,0)),"") | S10: =IF(AND(P10="TN",R10="TN"),N10+N(O10),IF(G10&""="1",N(K10)*N10,(N10+N(O10))*N(K10))) | T10: =IF(Q10="","",Q10-S10)
A11: =CONCATENATE(C11,E11,F11,I11) | B11: =CONCATENATE(C11,E11,I11) | C11: 900002648 | D11: =IFERROR(VLOOKUP(C11,TRAOPE!$G:$H,2,0),"") | E11: DW96 | F11: DW96 | G11: =IFERROR(VLOOKUP(A11,Flete!$A:$E,5,0),"") | H11: =IFERROR(VLOOKUP(F11,TRAOPE!$AA:$AB,2,0),"") | I11: 10112080 | J11: =IFERROR(VLOOKUP(I11,Materiales!$A:$H,8,0),"") | K11: =IFERROR(VLOOKUP(I11,Materiales!$A:$G,7,0),"") | L11: 20210801 | M11: 20250615 | N11: 154.23 | O11: =IFERROR(VLOOKUP(A11,Flete!$A:$J,10,0),"") | P11: TN | Q11: =IFERROR(IFERROR(VLOOKUP(A11,TRAOPE!$A:$U,21,0),VLOOKUP(B11,TRAOPE!$A:$U,21,0)),"") | R11: =IFERROR(IFERROR(VLOOKUP(A11,TRAOPE!$A:$W,23,0),VLOOKUP(B11,TRAOPE!$A:$W,23,0)),"") | S11: =IF(AND(P11="TN",R11="TN"),N11+N(O11),IF(G11&""="1",N(K11)*N11,(N11+N(O11))*N(K11))) | T11: =IF(Q11="","",Q11-S11)
A12: =CONCATENATE(C12,E12,F12,I12) | B12: =CONCATENATE(C12,E12,I12) | C12: 900004008 | D12: =IFERROR(VLOOKUP(C12,TRAOPE!$G:$H,2,0),"") | E12: DW96 | F12: D182 | G12: =IFERROR(VLOOKUP(A12,Flete!$A:$E,5,0),"") | H12: =IFERROR(VLOOKUP(F12,TRAOPE!$AA:$AB,2,0),"") | I12: 10000480 | J12: =IFERROR(VLOOKUP(I12,Materiales!$A:$H,8,0),"") | K12: =IFERROR(VLOOKUP(I12,Materiales!$A:$G,7,0),"") | L12: 20210801 | M12: 20250615 | N12: 69.98 | O12: =IFERROR(VLOOKUP(A12,Flete!$A:$J,10,0),"") | P12: TN | Q12: =IFERROR(IFERROR(VLOOKUP(A12,TRAOPE!$A:$U,21,0),VLOOKUP(B12,TRAOPE!$A:$U,21,0)),"") | R12: =IFERROR(IFERROR(VLOOKUP(A12,TRAOPE!$A:$W,23,0),VLOOKUP(B12,TRAOPE!$A:$W,23,0)),"") | S12: =IF(AND(P12="TN",R12="TN"),N12+N(O12),IF(G12&""="1",N(K12)*N12,(N12+N(O12))*N(K12))) | T12: =IF(Q12="","",Q12-S12)
A13: =CONCATENATE(C13,E13,F13,I13) | B13: =CONCATENATE(C13,E13,I13) | C13: 900004029 | D13: =IFERROR(VLOOKUP(C13,TRAOPE!$G:$H,2,0),"") | E13: DW96 | F13: D182 | G13: =IFERROR(VLOOKUP(A13,Flete!$A:$E,5,0),"") | H13: =IFERROR(VLOOKUP(F13,TRAOPE!$AA:$AB,2,0),"") | I13: 10000621 | J13: =IFERROR(VLOOKUP(I13,Materiales!$A:$H,8,0),"") | K13: =IFERROR(VLOOKUP(I13,Materiales!$A:$G,7,0),"") | L13: 20220516 | M13: 99991231 | N13: 192.5 | O13: =IFERROR(VLOOKUP(A13,Flete!$A:$J,10,0),"") | P13: TN | Q13: =IFERROR(IFERROR(VLOOKUP(A13,TRAOPE!$A:$U,21,0),VLOOKUP(B13,TRAOPE!$A:$U,21,0)),"") | R13: =IFERROR(IFERROR(VLOOKUP(A13,TRAOPE!$A:$W,23,0),VLOOKUP(B13,TRAOPE!$A:$W,23,0)),"") | S13: =IF(AND(P13="TN",R13="TN"),N13+N(O13),IF(G13&""="1",N(K13)*N13,(N13+N(O13))*N(K13))) | T13: =IF(Q13="","",Q13-S13)
A14: =CONCATENATE(C14,E14,F14,I14) | B14: =CONCATENATE(C14,E14,I14) | C14: 900004029 | D14: =IFERROR(VLOOKUP(C14,TRAOPE!$G:$H,2,0),"") | E14: DW96 | F14: D182 | G14: =IFERROR(VLOOKUP(A14,Flete!$A:$E,5,0),"") | H14: =IFERROR(VLOOKUP(F14,TRAOPE!$AA:$AB,2,0),"") | I14: 10000791 | J14: =IFERROR(VLOOKUP(I14,Materiales!$A:$H,8,0),"") | K14: =IFERROR(VLOOKUP(I14,Materiales!$A:$G,7,0),"") | L14: 20220516 | M14: 99991231 | N14: 130.77 | O14: =IFERROR(VLOOKUP(A14,Flete!$A:$J,10,0),"") | P14: TN | Q14: =IFERROR(IFERROR(VLOOKUP(A14,TRAOPE!$A:$U,21,0),VLOOKUP(B14,TRAOPE!$A:$U,21,0)),"") | R14: =IFERROR(IFERROR(VLOOKUP(A14,TRAOPE!$A:$W,23,0),VLOOKUP(B14,TRAOPE!$A:$W,23,0)),"") | S14: =IF(AND(P14="TN",R14="TN"),N14+N(O14),IF(G14&""="1",N(K14)*N14,(N14+N(O14))*N(K14))) | T14: =IF(Q14="","",Q14-S14)
... A43: =CONCATENATE(C43,E43,F43,I43) | B43: =CONCATENATE(C43,E43,I43) | C43: 900008156 | D43: =IFERROR(VLOOKUP(C43,TRAOPE!$G:$H,2,0),"") | E43: DW96 | F43: D182 | G43: =IFERROR(VLOOKUP(A43,Flete!$A:$E,5,0),"") | H43: =IFERROR(VLOOKUP(F43,TRAOPE!$AA:$AB,2,0),"") | I43: 10257608 | J43: =IFERROR(VLOOKUP(I43,Materiales!$A:$H,8,0),"") | K43: =IFERROR(VLOOKUP(I43,Materiales!$A:$G,7,0),"") | L43: 20240604 | M43: 99991231 | N43: 149.97 | O43: =IFERROR(VLOOKUP(A43,Flete!$A:$J,10,0),"") | P43: TN | Q43: =IFERROR(IFERROR(VLOOKUP(A43,TRAOPE!$A:$U,21,0),VLOOKUP(B43,TRAOPE!$A:$U,21,0)),"") | R43: =IFERROR(IFERROR(VLOOKUP(A43,TRAOPE!$A:$W,23,0),VLOOKUP(B43,TRAOPE!$A:$W,23,0)),"") | S43: =IF(AND(P43="TN",R43="TN"),N43+N(O43),IF(G43&""="1",N(K43)*N43,(N43+N(O43))*N(K43))) | T43: =IF(Q43="","",Q43-S43)

Sheet MP
A1: No. SF | B1: Cedis | C1: Destino | D1: No. Material | E1: Nombre Material | F1: Importe MP | G1: Moneda | H1: Cantidad | I1: UM | J1: C | K1: Inicio Vigencia | L1: Fin Vigencia
A2: 900000010 | B2: DW96 | C2: D182 | D2: 10000445 | F2: 122.98 | I2: TN | K2: 20210801 | L2: 20250615
A3: 900002648 | B3: DW96 | C3: D182 | D3: 10000735 | F3: 175 | I3: TN | K3: 20220516 | L3: 99991231
A4: 900002648 | B4: DW96 | C4: D182 | D4: 10087696 | F4: 165 | I4: TN | K4: 20220516 | L4: 99991231
A5: 900002648 | B5: DW96 | C5: D182 | D5: 10098596 | F5: 180 | I5: TN | K5: 20220516 | L5: 99991231
A6: 900002648 | B6: DW96 | C6: D182 | D6: 10112080 | F6: 170 | I6: TN | K6: 20220516 | L6: 99991231
A7: 900002648 | B7: DW96 | C7: DW96 | D7: 10000735 | F7: 156.03 | I7: TN | K7: 20210801 | L7: 20250615
A8: 900002648 | B8: DW96 | C8: DW96 | D8: 10087696 | F8: 137.74 | I8: TN | K8: 20210801 | L8: 20250615
A9: 900002648 | B9: DW96 | C9: DW96 | D9: 10098596 | F9: 149.6 | I9: TN | K9: 20210801 | L9: 20250615
A10: 900002648 | B10: DW96 | C10: DW96 | D10: 10112080 | F10: 154.23 | I10: TN | K10: 20210801 | L10: 20250615
A11: 900004008 | B11: DW96 | C11: D182 | D11: 10000480 | F11: 69.98 | I11: TN | K11: 20210801 | L11: 20250615
A12: 900004029 | B12: DW96 | C12: D182 | D12: 10000621 | F12: 192.5 | I12: TN | K12: 20220516 | L12: 99991231
A13: 900004029 | B13: DW96 | C13: D182 | D13: 10000791 | F13: 130.77 | I13: TN | K13: 20220516 | L13: 99991231
... A42: 900008156 | B42: DW96 | C42: D182 | D42: 10257608 | F42: 149.97 | I42: TN | K42: 20240604 | L42: 99991231

Sheet Flete
A1: Concat1 | B1: No. SF | C1: Cedis | D1: Destino | E1: Cond. Exp. | F1: Material | H1: Nombre Material | J1: Importe Flete | K1: Moneda | L1: Cantidad | M1: UM | N1: C | P1: Inicio Vigencia | Q1: Fin Vigencia
A2: 900000010DW96D18210000445 | B2: 900000010 | C2: DW96 | D2: D182 | E2: 4 | F2: 10000445 | J2: 148.87 | M2: TN | P2: 20210801 | Q2: 20250615
A3: 900002648DW96D18210000735 | B3: 900002648 | C3: DW96 | D3: D182 | E3: 1 | F3: 10000735 | J3: 88.28 | M3: TN | P3: 20210801 | Q3: 20250615
A4: 900002648DW96D18210087696 | B4: 900002648 | C4: DW96 | D4: D182 | E4: 1 | F4: 10087696 | J4: 76.82 | M4: TN | P4: 20210801 | Q4: 20250615
A5: 900002648DW96D18210098596 | B5: 900002648 | C5: DW96 | D5: D182 | E5: 1 | F5: 10098596 | J5: 64.09 | M5: TN | P5: 20210801 | Q5: 20250615
A6: 900002648DW96D18210112080 | B6: 900002648 | C6: DW96 | D6: D182 | E6: 1 | F6: 10112080 | J6: 78.84 | M6: TN | P6: 20210801 | Q6: 20250615
A7: 900004008DW96D18210000480 | B7: 900004008 | C7: DW96 | D7: D182 | E7: 4 | F7: 10000480 | J7: 53.42 | M7: TN | P7: 20210801 | Q7: 20250615
A8: 900004029DW96D18210000621 | B8: 900004029 | C8: DW96 | D8: D182 | E8: 1 | F8: 10000621 | J8: 50 | M8: TN | P8: 20210801 | Q8: 20250615
A9: 900004029DW96D18210000791 | B9: 900004029 | C9: DW96 | D9: D182 | E9: 1 | F9: 10000791 | J9: 50 | M9: TN | P9: 20210801 | Q9: 20250615
A10: 900004029DW96D18210065029 | B10: 900004029 | C10: DW96 | D10: D182 | E10: 1 | F10: 10065029 | J10: 50 | M10: TN | P10: 20210801 | Q10: 20250615
A11: 900004029DW96D18210112090 | B11: 900004029 | C11: DW96 | D11: D182 | E11: 1 | F11: 10112090 | J11: 50 | M11: TN | P11: 20210801 | Q11: 20250615
A12: 900004032DW96D18210000735 | B12: 900004032 | C12: DW96 | D12: D182 | E12: 4 | F12: 10000735 | J12: 106.38 | M12: TN | P12: 20210801 | Q12: 20250615
A13: 900004032DW96D18210087696 | B13: 900004032 | C13: DW96 | D13: D182 | E13: 4 | F13: 10087696 | J13: 103.31 | M13: TN | P13: 20210801 | Q13: 20250615
... A38: 900008156DW96D18210257608 | B38: 900008156 | C38: DW96 | D38: D182 | E38: 4 | F38: 10257608 | J38: 57.94 | M38: TN | P38: 20240604 | Q38: 99991231

Sheet Materiales
A1: Material | B1: TpMt | C1: Denom | D1: UMA | E1: Contador | F1: UMB | G1: PV | H1: Nombre Material
A2: 10000001 | B2: ZFER | C2: 1000 | D2: M3 | E2: 1000 | F2: TN | G2: 1262 | H2: GRAVA ANDESITA 10 MM (3/8")
A3: 10000003 | B3: ZFER | C3: 1000 | D3: M3 | E3: 1000 | F3: TN | G3: 1443 | H3: GRAVA CALIZA 10 MM (3/8")
A4: 10000006 | B4: ZFER | C4: 1000 | D4: M3 | E4: 1000 | F4: TN | G4: 1490 | H4: GRAVA RIO 10 MM (3/8")
A5: 10000007 | B5: ZFER | C5: 1000 | D5: M3 | E5: 1000 | F5: TN | G5: 1488 | H5: GRAVA BASALTO 13 MM (1/2")
A6: 10000008 | B6: ZFER | C6: 1000 | D6: M3 | E6: 1000 | F6: TN | G6: 1358 | H6: GRAVA CALIZA 13 MM (1/2")
A7: 10000011 | B7: ZFER | C7: 1000 | D7: M3 | E7: 1000 | F7: TN | G7: 1323 | H7: GRAVA ANDESITA 20 MM (3/4")
A8: 10000013 | B8: ZFER | C8: 1000 | D8: M3 | E8: 1000 | F8: TN | G8: 1514 | H8: GRAVA BASALTO 20 MM (3/4")
A9: 10000014 | B9: ZFER | C9: 1000 | D9: M3 | E9: 1000 | F9: TN | G9: 1400 | H9: GRAVA CALIZA 20 MM (3/4")
A10: 10000015 | B10: ZFER | C10: 1000 | D10: M3 | E10: 1000 | F10: TN | G10: 1410 | H10: GRAVA GRANITO 20 MM (3/4")
A11: 10000017 | B11: ZFER | C11: 1000 | D11: M3 | E11: 1000 | F11: TN | G11: 1475 | H11: GRAVA RIOLITA 20 MM (3/4")
A12: 10000019 | B12: ZFER | C12: 1000 | D12: M3 | E12: 1000 | F12: TN | G12: 1515 | H12: GRAVA RIO 20 MM (3/4")
A13: 10000020 | B13: ZFER | C13: 1000 | D13: M3 | E13: 1 | F13: TN | G13: 1 | H13: GRAVA MAQUILA 40MM (1 1/2")
... A2291: 10268770 | B2291: ZFE3 | C2291: 1000 | D2291: M3 | E2291: 1000 | F2291: TN | G2291: 1240 | H2291: MP GRAVA TRIT CALIZA 40MM 1 1/2" - ESP
A2292: 10268901 | B2292: ZFE3 | C2292: 1000 | D2292: M3 | E2292: 1000 | G2292: 1560 | H2292: MP GRAVA ANDESITA GRIS 3/4" - CAPADA
A2293: 10267983 | C2293: 1000 | G2293: 1800 | H2293: ESCORIA ALTO HORNO 3/4
A2294: 10268996 | C2294: 1000 | G2294: 1329 | H2294: GRAVA TRITURADA CALIZA 40 MM - 11/2"
A2295: 10269072 | C2295: 1000 | G2295: 1700 | H2295: BASE HIDRÁULICA SCREEN
A2296: 10269225 | B2296: ZFE3 | C2296: 1000 | D2296: M3 | E2296: 1000 | G2296: 1289 | H2296: MP ARENA CALIZA LAVADA MALLA 4 - DELTA I
A2297: 10269245 | B2297: ZFE3 | C2297: 1000 | D2297: M3 | E2297: 1000 | G2297: 1410 | H2297: MP GRAVA TRITURADA CALIZA 3/8 - 10MM
A2298: 10269246 | B2298: ZFE3 | C2298: 1000 | D2298: M3 | E2298: 1000 | G2298: 1400 | H2298: MP GRAVA TRITURADA CALIZA 1 1/2 - 40MM
A2299: 10269247 | B2299: ZFE3 | C2299: 1000 | D2299: M3 | E2299: 1000 | G2299: 1560 | H2299: MP ARENA TRIT CALIZA M-4
A2300: 10270431 | B2300: ZFE3 | C2300: 1000 | D2300: M3 | E2300: 1000 | G2300: 1423 | H2300: MP GRAVA RIOLITA 13 MM - 1/2"
A2301: 10270898 | B2301: ZFE3 | C2301: 1000 | D2301: M3 | E2301: 1000 | G2301: 1551 | H2301: MP BASE H. TRIT. BASALTO 1 1/2" A FINOS
A2302: 10270911 | B2302: ZFE3 | C2302: 1000 | D2302: M3 | E2302: 1000 | G2302: 1360 | H2302: MP GRAVA TRIT. BASALTO 40 MM - 1 1/2"
A2303: 10270912 | B2303: ZFE3 | C2303: 1000 | D2303: M3 | E2303: 1000 | G2303: 1589 | H2303: MP ARENA TRIT. BASALTO MALLA 4
A2304: 10270913 | B2304: ZFE3 | C2304: 1000 | D2304: M3 | E2304: 1000 | G2304: 1395 | H2304: MP GRAVA TRIT. BASALTO 20 MM - 3/4
A2305: 10270914 | B2305: ZFE3 | C2305: 1000 | D2305: M3 | E2305: 1000 | G2305: 1623 | H2305: MP ARENA ANDESITA BC
A2306: 10270824 | B2306: M3 | C2306: 1000 | D2306: M3 | E2306: 10007640 | G2306: 1325 | H2306: MP ARENA TRITURADA CALIZA MALLA 5
A2307: 10270825 | B2307: M3 | C2307: 1000 | D2307: M3 | E2307: 10000003 | G2307: 1242 | H2307: MP GRAVA TRITURADA CALIZA 10MM (3/8”)
... A2319: 10272527 | B2319: ZFE3 | C2319: 1000 | D2319: M3 | E2319: 1000 | G2319: 1620 | H2319: CNC - NO CLASIFICADO
A2320: 10000332 | C2320: 1000 | D2320: M3 | E2320: 1000 | G2320: 800 | H2320: Grava Triturada Pomez - Jal 20 mm - 3/4"
A2321: 10273001 | B2321: ZFE3 | C2321: 1000 | D2321: M3 | E2321: 1000 | G2321: 1688 | H2321: MP ARENA TRIT. BASALTO MALLA 4
A2322: 10273002 | B2322: ZFE3 | C2322: 1000 | D2322: M3 | E2322: 1000 | G2322: 1466 | H2322: MP GRAVA TRIT. BASALTO 20 MM - 3/4"
A2323: 10273351 | B2323: ZFE3 | C2323: 1000 | D2323: M3 | E2323: 1000 | G2323: 1612 | H2323: MP ARENA TRIT. CALIZA MALLA 4
A2324: 10273352 | B2324: ZFE3 | C2324: 1000 | D2324: M3 | E2324: 1000 | G2324: 1492 | H2324: MP GRAVA TRIT. CALIZA 20 MM - 3/4"
A2325: 10271724 | B2325: ZFE3 | C2325: 1000 | D2325: M3 | E2325: 1000 | G2325: 1900 | H2325: MP RESIDUO DE CONCRETO
A2326: 10000677 | C2326: 1000 | D2326: M3 | G2326: 1164 | H2326: Grava Triturada Caliza 20 mm - 3/4"
A2327: 10274190 | B2327: ZFE3 | C2327: 1000 | D2327: M3 | E2327: 1000 | G2327: 1800 | H2327: MP BASE HIDRAULICA ANDESITA 70-30
A2328: 10274601 | B2328: ZFE3 | C2328: 1000 | D2328: M3 | E2328: 1000 | G2328: 1447 | H2328: MP ARENA BASALTO N° 4
...

Sheet TRAOPE
A1: Concat1 | B1: Contrato_Pos | C1: Doc. Compras | D1: Pos | E1: Org.compras | F1: Grp-Compr. | G1: Ship From | H1: Nombre SF | I1: Proveedor | J1: Nombre Prov | K1: Cond. Pago | L1: Descr. Cond Pago | M1: Material | N1: Descripción | O1: Centro | P1: Descripción Centro | Q1: In.perído validez | R1: Fin perído validez | S1: Válido de | T1: Validez a | U1: Precio neto pedido | V1: Moneda | W1: UM Precio Pedido | X1: Importe Condición | Y1: Moneda KONP | Z1: UM Ctd Base | AA1: Destino | AB1: Nombre Destino | AC1: Cuenta de mayor | AD1: Centro de costo | AE1: Cond. Exp. | AF1: Descr. Cond. Exp. | AG1: Peso Vol. | AH1: UMB | AI1: Ind. Oblig. Conf. Ped. | AJ1: Ctrl-Conf. | AK1: IVA | AL1: Modif_Date | AM1: Ruta
A2: 900007067DW96D18210171645 | B2: 4600050767-30 | C2: 4600050767 | D2: 30 | E2: MXPO | F2: MXL | G2: 900007067 | H2: SF TC-ED- VIA TERRA | I2: 5076224 | J2: OBRAS Y CONCRETOS DE LA VIA TERRA | K2: N90 | L2: (AP) NAFIN 90 Dias | M2: 10171645 | N2: GRAVA TRITURADA CALIZA 40 MM - 1 1/2" | O2: DW96 | P2: MX-CEDIS ZACATECAS | Q2: 20210712 | R2: 20261231 | S2: 20210712 | T2: 20261231 | U2: 271.24 | V2: MXN | W2: M3 | X2: 110 | Y2: MXN | Z2: M3 | AA2: D182 | AB2: PD0544 ZACATECAS PLANTA 1 | AC2: 56103637 | AD2: 6644901540 | AE2: 4 | AF2: ENTREGA DIRECTA | AG2: 1.362 | AH2: M3 | AI2: X | AJ2: 4 | AK2: V4 | AL2: 20260108 | AM2: DW96-900007067-D182-10171645-4
A3: 900007067DW96D18210172329 | B3: 4600050767-10 | C3: 4600050767 | D3: 10 | E3: MXPO | F3: MXL | G3: 900007067 | H3: SF TC-ED- VIA TERRA | I3: 5076224 | J3: OBRAS Y CONCRETOS DE LA VIA TERRA | K3: N90 | L3: (AP) NAFIN 90 Dias | M3: 10172329 | N3: ARENA TRITURADA CALIZA MALLA 4 | O3: DW96 | P3: MX-CEDIS ZACATECAS | Q3: 20210712 | R3: 20261231 | S3: 20210712 | T3: 20261231 | U3: 276.07 | V3: MXN | W3: M3 | X3: 110 | Y3: MXN | Z3: M3 | AA3: D182 | AB3: PD0544 ZACATECAS PLANTA 1 | AC3: 56103638 | AD3: 6644901540 | AE3: 4 | AF3: ENTREGA DIRECTA | AG3: 1.615 | AH3: M3 | AI3: X | AJ3: 4 | AK3: V4 | AL3: 20260108 | AM3: DW96-900007067-D182-10172329-4
A4: 900007067DW96D18210171646 | B4: 4600050767-40 | C4: 4600050767 | D4: 40 | E4: MXPO | F4: MXL | G4: 900007067 | H4: SF TC-ED- VIA TERRA | I4: 5076224 | J4: OBRAS Y CONCRETOS DE LA VIA TERRA | K4: N90 | L4: (AP) NAFIN 90 Dias | M4: 10171646 | N4: GRAVA TRITURADA CALIZA 10 MM - 3/8" | O4: DW96 | P4: MX-CEDIS ZACATECAS | Q4: 20210712 | R4: 20261231 | S4: 20210712 | T4: 20261231 | U4: 280.91 | V4: MXN | W4: M3 | X4: 110 | Y4: MXN | Z4: M3 | AA4: D182 | AB4: PD0544 ZACATECAS PLANTA 1 | AC4: 56103637 | AD4: 6644901540 | AE4: 4 | AF4: ENTREGA DIRECTA | AG4: 1.473 | AH4: M3 | AI4: X | AJ4: 4 | AK4: V4 | AL4: 20260108 | AM4: DW96-900007067-D182-10171646-4
A5: 900007067DW96D18210172330 | B5: 4600050767-20 | C5: 4600050767 | D5: 20 | E5: MXPO | F5: MXL | G5: 900007067 | H5: SF TC-ED- VIA TERRA | I5: 5076224 | J5: OBRAS Y CONCRETOS DE LA VIA TERRA | K5: N90 | L5: (AP) NAFIN 90 Dias | M5: 10172330 | N5: GRAVA TRITURADA CALIZA 20 MM - 3/4" | O5: DW96 | P5: MX-CEDIS ZACATECAS | Q5: 20210712 | R5: 20261231 | S5: 20210712 | T5: 20261231 | U5: 271.24 | V5: MXN | W5: M3 | X5: 110 | Y5: MXN | Z5: M3 | AA5: D182 | AB5: PD0544 ZACATECAS PLANTA 1 | AC5: 56103637 | AD5: 6644901540 | AE5: 4 | AF5: ENTREGA DIRECTA | AG5: 1.335 | AH5: M3 | AI5: X | AJ5: 4 | AK5: V4 | AL5: 20260108 | AM5: DW96-900007067-D182-10172330-4
A6: 900006280DW9610171646 | B6: 4600050755-40 | C6: 4600050755 | D6: 40 | E6: MXPO | F6: MXL | G6: 900006280 | H6: SF TC- VIA TERRA | I6: 5076224 | J6: OBRAS Y CONCRETOS DE LA VIA TERRA | K6: Z09 | L6: (AP) 90 Dias | M6: 10171646 | N6: GRAVA TRITURADA CALIZA 10 MM - 3/8" | O6: DW96 | P6: MX-CEDIS ZACATECAS | Q6: 20210712 | R6: 20271231 | S6: 20220401 | T6: 20271231 | U6: 186.29 | V6: MXN | W6: M3 | X6: 0 | Y6: MXN | Z6: M3 | AC6: 56103637 | AD6: 6644901540 | AE6: 1 | AF6: ENTREGADO | AG6: 1.473 | AH6: M3 | AI6: X | AJ6: 4 | AK6: V4 | AL6: 20230920 | AM6: DW96-900006280-10171646
A7: 900006280DW9610172329 | B7: 4600050755-10 | C7: 4600050755 | D7: 10 | E7: MXPO | F7: MXL | G7: 900006280 | H7: SF TC- VIA TERRA | I7: 5076224 | J7: OBRAS Y CONCRETOS DE LA VIA TERRA | K7: Z09 | L7: (AP) 90 Dias | M7: 10172329 | N7: ARENA TRITURADA CALIZA MALLA 4 | O7: DW96 | P7: MX-CEDIS ZACATECAS | Q7: 20210712 | R7: 20271231 | S7: 20220401 | T7: 20271231 | U7: 181.02 | V7: MXN | W7: M3 | X7: 0 | Y7: MXN | Z7: M3 | AC7: 56103638 | AD7: 6644901540 | AE7: 1 | AF7: ENTREGADO | AG7: 1.615 | AH7: M3 | AI7: X | AJ7: 4 | AK7: V4 | AL7: 20230920 | AM7: DW96-900006280-10172329
A8: 900006280DW9610172330 | B8: 4600050755-20 | C8: 4600050755 | D8: 20 | E8: MXPO | F8: MXL | G8: 900006280 | H8: SF TC- VIA TERRA | I8: 5076224 | J8: OBRAS Y CONCRETOS DE LA VIA TERRA | K8: Z09 | L8: (AP) 90 Dias | M8: 10172330 | N8: GRAVA TRITURADA CALIZA 20 MM - 3/4" | O8: DW96 | P8: MX-CEDIS ZACATECAS | Q8: 20210712 | R8: 20271231 | S8: 20220401 | T8: 20271231 | U8: 175.75 | V8: MXN | W8: M3 | X8: 0 | Y8: MXN | Z8: M3 | AC8: 56103637 | AD8: 6644901540 | AE8: 1 | AF8: ENTREGADO | AG8: 1.335 | AH8: M3 | AI8: X | AJ8: 4 | AK8: V4 | AL8: 20230920 | AM8: DW96-900006280-10172330
A9: 900002648DW9610087696 | B9: 4600051524-20 | C9: 4600051524 | D9: 20 | E9: MXPO | F9: MXL | G9: 900002648 | H9: TC-LA CALERA | I9: 5045145 | J9: TRITURADOS LA CALERA,SA DE CV | K9: Z06 | L9: (AP) 45 Dias | M9: 10087696 | N9: GRAVA TRITURADA CALIZA 40 MM - 1 1/2" | O9: DW96 | P9: MX-CEDIS ZACATECAS | Q9: 20210712 | R9: 20281231 | S9: 20230201 | T9: 20281231 | U9: 200 | V9: MXN | W9: M3 | X9: 0 | Y9: MXN | Z9: M3 | AC9: 56103637 | AD9: 6644901540 | AE9: 1 | AF9: ENTREGADO | AG9: 1.452 | AH9: M3 | AI9: X | AJ9: 4 | AK9: V4 | AL9: 20230920 | AM9: DW96-900002648-10087696
A10: 900002648DW9610112080 | B10: 4600051524-40 | C10: 4600051524 | D10: 40 | E10: MXPO | F10: MXL | G10: 900002648 | H10: TC-LA CALERA | I10: 5045145 | J10: TRITURADOS LA CALERA,SA DE CV | K10: Z06 | L10: (AP) 45 Dias | M10: 10112080 | N10: GRAVA TRITURADA CALIZA 20 MM - 3/4" | O10: DW96 | P10: MX-CEDIS ZACATECAS | Q10: 20210712 | R10: 20281231 | S10: 20230201 | T10: 20281231 | U10: 215 | V10: MXN | W10: M3 | X10: 0 | Y10: MXN | Z10: M3 | AC10: 56103637 | AD10: 6644901540 | AE10: 1 | AF10: ENTREGADO | AG10: 1.394 | AH10: M3 | AI10: X | AJ10: 4 | AK10: V4 | AL10: 20230920 | AM10: DW96-900002648-10112080
A11: 900006280DW9610171645 | B11: 4600050755-30 | C11: 4600050755 | D11: 30 | E11: MXPO | F11: MXL | G11: 900006280 | H11: SF TC- VIA TERRA | I11: 5076224 | J11: OBRAS Y CONCRETOS DE LA VIA TERRA | K11: Z09 | L11: (AP) 90 Dias | M11: 10171645 | N11: GRAVA TRITURADA CALIZA 40 MM - 1 1/2" | O11: DW96 | P11: MX-CEDIS ZACATECAS | Q11: 20210712 | R11: 20271231 | S11: 20220401 | T11: 20271231 | U11: 175.75 | V11: MXN | W11: M3 | X11: 0 | Y11: MXN | Z11: M3 | AC11: 56103637 | AD11: 6644901540 | AE11: 1 | AF11: ENTREGADO | AG11: 1.362 | AH11: M3 | AI11: X | AJ11: 4 | AK11: V4 | AL11: 20230920 | AM11: DW96-900006280-10171645
A12: 900002648DW9610000735 | B12: 4600051524-10 | C12: 4600051524 | D12: 10 | E12: MXPO | F12: MXL | G12: 900002648 | H12: TC-LA CALERA | I12: 5045145 | J12: TRITURADOS LA CALERA,SA DE CV | K12: Z06 | L12: (AP) 45 Dias | M12: 10000735 | N12: Grava Triturada Caliza 10 mm - 3/8" | O12: DW96 | P12: MX-CEDIS ZACATECAS | Q12: 20210712 | R12: 20281231 | S12: 20230201 | T12: 20281231 | U12: 220 | V12: MXN | W12: M3 | X12: 0 | Y12: MXN | Z12: M3 | AC12: 56103637 | AD12: 6644901540 | AE12: 1 | AF12: ENTREGADO | AG12: 1.41 | AH12: M3 | AI12: X | AJ12: 4 | AK12: V4 | AL12: 20230920 | AM12: DW96-900002648-10000735
A13: 900002648DW9610098596 | B13: 4600051524-30 | C13: 4600051524 | D13: 30 | E13: MXPO | F13: MXL | G13: 900002648 | H13: TC-LA CALERA | I13: 5045145 | J13: TRITURADOS LA CALERA,SA DE CV | K13: Z06 | L13: (AP) 45 Dias | M13: 10098596 | N13: ARENA TRITURADA CALIZA MALLA 4 | O13: DW96 | P13: MX-CEDIS ZACATECAS | Q13: 20210712 | R13: 20281231 | S13: 20230201 | T13: 20281231 | U13: 225 | V13: MXN | W13: M3 | X13: 0 | Y13: MXN | Z13: M3 | AC13: 56103638 | AD13: 6644901540 | AE13: 1 | AF13: ENTREGADO | AG13: 1.504 | AH13: M3 | AI13: X | AJ13: 4 | AK13: V4 | AL13: 20230920 | AM13: DW96-900002648-10098596
A14: 900008156DW96D18210232717 | B14: 4600057298-10 | C14: 4600057298 | D14: 10 | E14: MXPO | F14: MXL | G14: 900008156 | H14: SF TC- ED- PETRA | I14: 5088776 | J14: PETREOS Y TRITURADOS DEL CENTRO LR | K14: N90 | L14: (AP) NAFIN 90 Dias | M14: 10232717 | N14: ARENA TRITURADA CALIZA MALLA 4 | O14: DW96 | P14: MX-CEDIS ZACATECAS | Q14: 20230417 | R14: 20281231 | S14: 20230417 | T14: 20281231 | U14: 309 | V14: MXN | W14: M3 | X14: 84 | Y14: MXN | Z14: M3 | AA14: D182 | AB14: PD0544 ZACATECAS PLANTA 1 | AC14: 56103638 | AD14: 6644901540 | AE14: 4 | AF14: ENTREGA DIRECTA | AG14: 1.609 | AH14: M3 | AI14: X | AJ14: 4 | AK14: V4 | AL14: 20230920 | AM14: DW96-900008156-D182-10232717-4
A15: 900008156DW96D18210233331 | B15: 4600057298-20 | C15: 4600057298 | D15: 20 | E15: MXPO | F15: MXL | G15: 900008156 | H15: SF TC- ED- PETRA | I15: 5088776 | J15: PETREOS Y TRITURADOS DEL CENTRO LR | K15: N90 | L15: (AP) NAFIN 90 Dias | M15: 10233331 | N15: GRAVA TRITURADA CALIZA 20 MM - 3/4" P | O15: DW96 | P15: MX-CEDIS ZACATECAS | Q15: 20230417 | R15: 20281231 | S15: 20230425 | T15: 20281231 | U15: 299 | V15: MXN | W15: M3 | X15: 84 | Y15: MXN | Z15: M3 | AA15: D182 | AB15: PD0544 ZACATECAS PLANTA 1 | AC15: 56103637 | AD15: 6644901540 | AE15: 4 | AF15: ENTREGA DIRECTA | AG15: 1.444 | AH15: M3 | AI15: X | AJ15: 4 | AK15: V4 | AL15: 20230920 | AM15: DW96-900008156-D182-10233331-4
A16: 900008156DW96D18210233332 | B16: 4600057298-30 | C16: 4600057298 | D16: 30 | E16: MXPO | F16: MXL | G16: 900008156 | H16: SF TC- ED- PETRA | I16: 5088776 | J16: PETREOS Y TRITURADOS DEL CENTRO LR | K16: N90 | L16: (AP) NAFIN 90 Dias | M16: 10233332 | N16: GRAVA TRITURADA CALIZA 40 MM - 1 1/2" P | O16: DW96 | P16: MX-CEDIS ZACATECAS | Q16: 20230417 | R16: 20281231 | S16: 20230425 | T16: 20281231 | U16: 284 | V16: MXN | W16: M3 | X16: 84 | Y16: MXN | Z16: M3 | AA16: D182 | AB16: PD0544 ZACATECAS PLANTA 1 | AC16: 56103637 | AD16: 6644901540 | AE16: 4 | AF16: ENTREGA DIRECTA | AG16: 1.472 | AH16: M3 | AI16: X | AJ16: 4 | AK16: V4 | AL16: 20230920 | AM16: DW96-900008156-D182-10233332-4
A17: 900008156DW96D18210257608 | B17: 4600057298-40 | C17: 4600057298 | D17: 40 | E17: MXPO | F17: MXL | G17: 900008156 | H17: SF TC- ED- PETRA | I17: 5088776 | J17: PETREOS Y TRITURADOS DEL CENTRO LR | K17: N90 | L17: (AP) NAFIN 90 Dias | M17: 10257608 | N17: GRAVA TRITURADA CALIZA 10 MM - 3/8" | O17: DW96 | P17: MX-CEDIS ZACATECAS | Q17: 20230417 | R17: 20281231 | S17: 20240604 | T17: 20291231 | U17: 305 | V17: MXN | W17: M3 | X17: 85 | Y17: MXN | Z17: M3 | AA17: D182 | AB17: PD0544 ZACATECAS PLANTA 1 | AC17: 56103637 | AD17: 6644901540 | AE17: 4 | AF17: ENTREGA DIRECTA | AG17: 1.467 | AH17: M3 | AI17: X | AJ17: 4 | AK17: V4 | AL17: 20240611 | AM17: DW96-900008156-D182-10257608-4
A18: 900008155DW9610257608 | B18: 4600057297-40 | C18: 4600057297 | D18: 40 | E18: MXPO | F18: MXL | G18: 900008155 | H18: SF TC- PETRA | I18: 5088776 | J18: PETREOS Y TRITURADOS DEL CENTRO LR | K18: N90 | L18: (AP) NAFIN 90 Dias | M18: 10257608 | N18: GRAVA TRITURADA CALIZA 10 MM - 3/8" | O18: DW96 | P18: MX-CEDIS ZACATECAS | Q18: 20230417 | R18: 20281231 | S18: 20240625 | T18: 20291231 | U18: 220 | V18: MXN | W18: M3 | X18: 0 | Y18: MXN | Z18: M3 | AC18: 56103637 | AD18: 6644901540 | AE18: 1 | AF18: ENTREGADO | AG18: 1.467 | AH18: M3 | AI18: X | AJ18: 4 | AK18: V4 | AL18: 20240627 | AM18: DW96-900008155-10257608
A19: 900004029DW9610112090 | B19: 4600050723-40 | C19: 4600050723 | D19: 40 | E19: MXPO | F19: MXL | G19: 900004029 | H19: TC-MEXICANA DE CALES | I19: 5001279 | J19: MEXICANA DE CALES SA DE CV | K19: Z03 | L19: (AP) 15 Dias | M19: 10112090 | N19: GRAVA TRITURADA CALIZA 20 MM - 3/4" | O19: DW96 | P19: MX-CEDIS ZACATECAS | Q19: 20210712 | R19: 20261231 | S19: 20210712 | T19: 20261231 | U19: 133.98 | V19: MXN | W19: M3 | X19: 0 | Y19: MXN | Z19: M3 | AC19: 56103637 | AD19: 6644901540 | AE19: 1 | AF19: ENTREGADO | AG19: 1.389 | AH19: M3 | AI19: X | AJ19: 4 | AK19: V4 | AL19: 20260108 | AM19: DW96-900004029-10112090
A20: 900008155DW9610233331 | B20: 4600057297-20 | C20: 4600057297 | D20: 20 | E20: MXPO | F20: MXL | G20: 900008155 | H20: SF TC- PETRA | I20: 5088776 | J20: PETREOS Y TRITURADOS DEL CENTRO LR | K20: N90 | L20: (AP) NAFIN 90 Dias | M20: 10233331 | N20: GRAVA TRITURADA CALIZA 20 MM - 3/4" P | O20: DW96 | P20: MX-CEDIS ZACATECAS | Q20: 20230417 | R20: 20281231 | S20: 20230425 | T20: 20281231 | U20: 215 | V20: MXN | W20: M3 | X20: 0 | Y20: MXN | Z20: M3 | AC20: 56103637 | AD20: 6644901540 | AE20: 1 | AF20: ENTREGADO | AG20: 1.444 | AH20: M3 | AI20: X | AJ20: 4 | AK20: V4 | AL20: 20230920 | AM20: DW96-900008155-10233331
A21: 900004029DW9610065029 | B21: 4600050723-30 | C21: 4600050723 | D21: 30 | E21: MXPO | F21: MXL | G21: 900004029 | H21: TC-MEXICANA DE CALES | I21: 5001279 | J21: MEXICANA DE CALES SA DE CV | K21: Z03 | L21: (AP) 15 Dias | M21: 10065029 | N21: GRAVA TRITURADA CALIZA 10 MM - 3/8" | O21: DW96 | P21: MX-CEDIS ZACATECAS | Q21: 20210712 | R21: 20261231 | S21: 20210712 | T21: 20261231 | U21: 145 | V21: MXN | W21: M3 | X21: 0 | Y21: MXN | Z21: M3 | AC21: 56103637 | AD21: 6644901540 | AE21: 1 | AF21: ENTREGADO | AG21: 1.479 | AH21: M3 | AI21: X | AJ21: 4 | AK21: V4 | AL21: 20260108 | AM21: DW96-900004029-10065029
A22: 900004029DW9610000621 | B22: 4600050723-10 | C22: 4600050723 | D22: 10 | E22: MXPO | F22: MXL | G22: 900004029 | H22: TC-MEXICANA DE CALES | I22: 5001279 | J22: MEXICANA DE CALES SA DE CV | K22: Z03 | L22: (AP) 15 Dias | M22: 10000621 | N22: Grava Triturada Caliza 40 mm - 1 1/2" | O22: DW96 | P22: MX-CEDIS ZACATECAS | Q22: 20210712 | R22: 20261231 | S22: 20210712 | T22: 20261231 | U22: 192.5 | V22: MXN | W22: M3 | X22: 0 | Y22: MXN | Z22: M3 | AC22: 56103637 | AD22: 6644901540 | AE22: 1 | AF22: ENTREGADO | AG22: 1.49 | AH22: M3 | AI22: X | AJ22: 4 | AK22: V4 | AL22: 20260108 | AM22: DW96-900004029-10000621
A23: 900004029DW9610000791 | B23: 4600050723-20 | C23: 4600050723 | D23: 20 | E23: MXPO | F23: MXL | G23: 900004029 | H23: TC-MEXICANA DE CALES | I23: 5001279 | J23: MEXICANA DE CALES SA DE CV | K23: Z03 | L23: (AP) 15 Dias | M23: 10000791 | N23: Arena Triturada Caliza Malla 4 | O23: DW96 | P23: MX-CEDIS ZACATECAS | Q23: 20210712 | R23: 20261231 | S23: 20210712 | T23: 20261231 | U23: 130.77 | V23: MXN | W23: M3 | X23: 0 | Y23: MXN | Z23: M3 | AC23: 56103638 | AD23: 6644901540 | AE23: 1 | AF23: ENTREGADO | AG23: 1.408 | AH23: M3 | AI23: X | AJ23: 4 | AK23: V4 | AL23: 20260108 | AM23: DW96-900004029-10000791
A24: 900008155DW9610232717 | B24: 4600057297-10 | C24: 4600057297 | D24: 10 | E24: MXPO | F24: MXL | G24: 900008155 | H24: SF TC- PETRA | I24: 5088776 | J24: PETREOS Y TRITURADOS DEL CENTRO LR | K24: N90 | L24: (AP) NAFIN 90 Dias | M24: 10232717 | N24: ARENA TRITURADA CALIZA MALLA 4 | O24: DW96 | P24: MX-CEDIS ZACATECAS | Q24: 20230417 | R24: 20281231 | S24: 20230417 | T24: 20281231 | U24: 225 | V24: MXN | W24: M3 | X24: 0 | Y24: MXN | Z24: M3 | AC24: 56103638 | AD24: 6644901540 | AE24: 1 | AF24: ENTREGADO | AG24: 1.609 | AH24: M3 | AI24: X | AJ24: 4 | AK24: V4 | AL24: 20230920 | AM24: DW96-900008155-10232717
A25: 900008155DW9610233332 | B25: 4600057297-30 | C25: 4600057297 | D25: 30 | E25: MXPO | F25: MXL | G25: 900008155 | H25: SF TC- PETRA | I25: 5088776 | J25: PETREOS Y TRITURADOS DEL CENTRO LR | K25: N90 | L25: (AP) NAFIN 90 Dias | M25: 10233332 | N25: GRAVA TRITURADA CALIZA 40 MM - 1 1/2" P | O25: DW96 | P25: MX-CEDIS ZACATECAS | Q25: 20230417 | R25: 20281231 | S25: 20230425 | T25: 20281231 | U25: 200 | V25: MXN | W25: M3 | X25: 0 | Y25: MXN | Z25: M3 | AC25: 56103637 | AD25: 6644901540 | AE25: 1 | AF25: ENTREGADO | AG25: 1.472 | AH25: M3 | AI25: X | AJ25: 4 | AK25: V4 | AL25: 20230920 | AM25: DW96-900008155-10233332
A26: 900004032DW96D18210000735 | B26: 4600056900-10 | C26: 4600056900 | D26: 10 | E26: MXPO | F26: MXL | G26: 900004032 | H26: TC-ED- LA CALERA | I26: 5045145 | J26: TRITURADOS LA CALERA,SA DE CV | K26: Z06 | L26: (AP) 45 Dias | M26: 10000735 | N26: Grava Triturada Caliza 10 mm - 3/8" | O26: DW96 | P26: MX-CEDIS ZACATECAS | Q26: 20230301 | R26: 20281231 | S26: 20230301 | T26: 20281231 | U26: 312 | V26: MXN | W26: M3 | X26: 150 | Y26: MXN | Z26: M3 | AA26: D182 | AB26: PD0544 ZACATECAS PLANTA 1 | AC26: 56103637 | AD26: 6644901540 | AE26: 4 | AF26: ENTREGA DIRECTA | AG26: 1.41 | AH26: M3 | AI26: X | AJ26: 4 | AK26: V4 | AL26: 20230920 | AM26: DW96-900004032-D182-10000735-4
A27: 900004032DW96D18210087696 | B27: 4600056900-20 | C27: 4600056900 | D27: 20 | E27: MXPO | F27: MXL | G27: 900004032 | H27: TC-ED- LA CALERA | I27: 5045145 | J27: TRITURADOS LA CALERA,SA DE CV | K27: Z06 | L27: (AP) 45 Dias | M27: 10087696 | N27: GRAVA TRITURADA CALIZA 40 MM - 1 1/2" | O27: DW96 | P27: MX-CEDIS ZACATECAS | Q27: 20230301 | R27: 20281231 | S27: 20230301 | T27: 20281231 | U27: 292 | V27: MXN | W27: M3 | X27: 150 | Y27: MXN | Z27: M3 | AA27: D182 | AB27: PD0544 ZACATECAS PLANTA 1 | AC27: 56103637 | AD27: 6644901540 | AE27: 4 | AF27: ENTREGA DIRECTA | AG27: 1.452 | AH27: M3 | AI27: X | AJ27: 4 | AK27: V4 | AL27: 20230920 | AM27: DW96-900004032-D182-10087696-4
A28: 900004032DW96D18210112080 | B28: 4600056900-40 | C28: 4600056900 | D28: 40 | E28: MXPO | F28: MXL | G28: 900004032 | H28: TC-ED- LA CALERA | I28: 5045145 | J28: TRITURADOS LA CALERA,SA DE CV | K28: Z06 | L28: (AP) 45 Dias | M28: 10112080 | N28: GRAVA TRITURADA CALIZA 20 MM - 3/4" | O28: DW96 | P28: MX-CEDIS ZACATECAS | Q28: 20230301 | R28: 20281231 | S28: 20230301 | T28: 20281231 | U28: 307 | V28: MXN | W28: M3 | X28: 150 | Y28: MXN | Z28: M3 | AA28: D182 | AB28: PD0544 ZACATECAS PLANTA 1 | AC28: 56103637 | AD28: 6644901540 | AE28: 4 | AF28: ENTREGA DIRECTA | AG28: 1.394 | AH28: M3 | AI28: X | AJ28: 4 | AK28: V4 | AL28: 20230920 | AM28: DW96-900004032-D182-10112080-4
A29: 900005256DW96D18210115820 | B29: 4600056813-10 | C29: 4600056813 | D29: 10 | E29: MXPO | F29: MXL | G29: 900005256 | H29: SF TC - ED R & R | I29: 5068065 | J29: R R TRITURADOS SA DE CV | K29: N90 | L29: (AP) NAFIN 90 Dias | M29: 10115820 | N29: ARENA TRITURADA CALIZA MALLA 4 | O29: DW96 | P29: MX-CEDIS ZACATECAS | Q29: 20230301 | R29: 20281231 | S29: 20230301 | T29: 20281231 | U29: 420 | V29: MXN | W29: M3 | X29: 250 | Y29: MXN | Z29: M3 | AA29: D182 | AB29: PD0544 ZACATECAS PLANTA 1 | AC29: 56103638 | AD29: 6644901540 | AE29: 4 | AF29: ENTREGA DIRECTA | AG29: 1.441 | AH29: M3 | AI29: X | AJ29: 4 | AK29: V4 | AL29: 20230920 | AM29: DW96-900005256-D182-10115820-4
A30: 900007136DW96D18210000669 | B30: 4600051818-10 | C30: 4600051818 | D30: 10 | E30: MXPO | F30: MXL | G30: 900007136 | H30: SF TC-ED-MINA QUIJANO | I30: 5004979 | J30: QUIJANO MARTINEZ LORENZO | K30: Z07 | L30: (AP) 60 Dias | M30: 10000669 | N30: Arena Clasificada Río Malla 4 | O30: DW96 | P30: MX-CEDIS ZACATECAS | Q30: 20210903 | R30: 20261231 | S30: 20210902 | T30: 20261231 | U30: 1300 | V30: MXN | W30: M3 | X30: 300 | Y30: MXN | Z30: M3 | AA30: D182 | AB30: PD0544 ZACATECAS PLANTA 1 | AC30: 56103638 | AD30: 6644901540 | AE30: 4 | AF30: ENTREGA DIRECTA | AG30: 1.312 | AH30: M3 | AI30: X | AJ30: 4 | AK30: V4 | AL30: 20260108 | AM30: DW96-900007136-D182-10000669-4
A31: 900006229DW96D18210171540 | B31: 4600050796-10 | C31: 4600050796 | D31: 10 | E31: MXPO | F31: MXL | G31: 900006229 | H31: SF TC-ED- IMHASA | I31: 5075596 | J31: CONSTRUCTORA DE REFRESQUEROS | K31: Z09 | L31: (AP) 90 Dias | M31: 10171540 | N31: ARENA TRITURADA CALIZA MALLA 4 | O31: DW96 | P31: MX-CEDIS ZACATECAS | Q31: 20210712 | R31: 20261231 | S31: 20210712 | T31: 20261231 | U31: 350 | V31: MXN | W31: M3 | X31: 150 | Y31: MXN | Z31: M3 | AA31: D182 | AB31: PD0544 ZACATECAS PLANTA 1 | AC31: 56103638 | AD31: 6644901540 | AE31: 4 | AF31: ENTREGA DIRECTA | AG31: 1.52 | AH31: M3 | AI31: X | AJ31: 4 | AK31: V4 | AL31: 20230920 | AM31: DW96-900006229-D182-10171540-4
A32: 900004032DW96D18210098596 | B32: 4600056900-30 | C32: 4600056900 | D32: 30 | E32: MXPO | F32: MXL | G32: 900004032 | H32: TC-ED- LA CALERA | I32: 5045145 | J32: TRITURADOS LA CALERA,SA DE CV | K32: Z06 | L32: (AP) 45 Dias | M32: 10098596 | N32: ARENA TRITURADA CALIZA MALLA 4 | O32: DW96 | P32: MX-CEDIS ZACATECAS | Q32: 20230301 | R32: 20281231 | S32: 20230301 | T32: 20281231 | U32: 317 | V32: MXN | W32: M3 | X32: 150 | Y32: MXN | Z32: M3 | AA32: D182 | AB32: PD0544 ZACATECAS PLANTA 1 | AC32: 56103638 | AD32: 6644901540 | AE32: 4 | AF32: ENTREGA DIRECTA | AG32: 1.504 | AH32: M3 | AI32: X | AJ32: 4 | AK32: V4 | AL32: 20230920 | AM32: DW96-900004032-D182-10098596-4
A33: 900005046DW96D18210138698 | B33: 4600050735-40 | C33: 4600050735 | D33: 40 | E33: MXPO | F33: MXL | G33: 900005046 | H33: SF TC-ED RIVERA | I33: 5011204 | J33: RIVERA Y RIVERA SA DE CV | K33: N90 | L33: (AP) NAFIN 90 Dias | M33: 10138698 | N33: GRAVA TRITURADA CALIZA 40 MM - 1 1/2" | O33: DW96 | P33: MX-CEDIS ZACATECAS | Q33: 20210712 | R33: 20261231 | S33: 20210712 | T33: 20261231 | U33: 240 | V33: MXN | W33: M3 | X33: 70 | Y33: MXN | Z33: M3 | AA33: D182 | AB33: PD0544 ZACATECAS PLANTA 1 | AC33: 56103637 | AD33: 6644901540 | AE33: 4 | AF33: ENTREGA DIRECTA | AG33: 1.399 | AH33: M3 | AI33: X | AJ33: 4 | AK33: V4 | AL33: 20260108 | AM33: DW96-900005046-D182-10138698-4
A34: 900005046DW96D18210138697 | B34: 4600050735-30 | C34: 4600050735 | D34: 30 | E34: MXPO | F34: MXL | G34: 900005046 | H34: SF TC-ED RIVERA | I34: 5011204 | J34: RIVERA Y RIVERA SA DE CV | K34: N90 | L34: (AP) NAFIN 90 Dias | M34: 10138697 | N34: ARENA TRITURADA CALIZA MALLA 4 | O34: DW96 | P34: MX-CEDIS ZACATECAS | Q34: 20210712 | R34: 20261231 | S34: 20210712 | T34: 20261231 | U34: 240 | V34: MXN | W34: M3 | X34: 70 | Y34: MXN | Z34: M3 | AA34: D182 | AB34: PD0544 ZACATECAS PLANTA 1 | AC34: 56103638 | AD34: 6644901540 | AE34: 4 | AF34: ENTREGA DIRECTA | AG34: 1.284 | AH34: M3 | AI34: X | AJ34: 4 | AK34: V4 | AL34: 20260108 | AM34: DW96-900005046-D182-10138697-4
A35: 900005046DW96D18210000340 | B35: 4600050735-10 | C35: 4600050735 | D35: 10 | E35: MXPO | F35: MXL | G35: 900005046 | H35: SF TC-ED RIVERA | I35: 5011204 | J35: RIVERA Y RIVERA SA DE CV | K35: N90 | L35: (AP) NAFIN 90 Dias | M35: 10000340 | N35: Grava Triturada Caliza 20 mm - 3/4" | O35: DW96 | P35: MX-CEDIS ZACATECAS | Q35: 20210712 | R35: 20261231 | S35: 20210712 | T35: 20261231 | U35: 240 | V35: MXN | W35: M3 | X35: 70 | Y35: MXN | Z35: M3 | AA35: D182 | AB35: PD0544 ZACATECAS PLANTA 1 | AC35: 56103637 | AD35: 6644901540 | AE35: 4 | AF35: ENTREGA DIRECTA | AG35: 1.345 | AH35: M3 | AI35: X | AJ35: 4 | AK35: V4 | AL35: 20260108 | AM35: DW96-900005046-D182-10000340-4
A36: 900004008DW96D18210000480 | B36: 4600050721-10 | C36: 4600050721 | D36: 10 | E36: MXPO | F36: MXL | G36: 900004008 | H36: TC- ED- INOCENCIO PARGA | I36: 5010510 | J36: PARGA URISTA INOCENCIO | K36: Z85 | L36: (AP) 75 Dias | M36: 10000480 | N36: Arena Clasificada Río Malla 4 | O36: DW96 | P36: MX-CEDIS ZACATECAS | Q36: 20210712 | R36: 20261231 | S36: 20210712 | T36: 20261231 | U36: 165 | V36: MXN | W36: M3 | X36: 75 | Y36: MXN | Z36: M3 | AA36: D182 | AB36: PD0544 ZACATECAS PLANTA 1 | AC36: 56103638 | AD36: 6644901540 | AE36: 4 | AF36: ENTREGA DIRECTA | AG36: 1.404 | AH36: M3 | AI36: X | AJ36: 4 | AK36: V4 | AL36: 20260108 | AM36: DW96-900004008-D182-10000480-4
A37: 900005046DW96D18210138696 | B37: 4600050735-20 | C37: 4600050735 | D37: 20 | E37: MXPO | F37: MXL | G37: 900005046 | H37: SF TC-ED RIVERA | I37: 5011204 | J37: RIVERA Y RIVERA SA DE CV | K37: N90 | L37: (AP) NAFIN 90 Dias | M37: 10138696 | N37: ARENA TRITURADA RIO MALLA 4 | O37: DW96 | P37: MX-CEDIS ZACATECAS | Q37: 20210712 | R37: 20261231 | S37: 20250315 | T37: 20301231 | U37: 280 | V37: MXN | W37: M3 | X37: 100 | Y37: MXN | Z37: M3 | AA37: D182 | AB37: PD0544 ZACATECAS PLANTA 1 | AC37: 56103638 | AD37: 6644901540 | AE37: 4 | AF37: ENTREGA DIRECTA | AG37: 1.334 | AH37: M3 | AI37: X | AJ37: 4 | AK37: V4 | AL37: 20250527 | AM37: DW96-900005046-D182-10138696-4
