Workbook

Sheet Base Cedis D814
N1: VENTA | Q1: COSTO
A2: CONCAT1 | B2: CONCAT2 | C2: No. SF | D2: Nombre SF | E2: Cedis | F2: Destino | G2: Condicion de Expedicion | H2: Nombre Destino | I2: No. de material | J2: Nombre de material | K2: PV | L2: Inicio de vigencia | M2: Fin de vigencia | N2: Importe MP | O2: Importe Flete | P2: UM Venta | Q2: Importe Costo | R2: UM Costo | S2: Validacion 1 | T2: Validacion 2
A3: =CONCATENATE(C3,E3,F3,I3) | B3: =CONCATENATE(C3,E3,I3) | C3: 900005920 | D3: =IFERROR(VLOOKUP(C3,TRAOPE!$G:$H,2,0),"") | E3: D814 | F3: ER67 | G3: =IFERROR(VLOOKUP(A3,Flete!$A:$E,5,0),"") | H3: =IFERROR(VLOOKUP(F3,TRAOPE!$AA:$AB,2,0),"") | I3: 10003240 | J3: =IFERROR(VLOOKUP(I3,Materiales!$A:$H,8,0),"") | K3: =IFERROR(VLOOKUP(I3,Materiales!$A:$G,7,0),"") | L3: 20220504 | M3: 20230127 | N3: 179.68 | O3: =IFERROR(VLOOKUP(A3,Flete!$A:$J,10,0),"") | P3: TN | Q3: =IFERROR(IFERROR(VLOOKUP(A3,TRAOPE!$A:$U,21,0),VLOOKUP(B3,TRAOPE!$A:$U,21,0)),"") | R3: =IFERROR(IFERROR(VLOOKUP(A3,TRAOPE!$A:$W,23,0),VLOOKUP(B3,TRAOPE!$A:$W,23,0)),"") | S3: =IF(AND(P3="TN",R3="TN"),N3+N(O3),IF(G3&""="1",N(K3)*N3,(N3+N(O3))*N(K3))) | T3: =IF(Q3="","",Q3-S3)
A4: =CONCATENATE(C4,E4,F4,I4) | B4: =CONCATENATE(C4,E4,I4) | C4: 900006731 | D4: =IFERROR(VLOOKUP(C4,TRAOPE!$G:$H,2,0),"") | E4: D814 | F4: EO04 | G4: =IFERROR(VLOOKUP(A4,Flete!$A:$E,5,0),"") | H4: =IFERROR(VLOOKUP(F4,TRAOPE!$AA:$AB,2,0),"") | I4: 10000561 | J4: =IFERROR(VLOOKUP(I4,Materiales!$A:$H,8,0),"") | K4: =IFERROR(VLOOKUP(I4,Materiales!$A:$G,7,0),"") | L4: 20220504 | M4: 20230127 | N4: 161.94 | O4: =IFERROR(VLOOKUP(A4,Flete!$A:$J,10,0),"") | P4: TN | Q4: =IFERROR(IFERROR(VLOOKUP(A4,TRAOPE!$A:$U,21,0),VLOOKUP(B4,TRAOPE!$A:$U,21,0)),"") | R4: =IFERROR(IFERROR(VLOOKUP(A4,TRAOPE!$A:$W,23,0),VLOOKUP(B4,TRAOPE!$A:$W,23,0)),"") | S4: =IF(AND(P4="TN",R4="TN"),N4+N(O4),IF(G4&""="1",N(K4)*N4,(N4+N(O4))*N(K4))) | T4: =IF(Q4="","",Q4-S4)
A5: =CONCATENATE(C5,E5,F5,I5) | B5: =CONCATENATE(C5,E5,I5) | C5: 900006731 | D5: =IFERROR(VLOOKUP(C5,TRAOPE!$G:$H,2,0),"") | E5: D814 | F5: EO04 | G5: =IFERROR(VLOOKUP(A5,Flete!$A:$E,5,0),"") | H5: =IFERROR(VLOOKUP(F5,TRAOPE!$AA:$AB,2,0),"") | I5: 10123034 | J5: =IFERROR(VLOOKUP(I5,Materiales!$A:$H,8,0),"") | K5: =IFERROR(VLOOKUP(I5,Materiales!$A:$G,7,0),"") | L5: 20220504 | M5: 20230127 | N5: 55.11 | O5: =IFERROR(VLOOKUP(A5,Flete!$A:$J,10,0),"") | P5: TN | Q5: =IFERROR(IFERROR(VLOOKUP(A5,TRAOPE!$A:$U,21,0),VLOOKUP(B5,TRAOPE!$A:$U,21,0)),"") | R5: =IFERROR(IFERROR(VLOOKUP(A5,TRAOPE!$A:$W,23,0),VLOOKUP(B5,TRAOPE!$A:$W,23,0)),"") | S5: =IF(AND(P5="TN",R5="TN"),N5+N(O5),IF(G5&""="1",N(K5)*N5,(N5+N(O5))*N(K5))) | T5: =IF(Q5="","",Q5-S5)
A6: =CONCATENATE(C6,E6,F6,I6) | B6: =CONCATENATE(C6,E6,I6) | C6: 900006732 | D6: =IFERROR(VLOOKUP(C6,TRAOPE!$G:$H,2,0),"") | E6: D814 | F6: EO04 | G6: =IFERROR(VLOOKUP(A6,Flete!$A:$E,5,0),"") | H6: =IFERROR(VLOOKUP(F6,TRAOPE!$AA:$AB,2,0),"") | I6: 10000372 | J6: =IFERROR(VLOOKUP(I6,Materiales!$A:$H,8,0),"") | K6: =IFERROR(VLOOKUP(I6,Materiales!$A:$G,7,0),"") | L6: 20220504 | M6: 20230127 | N6: 165.02 | O6: =IFERROR(VLOOKUP(A6,Flete!$A:$J,10,0),"") | P6: TN | Q6: =IFERROR(IFERROR(VLOOKUP(A6,TRAOPE!$A:$U,21,0),VLOOKUP(B6,TRAOPE!$A:$U,21,0)),"") | R6: =IFERROR(IFERROR(VLOOKUP(A6,TRAOPE!$A:$W,23,0),VLOOKUP(B6,TRAOPE!$A:$W,23,0)),"") | S6: =IF(AND(P6="TN",R6="TN"),N6+N(O6),IF(G6&""="1",N(K6)*N6,(N6+N(O6))*N(K6))) | T6: =IF(Q6="","",Q6-S6)
A7: =CONCATENATE(C7,E7,F7,I7) | B7: =CONCATENATE(C7,E7,I7) | C7: 900006732 | D7: =IFERROR(VLOOKUP(C7,TRAOPE!$G:$H,2,0),"") | E7: D814 | F7: EO04 | G7: =IFERROR(VLOOKUP(A7,Flete!$A:$E,5,0),"") | H7: =IFERROR(VLOOKUP(F7,TRAOPE!$AA:$AB,2,0),"") | I7: 10123034 | J7: =IFERROR(VLOOKUP(I7,Materiales!$A:$H,8,0),"") | K7: =IFERROR(VLOOKUP(I7,Materiales!$A:$G,7,0),"") | L7: 20220504 | M7: 20230127 | N7: 124 | O7: =IFERROR(VLOOKUP(A7,Flete!$A:$J,10,0),"") | P7: TN | Q7: =IFERROR(IFERROR(VLOOKUP(A7,TRAOPE!$A:$U,21,0),VLOOKUP(B7,TRAOPE!$A:$U,21,0)),"") | R7: =IFERROR(IFERROR(VLOOKUP(A7,TRAOPE!$A:$W,23,0),VLOOKUP(B7,TRAOPE!$A:$W,23,0)),"") | S7: =IF(AND(P7="TN",R7="TN"),N7+N(O7),IF(G7&""="1",N(K7)*N7,(N7+N(O7))*N(K7))) | T7: =IF(Q7="","",Q7-S7)
A8: =CONCATENATE(C8,E8,F8,I8) | B8: =CONCATENATE(C8,E8,I8) | C8: 900006733 | D8: =IFERROR(VLOOKUP(C8,TRAOPE!$G:$H,2,0),"") | E8: D814 | F8: EO04 | G8: =IFERROR(VLOOKUP(A8,Flete!$A:$E,5,0),"") | H8: =IFERROR(VLOOKUP(F8,TRAOPE!$AA:$AB,2,0),"") | I8: 10049559 | J8: =IFERROR(VLOOKUP(I8,Materiales!$A:$H,8,0),"") | K8: =IFERROR(VLOOKUP(I8,Materiales!$A:$G,7,0),"") | L8: 20220504 | M8: 20230127 | N8: 176.48 | O8: =IFERROR(VLOOKUP(A8,Flete!$A:$J,10,0),"") | P8: TN | Q8: =IFERROR(IFERROR(VLOOKUP(A8,TRAOPE!$A:$U,21,0),VLOOKUP(B8,TRAOPE!$A:$U,21,0)),"") | R8: =IFERROR(IFERROR(VLOOKUP(A8,TRAOPE!$A:$W,23,0),VLOOKUP(B8,TRAOPE!$A:$W,23,0)),"") | S8: =IF(AND(P8="TN",R8="TN"),N8+N(O8),IF(G8&""="1",N(K8)*N8,(N8+N(O8))*N(K8))) | T8: =IF(Q8="","",Q8-S8)
A9: =CONCATENATE(C9,E9,F9,I9) | B9: =CONCATENATE(C9,E9,I9) | C9: 900006734 | D9: =IFERROR(VLOOKUP(C9,TRAOPE!$G:$H,2,0),"") | E9: D814 | F9: EO04 | G9: =IFERROR(VLOOKUP(A9,Flete!$A:$E,5,0),"") | H9: =IFERROR(VLOOKUP(F9,TRAOPE!$AA:$AB,2,0),"") | I9: 10000452 | J9: =IFERROR(VLOOKUP(I9,Materiales!$A:$H,8,0),"") | K9: =IFERROR(VLOOKUP(I9,Materiales!$A:$G,7,0),"") | L9: 20220504 | M9: 20230127 | N9: 172.33 | O9: =IFERROR(VLOOKUP(A9,Flete!$A:$J,10,0),"") | P9: TN | Q9: =IFERROR(IFERROR(VLOOKUP(A9,TRAOPE!$A:$U,21,0),VLOOKUP(B9,TRAOPE!$A:$U,21,0)),"") | R9: =IFERROR(IFERROR(VLOOKUP(A9,TRAOPE!$A:$W,23,0),VLOOKUP(B9,TRAOPE!$A:$W,23,0)),"") | S9: =IF(AND(P9="TN",R9="TN"),N9+N(O9),IF(G9&""="1",N(K9)*N9,(N9+N(O9))*N(K9))) | T9: =IF(Q9="","",Q9-S9)
A10: =CONCATENATE(C10,E10,F10,I10) | B10: =CONCATENATE(C10,E10,I10) | C10: 900006740 | D10: =IFERROR(VLOOKUP(C10,TRAOPE!$G:$H,2,0),"") | E10: D814 | F10: EO04 | G10: =IFERROR(VLOOKUP(A10,Flete!$A:$E,5,0),"") | H10: =IFERROR(VLOOKUP(F10,TRAOPE!$AA:$AB,2,0),"") | I10: 10147454 | J10: =IFERROR(VLOOKUP(I10,Materiales!$A:$H,8,0),"") | K10: =IFERROR(VLOOKUP(I10,Materiales!$A:$G,7,0),"") | L10: 20220504 | M10: 20230127 | N10: 142.06 | O10: =IFERROR(VLOOKUP(A10,Flete!$A:$J,10,0),"") | P10: TN | Q10: =IFERROR(IFERROR(VLOOKUP(A10,TRAOPE!$A:$U,21,0),VLOOKUP(B10,TRAOPE!$A:$U,21,0)),"") | R10: =IFERROR(IFERROR(VLOOKUP(A10,TRAOPE!$A:$W,23,0),VLOOKUP(B10,TRAOPE!$A:$W,23,0)),"") | S10: =IF(AND(P10="TN",R10="TN"),N10+N(O10),IF(G10&""="1",N(K10)*N10,(N10+N(O10))*N(K10))) | T10: =IF(Q10="","",Q10-S10)
A11: =CONCATENATE(C11,E11,F11,I11) | B11: =CONCATENATE(C11,E11,I11) | C11: 900006741 | D11: =IFERROR(VLOOKUP(C11,TRAOPE!$G:$H,2,0),"") | E11: D814 | F11: EO04 | G11: =IFERROR(VLOOKUP(A11,Flete!$A:$E,5,0),"") | H11: =IFERROR(VLOOKUP(F11,TRAOPE!$AA:$AB,2,0),"") | I11: 10000834 | J11: =IFERROR(VLOOKUP(I11,Materiales!$A:$H,8,0),"") | K11: =IFERROR(VLOOKUP(I11,Materiales!$A:$G,7,0),"") | L11: 20220504 | M11: 20230127 | N11: 36.38 | O11: =IFERROR(VLOOKUP(A11,Flete!$A:$J,10,0),"") | P11: TN | Q11: =IFERROR(IFERROR(VLOOKUP(A11,TRAOPE!$A:$U,21,0),VLOOKUP(B11,TRAOPE!$A:$U,21,0)),"") | R11: =IFERROR(IFERROR(VLOOKUP(A11,TRAOPE!$A:$W,23,0),VLOOKUP(B11,TRAOPE!$A:$W,23,0)),"") | S11: =IF(AND(P11="TN",R11="TN"),N11+N(O11),IF(G11&""="1",N(K11)*N11,(N11+N(O11))*N(K11))) | T11: =IF(Q11="","",Q11-S11)
A12: =CONCATENATE(C12,E12,F12,I12) | B12: =CONCATENATE(C12,E12,I12) | C12: 900006742 | D12: =IFERROR(VLOOKUP(C12,TRAOPE!$G:$H,2,0),"") | E12: D814 | F12: EO04 | G12: =IFERROR(VLOOKUP(A12,Flete!$A:$E,5,0),"") | H12: =IFERROR(VLOOKUP(F12,TRAOPE!$AA:$AB,2,0),"") | I12: 10000834 | J12: =IFERROR(VLOOKUP(I12,Materiales!$A:$H,8,0),"") | K12: =IFERROR(VLOOKUP(I12,Materiales!$A:$G,7,0),"") | L12: 20220504 | M12: 20230127 | N12: 37.21 | O12: =IFERROR(VLOOKUP(A12,Flete!$A:$J,10,0),"") | P12: TN | Q12: =IFERROR(IFERROR(VLOOKUP(A12,TRAOPE!$A:$U,21,0),VLOOKUP(B12,TRAOPE!$A:$U,21,0)),"") | R12: =IFERROR(IFERROR(VLOOKUP(A12,TRAOPE!$A:$W,23,0),VLOOKUP(B12,TRAOPE!$A:$W,23,0)),"") | S12: =IF(AND(P12="TN",R12="TN"),N12+N(O12),IF(G12&""="1",N(K12)*N12,(N12+N(O12))*N(K12))) | T12: =IF(Q12="","",Q12-S12)
A13: =CONCATENATE(C13,E13,F13,I13) | B13: =CONCATENATE(C13,E13,I13) | C13: 900006743 | D13: =IFERROR(VLOOKUP(C13,TRAOPE!$G:$H,2,0),"") | E13: D814 | F13: EO04 | G13: =IFERROR(VLOOKUP(A13,Flete!$A:$E,5,0),"") | H13: =IFERROR(VLOOKUP(F13,TRAOPE!$AA:$AB,2,0),"") | I13: 10000834 | J13: =IFERROR(VLOOKUP(I13,Materiales!$A:$H,8,0),"") | K13: =IFERROR(VLOOKUP(I13,Materiales!$A:$G,7,0),"") | L13: 20220504 | M13: 20230127 | N13: 38.04 | O13: =IFERROR(VLOOKUP(A13,Flete!$A:$J,10,0),"") | P13: TN | Q13: =IFERROR(IFERROR(VLOOKUP(A13,TRAOPE!$A:$U,21,0),VLOOKUP(B13,TRAOPE!$A:$U,21,0)),"") | R13: =IFERROR(IFERROR(VLOOKUP(A13,TRAOPE!$A:$W,23,0),VLOOKUP(B13,TRAOPE!$A:$W,23,0)),"") | S13: =IF(AND(P13="TN",R13="TN"),N13+N(O13),IF(G13&""="1",N(K13)*N13,(N13+N(O13))*N(K13))) | T13: =IF(Q13="","",Q13-S13)
A14: =CONCATENATE(C14,E14,F14,I14) | B14: =CONCATENATE(C14,E14,I14) | C14: 900006744 | D14: =IFERROR(VLOOKUP(C14,TRAOPE!$G:$H,2,0),"") | E14: D814 | F14: EO04 | G14: =IFERROR(VLOOKUP(A14,Flete!$A:$E,5,0),"") | H14: =IFERROR(VLOOKUP(F14,TRAOPE!$AA:$AB,2,0),"") | I14: 10000834 | J14: =IFERROR(VLOOKUP(I14,Materiales!$A:$H,8,0),"") | K14: =IFERROR(VLOOKUP(I14,Materiales!$A:$G,7,0),"") | L14: 20220504 | M14: 20230127 | N14: 38.04 | O14: =IFERROR(VLOOKUP(A14,Flete!$A:$J,10,0),"") | P14: TN | Q14: =IFERROR(IFERROR(VLOOKUP(A14,TRAOPE!$A:$U,21,0),VLOOKUP(B14,TRAOPE!$A:$U,21,0)),"") | R14: =IFERROR(IFERROR(VLOOKUP(A14,TRAOPE!$A:$W,23,0),VLOOKUP(B14,TRAOPE!$A:$W,23,0)),"") | S14: =IF(AND(P14="TN",R14="TN"),N14+N(O14),IF(G14&""="1",N(K14)*N14,(N14+N(O14))*N(K14))) | T14: =IF(Q14="","",Q14-S14)
... A619: =CONCATENATE(C619,E619,F619,I619) | B619: =CONCATENATE(C619,E619,I619) | C619: 900009035 | D619: =IFERROR(VLOOKUP(C619,TRAOPE!$G:$H,2,0),"") | E619: D814 | F619: 67313510 | G619: =IFERROR(VLOOKUP(A619,Flete!$A:$E,5,0),"") | H619: =IFERROR(VLOOKUP(F619,TRAOPE!$AA:$AB,2,0),"") | I619: 10173699 | J619: =IFERROR(VLOOKUP(I619,Materiales!$A:$H,8,0),"") | K619: =IFERROR(VLOOKUP(I619,Materiales!$A:$G,7,0),"") | L619: 20250505 | M619: 20250507 | N619: 93 | O619: =IFERROR(VLOOKUP(A619,Flete!$A:$J,10,0),"") | P619: M3 | Q619: =IFERROR(IFERROR(VLOOKUP(A619,TRAOPE!$A:$U,21,0),VLOOKUP(B619,TRAOPE!$A:$U,21,0)),"") | R619: =IFERROR(IFERROR(VLOOKUP(A619,TRAOPE!$A:$W,23,0),VLOOKUP(B619,TRAOPE!$A:$W,23,0)),"") | S619: =IF(AND(P619="TN",R619="TN"),N619+N(O619),IF(G619&""="1",N(K619)*N619,(N619+N(O619))*N(K619))) | T619: =IF(Q619="","",Q619-S619)

Sheet MP
A1: No. SF | B1: Cedis | C1: Destino | D1: No. Material | E1: Nombre Material | F1: Importe MP | G1: Moneda | H1: Cantidad | I1: UM | J1: C | K1: Inicio Vigencia | L1: Fin Vigencia
A2: 900005920 | B2: D814 | C2: ER67 | D2: 10003240 | F2: 179.68 | I2: TN | K2: 20220504 | L2: 20230127
A3: 900006731 | B3: D814 | C3: EO04 | D3: 10000561 | F3: 161.94 | I3: TN | K3: 20220504 | L3: 20230127
A4: 900006731 | B4: D814 | C4: EO04 | D4: 10123034 | F4: 55.11 | I4: TN | K4: 20220504 | L4: 20230127
A5: 900006732 | B5: D814 | C5: EO04 | D5: 10000372 | F5: 165.02 | I5: TN | K5: 20220504 | L5: 20230127
A6: 900006732 | B6: D814 | C6: EO04 | D6: 10123034 | F6: 124 | I6: TN | K6: 20220504 | L6: 20230127
A7: 900006733 | B7: D814 | C7: EO04 | D7: 10049559 | F7: 176.48 | I7: TN | K7: 20220504 | L7: 20230127
A8: 900006734 | B8: D814 | C8: EO04 | D8: 10000452 | F8: 172.33 | I8: TN | K8: 20220504 | L8: 20230127
A9: 900006740 | B9: D814 | C9: EO04 | D9: 10147454 | F9: 142.06 | I9: TN | K9: 20220504 | L9: 20230127
A10: 900006741 | B10: D814 | C10: EO04 | D10: 10000834 | F10: 36.38 | I10: TN | K10: 20220504 | L10: 20230127
A11: 900006742 | B11: D814 | C11: EO04 | D11: 10000834 | F11: 37.21 | I11: TN | K11: 20220504 | L11: 20230127
A12: 900006743 | B12: D814 | C12: EO04 | D12: 10000834 | F12: 38.04 | I12: TN | K12: 20220504 | L12: 20230127
A13: 900006744 | B13: D814 | C13: EO04 | D13: 10000834 | F13: 38.04 | I13: TN | K13: 20220504 | L13: 20230127
... A618: 900009035 | B618: D814 | C618: 67313510 | D618: 10173699 | F618: 93 | I618: M3 | K618: 20250505 | L618: 20250507

Sheet Flete
A1: Concat1 | B1: No. SF | C1: Cedis | D1: Destino | E1: Cond. Exp. | F1: Material | H1: Nombre Material | J1: Importe Flete | K1: Moneda | L1: Cantidad | M1: UM | N1: C | P1: Inicio Vigencia | Q1: Fin Vigencia
A2: 900000129D8146511942310000834 | B2: 900000129 | C2: D814 | D2: 65119423 | E2: 1 | F2: 10000834 | J2: 50 | M2: M3 | P2: 20170210 | Q2: 99991231
A3: 900000129D8146574530510000834 | B3: 900000129 | C3: D814 | D3: 65745305 | E3: 1 | F3: 10000834 | J3: 4.08 | M3: M3 | P3: 20170210 | Q3: 99991231
A4: 900001325D8146574530510000223 | B4: 900001325 | C4: D814 | D4: 65745305 | E4: 1 | F4: 10000223 | J4: 11.92 | M4: M3 | P4: 20170210 | Q4: 99991231
A5: 900002302D8146511942310000834 | B5: 900002302 | C5: D814 | D5: 65119423 | E5: 1 | F5: 10000834 | J5: 57 | M5: M3 | P5: 20170210 | Q5: 99991231
A6: 900002862D8146574530510000452 | B6: 900002862 | C6: D814 | D6: 65745305 | E6: 1 | F6: 10000452 | J6: 11.52 | M6: M3 | P6: 20140801 | Q6: 99991231
A7: 900003621D8146574530510000223 | B7: 900003621 | C7: D814 | D7: 65745305 | E7: 1 | F7: 10000223 | J7: 150 | M7: M3 | P7: 20170210 | Q7: 99991231
A8: 900003624D8146574530510000452 | B8: 900003624 | C8: D814 | D8: 65745305 | E8: 1 | F8: 10000452 | J8: 145 | M8: M3 | P8: 20141106 | Q8: 99991231
A9: 900003631D8146574530510000834 | B9: 900003631 | C9: D814 | D9: 65745305 | E9: 1 | F9: 10000834 | J9: 51 | M9: M3 | P9: 20170210 | Q9: 99991231
A10: 900003735D8146636065010000541 | B10: 900003735 | C10: D814 | D10: 66360650 | E10: 4 | F10: 10000541 | J10: 315.4 | M10: M3 | P10: 20170210 | Q10: 20240320
A11: 900003735D8146657340610000541 | B11: 900003735 | C11: D814 | D11: 66573406 | E11: 4 | F11: 10000541 | J11: 653.05 | M11: M3 | P11: 20170210 | Q11: 20240320
A12: 900003735D8146664759010000541 | B12: 900003735 | C12: D814 | D12: 66647590 | E12: 4 | F12: 10000541 | J12: 232 | M12: M3 | P12: 20170210 | Q12: 20240320
A13: 900003735D8146677929210000541 | B13: 900003735 | C13: D814 | D13: 66779292 | E13: 4 | F13: 10000541 | J13: 200.4 | M13: M3 | P13: 20170210 | Q13: 20240320
... A433: 900009035D8146731351010173699 | B433: 900009035 | C433: D814 | D433: 67313510 | E433: 4 | F433: 10173699 | J433: 137 | M433: M3 | P433: 20250304 | Q433: 20250507

Sheet Materiales
A1: Material | B1: TpMt | C1: Denom | D1: UMA | E1: Contador | F1: UMB | G1: PV | H1: Nombre Material
A2: 10000001 | B2: ZFER | C2: 1000 | D2: M3 | E2: 1000 | F2: TN | G2: 1262 | H2: GRAVA ANDESITA 10 MM (3/8")
A3: 10000003 | B3: ZFER | C3: 1000 | D3: M3 | E3: 1000 | F3: TN | G3: 1443 | H3: GRAVA CALIZA 10 MM (3/8")
A4: 10000006 | B4: ZFER | C4: 1000 | D4: M3 | E4: 1000 | F4: TN | G4: 1490 | H4: GRAVA RIO 10 MM (3/8")
A5: 10000007 | B5: ZFER | C5: 1000 | D5: M3 | E5: 1000 | F5: TN | G5: 1488 | H5: GRAVA BASALTO 13 MM (1/2")
A6: 10000008 | B6: ZFER | C6: 1000 | D6: M3 | E6: 1000 | F6: TN | G6: 1358 | H6: GRAVA CALIZA 13 MM (1/2")
A7: 10000011 | B7: ZFER | C7: 1000 | D7: M3 | E7: 1000 | F7: TN | G7: 1323 | H7: GRAVA ANDESITA 20 MM (3/4")
A8: 10000013 | B8: ZFER | C8: 1000 | D8: M3 | E8: 1000 | F8: TN | G8: 1514 | H8: GRAVA BASALTO 20 MM (3/4")
A9: 10000014 | B9: ZFER | C9: 1000 | D9: M3 | E9: 1000 | F9: TN | G9: 1400 | H9: GRAVA CALIZA 20 MM (3/4")
A10: 10000015 | B10: ZFER | C10: 1000 | D10: M3 | E10: 1000 | F10: TN | G10: 1410 | H10: GRAVA GRANITO 20 MM (3/4")
A11: 10000017 | B11: ZFER | C11: 1000 | D11: M3 | E11: 1000 | F11: TN | G11: 1475 | H11: GRAVA RIOLITA 20 MM (3/4")
A12: 10000019 | B12: ZFER | C12: 1000 | D12: M3 | E12: 1000 | F12: TN | G12: 1515 | H12: GRAVA RIO 20 MM (3/4")
A13: 10000020 | B13: ZFER | C13: 1000 | D13: M3 | E13: 1 | F13: TN | G13: 1 | H13: GRAVA MAQUILA 40MM (1 1/2")
... A2291: 10268770 | B2291: ZFE3 | C2291: 1000 | D2291: M3 | E2291: 1000 | F2291: TN | G2291: 1240 | H2291: MP GRAVA TRIT CALIZA 40MM 1 1/2" - ESP
A2292: 10268901 | B2292: ZFE3 | C2292: 1000 | D2292: M3 | E2292: 1000 | G2292: 1560 | H2292: MP GRAVA ANDESITA GRIS 3/4" - CAPADA
A2293: 10267983 | C2293: 1000 | G2293: 1800 | H2293: ESCORIA ALTO HORNO 3/4
A2294: 10268996 | C2294: 1000 | G2294: 1329 | H2294: GRAVA TRITURADA CALIZA 40 MM - 11/2"
A2295: 10269072 | C2295: 1000 | G2295: 1700 | H2295: BASE HIDRÁULICA SCREEN
A2296: 10269225 | B2296: ZFE3 | C2296: 1000 | D2296: M3 | E2296: 1000 | G2296: 1289 | H2296: MP ARENA CALIZA LAVADA MALLA 4 - DELTA I
A2297: 10269245 | B2297: ZFE3 | C2297: 1000 | D2297: M3 | E2297: 1000 | G2297: 1410 | H2297: MP GRAVA TRITURADA CALIZA 3/8 - 10MM
A2298: 10269246 | B2298: ZFE3 | C2298: 1000 | D2298: M3 | E2298: 1000 | G2298: 1400 | H2298: MP GRAVA TRITURADA CALIZA 1 1/2 - 40MM
A2299: 10269247 | B2299: ZFE3 | C2299: 1000 | D2299: M3 | E2299: 1000 | G2299: 1560 | H2299: MP ARENA TRIT CALIZA M-4
A2300: 10270431 | B2300: ZFE3 | C2300: 1000 | D2300: M3 | E2300: 1000 | G2300: 1423 | H2300: MP GRAVA RIOLITA 13 MM - 1/2"
A2301: 10270898 | B2301: ZFE3 | C2301: 1000 | D2301: M3 | E2301: 1000 | G2301: 1551 | H2301: MP BASE H. TRIT. BASALTO 1 1/2" A FINOS
A2302: 10270911 | B2302: ZFE3 | C2302: 1000 | D2302: M3 | E2302: 1000 | G2302: 1360 | H2302: MP GRAVA TRIT. BASALTO 40 MM - 1 1/2"
A2303: 10270912 | B2303: ZFE3 | C2303: 1000 | D2303: M3 | E2303: 1000 | G2303: 1589 | H2303: MP ARENA TRIT. BASALTO MALLA 4
A2304: 10270913 | B2304: ZFE3 | C2304: 1000 | D2304: M3 | E2304: 1000 | G2304: 1395 | H2304: MP GRAVA TRIT. BASALTO 20 MM - 3/4
A2305: 10270914 | B2305: ZFE3 | C2305: 1000 | D2305: M3 | E2305: 1000 | G2305: 1623 | H2305: MP ARENA ANDESITA BC
A2306: 10270824 | B2306: M3 | C2306: 1000 | D2306: M3 | E2306: 10007640 | G2306: 1325 | H2306: MP ARENA TRITURADA CALIZA MALLA 5
A2307: 10270825 | B2307: M3 | C2307: 1000 | D2307: M3 | E2307: 10000003 | G2307: 1242 | H2307: MP GRAVA TRITURADA CALIZA 10MM (3/8”)
... A2319: 10272527 | B2319: ZFE3 | C2319: 1000 | D2319: M3 | E2319: 1000 | G2319: 1620 | H2319: CNC - NO CLASIFICADO
A2320: 10000332 | C2320: 1000 | D2320: M3 | E2320: 1000 | G2320: 800 | H2320: Grava Triturada Pomez - Jal 20 mm - 3/4"
A2321: 10273001 | B2321: ZFE3 | C2321: 1000 | D2321: M3 | E2321: 1000 | G2321: 1688 | H2321: MP ARENA TRIT. BASALTO MALLA 4
A2322: 10273002 | B2322: ZFE3 | C2322: 1000 | D2322: M3 | E2322: 1000 | G2322: 1466 | H2322: MP GRAVA TRIT. BASALTO 20 MM - 3/4"
A2323: 10273351 | B2323: ZFE3 | C2323: 1000 | D2323: M3 | E2323: 1000 | G2323: 1612 | H2323: MP ARENA TRIT. CALIZA MALLA 4
A2324: 10273352 | B2324: ZFE3 | C2324: 1000 | D2324: M3 | E2324: 1000 | G2324: 1492 | H2324: MP GRAVA TRIT. CALIZA 20 MM - 3/4"
A2325: 10271724 | B2325: ZFE3 | C2325: 1000 | D2325: M3 | E2325: 1000 | G2325: 1900 | H2325: MP RESIDUO DE CONCRETO
A2326: 10000677 | C2326: 1000 | D2326: M3 | G2326: 1164 | H2326: Grava Triturada Caliza 20 mm - 3/4"
A2327: 10274190 | B2327: ZFE3 | C2327: 1000 | D2327: M3 | E2327: 1000 | G2327: 1800 | H2327: MP BASE HIDRAULICA ANDESITA 70-30
A2328: 10274601 | B2328: ZFE3 | C2328: 1000 | D2328: M3 | E2328: 1000 | G2328: 1447 | H2328: MP ARENA BASALTO N° 4
...

Sheet TRAOPE
A1: Concat1 | B1: Contrato_Pos | C1: Doc. Compras | D1: Pos | E1: Org.compras | F1: Grp-Compr. | G1: Ship From | H1: Nombre SF | I1: Proveedor | J1: Nombre Prov | K1: Cond. Pago | L1: Descr. Cond Pago | M1: Material | N1: Descripción | O1: Centro | P1: Descripción Centro | Q1: In.perído validez | R1: Fin perído validez | S1: Válido de | T1: Validez a | U1: Precio neto pedido | V1: Moneda | W1: UM Precio Pedido | X1: Importe Condición | Y1: Moneda KONP | Z1: UM Ctd Base | AA1: Destino | AB1: Nombre Destino | AC1: Cuenta de mayor | AD1: Centro de costo | AE1: Cond. Exp. | AF1: Descr. Cond. Exp. | AG1: Peso Vol. | AH1: UMB | AI1: Ind. Oblig. Conf. Ped. | AJ1: Ctrl-Conf. | AK1: IVA | AL1: Modif_Date | AM1: Ruta
A2: 900009035D8146731351010173699 | B2: 4600070543-90 | C2: 4600070543 | D2: 90 | E2: MXPO | F2: MXL | G2: 900009035 | H2: SF TP-ED- GRUPO AF | I2: 5094278 | J2: LOGISTICA Y SERVICIOS ESPECIALIZADO | K2: Z09 | L2: (AP) 90 Dias | M2: 10173699 | N2: ARENA CLASIFICADA RIO MALLA 4 LAVADA | O2: D814 | P2: MX-CED. TABASCO | Q2: 20241115 | R2: 20291231 | S2: 20250407 | T2: 20301231 | U2: 212 | V2: MXN | W2: M3 | X2: 137 | Y2: MXN | Z2: M3 | AA2: 67313510 | AB2: OBRA NEXUMRAIL | AC2: 56103638 | AD2: 6622041540 | AE2: 4 | AF2: ENTREGA DIRECTA | AG2: 1.576 | AH2: M3 | AI2: X | AJ2: 4 | AK2: V4 | AL2: 20250410 | AM2: D814-900009035-67313510-10173699-4
A3: 900009035D8146731351010147454 | B3: 4600070543-80 | C3: 4600070543 | D3: 80 | E3: MXPO | F3: MXL | G3: 900009035 | H3: SF TP-ED- GRUPO AF | I3: 5094278 | J3: LOGISTICA Y SERVICIOS ESPECIALIZADO | K3: Z09 | L3: (AP) 90 Dias | M3: 10147454 | N3: GRAVA TRITURADA CALIZA 20 MM - 3/4" | O3: D814 | P3: MX-CED. TABASCO | Q3: 20241115 | R3: 20291231 | S3: 20250407 | T3: 20301231 | U3: 643 | V3: MXN | W3: M3 | X3: 348 | Y3: MXN | Z3: M3 | AA3: 67313510 | AB3: OBRA NEXUMRAIL | AC3: 56103637 | AD3: 6622041540 | AE3: 4 | AF3: ENTREGA DIRECTA | AG3: 1.556 | AH3: M3 | AI3: X | AJ3: 4 | AK3: V4 | AL3: 20250410 | AM3: D814-900009035-67313510-10147454-4
A4: 900006706D8146678288110193885 | B4: 4600047553-120 | C4: 4600047553 | D4: 120 | E4: MXPO | F4: MXL | G4: 900006706 | H4: SF TP-ED-FRISO TEAPA | I4: 5070657 | J4: FRISO SILRO SA DE CV | K4: N90 | L4: (AP) NAFIN 90 Dias | M4: 10193885 | N4: BASE H CALIZA GRIS 1 1/2 PARA PATIO NG | O4: D814 | P4: MX-CED. TABASCO | Q4: 20200717 | R4: 20281231 | S4: 20210504 | T4: 20261231 | U4: 450 | V4: MXN | W4: M3 | X4: 350 | Y4: MXN | Z4: M3 | AA4: 66782881 | AB4: PLANTA HOKCHI | AC4: 56103590 | AD4: 6622041540 | AE4: 4 | AF4: ENTREGA DIRECTA | AG4: 1.52 | AH4: M3 | AI4: X | AJ4: 4 | AK4: V4 | AL4: 20230920 | AM4: D814-900006706-66782881-10193885-4
A5: 900007054D8146694653610197737 | B5: 4600049598-150 | C5: 4600049598 | D5: 150 | E5: MXPO | F5: MXL | G5: 900007054 | H5: SF TP-ED-SAMUEL CARRASCO | I5: 5080454 | J5: CARRASCO ALCUDIA SAMUEL | K5: N90 | L5: (AP) NAFIN 90 Dias | M5: 10197737 | N5: ARENA CLASIFICADA RÍO MALLA 4- NG | O5: D814 | P5: MX-CED. TABASCO | Q5: 20210407 | R5: 20291231 | S5: 20230619 | T5: 20281231 | U5: 470 | V5: MXN | W5: M3 | X5: 350 | Y5: MXN | Z5: M3 | AA5: 66946536 | AB5: P6 - Pulmón - Refinería Dos Bocas | AC5: 56103638 | AD5: 6622041867 | AE5: 4 | AF5: ENTREGA DIRECTA | AG5: 1.55 | AH5: M3 | AI5: X | AJ5: 4 | AK5: V4 | AL5: 20230920 | AM5: D814-900007054-66946536-10197737-4
A6: 900006706D8146700595910147454 | B6: 4600047553-210 | C6: 4600047553 | D6: 210 | E6: MXPO | F6: MXL | G6: 900006706 | H6: SF TP-ED-FRISO TEAPA | I6: 5070657 | J6: FRISO SILRO SA DE CV | K6: N90 | L6: (AP) NAFIN 90 Dias | M6: 10147454 | N6: GRAVA TRITURADA CALIZA 20 MM - 3/4" | O6: D814 | P6: MX-CED. TABASCO | Q6: 20200717 | R6: 20281231 | S6: 20210918 | T6: 20261231 | U6: 400 | V6: MXN | W6: M3 | X6: 190 | Y6: MXN | Z6: M3 | AA6: 67005959 | AB6: INATERRA NUEVO CEDIS WALMART (LVC) | AC6: 56103637 | AD6: 6622041540 | AE6: 4 | AF6: ENTREGA DIRECTA | AG6: 1.556 | AH6: M3 | AI6: X | AJ6: 4 | AK6: V4 | AL6: 20230920 | AM6: D814-900006706-67005959-10147454-4
A7: 900005557D8146655463110116007 | B7: 4600041437-30 | C7: 4600041437 | D7: 30 | E7: MXPO | F7: MXL | G7: 900005557 | H7: TP-ED-DANIEL BECERRA | I7: 5070594 | J7: BECERRA MAYORGA DANIEL | K7: N90 | L7: (AP) NAFIN 90 Dias | M7: 10116007 | N7: PIEDRA BOLA 4" A 6" | O7: D814 | P7: MX-CED. TABASCO | Q7: 20180307 | R7: 20241231 | S7: 20180717 | T7: 20241231 | U7: 700 | V7: MXN | W7: M3 | X7: 350 | Y7: MXN | Z7: M3 | AA7: 66554631 | AC7: 56103591 | AD7: 6622041540 | AE7: 4 | AF7: ENTREGA DIRECTA | AG7: 1.6 | AH7: M3 | AI7: X | AJ7: 4 | AK7: V4 | AL7: 20230920 | AM7: D814-900005557-66554631-10116007-4
A8: 900009035D8146731342610000273 | B8: 4600070543-70 | C8: 4600070543 | D8: 70 | E8: MXPO | F8: MXL | G8: 900009035 | H8: SF TP-ED- GRUPO AF | I8: 5094278 | J8: LOGISTICA Y SERVICIOS ESPECIALIZADO | K8: Z09 | L8: (AP) 90 Dias | M8: 10000273 | N8: Base H Triturada Caliza 3/4" a Finos | O8: D814 | P8: MX-CED. TABASCO | Q8: 20241115 | R8: 20291231 | S8: 20250407 | T8: 20301231 | U8: 660 | V8: MXN | W8: M3 | X8: 360 | Y8: MXN | Z8: M3 | AA8: 67313426 | AB8: OBRA SILVERIO SOSA | AC8: 56103590 | AD8: 6622041540 | AE8: 4 | AF8: ENTREGA DIRECTA | AG8: 1.69 | AH8: M3 | AI8: X | AJ8: 4 | AK8: V4 | AL8: 20250410 | AM8: D814-900009035-67313426-10000273-4
A9: 900004418D81410183939 | B9: 4600038499-110 | C9: 4600038499 | D9: 110 | E9: MXPO | F9: MXL | G9: 900004418 | H9: TP-SIGSA | I9: 5021622 | J9: SERVICIOS DE INGENIERIA DEL GOLFO | K9: N60 | L9: (AP) NAFIN 60 Dias | M9: 10183939 | N9: BASE HIDRÁULICA 1 1/2" A FINOS 70/30 | O9: D814 | P9: MX-CED. TABASCO | Q9: 20170623 | R9: 20281231 | S9: 20231214 | T9: 20281231 | U9: 195 | V9: MXN | W9: M3 | X9: 0 | Y9: MXN | Z9: M3 | AC9: 56103590 | AD9: 6622041540 | AE9: 1 | AF9: ENTREGADO | AG9: 2.136 | AH9: M3 | AI9: X | AJ9: 4 | AK9: V4 | AL9: 20240331 | AM9: D814-900004418-10183939
A10: 900000743D81410166283 | B10: 4600029541-40 | C10: 4600029541 | D10: 40 | E10: MXPO | F10: MXL | G10: 900000743 | H10: TC SIGSA | I10: 5021622 | J10: SERVICIOS DE INGENIERIA DEL GOLFO | K10: N60 | L10: (AP) NAFIN 60 Dias | M10: 10166283 | N10: GRAVA TRITURADA CALIZA 20 MM - 3/4" | O10: D814 | P10: MX-CED. TABASCO | Q10: 20150205 | R10: 20241231 | S10: 20210408 | T10: 20261231 | U10: 234 | V10: MXN | W10: M3 | AC10: 56103637 | AD10: 6622041540 | AE10: 1 | AF10: ENTREGADO | AG10: 1.361 | AH10: M3 | AI10: X | AJ10: 4 | AK10: V4 | AL10: 20230920 | AM10: D814-900000743-10166283
A11: 900006703D81410000373 | B11: 4600048191-40 | C11: 4600048191 | D11: 40 | E11: MXPO | F11: MXL | G11: 900006703 | H11: SF TC- FRISO TEAPA | I11: 5070657 | J11: FRISO SILRO SA DE CV | K11: N90 | L11: (AP) NAFIN 90 Dias | M11: 10000373 | N11: Grava Triturada Caliza 13 mm - 1/2" | O11: D814 | P11: MX-CED. TABASCO | Q11: 20201006 | R11: 20291231 | S11: 20210526 | T11: 20261231 | U11: 480 | V11: MXN | W11: M3 | AC11: 56103637 | AD11: 6622041540 | AE11: 1 | AF11: ENTREGADO | AG11: 1.395 | AH11: M3 | AI11: X | AJ11: 4 | AK11: V4 | AL11: 20230920 | AM11: D814-900006703-10000373
A12: 900009316D81410147454 | B12: 4600071857-10 | C12: 4600071857 | D12: 10 | E12: MXPO | F12: MXL | G12: 900009316 | H12: SF TP FRISO STONE | I12: 5096328 | J12: FRISO STONE SCP DE B Y S RL DE CV | K12: N90 | L12: (AP) NAFIN 90 Dias | M12: 10147454 | N12: GRAVA TRITURADA CALIZA 20 MM - 3/4" | O12: D814 | P12: MX-CED. TABASCO | Q12: 20251211 | R12: 20301231 | S12: 20251211 | T12: 20301231 | U12: 287 | V12: MXN | W12: M3 | X12: 0 | Y12: MXN | Z12: M3 | AC12: 56103637 | AD12: 6622041540 | AE12: 1 | AF12: ENTREGADO | AG12: 1.556 | AH12: M3 | AI12: X | AJ12: 4 | AK12: V4 | AL12: 20251219 | AM12: D814-900009316-10147454
A13: 900006409D8146658035110147454 | B13: 4600071076-10 | C13: 4600071076 | D13: 10 | E13: MXPO | F13: MXL | G13: 900006409 | H13: SF TP-ED-GOLPAC | I13: 5041845 | J13: CONSTRUCCIONES Y URBANIZACIONES | K13: Z03 | L13: (AP) 15 Dias | M13: 10147454 | N13: GRAVA TRITURADA CALIZA 20 MM - 3/4" | O13: D814 | P13: MX-CED. TABASCO | Q13: 20250325 | R13: 20301231 | S13: 20250325 | T13: 20301231 | U13: 450 | V13: MXN | W13: M3 | X13: 155 | Y13: MXN | Z13: M3 | AA13: 66580351 | AB13: COLVI VILLAHERMOSA | AC13: 56103637 | AD13: 6622041540 | AE13: 4 | AF13: ENTREGA DIRECTA | AG13: 1.556 | AH13: M3 | AI13: X | AJ13: 4 | AK13: V4 | AL13: 20250328 | AM13: D814-900006409-66580351-10147454-4
A14: 900004418D81410059808 | B14: 4600038499-20 | C14: 4600038499 | D14: 20 | E14: MXPO | F14: MXL | G14: 900004418 | H14: TP-SIGSA | I14: 5021622 | J14: SERVICIOS DE INGENIERIA DEL GOLFO | K14: N60 | L14: (AP) NAFIN 60 Dias | M14: 10059808 | N14: SUB-BASE DE 1 ½” A FINOS | O14: D814 | P14: MX-CED. TABASCO | Q14: 20170623 | R14: 20281231 | S14: 20180314 | T14: 20241231 | U14: 107 | V14: MXN | W14: M3 | X14: 0 | Y14: MXN | Z14: M3 | AC14: 56103590 | AD14: 6622041540 | AE14: 1 | AF14: ENTREGADO | AG14: 1.65 | AH14: M3 | AI14: X | AJ14: 4 | AK14: V4 | AL14: 20230920 | AM14: D814-900004418-10059808
A15: 900003902D81410000834 | B15: 4600040799-10 | C15: 4600040799 | D15: 10 | E15: MXPO | F15: MXL | G15: 900003902 | H15: TP ESCUDERO AGUILAR | I15: 5014480 | J15: ESCUDERO AGUILAR ANDRES | K15: N90 | L15: (AP) NAFIN 90 Dias | M15: 10000834 | N15: Arena Clasificada Río Malla 4 | O15: D814 | P15: MX-CED. TABASCO | Q15: 20171228 | R15: 20281231 | S15: 20220404 | T15: 20271231 | U15: 53 | V15: MXN | W15: M3 | X15: 0 | Y15: MXN | Z15: M3 | AC15: 56103638 | AD15: 6622041540 | AE15: 1 | AF15: ENTREGADO | AG15: 1.273 | AH15: M3 | AI15: X | AJ15: 4 | AK15: V4 | AL15: 20230920 | AM15: D814-900003902-10000834
A16: 900003902D81410079650 | B16: 4600040799-20 | C16: 4600040799 | D16: 20 | E16: MXPO | F16: MXL | G16: 900003902 | H16: TP ESCUDERO AGUILAR | I16: 5014480 | J16: ESCUDERO AGUILAR ANDRES | K16: N90 | L16: (AP) NAFIN 90 Dias | M16: 10079650 | N16: ARENA DE RIO MALLA 4 | O16: D814 | P16: MX-CED. TABASCO | Q16: 20171228 | R16: 20281231 | S16: 20230515 | T16: 20281231 | U16: 66 | V16: MXN | W16: M3 | X16: 0 | Y16: MXN | Z16: M3 | AC16: 56103638 | AD16: 6622041540 | AE16: 1 | AF16: ENTREGADO | AG16: 1.448 | AH16: M3 | AI16: X | AJ16: 4 | AK16: V4 | AL16: 20230920 | AM16: D814-900003902-10079650
A17: 900005888D81410000561 | B17: 4600043667-20 | C17: 4600043667 | D17: 20 | E17: MXPO | F17: MXL | G17: 900005888 | H17: SF TP-FERMIN SABIAUR | I17: 5073829 | J17: SABIAUR PEREZ FERMIN | K17: N90 | L17: (AP) NAFIN 90 Dias | M17: 10000561 | N17: Grava Triturada Caliza 20 mm - 3/4" | O17: D814 | P17: MX-CED. TABASCO | Q17: 20181217 | R17: 20281231 | S17: 20190919 | T17: 20241231 | U17: 175 | V17: MXN | W17: M3 | X17: 0 | Y17: MXN | Z17: M3 | AC17: 56103637 | AD17: 6622041540 | AE17: 1 | AF17: ENTREGADO | AG17: 1.43 | AH17: M3 | AI17: X | AJ17: 4 | AK17: V4 | AL17: 20230920 | AM17: D814-900005888-10000561
A18: 900006705D81410123034 | B18: 4600047626-50 | C18: 4600047626 | D18: 50 | E18: MXPO | F18: MXL | G18: 900006705 | H18: SF TP- FRISO TEAPA | I18: 5070657 | J18: FRISO SILRO SA DE CV | K18: N90 | L18: (AP) NAFIN 90 Dias | M18: 10123034 | N18: ARENA TRITURADA CALIZA MALLA 4 | O18: D814 | P18: MX-CED. TABASCO | Q18: 20200727 | R18: 20281231 | S18: 20230106 | T18: 20271231 | U18: 150 | V18: MXN | W18: M3 | X18: 0 | Y18: MXN | Z18: M3 | AC18: 56103638 | AD18: 6622041540 | AE18: 1 | AF18: ENTREGADO | AG18: 1.528 | AH18: M3 | AI18: X | AJ18: 4 | AK18: V4 | AL18: 20230920 | AM18: D814-900006705-10123034
A19: 900006705D81410191484 | B19: 4600047626-60 | C19: 4600047626 | D19: 60 | E19: MXPO | F19: MXL | G19: 900006705 | H19: SF TP- FRISO TEAPA | I19: 5070657 | J19: FRISO SILRO SA DE CV | K19: N90 | L19: (AP) NAFIN 90 Dias | M19: 10191484 | N19: ARENA TRITURADA CALIZA MALLA 4-NG | O19: D814 | P19: MX-CED. TABASCO | Q19: 20200727 | R19: 20281231 | S19: 20230106 | T19: 20271231 | U19: 150 | V19: MXN | W19: M3 | X19: 0 | Y19: MXN | Z19: M3 | AC19: 56103638 | AD19: 6622041540 | AE19: 1 | AF19: ENTREGADO | AG19: 1.3 | AH19: M3 | AI19: X | AJ19: 4 | AK19: V4 | AL19: 20230920 | AM19: D814-900006705-10191484
A20: 900006321D81410191076 | B20: 4600047726-30 | C20: 4600047726 | D20: 30 | E20: MXPO | F20: MXL | G20: 900006321 | H20: SF TP-LBE SAMARIA TABASCO | I20: 5076625 | J20: LBE CONSTRUCTORES SA DE CV | K20: N90 | L20: (AP) NAFIN 90 Dias | M20: 10191076 | N20: ARENA RIO LIMOSA NG | O20: D814 | P20: MX-CED. TABASCO | Q20: 20200806 | R20: 20271231 | S20: 20230123 | T20: 20271231 | U20: 52 | V20: MXN | W20: M3 | X20: 0 | Y20: MXN | Z20: M3 | AC20: 56103638 | AD20: 6622041540 | AE20: 1 | AF20: ENTREGADO | AG20: 1.52 | AH20: M3 | AI20: X | AJ20: 4 | AK20: V4 | AL20: 20230920 | AM20: D814-900006321-10191076
A21: 900006815D81410079650 | B21: 4600048233-10 | C21: 4600048233 | D21: 10 | E21: MXPO | F21: MXL | G21: 900006815 | H21: SF TP-CAPASA | I21: 5079230 | J21: CONSTRUCCION ARRENDAMIENTOS | K21: N90 | L21: (AP) NAFIN 90 Dias | M21: 10079650 | N21: ARENA DE RIO MALLA 4 | O21: D814 | P21: MX-CED. TABASCO | Q21: 20201009 | R21: 20291231 | S21: 20220607 | T21: 20271231 | U21: 60 | V21: MXN | W21: M3 | X21: 0 | Y21: MXN | Z21: M3 | AC21: 56103638 | AD21: 6622041540 | AE21: 1 | AF21: ENTREGADO | AG21: 1.448 | AH21: M3 | AI21: X | AJ21: 4 | AK21: V4 | AL21: 20230920 | AM21: D814-900006815-10079650
A22: 900004418D81410000561 | B22: 4600038499-60 | C22: 4600038499 | D22: 60 | E22: MXPO | F22: MXL | G22: 900004418 | H22: TP-SIGSA | I22: 5021622 | J22: SERVICIOS DE INGENIERIA DEL GOLFO | K22: N60 | L22: (AP) NAFIN 60 Dias | M22: 10000561 | N22: Grava Triturada Caliza 20 mm - 3/4" | O22: D814 | P22: MX-CED. TABASCO | Q22: 20170623 | R22: 20281231 | S22: 20220615 | T22: 20271231 | U22: 250 | V22: MXN | W22: M3 | X22: 0 | Y22: MXN | Z22: M3 | AC22: 56103637 | AD22: 6622041540 | AE22: 1 | AF22: ENTREGADO | AG22: 1.43 | AH22: M3 | AI22: X | AJ22: 4 | AK22: V4 | AL22: 20230920 | AM22: D814-900004418-10000561
A23: 900006236D81410151600 | B23: 4600045630-10 | C23: 4600045630 | D23: 10 | E23: MXPO | F23: MXL | G23: 900006236 | H23: SF TC-VYCSA F SABIAUR | I23: 5073829 | J23: SABIAUR PEREZ FERMIN | K23: N90 | L23: (AP) NAFIN 90 Dias | M23: 10151600 | N23: GRAVA TRITURADA CALIZA 40 MM - 1 1/2" | O23: D814 | P23: MX-CED. TABASCO | Q23: 20190925 | R23: 20241231 | S23: 20190925 | T23: 20241231 | U23: 240 | V23: MXN | W23: M3 | X23: 0 | Y23: MXN | Z23: M3 | AC23: 56103637 | AD23: 6622041540 | AE23: 1 | AF23: ENTREGADO | AG23: 1.398 | AH23: M3 | AI23: X | AJ23: 4 | AK23: V4 | AL23: 20230920 | AM23: D814-900006236-10151600
A24: 900006705D81410000421 | B24: 4600047626-30 | C24: 4600047626 | D24: 30 | E24: MXPO | F24: MXL | G24: 900006705 | H24: SF TP- FRISO TEAPA | I24: 5070657 | J24: FRISO SILRO SA DE CV | K24: N90 | L24: (AP) NAFIN 90 Dias | M24: 10000421 | N24: Grava Triturada Caliza 40 mm - 1 1/2" | O24: D814 | P24: MX-CED. TABASCO | Q24: 20200727 | R24: 20281231 | S24: 20220726 | T24: 20271231 | U24: 220 | V24: MXN | W24: M3 | X24: 0 | Y24: MXN | Z24: M3 | AC24: 56103637 | AD24: 6622041540 | AE24: 1 | AF24: ENTREGADO | AG24: 1.496 | AH24: M3 | AI24: X | AJ24: 4 | AK24: V4 | AL24: 20230920 | AM24: D814-900006705-10000421
A25: 900005888D81410191175 | B25: 4600043667-30 | C25: 4600043667 | D25: 30 | E25: MXPO | F25: MXL | G25: 900005888 | H25: SF TP-FERMIN SABIAUR | I25: 5073829 | J25: SABIAUR PEREZ FERMIN | K25: N90 | L25: (AP) NAFIN 90 Dias | M25: 10191175 | N25: GRAVA TRITURADA CALIZA 40MM - 1 1/2 NG | O25: D814 | P25: MX-CED. TABASCO | Q25: 20181217 | R25: 20281231 | S25: 20230316 | T25: 20281231 | U25: 354.9 | V25: MXN | W25: M3 | X25: 0 | Y25: MXN | Z25: M3 | AC25: 56103637 | AD25: 6622041540 | AE25: 1 | AF25: ENTREGADO | AG25: 1.72 | AH25: M3 | AI25: X | AJ25: 4 | AK25: V4 | AL25: 20230920 | AM25: D814-900005888-10191175
... A28: 900004418D81410123034 | B28: 4600038499-90 | C28: 4600038499 | D28: 90 | E28: MXPO | F28: MXL | G28: 900004418 | H28: TP-SIGSA | I28: 5021622 | J28: SERVICIOS DE INGENIERIA DEL GOLFO | K28: N60 | L28: (AP) NAFIN 60 Dias | M28: 10123034 | N28: ARENA TRITURADA CALIZA MALLA 4 | O28: D814 | P28: MX-CED. TABASCO | Q28: 20170623 | R28: 20281231 | S28: 20230317 | T28: 20281231 | U28: 200 | V28: MXN | W28: M3 | X28: 0 | Y28: MXN | Z28: M3 | AC28: 56103638 | AD28: 6622041540 | AE28: 1 | AF28: ENTREGADO | AG28: 1.528 | AH28: M3 | AI28: X | AJ28: 4 | AK28: V4 | AL28: 20230920 | AM28: D814-900004418-10123034
A29: 900003735D8146664759010000541 | B29: 4600041691-50 | C29: 4600041691 | D29: 50 | E29: MXPO | F29: MXL | G29: 900003735 | H29: TP-ED-LAZCANO HUERTA | I29: 5000326 | J29: LAZCANO HUERTA ROCIO NANCY | K29: Z09 | L29: (AP) 90 Dias | M29: 10000541 | N29: Grava Clasificada Río 10 mm - 3/8" | O29: D814 | P29: MX-CED. TABASCO | Q29: 20180405 | R29: 20241231 | S29: 20200128 | T29: 20291231 | U29: 368.42 | V29: MXN | W29: M3 | X29: 0 | Y29: MXN | Z29: M3 | AA29: 66647590 | AB29: CP-I CLUSTER 7 ANRROCA (CISP) | AC29: 56103637 | AD29: 6622041540 | AE29: 4 | AF29: ENTREGA DIRECTA | AG29: 1.528 | AH29: M3 | AI29: X | AJ29: 4 | AK29: V4 | AL29: 20230920 | AM29: D814-900003735-66647590-10000541-4
A30: 900005888D81410001643 | B30: 4600043667-10 | C30: 4600043667 | D30: 10 | E30: MXPO | F30: MXL | G30: 900005888 | H30: SF TP-FERMIN SABIAUR | I30: 5073829 | J30: SABIAUR PEREZ FERMIN | K30: N90 | L30: (AP) NAFIN 90 Dias | M30: 10001643 | N30: Crudo Clasificado Río | O30: D814 | P30: MX-CED. TABASCO | Q30: 20181217 | R30: 20281231 | S30: 20190201 | T30: 20241231 | U30: 320 | V30: MXN | W30: M3 | X30: 0 | Y30: MXN | Z30: M3 | AC30: 56103636 | AD30: 6622041540 | AE30: 1 | AF30: ENTREGADO | AG30: 1.48 | AH30: M3 | AI30: X | AJ30: 4 | AK30: V4 | AL30: 20230920 | AM30: D814-900005888-10001643
A31: 900006705D81410147454 | B31: 4600047626-10 | C31: 4600047626 | D31: 10 | E31: MXPO | F31: MXL | G31: 900006705 | H31: SF TP- FRISO TEAPA | I31: 5070657 | J31: FRISO SILRO SA DE CV | K31: N90 | L31: (AP) NAFIN 90 Dias | M31: 10147454 | N31: GRAVA TRITURADA CALIZA 20 MM - 3/4" | O31: D814 | P31: MX-CED. TABASCO | Q31: 20200727 | R31: 20281231 | S31: 20230726 | T31: 20281231 | U31: 254 | V31: MXN | W31: M3 | X31: 0 | Y31: MXN | Z31: M3 | AC31: 56103637 | AD31: 6622041540 | AE31: 1 | AF31: ENTREGADO | AG31: 1.556 | AH31: M3 | AI31: X | AJ31: 4 | AK31: V4 | AL31: 20230920 | AM31: D814-900006705-10147454
A32: 900004418D81410047545 | B32: 4600038499-40 | C32: 4600038499 | D32: 40 | E32: MXPO | F32: MXL | G32: 900004418 | H32: TP-SIGSA | I32: 5021622 | J32: SERVICIOS DE INGENIERIA DEL GOLFO | K32: N60 | L32: (AP) NAFIN 60 Dias | M32: 10047545 | N32: Grava Triturada Caliza 20 mm - 3/4" -B | O32: D814 | P32: MX-CED. TABASCO | Q32: 20170623 | R32: 20281231 | S32: 20191108 | T32: 20241231 | U32: 175 | V32: MXN | W32: M3 | X32: 0 | Y32: MXN | Z32: M3 | AC32: 56103637 | AD32: 6622041540 | AE32: 1 | AF32: ENTREGADO | AG32: 1.46 | AH32: M3 | AI32: X | AJ32: 4 | AK32: V4 | AL32: 20230920 | AM32: D814-900004418-10047545
A33: 900004418D81410047545 | B33: 4600038499-80 | C33: 4600038499 | D33: 80 | E33: MXPO | F33: MXL | G33: 900004418 | H33: TP-SIGSA | I33: 5021622 | J33: SERVICIOS DE INGENIERIA DEL GOLFO | K33: N60 | L33: (AP) NAFIN 60 Dias | M33: 10047545 | N33: Grava Triturada Caliza 20 mm - 3/4" -B | O33: D814 | P33: MX-CED. TABASCO | Q33: 20170623 | R33: 20281231 | S33: 20211215 | T33: 20261231 | U33: 234 | V33: MXN | W33: M3 | X33: 0 | Y33: MXN | Z33: M3 | AC33: 56103637 | AD33: 6622041540 | AE33: 2 | AF33: RECOGIDO | AG33: 1.46 | AH33: M3 | AI33: X | AJ33: 4 | AK33: V4 | AL33: 20230920 | AM33: D814-900004418-10047545
A34: 900006321D81410079650 | B34: 4600047726-10 | C34: 4600047726 | D34: 10 | E34: MXPO | F34: MXL | G34: 900006321 | H34: SF TP-LBE SAMARIA TABASCO | I34: 5076625 | J34: LBE CONSTRUCTORES SA DE CV | K34: N90 | L34: (AP) NAFIN 90 Dias | M34: 10079650 | N34: ARENA DE RIO MALLA 4 | O34: D814 | P34: MX-CED. TABASCO | Q34: 20200806 | R34: 20271231 | S34: 20220404 | T34: 20271231 | U34: 51 | V34: MXN | W34: M3 | X34: 0 | Y34: MXN | Z34: M3 | AC34: 56103638 | AD34: 6622041540 | AE34: 1 | AF34: ENTREGADO | AG34: 1.448 | AH34: M3 | AI34: X | AJ34: 4 | AK34: V4 | AL34: 20230920 | AM34: D814-900006321-10079650
A35: 900007620D81410197438 | B35: 4600054015-20 | C35: 4600054015 | D35: 20 | E35: MXPO | F35: MXL | G35: 900007620 | H35: SF TP-FRISO CONSMIN TAB | I35: 5083592 | J35: FRISO CONSMIN SA DE CV | K35: N45 | L35: (AP) NAFIN 45 Dias | M35: 10197438 | N35: BASE H CALIZA 1 1/2" A FINOS ESPECIAL | O35: D814 | P35: MX-CED. TABASCO | Q35: 20220519 | R35: 20291231 | S35: 20230426 | T35: 20281231 | U35: 230 | V35: MXN | W35: M3 | X35: 0 | Y35: MXN | Z35: M3 | AC35: 56103590 | AD35: 6622041540 | AE35: 1 | AF35: ENTREGADO | AG35: 1.65 | AH35: M3 | AI35: X | AJ35: 4 | AK35: V4 | AL35: 20230920 | AM35: D814-900007620-10197438
A36: 900006321D81410210039 | B36: 4600053374-10 | C36: 4600053374 | D36: 10 | E36: MXPO | F36: MXL | G36: 900006321 | H36: SF TP-LBE SAMARIA TABASCO | I36: 5076625 | J36: LBE CONSTRUCTORES SA DE CV | K36: N90 | L36: (AP) NAFIN 90 Dias | M36: 10210039 | N36: ARENA CLASIFICADA RÍO MALLA 4 | O36: D814 | P36: MX-CED. TABASCO | Q36: 20220304 | R36: 20271231 | S36: 20220304 | T36: 20271231 | U36: 47 | V36: MXN | W36: M3 | X36: 0 | Y36: MXN | Z36: M3 | AC36: 56103638 | AD36: 6622041540 | AE36: 1 | AF36: ENTREGADO | AG36: 1.485 | AH36: M3 | AI36: X | AJ36: 4 | AK36: V4 | AL36: 20230920 | AM36: D814-900006321-10210039
A37: 900007620D81410047545 | B37: 4600054015-50 | C37: 4600054015 | D37: 50 | E37: MXPO | F37: MXL | G37: 900007620 | H37: SF TP-FRISO CONSMIN TAB | I37: 5083592 | J37: FRISO CONSMIN SA DE CV | K37: N45 | L37: (AP) NAFIN 45 Dias | M37: 10047545 | N37: Grava Triturada Caliza 20 mm - 3/4" -B | O37: D814 | P37: MX-CED. TABASCO | Q37: 20220519 | R37: 20291231 | S37: 20230416 | T37: 20281231 | U37: 252 | V37: MXN | W37: M3 | X37: 0 | Y37: MXN | Z37: M3 | AC37: 56103637 | AD37: 6622041540 | AE37: 1 | AF37: ENTREGADO | AG37: 1.46 | AH37: M3 | AI37: X | AJ37: 4 | AK37: V4 | AL37: 20230920 | AM37: D814-900007620-10047545
A38: 900006706D8146688714110193744 | B38: 4600047553-60 | C38: 4600047553 | D38: 60 | E38: MXPO | F38: MXL | G38: 900006706 | H38: SF TP-ED-FRISO TEAPA | I38: 5070657 | J38: FRISO SILRO SA DE CV | K38: N90 | L38: (AP) NAFIN 90 Dias | M38: 10193744 | N38: PIEDRA CALIZA BLANCA 2 1/2 A 3 - NG | O38: D814 | P38: MX-CED. TABASCO | Q38: 20200717 | R38: 20281231 | S38: 20210302 | T38: 20291231 | U38: 480 | V38: MXN | W38: M3 | X38: 380 | Y38: MXN | Z38: M3 | AA38: 66887141 | AB38: Tanque T3 Refinería Dos Bocas | AC38: 56103637 | AD38: 6622041540 | AE38: 4 | AF38: ENTREGA DIRECTA | AG38: 1.56 | AH38: M3 | AI38: X | AJ38: 4 | AK38: V4 | AL38: 20230920 | AM38: D814-900006706-66887141-10193744-4
A39: 900006706D8146694653610193744 | B39: 4600047553-70 | C39: 4600047553 | D39: 70 | E39: MXPO | F39: MXL | G39: 900006706 | H39: SF TP-ED-FRISO TEAPA | I39: 5070657 | J39: FRISO SILRO SA DE CV | K39: N90 | L39: (AP) NAFIN 90 Dias | M39: 10193744 | N39: PIEDRA CALIZA BLANCA 2 1/2 A 3 - NG | O39: D814 | P39: MX-CED. TABASCO | Q39: 20200717 | R39: 20281231 | S39: 20210316 | T39: 20291231 | U39: 480 | V39: MXN | W39: M3 | X39: 380 | Y39: MXN | Z39: M3 | AA39: 66946536 | AB39: P6 - Pulmón - Refinería Dos Bocas | AC39: 56103637 | AD39: 6622041540 | AE39: 4 | AF39: ENTREGA DIRECTA | AG39: 1.56 | AH39: M3 | AI39: X | AJ39: 4 | AK39: V4 | AL39: 20230920 | AM39: D814-900006706-66946536-10193744-4
A40: 900006706D8146687594810191175 | B40: 4600047553-110 | C40: 4600047553 | D40: 110 | E40: MXPO | F40: MXL | G40: 900006706 | H40: SF TP-ED-FRISO TEAPA | I40: 5070657 | J40: FRISO SILRO SA DE CV | K40: N90 | L40: (AP) NAFIN 90 Dias | M40: 10191175 | N40: GRAVA TRITURADA CALIZA 40MM - 1 1/2 NG | O40: D814 | P40: MX-CED. TABASCO | Q40: 20200717 | R40: 20281231 | S40: 20210406 | T40: 20261231 | U40: 480 | V40: MXN | W40: M3 | X40: 330 | Y40: MXN | Z40: M3 | AA40: 66875948 | AB40: COGENERACIÓN TECHINT REF | AC40: 56103637 | AD40: 6622041540 | AE40: 4 | AF40: ENTREGA DIRECTA | AG40: 1.72 | AH40: M3 | AI40: X | AJ40: 4 | AK40: V4 | AL40: 20230920 | AM40: D814-900006706-66875948-10191175-4
A41: 900006706D8146694653610000372 | B41: 4600047553-270 | C41: 4600047553 | D41: 270 | E41: MXPO | F41: MXL | G41: 900006706 | H41: SF TP-ED-FRISO TEAPA | I41: 5070657 | J41: FRISO SILRO SA DE CV | K41: N90 | L41: (AP) NAFIN 90 Dias | M41: 10000372 | N41: Grava Triturada Caliza 20 mm - 3/4" | O41: D814 | P41: MX-CED. TABASCO | Q41: 20200717 | R41: 20281231 | S41: 20220104 | T41: 20271231 | U41: 495 | V41: MXN | W41: M3 | X41: 330 | Y41: MXN | Z41: M3 | AA41: 66946536 | AB41: P6 - Pulmón - Refinería Dos Bocas | AC41: 56103637 | AD41: 6622041540 | AE41: 4 | AF41: ENTREGA DIRECTA | AG41: 1.448 | AH41: M3 | AI41: X | AJ41: 4 | AK41: V4 | AL41: 20230920 | AM41: D814-900006706-66946536-10000372-4
A42: 900007054D8146687594810000372 | B42: 4600049598-80 | C42: 4600049598 | D42: 80 | E42: MXPO | F42: MXL | G42: 900007054 | H42: SF TP-ED-SAMUEL CARRASCO | I42: 5080454 | J42: CARRASCO ALCUDIA SAMUEL | K42: N90 | L42: (AP) NAFIN 90 Dias | M42: 10000372 | N42: Grava Triturada Caliza 20 mm - 3/4" | O42: D814 | P42: MX-CED. TABASCO | Q42: 20210407 | R42: 20291231 | S42: 20220131 | T42: 20261231 | U42: 550 | V42: MXN | W42: M3 | X42: 380 | Y42: MXN | Z42: M3 | AA42: 66875948 | AB42: COGENERACIÓN TECHINT REF | AC42: 56103637 | AD42: 6622041540 | AE42: 4 | AF42: ENTREGA DIRECTA | AG42: 1.448 | AH42: M3 | AI42: X | AJ42: 4 | AK42: V4 | AL42: 20230920 | AM42: D814-900007054-66875948-10000372-4
...
