Workbook

Sheet Base Cedis D876
N1: VENTA | Q1: COSTO
A2: CONCAT1 | B2: CONCAT2 | C2: No. SF | D2: Nombre SF | E2: Cedis | F2: Destino | G2: Condicion de Expedicion | H2: Nombre Destino | I2: No. de material | J2: Nombre de material | K2: PV | L2: Inicio de vigencia | M2: Fin de vigencia | N2: Importe MP | O2: Importe Flete | P2: UM Venta | Q2: Importe Costo | R2: UM Costo | S2: Validacion 1 | T2: Validacion 2
A3: =CONCATENATE(C3,E3,F3,I3) | B3: =CONCATENATE(C3,E3,I3) | C3: 900005951 | D3: =IFERROR(VLOOKUP(C3,TRAOPE!$G:$H,2,0),"") | E3: D876 | F3: DG66 | G3: =IFERROR(VLOOKUP(A3,Flete!$A:$E,5,0),"") | H3: =IFERROR(VLOOKUP(F3,TRAOPE!$AA:$AB,2,0),"") | I3: 10138757 | J3: =IFERROR(VLOOKUP(I3,Materiales!$A:$H,8,0),"") | K3: =IFERROR(VLOOKUP(I3,Materiales!$A:$G,7,0),"") | L3: 20170210 | M3: 20241023 | N3: 54.55 | O3: =IFERROR(VLOOKUP(A3,Flete!$A:$J,10,0),"") | P3: TN | Q3: =IFERROR(IFERROR(VLOOKUP(A3,TRAOPE!$A:$U,21,0),VLOOKUP(B3,TRAOPE!$A:$U,21,0)),"") | R3: =IFERROR(IFERROR(VLOOKUP(A3,TRAOPE!$A:$W,23,0),VLOOKUP(B3,TRAOPE!$A:$W,23,0)),"") | S3: =IF(AND(P3="TN",R3="TN"),N3+N(O3),IF(G3&""="1",N(K3)*N3,(N3+N(O3))*N(K3))) | T3: =IF(Q3="","",Q3-S3)
A4: =CONCATENATE(C4,E4,F4,I4) | B4: =CONCATENATE(C4,E4,I4) | C4: 900005952 | D4: =IFERROR(VLOOKUP(C4,TRAOPE!$G:$H,2,0),"") | E4: D876 | F4: 65268112 | G4: =IFERROR(VLOOKUP(A4,Flete!$A:$E,5,0),"") | H4: =IFERROR(VLOOKUP(F4,TRAOPE!$AA:$AB,2,0),"") | I4: 10138757 | J4: =IFERROR(VLOOKUP(I4,Materiales!$A:$H,8,0),"") | K4: =IFERROR(VLOOKUP(I4,Materiales!$A:$G,7,0),"") | L4: 20170210 | M4: 20241023 | N4: 77.47 | O4: =IFERROR(VLOOKUP(A4,Flete!$A:$J,10,0),"") | P4: M3 | Q4: =IFERROR(IFERROR(VLOOKUP(A4,TRAOPE!$A:$U,21,0),VLOOKUP(B4,TRAOPE!$A:$U,21,0)),"") | R4: =IFERROR(IFERROR(VLOOKUP(A4,TRAOPE!$A:$W,23,0),VLOOKUP(B4,TRAOPE!$A:$W,23,0)),"") | S4: =IF(AND(P4="TN",R4="TN"),N4+N(O4),IF(G4&""="1",N(K4)*N4,(N4+N(O4))*N(K4))) | T4: =IF(Q4="","",Q4-S4)
A5: =CONCATENATE(C5,E5,F5,I5) | B5: =CONCATENATE(C5,E5,I5) | C5: 900005952 | D5: =IFERROR(VLOOKUP(C5,TRAOPE!$G:$H,2,0),"") | E5: D876 | F5: 65317027 | G5: =IFERROR(VLOOKUP(A5,Flete!$A:$E,5,0),"") | H5: =IFERROR(VLOOKUP(F5,TRAOPE!$AA:$AB,2,0),"") | I5: 10138757 | J5: =IFERROR(VLOOKUP(I5,Materiales!$A:$H,8,0),"") | K5: =IFERROR(VLOOKUP(I5,Materiales!$A:$G,7,0),"") | L5: 20170210 | M5: 20241023 | N5: 77.47 | O5: =IFERROR(VLOOKUP(A5,Flete!$A:$J,10,0),"") | P5: M3 | Q5: =IFERROR(IFERROR(VLOOKUP(A5,TRAOPE!$A:$U,21,0),VLOOKUP(B5,TRAOPE!$A:$U,21,0)),"") | R5: =IFERROR(IFERROR(VLOOKUP(A5,TRAOPE!$A:$W,23,0),VLOOKUP(B5,TRAOPE!$A:$W,23,0)),"") | S5: =IF(AND(P5="TN",R5="TN"),N5+N(O5),IF(G5&""="1",N(K5)*N5,(N5+N(O5))*N(K5))) | T5: =IF(Q5="","",Q5-S5)
A6: =CONCATENATE(C6,E6,F6,I6) | B6: =CONCATENATE(C6,E6,I6) | C6: 900005952 | D6: =IFERROR(VLOOKUP(C6,TRAOPE!$G:$H,2,0),"") | E6: D876 | F6: 66605648 | G6: =IFERROR(VLOOKUP(A6,Flete!$A:$E,5,0),"") | H6: =IFERROR(VLOOKUP(F6,TRAOPE!$AA:$AB,2,0),"") | I6: 10138757 | J6: =IFERROR(VLOOKUP(I6,Materiales!$A:$H,8,0),"") | K6: =IFERROR(VLOOKUP(I6,Materiales!$A:$G,7,0),"") | L6: 20170210 | M6: 20241023 | N6: 77.47 | O6: =IFERROR(VLOOKUP(A6,Flete!$A:$J,10,0),"") | P6: M3 | Q6: =IFERROR(IFERROR(VLOOKUP(A6,TRAOPE!$A:$U,21,0),VLOOKUP(B6,TRAOPE!$A:$U,21,0)),"") | R6: =IFERROR(IFERROR(VLOOKUP(A6,TRAOPE!$A:$W,23,0),VLOOKUP(B6,TRAOPE!$A:$W,23,0)),"") | S6: =IF(AND(P6="TN",R6="TN"),N6+N(O6),IF(G6&""="1",N(K6)*N6,(N6+N(O6))*N(K6))) | T6: =IF(Q6="","",Q6-S6)
A7: =CONCATENATE(C7,E7,F7,I7) | B7: =CONCATENATE(C7,E7,I7) | C7: 900005953 | D7: =IFERROR(VLOOKUP(C7,TRAOPE!$G:$H,2,0),"") | E7: D876 | F7: 65268112 | G7: =IFERROR(VLOOKUP(A7,Flete!$A:$E,5,0),"") | H7: =IFERROR(VLOOKUP(F7,TRAOPE!$AA:$AB,2,0),"") | I7: 10138757 | J7: =IFERROR(VLOOKUP(I7,Materiales!$A:$H,8,0),"") | K7: =IFERROR(VLOOKUP(I7,Materiales!$A:$G,7,0),"") | L7: 20190220 | M7: 20241023 | N7: 76.89 | O7: =IFERROR(VLOOKUP(A7,Flete!$A:$J,10,0),"") | P7: M3 | Q7: =IFERROR(IFERROR(VLOOKUP(A7,TRAOPE!$A:$U,21,0),VLOOKUP(B7,TRAOPE!$A:$U,21,0)),"") | R7: =IFERROR(IFERROR(VLOOKUP(A7,TRAOPE!$A:$W,23,0),VLOOKUP(B7,TRAOPE!$A:$W,23,0)),"") | S7: =IF(AND(P7="TN",R7="TN"),N7+N(O7),IF(G7&""="1",N(K7)*N7,(N7+N(O7))*N(K7))) | T7: =IF(Q7="","",Q7-S7)
A8: =CONCATENATE(C8,E8,F8,I8) | B8: =CONCATENATE(C8,E8,I8) | C8: 900005953 | D8: =IFERROR(VLOOKUP(C8,TRAOPE!$G:$H,2,0),"") | E8: D876 | F8: 65317027 | G8: =IFERROR(VLOOKUP(A8,Flete!$A:$E,5,0),"") | H8: =IFERROR(VLOOKUP(F8,TRAOPE!$AA:$AB,2,0),"") | I8: 10138757 | J8: =IFERROR(VLOOKUP(I8,Materiales!$A:$H,8,0),"") | K8: =IFERROR(VLOOKUP(I8,Materiales!$A:$G,7,0),"") | L8: 20190220 | M8: 20241023 | N8: 76.89 | O8: =IFERROR(VLOOKUP(A8,Flete!$A:$J,10,0),"") | P8: M3 | Q8: =IFERROR(IFERROR(VLOOKUP(A8,TRAOPE!$A:$U,21,0),VLOOKUP(B8,TRAOPE!$A:$U,21,0)),"") | R8: =IFERROR(IFERROR(VLOOKUP(A8,TRAOPE!$A:$W,23,0),VLOOKUP(B8,TRAOPE!$A:$W,23,0)),"") | S8: =IF(AND(P8="TN",R8="TN"),N8+N(O8),IF(G8&""="1",N(K8)*N8,(N8+N(O8))*N(K8))) | T8: =IF(Q8="","",Q8-S8)
A9: =CONCATENATE(C9,E9,F9,I9) | B9: =CONCATENATE(C9,E9,I9) | C9: 900005953 | D9: =IFERROR(VLOOKUP(C9,TRAOPE!$G:$H,2,0),"") | E9: D876 | F9: 65664469 | G9: =IFERROR(VLOOKUP(A9,Flete!$A:$E,5,0),"") | H9: =IFERROR(VLOOKUP(F9,TRAOPE!$AA:$AB,2,0),"") | I9: 10017374 | J9: =IFERROR(VLOOKUP(I9,Materiales!$A:$H,8,0),"") | K9: =IFERROR(VLOOKUP(I9,Materiales!$A:$G,7,0),"") | L9: 20201023 | M9: 20241023 | N9: 280 | O9: =IFERROR(VLOOKUP(A9,Flete!$A:$J,10,0),"") | P9: M3 | Q9: =IFERROR(IFERROR(VLOOKUP(A9,TRAOPE!$A:$U,21,0),VLOOKUP(B9,TRAOPE!$A:$U,21,0)),"") | R9: =IFERROR(IFERROR(VLOOKUP(A9,TRAOPE!$A:$W,23,0),VLOOKUP(B9,TRAOPE!$A:$W,23,0)),"") | S9: =IF(AND(P9="TN",R9="TN"),N9+N(O9),IF(G9&""="1",N(K9)*N9,(N9+N(O9))*N(K9))) | T9: =IF(Q9="","",Q9-S9)
A10: =CONCATENATE(C10,E10,F10,I10) | B10: =CONCATENATE(C10,E10,I10) | C10: 900005953 | D10: =IFERROR(VLOOKUP(C10,TRAOPE!$G:$H,2,0),"") | E10: D876 | F10: 65664469 | G10: =IFERROR(VLOOKUP(A10,Flete!$A:$E,5,0),"") | H10: =IFERROR(VLOOKUP(F10,TRAOPE!$AA:$AB,2,0),"") | I10: 10138757 | J10: =IFERROR(VLOOKUP(I10,Materiales!$A:$H,8,0),"") | K10: =IFERROR(VLOOKUP(I10,Materiales!$A:$G,7,0),"") | L10: 20170210 | M10: 20241023 | N10: 72.68 | O10: =IFERROR(VLOOKUP(A10,Flete!$A:$J,10,0),"") | P10: M3 | Q10: =IFERROR(IFERROR(VLOOKUP(A10,TRAOPE!$A:$U,21,0),VLOOKUP(B10,TRAOPE!$A:$U,21,0)),"") | R10: =IFERROR(IFERROR(VLOOKUP(A10,TRAOPE!$A:$W,23,0),VLOOKUP(B10,TRAOPE!$A:$W,23,0)),"") | S10: =IF(AND(P10="TN",R10="TN"),N10+N(O10),IF(G10&""="1",N(K10)*N10,(N10+N(O10))*N(K10))) | T10: =IF(Q10="","",Q10-S10)
A11: =CONCATENATE(C11,E11,F11,I11) | B11: =CONCATENATE(C11,E11,I11) | C11: 900005953 | D11: =IFERROR(VLOOKUP(C11,TRAOPE!$G:$H,2,0),"") | E11: D876 | F11: 66413773 | G11: =IFERROR(VLOOKUP(A11,Flete!$A:$E,5,0),"") | H11: =IFERROR(VLOOKUP(F11,TRAOPE!$AA:$AB,2,0),"") | I11: 10003023 | J11: =IFERROR(VLOOKUP(I11,Materiales!$A:$H,8,0),"") | K11: =IFERROR(VLOOKUP(I11,Materiales!$A:$G,7,0),"") | L11: 20170210 | M11: 20241023 | N11: 74 | O11: =IFERROR(VLOOKUP(A11,Flete!$A:$J,10,0),"") | P11: M3 | Q11: =IFERROR(IFERROR(VLOOKUP(A11,TRAOPE!$A:$U,21,0),VLOOKUP(B11,TRAOPE!$A:$U,21,0)),"") | R11: =IFERROR(IFERROR(VLOOKUP(A11,TRAOPE!$A:$W,23,0),VLOOKUP(B11,TRAOPE!$A:$W,23,0)),"") | S11: =IF(AND(P11="TN",R11="TN"),N11+N(O11),IF(G11&""="1",N(K11)*N11,(N11+N(O11))*N(K11))) | T11: =IF(Q11="","",Q11-S11)
A12: =CONCATENATE(C12,E12,F12,I12) | B12: =CONCATENATE(C12,E12,I12) | C12: 900005953 | D12: =IFERROR(VLOOKUP(C12,TRAOPE!$G:$H,2,0),"") | E12: D876 | F12: 66413773 | G12: =IFERROR(VLOOKUP(A12,Flete!$A:$E,5,0),"") | H12: =IFERROR(VLOOKUP(F12,TRAOPE!$AA:$AB,2,0),"") | I12: 10138757 | J12: =IFERROR(VLOOKUP(I12,Materiales!$A:$H,8,0),"") | K12: =IFERROR(VLOOKUP(I12,Materiales!$A:$G,7,0),"") | L12: 20200213 | M12: 20241023 | N12: 50 | O12: =IFERROR(VLOOKUP(A12,Flete!$A:$J,10,0),"") | P12: M3 | Q12: =IFERROR(IFERROR(VLOOKUP(A12,TRAOPE!$A:$U,21,0),VLOOKUP(B12,TRAOPE!$A:$U,21,0)),"") | R12: =IFERROR(IFERROR(VLOOKUP(A12,TRAOPE!$A:$W,23,0),VLOOKUP(B12,TRAOPE!$A:$W,23,0)),"") | S12: =IF(AND(P12="TN",R12="TN"),N12+N(O12),IF(G12&""="1",N(K12)*N12,(N12+N(O12))*N(K12))) | T12: =IF(Q12="","",Q12-S12)
A13: =CONCATENATE(C13,E13,F13,I13) | B13: =CONCATENATE(C13,E13,I13) | C13: 900005953 | D13: =IFERROR(VLOOKUP(C13,TRAOPE!$G:$H,2,0),"") | E13: D876 | F13: 66447833 | G13: =IFERROR(VLOOKUP(A13,Flete!$A:$E,5,0),"") | H13: =IFERROR(VLOOKUP(F13,TRAOPE!$AA:$AB,2,0),"") | I13: 10138757 | J13: =IFERROR(VLOOKUP(I13,Materiales!$A:$H,8,0),"") | K13: =IFERROR(VLOOKUP(I13,Materiales!$A:$G,7,0),"") | L13: 20170210 | M13: 20241023 | N13: 50 | O13: =IFERROR(VLOOKUP(A13,Flete!$A:$J,10,0),"") | P13: M3 | Q13: =IFERROR(IFERROR(VLOOKUP(A13,TRAOPE!$A:$U,21,0),VLOOKUP(B13,TRAOPE!$A:$U,21,0)),"") | R13: =IFERROR(IFERROR(VLOOKUP(A13,TRAOPE!$A:$W,23,0),VLOOKUP(B13,TRAOPE!$A:$W,23,0)),"") | S13: =IF(AND(P13="TN",R13="TN"),N13+N(O13),IF(G13&""="1",N(K13)*N13,(N13+N(O13))*N(K13))) | T13: =IF(Q13="","",Q13-S13)
A14: =CONCATENATE(C14,E14,F14,I14) | B14: =CONCATENATE(C14,E14,I14) | C14: 900005953 | D14: =IFERROR(VLOOKUP(C14,TRAOPE!$G:$H,2,0),"") | E14: D876 | F14: 66542833 | G14: =IFERROR(VLOOKUP(A14,Flete!$A:$E,5,0),"") | H14: =IFERROR(VLOOKUP(F14,TRAOPE!$AA:$AB,2,0),"") | I14: 10138757 | J14: =IFERROR(VLOOKUP(I14,Materiales!$A:$H,8,0),"") | K14: =IFERROR(VLOOKUP(I14,Materiales!$A:$G,7,0),"") | L14: 20200117 | M14: 20241023 | N14: 74.29 | O14: =IFERROR(VLOOKUP(A14,Flete!$A:$J,10,0),"") | P14: M3 | Q14: =IFERROR(IFERROR(VLOOKUP(A14,TRAOPE!$A:$U,21,0),VLOOKUP(B14,TRAOPE!$A:$U,21,0)),"") | R14: =IFERROR(IFERROR(VLOOKUP(A14,TRAOPE!$A:$W,23,0),VLOOKUP(B14,TRAOPE!$A:$W,23,0)),"") | S14: =IF(AND(P14="TN",R14="TN"),N14+N(O14),IF(G14&""="1",N(K14)*N14,(N14+N(O14))*N(K14))) | T14: =IF(Q14="","",Q14-S14)
... A80: =CONCATENATE(C80,E80,F80,I80) | B80: =CONCATENATE(C80,E80,I80) | C80: 900007244 | D80: =IFERROR(VLOOKUP(C80,TRAOPE!$G:$H,2,0),"") | E80: D876 | F80: 65664469 | G80: =IFERROR(VLOOKUP(A80,Flete!$A:$E,5,0),"") | H80: =IFERROR(VLOOKUP(F80,TRAOPE!$AA:$AB,2,0),"") | I80: 10138757 | J80: =IFERROR(VLOOKUP(I80,Materiales!$A:$H,8,0),"") | K80: =IFERROR(VLOOKUP(I80,Materiales!$A:$G,7,0),"") | L80: 20250505 | M80: 20250507 | N80: 120 | O80: =IFERROR(VLOOKUP(A80,Flete!$A:$J,10,0),"") | P80: M3 | Q80: =IFERROR(IFERROR(VLOOKUP(A80,TRAOPE!$A:$U,21,0),VLOOKUP(B80,TRAOPE!$A:$U,21,0)),"") | R80: =IFERROR(IFERROR(VLOOKUP(A80,TRAOPE!$A:$W,23,0),VLOOKUP(B80,TRAOPE!$A:$W,23,0)),"") | S80: =IF(AND(P80="TN",R80="TN"),N80+N(O80),IF(G80&""="1",N(K80)*N80,(N80+N(O80))*N(K80))) | T80: =IF(Q80="","",Q80-S80)

Sheet MP
A1: No. SF | B1: Cedis | C1: Destino | D1: No. Material | E1: Nombre Material | F1: Importe MP | G1: Moneda | H1: Cantidad | I1: UM | J1: C | K1: Inicio Vigencia | L1: Fin Vigencia
A2: 900005951 | B2: D876 | C2: DG66 | D2: 10138757 | F2: 54.55 | I2: TN | K2: 20170210 | L2: 20241023
A3: 900005952 | B3: D876 | C3: 65268112 | D3: 10138757 | F3: 77.47 | I3: M3 | K3: 20170210 | L3: 20241023
A4: 900005952 | B4: D876 | C4: 65317027 | D4: 10138757 | F4: 77.47 | I4: M3 | K4: 20170210 | L4: 20241023
A5: 900005952 | B5: D876 | C5: 66605648 | D5: 10138757 | F5: 77.47 | I5: M3 | K5: 20170210 | L5: 20241023
A6: 900005953 | B6: D876 | C6: 65268112 | D6: 10138757 | F6: 76.89 | I6: M3 | K6: 20190220 | L6: 20241023
A7: 900005953 | B7: D876 | C7: 65317027 | D7: 10138757 | F7: 76.89 | I7: M3 | K7: 20190220 | L7: 20241023
A8: 900005953 | B8: D876 | C8: 65664469 | D8: 10017374 | F8: 280 | I8: M3 | K8: 20201023 | L8: 20241023
A9: 900005953 | B9: D876 | C9: 65664469 | D9: 10138757 | F9: 72.68 | I9: M3 | K9: 20170210 | L9: 20241023
A10: 900005953 | B10: D876 | C10: 66413773 | D10: 10003023 | F10: 74 | I10: M3 | K10: 20170210 | L10: 20241023
A11: 900005953 | B11: D876 | C11: 66413773 | D11: 10138757 | F11: 50 | I11: M3 | K11: 20200213 | L11: 20241023
A12: 900005953 | B12: D876 | C12: 66447833 | D12: 10138757 | F12: 50 | I12: M3 | K12: 20170210 | L12: 20241023
A13: 900005953 | B13: D876 | C13: 66542833 | D13: 10138757 | F13: 74.29 | I13: M3 | K13: 20200117 | L13: 20241023
... A79: 900007244 | B79: D876 | C79: 65664469 | D79: 10138757 | F79: 120 | I79: M3 | K79: 20250505 | L79: 20250507

Sheet Flete
A1: Concat1 | B1: No. SF | C1: Cedis | D1: Destino | E1: Cond. Exp. | F1: Material | H1: Nombre Material | J1: Importe Flete | K1: Moneda | L1: Cantidad | M1: UM | N1: C | P1: Inicio Vigencia | Q1: Fin Vigencia
A2: 900003677D8766728173810000645 | B2: 900003677 | C2: D876 | D2: 67281738 | E2: 1 | F2: 10000645 | J2: 100 | M2: TN | P2: 20251121 | Q2: 99991231
A3: 900003677D8766728173810003344 | B3: 900003677 | C3: D876 | D3: 67281738 | E3: 1 | F3: 10003344 | J3: 100 | M3: TN | P3: 20251121 | Q3: 99991231
A4: 900003677D8766728173810133051 | B4: 900003677 | C4: D876 | D4: 67281738 | E4: 1 | F4: 10133051 | J4: 100 | M4: TN | P4: 20251121 | Q4: 99991231
A5: 900003677D8766733405010000645 | B5: 900003677 | C5: D876 | D5: 67334050 | E5: 1 | F5: 10000645 | J5: 100 | M5: TN | P5: 20250813 | Q5: 99991231
A6: 900003677D8766733405010003344 | B6: 900003677 | C6: D876 | D6: 67334050 | E6: 1 | F6: 10003344 | J6: 100 | M6: TN | P6: 20250813 | Q6: 99991231
A7: 900003677D8766733405010133051 | B7: 900003677 | C7: D876 | D7: 67334050 | E7: 1 | F7: 10133051 | J7: 100 | M7: TN | P7: 20250813 | Q7: 99991231
A8: 900003730D8766641377310003023 | B8: 900003730 | C8: D876 | D8: 66413773 | E8: 4 | F8: 10003023 | J8: 100 | M8: M3 | P8: 20180710 | Q8: 99991231
A9: 900003730D8766644783310003023 | B9: 900003730 | C9: D876 | D9: 66447833 | E9: 4 | F9: 10003023 | J9: 85 | M9: M3 | P9: 20180710 | Q9: 99991231
A10: 900003730D8766655568710138757 | B10: 900003730 | C10: D876 | D10: 66555687 | E10: 4 | F10: 10138757 | J10: 61.32 | M10: M3 | P10: 20180727 | Q10: 99991231
A11: 900003993D8766563023610117708 | B11: 900003993 | C11: D876 | D11: 65630236 | E11: 1 | F11: 10117708 | J11: 54.5 | M11: TN | P11: 20250513 | Q11: 99991231
A12: 900003993D8766566446910017374 | B12: 900003993 | C12: D876 | D12: 65664469 | E12: 1 | F12: 10017374 | J12: 50 | M12: TN | P12: 20250529 | Q12: 99991231
A13: 900003993D8766618210210117708 | B13: 900003993 | C13: D876 | D13: 66182102 | E13: 1 | F13: 10117708 | J13: 103 | M13: M3 | P13: 20191126 | Q13: 99991231
... A59: 900007244D8766566446910138757 | B59: 900007244 | C59: D876 | D59: 65664469 | E59: 4 | F59: 10138757 | J59: 159 | M59: M3 | P59: 20250304 | Q59: 20250507

Sheet Materiales
A1: Material | B1: TpMt | C1: Denom | D1: UMA | E1: Contador | F1: UMB | G1: PV | H1: Nombre Material
A2: 10000001 | B2: ZFER | C2: 1000 | D2: M3 | E2: 1000 | F2: TN | G2: 1262 | H2: GRAVA ANDESITA 10 MM (3/8")
A3: 10000003 | B3: ZFER | C3: 1000 | D3: M3 | E3: 1000 | F3: TN | G3: 1443 | H3: GRAVA CALIZA 10 MM (3/8")
A4: 10000006 | B4: ZFER | C4: 1000 | D4: M3 | E4: 1000 | F4: TN | G4: 1490 | H4: GRAVA RIO 10 MM (3/8")
A5: 10000007 | B5: ZFER | C5: 1000 | D5: M3 | E5: 1000 | F5: TN | G5: 1488 | H5: GRAVA BASALTO 13 MM (1/2")
A6: 10000008 | B6: ZFER | C6: 1000 | D6: M3 | E6: 1000 | F6: TN | G6: 1358 | H6: GRAVA CALIZA 13 MM (1/2")
A7: 10000011 | B7: ZFER | C7: 1000 | D7: M3 | E7: 1000 | F7: TN | G7: 1323 | H7: GRAVA ANDESITA 20 MM (3/4")
A8: 10000013 | B8: ZFER | C8: 1000 | D8: M3 | E8: 1000 | F8: TN | G8: 1514 | H8: GRAVA BASALTO 20 MM (3/4")
A9: 10000014 | B9: ZFER | C9: 1000 | D9: M3 | E9: 1000 | F9: TN | G9: 1400 | H9: GRAVA CALIZA 20 MM (3/4")
A10: 10000015 | B10: ZFER | C10: 1000 | D10: M3 | E10: 1000 | F10: TN | G10: 1410 | H10: GRAVA GRANITO 20 MM (3/4")
A11: 10000017 | B11: ZFER | C11: 1000 | D11: M3 | E11: 1000 | F11: TN | G11: 1475 | H11: GRAVA RIOLITA 20 MM (3/4")
A12: 10000019 | B12: ZFER | C12: 1000 | D12: M3 | E12: 1000 | F12: TN | G12: 1515 | H12: GRAVA RIO 20 MM (3/4")
A13: 10000020 | B13: ZFER | C13: 1000 | D13: M3 | E13: 1 | F13: TN | G13: 1 | H13: GRAVA MAQUILA 40MM (1 1/2")
... A2291: 10268770 | B2291: ZFE3 | C2291: 1000 | D2291: M3 | E2291: 1000 | F2291: TN | G2291: 1240 | H2291: MP GRAVA TRIT CALIZA 40MM 1 1/2" - ESP
A2292: 10268901 | B2292: ZFE3 | C2292: 1000 | D2292: M3 | E2292: 1000 | G2292: 1560 | H2292: MP GRAVA ANDESITA GRIS 3/4" - CAPADA
A2293: 10267983 | C2293: 1000 | G2293: 1800 | H2293: ESCORIA ALTO HORNO 3/4
A2294: 10268996 | C2294: 1000 | G2294: 1329 | H2294: GRAVA TRITURADA CALIZA 40 MM - 11/2"
A2295: 10269072 | C2295: 1000 | G2295: 1700 | H2295: BASE HIDRÁULICA SCREEN
A2296: 10269225 | B2296: ZFE3 | C2296: 1000 | D2296: M3 | E2296: 1000 | G2296: 1289 | H2296: MP ARENA CALIZA LAVADA MALLA 4 - DELTA I
A2297: 10269245 | B2297: ZFE3 | C2297: 1000 | D2297: M3 | E2297: 1000 | G2297: 1410 | H2297: MP GRAVA TRITURADA CALIZA 3/8 - 10MM
A2298: 10269246 | B2298: ZFE3 | C2298: 1000 | D2298: M3 | E2298: 1000 | G2298: 1400 | H2298: MP GRAVA TRITURADA CALIZA 1 1/2 - 40MM
A2299: 10269247 | B2299: ZFE3 | C2299: 1000 | D2299: M3 | E2299: 1000 | G2299: 1560 | H2299: MP ARENA TRIT CALIZA M-4
A2300: 10270431 | B2300: ZFE3 | C2300: 1000 | D2300: M3 | E2300: 1000 | G2300: 1423 | H2300: MP GRAVA RIOLITA 13 MM - 1/2"
A2301: 10270898 | B2301: ZFE3 | C2301: 1000 | D2301: M3 | E2301: 1000 | G2301: 1551 | H2301: MP BASE H. TRIT. BASALTO 1 1/2" A FINOS
A2302: 10270911 | B2302: ZFE3 | C2302: 1000 | D2302: M3 | E2302: 1000 | G2302: 1360 | H2302: MP GRAVA TRIT. BASALTO 40 MM - 1 1/2"
A2303: 10270912 | B2303: ZFE3 | C2303: 1000 | D2303: M3 | E2303: 1000 | G2303: 1589 | H2303: MP ARENA TRIT. BASALTO MALLA 4
A2304: 10270913 | B2304: ZFE3 | C2304: 1000 | D2304: M3 | E2304: 1000 | G2304: 1395 | H2304: MP GRAVA TRIT. BASALTO 20 MM - 3/4
A2305: 10270914 | B2305: ZFE3 | C2305: 1000 | D2305: M3 | E2305: 1000 | G2305: 1623 | H2305: MP ARENA ANDESITA BC
A2306: 10270824 | B2306: M3 | C2306: 1000 | D2306: M3 | E2306: 10007640 | G2306: 1325 | H2306: MP ARENA TRITURADA CALIZA MALLA 5
A2307: 10270825 | B2307: M3 | C2307: 1000 | D2307: M3 | E2307: 10000003 | G2307: 1242 | H2307: MP GRAVA TRITURADA CALIZA 10MM (3/8”)
... A2319: 10272527 | B2319: ZFE3 | C2319: 1000 | D2319: M3 | E2319: 1000 | G2319: 1620 | H2319: CNC - NO CLASIFICADO
A2320: 10000332 | C2320: 1000 | D2320: M3 | E2320: 1000 | G2320: 800 | H2320: Grava Triturada Pomez - Jal 20 mm - 3/4"
A2321: 10273001 | B2321: ZFE3 | C2321: 1000 | D2321: M3 | E2321: 1000 | G2321: 1688 | H2321: MP ARENA TRIT. BASALTO MALLA 4
A2322: 10273002 | B2322: ZFE3 | C2322: 1000 | D2322: M3 | E2322: 1000 | G2322: 1466 | H2322: MP GRAVA TRIT. BASALTO 20 MM - 3/4"
A2323: 10273351 | B2323: ZFE3 | C2323: 1000 | D2323: M3 | E2323: 1000 | G2323: 1612 | H2323: MP ARENA TRIT. CALIZA MALLA 4
A2324: 10273352 | B2324: ZFE3 | C2324: 1000 | D2324: M3 | E2324: 1000 | G2324: 1492 | H2324: MP GRAVA TRIT. CALIZA 20 MM - 3/4"
A2325: 10271724 | B2325: ZFE3 | C2325: 1000 | D2325: M3 | E2325: 1000 | G2325: 1900 | H2325: MP RESIDUO DE CONCRETO
A2326: 10000677 | C2326: 1000 | D2326: M3 | G2326: 1164 | H2326: Grava Triturada Caliza 20 mm - 3/4"
A2327: 10274190 | B2327: ZFE3 | C2327: 1000 | D2327: M3 | E2327: 1000 | G2327: 1800 | H2327: MP BASE HIDRAULICA ANDESITA 70-30
A2328: 10274601 | B2328: ZFE3 | C2328: 1000 | D2328: M3 | E2328: 1000 | G2328: 1447 | H2328: MP ARENA BASALTO N° 4
...

Sheet TRAOPE
A1: Concat1 | B1: Contrato_Pos | C1: Doc. Compras | D1: Pos | E1: Org.compras | F1: Grp-Compr. | G1: Ship From | H1: Nombre SF | I1: Proveedor | J1: Nombre Prov | K1: Cond. Pago | L1: Descr. Cond Pago | M1: Material | N1: Descripción | O1: Centro | P1: Descripción Centro | Q1: In.perído validez | R1: Fin perído validez | S1: Válido de | T1: Validez a | U1: Precio neto pedido | V1: Moneda | W1: UM Precio Pedido | X1: Importe Condición | Y1: Moneda KONP | Z1: UM Ctd Base | AA1: Destino | AB1: Nombre Destino | AC1: Cuenta de mayor | AD1: Centro de costo | AE1: Cond. Exp. | AF1: Descr. Cond. Exp. | AG1: Peso Vol. | AH1: UMB | AI1: Ind. Oblig. Conf. Ped. | AJ1: Ctrl-Conf. | AK1: IVA | AL1: Modif_Date | AM1: Ruta
A2: 900003993D87610017374 | B2: 4600033398-30 | C2: 4600033398 | D2: 30 | E2: MXPO | F2: MXL | G2: 900003993 | H2: TP-TRITURADOS Y AGREGADOS DEL VALLE | I2: 5055790 | J2: TRITURADOS Y AGREGADOS DEL VALLE | K2: N90 | L2: (AP) NAFIN 90 Dias | M2: 10017374 | N2: Grava Triturada Caliza 20 mm - 3/4" | O2: D876 | P2: MX-CED. CHIAPAS | Q2: 20160311 | R2: 20281231 | S2: 20250513 | T2: 20301231 | U2: 284.25 | V2: MXN | W2: M3 | X2: 0 | Y2: MXN | Z2: M3 | AC2: 56103637 | AD2: 6622661540 | AE2: 1 | AF2: ENTREGADO | AG2: 1.379 | AH2: M3 | AI2: X | AJ2: 4 | AK2: V4 | AL2: 20250514 | AM2: D876-900003993-10017374
A3: 900003993D87610117708 | B3: 4600033398-10 | C3: 4600033398 | D3: 10 | E3: MXPO | F3: MXL | G3: 900003993 | H3: TP-TRITURADOS Y AGREGADOS DEL VALLE | I3: 5055790 | J3: TRITURADOS Y AGREGADOS DEL VALLE | K3: N90 | L3: (AP) NAFIN 90 Dias | M3: 10117708 | N3: ARENA TRITURADA CALIZA MALLA 4 | O3: D876 | P3: MX-CED. CHIAPAS | Q3: 20160311 | R3: 20281231 | S3: 20250513 | T3: 20301231 | U3: 257.17 | V3: MXN | W3: M3 | X3: 0 | Y3: MXN | Z3: M3 | AC3: 56103638 | AD3: 6622661540 | AE3: 1 | AF3: ENTREGADO | AG3: 1.65 | AH3: M3 | AI3: X | AJ3: 4 | AK3: V4 | AL3: 20250514 | AM3: D876-900003993-10117708
A4: 900003993D87610003022 | B4: 4600033398-70 | C4: 4600033398 | D4: 70 | E4: MXPO | F4: MXL | G4: 900003993 | H4: TP-TRITURADOS Y AGREGADOS DEL VALLE | I4: 5055790 | J4: TRITURADOS Y AGREGADOS DEL VALLE | K4: N90 | L4: (AP) NAFIN 90 Dias | M4: 10003022 | N4: Grava Triturada Caliza 40 mm - 1 1/2" | O4: D876 | P4: MX-CED. CHIAPAS | Q4: 20160311 | R4: 20281231 | S4: 20241205 | T4: 20291231 | U4: 253 | V4: MXN | W4: M3 | X4: 0 | Y4: MXN | Z4: M3 | AC4: 56103637 | AD4: 6622661540 | AE4: 1 | AF4: ENTREGADO | AG4: 1.342 | AH4: M3 | AI4: X | AJ4: 4 | AK4: V4 | AL4: 20241212 | AM4: D876-900003993-10003022
A5: 900007457D8766655568710138757 | B5: 4600071552-10 | C5: 4600071552 | D5: 10 | E5: MXPO | F5: MXL | G5: 900007457 | H5: SF TP-ED- DIFERENTES CONCEPTOS | I5: 5070621 | J5: DP DIFERENTES CONCEPTOS SA DE CV | K5: N90 | L5: (AP) NAFIN 90 Dias | M5: 10138757 | N5: ARENA CLASIFICADA DE RÍO MALLA 4 | O5: D876 | P5: MX-CED. CHIAPAS | Q5: 20250802 | R5: 20301231 | S5: 20250802 | T5: 20301231 | U5: 220 | V5: MXN | W5: M3 | X5: 110 | Y5: MXN | Z5: M3 | AA5: 66555687 | AB5: SISTELEC TUXTLA | AC5: 56103638 | AD5: 6622661540 | AE5: 4 | AF5: ENTREGA DIRECTA | AG5: 1.48 | AH5: M3 | AI5: X | AJ5: 4 | AK5: V4 | AL5: 20250815 | AM5: D876-900007457-66555687-10138757-4
A6: 900003993D87610000273 | B6: 4600033398-50 | C6: 4600033398 | D6: 50 | E6: MXPO | F6: MXL | G6: 900003993 | H6: TP-TRITURADOS Y AGREGADOS DEL VALLE | I6: 5055790 | J6: TRITURADOS Y AGREGADOS DEL VALLE | K6: N90 | L6: (AP) NAFIN 90 Dias | M6: 10000273 | N6: Base H Triturada Caliza 3/4" a Finos | O6: D876 | P6: MX-CED. CHIAPAS | Q6: 20160311 | R6: 20281231 | S6: 20210922 | T6: 20261231 | U6: 135 | V6: MXN | W6: M3 | X6: 0 | Y6: MXN | Z6: M3 | AC6: 56103590 | AD6: 6622661540 | AE6: 1 | AF6: ENTREGADO | AG6: 1.69 | AH6: M3 | AI6: X | AJ6: 4 | AK6: V4 | AL6: 20230920 | AM6: D876-900003993-10000273
A7: 900003993D87610156312 | B7: 4600033398-40 | C7: 4600033398 | D7: 40 | E7: MXPO | F7: MXL | G7: 900003993 | H7: TP-TRITURADOS Y AGREGADOS DEL VALLE | I7: 5055790 | J7: TRITURADOS Y AGREGADOS DEL VALLE | K7: N90 | L7: (AP) NAFIN 90 Dias | M7: 10156312 | N7: GRAVON DE 4" | O7: D876 | P7: MX-CED. CHIAPAS | Q7: 20160311 | R7: 20281231 | S7: 20210922 | T7: 20261231 | U7: 130 | V7: MXN | W7: M3 | X7: 0 | Y7: MXN | Z7: M3 | AC7: 56103637 | AD7: 6622661540 | AE7: 1 | AF7: ENTREGADO | AG7: 2.4 | AH7: M3 | AI7: X | AJ7: 4 | AK7: V4 | AL7: 20230920 | AM7: D876-900003993-10156312
A8: 900003677D87610003344 | B8: 4600071263-30 | C8: 4600071263 | D8: 30 | E8: MXPO | F8: MXL | G8: 900003677 | H8: TP-GRUPO TAPACHULA | I8: 5002293 | J8: CONSTRUCTORA GRUPO TAPACHULA SA DE | K8: Z09 | L8: (AP) 90 Dias | M8: 10003344 | N8: Grava Clasificada Río 20 mm - 3/4" | O8: D876 | P8: MX-CED. CHIAPAS | Q8: 20250519 | R8: 20301231 | S8: 20250813 | T8: 20301231 | U8: 327.34 | V8: MXN | W8: M3 | X8: 0 | Y8: MXN | Z8: M3 | AC8: 56103637 | AD8: 6622661540 | AE8: 1 | AF8: ENTREGADO | AG8: 1.376 | AH8: M3 | AI8: X | AJ8: 4 | AK8: V4 | AL8: 20250818 | AM8: D876-900003677-10003344
A9: 900003993D87610195953 | B9: 4600033398-60 | C9: 4600033398 | D9: 60 | E9: MXPO | F9: MXL | G9: 900003993 | H9: TP-TRITURADOS Y AGREGADOS DEL VALLE | I9: 5055790 | J9: TRITURADOS Y AGREGADOS DEL VALLE | K9: N90 | L9: (AP) NAFIN 90 Dias | M9: 10195953 | N9: ARENA TRITURADA CALIZA MALLA 5 | O9: D876 | P9: MX-CED. CHIAPAS | Q9: 20160311 | R9: 20281231 | S9: 20250904 | T9: 20301231 | U9: 227.4 | V9: MXN | W9: M3 | X9: 0 | Y9: MXN | Z9: M3 | AC9: 56103638 | AD9: 6622661540 | AE9: 1 | AF9: ENTREGADO | AG9: 1.37 | AH9: M3 | AI9: X | AJ9: 4 | AK9: V4 | AL9: 20250905 | AM9: D876-900003993-10195953
A10: 900003677D87610000645 | B10: 4600071263-20 | C10: 4600071263 | D10: 20 | E10: MXPO | F10: MXL | G10: 900003677 | H10: TP-GRUPO TAPACHULA | I10: 5002293 | J10: CONSTRUCTORA GRUPO TAPACHULA SA DE | K10: Z09 | L10: (AP) 90 Dias | M10: 10000645 | N10: Arena Clasificada Río Malla 4 | O10: D876 | P10: MX-CED. CHIAPAS | Q10: 20250519 | R10: 20301231 | S10: 20250519 | T10: 20301231 | U10: 290.99 | V10: MXN | W10: M3 | X10: 0 | Y10: MXN | Z10: M3 | AC10: 56103638 | AD10: 6622661540 | AE10: 1 | AF10: ENTREGADO | AG10: 1.62 | AH10: M3 | AI10: X | AJ10: 4 | AK10: V4 | AL10: 20250522 | AM10: D876-900003677-10000645
A11: 900003677D87610133051 | B11: 4600071263-10 | C11: 4600071263 | D11: 10 | E11: MXPO | F11: MXL | G11: 900003677 | H11: TP-GRUPO TAPACHULA | I11: 5002293 | J11: CONSTRUCTORA GRUPO TAPACHULA SA DE | K11: Z09 | L11: (AP) 90 Dias | M11: 10133051 | N11: GRAVA RIO 10MM-3/8" | O11: D876 | P11: MX-CED. CHIAPAS | Q11: 20250519 | R11: 20301231 | S11: 20250519 | T11: 20301231 | U11: 697.77 | V11: MXN | W11: M3 | X11: 0 | Y11: MXN | Z11: M3 | AC11: 56103637 | AD11: 6622661540 | AE11: 1 | AF11: ENTREGADO | AG11: 1.48 | AH11: M3 | AI11: X | AJ11: 4 | AK11: V4 | AL11: 20250522 | AM11: D876-900003677-10133051
A12: 900003993D87610109200 | B12: 4600033398-20 | C12: 4600033398 | D12: 20 | E12: MXPO | F12: MXL | G12: 900003993 | H12: TP-TRITURADOS Y AGREGADOS DEL VALLE | I12: 5055790 | J12: TRITURADOS Y AGREGADOS DEL VALLE | K12: N90 | L12: (AP) NAFIN 90 Dias | M12: 10109200 | N12: GRAVA TRITURADA CALIZA 10 MM -3/8" | O12: D876 | P12: MX-CED. CHIAPAS | Q12: 20160311 | R12: 20281231 | S12: 20160311 | T12: 20281231 | U12: 270 | V12: MXN | W12: M3 | X12: 0 | Y12: MXN | Z12: M3 | AC12: 56103637 | AD12: 6622661540 | AE12: 1 | AF12: ENTREGADO | AG12: 1.462 | AH12: M3 | AI12: X | AJ12: 4 | AK12: V4 | AL12: 20230920 | AM12: D876-900003993-10109200
A13: 900007244D8766566446910138757 | B13: 4600070796-10 | C13: 4600070796 | D13: 10 | E13: MXPO | F13: MXL | G13: 900007244 | H13: SF TP-ED- JUAN PABLO SORDO | I13: 5081069 | J13: SORDO SANCHEZ JUAN PABLO | K13: Z09 | L13: (AP) 90 Dias | M13: 10138757 | N13: ARENA CLASIFICADA DE RÍO MALLA 4 | O13: D876 | P13: MX-CED. CHIAPAS | Q13: 20250128 | R13: 20301231 | S13: 20250128 | T13: 20301231 | U13: 240 | V13: MXN | W13: M3 | X13: 140 | Y13: MXN | Z13: M3 | AA13: 65664469 | AB13: CENTRIFUGADOS MEXICANOS TUXTLA GUTI | AC13: 56103638 | AD13: 6622661540 | AE13: 4 | AF13: ENTREGA DIRECTA | AG13: 1.48 | AH13: M3 | AI13: X | AJ13: 4 | AK13: V4 | AL13: 20250131 | AM13: D876-900007244-65664469-10138757-4
A14: 900005571D87610017374 | B14: 4600056840-20 | C14: 4600056840 | D14: 20 | E14: MXPO | F14: MXL | G14: 900005571 | H14: SF TP-VALLE-ZOQUE | I14: 5055790 | J14: TRITURADOS Y AGREGADOS DEL VALLE | K14: N90 | L14: (AP) NAFIN 90 Dias | M14: 10017374 | N14: Grava Triturada Caliza 20 mm - 3/4" | O14: D876 | P14: MX-CED. CHIAPAS | Q14: 20230308 | R14: 20281231 | S14: 20230308 | T14: 20281231 | U14: 262 | V14: MXN | W14: M3 | X14: 0 | Y14: MXN | Z14: M3 | AC14: 56103637 | AD14: 6622661540 | AE14: 1 | AF14: ENTREGADO | AG14: 1.379 | AH14: M3 | AI14: X | AJ14: 4 | AK14: V4 | AL14: 20230920 | AM14: D876-900005571-10017374
A15: 900005571D87610000861 | B15: 4600056840-30 | C15: 4600056840 | D15: 30 | E15: MXPO | F15: MXL | G15: 900005571 | H15: SF TP-VALLE-ZOQUE | I15: 5055790 | J15: TRITURADOS Y AGREGADOS DEL VALLE | K15: N90 | L15: (AP) NAFIN 90 Dias | M15: 10000861 | N15: Base H Triturada Caliza 1 1/2" a Finos | O15: D876 | P15: MX-CED. CHIAPAS | Q15: 20230308 | R15: 20281231 | S15: 20230308 | T15: 20281231 | U15: 253 | V15: MXN | W15: M3 | X15: 0 | Y15: MXN | Z15: M3 | AC15: 56103590 | AD15: 6622661540 | AE15: 1 | AF15: ENTREGADO | AG15: 1.52 | AH15: M3 | AI15: X | AJ15: 4 | AK15: V4 | AL15: 20230920 | AM15: D876-900005571-10000861
A16: 900005571D87610117708 | B16: 4600056840-10 | C16: 4600056840 | D16: 10 | E16: MXPO | F16: MXL | G16: 900005571 | H16: SF TP-VALLE-ZOQUE | I16: 5055790 | J16: TRITURADOS Y AGREGADOS DEL VALLE | K16: N90 | L16: (AP) NAFIN 90 Dias | M16: 10117708 | N16: ARENA TRITURADA CALIZA MALLA 4 | O16: D876 | P16: MX-CED. CHIAPAS | Q16: 20230308 | R16: 20281231 | S16: 20230308 | T16: 20281231 | U16: 207 | V16: MXN | W16: M3 | X16: 0 | Y16: MXN | Z16: M3 | AC16: 56103638 | AD16: 6622661540 | AE16: 1 | AF16: ENTREGADO | AG16: 1.65 | AH16: M3 | AI16: X | AJ16: 4 | AK16: V4 | AL16: 20230920 | AM16: D876-900005571-10117708
A17: 900003993D87610232465 | B17: 4600033398-80 | C17: 4600033398 | D17: 80 | E17: MXPO | F17: MXL | G17: 900003993 | H17: TP-TRITURADOS Y AGREGADOS DEL VALLE | I17: 5055790 | J17: TRITURADOS Y AGREGADOS DEL VALLE | K17: N90 | L17: (AP) NAFIN 90 Dias | M17: 10232465 | N17: GRAVA TRITURADA CALIZA 13 MM - 1/2" | O17: D876 | P17: MX-CED. CHIAPAS | Q17: 20160311 | R17: 20281231 | S17: 20260311 | T17: 20301231 | U17: 545 | V17: MXN | W17: M3 | X17: 0 | Y17: MXN | Z17: M3 | AC17: 56103637 | AD17: 6622661540 | AE17: 1 | AF17: ENTREGADO | AG17: 1.205 | AH17: M3 | AI17: X | AJ17: 4 | AK17: V4 | AL17: 20260319 | AM17: D876-900003993-10232465
