Workbook

Sheet Base Cedis DW55
N1: VENTA | Q1: COSTO
A2: CONCAT1 | B2: CONCAT2 | C2: No. SF | D2: Nombre SF | E2: Cedis | F2: Destino | G2: Condicion de Expedicion | H2: Nombre Destino | I2: No. de material | J2: Nombre de material | K2: PV | L2: Inicio de vigencia | M2: Fin de vigencia | N2: Importe MP | O2: Importe Flete | P2: UM Venta | Q2: Importe Costo | R2: UM Costo | S2: Validacion 1 | T2: Validacion 2
A3: =CONCATENATE(C3,E3,F3,I3) | B3: =CONCATENATE(C3,E3,I3) | C3: 900000000 | D3: =IFERROR(VLOOKUP(C3,TRAOPE!$G:$H,2,0),"") | E3: DW55 | F3: D284 | G3: =IFERROR(VLOOKUP(A3,Flete!$A:$E,5,0),"") | H3: =IFERROR(VLOOKUP(F3,TRAOPE!$AA:$AB,2,0),"") | I3: 10000541 | J3: =IFERROR(VLOOKUP(I3,Materiales!$A:$H,8,0),"") | K3: =IFERROR(VLOOKUP(I3,Materiales!$A:$G,7,0),"") | L3: 20260804 | M3: 99991231 | N3: 229.06 | O3: =IFERROR(VLOOKUP(A3,Flete!$A:$J,10,0),"") | P3: TN | Q3: =IFERROR(IFERROR(VLOOKUP(A3,TRAOPE!$A:$U,21,0),VLOOKUP(B3,TRAOPE!$A:$U,21,0)),"") | R3: =IFERROR(IFERROR(VLOOKUP(A3,TRAOPE!$A:$W,23,0),VLOOKUP(B3,TRAOPE!$A:$W,23,0)),"") | S3: =IF(AND(P3="TN",R3="TN"),N3+N(O3),IF(G3&""="1",N(K3)*N3,(N3+N(O3))*N(K3))) | T3: =IF(Q3="","",Q3-S3)
A4: =CONCATENATE(C4,E4,F4,I4) | B4: =CONCATENATE(C4,E4,I4) | C4: 900000000 | D4: =IFERROR(VLOOKUP(C4,TRAOPE!$G:$H,2,0),"") | E4: DW55 | F4: D309 | G4: =IFERROR(VLOOKUP(A4,Flete!$A:$E,5,0),"") | H4: =IFERROR(VLOOKUP(F4,TRAOPE!$AA:$AB,2,0),"") | I4: 10000541 | J4: =IFERROR(VLOOKUP(I4,Materiales!$A:$H,8,0),"") | K4: =IFERROR(VLOOKUP(I4,Materiales!$A:$G,7,0),"") | L4: 20240904 | M4: 99991231 | N4: 196.34 | O4: =IFERROR(VLOOKUP(A4,Flete!$A:$J,10,0),"") | P4: TN | Q4: =IFERROR(IFERROR(VLOOKUP(A4,TRAOPE!$A:$U,21,0),VLOOKUP(B4,TRAOPE!$A:$U,21,0)),"") | R4: =IFERROR(IFERROR(VLOOKUP(A4,TRAOPE!$A:$W,23,0),VLOOKUP(B4,TRAOPE!$A:$W,23,0)),"") | S4: =IF(AND(P4="TN",R4="TN"),N4+N(O4),IF(G4&""="1",N(K4)*N4,(N4+N(O4))*N(K4))) | T4: =IF(Q4="","",Q4-S4)
A5: =CONCATENATE(C5,E5,F5,I5) | B5: =CONCATENATE(C5,E5,I5) | C5: 900000000 | D5: =IFERROR(VLOOKUP(C5,TRAOPE!$G:$H,2,0),"") | E5: DW55 | F5: D342 | G5: =IFERROR(VLOOKUP(A5,Flete!$A:$E,5,0),"") | H5: =IFERROR(VLOOKUP(F5,TRAOPE!$AA:$AB,2,0),"") | I5: 10000541 | J5: =IFERROR(VLOOKUP(I5,Materiales!$A:$H,8,0),"") | K5: =IFERROR(VLOOKUP(I5,Materiales!$A:$G,7,0),"") | L5: 20220504 | M5: 20240930 | N5: 84.81 | O5: =IFERROR(VLOOKUP(A5,Flete!$A:$J,10,0),"") | P5: TN | Q5: =IFERROR(IFERROR(VLOOKUP(A5,TRAOPE!$A:$U,21,0),VLOOKUP(B5,TRAOPE!$A:$U,21,0)),"") | R5: =IFERROR(IFERROR(VLOOKUP(A5,TRAOPE!$A:$W,23,0),VLOOKUP(B5,TRAOPE!$A:$W,23,0)),"") | S5: =IF(AND(P5="TN",R5="TN"),N5+N(O5),IF(G5&""="1",N(K5)*N5,(N5+N(O5))*N(K5))) | T5: =IF(Q5="","",Q5-S5)
A6: =CONCATENATE(C6,E6,F6,I6) | B6: =CONCATENATE(C6,E6,I6) | C6: 900000000 | D6: =IFERROR(VLOOKUP(C6,TRAOPE!$G:$H,2,0),"") | E6: DW55 | F6: D348 | G6: =IFERROR(VLOOKUP(A6,Flete!$A:$E,5,0),"") | H6: =IFERROR(VLOOKUP(F6,TRAOPE!$AA:$AB,2,0),"") | I6: 10000541 | J6: =IFERROR(VLOOKUP(I6,Materiales!$A:$H,8,0),"") | K6: =IFERROR(VLOOKUP(I6,Materiales!$A:$G,7,0),"") | L6: 20240122 | M6: 20241015 | N6: 89.28 | O6: =IFERROR(VLOOKUP(A6,Flete!$A:$J,10,0),"") | P6: TN | Q6: =IFERROR(IFERROR(VLOOKUP(A6,TRAOPE!$A:$U,21,0),VLOOKUP(B6,TRAOPE!$A:$U,21,0)),"") | R6: =IFERROR(IFERROR(VLOOKUP(A6,TRAOPE!$A:$W,23,0),VLOOKUP(B6,TRAOPE!$A:$W,23,0)),"") | S6: =IF(AND(P6="TN",R6="TN"),N6+N(O6),IF(G6&""="1",N(K6)*N6,(N6+N(O6))*N(K6))) | T6: =IF(Q6="","",Q6-S6)
A7: =CONCATENATE(C7,E7,F7,I7) | B7: =CONCATENATE(C7,E7,I7) | C7: 900000000 | D7: =IFERROR(VLOOKUP(C7,TRAOPE!$G:$H,2,0),"") | E7: DW55 | F7: ER67 | G7: =IFERROR(VLOOKUP(A7,Flete!$A:$E,5,0),"") | H7: =IFERROR(VLOOKUP(F7,TRAOPE!$AA:$AB,2,0),"") | I7: 10000541 | J7: =IFERROR(VLOOKUP(I7,Materiales!$A:$H,8,0),"") | K7: =IFERROR(VLOOKUP(I7,Materiales!$A:$G,7,0),"") | L7: 20220504 | M7: 20230127 | N7: 84.81 | O7: =IFERROR(VLOOKUP(A7,Flete!$A:$J,10,0),"") | P7: TN | Q7: =IFERROR(IFERROR(VLOOKUP(A7,TRAOPE!$A:$U,21,0),VLOOKUP(B7,TRAOPE!$A:$U,21,0)),"") | R7: =IFERROR(IFERROR(VLOOKUP(A7,TRAOPE!$A:$W,23,0),VLOOKUP(B7,TRAOPE!$A:$W,23,0)),"") | S7: =IF(AND(P7="TN",R7="TN"),N7+N(O7),IF(G7&""="1",N(K7)*N7,(N7+N(O7))*N(K7))) | T7: =IF(Q7="","",Q7-S7)
A8: =CONCATENATE(C8,E8,F8,I8) | B8: =CONCATENATE(C8,E8,I8) | C8: 900000000 | D8: =IFERROR(VLOOKUP(C8,TRAOPE!$G:$H,2,0),"") | E8: DW55 | F8: ER68 | G8: =IFERROR(VLOOKUP(A8,Flete!$A:$E,5,0),"") | H8: =IFERROR(VLOOKUP(F8,TRAOPE!$AA:$AB,2,0),"") | I8: 10000541 | J8: =IFERROR(VLOOKUP(I8,Materiales!$A:$H,8,0),"") | K8: =IFERROR(VLOOKUP(I8,Materiales!$A:$G,7,0),"") | L8: 20240122 | M8: 20241015 | N8: 84.81 | O8: =IFERROR(VLOOKUP(A8,Flete!$A:$J,10,0),"") | P8: TN | Q8: =IFERROR(IFERROR(VLOOKUP(A8,TRAOPE!$A:$U,21,0),VLOOKUP(B8,TRAOPE!$A:$U,21,0)),"") | R8: =IFERROR(IFERROR(VLOOKUP(A8,TRAOPE!$A:$W,23,0),VLOOKUP(B8,TRAOPE!$A:$W,23,0)),"") | S8: =IF(AND(P8="TN",R8="TN"),N8+N(O8),IF(G8&""="1",N(K8)*N8,(N8+N(O8))*N(K8))) | T8: =IF(Q8="","",Q8-S8)
A9: =CONCATENATE(C9,E9,F9,I9) | B9: =CONCATENATE(C9,E9,I9) | C9: 900000515 | D9: =IFERROR(VLOOKUP(C9,TRAOPE!$G:$H,2,0),"") | E9: DW55 | F9: D284 | G9: =IFERROR(VLOOKUP(A9,Flete!$A:$E,5,0),"") | H9: =IFERROR(VLOOKUP(F9,TRAOPE!$AA:$AB,2,0),"") | I9: 10049559 | J9: =IFERROR(VLOOKUP(I9,Materiales!$A:$H,8,0),"") | K9: =IFERROR(VLOOKUP(I9,Materiales!$A:$G,7,0),"") | L9: 20220516 | M9: 20240710 | N9: 122.95 | O9: =IFERROR(VLOOKUP(A9,Flete!$A:$J,10,0),"") | P9: TN | Q9: =IFERROR(IFERROR(VLOOKUP(A9,TRAOPE!$A:$U,21,0),VLOOKUP(B9,TRAOPE!$A:$U,21,0)),"") | R9: =IFERROR(IFERROR(VLOOKUP(A9,TRAOPE!$A:$W,23,0),VLOOKUP(B9,TRAOPE!$A:$W,23,0)),"") | S9: =IF(AND(P9="TN",R9="TN"),N9+N(O9),IF(G9&""="1",N(K9)*N9,(N9+N(O9))*N(K9))) | T9: =IF(Q9="","",Q9-S9)
A10: =CONCATENATE(C10,E10,F10,I10) | B10: =CONCATENATE(C10,E10,I10) | C10: 900000515 | D10: =IFERROR(VLOOKUP(C10,TRAOPE!$G:$H,2,0),"") | E10: DW55 | F10: D284 | G10: =IFERROR(VLOOKUP(A10,Flete!$A:$E,5,0),"") | H10: =IFERROR(VLOOKUP(F10,TRAOPE!$AA:$AB,2,0),"") | I10: 10217663 | J10: =IFERROR(VLOOKUP(I10,Materiales!$A:$H,8,0),"") | K10: =IFERROR(VLOOKUP(I10,Materiales!$A:$G,7,0),"") | L10: 20220516 | M10: 20240710 | N10: 36.54 | O10: =IFERROR(VLOOKUP(A10,Flete!$A:$J,10,0),"") | P10: TN | Q10: =IFERROR(IFERROR(VLOOKUP(A10,TRAOPE!$A:$U,21,0),VLOOKUP(B10,TRAOPE!$A:$U,21,0)),"") | R10: =IFERROR(IFERROR(VLOOKUP(A10,TRAOPE!$A:$W,23,0),VLOOKUP(B10,TRAOPE!$A:$W,23,0)),"") | S10: =IF(AND(P10="TN",R10="TN"),N10+N(O10),IF(G10&""="1",N(K10)*N10,(N10+N(O10))*N(K10))) | T10: =IF(Q10="","",Q10-S10)
A11: =CONCATENATE(C11,E11,F11,I11) | B11: =CONCATENATE(C11,E11,I11) | C11: 900000515 | D11: =IFERROR(VLOOKUP(C11,TRAOPE!$G:$H,2,0),"") | E11: DW55 | F11: D284 | G11: =IFERROR(VLOOKUP(A11,Flete!$A:$E,5,0),"") | H11: =IFERROR(VLOOKUP(F11,TRAOPE!$AA:$AB,2,0),"") | I11: 10218414 | J11: =IFERROR(VLOOKUP(I11,Materiales!$A:$H,8,0),"") | K11: =IFERROR(VLOOKUP(I11,Materiales!$A:$G,7,0),"") | L11: 20220516 | M11: 20240710 | N11: 217.89 | O11: =IFERROR(VLOOKUP(A11,Flete!$A:$J,10,0),"") | P11: TN | Q11: =IFERROR(IFERROR(VLOOKUP(A11,TRAOPE!$A:$U,21,0),VLOOKUP(B11,TRAOPE!$A:$U,21,0)),"") | R11: =IFERROR(IFERROR(VLOOKUP(A11,TRAOPE!$A:$W,23,0),VLOOKUP(B11,TRAOPE!$A:$W,23,0)),"") | S11: =IF(AND(P11="TN",R11="TN"),N11+N(O11),IF(G11&""="1",N(K11)*N11,(N11+N(O11))*N(K11))) | T11: =IF(Q11="","",Q11-S11)
A12: =CONCATENATE(C12,E12,F12,I12) | B12: =CONCATENATE(C12,E12,I12) | C12: 900000515 | D12: =IFERROR(VLOOKUP(C12,TRAOPE!$G:$H,2,0),"") | E12: DW55 | F12: D309 | G12: =IFERROR(VLOOKUP(A12,Flete!$A:$E,5,0),"") | H12: =IFERROR(VLOOKUP(F12,TRAOPE!$AA:$AB,2,0),"") | I12: 10049559 | J12: =IFERROR(VLOOKUP(I12,Materiales!$A:$H,8,0),"") | K12: =IFERROR(VLOOKUP(I12,Materiales!$A:$G,7,0),"") | L12: 20220516 | M12: 20240710 | N12: 122.95 | O12: =IFERROR(VLOOKUP(A12,Flete!$A:$J,10,0),"") | P12: TN | Q12: =IFERROR(IFERROR(VLOOKUP(A12,TRAOPE!$A:$U,21,0),VLOOKUP(B12,TRAOPE!$A:$U,21,0)),"") | R12: =IFERROR(IFERROR(VLOOKUP(A12,TRAOPE!$A:$W,23,0),VLOOKUP(B12,TRAOPE!$A:$W,23,0)),"") | S12: =IF(AND(P12="TN",R12="TN"),N12+N(O12),IF(G12&""="1",N(K12)*N12,(N12+N(O12))*N(K12))) | T12: =IF(Q12="","",Q12-S12)
A13: =CONCATENATE(C13,E13,F13,I13) | B13: =CONCATENATE(C13,E13,I13) | C13: 900000515 | D13: =IFERROR(VLOOKUP(C13,TRAOPE!$G:$H,2,0),"") | E13: DW55 | F13: D326 | G13: =IFERROR(VLOOKUP(A13,Flete!$A:$E,5,0),"") | H13: =IFERROR(VLOOKUP(F13,TRAOPE!$AA:$AB,2,0),"") | I13: 10049559 | J13: =IFERROR(VLOOKUP(I13,Materiales!$A:$H,8,0),"") | K13: =IFERROR(VLOOKUP(I13,Materiales!$A:$G,7,0),"") | L13: 20220516 | M13: 20240710 | N13: 122.95 | O13: =IFERROR(VLOOKUP(A13,Flete!$A:$J,10,0),"") | P13: TN | Q13: =IFERROR(IFERROR(VLOOKUP(A13,TRAOPE!$A:$U,21,0),VLOOKUP(B13,TRAOPE!$A:$U,21,0)),"") | R13: =IFERROR(IFERROR(VLOOKUP(A13,TRAOPE!$A:$W,23,0),VLOOKUP(B13,TRAOPE!$A:$W,23,0)),"") | S13: =IF(AND(P13="TN",R13="TN"),N13+N(O13),IF(G13&""="1",N(K13)*N13,(N13+N(O13))*N(K13))) | T13: =IF(Q13="","",Q13-S13)
A14: =CONCATENATE(C14,E14,F14,I14) | B14: =CONCATENATE(C14,E14,I14) | C14: 900000515 | D14: =IFERROR(VLOOKUP(C14,TRAOPE!$G:$H,2,0),"") | E14: DW55 | F14: D342 | G14: =IFERROR(VLOOKUP(A14,Flete!$A:$E,5,0),"") | H14: =IFERROR(VLOOKUP(F14,TRAOPE!$AA:$AB,2,0),"") | I14: 10049559 | J14: =IFERROR(VLOOKUP(I14,Materiales!$A:$H,8,0),"") | K14: =IFERROR(VLOOKUP(I14,Materiales!$A:$G,7,0),"") | L14: 20220516 | M14: 20240710 | N14: 122.95 | O14: =IFERROR(VLOOKUP(A14,Flete!$A:$J,10,0),"") | P14: TN | Q14: =IFERROR(IFERROR(VLOOKUP(A14,TRAOPE!$A:$U,21,0),VLOOKUP(B14,TRAOPE!$A:$U,21,0)),"") | R14: =IFERROR(IFERROR(VLOOKUP(A14,TRAOPE!$A:$W,23,0),VLOOKUP(B14,TRAOPE!$A:$W,23,0)),"") | S14: =IF(AND(P14="TN",R14="TN"),N14+N(O14),IF(G14&""="1",N(K14)*N14,(N14+N(O14))*N(K14))) | T14: =IF(Q14="","",Q14-S14)
... A454: =CONCATENATE(C454,E454,F454,I454) | B454: =CONCATENATE(C454,E454,I454) | C454: 900009596 | D454: =IFERROR(VLOOKUP(C454,TRAOPE!$G:$H,2,0),"") | E454: DW55 | F454: D309 | G454: =IFERROR(VLOOKUP(A454,Flete!$A:$E,5,0),"") | H454: =IFERROR(VLOOKUP(F454,TRAOPE!$AA:$AB,2,0),"") | I454: 10260169 | J454: =IFERROR(VLOOKUP(I454,Materiales!$A:$H,8,0),"") | K454: =IFERROR(VLOOKUP(I454,Materiales!$A:$G,7,0),"") | L454: 20260819 | M454: 99991231 | N454: 48.58 | O454: =IFERROR(VLOOKUP(A454,Flete!$A:$J,10,0),"") | P454: TN | Q454: =IFERROR(IFERROR(VLOOKUP(A454,TRAOPE!$A:$U,21,0),VLOOKUP(B454,TRAOPE!$A:$U,21,0)),"") | R454: =IFERROR(IFERROR(VLOOKUP(A454,TRAOPE!$A:$W,23,0),VLOOKUP(B454,TRAOPE!$A:$W,23,0)),"") | S454: =IF(AND(P454="TN",R454="TN"),N454+N(O454),IF(G454&""="1",N(K454)*N454,(N454+N(O454))*N(K454))) | T454: =IF(Q454="","",Q454-S454)

Sheet MP
A1: No. SF | B1: Cedis | C1: Destino | D1: No. Material | E1: Nombre Material | F1: Importe MP | G1: Moneda | H1: Cantidad | I1: UM | J1: C | K1: Inicio Vigencia | L1: Fin Vigencia
A2: 900000000 | B2: DW55 | C2: D284 | D2: 10000541 | F2: 229.06 | I2: TN | K2: 20260804 | L2: 99991231
A3: 900000000 | B3: DW55 | C3: D309 | D3: 10000541 | F3: 196.34 | I3: TN | K3: 20240904 | L3: 99991231
A4: 900000000 | B4: DW55 | C4: D342 | D4: 10000541 | F4: 84.81 | I4: TN | K4: 20220504 | L4: 20240930
A5: 900000000 | B5: DW55 | C5: D348 | D5: 10000541 | F5: 89.28 | I5: TN | K5: 20240122 | L5: 20241015
A6: 900000000 | B6: DW55 | C6: ER67 | D6: 10000541 | F6: 84.81 | I6: TN | K6: 20220504 | L6: 20230127
A7: 900000000 | B7: DW55 | C7: ER68 | D7: 10000541 | F7: 84.81 | I7: TN | K7: 20240122 | L7: 20241015
A8: 900000515 | B8: DW55 | C8: D284 | D8: 10049559 | F8: 122.95 | I8: TN | K8: 20220516 | L8: 20240710
A9: 900000515 | B9: DW55 | C9: D284 | D9: 10217663 | F9: 36.54 | I9: TN | K9: 20220516 | L9: 20240710
A10: 900000515 | B10: DW55 | C10: D284 | D10: 10218414 | F10: 217.89 | I10: TN | K10: 20220516 | L10: 20240710
A11: 900000515 | B11: DW55 | C11: D309 | D11: 10049559 | F11: 122.95 | I11: TN | K11: 20220516 | L11: 20240710
A12: 900000515 | B12: DW55 | C12: D326 | D12: 10049559 | F12: 122.95 | I12: TN | K12: 20220516 | L12: 20240710
A13: 900000515 | B13: DW55 | C13: D342 | D13: 10049559 | F13: 122.95 | I13: TN | K13: 20220516 | L13: 20240710
... A453: 900009596 | B453: DW55 | C453: D309 | D453: 10260169 | F453: 48.58 | I453: TN | K453: 20260819 | L453: 99991231

Sheet Flete
A1: Concat1 | B1: No. SF | C1: Cedis | D1: Destino | E1: Cond. Exp. | F1: Material | H1: Nombre Material | J1: Importe Flete | K1: Moneda | L1: Cantidad | M1: UM | N1: C | P1: Inicio Vigencia | Q1: Fin Vigencia
A2: 900000000DW55D28410000541 | B2: 900000000 | C2: DW55 | D2: D284 | E2: 4 | F2: 10000541 | J2: 314.14 | M2: TN | P2: 20240122 | Q2: 99991231
A3: 900000000DW55D30910000541 | B3: 900000000 | C3: DW55 | D3: D309 | E3: 4 | F3: 10000541 | J3: 261.78 | M3: TN | P3: 20240904 | Q3: 99991231
A4: 900000000DW55D34210000541 | B4: 900000000 | C4: DW55 | D4: D342 | E4: 4 | F4: 10000541 | J4: 262.05 | M4: TN | P4: 20240122 | Q4: 20241015
A5: 900000515DW55D28410049559 | B5: 900000515 | C5: DW55 | D5: D284 | E5: 4 | F5: 10049559 | J5: 85.39 | M5: TN | P5: 20220516 | Q5: 20240710
A6: 900000515DW55D30910049559 | B6: 900000515 | C6: DW55 | D6: D309 | E6: 4 | F6: 10049559 | J6: 118.21 | M6: TN | P6: 20220516 | Q6: 20240710
A7: 900000515DW55D32610049559 | B7: 900000515 | C7: DW55 | D7: D326 | E7: 4 | F7: 10049559 | J7: 105.07 | M7: TN | P7: 20220516 | Q7: 20240710
A8: 900000515DW55D34210049559 | B8: 900000515 | C8: DW55 | D8: D342 | E8: 4 | F8: 10049559 | J8: 137.88 | M8: TN | P8: 20220516 | Q8: 20240710
A9: 900000515DW55D34810049559 | B9: 900000515 | C9: DW55 | D9: D348 | E9: 4 | F9: 10049559 | J9: 68.85 | M9: TN | P9: 20220516 | Q9: 20240710
A10: 900000743DW55D28410000372 | B10: 900000743 | C10: DW55 | D10: D284 | E10: 1 | F10: 10000372 | J10: 100.83 | M10: TN | P10: 20260417 | Q10: 20260427
A11: 900000743DW55D28410123034 | B11: 900000743 | C11: DW55 | D11: D284 | E11: 1 | F11: 10123034 | J11: 123.8 | M11: TN | P11: 20241001 | Q11: 99991231
A12: 900000743DW55D28410151600 | B12: 900000743 | C12: DW55 | D12: D284 | E12: 1 | F12: 10151600 | J12: 104.99 | M12: TN | P12: 20210620 | Q12: 20240930
A13: 900000743DW55D28410217664 | B13: 900000743 | C13: DW55 | D13: D284 | E13: 1 | F13: 10217664 | J13: 104.96 | M13: TN | P13: 20260417 | Q13: 99991231
... A252: 900009524DW55D28410217663 | B252: 900009524 | C252: DW55 | D252: D284 | E252: 4 | F252: 10217663 | J252: 54.95 | M252: TN | P252: 20260707 | Q252: 99991231

Sheet Materiales
A1: Material | B1: TpMt | C1: Denom | D1: UMA | E1: Contador | F1: UMB | G1: PV | H1: Nombre Material
A2: 10000001 | B2: ZFER | C2: 1000 | D2: M3 | E2: 1000 | F2: TN | G2: 1262 | H2: GRAVA ANDESITA 10 MM (3/8")
A3: 10000003 | B3: ZFER | C3: 1000 | D3: M3 | E3: 1000 | F3: TN | G3: 1443 | H3: GRAVA CALIZA 10 MM (3/8")
A4: 10000006 | B4: ZFER | C4: 1000 | D4: M3 | E4: 1000 | F4: TN | G4: 1490 | H4: GRAVA RIO 10 MM (3/8")
A5: 10000007 | B5: ZFER | C5: 1000 | D5: M3 | E5: 1000 | F5: TN | G5: 1488 | H5: GRAVA BASALTO 13 MM (1/2")
A6: 10000008 | B6: ZFER | C6: 1000 | D6: M3 | E6: 1000 | F6: TN | G6: 1358 | H6: GRAVA CALIZA 13 MM (1/2")
A7: 10000011 | B7: ZFER | C7: 1000 | D7: M3 | E7: 1000 | F7: TN | G7: 1323 | H7: GRAVA ANDESITA 20 MM (3/4")
A8: 10000013 | B8: ZFER | C8: 1000 | D8: M3 | E8: 1000 | F8: TN | G8: 1514 | H8: GRAVA BASALTO 20 MM (3/4")
A9: 10000014 | B9: ZFER | C9: 1000 | D9: M3 | E9: 1000 | F9: TN | G9: 1400 | H9: GRAVA CALIZA 20 MM (3/4")
A10: 10000015 | B10: ZFER | C10: 1000 | D10: M3 | E10: 1000 | F10: TN | G10: 1410 | H10: GRAVA GRANITO 20 MM (3/4")
A11: 10000017 | B11: ZFER | C11: 1000 | D11: M3 | E11: 1000 | F11: TN | G11: 1475 | H11: GRAVA RIOLITA 20 MM (3/4")
A12: 10000019 | B12: ZFER | C12: 1000 | D12: M3 | E12: 1000 | F12: TN | G12: 1515 | H12: GRAVA RIO 20 MM (3/4")
A13: 10000020 | B13: ZFER | C13: 1000 | D13: M3 | E13: 1 | F13: TN | G13: 1 | H13: GRAVA MAQUILA 40MM (1 1/2")
... A2291: 10268770 | B2291: ZFE3 | C2291: 1000 | D2291: M3 | E2291: 1000 | F2291: TN | G2291: 1240 | H2291: MP GRAVA TRIT CALIZA 40MM 1 1/2" - ESP
A2292: 10268901 | B2292: ZFE3 | C2292: 1000 | D2292: M3 | E2292: 1000 | G2292: 1560 | H2292: MP GRAVA ANDESITA GRIS 3/4" - CAPADA
A2293: 10267983 | C2293: 1000 | G2293: 1800 | H2293: ESCORIA ALTO HORNO 3/4
A2294: 10268996 | C2294: 1000 | G2294: 1329 | H2294: GRAVA TRITURADA CALIZA 40 MM - 11/2"
A2295: 10269072 | C2295: 1000 | G2295: 1700 | H2295: BASE HIDRÁULICA SCREEN
A2296: 10269225 | B2296: ZFE3 | C2296: 1000 | D2296: M3 | E2296: 1000 | G2296: 1289 | H2296: MP ARENA CALIZA LAVADA MALLA 4 - DELTA I
A2297: 10269245 | B2297: ZFE3 | C2297: 1000 | D2297: M3 | E2297: 1000 | G2297: 1410 | H2297: MP GRAVA TRITURADA CALIZA 3/8 - 10MM
A2298: 10269246 | B2298: ZFE3 | C2298: 1000 | D2298: M3 | E2298: 1000 | G2298: 1400 | H2298: MP GRAVA TRITURADA CALIZA 1 1/2 - 40MM
A2299: 10269247 | B2299: ZFE3 | C2299: 1000 | D2299: M3 | E2299: 1000 | G2299: 1560 | H2299: MP ARENA TRIT CALIZA M-4
A2300: 10270431 | B2300: ZFE3 | C2300: 1000 | D2300: M3 | E2300: 1000 | G2300: 1423 | H2300: MP GRAVA RIOLITA 13 MM - 1/2"
A2301: 10270898 | B2301: ZFE3 | C2301: 1000 | D2301: M3 | E2301: 1000 | G2301: 1551 | H2301: MP BASE H. TRIT. BASALTO 1 1/2" A FINOS
A2302: 10270911 | B2302: ZFE3 | C2302: 1000 | D2302: M3 | E2302: 1000 | G2302: 1360 | H2302: MP GRAVA TRIT. BASALTO 40 MM - 1 1/2"
A2303: 10270912 | B2303: ZFE3 | C2303: 1000 | D2303: M3 | E2303: 1000 | G2303: 1589 | H2303: MP ARENA TRIT. BASALTO MALLA 4
A2304: 10270913 | B2304: ZFE3 | C2304: 1000 | D2304: M3 | E2304: 1000 | G2304: 1395 | H2304: MP GRAVA TRIT. BASALTO 20 MM - 3/4
A2305: 10270914 | B2305: ZFE3 | C2305: 1000 | D2305: M3 | E2305: 1000 | G2305: 1623 | H2305: MP ARENA ANDESITA BC
A2306: 10270824 | B2306: M3 | C2306: 1000 | D2306: M3 | E2306: 10007640 | G2306: 1325 | H2306: MP ARENA TRITURADA CALIZA MALLA 5
A2307: 10270825 | B2307: M3 | C2307: 1000 | D2307: M3 | E2307: 10000003 | G2307: 1242 | H2307: MP GRAVA TRITURADA CALIZA 10MM (3/8”)
... A2319: 10272527 | B2319: ZFE3 | C2319: 1000 | D2319: M3 | E2319: 1000 | G2319: 1620 | H2319: CNC - NO CLASIFICADO
A2320: 10000332 | C2320: 1000 | D2320: M3 | E2320: 1000 | G2320: 800 | H2320: Grava Triturada Pomez - Jal 20 mm - 3/4"
A2321: 10273001 | B2321: ZFE3 | C2321: 1000 | D2321: M3 | E2321: 1000 | G2321: 1688 | H2321: MP ARENA TRIT. BASALTO MALLA 4
A2322: 10273002 | B2322: ZFE3 | C2322: 1000 | D2322: M3 | E2322: 1000 | G2322: 1466 | H2322: MP GRAVA TRIT. BASALTO 20 MM - 3/4"
A2323: 10273351 | B2323: ZFE3 | C2323: 1000 | D2323: M3 | E2323: 1000 | G2323: 1612 | H2323: MP ARENA TRIT. CALIZA MALLA 4
A2324: 10273352 | B2324: ZFE3 | C2324: 1000 | D2324: M3 | E2324: 1000 | G2324: 1492 | H2324: MP GRAVA TRIT. CALIZA 20 MM - 3/4"
A2325: 10271724 | B2325: ZFE3 | C2325: 1000 | D2325: M3 | E2325: 1000 | G2325: 1900 | H2325: MP RESIDUO DE CONCRETO
A2326: 10000677 | C2326: 1000 | D2326: M3 | G2326: 1164 | H2326: Grava Triturada Caliza 20 mm - 3/4"
A2327: 10274190 | B2327: ZFE3 | C2327: 1000 | D2327: M3 | E2327: 1000 | G2327: 1800 | H2327: MP BASE HIDRAULICA ANDESITA 70-30
A2328: 10274601 | B2328: ZFE3 | C2328: 1000 | D2328: M3 | E2328: 1000 | G2328: 1447 | H2328: MP ARENA BASALTO N° 4
...

Sheet TRAOPE
A1: Concat1 | B1: Contrato_Pos | C1: Doc. Compras | D1: Pos | E1: Org.compras | F1: Grp-Compr. | G1: Ship From | H1: Nombre SF | I1: Proveedor | J1: Nombre Prov | K1: Cond. Pago | L1: Descr. Cond Pago | M1: Material | N1: Descripción | O1: Centro | P1: Descripción Centro | Q1: In.perído validez | R1: Fin perído validez | S1: Válido de | T1: Validez a | U1: Precio neto pedido | V1: Moneda | W1: UM Precio Pedido | X1: Importe Condición | Y1: Moneda KONP | Z1: UM Ctd Base | AA1: Destino | AB1: Nombre Destino | AC1: Cuenta de mayor | AD1: Centro de costo | AE1: Cond. Exp. | AF1: Descr. Cond. Exp. | AG1: Peso Vol. | AH1: UMB | AI1: Ind. Oblig. Conf. Ped. | AJ1: Ctrl-Conf. | AK1: IVA | AL1: Modif_Date | AM1: Ruta
A2: 900009596DW55D30910260169 | B2: 4600072551-10 | C2: 4600072551 | D2: 10 | E2: MXPO | F2: MXL | G2: 900009596 | H2: SF TC-ED MARINA RAGA | I2: 5098523 | J2: CONSTRUCCIONES Y SERVICIOS RAGA SA | K2: Z09 | L2: (AP) 90 Dias | M2: 10260169 | N2: ARENA DE RIO MALLA 4# | O2: DW55 | P2: MX-CED. TABASCO | Q2: 20260819 | R2: 20301231 | S2: 20260819 | T2: 20301231 | U2: 150 | V2: MXN | W2: M3 | X2: 75 | Y2: MXN | Z2: M3 | AA2: D309 | AB2: PD0477 CARDENAS | AC2: 56103638 | AD2: 6644041540 | AE2: 4 | AF2: ENTREGA DIRECTA | AG2: 1.555 | AH2: M3 | AI2: X | AJ2: 4 | AK2: V4 | AL2: 20260825 | AM2: DW55-900009596-D309-10260169-4
A3: 900009580DW55D30910217663 | B3: 4600072526-20 | C3: 4600072526 | D3: 20 | E3: MXPO | F3: MXL | G3: 900009580 | H3: SF TC-ED HABANERO | I3: 5066828 | J3: DE LA CRUZ GARCIA FREDDY | K3: N90 | L3: (AP) NAFIN 90 Dias | M3: 10217663 | N3: ARENA CLASIFICADA RÍO MALLA 4 -TABASCO | O3: DW55 | P3: MX-CED. TABASCO | Q3: 20260806 | R3: 20301231 | S3: 20260806 | T3: 20301231 | U3: 155 | V3: MXN | W3: M3 | X3: 35 | Y3: MXN | Z3: M3 | AA3: D309 | AB3: PD0477 CARDENAS | AC3: 56103638 | AD3: 6644041540 | AE3: 4 | AF3: ENTREGA DIRECTA | AG3: 1.456 | AH3: M3 | AI3: X | AJ3: 4 | AK3: V4 | AL3: 20260811 | AM3: DW55-900009580-D309-10217663-4
A4: 900000000DW55D28410000541 | B4: 4600050874-60 | C4: 4600050874 | D4: 60 | E4: MXPO | F4: MXL | G4: 900000000 | H4: TC-ED-LAZCANO HUERTA | I4: 5000326 | J4: LAZCANO HUERTA ROCIO NANCY | K4: N90 | L4: (AP) NAFIN 90 Dias | M4: 10000541 | N4: Grava Clasificada Río 10 mm - 3/8" | O4: DW55 | P4: MX-CED. TABASCO | Q4: 20210712 | R4: 20291231 | S4: 20260804 | T4: 20301231 | U4: 900 | V4: MXN | W4: M3 | X4: 550 | Y4: MXN | Z4: M3 | AA4: D284 | AB4: PD0183 VILLAHERMOSA | AC4: 56103637 | AD4: 6644041540 | AE4: 4 | AF4: ENTREGA DIRECTA | AG4: 1.528 | AH4: M3 | AI4: X | AJ4: 4 | AK4: V4 | AL4: 20260806 | AM4: DW55-900000000-D284-10000541-4
A5: 900009577DW5510217663 | B5: 4600072536-10 | C5: 4600072536 | D5: 10 | E5: MXPO | F5: MXL | G5: 900009577 | H5: SF TC-JPM GARRAPATA | I5: 5098111 | J5: PEREZ MORALES JONAS | K5: N90 | L5: (AP) NAFIN 90 Dias | M5: 10217663 | N5: ARENA CLASIFICADA RÍO MALLA 4 -TABASCO | O5: DW55 | P5: MX-CED. TABASCO | Q5: 20260812 | R5: 20301231 | S5: 20260812 | T5: 20301231 | U5: 75 | V5: MXN | W5: M3 | X5: 0 | Y5: MXN | Z5: M3 | AC5: 56103638 | AD5: 6644041540 | AE5: 1 | AF5: ENTREGADO | AG5: 1.456 | AH5: M3 | AI5: X | AJ5: 4 | AK5: V4 | AL5: 20260814 | AM5: DW55-900009577-10217663
A6: 900009580DW55D28410217663 | B6: 4600072526-10 | C6: 4600072526 | D6: 10 | E6: MXPO | F6: MXL | G6: 900009580 | H6: SF TC-ED HABANERO | I6: 5066828 | J6: DE LA CRUZ GARCIA FREDDY | K6: N90 | L6: (AP) NAFIN 90 Dias | M6: 10217663 | N6: ARENA CLASIFICADA RÍO MALLA 4 -TABASCO | O6: DW55 | P6: MX-CED. TABASCO | Q6: 20260806 | R6: 20301231 | S6: 20260806 | T6: 20301231 | U6: 190 | V6: MXN | W6: M3 | X6: 70 | Y6: MXN | Z6: M3 | AA6: D284 | AB6: PD0183 VILLAHERMOSA | AC6: 56103638 | AD6: 6644041540 | AE6: 4 | AF6: ENTREGA DIRECTA | AG6: 1.456 | AH6: M3 | AI6: X | AJ6: 4 | AK6: V4 | AL6: 20260811 | AM6: DW55-900009580-D284-10217663-4
A7: 900007931DW5510000372 | B7: 4600072359-20 | C7: 4600072359 | D7: 20 | E7: MXPO | F7: MXL | G7: 900007931 | H7: SF TC-TRAPA | I7: 5087333 | J7: GARCIA MONTILLA VICTOR DAVID | K7: Z09 | L7: (AP) 90 Dias | M7: 10000372 | N7: Grava Triturada Caliza 20 mm - 3/4" | O7: DW55 | P7: MX-CED. TABASCO | Q7: 20260707 | R7: 20301231 | S7: 20260707 | T7: 20301231 | U7: 340 | V7: MXN | W7: M3 | X7: 0 | Y7: MXN | Z7: M3 | AC7: 56103637 | AD7: 6644041540 | AE7: 1 | AF7: ENTREGADO | AG7: 1.448 | AH7: M3 | AI7: X | AJ7: 4 | AK7: V4 | AL7: 20260709 | AM7: DW55-900007931-10000372
A8: 900007931DW5510000623 | B8: 4600072359-30 | C8: 4600072359 | D8: 30 | E8: MXPO | F8: MXL | G8: 900007931 | H8: SF TC-TRAPA | I8: 5087333 | J8: GARCIA MONTILLA VICTOR DAVID | K8: Z09 | L8: (AP) 90 Dias | M8: 10000623 | N8: Grava Triturada Caliza 10 mm - 3/8" | O8: DW55 | P8: MX-CED. TABASCO | Q8: 20260707 | R8: 20301231 | S8: 20260716 | T8: 20301231 | U8: 420 | V8: MXN | W8: M3 | X8: 0 | Y8: MXN | Z8: M3 | AC8: 56103637 | AD8: 6644041540 | AE8: 1 | AF8: ENTREGADO | AG8: 1.41 | AH8: M3 | AI8: X | AJ8: 4 | AK8: V4 | AL8: 20260720 | AM8: DW55-900007931-10000623
A9: 900003903DW5510217663 | B9: 4600050910-30 | C9: 4600050910 | D9: 30 | E9: MXPO | F9: MXL | G9: 900003903 | H9: TC ESCUDERO AGUILAR | I9: 5014480 | J9: ESCUDERO AGUILAR ANDRES | K9: N90 | L9: (AP) NAFIN 90 Dias | M9: 10217663 | N9: ARENA CLASIFICADA RÍO MALLA 4 -TABASCO | O9: DW55 | P9: MX-CED. TABASCO | Q9: 20210712 | R9: 20281231 | S9: 20260701 | T9: 20301231 | U9: 75 | V9: MXN | W9: M3 | X9: 0 | Y9: MXN | Z9: M3 | AC9: 56103638 | AD9: 6644041540 | AE9: 1 | AF9: ENTREGADO | AG9: 1.456 | AH9: M3 | AI9: X | AJ9: 4 | AK9: V4 | AL9: 20260707 | AM9: DW55-900003903-10217663
A10: 900009524DW55D28410217663 | B10: 4600072360-10 | C10: 4600072360 | D10: 10 | E10: MXPO | F10: MXL | G10: 900009524 | H10: SF TC-ED JPM EVELIO | I10: 5098111 | J10: PEREZ MORALES JONAS | K10: N90 | L10: (AP) NAFIN 90 Dias | M10: 10217663 | N10: ARENA CLASIFICADA RÍO MALLA 4 -TABASCO | O10: DW55 | P10: MX-CED. TABASCO | Q10: 20260707 | R10: 20301231 | S10: 20260707 | T10: 20301231 | U10: 155 | V10: MXN | W10: M3 | X10: 80 | Y10: MXN | Z10: M3 | AA10: D284 | AB10: PD0183 VILLAHERMOSA | AC10: 56103638 | AD10: 6644041540 | AE10: 4 | AF10: ENTREGA DIRECTA | AG10: 1.456 | AH10: M3 | AI10: X | AJ10: 4 | AK10: V4 | AL10: 20260709 | AM10: DW55-900009524-D284-10217663-4
A11: 900007932DW55D30910000372 | B11: 4600055937-70 | C11: 4600055937 | D11: 70 | E11: MXPO | F11: MXL | G11: 900007932 | H11: SF TC-ED-TRAPA | I11: 5087333 | J11: GARCIA MONTILLA VICTOR DAVID | K11: Z09 | L11: (AP) 90 Dias | M11: 10000372 | N11: Grava Triturada Caliza 20 mm - 3/4" | O11: DW55 | P11: MX-CED. TABASCO | Q11: 20221209 | R11: 20281231 | S11: 20260707 | T11: 20301231 | U11: 590 | V11: MXN | W11: M3 | X11: 250 | Y11: MXN | Z11: M3 | AA11: D309 | AB11: PD0477 CARDENAS | AC11: 56103637 | AD11: 6644041540 | AE11: 4 | AF11: ENTREGA DIRECTA | AG11: 1.448 | AH11: M3 | AI11: X | AJ11: 4 | AK11: V4 | AL11: 20260709 | AM11: DW55-900007932-D309-10000372-4
A12: 900007304DW55D34210000373 | B12: 4600053181-120 | C12: 4600053181 | D12: 120 | E12: MXPO | F12: MXL | G12: 900007304 | H12: SF TC-ED-ALFONSO ESPADAS | I12: 5079231 | J12: ESPADAS HERNANDEZ ALFONSO | K12: N90 | L12: (AP) NAFIN 90 Dias | M12: 10000373 | N12: Grava Triturada Caliza 13 mm - 1/2" | O12: DW55 | P12: MX-CED. TABASCO | Q12: 20220214 | R12: 20281231 | S12: 20230307 | T12: 20281231 | U12: 750 | V12: MXN | W12: M3 | X12: 350 | Y12: MXN | Z12: M3 | AA12: D342 | AB12: PD0268 SAMARIA II -PLANTA 2 | AC12: 56103637 | AD12: 6644041540 | AE12: 4 | AF12: ENTREGA DIRECTA | AG12: 1.395 | AH12: M3 | AI12: X | AJ12: 4 | AK12: V4 | AL12: 20230920 | AM12: DW55-900007304-D342-10000373-4
A13: 900007304DW55D32510000373 | B13: 4600053181-140 | C13: 4600053181 | D13: 140 | E13: MXPO | F13: MXL | G13: 900007304 | H13: SF TC-ED-ALFONSO ESPADAS | I13: 5079231 | J13: ESPADAS HERNANDEZ ALFONSO | K13: N90 | L13: (AP) NAFIN 90 Dias | M13: 10000373 | N13: Grava Triturada Caliza 13 mm - 1/2" | O13: DW55 | P13: MX-CED. TABASCO | Q13: 20220214 | R13: 20281231 | S13: 20230419 | T13: 20281231 | U13: 1000 | V13: MXN | W13: M3 | X13: 500 | Y13: MXN | Z13: M3 | AA13: D325 | AB13: PD0402 PALENQUE II | AC13: 56103637 | AD13: 6644041540 | AE13: 4 | AF13: ENTREGA DIRECTA | AG13: 1.395 | AH13: M3 | AI13: X | AJ13: 4 | AK13: V4 | AL13: 20230920 | AM13: DW55-900007304-D325-10000373-4
A14: 900007484DW55D34810000373 | B14: 4600053253-50 | C14: 4600053253 | D14: 50 | E14: MXPO | F14: MXL | G14: 900007484 | H14: SF-TC-ED-AURELIO CABRERA | I14: 5082823 | J14: CABRERA MARIN AURELIO ANTONIO | K14: Z09 | L14: (AP) 90 Dias | M14: 10000373 | N14: Grava Triturada Caliza 13 mm - 1/2" | O14: DW55 | P14: MX-CED. TABASCO | Q14: 20220222 | R14: 20281231 | S14: 20230426 | T14: 20281231 | U14: 1000 | V14: MXN | W14: M3 | X14: 500 | Y14: MXN | Z14: M3 | AA14: D348 | AB14: PD0294 LAGUNA VERDE 2 | AC14: 56103637 | AD14: 6644041540 | AE14: 4 | AF14: ENTREGA DIRECTA | AG14: 1.395 | AH14: M3 | AI14: X | AJ14: 4 | AK14: V4 | AL14: 20230920 | AM14: DW55-900007484-D348-10000373-4
A15: 900007304DW55D34810000373 | B15: 4600053181-130 | C15: 4600053181 | D15: 130 | E15: MXPO | F15: MXL | G15: 900007304 | H15: SF TC-ED-ALFONSO ESPADAS | I15: 5079231 | J15: ESPADAS HERNANDEZ ALFONSO | K15: N90 | L15: (AP) NAFIN 90 Dias | M15: 10000373 | N15: Grava Triturada Caliza 13 mm - 1/2" | O15: DW55 | P15: MX-CED. TABASCO | Q15: 20220214 | R15: 20281231 | S15: 20230419 | T15: 20281231 | U15: 1000 | V15: MXN | W15: M3 | X15: 500 | Y15: MXN | Z15: M3 | AA15: D348 | AB15: PD0294 LAGUNA VERDE 2 | AC15: 56103637 | AD15: 6644041540 | AE15: 4 | AF15: ENTREGA DIRECTA | AG15: 1.395 | AH15: M3 | AI15: X | AJ15: 4 | AK15: V4 | AL15: 20230920 | AM15: DW55-900007304-D348-10000373-4
A16: 900007484DW55D32510217663 | B16: 4600053253-70 | C16: 4600053253 | D16: 70 | E16: MXPO | F16: MXL | G16: 900007484 | H16: SF-TC-ED-AURELIO CABRERA | I16: 5082823 | J16: CABRERA MARIN AURELIO ANTONIO | K16: Z09 | L16: (AP) 90 Dias | M16: 10217663 | N16: ARENA CLASIFICADA RÍO MALLA 4 -TABASCO | O16: DW55 | P16: MX-CED. TABASCO | Q16: 20220222 | R16: 20281231 | S16: 20231218 | T16: 20281231 | U16: 400 | V16: MXN | W16: M3 | X16: 320 | Y16: MXN | Z16: M3 | AA16: D325 | AB16: PD0402 PALENQUE II | AC16: 56103638 | AD16: 6644041540 | AE16: 4 | AF16: ENTREGA DIRECTA | AG16: 1.456 | AH16: M3 | AI16: X | AJ16: 4 | AK16: V4 | AL16: 20231219 | AM16: DW55-900007484-D325-10217663-4
A17: 900007604DW55D30910123034 | B17: 4600054544-90 | C17: 4600054544 | D17: 90 | E17: MXPO | F17: MXL | G17: 900007604 | H17: SF TC-ED-FRISO CONSMIN TAB | I17: 5083592 | J17: FRISO CONSMIN SA DE CV | K17: N45 | L17: (AP) NAFIN 45 Dias | M17: 10123034 | N17: ARENA TRITURADA CALIZA MALLA 4 | O17: DW55 | P17: MX-CED. TABASCO | Q17: 20220715 | R17: 20271231 | U17: 0 | V17: MXN | W17: M3 | AA17: D309 | AB17: PD0477 CARDENAS | AC17: 56103638 | AD17: 6644041540 | AE17: 4 | AF17: ENTREGA DIRECTA | AG17: 1.528 | AH17: M3 | AI17: X | AJ17: 4 | AK17: V4 | AL17: 20260422 | AM17: DW55-900007604-D309-10123034-4
A18: 900007604DW55D28410000372 | B18: 4600054544-60 | C18: 4600054544 | D18: 60 | E18: MXPO | F18: MXL | G18: 900007604 | H18: SF TC-ED-FRISO CONSMIN TAB | I18: 5083592 | J18: FRISO CONSMIN SA DE CV | K18: N45 | L18: (AP) NAFIN 45 Dias | M18: 10000372 | N18: Grava Triturada Caliza 20 mm - 3/4" | O18: DW55 | P18: MX-CED. TABASCO | Q18: 20220715 | R18: 20271231 | U18: 0 | V18: MXN | W18: M3 | AA18: D284 | AB18: PD0183 VILLAHERMOSA | AC18: 56103637 | AD18: 6644041540 | AE18: 4 | AF18: ENTREGA DIRECTA | AG18: 1.448 | AH18: M3 | AI18: X | AJ18: 4 | AK18: V4 | AL18: 20260422 | AM18: DW55-900007604-D284-10000372-4
A19: 900007580DW5510217663 | B19: 4600071713-10 | C19: 4600071713 | D19: 10 | E19: MXPO | F19: MXL | G19: 900007580 | H19: SF-TC-FREDDY DE LA CRUZ | I19: 5066828 | J19: DE LA CRUZ GARCIA FREDDY | K19: N90 | L19: (AP) NAFIN 90 Dias | M19: 10217663 | N19: ARENA CLASIFICADA RÍO MALLA 4 -TABASCO | O19: DW55 | P19: MX-CED. TABASCO | Q19: 20251021 | R19: 20301231 | S19: 20260501 | T19: 20301231 | U19: 75 | V19: MXN | W19: M3 | X19: 0 | Y19: MXN | Z19: M3 | AC19: 56103638 | AD19: 6644041540 | AE19: 1 | AF19: ENTREGADO | AG19: 1.456 | AH19: M3 | AI19: X | AJ19: 4 | AK19: V4 | AL19: 20260513 | AM19: DW55-900007580-10217663
A20: 900007581DW55D34210217663 | B20: 4600071458-30 | C20: 4600071458 | D20: 30 | E20: MXPO | F20: MXL | G20: 900007581 | H20: SF-TC-ED-FREDDY DE LA CRUZ | I20: 5066828 | J20: DE LA CRUZ GARCIA FREDDY | K20: N90 | L20: (AP) NAFIN 90 Dias | M20: 10217663 | N20: ARENA CLASIFICADA RÍO MALLA 4 -TABASCO | O20: DW55 | P20: MX-CED. TABASCO | Q20: 20250717 | R20: 20301231 | S20: 20260501 | T20: 20301231 | U20: 217.5 | V20: MXN | W20: M3 | X20: 142.5 | Y20: MXN | Z20: M3 | AA20: D342 | AB20: PD0268 SAMARIA II -PLANTA 2 | AC20: 56103638 | AD20: 6644041540 | AE20: 4 | AF20: ENTREGA DIRECTA | AG20: 1.456 | AH20: M3 | AI20: X | AJ20: 4 | AK20: V4 | AL20: 20260513 | AM20: DW55-900007581-D342-10217663-4
A21: 900007581DW55D30910217663 | B21: 4600071458-20 | C21: 4600071458 | D21: 20 | E21: MXPO | F21: MXL | G21: 900007581 | H21: SF-TC-ED-FREDDY DE LA CRUZ | I21: 5066828 | J21: DE LA CRUZ GARCIA FREDDY | K21: N90 | L21: (AP) NAFIN 90 Dias | M21: 10217663 | N21: ARENA CLASIFICADA RÍO MALLA 4 -TABASCO | O21: DW55 | P21: MX-CED. TABASCO | Q21: 20250717 | R21: 20301231 | S21: 20260501 | T21: 20301231 | U21: 127 | V21: MXN | W21: M3 | X21: 52 | Y21: MXN | Z21: M3 | AA21: D309 | AB21: PD0477 CARDENAS | AC21: 56103638 | AD21: 6644041540 | AE21: 4 | AF21: ENTREGA DIRECTA | AG21: 1.456 | AH21: M3 | AI21: X | AJ21: 4 | AK21: V4 | AL21: 20260513 | AM21: DW55-900007581-D309-10217663-4
A22: 900007581DW55D28410217663 | B22: 4600071458-10 | C22: 4600071458 | D22: 10 | E22: MXPO | F22: MXL | G22: 900007581 | H22: SF-TC-ED-FREDDY DE LA CRUZ | I22: 5066828 | J22: DE LA CRUZ GARCIA FREDDY | K22: N90 | L22: (AP) NAFIN 90 Dias | M22: 10217663 | N22: ARENA CLASIFICADA RÍO MALLA 4 -TABASCO | O22: DW55 | P22: MX-CED. TABASCO | Q22: 20250717 | R22: 20301231 | S22: 20260501 | T22: 20301231 | U22: 147 | V22: MXN | W22: M3 | X22: 72 | Y22: MXN | Z22: M3 | AA22: D284 | AB22: PD0183 VILLAHERMOSA | AC22: 56103638 | AD22: 6644041540 | AE22: 4 | AF22: ENTREGA DIRECTA | AG22: 1.456 | AH22: M3 | AI22: X | AJ22: 4 | AK22: V4 | AL22: 20260513 | AM22: DW55-900007581-D284-10217663-4
A23: 900009523DW5510217663 | B23: 4600072293-10 | C23: 4600072293 | D23: 10 | E23: MXPO | F23: MXL | G23: 900009523 | H23: SF TC-JPM EVELIO | I23: 5098111 | J23: PEREZ MORALES JONAS | K23: N90 | L23: (AP) NAFIN 90 Dias | M23: 10217663 | N23: ARENA CLASIFICADA RÍO MALLA 4 -TABASCO | O23: DW55 | P23: MX-CED. TABASCO | Q23: 20260605 | R23: 20301231 | S23: 20260605 | T23: 20301231 | U23: 75 | V23: MXN | W23: M3 | X23: 0 | Y23: MXN | Z23: M3 | AC23: 56103638 | AD23: 6644041540 | AE23: 1 | AF23: ENTREGADO | AG23: 1.456 | AH23: M3 | AI23: X | AJ23: 4 | AK23: V4 | AL23: 20260611 | AM23: DW55-900009523-10217663
A24: 900007304DW55D34210000372 | B24: 4600053181-180 | C24: 4600053181 | D24: 180 | E24: MXPO | F24: MXL | G24: 900007304 | H24: SF TC-ED-ALFONSO ESPADAS | I24: 5079231 | J24: ESPADAS HERNANDEZ ALFONSO | K24: N90 | L24: (AP) NAFIN 90 Dias | M24: 10000372 | N24: Grava Triturada Caliza 20 mm - 3/4" | O24: DW55 | P24: MX-CED. TABASCO | Q24: 20220214 | R24: 20281231 | S24: 20250212 | T24: 20301231 | U24: 580 | V24: MXN | W24: M3 | X24: 290 | Y24: MXN | Z24: M3 | AA24: D342 | AB24: PD0268 SAMARIA II -PLANTA 2 | AC24: 56103637 | AD24: 6644041540 | AE24: 4 | AF24: ENTREGA DIRECTA | AG24: 1.448 | AH24: M3 | AI24: X | AJ24: 4 | AK24: V4 | AL24: 20250213 | AM24: DW55-900007304-D342-10000372-4
A25: 900007304DW55D30910000372 | B25: 4600053181-190 | C25: 4600053181 | D25: 190 | E25: MXPO | F25: MXL | G25: 900007304 | H25: SF TC-ED-ALFONSO ESPADAS | I25: 5079231 | J25: ESPADAS HERNANDEZ ALFONSO | K25: N90 | L25: (AP) NAFIN 90 Dias | M25: 10000372 | N25: Grava Triturada Caliza 20 mm - 3/4" | O25: DW55 | P25: MX-CED. TABASCO | Q25: 20220214 | R25: 20281231 | S25: 20250212 | T25: 20301231 | U25: 533 | V25: MXN | W25: M3 | X25: 243 | Y25: MXN | Z25: M3 | AA25: D309 | AB25: PD0477 CARDENAS | AC25: 56103637 | AD25: 6644041540 | AE25: 4 | AF25: ENTREGA DIRECTA | AG25: 1.448 | AH25: M3 | AI25: X | AJ25: 4 | AK25: V4 | AL25: 20250213 | AM25: DW55-900007304-D309-10000372-4
A26: 900007303DW5510213318 | B26: 4600053579-10 | C26: 4600053579 | D26: 10 | E26: MXPO | F26: MXL | G26: 900007303 | H26: SF TC-ALFONSO ESPADAS | I26: 5079231 | J26: ESPADAS HERNANDEZ ALFONSO | K26: N90 | L26: (AP) NAFIN 90 Dias | M26: 10213318 | N26: GRAVA TRITURADA RÍO 10 MM - 3/8" | O26: DW55 | P26: MX-CED. TABASCO | Q26: 20220331 | R26: 20271231 | S26: 20220331 | T26: 20271231 | U26: 660 | V26: MXN | W26: M3 | X26: 0 | Y26: MXN | Z26: M3 | AC26: 56103637 | AD26: 6644041540 | AE26: 1 | AF26: ENTREGADO | AG26: 1.433 | AH26: M3 | AI26: X | AJ26: 4 | AK26: V4 | AL26: 20230920 | AM26: DW55-900007303-10213318
A27: 900007932DW55D34810000372 | B27: 4600055937-10 | C27: 4600055937 | D27: 10 | E27: MXPO | F27: MXL | G27: 900007932 | H27: SF TC-ED-TRAPA | I27: 5087333 | J27: GARCIA MONTILLA VICTOR DAVID | K27: Z09 | L27: (AP) 90 Dias | M27: 10000372 | N27: Grava Triturada Caliza 20 mm - 3/4" | O27: DW55 | P27: MX-CED. TABASCO | Q27: 20221209 | R27: 20281231 | S27: 20221209 | T27: 20271231 | U27: 630 | V27: MXN | W27: M3 | X27: 410 | Y27: MXN | Z27: M3 | AA27: D348 | AB27: PD0294 LAGUNA VERDE 2 | AC27: 56103637 | AD27: 6644041540 | AE27: 4 | AF27: ENTREGA DIRECTA | AG27: 1.448 | AH27: M3 | AI27: X | AJ27: 4 | AK27: V4 | AL27: 20230920 | AM27: DW55-900007932-D348-10000372-4
A28: 900007932DW55D34810000834 | B28: 4600055937-30 | C28: 4600055937 | D28: 30 | E28: MXPO | F28: MXL | G28: 900007932 | H28: SF TC-ED-TRAPA | I28: 5087333 | J28: GARCIA MONTILLA VICTOR DAVID | K28: Z09 | L28: (AP) 90 Dias | M28: 10000834 | N28: Arena Clasificada Río Malla 4 | O28: DW55 | P28: MX-CED. TABASCO | Q28: 20221209 | R28: 20281231 | S28: 20230627 | T28: 20281231 | U28: 620 | V28: MXN | W28: M3 | X28: 520 | Y28: MXN | Z28: M3 | AA28: D348 | AB28: PD0294 LAGUNA VERDE 2 | AC28: 56103638 | AD28: 6644041540 | AE28: 4 | AF28: ENTREGA DIRECTA | AG28: 1.273 | AH28: M3 | AI28: X | AJ28: 4 | AK28: V4 | AL28: 20230920 | AM28: DW55-900007932-D348-10000834-4
A29: 900006948DW55D32510000372 | B29: 4600050995-10 | C29: 4600050995 | D29: 10 | E29: MXPO | F29: MXL | G29: 900006948 | H29: SF TC- ED -OTONIEL PALENQUE | I29: 5079933 | J29: MEDINA CORNELIO OTONIEL | K29: Z09 | L29: (AP) 90 Dias | M29: 10000372 | N29: Grava Triturada Caliza 20 mm - 3/4" | O29: DW55 | P29: MX-CED. TABASCO | Q29: 20210712 | R29: 20281231 | S29: 20230522 | T29: 20281231 | U29: 400 | V29: MXN | W29: M3 | X29: 195 | Y29: MXN | Z29: M3 | AA29: D325 | AB29: PD0402 PALENQUE II | AC29: 56103637 | AD29: 6644041540 | AE29: 4 | AF29: ENTREGA DIRECTA | AG29: 1.448 | AH29: M3 | AI29: X | AJ29: 4 | AK29: V4 | AL29: 20230920 | AM29: DW55-900006948-D325-10000372-4
A30: 900007052DW55D34810213318 | B30: 4600050996-160 | C30: 4600050996 | D30: 160 | E30: MXPO | F30: MXL | G30: 900007052 | H30: SF TC-ED-SAMUEL CARRASCO | I30: 5080454 | J30: CARRASCO ALCUDIA SAMUEL | K30: N90 | L30: (AP) NAFIN 90 Dias | M30: 10213318 | N30: GRAVA TRITURADA RÍO 10 MM - 3/8" | O30: DW55 | P30: MX-CED. TABASCO | Q30: 20210712 | R30: 20281231 | S30: 20230524 | T30: 20281231 | U30: 1300 | V30: MXN | W30: M3 | X30: 450 | Y30: MXN | Z30: M3 | AA30: D348 | AB30: PD0294 LAGUNA VERDE 2 | AC30: 56103637 | AD30: 6644041540 | AE30: 4 | AF30: ENTREGA DIRECTA | AG30: 1.433 | AH30: M3 | AI30: X | AJ30: 4 | AK30: V4 | AL30: 20230920 | AM30: DW55-900007052-D348-10213318-4
A31: 900007304DW55D30910000373 | B31: 4600053181-110 | C31: 4600053181 | D31: 110 | E31: MXPO | F31: MXL | G31: 900007304 | H31: SF TC-ED-ALFONSO ESPADAS | I31: 5079231 | J31: ESPADAS HERNANDEZ ALFONSO | K31: N90 | L31: (AP) NAFIN 90 Dias | M31: 10000373 | N31: Grava Triturada Caliza 13 mm - 1/2" | O31: DW55 | P31: MX-CED. TABASCO | Q31: 20220214 | R31: 20281231 | S31: 20230307 | T31: 20281231 | U31: 710 | V31: MXN | W31: M3 | X31: 310 | Y31: MXN | Z31: M3 | AA31: D309 | AB31: PD0477 CARDENAS | AC31: 56103637 | AD31: 6644041540 | AE31: 4 | AF31: ENTREGA DIRECTA | AG31: 1.395 | AH31: M3 | AI31: X | AJ31: 4 | AK31: V4 | AL31: 20230920 | AM31: DW55-900007304-D309-10000373-4
A32: 900006948DW55D32510023592 | B32: 4600050995-20 | C32: 4600050995 | D32: 20 | E32: MXPO | F32: MXL | G32: 900006948 | H32: SF TC- ED -OTONIEL PALENQUE | I32: 5079933 | J32: MEDINA CORNELIO OTONIEL | K32: Z09 | L32: (AP) 90 Dias | M32: 10023592 | N32: Arena Triturada Caliza Malla 4 | O32: DW55 | P32: MX-CED. TABASCO | Q32: 20210712 | R32: 20281231 | S32: 20220606 | T32: 20271231 | U32: 335 | V32: MXN | W32: M3 | X32: 185 | Y32: MXN | Z32: M3 | AA32: D325 | AB32: PD0402 PALENQUE II | AC32: 56103638 | AD32: 6644041540 | AE32: 4 | AF32: ENTREGA DIRECTA | AG32: 1.356 | AH32: M3 | AI32: X | AJ32: 4 | AK32: V4 | AL32: 20230920 | AM32: DW55-900006948-D325-10023592-4
A33: 900007484DW55D34810000372 | B33: 4600053253-10 | C33: 4600053253 | D33: 10 | E33: MXPO | F33: MXL | G33: 900007484 | H33: SF-TC-ED-AURELIO CABRERA | I33: 5082823 | J33: CABRERA MARIN AURELIO ANTONIO | K33: Z09 | L33: (AP) 90 Dias | M33: 10000372 | N33: Grava Triturada Caliza 20 mm - 3/4" | O33: DW55 | P33: MX-CED. TABASCO | Q33: 20220222 | R33: 20281231 | S33: 20230111 | T33: 20271231 | U33: 495 | V33: MXN | W33: M3 | X33: 265 | Y33: MXN | Z33: M3 | AA33: D348 | AB33: PD0294 LAGUNA VERDE 2 | AC33: 56103637 | AD33: 6644041540 | AE33: 4 | AF33: ENTREGA DIRECTA | AG33: 1.448 | AH33: M3 | AI33: X | AJ33: 4 | AK33: V4 | AL33: 20230920 | AM33: DW55-900007484-D348-10000372-4
A34: 900007484DW55D34210000372 | B34: 4600053253-100 | C34: 4600053253 | D34: 100 | E34: MXPO | F34: MXL | G34: 900007484 | H34: SF-TC-ED-AURELIO CABRERA | I34: 5082823 | J34: CABRERA MARIN AURELIO ANTONIO | K34: Z09 | L34: (AP) 90 Dias | M34: 10000372 | N34: Grava Triturada Caliza 20 mm - 3/4" | O34: DW55 | P34: MX-CED. TABASCO | Q34: 20220222 | R34: 20281231 | S34: 20251107 | T34: 20301231 | U34: 600 | V34: MXN | W34: M3 | X34: 400 | Y34: MXN | Z34: M3 | AA34: D342 | AB34: PD0268 SAMARIA II -PLANTA 2 | AC34: 56103637 | AD34: 6644041540 | AE34: 4 | AF34: ENTREGA DIRECTA | AG34: 1.448 | AH34: M3 | AI34: X | AJ34: 4 | AK34: V4 | AL34: 20251111 | AM34: DW55-900007484-D342-10000372-4
A35: 900007484DW55D28410000372 | B35: 4600053253-60 | C35: 4600053253 | D35: 60 | E35: MXPO | F35: MXL | G35: 900007484 | H35: SF-TC-ED-AURELIO CABRERA | I35: 5082823 | J35: CABRERA MARIN AURELIO ANTONIO | K35: Z09 | L35: (AP) 90 Dias | M35: 10000372 | N35: Grava Triturada Caliza 20 mm - 3/4" | O35: DW55 | P35: MX-CED. TABASCO | Q35: 20220222 | R35: 20281231 | S35: 20251107 | T35: 20301231 | U35: 480 | V35: MXN | W35: M3 | X35: 280 | Y35: MXN | Z35: M3 | AA35: D284 | AB35: PD0183 VILLAHERMOSA | AC35: 56103637 | AD35: 6644041540 | AE35: 4 | AF35: ENTREGA DIRECTA | AG35: 1.448 | AH35: M3 | AI35: X | AJ35: 4 | AK35: V4 | AL35: 20251111 | AM35: DW55-900007484-D284-10000372-4
A36: 900007484DW55D30910000372 | B36: 4600053253-80 | C36: 4600053253 | D36: 80 | E36: MXPO | F36: MXL | G36: 900007484 | H36: SF-TC-ED-AURELIO CABRERA | I36: 5082823 | J36: CABRERA MARIN AURELIO ANTONIO | K36: Z09 | L36: (AP) 90 Dias | M36: 10000372 | N36: Grava Triturada Caliza 20 mm - 3/4" | O36: DW55 | P36: MX-CED. TABASCO | Q36: 20220222 | R36: 20281231 | S36: 20251107 | T36: 20301231 | U36: 550 | V36: MXN | W36: M3 | X36: 350 | Y36: MXN | Z36: M3 | AA36: D309 | AB36: PD0477 CARDENAS | AC36: 56103637 | AD36: 6644041540 | AE36: 4 | AF36: ENTREGA DIRECTA | AG36: 1.448 | AH36: M3 | AI36: X | AJ36: 4 | AK36: V4 | AL36: 20251111 | AM36: DW55-900007484-D309-10000372-4
A37: 900007604DW55D34210000372 | B37: 4600054544-50 | C37: 4600054544 | D37: 50 | E37: MXPO | F37: MXL | G37: 900007604 | H37: SF TC-ED-FRISO CONSMIN TAB | I37: 5083592 | J37: FRISO CONSMIN SA DE CV | K37: N45 | L37: (AP) NAFIN 45 Dias | M37: 10000372 | N37: Grava Triturada Caliza 20 mm - 3/4" | O37: DW55 | P37: MX-CED. TABASCO | Q37: 20220715 | R37: 20271231 | U37: 0 | V37: MXN | W37: M3 | AA37: D342 | AB37: PD0268 SAMARIA II -PLANTA 2 | AC37: 56103637 | AD37: 6644041540 | AE37: 4 | AF37: ENTREGA DIRECTA | AG37: 1.448 | AH37: M3 | AI37: X | AJ37: 4 | AK37: V4 | AL37: 20260422 | AM37: DW55-900007604-D342-10000372-4
A38: 900007604DW55D34210123034 | B38: 4600054544-80 | C38: 4600054544 | D38: 80 | E38: MXPO | F38: MXL | G38: 900007604 | H38: SF TC-ED-FRISO CONSMIN TAB | I38: 5083592 | J38: FRISO CONSMIN SA DE CV | K38: N45 | L38: (AP) NAFIN 45 Dias | M38: 10123034 | N38: ARENA TRITURADA CALIZA MALLA 4 | O38: DW55 | P38: MX-CED. TABASCO | Q38: 20220715 | R38: 20271231 | U38: 0 | V38: MXN | W38: M3 | AA38: D342 | AB38: PD0268 SAMARIA II -PLANTA 2 | AC38: 56103638 | AD38: 6644041540 | AE38: 4 | AF38: ENTREGA DIRECTA | AG38: 1.528 | AH38: M3 | AI38: X | AJ38: 4 | AK38: V4 | AL38: 20260422 | AM38: DW55-900007604-D342-10123034-4
A39: 900007932DW55D32510000834 | B39: 4600055937-20 | C39: 4600055937 | D39: 20 | E39: MXPO | F39: MXL | G39: 900007932 | H39: SF TC-ED-TRAPA | I39: 5087333 | J39: GARCIA MONTILLA VICTOR DAVID | K39: Z09 | L39: (AP) 90 Dias | M39: 10000834 | N39: Arena Clasificada Río Malla 4 | O39: DW55 | P39: MX-CED. TABASCO | Q39: 20221209 | R39: 20281231 | S39: 20240814 | T39: 20291231 | U39: 435 | V39: MXN | W39: M3 | X39: 200 | Y39: MXN | Z39: M3 | AA39: D325 | AB39: PD0402 PALENQUE II | AC39: 56103638 | AD39: 6644041540 | AE39: 4 | AF39: ENTREGA DIRECTA | AG39: 1.273 | AH39: M3 | AI39: X | AJ39: 4 | AK39: V4 | AL39: 20240819 | AM39: DW55-900007932-D325-10000834-4
A40: 900000743DW5510000372 | B40: 4600050889-50 | C40: 4600050889 | D40: 50 | E40: MXPO | F40: MXL | G40: 900000743 | H40: TC SIGSA | I40: 5021622 | J40: SERVICIOS DE INGENIERIA DEL GOLFO | K40: N60 | L40: (AP) NAFIN 60 Dias | M40: 10000372 | N40: Grava Triturada Caliza 20 mm - 3/4" | O40: DW55 | P40: MX-CED. TABASCO | Q40: 20210712 | R40: 20281231 | S40: 20260428 | T40: 20301231 | U40: 320 | V40: MXN | W40: M3 | X40: 0 | Y40: MXN | Z40: M3 | AC40: 56103637 | AD40: 6644041540 | AE40: 1 | AF40: ENTREGADO | AG40: 1.448 | AH40: M3 | AI40: X | AJ40: 4 | AK40: V4 | AL40: 20260428 | AM40: DW55-900000743-10000372
...
