Workbook

Sheet Base Cedis DW39
N1: VENTA | Q1: COSTO
A2: CONCAT1 | B2: CONCAT2 | C2: No. SF | D2: Nombre SF | E2: Cedis | F2: Destino | G2: Condicion de Expedicion | H2: Nombre Destino | I2: No. de material | J2: Nombre de material | K2: PV | L2: Inicio de vigencia | M2: Fin de vigencia | N2: Importe MP | O2: Importe Flete | P2: UM Venta | Q2: Importe Costo | R2: UM Costo | S2: Validacion 1 | T2: Validacion 2
A3: =CONCATENATE(C3,E3,F3,I3) | B3: =CONCATENATE(C3,E3,I3) | C3: 900008171 | D3: =IFERROR(VLOOKUP(C3,TRAOPE!$G:$H,2,0),"") | E3: DW39 | G3: =IFERROR(VLOOKUP(A3,Flete!$A:$E,5,0),"") | H3: =IFERROR(VLOOKUP(F3,TRAOPE!$AA:$AB,2,0),"") | I3: 10238734 | J3: =IFERROR(VLOOKUP(I3,Materiales!$A:$H,8,0),"") | K3: =IFERROR(VLOOKUP(I3,Materiales!$A:$G,7,0),"") | L3: 20001010 | M3: 20001010 | N3: 499.56 | O3: =IFERROR(VLOOKUP(A3,Flete!$A:$J,10,0),"") | P3: TN | Q3: =IFERROR(IFERROR(VLOOKUP(A3,TRAOPE!$A:$U,21,0),VLOOKUP(B3,TRAOPE!$A:$U,21,0)),"") | R3: =IFERROR(IFERROR(VLOOKUP(A3,TRAOPE!$A:$W,23,0),VLOOKUP(B3,TRAOPE!$A:$W,23,0)),"") | S3: =IF(AND(P3="TN",R3="TN"),N3+N(O3),IF(G3&""="1",N(K3)*N3,(N3+N(O3))*N(K3))) | T3: =IF(Q3="","",Q3-S3)
A4: =CONCATENATE(C4,E4,F4,I4) | B4: =CONCATENATE(C4,E4,I4) | C4: 900008171 | D4: =IFERROR(VLOOKUP(C4,TRAOPE!$G:$H,2,0),"") | E4: DW39 | G4: =IFERROR(VLOOKUP(A4,Flete!$A:$E,5,0),"") | H4: =IFERROR(VLOOKUP(F4,TRAOPE!$AA:$AB,2,0),"") | I4: 10238940 | J4: =IFERROR(VLOOKUP(I4,Materiales!$A:$H,8,0),"") | K4: =IFERROR(VLOOKUP(I4,Materiales!$A:$G,7,0),"") | L4: 20001010 | M4: 20001010 | N4: 456.88 | O4: =IFERROR(VLOOKUP(A4,Flete!$A:$J,10,0),"") | P4: TN | Q4: =IFERROR(IFERROR(VLOOKUP(A4,TRAOPE!$A:$U,21,0),VLOOKUP(B4,TRAOPE!$A:$U,21,0)),"") | R4: =IFERROR(IFERROR(VLOOKUP(A4,TRAOPE!$A:$W,23,0),VLOOKUP(B4,TRAOPE!$A:$W,23,0)),"") | S4: =IF(AND(P4="TN",R4="TN"),N4+N(O4),IF(G4&""="1",N(K4)*N4,(N4+N(O4))*N(K4))) | T4: =IF(Q4="","",Q4-S4)
A5: =CONCATENATE(C5,E5,F5,I5) | B5: =CONCATENATE(C5,E5,I5) | C5: 900008171 | D5: =IFERROR(VLOOKUP(C5,TRAOPE!$G:$H,2,0),"") | E5: DW39 | F5: D297 | G5: =IFERROR(VLOOKUP(A5,Flete!$A:$E,5,0),"") | H5: =IFERROR(VLOOKUP(F5,TRAOPE!$AA:$AB,2,0),"") | I5: 10238734 | J5: =IFERROR(VLOOKUP(I5,Materiales!$A:$H,8,0),"") | K5: =IFERROR(VLOOKUP(I5,Materiales!$A:$G,7,0),"") | L5: 20250301 | M5: 20251031 | N5: 241.86 | O5: =IFERROR(VLOOKUP(A5,Flete!$A:$J,10,0),"") | P5: TN | Q5: =IFERROR(IFERROR(VLOOKUP(A5,TRAOPE!$A:$U,21,0),VLOOKUP(B5,TRAOPE!$A:$U,21,0)),"") | R5: =IFERROR(IFERROR(VLOOKUP(A5,TRAOPE!$A:$W,23,0),VLOOKUP(B5,TRAOPE!$A:$W,23,0)),"") | S5: =IF(AND(P5="TN",R5="TN"),N5+N(O5),IF(G5&""="1",N(K5)*N5,(N5+N(O5))*N(K5))) | T5: =IF(Q5="","",Q5-S5)
A6: =CONCATENATE(C6,E6,F6,I6) | B6: =CONCATENATE(C6,E6,I6) | C6: 900008171 | D6: =IFERROR(VLOOKUP(C6,TRAOPE!$G:$H,2,0),"") | E6: DW39 | F6: D678 | G6: =IFERROR(VLOOKUP(A6,Flete!$A:$E,5,0),"") | H6: =IFERROR(VLOOKUP(F6,TRAOPE!$AA:$AB,2,0),"") | I6: 10238734 | J6: =IFERROR(VLOOKUP(I6,Materiales!$A:$H,8,0),"") | K6: =IFERROR(VLOOKUP(I6,Materiales!$A:$G,7,0),"") | L6: 20250301 | M6: 20251031 | N6: 180.3 | O6: =IFERROR(VLOOKUP(A6,Flete!$A:$J,10,0),"") | P6: TN | Q6: =IFERROR(IFERROR(VLOOKUP(A6,TRAOPE!$A:$U,21,0),VLOOKUP(B6,TRAOPE!$A:$U,21,0)),"") | R6: =IFERROR(IFERROR(VLOOKUP(A6,TRAOPE!$A:$W,23,0),VLOOKUP(B6,TRAOPE!$A:$W,23,0)),"") | S6: =IF(AND(P6="TN",R6="TN"),N6+N(O6),IF(G6&""="1",N(K6)*N6,(N6+N(O6))*N(K6))) | T6: =IF(Q6="","",Q6-S6)
A7: =CONCATENATE(C7,E7,F7,I7) | B7: =CONCATENATE(C7,E7,I7) | C7: 900008171 | D7: =IFERROR(VLOOKUP(C7,TRAOPE!$G:$H,2,0),"") | E7: DW39 | F7: D678 | G7: =IFERROR(VLOOKUP(A7,Flete!$A:$E,5,0),"") | H7: =IFERROR(VLOOKUP(F7,TRAOPE!$AA:$AB,2,0),"") | I7: 10238940 | J7: =IFERROR(VLOOKUP(I7,Materiales!$A:$H,8,0),"") | K7: =IFERROR(VLOOKUP(I7,Materiales!$A:$G,7,0),"") | L7: 20250301 | M7: 20251031 | N7: 472.01 | O7: =IFERROR(VLOOKUP(A7,Flete!$A:$J,10,0),"") | P7: TN | Q7: =IFERROR(IFERROR(VLOOKUP(A7,TRAOPE!$A:$U,21,0),VLOOKUP(B7,TRAOPE!$A:$U,21,0)),"") | R7: =IFERROR(IFERROR(VLOOKUP(A7,TRAOPE!$A:$W,23,0),VLOOKUP(B7,TRAOPE!$A:$W,23,0)),"") | S7: =IF(AND(P7="TN",R7="TN"),N7+N(O7),IF(G7&""="1",N(K7)*N7,(N7+N(O7))*N(K7))) | T7: =IF(Q7="","",Q7-S7)
A8: =CONCATENATE(C8,E8,F8,I8) | B8: =CONCATENATE(C8,E8,I8) | C8: 900008171 | D8: =IFERROR(VLOOKUP(C8,TRAOPE!$G:$H,2,0),"") | E8: DW39 | F8: EQ86 | G8: =IFERROR(VLOOKUP(A8,Flete!$A:$E,5,0),"") | H8: =IFERROR(VLOOKUP(F8,TRAOPE!$AA:$AB,2,0),"") | I8: 10238734 | J8: =IFERROR(VLOOKUP(I8,Materiales!$A:$H,8,0),"") | K8: =IFERROR(VLOOKUP(I8,Materiales!$A:$G,7,0),"") | L8: 20240607 | M8: 20250220 | N8: 499.56 | O8: =IFERROR(VLOOKUP(A8,Flete!$A:$J,10,0),"") | P8: TN | Q8: =IFERROR(IFERROR(VLOOKUP(A8,TRAOPE!$A:$U,21,0),VLOOKUP(B8,TRAOPE!$A:$U,21,0)),"") | R8: =IFERROR(IFERROR(VLOOKUP(A8,TRAOPE!$A:$W,23,0),VLOOKUP(B8,TRAOPE!$A:$W,23,0)),"") | S8: =IF(AND(P8="TN",R8="TN"),N8+N(O8),IF(G8&""="1",N(K8)*N8,(N8+N(O8))*N(K8))) | T8: =IF(Q8="","",Q8-S8)
A9: =CONCATENATE(C9,E9,F9,I9) | B9: =CONCATENATE(C9,E9,I9) | C9: 900008171 | D9: =IFERROR(VLOOKUP(C9,TRAOPE!$G:$H,2,0),"") | E9: DW39 | F9: EQ86 | G9: =IFERROR(VLOOKUP(A9,Flete!$A:$E,5,0),"") | H9: =IFERROR(VLOOKUP(F9,TRAOPE!$AA:$AB,2,0),"") | I9: 10238940 | J9: =IFERROR(VLOOKUP(I9,Materiales!$A:$H,8,0),"") | K9: =IFERROR(VLOOKUP(I9,Materiales!$A:$G,7,0),"") | L9: 20240607 | M9: 20250220 | N9: 456.88 | O9: =IFERROR(VLOOKUP(A9,Flete!$A:$J,10,0),"") | P9: TN | Q9: =IFERROR(IFERROR(VLOOKUP(A9,TRAOPE!$A:$U,21,0),VLOOKUP(B9,TRAOPE!$A:$U,21,0)),"") | R9: =IFERROR(IFERROR(VLOOKUP(A9,TRAOPE!$A:$W,23,0),VLOOKUP(B9,TRAOPE!$A:$W,23,0)),"") | S9: =IF(AND(P9="TN",R9="TN"),N9+N(O9),IF(G9&""="1",N(K9)*N9,(N9+N(O9))*N(K9))) | T9: =IF(Q9="","",Q9-S9)
A10: =CONCATENATE(C10,E10,F10,I10) | B10: =CONCATENATE(C10,E10,I10) | C10: 900008171 | D10: =IFERROR(VLOOKUP(C10,TRAOPE!$G:$H,2,0),"") | E10: DW39 | F10: ER00 | G10: =IFERROR(VLOOKUP(A10,Flete!$A:$E,5,0),"") | H10: =IFERROR(VLOOKUP(F10,TRAOPE!$AA:$AB,2,0),"") | I10: 10000861 | J10: =IFERROR(VLOOKUP(I10,Materiales!$A:$H,8,0),"") | K10: =IFERROR(VLOOKUP(I10,Materiales!$A:$G,7,0),"") | L10: 20240320 | M10: 20250220 | N10: 184.21 | O10: =IFERROR(VLOOKUP(A10,Flete!$A:$J,10,0),"") | P10: TN | Q10: =IFERROR(IFERROR(VLOOKUP(A10,TRAOPE!$A:$U,21,0),VLOOKUP(B10,TRAOPE!$A:$U,21,0)),"") | R10: =IFERROR(IFERROR(VLOOKUP(A10,TRAOPE!$A:$W,23,0),VLOOKUP(B10,TRAOPE!$A:$W,23,0)),"") | S10: =IF(AND(P10="TN",R10="TN"),N10+N(O10),IF(G10&""="1",N(K10)*N10,(N10+N(O10))*N(K10))) | T10: =IF(Q10="","",Q10-S10)
A11: =CONCATENATE(C11,E11,F11,I11) | B11: =CONCATENATE(C11,E11,I11) | C11: 900008171 | D11: =IFERROR(VLOOKUP(C11,TRAOPE!$G:$H,2,0),"") | E11: DW39 | F11: ER00 | G11: =IFERROR(VLOOKUP(A11,Flete!$A:$E,5,0),"") | H11: =IFERROR(VLOOKUP(F11,TRAOPE!$AA:$AB,2,0),"") | I11: 10238734 | J11: =IFERROR(VLOOKUP(I11,Materiales!$A:$H,8,0),"") | K11: =IFERROR(VLOOKUP(I11,Materiales!$A:$G,7,0),"") | L11: 20240320 | M11: 20250220 | N11: 499.56 | O11: =IFERROR(VLOOKUP(A11,Flete!$A:$J,10,0),"") | P11: TN | Q11: =IFERROR(IFERROR(VLOOKUP(A11,TRAOPE!$A:$U,21,0),VLOOKUP(B11,TRAOPE!$A:$U,21,0)),"") | R11: =IFERROR(IFERROR(VLOOKUP(A11,TRAOPE!$A:$W,23,0),VLOOKUP(B11,TRAOPE!$A:$W,23,0)),"") | S11: =IF(AND(P11="TN",R11="TN"),N11+N(O11),IF(G11&""="1",N(K11)*N11,(N11+N(O11))*N(K11))) | T11: =IF(Q11="","",Q11-S11)
A12: =CONCATENATE(C12,E12,F12,I12) | B12: =CONCATENATE(C12,E12,I12) | C12: 900008171 | D12: =IFERROR(VLOOKUP(C12,TRAOPE!$G:$H,2,0),"") | E12: DW39 | F12: ER00 | G12: =IFERROR(VLOOKUP(A12,Flete!$A:$E,5,0),"") | H12: =IFERROR(VLOOKUP(F12,TRAOPE!$AA:$AB,2,0),"") | I12: 10238940 | J12: =IFERROR(VLOOKUP(I12,Materiales!$A:$H,8,0),"") | K12: =IFERROR(VLOOKUP(I12,Materiales!$A:$G,7,0),"") | L12: 20240320 | M12: 20250220 | N12: 456.88 | O12: =IFERROR(VLOOKUP(A12,Flete!$A:$J,10,0),"") | P12: TN | Q12: =IFERROR(IFERROR(VLOOKUP(A12,TRAOPE!$A:$U,21,0),VLOOKUP(B12,TRAOPE!$A:$U,21,0)),"") | R12: =IFERROR(IFERROR(VLOOKUP(A12,TRAOPE!$A:$W,23,0),VLOOKUP(B12,TRAOPE!$A:$W,23,0)),"") | S12: =IF(AND(P12="TN",R12="TN"),N12+N(O12),IF(G12&""="1",N(K12)*N12,(N12+N(O12))*N(K12))) | T12: =IF(Q12="","",Q12-S12)
A13: =CONCATENATE(C13,E13,F13,I13) | B13: =CONCATENATE(C13,E13,I13) | C13: 900008184 | D13: =IFERROR(VLOOKUP(C13,TRAOPE!$G:$H,2,0),"") | E13: DW39 | F13: ER00 | G13: =IFERROR(VLOOKUP(A13,Flete!$A:$E,5,0),"") | H13: =IFERROR(VLOOKUP(F13,TRAOPE!$AA:$AB,2,0),"") | I13: 10238734 | J13: =IFERROR(VLOOKUP(I13,Materiales!$A:$H,8,0),"") | K13: =IFERROR(VLOOKUP(I13,Materiales!$A:$G,7,0),"") | L13: 20240320 | M13: 20250220 | N13: 517.15 | O13: =IFERROR(VLOOKUP(A13,Flete!$A:$J,10,0),"") | P13: TN | Q13: =IFERROR(IFERROR(VLOOKUP(A13,TRAOPE!$A:$U,21,0),VLOOKUP(B13,TRAOPE!$A:$U,21,0)),"") | R13: =IFERROR(IFERROR(VLOOKUP(A13,TRAOPE!$A:$W,23,0),VLOOKUP(B13,TRAOPE!$A:$W,23,0)),"") | S13: =IF(AND(P13="TN",R13="TN"),N13+N(O13),IF(G13&""="1",N(K13)*N13,(N13+N(O13))*N(K13))) | T13: =IF(Q13="","",Q13-S13)
A14: =CONCATENATE(C14,E14,F14,I14) | B14: =CONCATENATE(C14,E14,I14) | C14: 900008184 | D14: =IFERROR(VLOOKUP(C14,TRAOPE!$G:$H,2,0),"") | E14: DW39 | F14: ER00 | G14: =IFERROR(VLOOKUP(A14,Flete!$A:$E,5,0),"") | H14: =IFERROR(VLOOKUP(F14,TRAOPE!$AA:$AB,2,0),"") | I14: 10238940 | J14: =IFERROR(VLOOKUP(I14,Materiales!$A:$H,8,0),"") | K14: =IFERROR(VLOOKUP(I14,Materiales!$A:$G,7,0),"") | L14: 20240320 | M14: 20250220 | N14: 472.01 | O14: =IFERROR(VLOOKUP(A14,Flete!$A:$J,10,0),"") | P14: TN | Q14: =IFERROR(IFERROR(VLOOKUP(A14,TRAOPE!$A:$U,21,0),VLOOKUP(B14,TRAOPE!$A:$U,21,0)),"") | R14: =IFERROR(IFERROR(VLOOKUP(A14,TRAOPE!$A:$W,23,0),VLOOKUP(B14,TRAOPE!$A:$W,23,0)),"") | S14: =IF(AND(P14="TN",R14="TN"),N14+N(O14),IF(G14&""="1",N(K14)*N14,(N14+N(O14))*N(K14))) | T14: =IF(Q14="","",Q14-S14)
A15: =CONCATENATE(C15,E15,F15,I15) | B15: =CONCATENATE(C15,E15,I15) | C15: 900008207 | D15: =IFERROR(VLOOKUP(C15,TRAOPE!$G:$H,2,0),"") | E15: DW39 | G15: =IFERROR(VLOOKUP(A15,Flete!$A:$E,5,0),"") | H15: =IFERROR(VLOOKUP(F15,TRAOPE!$AA:$AB,2,0),"") | I15: 10239308 | J15: =IFERROR(VLOOKUP(I15,Materiales!$A:$H,8,0),"") | K15: =IFERROR(VLOOKUP(I15,Materiales!$A:$G,7,0),"") | L15: 20001010 | M15: 20001010 | N15: 480.14 | O15: =IFERROR(VLOOKUP(A15,Flete!$A:$J,10,0),"") | P15: TN | Q15: =IFERROR(IFERROR(VLOOKUP(A15,TRAOPE!$A:$U,21,0),VLOOKUP(B15,TRAOPE!$A:$U,21,0)),"") | R15: =IFERROR(IFERROR(VLOOKUP(A15,TRAOPE!$A:$W,23,0),VLOOKUP(B15,TRAOPE!$A:$W,23,0)),"") | S15: =IF(AND(P15="TN",R15="TN"),N15+N(O15),IF(G15&""="1",N(K15)*N15,(N15+N(O15))*N(K15))) | T15: =IF(Q15="","",Q15-S15)
A16: =CONCATENATE(C16,E16,F16,I16) | B16: =CONCATENATE(C16,E16,I16) | C16: 900008207 | D16: =IFERROR(VLOOKUP(C16,TRAOPE!$G:$H,2,0),"") | E16: DW39 | G16: =IFERROR(VLOOKUP(A16,Flete!$A:$E,5,0),"") | H16: =IFERROR(VLOOKUP(F16,TRAOPE!$AA:$AB,2,0),"") | I16: 10239309 | J16: =IFERROR(VLOOKUP(I16,Materiales!$A:$H,8,0),"") | K16: =IFERROR(VLOOKUP(I16,Materiales!$A:$G,7,0),"") | L16: 20001010 | M16: 20001010 | N16: 495.89 | O16: =IFERROR(VLOOKUP(A16,Flete!$A:$J,10,0),"") | P16: TN | Q16: =IFERROR(IFERROR(VLOOKUP(A16,TRAOPE!$A:$U,21,0),VLOOKUP(B16,TRAOPE!$A:$U,21,0)),"") | R16: =IFERROR(IFERROR(VLOOKUP(A16,TRAOPE!$A:$W,23,0),VLOOKUP(B16,TRAOPE!$A:$W,23,0)),"") | S16: =IF(AND(P16="TN",R16="TN"),N16+N(O16),IF(G16&""="1",N(K16)*N16,(N16+N(O16))*N(K16))) | T16: =IF(Q16="","",Q16-S16)
A17: =CONCATENATE(C17,E17,F17,I17) | B17: =CONCATENATE(C17,E17,I17) | C17: 900008207 | D17: =IFERROR(VLOOKUP(C17,TRAOPE!$G:$H,2,0),"") | E17: DW39 | F17: ER00 | G17: =IFERROR(VLOOKUP(A17,Flete!$A:$E,5,0),"") | H17: =IFERROR(VLOOKUP(F17,TRAOPE!$AA:$AB,2,0),"") | I17: 10239308 | J17: =IFERROR(VLOOKUP(I17,Materiales!$A:$H,8,0),"") | K17: =IFERROR(VLOOKUP(I17,Materiales!$A:$G,7,0),"") | L17: 20240320 | M17: 20250220 | N17: 480.14 | O17: =IFERROR(VLOOKUP(A17,Flete!$A:$J,10,0),"") | P17: TN | Q17: =IFERROR(IFERROR(VLOOKUP(A17,TRAOPE!$A:$U,21,0),VLOOKUP(B17,TRAOPE!$A:$U,21,0)),"") | R17: =IFERROR(IFERROR(VLOOKUP(A17,TRAOPE!$A:$W,23,0),VLOOKUP(B17,TRAOPE!$A:$W,23,0)),"") | S17: =IF(AND(P17="TN",R17="TN"),N17+N(O17),IF(G17&""="1",N(K17)*N17,(N17+N(O17))*N(K17))) | T17: =IF(Q17="","",Q17-S17)
A18: =CONCATENATE(C18,E18,F18,I18) | B18: =CONCATENATE(C18,E18,I18) | C18: 900008207 | D18: =IFERROR(VLOOKUP(C18,TRAOPE!$G:$H,2,0),"") | E18: DW39 | F18: ER00 | G18: =IFERROR(VLOOKUP(A18,Flete!$A:$E,5,0),"") | H18: =IFERROR(VLOOKUP(F18,TRAOPE!$AA:$AB,2,0),"") | I18: 10239309 | J18: =IFERROR(VLOOKUP(I18,Materiales!$A:$H,8,0),"") | K18: =IFERROR(VLOOKUP(I18,Materiales!$A:$G,7,0),"") | L18: 20240320 | M18: 20250220 | N18: 495.89 | O18: =IFERROR(VLOOKUP(A18,Flete!$A:$J,10,0),"") | P18: TN | Q18: =IFERROR(IFERROR(VLOOKUP(A18,TRAOPE!$A:$U,21,0),VLOOKUP(B18,TRAOPE!$A:$U,21,0)),"") | R18: =IFERROR(IFERROR(VLOOKUP(A18,TRAOPE!$A:$W,23,0),VLOOKUP(B18,TRAOPE!$A:$W,23,0)),"") | S18: =IF(AND(P18="TN",R18="TN"),N18+N(O18),IF(G18&""="1",N(K18)*N18,(N18+N(O18))*N(K18))) | T18: =IF(Q18="","",Q18-S18)
A19: =CONCATENATE(C19,E19,F19,I19) | B19: =CONCATENATE(C19,E19,I19) | C19: 900008365 | D19: =IFERROR(VLOOKUP(C19,TRAOPE!$G:$H,2,0),"") | E19: DW39 | G19: =IFERROR(VLOOKUP(A19,Flete!$A:$E,5,0),"") | H19: =IFERROR(VLOOKUP(F19,TRAOPE!$AA:$AB,2,0),"") | I19: 10239308 | J19: =IFERROR(VLOOKUP(I19,Materiales!$A:$H,8,0),"") | K19: =IFERROR(VLOOKUP(I19,Materiales!$A:$G,7,0),"") | L19: 20001010 | M19: 20001010 | N19: 480.14 | O19: =IFERROR(VLOOKUP(A19,Flete!$A:$J,10,0),"") | P19: TN | Q19: =IFERROR(IFERROR(VLOOKUP(A19,TRAOPE!$A:$U,21,0),VLOOKUP(B19,TRAOPE!$A:$U,21,0)),"") | R19: =IFERROR(IFERROR(VLOOKUP(A19,TRAOPE!$A:$W,23,0),VLOOKUP(B19,TRAOPE!$A:$W,23,0)),"") | S19: =IF(AND(P19="TN",R19="TN"),N19+N(O19),IF(G19&""="1",N(K19)*N19,(N19+N(O19))*N(K19))) | T19: =IF(Q19="","",Q19-S19)
A20: =CONCATENATE(C20,E20,F20,I20) | B20: =CONCATENATE(C20,E20,I20) | C20: 900008365 | D20: =IFERROR(VLOOKUP(C20,TRAOPE!$G:$H,2,0),"") | E20: DW39 | G20: =IFERROR(VLOOKUP(A20,Flete!$A:$E,5,0),"") | H20: =IFERROR(VLOOKUP(F20,TRAOPE!$AA:$AB,2,0),"") | I20: 10239309 | J20: =IFERROR(VLOOKUP(I20,Materiales!$A:$H,8,0),"") | K20: =IFERROR(VLOOKUP(I20,Materiales!$A:$G,7,0),"") | L20: 20001010 | M20: 20001010 | N20: 495.89 | O20: =IFERROR(VLOOKUP(A20,Flete!$A:$J,10,0),"") | P20: TN | Q20: =IFERROR(IFERROR(VLOOKUP(A20,TRAOPE!$A:$U,21,0),VLOOKUP(B20,TRAOPE!$A:$U,21,0)),"") | R20: =IFERROR(IFERROR(VLOOKUP(A20,TRAOPE!$A:$W,23,0),VLOOKUP(B20,TRAOPE!$A:$W,23,0)),"") | S20: =IF(AND(P20="TN",R20="TN"),N20+N(O20),IF(G20&""="1",N(K20)*N20,(N20+N(O20))*N(K20))) | T20: =IF(Q20="","",Q20-S20)
A21: =CONCATENATE(C21,E21,F21,I21) | B21: =CONCATENATE(C21,E21,I21) | C21: 900008365 | D21: =IFERROR(VLOOKUP(C21,TRAOPE!$G:$H,2,0),"") | E21: DW39 | F21: ER00 | G21: =IFERROR(VLOOKUP(A21,Flete!$A:$E,5,0),"") | H21: =IFERROR(VLOOKUP(F21,TRAOPE!$AA:$AB,2,0),"") | I21: 10239308 | J21: =IFERROR(VLOOKUP(I21,Materiales!$A:$H,8,0),"") | K21: =IFERROR(VLOOKUP(I21,Materiales!$A:$G,7,0),"") | L21: 20240320 | M21: 20250220 | N21: 480.14 | O21: =IFERROR(VLOOKUP(A21,Flete!$A:$J,10,0),"") | P21: TN | Q21: =IFERROR(IFERROR(VLOOKUP(A21,TRAOPE!$A:$U,21,0),VLOOKUP(B21,TRAOPE!$A:$U,21,0)),"") | R21: =IFERROR(IFERROR(VLOOKUP(A21,TRAOPE!$A:$W,23,0),VLOOKUP(B21,TRAOPE!$A:$W,23,0)),"") | S21: =IF(AND(P21="TN",R21="TN"),N21+N(O21),IF(G21&""="1",N(K21)*N21,(N21+N(O21))*N(K21))) | T21: =IF(Q21="","",Q21-S21)
A22: =CONCATENATE(C22,E22,F22,I22) | B22: =CONCATENATE(C22,E22,I22) | C22: 900008365 | D22: =IFERROR(VLOOKUP(C22,TRAOPE!$G:$H,2,0),"") | E22: DW39 | F22: ER00 | G22: =IFERROR(VLOOKUP(A22,Flete!$A:$E,5,0),"") | H22: =IFERROR(VLOOKUP(F22,TRAOPE!$AA:$AB,2,0),"") | I22: 10239309 | J22: =IFERROR(VLOOKUP(I22,Materiales!$A:$H,8,0),"") | K22: =IFERROR(VLOOKUP(I22,Materiales!$A:$G,7,0),"") | L22: 20240320 | M22: 20250220 | N22: 495.89 | O22: =IFERROR(VLOOKUP(A22,Flete!$A:$J,10,0),"") | P22: TN | Q22: =IFERROR(IFERROR(VLOOKUP(A22,TRAOPE!$A:$U,21,0),VLOOKUP(B22,TRAOPE!$A:$U,21,0)),"") | R22: =IFERROR(IFERROR(VLOOKUP(A22,TRAOPE!$A:$W,23,0),VLOOKUP(B22,TRAOPE!$A:$W,23,0)),"") | S22: =IF(AND(P22="TN",R22="TN"),N22+N(O22),IF(G22&""="1",N(K22)*N22,(N22+N(O22))*N(K22))) | T22: =IF(Q22="","",Q22-S22)

Sheet MP
A1: No. SF | B1: Cedis | C1: Destino | D1: No. Material | E1: Nombre Material | F1: Importe MP | G1: Moneda | H1: Cantidad | I1: UM | J1: C | K1: Inicio Vigencia | L1: Fin Vigencia
A2: 900008171 | B2: DW39 | D2: 10238734 | F2: 499.56 | I2: TN | K2: 20001010 | L2: 20001010
A3: 900008171 | B3: DW39 | D3: 10238940 | F3: 456.88 | I3: TN | K3: 20001010 | L3: 20001010
A4: 900008171 | B4: DW39 | C4: D297 | D4: 10238734 | F4: 241.86 | I4: TN | K4: 20250301 | L4: 20251031
A5: 900008171 | B5: DW39 | C5: D678 | D5: 10238734 | F5: 180.3 | I5: TN | K5: 20250301 | L5: 20251031
A6: 900008171 | B6: DW39 | C6: D678 | D6: 10238940 | F6: 472.01 | I6: TN | K6: 20250301 | L6: 20251031
A7: 900008171 | B7: DW39 | C7: EQ86 | D7: 10238734 | F7: 499.56 | I7: TN | K7: 20240607 | L7: 20250220
A8: 900008171 | B8: DW39 | C8: EQ86 | D8: 10238940 | F8: 456.88 | I8: TN | K8: 20240607 | L8: 20250220
A9: 900008171 | B9: DW39 | C9: ER00 | D9: 10000861 | F9: 184.21 | I9: TN | K9: 20240320 | L9: 20250220
A10: 900008171 | B10: DW39 | C10: ER00 | D10: 10238734 | F10: 499.56 | I10: TN | K10: 20240320 | L10: 20250220
A11: 900008171 | B11: DW39 | C11: ER00 | D11: 10238940 | F11: 456.88 | I11: TN | K11: 20240320 | L11: 20250220
A12: 900008184 | B12: DW39 | C12: ER00 | D12: 10238734 | F12: 517.15 | I12: TN | K12: 20240320 | L12: 20250220
A13: 900008184 | B13: DW39 | C13: ER00 | D13: 10238940 | F13: 472.01 | I13: TN | K13: 20240320 | L13: 20250220
A14: 900008207 | B14: DW39 | D14: 10239308 | F14: 480.14 | I14: TN | K14: 20001010 | L14: 20001010
A15: 900008207 | B15: DW39 | D15: 10239309 | F15: 495.89 | I15: TN | K15: 20001010 | L15: 20001010
A16: 900008207 | B16: DW39 | C16: ER00 | D16: 10239308 | F16: 480.14 | I16: TN | K16: 20240320 | L16: 20250220
A17: 900008207 | B17: DW39 | C17: ER00 | D17: 10239309 | F17: 495.89 | I17: TN | K17: 20240320 | L17: 20250220
A18: 900008365 | B18: DW39 | D18: 10239308 | F18: 480.14 | I18: TN | K18: 20001010 | L18: 20001010
A19: 900008365 | B19: DW39 | D19: 10239309 | F19: 495.89 | I19: TN | K19: 20001010 | L19: 20001010
A20: 900008365 | B20: DW39 | C20: ER00 | D20: 10239308 | F20: 480.14 | I20: TN | K20: 20240320 | L20: 20250220
A21: 900008365 | B21: DW39 | C21: ER00 | D21: 10239309 | F21: 495.89 | I21: TN | K21: 20240320 | L21: 20250220

Sheet Flete
A1: Concat1 | B1: No. SF | C1: Cedis | D1: Destino | E1: Cond. Exp. | F1: Material | H1: Nombre Material | J1: Importe Flete | K1: Moneda | L1: Cantidad | M1: UM | N1: C | P1: Inicio Vigencia | Q1: Fin Vigencia
A2: 900008171DW39D29710238734 | B2: 900008171 | C2: DW39 | D2: D297 | E2: 1 | F2: 10238734 | J2: 175.9 | M2: TN | P2: 20230831 | Q2: 20251031
A3: 900008171DW39D67810238734 | B3: 900008171 | C3: DW39 | D3: D678 | E3: 1 | F3: 10238734 | J3: 153.91 | M3: TN | P3: 20230831 | Q3: 20251031
A4: 900008171DW39D67810238940 | B4: 900008171 | C4: DW39 | D4: D678 | E4: 1 | F4: 10238940 | J4: 121.03 | M4: TN | P4: 20230831 | Q4: 20251031
A5: 900008171DW39EQ8610229215 | B5: 900008171 | C5: DW39 | D5: EQ86 | E5: 1 | F5: 10229215 | J5: 103.8 | M5: TN | P5: 20240320 | Q5: 20250220
A6: 900008171DW39EQ8610231740 | B6: 900008171 | C6: DW39 | D6: EQ86 | E6: 1 | F6: 10231740 | J6: 114 | M6: TN | P6: 20240320 | Q6: 20250220
A7: 900008171DW39EQ8610238734 | B7: 900008171 | C7: DW39 | D7: EQ86 | E7: 1 | F7: 10238734 | J7: 127.44 | M7: TN | P7: 20240320 | Q7: 20250220
A8: 900008171DW39EQ8610238940 | B8: 900008171 | C8: DW39 | D8: EQ86 | E8: 1 | F8: 10238940 | J8: 109.61 | M8: TN | P8: 20240320 | Q8: 20250220
A9: 900008365DW3910239308 | B9: 900008365 | C9: DW39 | E9: 4 | F9: 10239308 | J9: 15.22 | M9: TN | P9: 20001010 | Q9: 20001010
A10: 900008365DW3910239309 | B10: 900008365 | C10: DW39 | E10: 4 | F10: 10239309 | J10: 14.78 | M10: TN | P10: 20001010 | Q10: 20001010
A11: 900008365DW39ER0010239308 | B11: 900008365 | C11: DW39 | D11: ER00 | E11: 4 | F11: 10239308 | J11: 15.22 | M11: TN | P11: 20240320 | Q11: 20250220
A12: 900008365DW39ER0010239309 | B12: 900008365 | C12: DW39 | D12: ER00 | E12: 4 | F12: 10239309 | J12: 14.78 | M12: TN | P12: 20240320 | Q12: 20250220

Sheet Materiales
A1: Material | B1: TpMt | C1: Denom | D1: UMA | E1: Contador | F1: UMB | G1: PV | H1: Nombre Material
A2: 10000001 | B2: ZFER | C2: 1000 | D2: M3 | E2: 1000 | F2: TN | G2: 1262 | H2: GRAVA ANDESITA 10 MM (3/8")
A3: 10000003 | B3: ZFER | C3: 1000 | D3: M3 | E3: 1000 | F3: TN | G3: 1443 | H3: GRAVA CALIZA 10 MM (3/8")
A4: 10000006 | B4: ZFER | C4: 1000 | D4: M3 | E4: 1000 | F4: TN | G4: 1490 | H4: GRAVA RIO 10 MM (3/8")
A5: 10000007 | B5: ZFER | C5: 1000 | D5: M3 | E5: 1000 | F5: TN | G5: 1488 | H5: GRAVA BASALTO 13 MM (1/2")
A6: 10000008 | B6: ZFER | C6: 1000 | D6: M3 | E6: 1000 | F6: TN | G6: 1358 | H6: GRAVA CALIZA 13 MM (1/2")
A7: 10000011 | B7: ZFER | C7: 1000 | D7: M3 | E7: 1000 | F7: TN | G7: 1323 | H7: GRAVA ANDESITA 20 MM (3/4")
A8: 10000013 | B8: ZFER | C8: 1000 | D8: M3 | E8: 1000 | F8: TN | G8: 1514 | H8: GRAVA BASALTO 20 MM (3/4")
A9: 10000014 | B9: ZFER | C9: 1000 | D9: M3 | E9: 1000 | F9: TN | G9: 1400 | H9: GRAVA CALIZA 20 MM (3/4")
A10: 10000015 | B10: ZFER | C10: 1000 | D10: M3 | E10: 1000 | F10: TN | G10: 1410 | H10: GRAVA GRANITO 20 MM (3/4")
A11: 10000017 | B11: ZFER | C11: 1000 | D11: M3 | E11: 1000 | F11: TN | G11: 1475 | H11: GRAVA RIOLITA 20 MM (3/4")
A12: 10000019 | B12: ZFER | C12: 1000 | D12: M3 | E12: 1000 | F12: TN | G12: 1515 | H12: GRAVA RIO 20 MM (3/4")
A13: 10000020 | B13: ZFER | C13: 1000 | D13: M3 | E13: 1 | F13: TN | G13: 1 | H13: GRAVA MAQUILA 40MM (1 1/2")
... A2291: 10268770 | B2291: ZFE3 | C2291: 1000 | D2291: M3 | E2291: 1000 | F2291: TN | G2291: 1240 | H2291: MP GRAVA TRIT CALIZA 40MM 1 1/2" - ESP
A2292: 10268901 | B2292: ZFE3 | C2292: 1000 | D2292: M3 | E2292: 1000 | G2292: 1560 | H2292: MP GRAVA ANDESITA GRIS 3/4" - CAPADA
A2293: 10267983 | C2293: 1000 | G2293: 1800 | H2293: ESCORIA ALTO HORNO 3/4
A2294: 10268996 | C2294: 1000 | G2294: 1329 | H2294: GRAVA TRITURADA CALIZA 40 MM - 11/2"
A2295: 10269072 | C2295: 1000 | G2295: 1700 | H2295: BASE HIDRÁULICA SCREEN
A2296: 10269225 | B2296: ZFE3 | C2296: 1000 | D2296: M3 | E2296: 1000 | G2296: 1289 | H2296: MP ARENA CALIZA LAVADA MALLA 4 - DELTA I
A2297: 10269245 | B2297: ZFE3 | C2297: 1000 | D2297: M3 | E2297: 1000 | G2297: 1410 | H2297: MP GRAVA TRITURADA CALIZA 3/8 - 10MM
A2298: 10269246 | B2298: ZFE3 | C2298: 1000 | D2298: M3 | E2298: 1000 | G2298: 1400 | H2298: MP GRAVA TRITURADA CALIZA 1 1/2 - 40MM
A2299: 10269247 | B2299: ZFE3 | C2299: 1000 | D2299: M3 | E2299: 1000 | G2299: 1560 | H2299: MP ARENA TRIT CALIZA M-4
A2300: 10270431 | B2300: ZFE3 | C2300: 1000 | D2300: M3 | E2300: 1000 | G2300: 1423 | H2300: MP GRAVA RIOLITA 13 MM - 1/2"
A2301: 10270898 | B2301: ZFE3 | C2301: 1000 | D2301: M3 | E2301: 1000 | G2301: 1551 | H2301: MP BASE H. TRIT. BASALTO 1 1/2" A FINOS
A2302: 10270911 | B2302: ZFE3 | C2302: 1000 | D2302: M3 | E2302: 1000 | G2302: 1360 | H2302: MP GRAVA TRIT. BASALTO 40 MM - 1 1/2"
A2303: 10270912 | B2303: ZFE3 | C2303: 1000 | D2303: M3 | E2303: 1000 | G2303: 1589 | H2303: MP ARENA TRIT. BASALTO MALLA 4
A2304: 10270913 | B2304: ZFE3 | C2304: 1000 | D2304: M3 | E2304: 1000 | G2304: 1395 | H2304: MP GRAVA TRIT. BASALTO 20 MM - 3/4
A2305: 10270914 | B2305: ZFE3 | C2305: 1000 | D2305: M3 | E2305: 1000 | G2305: 1623 | H2305: MP ARENA ANDESITA BC
A2306: 10270824 | B2306: M3 | C2306: 1000 | D2306: M3 | E2306: 10007640 | G2306: 1325 | H2306: MP ARENA TRITURADA CALIZA MALLA 5
A2307: 10270825 | B2307: M3 | C2307: 1000 | D2307: M3 | E2307: 10000003 | G2307: 1242 | H2307: MP GRAVA TRITURADA CALIZA 10MM (3/8”)
... A2319: 10272527 | B2319: ZFE3 | C2319: 1000 | D2319: M3 | E2319: 1000 | G2319: 1620 | H2319: CNC - NO CLASIFICADO
A2320: 10000332 | C2320: 1000 | D2320: M3 | E2320: 1000 | G2320: 800 | H2320: Grava Triturada Pomez - Jal 20 mm - 3/4"
A2321: 10273001 | B2321: ZFE3 | C2321: 1000 | D2321: M3 | E2321: 1000 | G2321: 1688 | H2321: MP ARENA TRIT. BASALTO MALLA 4
A2322: 10273002 | B2322: ZFE3 | C2322: 1000 | D2322: M3 | E2322: 1000 | G2322: 1466 | H2322: MP GRAVA TRIT. BASALTO 20 MM - 3/4"
A2323: 10273351 | B2323: ZFE3 | C2323: 1000 | D2323: M3 | E2323: 1000 | G2323: 1612 | H2323: MP ARENA TRIT. CALIZA MALLA 4
A2324: 10273352 | B2324: ZFE3 | C2324: 1000 | D2324: M3 | E2324: 1000 | G2324: 1492 | H2324: MP GRAVA TRIT. CALIZA 20 MM - 3/4"
A2325: 10271724 | B2325: ZFE3 | C2325: 1000 | D2325: M3 | E2325: 1000 | G2325: 1900 | H2325: MP RESIDUO DE CONCRETO
A2326: 10000677 | C2326: 1000 | D2326: M3 | G2326: 1164 | H2326: Grava Triturada Caliza 20 mm - 3/4"
A2327: 10274190 | B2327: ZFE3 | C2327: 1000 | D2327: M3 | E2327: 1000 | G2327: 1800 | H2327: MP BASE HIDRAULICA ANDESITA 70-30
A2328: 10274601 | B2328: ZFE3 | C2328: 1000 | D2328: M3 | E2328: 1000 | G2328: 1447 | H2328: MP ARENA BASALTO N° 4
...

Sheet TRAOPE
A1: Concat1 | B1: Contrato_Pos | C1: Doc. Compras | D1: Pos | E1: Org.compras | F1: Grp-Compr. | G1: Ship From | H1: Nombre SF | I1: Proveedor | J1: Nombre Prov | K1: Cond. Pago | L1: Descr. Cond Pago | M1: Material | N1: Descripción | O1: Centro | P1: Descripción Centro | Q1: In.perído validez | R1: Fin perído validez | S1: Válido de | T1: Validez a | U1: Precio neto pedido | V1: Moneda | W1: UM Precio Pedido | X1: Importe Condición | Y1: Moneda KONP | Z1: UM Ctd Base | AA1: Destino | AB1: Nombre Destino | AC1: Cuenta de mayor | AD1: Centro de costo | AE1: Cond. Exp. | AF1: Descr. Cond. Exp. | AG1: Peso Vol. | AH1: UMB | AI1: Ind. Oblig. Conf. Ped. | AJ1: Ctrl-Conf. | AK1: IVA | AL1: Modif_Date | AM1: Ruta
A2: 900008171DW3910000861 | B2: 4600068852-10 | C2: 4600068852 | D2: 10 | E2: MXPO | F2: MXL | G2: 900008171 | H2: SF TC-IASSO CHEMUYIL | I2: 5086846 | J2: IASSO CONSTRUCCIONES SA DE CV | K2: N90 | L2: (AP) NAFIN 90 Dias | M2: 10000861 | N2: Base H Triturada Caliza 1 1/2" a Finos | O2: DW39 | P2: MX - CEDIS CHEMUYIL | Q2: 20231202 | R2: 20281231 | S2: 20231202 | T2: 20281231 | U2: 66 | V2: MXN | W2: M3 | X2: 0 | Y2: MXN | Z2: M3 | AC2: 56103590 | AD2: 6644451540 | AE2: 1 | AF2: ENTREGADO | AG2: 1.52 | AH2: M3 | AI2: X | AJ2: 4 | AK2: V4 | AL2: 20231204 | AM2: DW39-900008171-10000861
A3: 900008184DW3910238940 | B3: 4600068819-20 | C3: 4600068819 | D3: 20 | E3: MXPO | F3: MXL | G3: 900008184 | H3: SF TC-REC IASSO CHEMUYIL / CAMIONES | I3: 5086846 | J3: IASSO CONSTRUCCIONES SA DE CV | K3: N90 | L3: (AP) NAFIN 90 Dias | M3: 10238940 | N3: ARENA TRIT. CALIZA MALLA N° 4 | O3: DW39 | P3: MX - CEDIS CHEMUYIL | Q3: 20231128 | R3: 20281231 | S3: 20231128 | T3: 20281231 | U3: 177 | V3: MXN | W3: M3 | X3: 0 | Y3: MXN | Z3: M3 | AC3: 56103638 | AD3: 6644451540 | AE3: 2 | AF3: RECOGIDO | AG3: 1.322 | AH3: M3 | AI3: X | AJ3: 4 | AK3: V4 | AL3: 20231128 | AM3: DW39-900008184-10238940
A4: 900008184DW3910238734 | B4: 4600068819-10 | C4: 4600068819 | D4: 10 | E4: MXPO | F4: MXL | G4: 900008184 | H4: SF TC-REC IASSO CHEMUYIL / CAMIONES | I4: 5086846 | J4: IASSO CONSTRUCCIONES SA DE CV | K4: N90 | L4: (AP) NAFIN 90 Dias | M4: 10238734 | N4: GRAVA TRITURADA CALIZA 20MM 3/4 | O4: DW39 | P4: MX - CEDIS CHEMUYIL | Q4: 20231128 | R4: 20281231 | S4: 20231128 | T4: 20281231 | U4: 156 | V4: MXN | W4: M3 | X4: 0 | Y4: MXN | Z4: M3 | AC4: 56103637 | AD4: 6644451540 | AE4: 2 | AF4: RECOGIDO | AG4: 1.137 | AH4: M3 | AI4: X | AJ4: 4 | AK4: V4 | AL4: 20231128 | AM4: DW39-900008184-10238734
A5: 900008207DW3910239308 | B5: 4600058416-10 | C5: 4600058416 | D5: 10 | E5: MXPO | F5: MXL | G5: 900008207 | H5: SF TC-ELEMAR CHEMUYIL | I5: 5081743 | J5: INFRAESTRUCTURA MEXICANA DEL SUREST | K5: N45 | L5: (AP) NAFIN 45 Dias | M5: 10239308 | N5: GRAVA TRITURADA CALIZA 3/4 - ELEMAR | O5: DW39 | P5: MX - CEDIS CHEMUYIL | Q5: 20230821 | R5: 20281231 | S5: 20230825 | T5: 20281231 | U5: 204 | V5: MXN | W5: M3 | X5: 0 | Y5: MXN | Z5: M3 | AC5: 56103637 | AD5: 6644451540 | AE5: 1 | AF5: ENTREGADO | AG5: 1.183 | AH5: M3 | AI5: X | AJ5: 4 | AK5: V4 | AL5: 20230920 | AM5: DW39-900008207-10239308
A6: 900008207DW3910239309 | B6: 4600058416-20 | C6: 4600058416 | D6: 20 | E6: MXPO | F6: MXL | G6: 900008207 | H6: SF TC-ELEMAR CHEMUYIL | I6: 5081743 | J6: INFRAESTRUCTURA MEXICANA DEL SUREST | K6: N45 | L6: (AP) NAFIN 45 Dias | M6: 10239309 | N6: ARENA TRITURADA CALIZA MALLA 4 - ELEMAR | O6: DW39 | P6: MX - CEDIS CHEMUYIL | Q6: 20230821 | R6: 20281231 | S6: 20230825 | T6: 20281231 | U6: 235 | V6: MXN | W6: M3 | X6: 0 | Y6: MXN | Z6: M3 | AC6: 56103638 | AD6: 6644451540 | AE6: 1 | AF6: ENTREGADO | AG6: 1.218 | AH6: M3 | AI6: X | AJ6: 4 | AK6: V4 | AL6: 20230920 | AM6: DW39-900008207-10239309
A7: 900008171DW3910238940 | B7: 4600057901-40 | C7: 4600057901 | D7: 40 | E7: MXPO | F7: MXL | G7: 900008171 | H7: SF TC-IASSO CHEMUYIL | I7: 5086846 | J7: IASSO CONSTRUCCIONES SA DE CV | K7: N90 | L7: (AP) NAFIN 90 Dias | M7: 10238940 | N7: ARENA TRIT. CALIZA MALLA N° 4 | O7: DW39 | P7: MX - CEDIS CHEMUYIL | Q7: 20230629 | R7: 20281231 | S7: 20230804 | T7: 20281231 | U7: 177 | V7: MXN | W7: M3 | X7: 0 | Y7: MXN | Z7: M3 | AC7: 56103638 | AD7: 6644451540 | AE7: 1 | AF7: ENTREGADO | AG7: 1.322 | AH7: M3 | AI7: X | AJ7: 4 | AK7: V4 | AL7: 20230920 | AM7: DW39-900008171-10238940
A8: 900008171DW3910238734 | B8: 4600057901-30 | C8: 4600057901 | D8: 30 | E8: MXPO | F8: MXL | G8: 900008171 | H8: SF TC-IASSO CHEMUYIL | I8: 5086846 | J8: IASSO CONSTRUCCIONES SA DE CV | K8: N90 | L8: (AP) NAFIN 90 Dias | M8: 10238734 | N8: GRAVA TRITURADA CALIZA 20MM 3/4 | O8: DW39 | P8: MX - CEDIS CHEMUYIL | Q8: 20230629 | R8: 20281231 | S8: 20230804 | T8: 20281231 | U8: 156 | V8: MXN | W8: M3 | X8: 0 | Y8: MXN | Z8: M3 | AC8: 56103637 | AD8: 6644451540 | AE8: 1 | AF8: ENTREGADO | AG8: 1.137 | AH8: M3 | AI8: X | AJ8: 4 | AK8: V4 | AL8: 20230920 | AM8: DW39-900008171-10238734
