Workbook

Sheet Base Cedis DW70
N1: VENTA | Q1: COSTO
A2: CONCAT1 | B2: CONCAT2 | C2: No. SF | D2: Nombre SF | E2: Cedis | F2: Destino | G2: Condicion de Expedicion | H2: Nombre Destino | I2: No. de material | J2: Nombre de material | K2: PV | L2: Inicio de vigencia | M2: Fin de vigencia | N2: Importe MP | O2: Importe Flete | P2: UM Venta | Q2: Importe Costo | R2: UM Costo | S2: Validacion 1 | T2: Validacion 2
A3: =CONCATENATE(C3,E3,F3,I3) | B3: =CONCATENATE(C3,E3,I3) | C3: 900000034 | D3: =IFERROR(VLOOKUP(C3,TRAOPE!$G:$H,2,0),"") | E3: DW70 | F3: D074 | G3: =IFERROR(VLOOKUP(A3,Flete!$A:$E,5,0),"") | H3: =IFERROR(VLOOKUP(F3,TRAOPE!$AA:$AB,2,0),"") | I3: 10000623 | J3: =IFERROR(VLOOKUP(I3,Materiales!$A:$H,8,0),"") | K3: =IFERROR(VLOOKUP(I3,Materiales!$A:$G,7,0),"") | L3: 20250701 | M3: 99991231 | N3: 100 | O3: =IFERROR(VLOOKUP(A3,Flete!$A:$J,10,0),"") | P3: TN | Q3: =IFERROR(IFERROR(VLOOKUP(A3,TRAOPE!$A:$U,21,0),VLOOKUP(B3,TRAOPE!$A:$U,21,0)),"") | R3: =IFERROR(IFERROR(VLOOKUP(A3,TRAOPE!$A:$W,23,0),VLOOKUP(B3,TRAOPE!$A:$W,23,0)),"") | S3: =IF(AND(P3="TN",R3="TN"),N3+N(O3),IF(G3&""="1",N(K3)*N3,(N3+N(O3))*N(K3))) | T3: =IF(Q3="","",Q3-S3)
A4: =CONCATENATE(C4,E4,F4,I4) | B4: =CONCATENATE(C4,E4,I4) | C4: 900000034 | D4: =IFERROR(VLOOKUP(C4,TRAOPE!$G:$H,2,0),"") | E4: DW70 | F4: D074 | G4: =IFERROR(VLOOKUP(A4,Flete!$A:$E,5,0),"") | H4: =IFERROR(VLOOKUP(F4,TRAOPE!$AA:$AB,2,0),"") | I4: 10000811 | J4: =IFERROR(VLOOKUP(I4,Materiales!$A:$H,8,0),"") | K4: =IFERROR(VLOOKUP(I4,Materiales!$A:$G,7,0),"") | L4: 20230501 | M4: 20250131 | N4: 100.01 | O4: =IFERROR(VLOOKUP(A4,Flete!$A:$J,10,0),"") | P4: TN | Q4: =IFERROR(IFERROR(VLOOKUP(A4,TRAOPE!$A:$U,21,0),VLOOKUP(B4,TRAOPE!$A:$U,21,0)),"") | R4: =IFERROR(IFERROR(VLOOKUP(A4,TRAOPE!$A:$W,23,0),VLOOKUP(B4,TRAOPE!$A:$W,23,0)),"") | S4: =IF(AND(P4="TN",R4="TN"),N4+N(O4),IF(G4&""="1",N(K4)*N4,(N4+N(O4))*N(K4))) | T4: =IF(Q4="","",Q4-S4)
A5: =CONCATENATE(C5,E5,F5,I5) | B5: =CONCATENATE(C5,E5,I5) | C5: 900000034 | D5: =IFERROR(VLOOKUP(C5,TRAOPE!$G:$H,2,0),"") | E5: DW70 | F5: D075 | G5: =IFERROR(VLOOKUP(A5,Flete!$A:$E,5,0),"") | H5: =IFERROR(VLOOKUP(F5,TRAOPE!$AA:$AB,2,0),"") | I5: 10000623 | J5: =IFERROR(VLOOKUP(I5,Materiales!$A:$H,8,0),"") | K5: =IFERROR(VLOOKUP(I5,Materiales!$A:$G,7,0),"") | L5: 20250701 | M5: 99991231 | N5: 100 | O5: =IFERROR(VLOOKUP(A5,Flete!$A:$J,10,0),"") | P5: TN | Q5: =IFERROR(IFERROR(VLOOKUP(A5,TRAOPE!$A:$U,21,0),VLOOKUP(B5,TRAOPE!$A:$U,21,0)),"") | R5: =IFERROR(IFERROR(VLOOKUP(A5,TRAOPE!$A:$W,23,0),VLOOKUP(B5,TRAOPE!$A:$W,23,0)),"") | S5: =IF(AND(P5="TN",R5="TN"),N5+N(O5),IF(G5&""="1",N(K5)*N5,(N5+N(O5))*N(K5))) | T5: =IF(Q5="","",Q5-S5)
A6: =CONCATENATE(C6,E6,F6,I6) | B6: =CONCATENATE(C6,E6,I6) | C6: 900000034 | D6: =IFERROR(VLOOKUP(C6,TRAOPE!$G:$H,2,0),"") | E6: DW70 | F6: D075 | G6: =IFERROR(VLOOKUP(A6,Flete!$A:$E,5,0),"") | H6: =IFERROR(VLOOKUP(F6,TRAOPE!$AA:$AB,2,0),"") | I6: 10000811 | J6: =IFERROR(VLOOKUP(I6,Materiales!$A:$H,8,0),"") | K6: =IFERROR(VLOOKUP(I6,Materiales!$A:$G,7,0),"") | L6: 20230501 | M6: 20250131 | N6: 100.01 | O6: =IFERROR(VLOOKUP(A6,Flete!$A:$J,10,0),"") | P6: TN | Q6: =IFERROR(IFERROR(VLOOKUP(A6,TRAOPE!$A:$U,21,0),VLOOKUP(B6,TRAOPE!$A:$U,21,0)),"") | R6: =IFERROR(IFERROR(VLOOKUP(A6,TRAOPE!$A:$W,23,0),VLOOKUP(B6,TRAOPE!$A:$W,23,0)),"") | S6: =IF(AND(P6="TN",R6="TN"),N6+N(O6),IF(G6&""="1",N(K6)*N6,(N6+N(O6))*N(K6))) | T6: =IF(Q6="","",Q6-S6)
A7: =CONCATENATE(C7,E7,F7,I7) | B7: =CONCATENATE(C7,E7,I7) | C7: 900000034 | D7: =IFERROR(VLOOKUP(C7,TRAOPE!$G:$H,2,0),"") | E7: DW70 | F7: D077 | G7: =IFERROR(VLOOKUP(A7,Flete!$A:$E,5,0),"") | H7: =IFERROR(VLOOKUP(F7,TRAOPE!$AA:$AB,2,0),"") | I7: 10000623 | J7: =IFERROR(VLOOKUP(I7,Materiales!$A:$H,8,0),"") | K7: =IFERROR(VLOOKUP(I7,Materiales!$A:$G,7,0),"") | L7: 20260508 | M7: 99991231 | N7: 100 | O7: =IFERROR(VLOOKUP(A7,Flete!$A:$J,10,0),"") | P7: TN | Q7: =IFERROR(IFERROR(VLOOKUP(A7,TRAOPE!$A:$U,21,0),VLOOKUP(B7,TRAOPE!$A:$U,21,0)),"") | R7: =IFERROR(IFERROR(VLOOKUP(A7,TRAOPE!$A:$W,23,0),VLOOKUP(B7,TRAOPE!$A:$W,23,0)),"") | S7: =IF(AND(P7="TN",R7="TN"),N7+N(O7),IF(G7&""="1",N(K7)*N7,(N7+N(O7))*N(K7))) | T7: =IF(Q7="","",Q7-S7)
A8: =CONCATENATE(C8,E8,F8,I8) | B8: =CONCATENATE(C8,E8,I8) | C8: 900000034 | D8: =IFERROR(VLOOKUP(C8,TRAOPE!$G:$H,2,0),"") | E8: DW70 | F8: D077 | G8: =IFERROR(VLOOKUP(A8,Flete!$A:$E,5,0),"") | H8: =IFERROR(VLOOKUP(F8,TRAOPE!$AA:$AB,2,0),"") | I8: 10000811 | J8: =IFERROR(VLOOKUP(I8,Materiales!$A:$H,8,0),"") | K8: =IFERROR(VLOOKUP(I8,Materiales!$A:$G,7,0),"") | L8: 20230501 | M8: 20250131 | N8: 100.01 | O8: =IFERROR(VLOOKUP(A8,Flete!$A:$J,10,0),"") | P8: TN | Q8: =IFERROR(IFERROR(VLOOKUP(A8,TRAOPE!$A:$U,21,0),VLOOKUP(B8,TRAOPE!$A:$U,21,0)),"") | R8: =IFERROR(IFERROR(VLOOKUP(A8,TRAOPE!$A:$W,23,0),VLOOKUP(B8,TRAOPE!$A:$W,23,0)),"") | S8: =IF(AND(P8="TN",R8="TN"),N8+N(O8),IF(G8&""="1",N(K8)*N8,(N8+N(O8))*N(K8))) | T8: =IF(Q8="","",Q8-S8)
A9: =CONCATENATE(C9,E9,F9,I9) | B9: =CONCATENATE(C9,E9,I9) | C9: 900000034 | D9: =IFERROR(VLOOKUP(C9,TRAOPE!$G:$H,2,0),"") | E9: DW70 | F9: D079 | G9: =IFERROR(VLOOKUP(A9,Flete!$A:$E,5,0),"") | H9: =IFERROR(VLOOKUP(F9,TRAOPE!$AA:$AB,2,0),"") | I9: 10000623 | J9: =IFERROR(VLOOKUP(I9,Materiales!$A:$H,8,0),"") | K9: =IFERROR(VLOOKUP(I9,Materiales!$A:$G,7,0),"") | L9: 20250701 | M9: 99991231 | N9: 100 | O9: =IFERROR(VLOOKUP(A9,Flete!$A:$J,10,0),"") | P9: TN | Q9: =IFERROR(IFERROR(VLOOKUP(A9,TRAOPE!$A:$U,21,0),VLOOKUP(B9,TRAOPE!$A:$U,21,0)),"") | R9: =IFERROR(IFERROR(VLOOKUP(A9,TRAOPE!$A:$W,23,0),VLOOKUP(B9,TRAOPE!$A:$W,23,0)),"") | S9: =IF(AND(P9="TN",R9="TN"),N9+N(O9),IF(G9&""="1",N(K9)*N9,(N9+N(O9))*N(K9))) | T9: =IF(Q9="","",Q9-S9)
A10: =CONCATENATE(C10,E10,F10,I10) | B10: =CONCATENATE(C10,E10,I10) | C10: 900000034 | D10: =IFERROR(VLOOKUP(C10,TRAOPE!$G:$H,2,0),"") | E10: DW70 | F10: D079 | G10: =IFERROR(VLOOKUP(A10,Flete!$A:$E,5,0),"") | H10: =IFERROR(VLOOKUP(F10,TRAOPE!$AA:$AB,2,0),"") | I10: 10000811 | J10: =IFERROR(VLOOKUP(I10,Materiales!$A:$H,8,0),"") | K10: =IFERROR(VLOOKUP(I10,Materiales!$A:$G,7,0),"") | L10: 20230501 | M10: 20250131 | N10: 100.01 | O10: =IFERROR(VLOOKUP(A10,Flete!$A:$J,10,0),"") | P10: TN | Q10: =IFERROR(IFERROR(VLOOKUP(A10,TRAOPE!$A:$U,21,0),VLOOKUP(B10,TRAOPE!$A:$U,21,0)),"") | R10: =IFERROR(IFERROR(VLOOKUP(A10,TRAOPE!$A:$W,23,0),VLOOKUP(B10,TRAOPE!$A:$W,23,0)),"") | S10: =IF(AND(P10="TN",R10="TN"),N10+N(O10),IF(G10&""="1",N(K10)*N10,(N10+N(O10))*N(K10))) | T10: =IF(Q10="","",Q10-S10)
A11: =CONCATENATE(C11,E11,F11,I11) | B11: =CONCATENATE(C11,E11,I11) | C11: 900000034 | D11: =IFERROR(VLOOKUP(C11,TRAOPE!$G:$H,2,0),"") | E11: DW70 | F11: D080 | G11: =IFERROR(VLOOKUP(A11,Flete!$A:$E,5,0),"") | H11: =IFERROR(VLOOKUP(F11,TRAOPE!$AA:$AB,2,0),"") | I11: 10000623 | J11: =IFERROR(VLOOKUP(I11,Materiales!$A:$H,8,0),"") | K11: =IFERROR(VLOOKUP(I11,Materiales!$A:$G,7,0),"") | L11: 20250701 | M11: 99991231 | N11: 100 | O11: =IFERROR(VLOOKUP(A11,Flete!$A:$J,10,0),"") | P11: TN | Q11: =IFERROR(IFERROR(VLOOKUP(A11,TRAOPE!$A:$U,21,0),VLOOKUP(B11,TRAOPE!$A:$U,21,0)),"") | R11: =IFERROR(IFERROR(VLOOKUP(A11,TRAOPE!$A:$W,23,0),VLOOKUP(B11,TRAOPE!$A:$W,23,0)),"") | S11: =IF(AND(P11="TN",R11="TN"),N11+N(O11),IF(G11&""="1",N(K11)*N11,(N11+N(O11))*N(K11))) | T11: =IF(Q11="","",Q11-S11)
A12: =CONCATENATE(C12,E12,F12,I12) | B12: =CONCATENATE(C12,E12,I12) | C12: 900000034 | D12: =IFERROR(VLOOKUP(C12,TRAOPE!$G:$H,2,0),"") | E12: DW70 | F12: D080 | G12: =IFERROR(VLOOKUP(A12,Flete!$A:$E,5,0),"") | H12: =IFERROR(VLOOKUP(F12,TRAOPE!$AA:$AB,2,0),"") | I12: 10000811 | J12: =IFERROR(VLOOKUP(I12,Materiales!$A:$H,8,0),"") | K12: =IFERROR(VLOOKUP(I12,Materiales!$A:$G,7,0),"") | L12: 20230501 | M12: 20250131 | N12: 100.01 | O12: =IFERROR(VLOOKUP(A12,Flete!$A:$J,10,0),"") | P12: TN | Q12: =IFERROR(IFERROR(VLOOKUP(A12,TRAOPE!$A:$U,21,0),VLOOKUP(B12,TRAOPE!$A:$U,21,0)),"") | R12: =IFERROR(IFERROR(VLOOKUP(A12,TRAOPE!$A:$W,23,0),VLOOKUP(B12,TRAOPE!$A:$W,23,0)),"") | S12: =IF(AND(P12="TN",R12="TN"),N12+N(O12),IF(G12&""="1",N(K12)*N12,(N12+N(O12))*N(K12))) | T12: =IF(Q12="","",Q12-S12)
A13: =CONCATENATE(C13,E13,F13,I13) | B13: =CONCATENATE(C13,E13,I13) | C13: 900000034 | D13: =IFERROR(VLOOKUP(C13,TRAOPE!$G:$H,2,0),"") | E13: DW70 | F13: D081 | G13: =IFERROR(VLOOKUP(A13,Flete!$A:$E,5,0),"") | H13: =IFERROR(VLOOKUP(F13,TRAOPE!$AA:$AB,2,0),"") | I13: 10000623 | J13: =IFERROR(VLOOKUP(I13,Materiales!$A:$H,8,0),"") | K13: =IFERROR(VLOOKUP(I13,Materiales!$A:$G,7,0),"") | L13: 20250701 | M13: 99991231 | N13: 100 | O13: =IFERROR(VLOOKUP(A13,Flete!$A:$J,10,0),"") | P13: TN | Q13: =IFERROR(IFERROR(VLOOKUP(A13,TRAOPE!$A:$U,21,0),VLOOKUP(B13,TRAOPE!$A:$U,21,0)),"") | R13: =IFERROR(IFERROR(VLOOKUP(A13,TRAOPE!$A:$W,23,0),VLOOKUP(B13,TRAOPE!$A:$W,23,0)),"") | S13: =IF(AND(P13="TN",R13="TN"),N13+N(O13),IF(G13&""="1",N(K13)*N13,(N13+N(O13))*N(K13))) | T13: =IF(Q13="","",Q13-S13)
A14: =CONCATENATE(C14,E14,F14,I14) | B14: =CONCATENATE(C14,E14,I14) | C14: 900000034 | D14: =IFERROR(VLOOKUP(C14,TRAOPE!$G:$H,2,0),"") | E14: DW70 | F14: D081 | G14: =IFERROR(VLOOKUP(A14,Flete!$A:$E,5,0),"") | H14: =IFERROR(VLOOKUP(F14,TRAOPE!$AA:$AB,2,0),"") | I14: 10000811 | J14: =IFERROR(VLOOKUP(I14,Materiales!$A:$H,8,0),"") | K14: =IFERROR(VLOOKUP(I14,Materiales!$A:$G,7,0),"") | L14: 20230501 | M14: 20250131 | N14: 100.01 | O14: =IFERROR(VLOOKUP(A14,Flete!$A:$J,10,0),"") | P14: TN | Q14: =IFERROR(IFERROR(VLOOKUP(A14,TRAOPE!$A:$U,21,0),VLOOKUP(B14,TRAOPE!$A:$U,21,0)),"") | R14: =IFERROR(IFERROR(VLOOKUP(A14,TRAOPE!$A:$W,23,0),VLOOKUP(B14,TRAOPE!$A:$W,23,0)),"") | S14: =IF(AND(P14="TN",R14="TN"),N14+N(O14),IF(G14&""="1",N(K14)*N14,(N14+N(O14))*N(K14))) | T14: =IF(Q14="","",Q14-S14)
... A1403: =CONCATENATE(C1403,E1403,F1403,I1403) | B1403: =CONCATENATE(C1403,E1403,I1403) | C1403: 900009585 | D1403: =IFERROR(VLOOKUP(C1403,TRAOPE!$G:$H,2,0),"") | E1403: DW70 | F1403: D681 | G1403: =IFERROR(VLOOKUP(A1403,Flete!$A:$E,5,0),"") | H1403: =IFERROR(VLOOKUP(F1403,TRAOPE!$AA:$AB,2,0),"") | I1403: 10000811 | J1403: =IFERROR(VLOOKUP(I1403,Materiales!$A:$H,8,0),"") | K1403: =IFERROR(VLOOKUP(I1403,Materiales!$A:$G,7,0),"") | L1403: 20260814 | M1403: 99991231 | N1403: 155.49 | O1403: =IFERROR(VLOOKUP(A1403,Flete!$A:$J,10,0),"") | P1403: TN | Q1403: =IFERROR(IFERROR(VLOOKUP(A1403,TRAOPE!$A:$U,21,0),VLOOKUP(B1403,TRAOPE!$A:$U,21,0)),"") | R1403: =IFERROR(IFERROR(VLOOKUP(A1403,TRAOPE!$A:$W,23,0),VLOOKUP(B1403,TRAOPE!$A:$W,23,0)),"") | S1403: =IF(AND(P1403="TN",R1403="TN"),N1403+N(O1403),IF(G1403&""="1",N(K1403)*N1403,(N1403+N(O1403))*N(K1403))) | T1403: =IF(Q1403="","",Q1403-S1403)

Sheet MP
A1: No. SF | B1: Cedis | C1: Destino | D1: No. Material | E1: Nombre Material | F1: Importe MP | G1: Moneda | H1: Cantidad | I1: UM | J1: C | K1: Inicio Vigencia | L1: Fin Vigencia
A2: 900000034 | B2: DW70 | C2: D074 | D2: 10000623 | F2: 100 | I2: TN | K2: 20250701 | L2: 99991231
A3: 900000034 | B3: DW70 | C3: D074 | D3: 10000811 | F3: 100.01 | I3: TN | K3: 20230501 | L3: 20250131
A4: 900000034 | B4: DW70 | C4: D075 | D4: 10000623 | F4: 100 | I4: TN | K4: 20250701 | L4: 99991231
A5: 900000034 | B5: DW70 | C5: D075 | D5: 10000811 | F5: 100.01 | I5: TN | K5: 20230501 | L5: 20250131
A6: 900000034 | B6: DW70 | C6: D077 | D6: 10000623 | F6: 100 | I6: TN | K6: 20260508 | L6: 99991231
A7: 900000034 | B7: DW70 | C7: D077 | D7: 10000811 | F7: 100.01 | I7: TN | K7: 20230501 | L7: 20250131
A8: 900000034 | B8: DW70 | C8: D079 | D8: 10000623 | F8: 100 | I8: TN | K8: 20250701 | L8: 99991231
A9: 900000034 | B9: DW70 | C9: D079 | D9: 10000811 | F9: 100.01 | I9: TN | K9: 20230501 | L9: 20250131
A10: 900000034 | B10: DW70 | C10: D080 | D10: 10000623 | F10: 100 | I10: TN | K10: 20250701 | L10: 99991231
A11: 900000034 | B11: DW70 | C11: D080 | D11: 10000811 | F11: 100.01 | I11: TN | K11: 20230501 | L11: 20250131
A12: 900000034 | B12: DW70 | C12: D081 | D12: 10000623 | F12: 100 | I12: TN | K12: 20250701 | L12: 99991231
A13: 900000034 | B13: DW70 | C13: D081 | D13: 10000811 | F13: 100.01 | I13: TN | K13: 20230501 | L13: 20250131
... A1402: 900009585 | B1402: DW70 | C1402: D681 | D1402: 10000811 | F1402: 155.49 | I1402: TN | K1402: 20260814 | L1402: 99991231

Sheet Flete
A1: Concat1 | B1: No. SF | C1: Cedis | D1: Destino | E1: Cond. Exp. | F1: Material | H1: Nombre Material | J1: Importe Flete | K1: Moneda | L1: Cantidad | M1: UM | N1: C | P1: Inicio Vigencia | Q1: Fin Vigencia
A2: 900000034DW70D07410000623 | B2: 900000034 | C2: DW70 | D2: D074 | E2: 1 | F2: 10000623 | J2: 263.76 | M2: TN | P2: 20260430 | Q2: 99991231
A3: 900000034DW70D07410000811 | B3: 900000034 | C3: DW70 | D3: D074 | E3: 1 | F3: 10000811 | J3: 189.28 | M3: TN | P3: 20220331 | Q3: 20250131
A4: 900000034DW70D07510000623 | B4: 900000034 | C4: DW70 | D4: D075 | E4: 1 | F4: 10000623 | J4: 218.72 | M4: TN | P4: 20260430 | Q4: 99991231
A5: 900000034DW70D07510000811 | B5: 900000034 | C5: DW70 | D5: D075 | E5: 1 | F5: 10000811 | J5: 156.97 | M5: TN | P5: 20220331 | Q5: 20250131
A6: 900000034DW70D07710000623 | B6: 900000034 | C6: DW70 | D6: D077 | E6: 1 | F6: 10000623 | J6: 223.62 | M6: TN | P6: 20260508 | Q6: 99991231
A7: 900000034DW70D07710000811 | B7: 900000034 | C7: DW70 | D7: D077 | E7: 1 | F7: 10000811 | J7: 240.06 | M7: TN | P7: 20220331 | Q7: 20250131
A8: 900000034DW70D07910000623 | B8: 900000034 | C8: DW70 | D8: D079 | E8: 1 | F8: 10000623 | J8: 331.31 | M8: TN | P8: 20260430 | Q8: 99991231
A9: 900000034DW70D07910000811 | B9: 900000034 | C9: DW70 | D9: D079 | E9: 1 | F9: 10000811 | J9: 237.75 | M9: TN | P9: 20220331 | Q9: 20250131
A10: 900000034DW70D08010000623 | B10: 900000034 | C10: DW70 | D10: D080 | E10: 1 | F10: 10000623 | J10: 218.72 | M10: TN | P10: 20260430 | Q10: 99991231
A11: 900000034DW70D08010000811 | B11: 900000034 | C11: DW70 | D11: D080 | E11: 1 | F11: 10000811 | J11: 156.97 | M11: TN | P11: 20220331 | Q11: 20250131
A12: 900000034DW70D08110000623 | B12: 900000034 | C12: DW70 | D12: D081 | E12: 1 | F12: 10000623 | J12: 202.65 | M12: TN | P12: 20260430 | Q12: 99991231
A13: 900000034DW70D08110000811 | B13: 900000034 | C13: DW70 | D13: D081 | E13: 1 | F13: 10000811 | J13: 145.43 | M13: TN | P13: 20220331 | Q13: 20250131
... A1318: 900009480DW70D68110275115 | B1318: 900009480 | C1318: DW70 | D1318: D681 | E1318: 1 | F1318: 10275115 | J1318: 262.98 | M1318: TN | P1318: 20260430 | Q1318: 99991231

Sheet Materiales
A1: Material | B1: TpMt | C1: Denom | D1: UMA | E1: Contador | F1: UMB | G1: PV | H1: Nombre Material
A2: 10000001 | B2: ZFER | C2: 1000 | D2: M3 | E2: 1000 | F2: TN | G2: 1262 | H2: GRAVA ANDESITA 10 MM (3/8")
A3: 10000003 | B3: ZFER | C3: 1000 | D3: M3 | E3: 1000 | F3: TN | G3: 1443 | H3: GRAVA CALIZA 10 MM (3/8")
A4: 10000006 | B4: ZFER | C4: 1000 | D4: M3 | E4: 1000 | F4: TN | G4: 1490 | H4: GRAVA RIO 10 MM (3/8")
A5: 10000007 | B5: ZFER | C5: 1000 | D5: M3 | E5: 1000 | F5: TN | G5: 1488 | H5: GRAVA BASALTO 13 MM (1/2")
A6: 10000008 | B6: ZFER | C6: 1000 | D6: M3 | E6: 1000 | F6: TN | G6: 1358 | H6: GRAVA CALIZA 13 MM (1/2")
A7: 10000011 | B7: ZFER | C7: 1000 | D7: M3 | E7: 1000 | F7: TN | G7: 1323 | H7: GRAVA ANDESITA 20 MM (3/4")
A8: 10000013 | B8: ZFER | C8: 1000 | D8: M3 | E8: 1000 | F8: TN | G8: 1514 | H8: GRAVA BASALTO 20 MM (3/4")
A9: 10000014 | B9: ZFER | C9: 1000 | D9: M3 | E9: 1000 | F9: TN | G9: 1400 | H9: GRAVA CALIZA 20 MM (3/4")
A10: 10000015 | B10: ZFER | C10: 1000 | D10: M3 | E10: 1000 | F10: TN | G10: 1410 | H10: GRAVA GRANITO 20 MM (3/4")
A11: 10000017 | B11: ZFER | C11: 1000 | D11: M3 | E11: 1000 | F11: TN | G11: 1475 | H11: GRAVA RIOLITA 20 MM (3/4")
A12: 10000019 | B12: ZFER | C12: 1000 | D12: M3 | E12: 1000 | F12: TN | G12: 1515 | H12: GRAVA RIO 20 MM (3/4")
A13: 10000020 | B13: ZFER | C13: 1000 | D13: M3 | E13: 1 | F13: TN | G13: 1 | H13: GRAVA MAQUILA 40MM (1 1/2")
... A2291: 10268770 | B2291: ZFE3 | C2291: 1000 | D2291: M3 | E2291: 1000 | F2291: TN | G2291: 1240 | H2291: MP GRAVA TRIT CALIZA 40MM 1 1/2" - ESP
A2292: 10268901 | B2292: ZFE3 | C2292: 1000 | D2292: M3 | E2292: 1000 | G2292: 1560 | H2292: MP GRAVA ANDESITA GRIS 3/4" - CAPADA
A2293: 10267983 | C2293: 1000 | G2293: 1800 | H2293: ESCORIA ALTO HORNO 3/4
A2294: 10268996 | C2294: 1000 | G2294: 1329 | H2294: GRAVA TRITURADA CALIZA 40 MM - 11/2"
A2295: 10269072 | C2295: 1000 | G2295: 1700 | H2295: BASE HIDRÁULICA SCREEN
A2296: 10269225 | B2296: ZFE3 | C2296: 1000 | D2296: M3 | E2296: 1000 | G2296: 1289 | H2296: MP ARENA CALIZA LAVADA MALLA 4 - DELTA I
A2297: 10269245 | B2297: ZFE3 | C2297: 1000 | D2297: M3 | E2297: 1000 | G2297: 1410 | H2297: MP GRAVA TRITURADA CALIZA 3/8 - 10MM
A2298: 10269246 | B2298: ZFE3 | C2298: 1000 | D2298: M3 | E2298: 1000 | G2298: 1400 | H2298: MP GRAVA TRITURADA CALIZA 1 1/2 - 40MM
A2299: 10269247 | B2299: ZFE3 | C2299: 1000 | D2299: M3 | E2299: 1000 | G2299: 1560 | H2299: MP ARENA TRIT CALIZA M-4
A2300: 10270431 | B2300: ZFE3 | C2300: 1000 | D2300: M3 | E2300: 1000 | G2300: 1423 | H2300: MP GRAVA RIOLITA 13 MM - 1/2"
A2301: 10270898 | B2301: ZFE3 | C2301: 1000 | D2301: M3 | E2301: 1000 | G2301: 1551 | H2301: MP BASE H. TRIT. BASALTO 1 1/2" A FINOS
A2302: 10270911 | B2302: ZFE3 | C2302: 1000 | D2302: M3 | E2302: 1000 | G2302: 1360 | H2302: MP GRAVA TRIT. BASALTO 40 MM - 1 1/2"
A2303: 10270912 | B2303: ZFE3 | C2303: 1000 | D2303: M3 | E2303: 1000 | G2303: 1589 | H2303: MP ARENA TRIT. BASALTO MALLA 4
A2304: 10270913 | B2304: ZFE3 | C2304: 1000 | D2304: M3 | E2304: 1000 | G2304: 1395 | H2304: MP GRAVA TRIT. BASALTO 20 MM - 3/4
A2305: 10270914 | B2305: ZFE3 | C2305: 1000 | D2305: M3 | E2305: 1000 | G2305: 1623 | H2305: MP ARENA ANDESITA BC
A2306: 10270824 | B2306: M3 | C2306: 1000 | D2306: M3 | E2306: 10007640 | G2306: 1325 | H2306: MP ARENA TRITURADA CALIZA MALLA 5
A2307: 10270825 | B2307: M3 | C2307: 1000 | D2307: M3 | E2307: 10000003 | G2307: 1242 | H2307: MP GRAVA TRITURADA CALIZA 10MM (3/8”)
... A2319: 10272527 | B2319: ZFE3 | C2319: 1000 | D2319: M3 | E2319: 1000 | G2319: 1620 | H2319: CNC - NO CLASIFICADO
A2320: 10000332 | C2320: 1000 | D2320: M3 | E2320: 1000 | G2320: 800 | H2320: Grava Triturada Pomez - Jal 20 mm - 3/4"
A2321: 10273001 | B2321: ZFE3 | C2321: 1000 | D2321: M3 | E2321: 1000 | G2321: 1688 | H2321: MP ARENA TRIT. BASALTO MALLA 4
A2322: 10273002 | B2322: ZFE3 | C2322: 1000 | D2322: M3 | E2322: 1000 | G2322: 1466 | H2322: MP GRAVA TRIT. BASALTO 20 MM - 3/4"
A2323: 10273351 | B2323: ZFE3 | C2323: 1000 | D2323: M3 | E2323: 1000 | G2323: 1612 | H2323: MP ARENA TRIT. CALIZA MALLA 4
A2324: 10273352 | B2324: ZFE3 | C2324: 1000 | D2324: M3 | E2324: 1000 | G2324: 1492 | H2324: MP GRAVA TRIT. CALIZA 20 MM - 3/4"
A2325: 10271724 | B2325: ZFE3 | C2325: 1000 | D2325: M3 | E2325: 1000 | G2325: 1900 | H2325: MP RESIDUO DE CONCRETO
A2326: 10000677 | C2326: 1000 | D2326: M3 | G2326: 1164 | H2326: Grava Triturada Caliza 20 mm - 3/4"
A2327: 10274190 | B2327: ZFE3 | C2327: 1000 | D2327: M3 | E2327: 1000 | G2327: 1800 | H2327: MP BASE HIDRAULICA ANDESITA 70-30
A2328: 10274601 | B2328: ZFE3 | C2328: 1000 | D2328: M3 | E2328: 1000 | G2328: 1447 | H2328: MP ARENA BASALTO N° 4
...

Sheet TRAOPE
A1: Concat1 | B1: Contrato_Pos | C1: Doc. Compras | D1: Pos | E1: Org.compras | F1: Grp-Compr. | G1: Ship From | H1: Nombre SF | I1: Proveedor | J1: Nombre Prov | K1: Cond. Pago | L1: Descr. Cond Pago | M1: Material | N1: Descripción | O1: Centro | P1: Descripción Centro | Q1: In.perído validez | R1: Fin perído validez | S1: Válido de | T1: Validez a | U1: Precio neto pedido | V1: Moneda | W1: UM Precio Pedido | X1: Importe Condición | Y1: Moneda KONP | Z1: UM Ctd Base | AA1: Destino | AB1: Nombre Destino | AC1: Cuenta de mayor | AD1: Centro de costo | AE1: Cond. Exp. | AF1: Descr. Cond. Exp. | AG1: Peso Vol. | AH1: UMB | AI1: Ind. Oblig. Conf. Ped. | AJ1: Ctrl-Conf. | AK1: IVA | AL1: Modif_Date | AM1: Ruta
A2: 900006172DW70D07410000811 | B2: 4600072309-160 | C2: 4600072309 | D2: 160 | E2: MXPO | F2: MXL | G2: 900006172 | H2: SF TC-ED ESTRATEGIAS SANTA CALIZA | I2: 5049458 | J2: ESTRATEGIAS AVANZADAS PARA OBTEN | K2: Z03 | L2: (AP) 15 Dias | M2: 10000811 | N2: Grava Triturada Caliza 20 mm - 3/4" | O2: DW70 | P2: MX-CED. CENTRO | Q2: 20260616 | R2: 20301231 | S2: 20260805 | T2: 20301231 | U2: 569 | V2: MXN | W2: M3 | X2: 413 | Y2: MXN | Z2: M3 | AA2: D074 | AB2: PD0063 CENTRAL | AC2: 56103637 | AD2: 6644261540 | AE2: 4 | AF2: ENTREGA DIRECTA | AG2: 1.447 | AH2: M3 | AI2: X | AJ2: 4 | AK2: V4 | AL2: 20260811 | AM2: DW70-900006172-D074-10000811-4
A3: 900006172DW70D09810000811 | B3: 4600072309-250 | C3: 4600072309 | D3: 250 | E3: MXPO | F3: MXL | G3: 900006172 | H3: SF TC-ED ESTRATEGIAS SANTA CALIZA | I3: 5049458 | J3: ESTRATEGIAS AVANZADAS PARA OBTEN | K3: Z03 | L3: (AP) 15 Dias | M3: 10000811 | N3: Grava Triturada Caliza 20 mm - 3/4" | O3: DW70 | P3: MX-CED. CENTRO | Q3: 20260616 | R3: 20301231 | S3: 20260805 | T3: 20301231 | U3: 405 | V3: MXN | W3: M3 | X3: 249 | Y3: MXN | Z3: M3 | AA3: D098 | AB3: PD0315 CUAUTITLAN II | AC3: 56103637 | AD3: 6644261540 | AE3: 4 | AF3: ENTREGA DIRECTA | AG3: 1.447 | AH3: M3 | AI3: X | AJ3: 4 | AK3: V4 | AL3: 20260811 | AM3: DW70-900006172-D098-10000811-4
A4: 900006172DW70D09310000811 | B4: 4600072309-280 | C4: 4600072309 | D4: 280 | E4: MXPO | F4: MXL | G4: 900006172 | H4: SF TC-ED ESTRATEGIAS SANTA CALIZA | I4: 5049458 | J4: ESTRATEGIAS AVANZADAS PARA OBTEN | K4: Z03 | L4: (AP) 15 Dias | M4: 10000811 | N4: Grava Triturada Caliza 20 mm - 3/4" | O4: DW70 | P4: MX-CED. CENTRO | Q4: 20260616 | R4: 20301231 | S4: 20260805 | T4: 20301231 | U4: 347 | V4: MXN | W4: M3 | X4: 191 | Y4: MXN | Z4: M3 | AA4: D093 | AB4: PD0556 ZUMPANGO | AC4: 56103637 | AD4: 6644261540 | AE4: 4 | AF4: ENTREGA DIRECTA | AG4: 1.447 | AH4: M3 | AI4: X | AJ4: 4 | AK4: V4 | AL4: 20260811 | AM4: DW70-900006172-D093-10000811-4
A5: 900003438DW70D68110000811 | B5: 4600050497-950 | C5: 4600050497 | D5: 950 | E5: MXPO | F5: MXL | G5: 900003438 | H5: TC-ED-ESTRATEGIAS AVANZADAS | I5: 5049458 | J5: ESTRATEGIAS AVANZADAS PARA OBTEN | K5: Z03 | L5: (AP) 15 Dias | M5: 10000811 | N5: Grava Triturada Caliza 20 mm - 3/4" | O5: DW70 | P5: MX-CED. CENTRO | Q5: 20210712 | R5: 20281231 | S5: 20260819 | T5: 20301231 | U5: 522 | V5: MXN | W5: M3 | X5: 322 | Y5: MXN | Z5: M3 | AA5: D681 | AB5: PD0639 TULTEPEC | AC5: 56103637 | AD5: 6644261540 | AE5: 4 | AF5: ENTREGA DIRECTA | AG5: 1.447 | AH5: M3 | AI5: X | AJ5: 4 | AK5: V4 | AL5: 20260821 | AM5: DW70-900003438-D681-10000811-4
A6: 900009585DW70D68110000811 | B6: 4600072549-30 | C6: 4600072549 | D6: 30 | E6: MXPO | F6: MXL | G6: 900009585 | H6: SF TC-ED ESTRATEGIAS MAQ Y CANTERAS | I6: 5049458 | J6: ESTRATEGIAS AVANZADAS PARA OBTEN | K6: Z03 | L6: (AP) 15 Dias | M6: 10000811 | N6: Grava Triturada Caliza 20 mm - 3/4" | O6: DW70 | P6: MX-CED. CENTRO | Q6: 20260814 | R6: 20301231 | S6: 20260814 | T6: 20301231 | U6: 492.4 | V6: MXN | W6: M3 | X6: 267.4 | Y6: MXN | Z6: M3 | AA6: D681 | AB6: PD0639 TULTEPEC | AC6: 56103637 | AD6: 6644261540 | AE6: 4 | AF6: ENTREGA DIRECTA | AG6: 1.447 | AH6: M3 | AI6: X | AJ6: 4 | AK6: V4 | AL6: 20260821 | AM6: DW70-900009585-D681-10000811-4
A7: 900006172DW70D07510000811 | B7: 4600072309-170 | C7: 4600072309 | D7: 170 | E7: MXPO | F7: MXL | G7: 900006172 | H7: SF TC-ED ESTRATEGIAS SANTA CALIZA | I7: 5049458 | J7: ESTRATEGIAS AVANZADAS PARA OBTEN | K7: Z03 | L7: (AP) 15 Dias | M7: 10000811 | N7: Grava Triturada Caliza 20 mm - 3/4" | O7: DW70 | P7: MX-CED. CENTRO | Q7: 20260616 | R7: 20301231 | S7: 20260805 | T7: 20301231 | U7: 507 | V7: MXN | W7: M3 | X7: 351 | Y7: MXN | Z7: M3 | AA7: D075 | AB7: PD0065 CEYLAN | AC7: 56103637 | AD7: 6644261540 | AE7: 4 | AF7: ENTREGA DIRECTA | AG7: 1.447 | AH7: M3 | AI7: X | AJ7: 4 | AK7: V4 | AL7: 20260811 | AM7: DW70-900006172-D075-10000811-4
A8: 900006172DW70D13610000811 | B8: 4600072309-240 | C8: 4600072309 | D8: 240 | E8: MXPO | F8: MXL | G8: 900006172 | H8: SF TC-ED ESTRATEGIAS SANTA CALIZA | I8: 5049458 | J8: ESTRATEGIAS AVANZADAS PARA OBTEN | K8: Z03 | L8: (AP) 15 Dias | M8: 10000811 | N8: Grava Triturada Caliza 20 mm - 3/4" | O8: DW70 | P8: MX-CED. CENTRO | Q8: 20260616 | R8: 20301231 | S8: 20260805 | T8: 20301231 | U8: 627 | V8: MXN | W8: M3 | X8: 471 | Y8: MXN | Z8: M3 | AA8: D136 | AB8: PD0237 LA ESTRELLA | AC8: 56103637 | AD8: 6644261540 | AE8: 4 | AF8: ENTREGA DIRECTA | AG8: 1.447 | AH8: M3 | AI8: X | AJ8: 4 | AK8: V4 | AL8: 20260811 | AM8: DW70-900006172-D136-10000811-4
A9: 900009292DW7010058345 | B9: 4600071553-60 | C9: 4600071553 | D9: 60 | E9: MXPO | F9: MXL | G9: 900009292 | H9: SF TC-GRAVICOR GIL | I9: 5096226 | J9: GIL HERNANDEZ RACIEL | K9: N90 | L9: (AP) NAFIN 90 Dias | M9: 10058345 | N9: Arena Triturada Caliza Malla 4 | O9: DW70 | P9: MX-CED. CENTRO | Q9: 20250813 | R9: 20301231 | S9: 20260814 | T9: 20301231 | U9: 150 | V9: MXN | W9: M3 | X9: 0 | Y9: MXN | Z9: M3 | AC9: 56103638 | AD9: 6644261540 | AE9: 1 | AF9: ENTREGADO | AG9: 1.575 | AH9: M3 | AI9: X | AJ9: 4 | AK9: V4 | AL9: 20260821 | AM9: DW70-900009292-10058345
A10: 900006172DW70D08510000811 | B10: 4600072309-230 | C10: 4600072309 | D10: 230 | E10: MXPO | F10: MXL | G10: 900006172 | H10: SF TC-ED ESTRATEGIAS SANTA CALIZA | I10: 5049458 | J10: ESTRATEGIAS AVANZADAS PARA OBTEN | K10: Z03 | L10: (AP) 15 Dias | M10: 10000811 | N10: Grava Triturada Caliza 20 mm - 3/4" | O10: DW70 | P10: MX-CED. CENTRO | Q10: 20260616 | R10: 20301231 | S10: 20260805 | T10: 20301231 | U10: 636 | V10: MXN | W10: M3 | X10: 480 | Y10: MXN | Z10: M3 | AA10: D085 | AB10: PD0189 ROJO GOMEZ | AC10: 56103637 | AD10: 6644261540 | AE10: 4 | AF10: ENTREGA DIRECTA | AG10: 1.447 | AH10: M3 | AI10: X | AJ10: 4 | AK10: V4 | AL10: 20260811 | AM10: DW70-900006172-D085-10000811-4
A11: 900006172DW70D07710000811 | B11: 4600072309-180 | C11: 4600072309 | D11: 180 | E11: MXPO | F11: MXL | G11: 900006172 | H11: SF TC-ED ESTRATEGIAS SANTA CALIZA | I11: 5049458 | J11: ESTRATEGIAS AVANZADAS PARA OBTEN | K11: Z03 | L11: (AP) 15 Dias | M11: 10000811 | N11: Grava Triturada Caliza 20 mm - 3/4" | O11: DW70 | P11: MX-CED. CENTRO | Q11: 20260616 | R11: 20301231 | S11: 20260805 | T11: 20301231 | U11: 667 | V11: MXN | W11: M3 | X11: 511 | Y11: MXN | Z11: M3 | AA11: D077 | AB11: PD0067 LOS REYES | AC11: 56103637 | AD11: 6644261540 | AE11: 4 | AF11: ENTREGA DIRECTA | AG11: 1.447 | AH11: M3 | AI11: X | AJ11: 4 | AK11: V4 | AL11: 20260811 | AM11: DW70-900006172-D077-10000811-4
A12: 900003438DW70D08610000811 | B12: 4600050497-860 | C12: 4600050497 | D12: 860 | E12: MXPO | F12: MXL | G12: 900003438 | H12: TC-ED-ESTRATEGIAS AVANZADAS | I12: 5049458 | J12: ESTRATEGIAS AVANZADAS PARA OBTEN | K12: Z03 | L12: (AP) 15 Dias | M12: 10000811 | N12: Grava Triturada Caliza 20 mm - 3/4" | O12: DW70 | P12: MX-CED. CENTRO | Q12: 20210712 | R12: 20281231 | S12: 20260819 | T12: 20301231 | U12: 576.5 | V12: MXN | W12: M3 | X12: 376.5 | Y12: MXN | Z12: M3 | AA12: D086 | AB12: PD0190 XALOSTC | AC12: 56103637 | AD12: 6644261540 | AE12: 4 | AF12: ENTREGA DIRECTA | AG12: 1.447 | AH12: M3 | AI12: X | AJ12: 4 | AK12: V4 | AL12: 20260821 | AM12: DW70-900003438-D086-10000811-4
A13: 900006544DW7010185477 | B13: 4600050562-20 | C13: 4600050562 | D13: 20 | E13: MXPO | F13: MXL | G13: 900006544 | H13: TC-MARTINEZ VILLEGAS | I13: 5078107 | J13: MARTINEZ VILLEGAS SA DE CV | K13: Z04 | L13: (AP) 30 Dias | M13: 10185477 | N13: GRAVA TRITURADA ANDESITA 20 MM - 3/4" | O13: DW70 | P13: MX-CED. CENTRO | Q13: 20210712 | R13: 20261231 | S13: 20260805 | T13: 20301231 | U13: 160 | V13: MXN | W13: M3 | X13: 0 | Y13: MXN | Z13: M3 | AC13: 56103637 | AD13: 6644261540 | AE13: 1 | AF13: ENTREGADO | AG13: 1.39 | AH13: M3 | AI13: X | AJ13: 4 | AK13: V4 | AL13: 20260813 | AM13: DW70-900006544-10185477
A14: 900006172DW70D14510000811 | B14: 4600072309-270 | C14: 4600072309 | D14: 270 | E14: MXPO | F14: MXL | G14: 900006172 | H14: SF TC-ED ESTRATEGIAS SANTA CALIZA | I14: 5049458 | J14: ESTRATEGIAS AVANZADAS PARA OBTEN | K14: Z03 | L14: (AP) 15 Dias | M14: 10000811 | N14: Grava Triturada Caliza 20 mm - 3/4" | O14: DW70 | P14: MX-CED. CENTRO | Q14: 20260616 | R14: 20301231 | S14: 20260805 | T14: 20301231 | U14: 454 | V14: MXN | W14: M3 | X14: 298 | Y14: MXN | Z14: M3 | AA14: D145 | AB14: PD0458 ECATEPEC II | AC14: 56103637 | AD14: 6644261540 | AE14: 4 | AF14: ENTREGA DIRECTA | AG14: 1.447 | AH14: M3 | AI14: X | AJ14: 4 | AK14: V4 | AL14: 20260811 | AM14: DW70-900006172-D145-10000811-4
A15: 900009585DW70D14510000811 | B15: 4600072549-20 | C15: 4600072549 | D15: 20 | E15: MXPO | F15: MXL | G15: 900009585 | H15: SF TC-ED ESTRATEGIAS MAQ Y CANTERAS | I15: 5049458 | J15: ESTRATEGIAS AVANZADAS PARA OBTEN | K15: Z03 | L15: (AP) 15 Dias | M15: 10000811 | N15: Grava Triturada Caliza 20 mm - 3/4" | O15: DW70 | P15: MX-CED. CENTRO | Q15: 20260814 | R15: 20301231 | S15: 20260814 | T15: 20301231 | U15: 501.2 | V15: MXN | W15: M3 | X15: 276.2 | Y15: MXN | Z15: M3 | AA15: D145 | AB15: PD0458 ECATEPEC II | AC15: 56103637 | AD15: 6644261540 | AE15: 4 | AF15: ENTREGA DIRECTA | AG15: 1.447 | AH15: M3 | AI15: X | AJ15: 4 | AK15: V4 | AL15: 20260821 | AM15: DW70-900009585-D145-10000811-4
A16: 900003438DW70D09810000811 | B16: 4600050497-880 | C16: 4600050497 | D16: 880 | E16: MXPO | F16: MXL | G16: 900003438 | H16: TC-ED-ESTRATEGIAS AVANZADAS | I16: 5049458 | J16: ESTRATEGIAS AVANZADAS PARA OBTEN | K16: Z03 | L16: (AP) 15 Dias | M16: 10000811 | N16: Grava Triturada Caliza 20 mm - 3/4" | O16: DW70 | P16: MX-CED. CENTRO | Q16: 20210712 | R16: 20281231 | S16: 20260819 | T16: 20301231 | U16: 427 | V16: MXN | W16: M3 | X16: 227 | Y16: MXN | Z16: M3 | AA16: D098 | AB16: PD0315 CUAUTITLAN II | AC16: 56103637 | AD16: 6644261540 | AE16: 4 | AF16: ENTREGA DIRECTA | AG16: 1.447 | AH16: M3 | AI16: X | AJ16: 4 | AK16: V4 | AL16: 20260821 | AM16: DW70-900003438-D098-10000811-4
A17: 900006172DW70D68110000811 | B17: 4600072309-290 | C17: 4600072309 | D17: 290 | E17: MXPO | F17: MXL | G17: 900006172 | H17: SF TC-ED ESTRATEGIAS SANTA CALIZA | I17: 5049458 | J17: ESTRATEGIAS AVANZADAS PARA OBTEN | K17: Z03 | L17: (AP) 15 Dias | M17: 10000811 | N17: Grava Triturada Caliza 20 mm - 3/4" | O17: DW70 | P17: MX-CED. CENTRO | Q17: 20260616 | R17: 20301231 | S17: 20260805 | T17: 20301231 | U17: 436 | V17: MXN | W17: M3 | X17: 280 | Y17: MXN | Z17: M3 | AA17: D681 | AB17: PD0639 TULTEPEC | AC17: 56103637 | AD17: 6644261540 | AE17: 4 | AF17: ENTREGA DIRECTA | AG17: 1.447 | AH17: M3 | AI17: X | AJ17: 4 | AK17: V4 | AL17: 20260811 | AM17: DW70-900006172-D681-10000811-4
A18: 900006172DW70D07910000811 | B18: 4600072309-190 | C18: 4600072309 | D18: 190 | E18: MXPO | F18: MXL | G18: 900006172 | H18: SF TC-ED ESTRATEGIAS SANTA CALIZA | I18: 5049458 | J18: ESTRATEGIAS AVANZADAS PARA OBTEN | K18: Z03 | L18: (AP) 15 Dias | M18: 10000811 | N18: Grava Triturada Caliza 20 mm - 3/4" | O18: DW70 | P18: MX-CED. CENTRO | Q18: 20260616 | R18: 20301231 | S18: 20260805 | T18: 20301231 | U18: 694 | V18: MXN | W18: M3 | X18: 538 | Y18: MXN | Z18: M3 | AA18: D079 | AB18: PD0071 XOCHIMILCO | AC18: 56103637 | AD18: 6644261540 | AE18: 4 | AF18: ENTREGA DIRECTA | AG18: 1.447 | AH18: M3 | AI18: X | AJ18: 4 | AK18: V4 | AL18: 20260811 | AM18: DW70-900006172-D079-10000811-4
A19: 900009585DW70D09310000811 | B19: 4600072549-10 | C19: 4600072549 | D19: 10 | E19: MXPO | F19: MXL | G19: 900009585 | H19: SF TC-ED ESTRATEGIAS MAQ Y CANTERAS | I19: 5049458 | J19: ESTRATEGIAS AVANZADAS PARA OBTEN | K19: Z03 | L19: (AP) 15 Dias | M19: 10000811 | N19: Grava Triturada Caliza 20 mm - 3/4" | O19: DW70 | P19: MX-CED. CENTRO | Q19: 20260814 | R19: 20301231 | S19: 20260814 | T19: 20301231 | U19: 405.9 | V19: MXN | W19: M3 | X19: 180.9 | Y19: MXN | Z19: M3 | AA19: D093 | AB19: PD0556 ZUMPANGO | AC19: 56103637 | AD19: 6644261540 | AE19: 4 | AF19: ENTREGA DIRECTA | AG19: 1.447 | AH19: M3 | AI19: X | AJ19: 4 | AK19: V4 | AL19: 20260821 | AM19: DW70-900009585-D093-10000811-4
A20: 900009292DW7010000811 | B20: 4600071553-30 | C20: 4600071553 | D20: 30 | E20: MXPO | F20: MXL | G20: 900009292 | H20: SF TC-GRAVICOR GIL | I20: 5096226 | J20: GIL HERNANDEZ RACIEL | K20: N90 | L20: (AP) NAFIN 90 Dias | M20: 10000811 | N20: Grava Triturada Caliza 20 mm - 3/4" | O20: DW70 | P20: MX-CED. CENTRO | Q20: 20250813 | R20: 20301231 | S20: 20260814 | T20: 20301231 | U20: 225 | V20: MXN | W20: M3 | X20: 0 | Y20: MXN | Z20: M3 | AC20: 56103637 | AD20: 6644261540 | AE20: 1 | AF20: ENTREGADO | AG20: 1.447 | AH20: M3 | AI20: X | AJ20: 4 | AK20: V4 | AL20: 20260821 | AM20: DW70-900009292-10000811
A21: 900003438DW70D08110000811 | B21: 4600050497-820 | C21: 4600050497 | D21: 820 | E21: MXPO | F21: MXL | G21: 900003438 | H21: TC-ED-ESTRATEGIAS AVANZADAS | I21: 5049458 | J21: ESTRATEGIAS AVANZADAS PARA OBTEN | K21: Z03 | L21: (AP) 15 Dias | M21: 10000811 | N21: Grava Triturada Caliza 20 mm - 3/4" | O21: DW70 | P21: MX-CED. CENTRO | Q21: 20210712 | R21: 20281231 | S21: 20260819 | T21: 20301231 | U21: 536 | V21: MXN | W21: M3 | X21: 336 | Y21: MXN | Z21: M3 | AA21: D081 | AB21: PD0088 ARMAS | AC21: 56103637 | AD21: 6644261540 | AE21: 4 | AF21: ENTREGA DIRECTA | AG21: 1.447 | AH21: M3 | AI21: X | AJ21: 4 | AK21: V4 | AL21: 20260821 | AM21: DW70-900003438-D081-10000811-4
A22: 900003438DW70D14510000811 | B22: 4600050497-910 | C22: 4600050497 | D22: 910 | E22: MXPO | F22: MXL | G22: 900003438 | H22: TC-ED-ESTRATEGIAS AVANZADAS | I22: 5049458 | J22: ESTRATEGIAS AVANZADAS PARA OBTEN | K22: Z03 | L22: (AP) 15 Dias | M22: 10000811 | N22: Grava Triturada Caliza 20 mm - 3/4" | O22: DW70 | P22: MX-CED. CENTRO | Q22: 20210712 | R22: 20281231 | S22: 20260819 | T22: 20301231 | U22: 540.5 | V22: MXN | W22: M3 | X22: 340.5 | Y22: MXN | Z22: M3 | AA22: D145 | AB22: PD0458 ECATEPEC II | AC22: 56103637 | AD22: 6644261540 | AE22: 4 | AF22: ENTREGA DIRECTA | AG22: 1.447 | AH22: M3 | AI22: X | AJ22: 4 | AK22: V4 | AL22: 20260821 | AM22: DW70-900003438-D145-10000811-4
A23: 900006172DW70D08310000811 | B23: 4600072309-210 | C23: 4600072309 | D23: 210 | E23: MXPO | F23: MXL | G23: 900006172 | H23: SF TC-ED ESTRATEGIAS SANTA CALIZA | I23: 5049458 | J23: ESTRATEGIAS AVANZADAS PARA OBTEN | K23: Z03 | L23: (AP) 15 Dias | M23: 10000811 | N23: Grava Triturada Caliza 20 mm - 3/4" | O23: DW70 | P23: MX-CED. CENTRO | Q23: 20260616 | R23: 20301231 | S23: 20260805 | T23: 20301231 | U23: 579 | V23: MXN | W23: M3 | X23: 423 | Y23: MXN | Z23: M3 | AA23: D083 | AB23: PD0099 MINAS | AC23: 56103637 | AD23: 6644261540 | AE23: 4 | AF23: ENTREGA DIRECTA | AG23: 1.447 | AH23: M3 | AI23: X | AJ23: 4 | AK23: V4 | AL23: 20260811 | AM23: DW70-900006172-D083-10000811-4
A24: 900006172DW70D10510000811 | B24: 4600072309-260 | C24: 4600072309 | D24: 260 | E24: MXPO | F24: MXL | G24: 900006172 | H24: SF TC-ED ESTRATEGIAS SANTA CALIZA | I24: 5049458 | J24: ESTRATEGIAS AVANZADAS PARA OBTEN | K24: Z03 | L24: (AP) 15 Dias | M24: 10000811 | N24: Grava Triturada Caliza 20 mm - 3/4" | O24: DW70 | P24: MX-CED. CENTRO | Q24: 20260616 | R24: 20301231 | S24: 20260805 | T24: 20301231 | U24: 516 | V24: MXN | W24: M3 | X24: 360 | Y24: MXN | Z24: M3 | AA24: D105 | AB24: PD0331 NAUCALPAN II | AC24: 56103637 | AD24: 6644261540 | AE24: 4 | AF24: ENTREGA DIRECTA | AG24: 1.447 | AH24: M3 | AI24: X | AJ24: 4 | AK24: V4 | AL24: 20260811 | AM24: DW70-900006172-D105-10000811-4
A25: 900006172DW70D08110000811 | B25: 4600072309-200 | C25: 4600072309 | D25: 200 | E25: MXPO | F25: MXL | G25: 900006172 | H25: SF TC-ED ESTRATEGIAS SANTA CALIZA | I25: 5049458 | J25: ESTRATEGIAS AVANZADAS PARA OBTEN | K25: Z03 | L25: (AP) 15 Dias | M25: 10000811 | N25: Grava Triturada Caliza 20 mm - 3/4" | O25: DW70 | P25: MX-CED. CENTRO | Q25: 20260616 | R25: 20301231 | S25: 20260805 | T25: 20301231 | U25: 507 | V25: MXN | W25: M3 | X25: 351 | Y25: MXN | Z25: M3 | AA25: D081 | AB25: PD0088 ARMAS | AC25: 56103637 | AD25: 6644261540 | AE25: 4 | AF25: ENTREGA DIRECTA | AG25: 1.447 | AH25: M3 | AI25: X | AJ25: 4 | AK25: V4 | AL25: 20260811 | AM25: DW70-900006172-D081-10000811-4
A26: 900006172DW70D08410000811 | B26: 4600072309-220 | C26: 4600072309 | D26: 220 | E26: MXPO | F26: MXL | G26: 900006172 | H26: SF TC-ED ESTRATEGIAS SANTA CALIZA | I26: 5049458 | J26: ESTRATEGIAS AVANZADAS PARA OBTEN | K26: Z03 | L26: (AP) 15 Dias | M26: 10000811 | N26: Grava Triturada Caliza 20 mm - 3/4" | O26: DW70 | P26: MX-CED. CENTRO | Q26: 20260616 | R26: 20301231 | S26: 20260805 | T26: 20301231 | U26: 627 | V26: MXN | W26: M3 | X26: 471 | Y26: MXN | Z26: M3 | AA26: D084 | AB26: PD0186 IZTAPALAPA | AC26: 56103637 | AD26: 6644261540 | AE26: 4 | AF26: ENTREGA DIRECTA | AG26: 1.447 | AH26: M3 | AI26: X | AJ26: 4 | AK26: V4 | AL26: 20260811 | AM26: DW70-900006172-D084-10000811-4
A27: 900003438DW70D09310000811 | B27: 4600050497-930 | C27: 4600050497 | D27: 930 | E27: MXPO | F27: MXL | G27: 900003438 | H27: TC-ED-ESTRATEGIAS AVANZADAS | I27: 5049458 | J27: ESTRATEGIAS AVANZADAS PARA OBTEN | K27: Z03 | L27: (AP) 15 Dias | M27: 10000811 | N27: Grava Triturada Caliza 20 mm - 3/4" | O27: DW70 | P27: MX-CED. CENTRO | Q27: 20210712 | R27: 20281231 | S27: 20260819 | T27: 20301231 | U27: 413.5 | V27: MXN | W27: M3 | X27: 213.5 | Y27: MXN | Z27: M3 | AA27: D093 | AB27: PD0556 ZUMPANGO | AC27: 56103637 | AD27: 6644261540 | AE27: 4 | AF27: ENTREGA DIRECTA | AG27: 1.447 | AH27: M3 | AI27: X | AJ27: 4 | AK27: V4 | AL27: 20260821 | AM27: DW70-900003438-D093-10000811-4
A28: 900003438DW70D08510002802 | B28: 4600050497-500 | C28: 4600050497 | D28: 500 | E28: MXPO | F28: MXL | G28: 900003438 | H28: TC-ED-ESTRATEGIAS AVANZADAS | I28: 5049458 | J28: ESTRATEGIAS AVANZADAS PARA OBTEN | K28: Z03 | L28: (AP) 15 Dias | M28: 10002802 | N28: Arena Clasificada Río Malla 4 Lavado | O28: DW70 | P28: MX-CED. CENTRO | Q28: 20210712 | R28: 20281231 | S28: 20240827 | T28: 20291231 | U28: 327.98 | V28: MXN | W28: M3 | X28: 192.98 | Y28: MXN | Z28: M3 | AA28: D085 | AB28: PD0189 ROJO GOMEZ | AC28: 56103638 | AD28: 6644261540 | AE28: 4 | AF28: ENTREGA DIRECTA | AG28: 1.463 | AH28: M3 | AI28: X | AJ28: 4 | AK28: V4 | AL28: 20240830 | AM28: DW70-900003438-D085-10002802-4
A29: 900003438DW70D07410002802 | B29: 4600050497-440 | C29: 4600050497 | D29: 440 | E29: MXPO | F29: MXL | G29: 900003438 | H29: TC-ED-ESTRATEGIAS AVANZADAS | I29: 5049458 | J29: ESTRATEGIAS AVANZADAS PARA OBTEN | K29: Z03 | L29: (AP) 15 Dias | M29: 10002802 | N29: Arena Clasificada Río Malla 4 Lavado | O29: DW70 | P29: MX-CED. CENTRO | Q29: 20210712 | R29: 20281231 | S29: 20240827 | T29: 20291231 | U29: 371.83 | V29: MXN | W29: M3 | X29: 236.83 | Y29: MXN | Z29: M3 | AA29: D074 | AB29: PD0063 CENTRAL | AC29: 56103638 | AD29: 6644261540 | AE29: 4 | AF29: ENTREGA DIRECTA | AG29: 1.463 | AH29: M3 | AI29: X | AJ29: 4 | AK29: V4 | AL29: 20240830 | AM29: DW70-900003438-D074-10002802-4
A30: 900003438DW70D07910002802 | B30: 4600050497-460 | C30: 4600050497 | D30: 460 | E30: MXPO | F30: MXL | G30: 900003438 | H30: TC-ED-ESTRATEGIAS AVANZADAS | I30: 5049458 | J30: ESTRATEGIAS AVANZADAS PARA OBTEN | K30: Z03 | L30: (AP) 15 Dias | M30: 10002802 | N30: Arena Clasificada Río Malla 4 Lavado | O30: DW70 | P30: MX-CED. CENTRO | Q30: 20210712 | R30: 20281231 | S30: 20240827 | T30: 20291231 | U30: 375.48 | V30: MXN | W30: M3 | X30: 240.48 | Y30: MXN | Z30: M3 | AA30: D079 | AB30: PD0071 XOCHIMILCO | AC30: 56103638 | AD30: 6644261540 | AE30: 4 | AF30: ENTREGA DIRECTA | AG30: 1.463 | AH30: M3 | AI30: X | AJ30: 4 | AK30: V4 | AL30: 20240830 | AM30: DW70-900003438-D079-10002802-4
A31: 900003438DW70D08010002802 | B31: 4600050497-470 | C31: 4600050497 | D31: 470 | E31: MXPO | F31: MXL | G31: 900003438 | H31: TC-ED-ESTRATEGIAS AVANZADAS | I31: 5049458 | J31: ESTRATEGIAS AVANZADAS PARA OBTEN | K31: Z03 | L31: (AP) 15 Dias | M31: 10002802 | N31: Arena Clasificada Río Malla 4 Lavado | O31: DW70 | P31: MX-CED. CENTRO | Q31: 20210712 | R31: 20281231 | S31: 20240827 | T31: 20291231 | U31: 375.48 | V31: MXN | W31: M3 | X31: 240.48 | Y31: MXN | Z31: M3 | AA31: D080 | AB31: PD0086 VALLEJO | AC31: 56103638 | AD31: 6644261540 | AE31: 4 | AF31: ENTREGA DIRECTA | AG31: 1.463 | AH31: M3 | AI31: X | AJ31: 4 | AK31: V4 | AL31: 20240830 | AM31: DW70-900003438-D080-10002802-4
A32: 900003438DW70D14510002802 | B32: 4600050497-420 | C32: 4600050497 | D32: 420 | E32: MXPO | F32: MXL | G32: 900003438 | H32: TC-ED-ESTRATEGIAS AVANZADAS | I32: 5049458 | J32: ESTRATEGIAS AVANZADAS PARA OBTEN | K32: Z03 | L32: (AP) 15 Dias | M32: 10002802 | N32: Arena Clasificada Río Malla 4 Lavado | O32: DW70 | P32: MX-CED. CENTRO | Q32: 20210712 | R32: 20281231 | S32: 20240827 | T32: 20291231 | U32: 280.48 | V32: MXN | W32: M3 | X32: 145.48 | Y32: MXN | Z32: M3 | AA32: D145 | AB32: PD0458 ECATEPEC II | AC32: 56103638 | AD32: 6644261540 | AE32: 4 | AF32: ENTREGA DIRECTA | AG32: 1.463 | AH32: M3 | AI32: X | AJ32: 4 | AK32: V4 | AL32: 20240830 | AM32: DW70-900003438-D145-10002802-4
... A185: 900003438DW70D08810000623 | B185: 4600050497-220 | C185: 4600050497 | D185: 220 | E185: MXPO | F185: MXL | G185: 900003438 | H185: TC-ED-ESTRATEGIAS AVANZADAS | I185: 5049458 | J185: ESTRATEGIAS AVANZADAS PARA OBTEN | K185: Z03 | L185: (AP) 15 Dias | M185: 10000623 | N185: Grava Triturada Caliza 10 mm - 3/8" | O185: DW70 | P185: MX-CED. CENTRO | Q185: 20210712 | R185: 20281231 | S185: 20210712 | T185: 20251231 | U185: 195.72 | V185: MXN | W185: M3 | X185: 60.72 | Y185: MXN | Z185: M3 | AA185: D088 | AB185: PD081 HUEHUETOCA V | AC185: 56103637 | AD185: 6644261540 | AE185: 4 | AF185: ENTREGA DIRECTA | AG185: 1.41 | AH185: M3 | AI185: X | AJ185: 4 | AK185: V4 | AL185: 20230920 | AM185: DW70-900003438-D088-10000623-4
A186: 900009480DW7010000160 | B186: 4600071977-10 | C186: 4600071977 | D186: 10 | E186: MXPO | F186: MXL | G186: 900009480 | H186: SF TC-LOMA ANCHA SC | I186: 5047262 | J186: AGREGADOS PETREOS SAN CRISTOBAL | K186: Z03 | L186: (AP) 15 Dias | M186: 10000160 | N186: Arena Triturada Andesita Malla 4 | O186: DW70 | P186: MX-CED. CENTRO | Q186: 20260211 | R186: 20301231 | U186: 0 | V186: MXN | W186: M3 | AC186: 56103638 | AD186: 6644261540 | AE186: 1 | AF186: ENTREGADO | AG186: 1.409 | AH186: M3 | AI186: X | AJ186: 4 | AK186: V4 | AL186: 20260311 | AM186: DW70-900009480-10000160
A187: 900008265DW70ENXE10271724 | B187: 4600071526-50 | C187: 4600071526 | D187: 50 | E187: MXPO | F187: MXL | G187: 900008265 | H187: SF TC-ED CONCRETOS Y PAVIMENTOS | I187: 5089601 | J187: CONCRETOS Y PAVIMENTOS EXTERIORES S | K187: N90 | L187: (AP) NAFIN 90 Dias | M187: 10271724 | N187: MP RESIDUO DE CONCRETO | O187: DW70 | P187: MX-CED. CENTRO | Q187: 20250807 | R187: 20301231 | S187: 20251218 | T187: 20301231 | U187: 241.8 | V187: MXN | W187: M3 | X187: 200 | Y187: MXN | Z187: M3 | AA187: ENXE | AB187: PUENTES PERIFERICO ORIENTE/SICT | AC187: 56103636 | AD187: 6644261540 | AE187: 4 | AF187: ENTREGA DIRECTA | AG187: 1.9 | AH187: M3 | AI187: X | AJ187: 4 | AK187: V4 | AL187: 20251224 | AM187: DW70-900008265-ENXE-10271724-4
A188: 900006172DW70D08110233033 | B188: 4600072309-60 | C188: 4600072309 | D188: 60 | E188: MXPO | F188: MXL | G188: 900006172 | H188: SF TC-ED ESTRATEGIAS SANTA CALIZA | I188: 5049458 | J188: ESTRATEGIAS AVANZADAS PARA OBTEN | K188: Z03 | L188: (AP) 15 Dias | M188: 10233033 | N188: GRAVA TRITURADA CALIZA 13 MM - 1/2" P | O188: DW70 | P188: MX-CED. CENTRO | Q188: 20260616 | R188: 20301231 | S188: 20260616 | T188: 20301231 | U188: 507 | V188: MXN | W188: M3 | X188: 351 | Y188: MXN | Z188: M3 | AA188: D081 | AB188: PD0088 ARMAS | AC188: 56103637 | AD188: 6644261540 | AE188: 4 | AF188: ENTREGA DIRECTA | AG188: 1.4 | AH188: M3 | AI188: X | AJ188: 4 | AK188: V4 | AL188: 20260622 | AM188: DW70-900006172-D081-10233033-4
A189: 900000472DW70D13610000175 | B189: 4600050481-1090 | C189: 4600050481 | D189: 1090 | E189: MXPO | F189: MXL | G189: 900000472 | H189: TC-ED-TRIMCAV | I189: 5010147 | J189: TRITURACIONES DE MARMOL Y CALCIOS | K189: Z04 | L189: (AP) 30 Dias | M189: 10000175 | N189: Arena Triturada Caliza Malla 4 | O189: DW70 | P189: MX-CED. CENTRO | Q189: 20210712 | R189: 20291231 | S189: 20260605 | T189: 20301231 | U189: 600 | V189: MXN | W189: TN | X189: 440.86 | Y189: MXN | Z189: TN | AA189: D136 | AB189: PD0237 LA ESTRELLA | AC189: 56103638 | AD189: 6644261540 | AE189: 4 | AF189: ENTREGA DIRECTA | AG189: 1 | AH189: TO | AI189: X | AJ189: 4 | AK189: V4 | AL189: 20260611 | AM189: DW70-900000472-D136-10000175-4
A190: 900006172DW70D10510233033 | B190: 4600072309-120 | C190: 4600072309 | D190: 120 | E190: MXPO | F190: MXL | G190: 900006172 | H190: SF TC-ED ESTRATEGIAS SANTA CALIZA | I190: 5049458 | J190: ESTRATEGIAS AVANZADAS PARA OBTEN | K190: Z03 | L190: (AP) 15 Dias | M190: 10233033 | N190: GRAVA TRITURADA CALIZA 13 MM - 1/2" P | O190: DW70 | P190: MX-CED. CENTRO | Q190: 20260616 | R190: 20301231 | S190: 20260616 | T190: 20301231 | U190: 516 | V190: MXN | W190: M3 | X190: 360 | Y190: MXN | Z190: M3 | AA190: D105 | AB190: PD0331 NAUCALPAN II | AC190: 56103637 | AD190: 6644261540 | AE190: 4 | AF190: ENTREGA DIRECTA | AG190: 1.4 | AH190: M3 | AI190: X | AJ190: 4 | AK190: V4 | AL190: 20260622 | AM190: DW70-900006172-D105-10233033-4
A191: 900006172DW70D08510233033 | B191: 4600072309-90 | C191: 4600072309 | D191: 90 | E191: MXPO | F191: MXL | G191: 900006172 | H191: SF TC-ED ESTRATEGIAS SANTA CALIZA | I191: 5049458 | J191: ESTRATEGIAS AVANZADAS PARA OBTEN | K191: Z03 | L191: (AP) 15 Dias | M191: 10233033 | N191: GRAVA TRITURADA CALIZA 13 MM - 1/2" P | O191: DW70 | P191: MX-CED. CENTRO | Q191: 20260616 | R191: 20301231 | S191: 20260616 | T191: 20301231 | U191: 636 | V191: MXN | W191: M3 | X191: 480 | Y191: MXN | Z191: M3 | AA191: D085 | AB191: PD0189 ROJO GOMEZ | AC191: 56103637 | AD191: 6644261540 | AE191: 4 | AF191: ENTREGA DIRECTA | AG191: 1.4 | AH191: M3 | AI191: X | AJ191: 4 | AK191: V4 | AL191: 20260622 | AM191: DW70-900006172-D085-10233033-4
A192: 900006172DW70D14510233033 | B192: 4600072309-130 | C192: 4600072309 | D192: 130 | E192: MXPO | F192: MXL | G192: 900006172 | H192: SF TC-ED ESTRATEGIAS SANTA CALIZA | I192: 5049458 | J192: ESTRATEGIAS AVANZADAS PARA OBTEN | K192: Z03 | L192: (AP) 15 Dias | M192: 10233033 | N192: GRAVA TRITURADA CALIZA 13 MM - 1/2" P | O192: DW70 | P192: MX-CED. CENTRO | Q192: 20260616 | R192: 20301231 | S192: 20260616 | T192: 20301231 | U192: 454 | V192: MXN | W192: M3 | X192: 298 | Y192: MXN | Z192: M3 | AA192: D145 | AB192: PD0458 ECATEPEC II | AC192: 56103637 | AD192: 6644261540 | AE192: 4 | AF192: ENTREGA DIRECTA | AG192: 1.4 | AH192: M3 | AI192: X | AJ192: 4 | AK192: V4 | AL192: 20260622 | AM192: DW70-900006172-D145-10233033-4
...
