Workbook

Sheet Base Cedis D845
N1: VENTA | Q1: COSTO
A2: CONCAT1 | B2: CONCAT2 | C2: No. SF | D2: Nombre SF | E2: Cedis | F2: Destino | G2: Condicion de Expedicion | H2: Nombre Destino | I2: No. de material | J2: Nombre de material | K2: PV | L2: Inicio de vigencia | M2: Fin de vigencia | N2: Importe MP | O2: Importe Flete | P2: UM Venta | Q2: Importe Costo | R2: UM Costo | S2: Validacion 1 | T2: Validacion 2
A3: =CONCATENATE(C3,E3,F3,I3) | B3: =CONCATENATE(C3,E3,I3) | C3: 900003571 | D3: =IFERROR(VLOOKUP(C3,TRAOPE!$G:$H,2,0),"") | E3: D845 | F3: 66389450 | G3: =IFERROR(VLOOKUP(A3,Flete!$A:$E,5,0),"") | H3: =IFERROR(VLOOKUP(F3,TRAOPE!$AA:$AB,2,0),"") | I3: 10000578 | J3: =IFERROR(VLOOKUP(I3,Materiales!$A:$H,8,0),"") | K3: =IFERROR(VLOOKUP(I3,Materiales!$A:$G,7,0),"") | L3: 20190601 | M3: 20230219 | N3: 75 | O3: =IFERROR(VLOOKUP(A3,Flete!$A:$J,10,0),"") | P3: TN | Q3: =IFERROR(IFERROR(VLOOKUP(A3,TRAOPE!$A:$U,21,0),VLOOKUP(B3,TRAOPE!$A:$U,21,0)),"") | R3: =IFERROR(IFERROR(VLOOKUP(A3,TRAOPE!$A:$W,23,0),VLOOKUP(B3,TRAOPE!$A:$W,23,0)),"") | S3: =IF(AND(P3="TN",R3="TN"),N3+N(O3),IF(G3&""="1",N(K3)*N3,(N3+N(O3))*N(K3))) | T3: =IF(Q3="","",Q3-S3)
A4: =CONCATENATE(C4,E4,F4,I4) | B4: =CONCATENATE(C4,E4,I4) | C4: 900003571 | D4: =IFERROR(VLOOKUP(C4,TRAOPE!$G:$H,2,0),"") | E4: D845 | F4: 66779741 | G4: =IFERROR(VLOOKUP(A4,Flete!$A:$E,5,0),"") | H4: =IFERROR(VLOOKUP(F4,TRAOPE!$AA:$AB,2,0),"") | I4: 10026100 | J4: =IFERROR(VLOOKUP(I4,Materiales!$A:$H,8,0),"") | K4: =IFERROR(VLOOKUP(I4,Materiales!$A:$G,7,0),"") | L4: 20190524 | M4: 20230219 | N4: 66 | O4: =IFERROR(VLOOKUP(A4,Flete!$A:$J,10,0),"") | P4: TN | Q4: =IFERROR(IFERROR(VLOOKUP(A4,TRAOPE!$A:$U,21,0),VLOOKUP(B4,TRAOPE!$A:$U,21,0)),"") | R4: =IFERROR(IFERROR(VLOOKUP(A4,TRAOPE!$A:$W,23,0),VLOOKUP(B4,TRAOPE!$A:$W,23,0)),"") | S4: =IF(AND(P4="TN",R4="TN"),N4+N(O4),IF(G4&""="1",N(K4)*N4,(N4+N(O4))*N(K4))) | T4: =IF(Q4="","",Q4-S4)
A5: =CONCATENATE(C5,E5,F5,I5) | B5: =CONCATENATE(C5,E5,I5) | C5: 900003571 | D5: =IFERROR(VLOOKUP(C5,TRAOPE!$G:$H,2,0),"") | E5: D845 | F5: 66827900 | G5: =IFERROR(VLOOKUP(A5,Flete!$A:$E,5,0),"") | H5: =IFERROR(VLOOKUP(F5,TRAOPE!$AA:$AB,2,0),"") | I5: 10000578 | J5: =IFERROR(VLOOKUP(I5,Materiales!$A:$H,8,0),"") | K5: =IFERROR(VLOOKUP(I5,Materiales!$A:$G,7,0),"") | L5: 20190601 | M5: 20230219 | N5: 82 | O5: =IFERROR(VLOOKUP(A5,Flete!$A:$J,10,0),"") | P5: TN | Q5: =IFERROR(IFERROR(VLOOKUP(A5,TRAOPE!$A:$U,21,0),VLOOKUP(B5,TRAOPE!$A:$U,21,0)),"") | R5: =IFERROR(IFERROR(VLOOKUP(A5,TRAOPE!$A:$W,23,0),VLOOKUP(B5,TRAOPE!$A:$W,23,0)),"") | S5: =IF(AND(P5="TN",R5="TN"),N5+N(O5),IF(G5&""="1",N(K5)*N5,(N5+N(O5))*N(K5))) | T5: =IF(Q5="","",Q5-S5)
A6: =CONCATENATE(C6,E6,F6,I6) | B6: =CONCATENATE(C6,E6,I6) | C6: 900005260 | D6: =IFERROR(VLOOKUP(C6,TRAOPE!$G:$H,2,0),"") | E6: D845 | F6: 66256509 | G6: =IFERROR(VLOOKUP(A6,Flete!$A:$E,5,0),"") | H6: =IFERROR(VLOOKUP(F6,TRAOPE!$AA:$AB,2,0),"") | I6: 10000536 | J6: =IFERROR(VLOOKUP(I6,Materiales!$A:$H,8,0),"") | K6: =IFERROR(VLOOKUP(I6,Materiales!$A:$G,7,0),"") | L6: 20200918 | M6: 20230219 | N6: 78.75 | O6: =IFERROR(VLOOKUP(A6,Flete!$A:$J,10,0),"") | P6: TN | Q6: =IFERROR(IFERROR(VLOOKUP(A6,TRAOPE!$A:$U,21,0),VLOOKUP(B6,TRAOPE!$A:$U,21,0)),"") | R6: =IFERROR(IFERROR(VLOOKUP(A6,TRAOPE!$A:$W,23,0),VLOOKUP(B6,TRAOPE!$A:$W,23,0)),"") | S6: =IF(AND(P6="TN",R6="TN"),N6+N(O6),IF(G6&""="1",N(K6)*N6,(N6+N(O6))*N(K6))) | T6: =IF(Q6="","",Q6-S6)
A7: =CONCATENATE(C7,E7,F7,I7) | B7: =CONCATENATE(C7,E7,I7) | C7: 900005260 | D7: =IFERROR(VLOOKUP(C7,TRAOPE!$G:$H,2,0),"") | E7: D845 | F7: 66256509 | G7: =IFERROR(VLOOKUP(A7,Flete!$A:$E,5,0),"") | H7: =IFERROR(VLOOKUP(F7,TRAOPE!$AA:$AB,2,0),"") | I7: 10000578 | J7: =IFERROR(VLOOKUP(I7,Materiales!$A:$H,8,0),"") | K7: =IFERROR(VLOOKUP(I7,Materiales!$A:$G,7,0),"") | L7: 20200918 | M7: 20230219 | N7: 81.8 | O7: =IFERROR(VLOOKUP(A7,Flete!$A:$J,10,0),"") | P7: TN | Q7: =IFERROR(IFERROR(VLOOKUP(A7,TRAOPE!$A:$U,21,0),VLOOKUP(B7,TRAOPE!$A:$U,21,0)),"") | R7: =IFERROR(IFERROR(VLOOKUP(A7,TRAOPE!$A:$W,23,0),VLOOKUP(B7,TRAOPE!$A:$W,23,0)),"") | S7: =IF(AND(P7="TN",R7="TN"),N7+N(O7),IF(G7&""="1",N(K7)*N7,(N7+N(O7))*N(K7))) | T7: =IF(Q7="","",Q7-S7)
A8: =CONCATENATE(C8,E8,F8,I8) | B8: =CONCATENATE(C8,E8,I8) | C8: 900005260 | D8: =IFERROR(VLOOKUP(C8,TRAOPE!$G:$H,2,0),"") | E8: D845 | F8: 66256509 | G8: =IFERROR(VLOOKUP(A8,Flete!$A:$E,5,0),"") | H8: =IFERROR(VLOOKUP(F8,TRAOPE!$AA:$AB,2,0),"") | I8: 10000617 | J8: =IFERROR(VLOOKUP(I8,Materiales!$A:$H,8,0),"") | K8: =IFERROR(VLOOKUP(I8,Materiales!$A:$G,7,0),"") | L8: 20200918 | M8: 20230219 | N8: 95.55 | O8: =IFERROR(VLOOKUP(A8,Flete!$A:$J,10,0),"") | P8: TN | Q8: =IFERROR(IFERROR(VLOOKUP(A8,TRAOPE!$A:$U,21,0),VLOOKUP(B8,TRAOPE!$A:$U,21,0)),"") | R8: =IFERROR(IFERROR(VLOOKUP(A8,TRAOPE!$A:$W,23,0),VLOOKUP(B8,TRAOPE!$A:$W,23,0)),"") | S8: =IF(AND(P8="TN",R8="TN"),N8+N(O8),IF(G8&""="1",N(K8)*N8,(N8+N(O8))*N(K8))) | T8: =IF(Q8="","",Q8-S8)
A9: =CONCATENATE(C9,E9,F9,I9) | B9: =CONCATENATE(C9,E9,I9) | C9: 900005260 | D9: =IFERROR(VLOOKUP(C9,TRAOPE!$G:$H,2,0),"") | E9: D845 | F9: 66256509 | G9: =IFERROR(VLOOKUP(A9,Flete!$A:$E,5,0),"") | H9: =IFERROR(VLOOKUP(F9,TRAOPE!$AA:$AB,2,0),"") | I9: 10000656 | J9: =IFERROR(VLOOKUP(I9,Materiales!$A:$H,8,0),"") | K9: =IFERROR(VLOOKUP(I9,Materiales!$A:$G,7,0),"") | L9: 20200918 | M9: 20230219 | N9: 75 | O9: =IFERROR(VLOOKUP(A9,Flete!$A:$J,10,0),"") | P9: TN | Q9: =IFERROR(IFERROR(VLOOKUP(A9,TRAOPE!$A:$U,21,0),VLOOKUP(B9,TRAOPE!$A:$U,21,0)),"") | R9: =IFERROR(IFERROR(VLOOKUP(A9,TRAOPE!$A:$W,23,0),VLOOKUP(B9,TRAOPE!$A:$W,23,0)),"") | S9: =IF(AND(P9="TN",R9="TN"),N9+N(O9),IF(G9&""="1",N(K9)*N9,(N9+N(O9))*N(K9))) | T9: =IF(Q9="","",Q9-S9)
A10: =CONCATENATE(C10,E10,F10,I10) | B10: =CONCATENATE(C10,E10,I10) | C10: 900005260 | D10: =IFERROR(VLOOKUP(C10,TRAOPE!$G:$H,2,0),"") | E10: D845 | F10: 66389450 | G10: =IFERROR(VLOOKUP(A10,Flete!$A:$E,5,0),"") | H10: =IFERROR(VLOOKUP(F10,TRAOPE!$AA:$AB,2,0),"") | I10: 10000536 | J10: =IFERROR(VLOOKUP(I10,Materiales!$A:$H,8,0),"") | K10: =IFERROR(VLOOKUP(I10,Materiales!$A:$G,7,0),"") | L10: 20200817 | M10: 20230219 | N10: 78.75 | O10: =IFERROR(VLOOKUP(A10,Flete!$A:$J,10,0),"") | P10: TN | Q10: =IFERROR(IFERROR(VLOOKUP(A10,TRAOPE!$A:$U,21,0),VLOOKUP(B10,TRAOPE!$A:$U,21,0)),"") | R10: =IFERROR(IFERROR(VLOOKUP(A10,TRAOPE!$A:$W,23,0),VLOOKUP(B10,TRAOPE!$A:$W,23,0)),"") | S10: =IF(AND(P10="TN",R10="TN"),N10+N(O10),IF(G10&""="1",N(K10)*N10,(N10+N(O10))*N(K10))) | T10: =IF(Q10="","",Q10-S10)
A11: =CONCATENATE(C11,E11,F11,I11) | B11: =CONCATENATE(C11,E11,I11) | C11: 900005260 | D11: =IFERROR(VLOOKUP(C11,TRAOPE!$G:$H,2,0),"") | E11: D845 | F11: 66389450 | G11: =IFERROR(VLOOKUP(A11,Flete!$A:$E,5,0),"") | H11: =IFERROR(VLOOKUP(F11,TRAOPE!$AA:$AB,2,0),"") | I11: 10000578 | J11: =IFERROR(VLOOKUP(I11,Materiales!$A:$H,8,0),"") | K11: =IFERROR(VLOOKUP(I11,Materiales!$A:$G,7,0),"") | L11: 20200817 | M11: 20230219 | N11: 81.8 | O11: =IFERROR(VLOOKUP(A11,Flete!$A:$J,10,0),"") | P11: TN | Q11: =IFERROR(IFERROR(VLOOKUP(A11,TRAOPE!$A:$U,21,0),VLOOKUP(B11,TRAOPE!$A:$U,21,0)),"") | R11: =IFERROR(IFERROR(VLOOKUP(A11,TRAOPE!$A:$W,23,0),VLOOKUP(B11,TRAOPE!$A:$W,23,0)),"") | S11: =IF(AND(P11="TN",R11="TN"),N11+N(O11),IF(G11&""="1",N(K11)*N11,(N11+N(O11))*N(K11))) | T11: =IF(Q11="","",Q11-S11)
A12: =CONCATENATE(C12,E12,F12,I12) | B12: =CONCATENATE(C12,E12,I12) | C12: 900005260 | D12: =IFERROR(VLOOKUP(C12,TRAOPE!$G:$H,2,0),"") | E12: D845 | F12: 66389450 | G12: =IFERROR(VLOOKUP(A12,Flete!$A:$E,5,0),"") | H12: =IFERROR(VLOOKUP(F12,TRAOPE!$AA:$AB,2,0),"") | I12: 10000617 | J12: =IFERROR(VLOOKUP(I12,Materiales!$A:$H,8,0),"") | K12: =IFERROR(VLOOKUP(I12,Materiales!$A:$G,7,0),"") | L12: 20200817 | M12: 20230219 | N12: 95.55 | O12: =IFERROR(VLOOKUP(A12,Flete!$A:$J,10,0),"") | P12: TN | Q12: =IFERROR(IFERROR(VLOOKUP(A12,TRAOPE!$A:$U,21,0),VLOOKUP(B12,TRAOPE!$A:$U,21,0)),"") | R12: =IFERROR(IFERROR(VLOOKUP(A12,TRAOPE!$A:$W,23,0),VLOOKUP(B12,TRAOPE!$A:$W,23,0)),"") | S12: =IF(AND(P12="TN",R12="TN"),N12+N(O12),IF(G12&""="1",N(K12)*N12,(N12+N(O12))*N(K12))) | T12: =IF(Q12="","",Q12-S12)
A13: =CONCATENATE(C13,E13,F13,I13) | B13: =CONCATENATE(C13,E13,I13) | C13: 900005260 | D13: =IFERROR(VLOOKUP(C13,TRAOPE!$G:$H,2,0),"") | E13: D845 | F13: 66389450 | G13: =IFERROR(VLOOKUP(A13,Flete!$A:$E,5,0),"") | H13: =IFERROR(VLOOKUP(F13,TRAOPE!$AA:$AB,2,0),"") | I13: 10000656 | J13: =IFERROR(VLOOKUP(I13,Materiales!$A:$H,8,0),"") | K13: =IFERROR(VLOOKUP(I13,Materiales!$A:$G,7,0),"") | L13: 20200817 | M13: 20230219 | N13: 75 | O13: =IFERROR(VLOOKUP(A13,Flete!$A:$J,10,0),"") | P13: TN | Q13: =IFERROR(IFERROR(VLOOKUP(A13,TRAOPE!$A:$U,21,0),VLOOKUP(B13,TRAOPE!$A:$U,21,0)),"") | R13: =IFERROR(IFERROR(VLOOKUP(A13,TRAOPE!$A:$W,23,0),VLOOKUP(B13,TRAOPE!$A:$W,23,0)),"") | S13: =IF(AND(P13="TN",R13="TN"),N13+N(O13),IF(G13&""="1",N(K13)*N13,(N13+N(O13))*N(K13))) | T13: =IF(Q13="","",Q13-S13)
A14: =CONCATENATE(C14,E14,F14,I14) | B14: =CONCATENATE(C14,E14,I14) | C14: 900005260 | D14: =IFERROR(VLOOKUP(C14,TRAOPE!$G:$H,2,0),"") | E14: D845 | F14: 66704967 | G14: =IFERROR(VLOOKUP(A14,Flete!$A:$E,5,0),"") | H14: =IFERROR(VLOOKUP(F14,TRAOPE!$AA:$AB,2,0),"") | I14: 10000536 | J14: =IFERROR(VLOOKUP(I14,Materiales!$A:$H,8,0),"") | K14: =IFERROR(VLOOKUP(I14,Materiales!$A:$G,7,0),"") | L14: 20190808 | M14: 20230219 | N14: 80 | O14: =IFERROR(VLOOKUP(A14,Flete!$A:$J,10,0),"") | P14: TN | Q14: =IFERROR(IFERROR(VLOOKUP(A14,TRAOPE!$A:$U,21,0),VLOOKUP(B14,TRAOPE!$A:$U,21,0)),"") | R14: =IFERROR(IFERROR(VLOOKUP(A14,TRAOPE!$A:$W,23,0),VLOOKUP(B14,TRAOPE!$A:$W,23,0)),"") | S14: =IF(AND(P14="TN",R14="TN"),N14+N(O14),IF(G14&""="1",N(K14)*N14,(N14+N(O14))*N(K14))) | T14: =IF(Q14="","",Q14-S14)
... A336: =CONCATENATE(C336,E336,F336,I336) | B336: =CONCATENATE(C336,E336,I336) | C336: 900009255 | D336: =IFERROR(VLOOKUP(C336,TRAOPE!$G:$H,2,0),"") | E336: D845 | F336: 67318246 | G336: =IFERROR(VLOOKUP(A336,Flete!$A:$E,5,0),"") | H336: =IFERROR(VLOOKUP(F336,TRAOPE!$AA:$AB,2,0),"") | I336: 10169508 | J336: =IFERROR(VLOOKUP(I336,Materiales!$A:$H,8,0),"") | K336: =IFERROR(VLOOKUP(I336,Materiales!$A:$G,7,0),"") | L336: 20250528 | M336: 20250710 | N336: 194 | O336: =IFERROR(VLOOKUP(A336,Flete!$A:$J,10,0),"") | P336: TN | Q336: =IFERROR(IFERROR(VLOOKUP(A336,TRAOPE!$A:$U,21,0),VLOOKUP(B336,TRAOPE!$A:$U,21,0)),"") | R336: =IFERROR(IFERROR(VLOOKUP(A336,TRAOPE!$A:$W,23,0),VLOOKUP(B336,TRAOPE!$A:$W,23,0)),"") | S336: =IF(AND(P336="TN",R336="TN"),N336+N(O336),IF(G336&""="1",N(K336)*N336,(N336+N(O336))*N(K336))) | T336: =IF(Q336="","",Q336-S336)

Sheet MP
A1: No. SF | B1: Cedis | C1: Destino | D1: No. Material | E1: Nombre Material | F1: Importe MP | G1: Moneda | H1: Cantidad | I1: UM | J1: C | K1: Inicio Vigencia | L1: Fin Vigencia
A2: 900003571 | B2: D845 | C2: 66389450 | D2: 10000578 | F2: 75 | I2: TN | K2: 20190601 | L2: 20230219
A3: 900003571 | B3: D845 | C3: 66779741 | D3: 10026100 | F3: 66 | I3: TN | K3: 20190524 | L3: 20230219
A4: 900003571 | B4: D845 | C4: 66827900 | D4: 10000578 | F4: 82 | I4: TN | K4: 20190601 | L4: 20230219
A5: 900005260 | B5: D845 | C5: 66256509 | D5: 10000536 | F5: 78.75 | I5: TN | K5: 20200918 | L5: 20230219
A6: 900005260 | B6: D845 | C6: 66256509 | D6: 10000578 | F6: 81.8 | I6: TN | K6: 20200918 | L6: 20230219
A7: 900005260 | B7: D845 | C7: 66256509 | D7: 10000617 | F7: 95.55 | I7: TN | K7: 20200918 | L7: 20230219
A8: 900005260 | B8: D845 | C8: 66256509 | D8: 10000656 | F8: 75 | I8: TN | K8: 20200918 | L8: 20230219
A9: 900005260 | B9: D845 | C9: 66389450 | D9: 10000536 | F9: 78.75 | I9: TN | K9: 20200817 | L9: 20230219
A10: 900005260 | B10: D845 | C10: 66389450 | D10: 10000578 | F10: 81.8 | I10: TN | K10: 20200817 | L10: 20230219
A11: 900005260 | B11: D845 | C11: 66389450 | D11: 10000617 | F11: 95.55 | I11: TN | K11: 20200817 | L11: 20230219
A12: 900005260 | B12: D845 | C12: 66389450 | D12: 10000656 | F12: 75 | I12: TN | K12: 20200817 | L12: 20230219
A13: 900005260 | B13: D845 | C13: 66704967 | D13: 10000536 | F13: 80 | I13: TN | K13: 20190808 | L13: 20230219
... A335: 900009255 | B335: D845 | C335: 67318246 | D335: 10169508 | F335: 194 | I335: TN | K335: 20250528 | L335: 20250710

Sheet Flete
A1: Concat1 | B1: No. SF | C1: Cedis | D1: Destino | E1: Cond. Exp. | F1: Material | H1: Nombre Material | J1: Importe Flete | K1: Moneda | L1: Cantidad | M1: UM | N1: C | P1: Inicio Vigencia | Q1: Fin Vigencia
A2: 900006074D8456500513910000536 | B2: 900006074 | C2: D845 | D2: 65005139 | E2: 4 | F2: 10000536 | J2: 72 | M2: TN | P2: 20260212 | Q2: 99991231
A3: 900006074D8456500513910000578 | B3: 900006074 | C3: D845 | D3: 65005139 | E3: 4 | F3: 10000578 | J3: 72 | M3: TN | P3: 20260212 | Q3: 99991231
A4: 900006074D8456500513910000617 | B4: 900006074 | C4: D845 | D4: 65005139 | E4: 4 | F4: 10000617 | J4: 72 | M4: TN | P4: 20260212 | Q4: 99991231
A5: 900006074D8456500513910000656 | B5: 900006074 | C5: D845 | D5: 65005139 | E5: 4 | F5: 10000656 | J5: 72 | M5: TN | P5: 20260212 | Q5: 99991231
A6: 900006074D8456500513910058501 | B6: 900006074 | C6: D845 | D6: 65005139 | E6: 4 | F6: 10058501 | J6: 65 | M6: TN | P6: 20191211 | Q6: 20251031
A7: 900006074D8456500513910167749 | B7: 900006074 | C7: D845 | D7: 65005139 | E7: 4 | F7: 10167749 | J7: 72 | M7: TN | P7: 20260212 | Q7: 99991231
A8: 900006074D8456500513910169508 | B8: 900006074 | C8: D845 | D8: 65005139 | E8: 4 | F8: 10169508 | J8: 72 | M8: TN | P8: 20260212 | Q8: 99991231
A9: 900006074D8456500698910000536 | B9: 900006074 | C9: D845 | D9: 65006989 | E9: 4 | F9: 10000536 | J9: 323 | M9: TN | P9: 20251230 | Q9: 99991231
A10: 900006074D8456500698910000578 | B10: 900006074 | C10: D845 | D10: 65006989 | E10: 4 | F10: 10000578 | J10: 323 | M10: TN | P10: 20251230 | Q10: 99991231
A11: 900006074D8456500698910000617 | B11: 900006074 | C11: D845 | D11: 65006989 | E11: 4 | F11: 10000617 | J11: 323 | M11: TN | P11: 20251230 | Q11: 99991231
A12: 900006074D8456500698910000656 | B12: 900006074 | C12: D845 | D12: 65006989 | E12: 4 | F12: 10000656 | J12: 323 | M12: TN | P12: 20251230 | Q12: 99991231
A13: 900006074D8456565836210000536 | B13: 900006074 | C13: D845 | D13: 65658362 | E13: 4 | F13: 10000536 | J13: 38 | M13: TN | P13: 20191211 | Q13: 20251031
... A127: 900008838D8456724110210167749 | B127: 900008838 | C127: D845 | D127: 67241102 | E127: 4 | F127: 10167749 | J127: 150 | M127: TN | P127: 20240706 | Q127: 20240814

Sheet Materiales
A1: Material | B1: TpMt | C1: Denom | D1: UMA | E1: Contador | F1: UMB | G1: PV | H1: Nombre Material
A2: 10000001 | B2: ZFER | C2: 1000 | D2: M3 | E2: 1000 | F2: TN | G2: 1262 | H2: GRAVA ANDESITA 10 MM (3/8")
A3: 10000003 | B3: ZFER | C3: 1000 | D3: M3 | E3: 1000 | F3: TN | G3: 1443 | H3: GRAVA CALIZA 10 MM (3/8")
A4: 10000006 | B4: ZFER | C4: 1000 | D4: M3 | E4: 1000 | F4: TN | G4: 1490 | H4: GRAVA RIO 10 MM (3/8")
A5: 10000007 | B5: ZFER | C5: 1000 | D5: M3 | E5: 1000 | F5: TN | G5: 1488 | H5: GRAVA BASALTO 13 MM (1/2")
A6: 10000008 | B6: ZFER | C6: 1000 | D6: M3 | E6: 1000 | F6: TN | G6: 1358 | H6: GRAVA CALIZA 13 MM (1/2")
A7: 10000011 | B7: ZFER | C7: 1000 | D7: M3 | E7: 1000 | F7: TN | G7: 1323 | H7: GRAVA ANDESITA 20 MM (3/4")
A8: 10000013 | B8: ZFER | C8: 1000 | D8: M3 | E8: 1000 | F8: TN | G8: 1514 | H8: GRAVA BASALTO 20 MM (3/4")
A9: 10000014 | B9: ZFER | C9: 1000 | D9: M3 | E9: 1000 | F9: TN | G9: 1400 | H9: GRAVA CALIZA 20 MM (3/4")
A10: 10000015 | B10: ZFER | C10: 1000 | D10: M3 | E10: 1000 | F10: TN | G10: 1410 | H10: GRAVA GRANITO 20 MM (3/4")
A11: 10000017 | B11: ZFER | C11: 1000 | D11: M3 | E11: 1000 | F11: TN | G11: 1475 | H11: GRAVA RIOLITA 20 MM (3/4")
A12: 10000019 | B12: ZFER | C12: 1000 | D12: M3 | E12: 1000 | F12: TN | G12: 1515 | H12: GRAVA RIO 20 MM (3/4")
A13: 10000020 | B13: ZFER | C13: 1000 | D13: M3 | E13: 1 | F13: TN | G13: 1 | H13: GRAVA MAQUILA 40MM (1 1/2")
... A2291: 10268770 | B2291: ZFE3 | C2291: 1000 | D2291: M3 | E2291: 1000 | F2291: TN | G2291: 1240 | H2291: MP GRAVA TRIT CALIZA 40MM 1 1/2" - ESP
A2292: 10268901 | B2292: ZFE3 | C2292: 1000 | D2292: M3 | E2292: 1000 | G2292: 1560 | H2292: MP GRAVA ANDESITA GRIS 3/4" - CAPADA
A2293: 10267983 | C2293: 1000 | G2293: 1800 | H2293: ESCORIA ALTO HORNO 3/4
A2294: 10268996 | C2294: 1000 | G2294: 1329 | H2294: GRAVA TRITURADA CALIZA 40 MM - 11/2"
A2295: 10269072 | C2295: 1000 | G2295: 1700 | H2295: BASE HIDRÁULICA SCREEN
A2296: 10269225 | B2296: ZFE3 | C2296: 1000 | D2296: M3 | E2296: 1000 | G2296: 1289 | H2296: MP ARENA CALIZA LAVADA MALLA 4 - DELTA I
A2297: 10269245 | B2297: ZFE3 | C2297: 1000 | D2297: M3 | E2297: 1000 | G2297: 1410 | H2297: MP GRAVA TRITURADA CALIZA 3/8 - 10MM
A2298: 10269246 | B2298: ZFE3 | C2298: 1000 | D2298: M3 | E2298: 1000 | G2298: 1400 | H2298: MP GRAVA TRITURADA CALIZA 1 1/2 - 40MM
A2299: 10269247 | B2299: ZFE3 | C2299: 1000 | D2299: M3 | E2299: 1000 | G2299: 1560 | H2299: MP ARENA TRIT CALIZA M-4
A2300: 10270431 | B2300: ZFE3 | C2300: 1000 | D2300: M3 | E2300: 1000 | G2300: 1423 | H2300: MP GRAVA RIOLITA 13 MM - 1/2"
A2301: 10270898 | B2301: ZFE3 | C2301: 1000 | D2301: M3 | E2301: 1000 | G2301: 1551 | H2301: MP BASE H. TRIT. BASALTO 1 1/2" A FINOS
A2302: 10270911 | B2302: ZFE3 | C2302: 1000 | D2302: M3 | E2302: 1000 | G2302: 1360 | H2302: MP GRAVA TRIT. BASALTO 40 MM - 1 1/2"
A2303: 10270912 | B2303: ZFE3 | C2303: 1000 | D2303: M3 | E2303: 1000 | G2303: 1589 | H2303: MP ARENA TRIT. BASALTO MALLA 4
A2304: 10270913 | B2304: ZFE3 | C2304: 1000 | D2304: M3 | E2304: 1000 | G2304: 1395 | H2304: MP GRAVA TRIT. BASALTO 20 MM - 3/4
A2305: 10270914 | B2305: ZFE3 | C2305: 1000 | D2305: M3 | E2305: 1000 | G2305: 1623 | H2305: MP ARENA ANDESITA BC
A2306: 10270824 | B2306: M3 | C2306: 1000 | D2306: M3 | E2306: 10007640 | G2306: 1325 | H2306: MP ARENA TRITURADA CALIZA MALLA 5
A2307: 10270825 | B2307: M3 | C2307: 1000 | D2307: M3 | E2307: 10000003 | G2307: 1242 | H2307: MP GRAVA TRITURADA CALIZA 10MM (3/8”)
... A2319: 10272527 | B2319: ZFE3 | C2319: 1000 | D2319: M3 | E2319: 1000 | G2319: 1620 | H2319: CNC - NO CLASIFICADO
A2320: 10000332 | C2320: 1000 | D2320: M3 | E2320: 1000 | G2320: 800 | H2320: Grava Triturada Pomez - Jal 20 mm - 3/4"
A2321: 10273001 | B2321: ZFE3 | C2321: 1000 | D2321: M3 | E2321: 1000 | G2321: 1688 | H2321: MP ARENA TRIT. BASALTO MALLA 4
A2322: 10273002 | B2322: ZFE3 | C2322: 1000 | D2322: M3 | E2322: 1000 | G2322: 1466 | H2322: MP GRAVA TRIT. BASALTO 20 MM - 3/4"
A2323: 10273351 | B2323: ZFE3 | C2323: 1000 | D2323: M3 | E2323: 1000 | G2323: 1612 | H2323: MP ARENA TRIT. CALIZA MALLA 4
A2324: 10273352 | B2324: ZFE3 | C2324: 1000 | D2324: M3 | E2324: 1000 | G2324: 1492 | H2324: MP GRAVA TRIT. CALIZA 20 MM - 3/4"
A2325: 10271724 | B2325: ZFE3 | C2325: 1000 | D2325: M3 | E2325: 1000 | G2325: 1900 | H2325: MP RESIDUO DE CONCRETO
A2326: 10000677 | C2326: 1000 | D2326: M3 | G2326: 1164 | H2326: Grava Triturada Caliza 20 mm - 3/4"
A2327: 10274190 | B2327: ZFE3 | C2327: 1000 | D2327: M3 | E2327: 1000 | G2327: 1800 | H2327: MP BASE HIDRAULICA ANDESITA 70-30
A2328: 10274601 | B2328: ZFE3 | C2328: 1000 | D2328: M3 | E2328: 1000 | G2328: 1447 | H2328: MP ARENA BASALTO N° 4
...

Sheet TRAOPE
A1: Concat1 | B1: Contrato_Pos | C1: Doc. Compras | D1: Pos | E1: Org.compras | F1: Grp-Compr. | G1: Ship From | H1: Nombre SF | I1: Proveedor | J1: Nombre Prov | K1: Cond. Pago | L1: Descr. Cond Pago | M1: Material | N1: Descripción | O1: Centro | P1: Descripción Centro | Q1: In.perído validez | R1: Fin perído validez | S1: Válido de | T1: Validez a | U1: Precio neto pedido | V1: Moneda | W1: UM Precio Pedido | X1: Importe Condición | Y1: Moneda KONP | Z1: UM Ctd Base | AA1: Destino | AB1: Nombre Destino | AC1: Cuenta de mayor | AD1: Centro de costo | AE1: Cond. Exp. | AF1: Descr. Cond. Exp. | AG1: Peso Vol. | AH1: UMB | AI1: Ind. Oblig. Conf. Ped. | AJ1: Ctrl-Conf. | AK1: IVA | AL1: Modif_Date | AM1: Ruta
A2: 900009255D84510000656 | B2: 4600071321-20 | C2: 4600071321 | D2: 20 | E2: MXPO | F2: MXL | G2: 900009255 | H2: SF TP-GRAMOL CLIENTES FORANEOS | I2: 5005459 | J2: TRITURADOS GRAMOL SA DE CV | K2: Z04 | L2: (AP) 30 Dias | M2: 10000656 | N2: Grava Triturada Caliza 10 mm - 3/8" | O2: D845 | P2: MX-CED. SLP | Q2: 20250604 | R2: 20301231 | S2: 20260826 | T2: 20301231 | U2: 176 | V2: MXN | W2: TN | X2: 0 | Y2: MXN | Z2: TN | AC2: 56103637 | AD2: 6622351540 | AE2: 1 | AF2: ENTREGADO | AG2: 1 | AH2: TO | AI2: X | AJ2: 4 | AK2: V4 | AL2: 20260826 | AM2: D845-900009255-10000656
A3: 900009255D84510058501 | B3: 4600072516-10 | C3: 4600072516 | D3: 10 | E3: MXPO | F3: MXL | G3: 900009255 | H3: SF TP-GRAMOL CLIENTES FORANEOS | I3: 5005459 | J3: TRITURADOS GRAMOL SA DE CV | K3: Z04 | L3: (AP) 30 Dias | M3: 10058501 | N3: Base H Triturada Caliza 1 1/2" a Finos | O3: D845 | P3: MX-CED. SLP | Q3: 20260804 | R3: 20301231 | S3: 20260804 | T3: 20301231 | U3: 175 | V3: MXN | W3: TN | X3: 0 | Y3: MXN | Z3: TN | AC3: 56103590 | AD3: 6622351540 | AE3: 1 | AF3: ENTREGADO | AG3: 1 | AH3: TO | AI3: X | AJ3: 4 | AK3: V4 | AL3: 20260806 | AM3: D845-900009255-10058501
A4: 900008838D8456724110210167749 | B4: 4600069664-10 | C4: 4600069664 | D4: 10 | E4: MXPO | F4: MXL | G4: 900008838 | H4: SF TP-ED LA MISION RP | I4: 5086121 | J4: LA MISION RP DEL BAJIO S DE RL DE C | K4: N15 | L4: (AP) NAFIN 15 Dias | M4: 10167749 | N4: BASE H CALIZA 1 1/2" A FINOS ESPECIAL | O4: D845 | P4: MX-CED. SLP | Q4: 20240606 | R4: 20291231 | S4: 20240606 | T4: 20291231 | U4: 307 | V4: MXN | W4: TN | X4: 150 | Y4: MXN | Z4: TN | AA4: 67241102 | AB4: Estación Moctezuma Lmr | AC4: 56103590 | AD4: 6622351540 | AE4: 4 | AF4: ENTREGA DIRECTA | AG4: 1 | AH4: TO | AI4: X | AJ4: 4 | AK4: V4 | AL4: 20240806 | AM4: D845-900008838-67241102-10167749-4
A5: 900006074D8456731824610169508 | B5: 4600044538-1090 | C5: 4600044538 | D5: 1090 | E5: MXPO | F5: MXL | G5: 900006074 | H5: SF TP-ED- GRAMOL SLP | I5: 5005459 | J5: TRITURADOS GRAMOL SA DE CV | K5: Z04 | L5: (AP) 30 Dias | M5: 10169508 | N5: GRAVA TRITURADA CALIZA 13 MM - 1/2" | O5: D845 | P5: MX-CED. SLP | Q5: 20190415 | R5: 20291231 | S5: 20250517 | T5: 20301231 | U5: 314 | V5: MXN | W5: TN | X5: 141 | Y5: MXN | Z5: TN | AA5: 67318246 | AB5: DC CONCRETOS EL FUERTE | AC5: 56103637 | AD5: 6622351540 | AE5: 4 | AF5: ENTREGA DIRECTA | AG5: 1 | AH5: TO | AI5: X | AJ5: 4 | AK5: V4 | AL5: 20250520 | AM5: D845-900006074-67318246-10169508-4
A6: 900006074D8456699814910167749 | B6: 4600044538-480 | C6: 4600044538 | D6: 480 | E6: MXPO | F6: MXL | G6: 900006074 | H6: SF TP-ED- GRAMOL SLP | I6: 5005459 | J6: TRITURADOS GRAMOL SA DE CV | K6: Z04 | L6: (AP) 30 Dias | M6: 10167749 | N6: BASE H CALIZA 1 1/2" A FINOS ESPECIAL | O6: D845 | P6: MX-CED. SLP | Q6: 20190415 | R6: 20291231 | S6: 20211203 | T6: 20261231 | U6: 175 | V6: MXN | W6: TN | X6: 85 | Y6: MXN | Z6: TN | AA6: 66998149 | AB6: KANSAS | AC6: 56103590 | AD6: 6622351540 | AE6: 4 | AF6: ENTREGA DIRECTA | AG6: 1 | AH6: TO | AI6: X | AJ6: 4 | AK6: V4 | AL6: 20230920 | AM6: D845-900006074-66998149-10167749-4
A7: 900006074D8456699814910000617 | B7: 4600044538-490 | C7: 4600044538 | D7: 490 | E7: MXPO | F7: MXL | G7: 900006074 | H7: SF TP-ED- GRAMOL SLP | I7: 5005459 | J7: TRITURADOS GRAMOL SA DE CV | K7: Z04 | L7: (AP) 30 Dias | M7: 10000617 | N7: Arena Triturada Caliza Malla 5 | O7: D845 | P7: MX-CED. SLP | Q7: 20190415 | R7: 20291231 | S7: 20220223 | T7: 20271231 | U7: 182 | V7: MXN | W7: TN | X7: 85 | Y7: MXN | Z7: TN | AA7: 66998149 | AB7: KANSAS | AC7: 56103638 | AD7: 6622351540 | AE7: 4 | AF7: ENTREGA DIRECTA | AG7: 1 | AH7: TO | AI7: X | AJ7: 4 | AK7: V4 | AL7: 20230920 | AM7: D845-900006074-66998149-10000617-4
A8: 900006074D8456699814910000656 | B8: 4600044538-500 | C8: 4600044538 | D8: 500 | E8: MXPO | F8: MXL | G8: 900006074 | H8: SF TP-ED- GRAMOL SLP | I8: 5005459 | J8: TRITURADOS GRAMOL SA DE CV | K8: Z04 | L8: (AP) 30 Dias | M8: 10000656 | N8: Grava Triturada Caliza 10 mm - 3/8" | O8: D845 | P8: MX-CED. SLP | Q8: 20190415 | R8: 20291231 | S8: 20220223 | T8: 20271231 | U8: 180 | V8: MXN | W8: TN | X8: 85 | Y8: MXN | Z8: TN | AA8: 66998149 | AB8: KANSAS | AC8: 56103637 | AD8: 6622351540 | AE8: 4 | AF8: ENTREGA DIRECTA | AG8: 1 | AH8: TO | AI8: X | AJ8: 4 | AK8: V4 | AL8: 20230920 | AM8: D845-900006074-66998149-10000656-4
A9: 900006074D8456725700110000536 | B9: 4600044538-1000 | C9: 4600044538 | D9: 1000 | E9: MXPO | F9: MXL | G9: 900006074 | H9: SF TP-ED- GRAMOL SLP | I9: 5005459 | J9: TRITURADOS GRAMOL SA DE CV | K9: Z04 | L9: (AP) 30 Dias | M9: 10000536 | N9: Grava Triturada Caliza 40 mm - 1 1/2" | O9: D845 | P9: MX-CED. SLP | Q9: 20190415 | R9: 20291231 | S9: 20250409 | T9: 20301231 | U9: 270 | V9: MXN | W9: TN | X9: 89 | Y9: MXN | Z9: TN | AA9: 67257001 | AB9: KANSAS TERCERA GRANDE (ERA) | AC9: 56103637 | AD9: 6622351540 | AE9: 4 | AF9: ENTREGA DIRECTA | AG9: 1 | AH9: TO | AI9: X | AJ9: 4 | AK9: V4 | AL9: 20250410 | AM9: D845-900006074-67257001-10000536-4
A10: 900006074D8456717023610167749 | B10: 4600044538-830 | C10: 4600044538 | D10: 830 | E10: MXPO | F10: MXL | G10: 900006074 | H10: SF TP-ED- GRAMOL SLP | I10: 5005459 | J10: TRITURADOS GRAMOL SA DE CV | K10: Z04 | L10: (AP) 30 Dias | M10: 10167749 | N10: BASE H CALIZA 1 1/2" A FINOS ESPECIAL | O10: D845 | P10: MX-CED. SLP | Q10: 20190415 | R10: 20291231 | S10: 20240325 | T10: 20291231 | U10: 219 | V10: MXN | W10: TN | X10: 66 | Y10: MXN | Z10: TN | AA10: 67170236 | AB10: URBANIZACIÓN RANCHO ZAMORA 2DA(ERA | AC10: 56103590 | AD10: 6622351540 | AE10: 4 | AF10: ENTREGA DIRECTA | AG10: 1 | AH10: TO | AI10: X | AJ10: 4 | AK10: V4 | AL10: 20240331 | AM10: D845-900006074-67170236-10167749-4
A11: 900006074D8456699814910178270 | B11: 4600044538-470 | C11: 4600044538 | D11: 470 | E11: MXPO | F11: MXL | G11: 900006074 | H11: SF TP-ED- GRAMOL SLP | I11: 5005459 | J11: TRITURADOS GRAMOL SA DE CV | K11: Z04 | L11: (AP) 30 Dias | M11: 10178270 | N11: SUB BASE H TRITURADA CALIZA 1 1/2" A FIN | O11: D845 | P11: MX-CED. SLP | Q11: 20190415 | R11: 20291231 | S11: 20211203 | T11: 20261231 | U11: 155 | V11: MXN | W11: TN | X11: 85 | Y11: MXN | Z11: TN | AA11: 66998149 | AB11: KANSAS | AC11: 56103590 | AD11: 6622351540 | AE11: 4 | AF11: ENTREGA DIRECTA | AG11: 1 | AH11: TO | AI11: X | AJ11: 4 | AK11: V4 | AL11: 20230920 | AM11: D845-900006074-66998149-10178270-4
A12: 900006124D84510000646 | B12: 4600044703-10 | C12: 4600044703 | D12: 10 | E12: MXPO | F12: MXL | G12: 900006124 | H12: SF TP- INCASA | I12: 5001208 | J12: INDUSTRIALIZADORA DE CALIZA SA DE | K12: Z04 | L12: (AP) 30 Dias | M12: 10000646 | N12: Grava Triturada Caliza 20 mm - 3/4" | O12: D845 | P12: MX-CED. SLP | Q12: 20190501 | R12: 20291231 | S12: 20210308 | T12: 20291231 | U12: 87 | V12: MXN | W12: TN | AC12: 56103637 | AD12: 6622351540 | AE12: 1 | AF12: ENTREGADO | AG12: 1 | AH12: TO | AI12: X | AJ12: 4 | AK12: V4 | AL12: 20230920 | AM12: D845-900006124-10000646
A13: 900006074D8456734808910167749 | B13: 4600044538-1230 | C13: 4600044538 | D13: 1230 | E13: MXPO | F13: MXL | G13: 900006074 | H13: SF TP-ED- GRAMOL SLP | I13: 5005459 | J13: TRITURADOS GRAMOL SA DE CV | K13: Z04 | L13: (AP) 30 Dias | M13: 10167749 | N13: BASE H CALIZA 1 1/2" A FINOS ESPECIAL | O13: D845 | P13: MX-CED. SLP | Q13: 20190415 | R13: 20291231 | S13: 20251118 | T13: 20301231 | U13: 269 | V13: MXN | W13: TN | X13: 86 | Y13: MXN | Z13: TN | AA13: 67348089 | AB13: CIMENTACIÓN DE TANQUE BOSCALIA | AC13: 56103590 | AD13: 6622351540 | AE13: 4 | AF13: ENTREGA DIRECTA | AG13: 1 | AH13: TO | AI13: X | AJ13: 4 | AK13: V4 | AL13: 20251120 | AM13: D845-900006074-67348089-10167749-4
A14: 900006074D8456734854410167749 | B14: 4600044538-1220 | C14: 4600044538 | D14: 1220 | E14: MXPO | F14: MXL | G14: 900006074 | H14: SF TP-ED- GRAMOL SLP | I14: 5005459 | J14: TRITURADOS GRAMOL SA DE CV | K14: Z04 | L14: (AP) 30 Dias | M14: 10167749 | N14: BASE H CALIZA 1 1/2" A FINOS ESPECIAL | O14: D845 | P14: MX-CED. SLP | Q14: 20190415 | R14: 20291231 | S14: 20251118 | T14: 20301231 | U14: 258 | V14: MXN | W14: TN | X14: 75 | Y14: MXN | Z14: TN | AA14: 67348544 | AB14: PRIVADA HIDALGO LA PILA GLL | AC14: 56103590 | AD14: 6622351540 | AE14: 4 | AF14: ENTREGA DIRECTA | AG14: 1 | AH14: TO | AI14: X | AJ14: 4 | AK14: V4 | AL14: 20251120 | AM14: D845-900006074-67348544-10167749-4
A15: 900003510D84510000405 | B15: 4600038453-30 | C15: 4600038453 | D15: 30 | E15: MXPO | F15: MXL | G15: 900003510 | H15: TP-TRISEGO | I15: 5041773 | J15: TRISEGO SA DE CV | K15: N90 | L15: (AP) NAFIN 90 Dias | M15: 10000405 | N15: Grava Triturada Caliza 20 mm - 3/4" | O15: D845 | P15: MX-CED. SLP | Q15: 20170621 | R15: 20241231 | S15: 20170621 | T15: 20241231 | U15: 110 | V15: MXN | W15: M3 | X15: 0 | Y15: MXN | Z15: M3 | AC15: 56103637 | AD15: 6622351540 | AE15: 1 | AF15: ENTREGADO | AG15: 1.4 | AH15: M3 | AI15: X | AJ15: 4 | AK15: V4 | AL15: 20230920 | AM15: D845-900003510-10000405
A16: 900003510D84510000624 | B16: 4600038453-40 | C16: 4600038453 | D16: 40 | E16: MXPO | F16: MXL | G16: 900003510 | H16: TP-TRISEGO | I16: 5041773 | J16: TRISEGO SA DE CV | K16: N90 | L16: (AP) NAFIN 90 Dias | M16: 10000624 | N16: Grava Triturada Caliza 40 mm - 1 1/2" | O16: D845 | P16: MX-CED. SLP | Q16: 20170621 | R16: 20241231 | S16: 20170621 | T16: 20241231 | U16: 110 | V16: MXN | W16: M3 | X16: 0 | Y16: MXN | Z16: M3 | AC16: 56103637 | AD16: 6622351540 | AE16: 1 | AF16: ENTREGADO | AG16: 1.45 | AH16: M3 | AI16: X | AJ16: 4 | AK16: V4 | AL16: 20230920 | AM16: D845-900003510-10000624
A17: 900003510D84510000403 | B17: 4600038453-10 | C17: 4600038453 | D17: 10 | E17: MXPO | F17: MXL | G17: 900003510 | H17: TP-TRISEGO | I17: 5041773 | J17: TRISEGO SA DE CV | K17: N90 | L17: (AP) NAFIN 90 Dias | M17: 10000403 | N17: Arena Triturada Caliza Malla 4 | O17: D845 | P17: MX-CED. SLP | Q17: 20170621 | R17: 20241231 | S17: 20170621 | T17: 20241231 | U17: 137 | V17: MXN | W17: M3 | X17: 0 | Y17: MXN | Z17: M3 | AC17: 56103638 | AD17: 6622351540 | AE17: 1 | AF17: ENTREGADO | AG17: 1.56 | AH17: M3 | AI17: X | AJ17: 4 | AK17: V4 | AL17: 20230920 | AM17: D845-900003510-10000403
A18: 900003510D84510000617 | B18: 4600038453-20 | C18: 4600038453 | D18: 20 | E18: MXPO | F18: MXL | G18: 900003510 | H18: TP-TRISEGO | I18: 5041773 | J18: TRISEGO SA DE CV | K18: N90 | L18: (AP) NAFIN 90 Dias | M18: 10000617 | N18: Arena Triturada Caliza Malla 5 | O18: D845 | P18: MX-CED. SLP | Q18: 20170621 | R18: 20241231 | S18: 20170621 | T18: 20241231 | U18: 137 | V18: MXN | W18: M3 | X18: 0 | Y18: MXN | Z18: M3 | AC18: 56103638 | AD18: 6622351540 | AE18: 1 | AF18: ENTREGADO | AG18: 1.56 | AH18: M3 | AI18: X | AJ18: 4 | AK18: V4 | AL18: 20230920 | AM18: D845-900003510-10000617
A19: 900003510D84510043202 | B19: 4600038453-50 | C19: 4600038453 | D19: 50 | E19: MXPO | F19: MXL | G19: 900003510 | H19: TP-TRISEGO | I19: 5041773 | J19: TRISEGO SA DE CV | K19: N90 | L19: (AP) NAFIN 90 Dias | M19: 10043202 | N19: Grava Triturada Caliza 10 mm - 3/8" | O19: D845 | P19: MX-CED. SLP | Q19: 20170621 | R19: 20241231 | S19: 20170621 | T19: 20241231 | U19: 115 | V19: MXN | W19: M3 | X19: 0 | Y19: MXN | Z19: M3 | AC19: 56103637 | AD19: 6622351540 | AE19: 1 | AF19: ENTREGADO | AG19: 1.355 | AH19: M3 | AI19: X | AJ19: 4 | AK19: V4 | AL19: 20230920 | AM19: D845-900003510-10043202
A20: 900005260D84510217514 | B20: 4600068951-190 | C20: 4600068951 | D20: 190 | E20: MXPO | F20: MXL | G20: 900005260 | H20: TP-GRAMOL SLP ESPECIAL | I20: 5005459 | J20: TRITURADOS GRAMOL SA DE CV | K20: Z04 | L20: (AP) 30 Dias | M20: 10217514 | N20: ECOBASE | O20: D845 | P20: MX-CED. SLP | Q20: 20231201 | R20: 20291231 | S20: 20250127 | T20: 20301231 | U20: 75 | V20: MXN | W20: M3 | X20: 0 | Y20: MXN | Z20: M3 | AC20: 56103590 | AD20: 6622351540 | AE20: 1 | AF20: ENTREGADO | AG20: 1.5 | AH20: M3 | AI20: X | AJ20: 4 | AK20: V4 | AL20: 20250212 | AM20: D845-900005260-10217514
A21: 900006074D8456735589710000578 | B21: 4600044538-1390 | C21: 4600044538 | D21: 1390 | E21: MXPO | F21: MXL | G21: 900006074 | H21: SF TP-ED- GRAMOL SLP | I21: 5005459 | J21: TRITURADOS GRAMOL SA DE CV | K21: Z04 | L21: (AP) 30 Dias | M21: 10000578 | N21: GRAVA TRITURADA CALIZA 20 MM - 3/4" | O21: D845 | P21: MX-CED. SLP | Q21: 20190415 | R21: 20291231 | S21: 20260123 | T21: 20301231 | U21: 251 | V21: MXN | W21: TN | X21: 70 | Y21: MXN | Z21: TN | AA21: 67355897 | AB21: ACCESO A HUIZACHES | AC21: 56103637 | AD21: 6622351540 | AE21: 4 | AF21: ENTREGA DIRECTA | AG21: 1 | AH21: TO | AI21: X | AJ21: 4 | AK21: V4 | AL21: 20260127 | AM21: D845-900006074-67355897-10000578-4
A22: 900006074D8456735589710167749 | B22: 4600044538-1370 | C22: 4600044538 | D22: 1370 | E22: MXPO | F22: MXL | G22: 900006074 | H22: SF TP-ED- GRAMOL SLP | I22: 5005459 | J22: TRITURADOS GRAMOL SA DE CV | K22: Z04 | L22: (AP) 30 Dias | M22: 10167749 | N22: BASE H CALIZA 1 1/2" A FINOS ESPECIAL | O22: D845 | P22: MX-CED. SLP | Q22: 20190415 | R22: 20291231 | S22: 20260123 | T22: 20301231 | U22: 253 | V22: MXN | W22: TN | X22: 70 | Y22: MXN | Z22: TN | AA22: 67355897 | AB22: ACCESO A HUIZACHES | AC22: 56103590 | AD22: 6622351540 | AE22: 4 | AF22: ENTREGA DIRECTA | AG22: 1 | AH22: TO | AI22: X | AJ22: 4 | AK22: V4 | AL22: 20260127 | AM22: D845-900006074-67355897-10167749-4
A23: 900006074D8456720008610167749 | B23: 4600044538-730 | C23: 4600044538 | D23: 730 | E23: MXPO | F23: MXL | G23: 900006074 | H23: SF TP-ED- GRAMOL SLP | I23: 5005459 | J23: TRITURADOS GRAMOL SA DE CV | K23: Z04 | L23: (AP) 30 Dias | M23: 10167749 | N23: BASE H CALIZA 1 1/2" A FINOS ESPECIAL | O23: D845 | P23: MX-CED. SLP | Q23: 20190415 | R23: 20291231 | S23: 20240227 | T23: 20291231 | U23: 218 | V23: MXN | W23: TN | X23: 65 | Y23: MXN | Z23: TN | AA23: 67200086 | AB23: MABE AGREGADOS (ERA) | AC23: 56103590 | AD23: 6622351540 | AE23: 4 | AF23: ENTREGA DIRECTA | AG23: 1 | AH23: TO | AI23: X | AJ23: 4 | AK23: V4 | AL23: 20240229 | AM23: D845-900006074-67200086-10167749-4
A24: 900006074D8456720008610000578 | B24: 4600044538-750 | C24: 4600044538 | D24: 750 | E24: MXPO | F24: MXL | G24: 900006074 | H24: SF TP-ED- GRAMOL SLP | I24: 5005459 | J24: TRITURADOS GRAMOL SA DE CV | K24: Z04 | L24: (AP) 30 Dias | M24: 10000578 | N24: Grava Triturada Caliza 20 mm - 3/4" | O24: D845 | P24: MX-CED. SLP | Q24: 20190415 | R24: 20291231 | S24: 20240227 | T24: 20291231 | U24: 215 | V24: MXN | W24: TN | X24: 65 | Y24: MXN | Z24: TN | AA24: 67200086 | AB24: MABE AGREGADOS (ERA) | AC24: 56103637 | AD24: 6622351540 | AE24: 4 | AF24: ENTREGA DIRECTA | AG24: 1 | AH24: TO | AI24: X | AJ24: 4 | AK24: V4 | AL24: 20240229 | AM24: D845-900006074-67200086-10000578-4
A25: 900006074D8456737467110167749 | B25: 4600044538-1400 | C25: 4600044538 | D25: 1400 | E25: MXPO | F25: MXL | G25: 900006074 | H25: SF TP-ED- GRAMOL SLP | I25: 5005459 | J25: TRITURADOS GRAMOL SA DE CV | K25: Z04 | L25: (AP) 30 Dias | M25: 10167749 | N25: BASE H CALIZA 1 1/2" A FINOS ESPECIAL | O25: D845 | P25: MX-CED. SLP | Q25: 20190415 | R25: 20291231 | S25: 20260417 | T25: 20301231 | U25: 306 | V25: MXN | W25: TN | X25: 86 | Y25: MXN | Z25: TN | AA25: 67374671 | AB25: ACCESO A LOS DUARTE | AC25: 56103590 | AD25: 6622351540 | AE25: 4 | AF25: ENTREGA DIRECTA | AG25: 1 | AH25: TO | AI25: X | AJ25: 4 | AK25: V4 | AL25: 20260422 | AM25: D845-900006074-67374671-10167749-4
A26: 900006074D8456735589710000536 | B26: 4600044538-1380 | C26: 4600044538 | D26: 1380 | E26: MXPO | F26: MXL | G26: 900006074 | H26: SF TP-ED- GRAMOL SLP | I26: 5005459 | J26: TRITURADOS GRAMOL SA DE CV | K26: Z04 | L26: (AP) 30 Dias | M26: 10000536 | N26: Grava Triturada Caliza 40 mm - 1 1/2" | O26: D845 | P26: MX-CED. SLP | Q26: 20190415 | R26: 20291231 | S26: 20260123 | T26: 20301231 | U26: 251 | V26: MXN | W26: TN | X26: 70 | Y26: MXN | Z26: TN | AA26: 67355897 | AB26: ACCESO A HUIZACHES | AC26: 56103637 | AD26: 6622351540 | AE26: 4 | AF26: ENTREGA DIRECTA | AG26: 1 | AH26: TO | AI26: X | AJ26: 4 | AK26: V4 | AL26: 20260127 | AM26: D845-900006074-67355897-10000536-4
A27: 900006074D8456728337510167749 | B27: 4600044538-960 | C27: 4600044538 | D27: 960 | E27: MXPO | F27: MXL | G27: 900006074 | H27: SF TP-ED- GRAMOL SLP | I27: 5005459 | J27: TRITURADOS GRAMOL SA DE CV | K27: Z04 | L27: (AP) 30 Dias | M27: 10167749 | N27: BASE H CALIZA 1 1/2" A FINOS ESPECIAL | O27: D845 | P27: MX-CED. SLP | Q27: 20190415 | R27: 20291231 | S27: 20240918 | T27: 20291231 | U27: 238 | V27: MXN | W27: TN | X27: 85 | Y27: MXN | Z27: TN | AA27: 67283375 | AB27: LA SECA 24 K | AC27: 56103590 | AD27: 6622351540 | AE27: 4 | AF27: ENTREGA DIRECTA | AG27: 1 | AH27: TO | AI27: X | AJ27: 4 | AK27: V4 | AL27: 20241004 | AM27: D845-900006074-67283375-10167749-4
A28: 900006074D8456730740210000536 | B28: 4600044538-1140 | C28: 4600044538 | D28: 1140 | E28: MXPO | F28: MXL | G28: 900006074 | H28: SF TP-ED- GRAMOL SLP | I28: 5005459 | J28: TRITURADOS GRAMOL SA DE CV | K28: Z04 | L28: (AP) 30 Dias | M28: 10000536 | N28: Grava Triturada Caliza 40 mm - 1 1/2" | O28: D845 | P28: MX-CED. SLP | Q28: 20190415 | R28: 20291231 | S28: 20250708 | T28: 20301231 | U28: 231 | V28: MXN | W28: TN | X28: 50 | Y28: MXN | Z28: TN | AA28: 67307402 | AB28: C1802 WTC 3B SLP | AC28: 56103637 | AD28: 6622351540 | AE28: 4 | AF28: ENTREGA DIRECTA | AG28: 1 | AH28: TO | AI28: X | AJ28: 4 | AK28: V4 | AL28: 20250711 | AM28: D845-900006074-67307402-10000536-4
A29: 900006074D8456730740210167749 | B29: 4600044538-1150 | C29: 4600044538 | D29: 1150 | E29: MXPO | F29: MXL | G29: 900006074 | H29: SF TP-ED- GRAMOL SLP | I29: 5005459 | J29: TRITURADOS GRAMOL SA DE CV | K29: Z04 | L29: (AP) 30 Dias | M29: 10167749 | N29: BASE H CALIZA 1 1/2" A FINOS ESPECIAL | O29: D845 | P29: MX-CED. SLP | Q29: 20190415 | R29: 20291231 | S29: 20250708 | T29: 20301231 | U29: 233 | V29: MXN | W29: TN | X29: 50 | Y29: MXN | Z29: TN | AA29: 67307402 | AB29: C1802 WTC 3B SLP | AC29: 56103590 | AD29: 6622351540 | AE29: 4 | AF29: ENTREGA DIRECTA | AG29: 1 | AH29: TO | AI29: X | AJ29: 4 | AK29: V4 | AL29: 20250711 | AM29: D845-900006074-67307402-10167749-4
A30: 900006074D8456730740210000578 | B30: 4600044538-1130 | C30: 4600044538 | D30: 1130 | E30: MXPO | F30: MXL | G30: 900006074 | H30: SF TP-ED- GRAMOL SLP | I30: 5005459 | J30: TRITURADOS GRAMOL SA DE CV | K30: Z04 | L30: (AP) 30 Dias | M30: 10000578 | N30: Grava Triturada Caliza 20 mm - 3/4" | O30: D845 | P30: MX-CED. SLP | Q30: 20190415 | R30: 20291231 | S30: 20250708 | T30: 20301231 | U30: 231 | V30: MXN | W30: TN | X30: 50 | Y30: MXN | Z30: TN | AA30: 67307402 | AB30: C1802 WTC 3B SLP | AC30: 56103637 | AD30: 6622351540 | AE30: 4 | AF30: ENTREGA DIRECTA | AG30: 1 | AH30: TO | AI30: X | AJ30: 4 | AK30: V4 | AL30: 20250711 | AM30: D845-900006074-67307402-10000578-4
A31: 900006074D8456705950510000578 | B31: 4600044538-520 | C31: 4600044538 | D31: 520 | E31: MXPO | F31: MXL | G31: 900006074 | H31: SF TP-ED- GRAMOL SLP | I31: 5005459 | J31: TRITURADOS GRAMOL SA DE CV | K31: Z04 | L31: (AP) 30 Dias | M31: 10000578 | N31: Grava Triturada Caliza 20 mm - 3/4" | O31: D845 | P31: MX-CED. SLP | Q31: 20190415 | R31: 20291231 | S31: 20240227 | T31: 20291231 | U31: 209 | V31: MXN | W31: TN | X31: 59 | Y31: MXN | Z31: TN | AA31: 67059505 | AB31: PLANTA SAN LUIS POTOSI | AC31: 56103637 | AD31: 6622351540 | AE31: 4 | AF31: ENTREGA DIRECTA | AG31: 1 | AH31: TO | AI31: X | AJ31: 4 | AK31: V4 | AL31: 20240417 | AM31: D845-900006074-67059505-10000578-4
A32: 900006074D8456730740210000617 | B32: 4600044538-1120 | C32: 4600044538 | D32: 1120 | E32: MXPO | F32: MXL | G32: 900006074 | H32: SF TP-ED- GRAMOL SLP | I32: 5005459 | J32: TRITURADOS GRAMOL SA DE CV | K32: Z04 | L32: (AP) 30 Dias | M32: 10000617 | N32: Arena Triturada Caliza Malla 5 | O32: D845 | P32: MX-CED. SLP | Q32: 20190415 | R32: 20291231 | S32: 20250708 | T32: 20301231 | U32: 240 | V32: MXN | W32: TN | X32: 50 | Y32: MXN | Z32: TN | AA32: 67307402 | AB32: C1802 WTC 3B SLP | AC32: 56103638 | AD32: 6622351540 | AE32: 4 | AF32: ENTREGA DIRECTA | AG32: 1 | AH32: TO | AI32: X | AJ32: 4 | AK32: V4 | AL32: 20250711 | AM32: D845-900006074-67307402-10000617-4
... A38: 900006074D8456500513910000536 | B38: 4600044538-700 | C38: 4600044538 | D38: 700 | E38: MXPO | F38: MXL | G38: 900006074 | H38: SF TP-ED- GRAMOL SLP | I38: 5005459 | J38: TRITURADOS GRAMOL SA DE CV | K38: Z04 | L38: (AP) 30 Dias | M38: 10000536 | N38: Grava Triturada Caliza 40 mm - 1 1/2" | O38: D845 | P38: MX-CED. SLP | Q38: 20190415 | R38: 20291231 | S38: 20260212 | T38: 20301231 | U38: 296 | V38: MXN | W38: TN | X38: 68 | Y38: MXN | Z38: TN | AA38: 65005139 | AB38: CONSTRUCTORA QUID S.A. DE C.V. | AC38: 56103637 | AD38: 6622351540 | AE38: 4 | AF38: ENTREGA DIRECTA | AG38: 1 | AH38: TO | AI38: X | AJ38: 4 | AK38: V4 | AL38: 20260216 | AM38: D845-900006074-65005139-10000536-4
A39: 900005260D84510268651 | B39: 4600068951-210 | C39: 4600068951 | D39: 210 | E39: MXPO | F39: MXL | G39: 900005260 | H39: TP-GRAMOL SLP ESPECIAL | I39: 5005459 | J39: TRITURADOS GRAMOL SA DE CV | K39: Z04 | L39: (AP) 30 Dias | M39: 10268651 | N39: MP PIEDRA CALIZA 6 - 8" | O39: D845 | P39: MX-CED. SLP | Q39: 20231201 | R39: 20291231 | S39: 20260210 | T39: 20301231 | U39: 200 | V39: MXN | W39: TN | X39: 0 | Y39: MXN | Z39: TN | AC39: 56103637 | AD39: 6622351540 | AE39: 1 | AF39: ENTREGADO | AG39: 1 | AH39: TO | AI39: X | AJ39: 4 | AK39: V4 | AL39: 20260212 | AM39: D845-900005260-10268651
A40: 900005260D84510000536 | B40: 4600068951-150 | C40: 4600068951 | D40: 150 | E40: MXPO | F40: MXL | G40: 900005260 | H40: TP-GRAMOL SLP ESPECIAL | I40: 5005459 | J40: TRITURADOS GRAMOL SA DE CV | K40: Z04 | L40: (AP) 30 Dias | M40: 10000536 | N40: Grava Triturada Caliza 40 mm - 1 1/2" | O40: D845 | P40: MX-CED. SLP | Q40: 20231201 | R40: 20291231 | S40: 20260210 | T40: 20301231 | U40: 228 | V40: MXN | W40: TN | X40: 0 | Y40: MXN | Z40: TN | AC40: 56103637 | AD40: 6622351540 | AE40: 1 | AF40: ENTREGADO | AG40: 1 | AH40: TO | AI40: X | AJ40: 4 | AK40: V4 | AL40: 20260212 | AM40: D845-900005260-10000536
A41: 900005260D84510000617 | B41: 4600068951-130 | C41: 4600068951 | D41: 130 | E41: MXPO | F41: MXL | G41: 900005260 | H41: TP-GRAMOL SLP ESPECIAL | I41: 5005459 | J41: TRITURADOS GRAMOL SA DE CV | K41: Z04 | L41: (AP) 30 Dias | M41: 10000617 | N41: Arena Triturada Caliza Malla 5 | O41: D845 | P41: MX-CED. SLP | Q41: 20231201 | R41: 20291231 | S41: 20260210 | T41: 20301231 | U41: 228 | V41: MXN | W41: TN | X41: 0 | Y41: MXN | Z41: TN | AC41: 56103638 | AD41: 6622351540 | AE41: 1 | AF41: ENTREGADO | AG41: 1 | AH41: TO | AI41: X | AJ41: 4 | AK41: V4 | AL41: 20260212 | AM41: D845-900005260-10000617
A42: 900005260D84510169508 | B42: 4600068951-170 | C42: 4600068951 | D42: 170 | E42: MXPO | F42: MXL | G42: 900005260 | H42: TP-GRAMOL SLP ESPECIAL | I42: 5005459 | J42: TRITURADOS GRAMOL SA DE CV | K42: Z04 | L42: (AP) 30 Dias | M42: 10169508 | N42: GRAVA TRITURADA CALIZA 13 MM - 1/2" | O42: D845 | P42: MX-CED. SLP | Q42: 20231201 | R42: 20291231 | S42: 20260210 | T42: 20301231 | U42: 238 | V42: MXN | W42: TN | X42: 0 | Y42: MXN | Z42: TN | AC42: 56103637 | AD42: 6622351540 | AE42: 1 | AF42: ENTREGADO | AG42: 1 | AH42: TO | AI42: X | AJ42: 4 | AK42: V4 | AL42: 20260212 | AM42: D845-900005260-10169508
A43: 900005260D84510167749 | B43: 4600068951-120 | C43: 4600068951 | D43: 120 | E43: MXPO | F43: MXL | G43: 900005260 | H43: TP-GRAMOL SLP ESPECIAL | I43: 5005459 | J43: TRITURADOS GRAMOL SA DE CV | K43: Z04 | L43: (AP) 30 Dias | M43: 10167749 | N43: BASE H CALIZA 1 1/2" A FINOS ESPECIAL | O43: D845 | P43: MX-CED. SLP | Q43: 20231201 | R43: 20291231 | S43: 20260210 | T43: 20301231 | U43: 220 | V43: MXN | W43: TN | X43: 0 | Y43: MXN | Z43: TN | AC43: 56103590 | AD43: 6622351540 | AE43: 1 | AF43: ENTREGADO | AG43: 1 | AH43: TO | AI43: X | AJ43: 4 | AK43: V4 | AL43: 20260212 | AM43: D845-900005260-10167749
A44: 900005260D84510000656 | B44: 4600068951-160 | C44: 4600068951 | D44: 160 | E44: MXPO | F44: MXL | G44: 900005260 | H44: TP-GRAMOL SLP ESPECIAL | I44: 5005459 | J44: TRITURADOS GRAMOL SA DE CV | K44: Z04 | L44: (AP) 30 Dias | M44: 10000656 | N44: Grava Triturada Caliza 10 mm - 3/8" | O44: D845 | P44: MX-CED. SLP | Q44: 20231201 | R44: 20291231 | S44: 20260210 | T44: 20301231 | U44: 233 | V44: MXN | W44: TN | X44: 0 | Y44: MXN | Z44: TN | AC44: 56103637 | AD44: 6622351540 | AE44: 1 | AF44: ENTREGADO | AG44: 1 | AH44: TO | AI44: X | AJ44: 4 | AK44: V4 | AL44: 20260212 | AM44: D845-900005260-10000656
A45: 900005260D84510000578 | B45: 4600068951-140 | C45: 4600068951 | D45: 140 | E45: MXPO | F45: MXL | G45: 900005260 | H45: TP-GRAMOL SLP ESPECIAL | I45: 5005459 | J45: TRITURADOS GRAMOL SA DE CV | K45: Z04 | L45: (AP) 30 Dias | M45: 10000578 | N45: Grava Triturada Caliza 20 mm - 3/4" | O45: D845 | P45: MX-CED. SLP | Q45: 20231201 | R45: 20291231 | S45: 20260210 | T45: 20301231 | U45: 228 | V45: MXN | W45: TN | X45: 0 | Y45: MXN | Z45: TN | AC45: 56103637 | AD45: 6622351540 | AE45: 1 | AF45: ENTREGADO | AG45: 1 | AH45: TO | AI45: X | AJ45: 4 | AK45: V4 | AL45: 20260212 | AM45: D845-900005260-10000578
...
