Workbook

Sheet Base Cedis D853
N1: VENTA | Q1: COSTO
A2: CONCAT1 | B2: CONCAT2 | C2: No. SF | D2: Nombre SF | E2: Cedis | F2: Destino | G2: Condicion de Expedicion | H2: Nombre Destino | I2: No. de material | J2: Nombre de material | K2: PV | L2: Inicio de vigencia | M2: Fin de vigencia | N2: Importe MP | O2: Importe Flete | P2: UM Venta | Q2: Importe Costo | R2: UM Costo | S2: Validacion 1 | T2: Validacion 2
A3: =CONCATENATE(C3,E3,F3,I3) | B3: =CONCATENATE(C3,E3,I3) | C3: 900003541 | D3: =IFERROR(VLOOKUP(C3,TRAOPE!$G:$H,2,0),"") | E3: D853 | F3: 66650160 | G3: =IFERROR(VLOOKUP(A3,Flete!$A:$E,5,0),"") | H3: =IFERROR(VLOOKUP(F3,TRAOPE!$AA:$AB,2,0),"") | I3: 10000363 | J3: =IFERROR(VLOOKUP(I3,Materiales!$A:$H,8,0),"") | K3: =IFERROR(VLOOKUP(I3,Materiales!$A:$G,7,0),"") | L3: 20221109 | M3: 20251031 | N3: 105 | O3: =IFERROR(VLOOKUP(A3,Flete!$A:$J,10,0),"") | P3: M3 | Q3: =IFERROR(IFERROR(VLOOKUP(A3,TRAOPE!$A:$U,21,0),VLOOKUP(B3,TRAOPE!$A:$U,21,0)),"") | R3: =IFERROR(IFERROR(VLOOKUP(A3,TRAOPE!$A:$W,23,0),VLOOKUP(B3,TRAOPE!$A:$W,23,0)),"") | S3: =IF(AND(P3="TN",R3="TN"),N3+N(O3),IF(G3&""="1",N(K3)*N3,(N3+N(O3))*N(K3))) | T3: =IF(Q3="","",Q3-S3)
A4: =CONCATENATE(C4,E4,F4,I4) | B4: =CONCATENATE(C4,E4,I4) | C4: 900004527 | D4: =IFERROR(VLOOKUP(C4,TRAOPE!$G:$H,2,0),"") | E4: D853 | F4: 66650406 | G4: =IFERROR(VLOOKUP(A4,Flete!$A:$E,5,0),"") | H4: =IFERROR(VLOOKUP(F4,TRAOPE!$AA:$AB,2,0),"") | I4: 10048387 | J4: =IFERROR(VLOOKUP(I4,Materiales!$A:$H,8,0),"") | K4: =IFERROR(VLOOKUP(I4,Materiales!$A:$G,7,0),"") | L4: 20221109 | M4: 20251031 | N4: 196 | O4: =IFERROR(VLOOKUP(A4,Flete!$A:$J,10,0),"") | P4: M3 | Q4: =IFERROR(IFERROR(VLOOKUP(A4,TRAOPE!$A:$U,21,0),VLOOKUP(B4,TRAOPE!$A:$U,21,0)),"") | R4: =IFERROR(IFERROR(VLOOKUP(A4,TRAOPE!$A:$W,23,0),VLOOKUP(B4,TRAOPE!$A:$W,23,0)),"") | S4: =IF(AND(P4="TN",R4="TN"),N4+N(O4),IF(G4&""="1",N(K4)*N4,(N4+N(O4))*N(K4))) | T4: =IF(Q4="","",Q4-S4)
A5: =CONCATENATE(C5,E5,F5,I5) | B5: =CONCATENATE(C5,E5,I5) | C5: 900005092 | D5: =IFERROR(VLOOKUP(C5,TRAOPE!$G:$H,2,0),"") | E5: D853 | F5: 66804658 | G5: =IFERROR(VLOOKUP(A5,Flete!$A:$E,5,0),"") | H5: =IFERROR(VLOOKUP(F5,TRAOPE!$AA:$AB,2,0),"") | I5: 10144288 | J5: =IFERROR(VLOOKUP(I5,Materiales!$A:$H,8,0),"") | K5: =IFERROR(VLOOKUP(I5,Materiales!$A:$G,7,0),"") | L5: 20221109 | M5: 20251031 | N5: 95 | O5: =IFERROR(VLOOKUP(A5,Flete!$A:$J,10,0),"") | P5: M3 | Q5: =IFERROR(IFERROR(VLOOKUP(A5,TRAOPE!$A:$U,21,0),VLOOKUP(B5,TRAOPE!$A:$U,21,0)),"") | R5: =IFERROR(IFERROR(VLOOKUP(A5,TRAOPE!$A:$W,23,0),VLOOKUP(B5,TRAOPE!$A:$W,23,0)),"") | S5: =IF(AND(P5="TN",R5="TN"),N5+N(O5),IF(G5&""="1",N(K5)*N5,(N5+N(O5))*N(K5))) | T5: =IF(Q5="","",Q5-S5)
A6: =CONCATENATE(C6,E6,F6,I6) | B6: =CONCATENATE(C6,E6,I6) | C6: 900005242 | D6: =IFERROR(VLOOKUP(C6,TRAOPE!$G:$H,2,0),"") | E6: D853 | F6: 66804658 | G6: =IFERROR(VLOOKUP(A6,Flete!$A:$E,5,0),"") | H6: =IFERROR(VLOOKUP(F6,TRAOPE!$AA:$AB,2,0),"") | I6: 10144288 | J6: =IFERROR(VLOOKUP(I6,Materiales!$A:$H,8,0),"") | K6: =IFERROR(VLOOKUP(I6,Materiales!$A:$G,7,0),"") | L6: 20221109 | M6: 20251031 | N6: 137.64 | O6: =IFERROR(VLOOKUP(A6,Flete!$A:$J,10,0),"") | P6: M3 | Q6: =IFERROR(IFERROR(VLOOKUP(A6,TRAOPE!$A:$U,21,0),VLOOKUP(B6,TRAOPE!$A:$U,21,0)),"") | R6: =IFERROR(IFERROR(VLOOKUP(A6,TRAOPE!$A:$W,23,0),VLOOKUP(B6,TRAOPE!$A:$W,23,0)),"") | S6: =IF(AND(P6="TN",R6="TN"),N6+N(O6),IF(G6&""="1",N(K6)*N6,(N6+N(O6))*N(K6))) | T6: =IF(Q6="","",Q6-S6)
A7: =CONCATENATE(C7,E7,F7,I7) | B7: =CONCATENATE(C7,E7,I7) | C7: 900005983 | D7: =IFERROR(VLOOKUP(C7,TRAOPE!$G:$H,2,0),"") | E7: D853 | F7: 66650406 | G7: =IFERROR(VLOOKUP(A7,Flete!$A:$E,5,0),"") | H7: =IFERROR(VLOOKUP(F7,TRAOPE!$AA:$AB,2,0),"") | I7: 10133812 | J7: =IFERROR(VLOOKUP(I7,Materiales!$A:$H,8,0),"") | K7: =IFERROR(VLOOKUP(I7,Materiales!$A:$G,7,0),"") | L7: 20221109 | M7: 20251031 | N7: 162 | O7: =IFERROR(VLOOKUP(A7,Flete!$A:$J,10,0),"") | P7: M3 | Q7: =IFERROR(IFERROR(VLOOKUP(A7,TRAOPE!$A:$U,21,0),VLOOKUP(B7,TRAOPE!$A:$U,21,0)),"") | R7: =IFERROR(IFERROR(VLOOKUP(A7,TRAOPE!$A:$W,23,0),VLOOKUP(B7,TRAOPE!$A:$W,23,0)),"") | S7: =IF(AND(P7="TN",R7="TN"),N7+N(O7),IF(G7&""="1",N(K7)*N7,(N7+N(O7))*N(K7))) | T7: =IF(Q7="","",Q7-S7)
A8: =CONCATENATE(C8,E8,F8,I8) | B8: =CONCATENATE(C8,E8,I8) | C8: 900005983 | D8: =IFERROR(VLOOKUP(C8,TRAOPE!$G:$H,2,0),"") | E8: D853 | F8: 66942585 | G8: =IFERROR(VLOOKUP(A8,Flete!$A:$E,5,0),"") | H8: =IFERROR(VLOOKUP(F8,TRAOPE!$AA:$AB,2,0),"") | I8: 10133812 | J8: =IFERROR(VLOOKUP(I8,Materiales!$A:$H,8,0),"") | K8: =IFERROR(VLOOKUP(I8,Materiales!$A:$G,7,0),"") | L8: 20221109 | M8: 20251031 | N8: 196 | O8: =IFERROR(VLOOKUP(A8,Flete!$A:$J,10,0),"") | P8: M3 | Q8: =IFERROR(IFERROR(VLOOKUP(A8,TRAOPE!$A:$U,21,0),VLOOKUP(B8,TRAOPE!$A:$U,21,0)),"") | R8: =IFERROR(IFERROR(VLOOKUP(A8,TRAOPE!$A:$W,23,0),VLOOKUP(B8,TRAOPE!$A:$W,23,0)),"") | S8: =IF(AND(P8="TN",R8="TN"),N8+N(O8),IF(G8&""="1",N(K8)*N8,(N8+N(O8))*N(K8))) | T8: =IF(Q8="","",Q8-S8)
A9: =CONCATENATE(C9,E9,F9,I9) | B9: =CONCATENATE(C9,E9,I9) | C9: 900005992 | D9: =IFERROR(VLOOKUP(C9,TRAOPE!$G:$H,2,0),"") | E9: D853 | F9: 66650160 | G9: =IFERROR(VLOOKUP(A9,Flete!$A:$E,5,0),"") | H9: =IFERROR(VLOOKUP(F9,TRAOPE!$AA:$AB,2,0),"") | I9: 10139786 | J9: =IFERROR(VLOOKUP(I9,Materiales!$A:$H,8,0),"") | K9: =IFERROR(VLOOKUP(I9,Materiales!$A:$G,7,0),"") | L9: 20221109 | M9: 20251031 | N9: 105 | O9: =IFERROR(VLOOKUP(A9,Flete!$A:$J,10,0),"") | P9: M3 | Q9: =IFERROR(IFERROR(VLOOKUP(A9,TRAOPE!$A:$U,21,0),VLOOKUP(B9,TRAOPE!$A:$U,21,0)),"") | R9: =IFERROR(IFERROR(VLOOKUP(A9,TRAOPE!$A:$W,23,0),VLOOKUP(B9,TRAOPE!$A:$W,23,0)),"") | S9: =IF(AND(P9="TN",R9="TN"),N9+N(O9),IF(G9&""="1",N(K9)*N9,(N9+N(O9))*N(K9))) | T9: =IF(Q9="","",Q9-S9)
A10: =CONCATENATE(C10,E10,F10,I10) | B10: =CONCATENATE(C10,E10,I10) | C10: 900005992 | D10: =IFERROR(VLOOKUP(C10,TRAOPE!$G:$H,2,0),"") | E10: D853 | F10: 66651140 | G10: =IFERROR(VLOOKUP(A10,Flete!$A:$E,5,0),"") | H10: =IFERROR(VLOOKUP(F10,TRAOPE!$AA:$AB,2,0),"") | I10: 10139786 | J10: =IFERROR(VLOOKUP(I10,Materiales!$A:$H,8,0),"") | K10: =IFERROR(VLOOKUP(I10,Materiales!$A:$G,7,0),"") | L10: 20221109 | M10: 20251031 | N10: 106 | O10: =IFERROR(VLOOKUP(A10,Flete!$A:$J,10,0),"") | P10: M3 | Q10: =IFERROR(IFERROR(VLOOKUP(A10,TRAOPE!$A:$U,21,0),VLOOKUP(B10,TRAOPE!$A:$U,21,0)),"") | R10: =IFERROR(IFERROR(VLOOKUP(A10,TRAOPE!$A:$W,23,0),VLOOKUP(B10,TRAOPE!$A:$W,23,0)),"") | S10: =IF(AND(P10="TN",R10="TN"),N10+N(O10),IF(G10&""="1",N(K10)*N10,(N10+N(O10))*N(K10))) | T10: =IF(Q10="","",Q10-S10)
A11: =CONCATENATE(C11,E11,F11,I11) | B11: =CONCATENATE(C11,E11,I11) | C11: 900005992 | D11: =IFERROR(VLOOKUP(C11,TRAOPE!$G:$H,2,0),"") | E11: D853 | F11: 66905766 | G11: =IFERROR(VLOOKUP(A11,Flete!$A:$E,5,0),"") | H11: =IFERROR(VLOOKUP(F11,TRAOPE!$AA:$AB,2,0),"") | I11: 10139786 | J11: =IFERROR(VLOOKUP(I11,Materiales!$A:$H,8,0),"") | K11: =IFERROR(VLOOKUP(I11,Materiales!$A:$G,7,0),"") | L11: 20221109 | M11: 20251031 | N11: 110 | O11: =IFERROR(VLOOKUP(A11,Flete!$A:$J,10,0),"") | P11: M3 | Q11: =IFERROR(IFERROR(VLOOKUP(A11,TRAOPE!$A:$U,21,0),VLOOKUP(B11,TRAOPE!$A:$U,21,0)),"") | R11: =IFERROR(IFERROR(VLOOKUP(A11,TRAOPE!$A:$W,23,0),VLOOKUP(B11,TRAOPE!$A:$W,23,0)),"") | S11: =IF(AND(P11="TN",R11="TN"),N11+N(O11),IF(G11&""="1",N(K11)*N11,(N11+N(O11))*N(K11))) | T11: =IF(Q11="","",Q11-S11)
A12: =CONCATENATE(C12,E12,F12,I12) | B12: =CONCATENATE(C12,E12,I12) | C12: 900006361 | D12: =IFERROR(VLOOKUP(C12,TRAOPE!$G:$H,2,0),"") | E12: D853 | F12: 66650160 | G12: =IFERROR(VLOOKUP(A12,Flete!$A:$E,5,0),"") | H12: =IFERROR(VLOOKUP(F12,TRAOPE!$AA:$AB,2,0),"") | I12: 10139786 | J12: =IFERROR(VLOOKUP(I12,Materiales!$A:$H,8,0),"") | K12: =IFERROR(VLOOKUP(I12,Materiales!$A:$G,7,0),"") | L12: 20221109 | M12: 20251031 | N12: 105 | O12: =IFERROR(VLOOKUP(A12,Flete!$A:$J,10,0),"") | P12: M3 | Q12: =IFERROR(IFERROR(VLOOKUP(A12,TRAOPE!$A:$U,21,0),VLOOKUP(B12,TRAOPE!$A:$U,21,0)),"") | R12: =IFERROR(IFERROR(VLOOKUP(A12,TRAOPE!$A:$W,23,0),VLOOKUP(B12,TRAOPE!$A:$W,23,0)),"") | S12: =IF(AND(P12="TN",R12="TN"),N12+N(O12),IF(G12&""="1",N(K12)*N12,(N12+N(O12))*N(K12))) | T12: =IF(Q12="","",Q12-S12)
A13: =CONCATENATE(C13,E13,F13,I13) | B13: =CONCATENATE(C13,E13,I13) | C13: 900006962 | D13: =IFERROR(VLOOKUP(C13,TRAOPE!$G:$H,2,0),"") | E13: D853 | F13: 65000971 | G13: =IFERROR(VLOOKUP(A13,Flete!$A:$E,5,0),"") | H13: =IFERROR(VLOOKUP(F13,TRAOPE!$AA:$AB,2,0),"") | I13: 10140391 | J13: =IFERROR(VLOOKUP(I13,Materiales!$A:$H,8,0),"") | K13: =IFERROR(VLOOKUP(I13,Materiales!$A:$G,7,0),"") | L13: 20221109 | M13: 20251031 | N13: 122 | O13: =IFERROR(VLOOKUP(A13,Flete!$A:$J,10,0),"") | P13: M3 | Q13: =IFERROR(IFERROR(VLOOKUP(A13,TRAOPE!$A:$U,21,0),VLOOKUP(B13,TRAOPE!$A:$U,21,0)),"") | R13: =IFERROR(IFERROR(VLOOKUP(A13,TRAOPE!$A:$W,23,0),VLOOKUP(B13,TRAOPE!$A:$W,23,0)),"") | S13: =IF(AND(P13="TN",R13="TN"),N13+N(O13),IF(G13&""="1",N(K13)*N13,(N13+N(O13))*N(K13))) | T13: =IF(Q13="","",Q13-S13)
A14: =CONCATENATE(C14,E14,F14,I14) | B14: =CONCATENATE(C14,E14,I14) | C14: 900006962 | D14: =IFERROR(VLOOKUP(C14,TRAOPE!$G:$H,2,0),"") | E14: D853 | F14: 66650160 | G14: =IFERROR(VLOOKUP(A14,Flete!$A:$E,5,0),"") | H14: =IFERROR(VLOOKUP(F14,TRAOPE!$AA:$AB,2,0),"") | I14: 10140391 | J14: =IFERROR(VLOOKUP(I14,Materiales!$A:$H,8,0),"") | K14: =IFERROR(VLOOKUP(I14,Materiales!$A:$G,7,0),"") | L14: 20221109 | M14: 20251031 | N14: 122 | O14: =IFERROR(VLOOKUP(A14,Flete!$A:$J,10,0),"") | P14: M3 | Q14: =IFERROR(IFERROR(VLOOKUP(A14,TRAOPE!$A:$U,21,0),VLOOKUP(B14,TRAOPE!$A:$U,21,0)),"") | R14: =IFERROR(IFERROR(VLOOKUP(A14,TRAOPE!$A:$W,23,0),VLOOKUP(B14,TRAOPE!$A:$W,23,0)),"") | S14: =IF(AND(P14="TN",R14="TN"),N14+N(O14),IF(G14&""="1",N(K14)*N14,(N14+N(O14))*N(K14))) | T14: =IF(Q14="","",Q14-S14)
... A70: =CONCATENATE(C70,E70,F70,I70) | B70: =CONCATENATE(C70,E70,I70) | C70: 900009025 | D70: =IFERROR(VLOOKUP(C70,TRAOPE!$G:$H,2,0),"") | E70: D853 | F70: 67330441 | G70: =IFERROR(VLOOKUP(A70,Flete!$A:$E,5,0),"") | H70: =IFERROR(VLOOKUP(F70,TRAOPE!$AA:$AB,2,0),"") | I70: 10260652 | J70: =IFERROR(VLOOKUP(I70,Materiales!$A:$H,8,0),"") | K70: =IFERROR(VLOOKUP(I70,Materiales!$A:$G,7,0),"") | L70: 20250719 | M70: 99991231 | N70: 134.4 | O70: =IFERROR(VLOOKUP(A70,Flete!$A:$J,10,0),"") | P70: M3 | Q70: =IFERROR(IFERROR(VLOOKUP(A70,TRAOPE!$A:$U,21,0),VLOOKUP(B70,TRAOPE!$A:$U,21,0)),"") | R70: =IFERROR(IFERROR(VLOOKUP(A70,TRAOPE!$A:$W,23,0),VLOOKUP(B70,TRAOPE!$A:$W,23,0)),"") | S70: =IF(AND(P70="TN",R70="TN"),N70+N(O70),IF(G70&""="1",N(K70)*N70,(N70+N(O70))*N(K70))) | T70: =IF(Q70="","",Q70-S70)

Sheet MP
A1: No. SF | B1: Cedis | C1: Destino | D1: No. Material | E1: Nombre Material | F1: Importe MP | G1: Moneda | H1: Cantidad | I1: UM | J1: C | K1: Inicio Vigencia | L1: Fin Vigencia
A2: 900003541 | B2: D853 | C2: 66650160 | D2: 10000363 | F2: 105 | I2: M3 | K2: 20221109 | L2: 20251031
A3: 900004527 | B3: D853 | C3: 66650406 | D3: 10048387 | F3: 196 | I3: M3 | K3: 20221109 | L3: 20251031
A4: 900005092 | B4: D853 | C4: 66804658 | D4: 10144288 | F4: 95 | I4: M3 | K4: 20221109 | L4: 20251031
A5: 900005242 | B5: D853 | C5: 66804658 | D5: 10144288 | F5: 137.64 | I5: M3 | K5: 20221109 | L5: 20251031
A6: 900005983 | B6: D853 | C6: 66650406 | D6: 10133812 | F6: 162 | I6: M3 | K6: 20221109 | L6: 20251031
A7: 900005983 | B7: D853 | C7: 66942585 | D7: 10133812 | F7: 196 | I7: M3 | K7: 20221109 | L7: 20251031
A8: 900005992 | B8: D853 | C8: 66650160 | D8: 10139786 | F8: 105 | I8: M3 | K8: 20221109 | L8: 20251031
A9: 900005992 | B9: D853 | C9: 66651140 | D9: 10139786 | F9: 106 | I9: M3 | K9: 20221109 | L9: 20251031
A10: 900005992 | B10: D853 | C10: 66905766 | D10: 10139786 | F10: 110 | I10: M3 | K10: 20221109 | L10: 20251031
A11: 900006361 | B11: D853 | C11: 66650160 | D11: 10139786 | F11: 105 | I11: M3 | K11: 20221109 | L11: 20251031
A12: 900006962 | B12: D853 | C12: 65000971 | D12: 10140391 | F12: 122 | I12: M3 | K12: 20221109 | L12: 20251031
A13: 900006962 | B13: D853 | C13: 66650160 | D13: 10140391 | F13: 122 | I13: M3 | K13: 20221109 | L13: 20251031
... A69: 900009025 | B69: D853 | C69: 67330441 | D69: 10260652 | F69: 134.4 | I69: M3 | K69: 20250719 | L69: 99991231

Sheet Flete
A1: Concat1 | B1: No. SF | C1: Cedis | D1: Destino | E1: Cond. Exp. | F1: Material | H1: Nombre Material | J1: Importe Flete | K1: Moneda | L1: Cantidad | M1: UM | N1: C | P1: Inicio Vigencia | Q1: Fin Vigencia
A2: 900002329D8536690576610140391 | B2: 900002329 | C2: D853 | D2: 66905766 | E2: 4 | F2: 10140391 | J2: 153 | M2: M3 | P2: 20201014 | Q2: 99991231
A3: 900005242D8536680465810144288 | B3: 900005242 | C3: D853 | D3: 66804658 | E3: 1 | F3: 10144288 | J3: 62.36 | M3: M3 | P3: 20210424 | Q3: 99991231
A4: 900005992D8536512021210173699 | B4: 900005992 | C4: D853 | D4: 65120212 | E4: 4 | F4: 10173699 | J4: 19.98 | M4: TN | P4: 20191011 | Q4: 99991231
A5: 900005992D8536665114010000363 | B5: 900005992 | C5: D853 | D5: 66651140 | E5: 4 | F5: 10000363 | J5: 239 | M5: M3 | P5: 20210424 | Q5: 99991231
A6: 900005992D8536665114010139786 | B6: 900005992 | C6: D853 | D6: 66651140 | E6: 4 | F6: 10139786 | J6: 239 | M6: M3 | P6: 20210424 | Q6: 99991231
A7: 900005992D8536690576610139786 | B7: 900005992 | C7: D853 | D7: 66905766 | E7: 4 | F7: 10139786 | J7: 300 | M7: M3 | P7: 20200403 | Q7: 20251031
A8: 900005992D853D85310147091 | B8: 900005992 | C8: D853 | D8: D853 | E8: 4 | F8: 10147091 | J8: 270 | M8: TN | P8: 20190306 | Q8: 99991231
A9: 900007579D8536512021210173699 | B9: 900007579 | C9: D853 | D9: 65120212 | E9: 4 | F9: 10173699 | J9: 600 | M9: TN | P9: 20230120 | Q9: 99991231
A10: 900002329D8536680652910140391 | B10: 900002329 | C10: D853 | D10: 66806529 | E10: 4 | F10: 10140391 | J10: 127.5 | M10: M3 | P10: 20240706 | Q10: 20240814
A11: 900002329D8536690576610140391 | B11: 900002329 | C11: D853 | D11: 66905766 | E11: 4 | F11: 10140391 | J11: 153 | M11: M3 | P11: 20210615 | Q11: 20261231
A12: 900003677D8536730024110000645 | B12: 900003677 | C12: D853 | D12: 67300241 | E12: 1 | F12: 10000645 | J12: 100 | M12: M3 | P12: 20250721 | Q12: 99991231
A13: 900003677D8536730024110003344 | B13: 900003677 | C13: D853 | D13: 67300241 | E13: 1 | F13: 10003344 | J13: 100 | M13: M3 | P13: 20250721 | Q13: 99991231
... A33: 900009025D8536733044110260652 | B33: 900009025 | C33: D853 | D33: 67330441 | E33: 4 | F33: 10260652 | J33: 56 | M33: M3 | P33: 20250719 | Q33: 99991231

Sheet Materiales
A1: Material | B1: TpMt | C1: Denom | D1: UMA | E1: Contador | F1: UMB | G1: PV | H1: Nombre Material
A2: 10000001 | B2: ZFER | C2: 1000 | D2: M3 | E2: 1000 | F2: TN | G2: 1262 | H2: GRAVA ANDESITA 10 MM (3/8")
A3: 10000003 | B3: ZFER | C3: 1000 | D3: M3 | E3: 1000 | F3: TN | G3: 1443 | H3: GRAVA CALIZA 10 MM (3/8")
A4: 10000006 | B4: ZFER | C4: 1000 | D4: M3 | E4: 1000 | F4: TN | G4: 1490 | H4: GRAVA RIO 10 MM (3/8")
A5: 10000007 | B5: ZFER | C5: 1000 | D5: M3 | E5: 1000 | F5: TN | G5: 1488 | H5: GRAVA BASALTO 13 MM (1/2")
A6: 10000008 | B6: ZFER | C6: 1000 | D6: M3 | E6: 1000 | F6: TN | G6: 1358 | H6: GRAVA CALIZA 13 MM (1/2")
A7: 10000011 | B7: ZFER | C7: 1000 | D7: M3 | E7: 1000 | F7: TN | G7: 1323 | H7: GRAVA ANDESITA 20 MM (3/4")
A8: 10000013 | B8: ZFER | C8: 1000 | D8: M3 | E8: 1000 | F8: TN | G8: 1514 | H8: GRAVA BASALTO 20 MM (3/4")
A9: 10000014 | B9: ZFER | C9: 1000 | D9: M3 | E9: 1000 | F9: TN | G9: 1400 | H9: GRAVA CALIZA 20 MM (3/4")
A10: 10000015 | B10: ZFER | C10: 1000 | D10: M3 | E10: 1000 | F10: TN | G10: 1410 | H10: GRAVA GRANITO 20 MM (3/4")
A11: 10000017 | B11: ZFER | C11: 1000 | D11: M3 | E11: 1000 | F11: TN | G11: 1475 | H11: GRAVA RIOLITA 20 MM (3/4")
A12: 10000019 | B12: ZFER | C12: 1000 | D12: M3 | E12: 1000 | F12: TN | G12: 1515 | H12: GRAVA RIO 20 MM (3/4")
A13: 10000020 | B13: ZFER | C13: 1000 | D13: M3 | E13: 1 | F13: TN | G13: 1 | H13: GRAVA MAQUILA 40MM (1 1/2")
... A2291: 10268770 | B2291: ZFE3 | C2291: 1000 | D2291: M3 | E2291: 1000 | F2291: TN | G2291: 1240 | H2291: MP GRAVA TRIT CALIZA 40MM 1 1/2" - ESP
A2292: 10268901 | B2292: ZFE3 | C2292: 1000 | D2292: M3 | E2292: 1000 | G2292: 1560 | H2292: MP GRAVA ANDESITA GRIS 3/4" - CAPADA
A2293: 10267983 | C2293: 1000 | G2293: 1800 | H2293: ESCORIA ALTO HORNO 3/4
A2294: 10268996 | C2294: 1000 | G2294: 1329 | H2294: GRAVA TRITURADA CALIZA 40 MM - 11/2"
A2295: 10269072 | C2295: 1000 | G2295: 1700 | H2295: BASE HIDRÁULICA SCREEN
A2296: 10269225 | B2296: ZFE3 | C2296: 1000 | D2296: M3 | E2296: 1000 | G2296: 1289 | H2296: MP ARENA CALIZA LAVADA MALLA 4 - DELTA I
A2297: 10269245 | B2297: ZFE3 | C2297: 1000 | D2297: M3 | E2297: 1000 | G2297: 1410 | H2297: MP GRAVA TRITURADA CALIZA 3/8 - 10MM
A2298: 10269246 | B2298: ZFE3 | C2298: 1000 | D2298: M3 | E2298: 1000 | G2298: 1400 | H2298: MP GRAVA TRITURADA CALIZA 1 1/2 - 40MM
A2299: 10269247 | B2299: ZFE3 | C2299: 1000 | D2299: M3 | E2299: 1000 | G2299: 1560 | H2299: MP ARENA TRIT CALIZA M-4
A2300: 10270431 | B2300: ZFE3 | C2300: 1000 | D2300: M3 | E2300: 1000 | G2300: 1423 | H2300: MP GRAVA RIOLITA 13 MM - 1/2"
A2301: 10270898 | B2301: ZFE3 | C2301: 1000 | D2301: M3 | E2301: 1000 | G2301: 1551 | H2301: MP BASE H. TRIT. BASALTO 1 1/2" A FINOS
A2302: 10270911 | B2302: ZFE3 | C2302: 1000 | D2302: M3 | E2302: 1000 | G2302: 1360 | H2302: MP GRAVA TRIT. BASALTO 40 MM - 1 1/2"
A2303: 10270912 | B2303: ZFE3 | C2303: 1000 | D2303: M3 | E2303: 1000 | G2303: 1589 | H2303: MP ARENA TRIT. BASALTO MALLA 4
A2304: 10270913 | B2304: ZFE3 | C2304: 1000 | D2304: M3 | E2304: 1000 | G2304: 1395 | H2304: MP GRAVA TRIT. BASALTO 20 MM - 3/4
A2305: 10270914 | B2305: ZFE3 | C2305: 1000 | D2305: M3 | E2305: 1000 | G2305: 1623 | H2305: MP ARENA ANDESITA BC
A2306: 10270824 | B2306: M3 | C2306: 1000 | D2306: M3 | E2306: 10007640 | G2306: 1325 | H2306: MP ARENA TRITURADA CALIZA MALLA 5
A2307: 10270825 | B2307: M3 | C2307: 1000 | D2307: M3 | E2307: 10000003 | G2307: 1242 | H2307: MP GRAVA TRITURADA CALIZA 10MM (3/8”)
... A2319: 10272527 | B2319: ZFE3 | C2319: 1000 | D2319: M3 | E2319: 1000 | G2319: 1620 | H2319: CNC - NO CLASIFICADO
A2320: 10000332 | C2320: 1000 | D2320: M3 | E2320: 1000 | G2320: 800 | H2320: Grava Triturada Pomez - Jal 20 mm - 3/4"
A2321: 10273001 | B2321: ZFE3 | C2321: 1000 | D2321: M3 | E2321: 1000 | G2321: 1688 | H2321: MP ARENA TRIT. BASALTO MALLA 4
A2322: 10273002 | B2322: ZFE3 | C2322: 1000 | D2322: M3 | E2322: 1000 | G2322: 1466 | H2322: MP GRAVA TRIT. BASALTO 20 MM - 3/4"
A2323: 10273351 | B2323: ZFE3 | C2323: 1000 | D2323: M3 | E2323: 1000 | G2323: 1612 | H2323: MP ARENA TRIT. CALIZA MALLA 4
A2324: 10273352 | B2324: ZFE3 | C2324: 1000 | D2324: M3 | E2324: 1000 | G2324: 1492 | H2324: MP GRAVA TRIT. CALIZA 20 MM - 3/4"
A2325: 10271724 | B2325: ZFE3 | C2325: 1000 | D2325: M3 | E2325: 1000 | G2325: 1900 | H2325: MP RESIDUO DE CONCRETO
A2326: 10000677 | C2326: 1000 | D2326: M3 | G2326: 1164 | H2326: Grava Triturada Caliza 20 mm - 3/4"
A2327: 10274190 | B2327: ZFE3 | C2327: 1000 | D2327: M3 | E2327: 1000 | G2327: 1800 | H2327: MP BASE HIDRAULICA ANDESITA 70-30
A2328: 10274601 | B2328: ZFE3 | C2328: 1000 | D2328: M3 | E2328: 1000 | G2328: 1447 | H2328: MP ARENA BASALTO N° 4
...

Sheet TRAOPE
A1: Concat1 | B1: Contrato_Pos | C1: Doc. Compras | D1: Pos | E1: Org.compras | F1: Grp-Compr. | G1: Ship From | H1: Nombre SF | I1: Proveedor | J1: Nombre Prov | K1: Cond. Pago | L1: Descr. Cond Pago | M1: Material | N1: Descripción | O1: Centro | P1: Descripción Centro | Q1: In.perído validez | R1: Fin perído validez | S1: Válido de | T1: Validez a | U1: Precio neto pedido | V1: Moneda | W1: UM Precio Pedido | X1: Importe Condición | Y1: Moneda KONP | Z1: UM Ctd Base | AA1: Destino | AB1: Nombre Destino | AC1: Cuenta de mayor | AD1: Centro de costo | AE1: Cond. Exp. | AF1: Descr. Cond. Exp. | AG1: Peso Vol. | AH1: UMB | AI1: Ind. Oblig. Conf. Ped. | AJ1: Ctrl-Conf. | AK1: IVA | AL1: Modif_Date | AM1: Ruta
A2: 900007188D85310000176 | B2: 4600050169-120 | C2: 4600050169 | D2: 120 | E2: MXPO | F2: MXL | G2: 900007188 | H2: TP-FERNANDO WOOLFOLK | I2: 5081080 | J2: WOOLFOLK CARBALLO FERNANDO | K2: N90 | L2: (AP) NAFIN 90 Dias | M2: 10000176 | N2: Base H Clasificada Río 1 1/2" a Finos | O2: D853 | P2: MX-CED. MEXICALI | Q2: 20210615 | R2: 20271231 | S2: 20250610 | T2: 20301231 | U2: 50 | V2: MXN | W2: M3 | X2: 0 | Y2: MXN | Z2: M3 | AC2: 56103590 | AD2: 6622431540 | AE2: 1 | AF2: ENTREGADO | AG2: 1.6 | AH2: M3 | AI2: X | AJ2: 4 | AK2: V1 | AL2: 20260127 | AM2: D853-900007188-10000176
A3: 900005242D8536500097110148458 | B3: 4600038144-40 | C3: 4600038144 | D3: 40 | E3: MXPO | F3: MXL | G3: 900005242 | H3: SF TP-ED- SEXTIN MEXICALI | I3: 5042038 | J3: CONSTRUCTORA SEXTIN SA DE CV | K3: N120 | L3: (AP) NAFIN 120 Dias | M3: 10148458 | N3: GRAVA TRITURADA GRANITO 10 MM - 3/8" | O3: D853 | P3: MX-CED. MEXICALI | Q3: 20170530 | R3: 20241231 | S3: 20180501 | T3: 20241231 | U3: 260 | V3: MXN | W3: M3 | X3: 95 | Y3: MXN | Z3: M3 | AA3: 65000971 | AB3: (P) BLOQUERA MODERNA, S.A. DE C.V.. | AC3: 56103637 | AD3: 6622431540 | AE3: 4 | AF3: ENTREGA DIRECTA | AG3: 1.486 | AH3: M3 | AI3: X | AJ3: 4 | AK3: V1 | AL3: 20230920 | AM3: D853-900005242-65000971-10148458-4
A4: 900007188D85310148458 | B4: 4600050169-60 | C4: 4600050169 | D4: 60 | E4: MXPO | F4: MXL | G4: 900007188 | H4: TP-FERNANDO WOOLFOLK | I4: 5081080 | J4: WOOLFOLK CARBALLO FERNANDO | K4: N90 | L4: (AP) NAFIN 90 Dias | M4: 10148458 | N4: GRAVA TRITURADA GRANITO 10 MM - 3/8" | O4: D853 | P4: MX-CED. MEXICALI | Q4: 20210615 | R4: 20271231 | S4: 20250711 | T4: 20301231 | U4: 220 | V4: MXN | W4: M3 | X4: 0 | Y4: MXN | Z4: M3 | AC4: 56103637 | AD4: 6622431540 | AE4: 1 | AF4: ENTREGADO | AG4: 1.486 | AH4: M3 | AI4: X | AJ4: 4 | AK4: V1 | AL4: 20260127 | AM4: D853-900007188-10148458
A5: 900009025D8536732303210000176 | B5: 4600070533-90 | C5: 4600070533 | D5: 90 | E5: MXPO | F5: MXL | G5: 900009025 | H5: SF TP-ED FERNANDO WOOLFOLK | I5: 5081080 | J5: WOOLFOLK CARBALLO FERNANDO | K5: N90 | L5: (AP) NAFIN 90 Dias | M5: 10000176 | N5: Base H Clasificada Río 1 1/2" a Finos | O5: D853 | P5: MX-CED. MEXICALI | Q5: 20241108 | R5: 20291231 | S5: 20250610 | T5: 20301231 | U5: 175 | V5: MXN | W5: M3 | X5: 125 | Y5: MXN | Z5: M3 | AA5: 67323032 | AB5: JL PLANTA MEXICALI | AC5: 56103590 | AD5: 6622431540 | AE5: 4 | AF5: ENTREGA DIRECTA | AG5: 1.6 | AH5: M3 | AI5: X | AJ5: 4 | AK5: V1 | AL5: 20260127 | AM5: D853-900009025-67323032-10000176-4
A6: 900007188D85310152920 | B6: 4600050169-10 | C6: 4600050169 | D6: 10 | E6: MXPO | F6: MXL | G6: 900007188 | H6: TP-FERNANDO WOOLFOLK | I6: 5081080 | J6: WOOLFOLK CARBALLO FERNANDO | K6: N90 | L6: (AP) NAFIN 90 Dias | M6: 10152920 | N6: POLVO TRITURADO GRANITO | O6: D853 | P6: MX-CED. MEXICALI | Q6: 20210615 | R6: 20271231 | S6: 20250711 | T6: 20301231 | U6: 100 | V6: MXN | W6: M3 | X6: 0 | Y6: MXN | Z6: M3 | AC6: 56103591 | AD6: 6622431867 | AE6: 1 | AF6: ENTREGADO | AG6: 1.615 | AH6: M3 | AI6: X | AJ6: 4 | AK6: V1 | AL6: 20260127 | AM6: D853-900007188-10152920
A7: 900007188D85310173699 | B7: 4600050169-40 | C7: 4600050169 | D7: 40 | E7: MXPO | F7: MXL | G7: 900007188 | H7: TP-FERNANDO WOOLFOLK | I7: 5081080 | J7: WOOLFOLK CARBALLO FERNANDO | K7: N90 | L7: (AP) NAFIN 90 Dias | M7: 10173699 | N7: ARENA CLASIFICADA RIO MALLA 4 LAVADA | O7: D853 | P7: MX-CED. MEXICALI | Q7: 20210615 | R7: 20271231 | S7: 20250711 | T7: 20301231 | U7: 103 | V7: MXN | W7: M3 | X7: 0 | Y7: MXN | Z7: M3 | AC7: 56103638 | AD7: 6622431540 | AE7: 1 | AF7: ENTREGADO | AG7: 1.576 | AH7: M3 | AI7: X | AJ7: 4 | AK7: V1 | AL7: 20260127 | AM7: D853-900007188-10173699
A8: 900005092D85310148458 | B8: 4600036854-50 | C8: 4600036854 | D8: 50 | E8: MXPO | F8: MXL | G8: 900005092 | H8: SF TP- SEXTIN MEXICALI | I8: 5042038 | J8: CONSTRUCTORA SEXTIN SA DE CV | K8: N120 | L8: (AP) NAFIN 120 Dias | M8: 10148458 | N8: GRAVA TRITURADA GRANITO 10 MM - 3/8" | O8: D853 | P8: MX-CED. MEXICALI | Q8: 20170210 | R8: 20241231 | S8: 20180501 | T8: 20241231 | U8: 176 | V8: MXN | W8: M3 | X8: 0 | Y8: MXN | Z8: M3 | AC8: 56103637 | AD8: 6622431540 | AE8: 1 | AF8: ENTREGADO | AG8: 1.486 | AH8: M3 | AI8: X | AJ8: 4 | AK8: V1 | AL8: 20230920 | AM8: D853-900005092-10148458
A9: 900007188D85310208119 | B9: 4600050169-30 | C9: 4600050169 | D9: 30 | E9: MXPO | F9: MXL | G9: 900007188 | H9: TP-FERNANDO WOOLFOLK | I9: 5081080 | J9: WOOLFOLK CARBALLO FERNANDO | K9: N90 | L9: (AP) NAFIN 90 Dias | M9: 10208119 | N9: ARENA DE RIO 50% - POLVO TRITURADO GRANI | O9: D853 | P9: MX-CED. MEXICALI | Q9: 20210615 | R9: 20271231 | S9: 20211110 | T9: 20261231 | U9: 95 | V9: MXN | W9: M3 | X9: 0 | Y9: MXN | Z9: M3 | AC9: 56103638 | AD9: 6622431867 | AE9: 1 | AF9: ENTREGADO | AG9: 1.565 | AH9: M3 | AI9: X | AJ9: 4 | AK9: V1 | AL9: 20260127 | AM9: D853-900007188-10208119
A10: 900004527D85310000375 | B10: 4600033292-10 | C10: 4600033292 | D10: 10 | E10: MXPO | F10: MXL | G10: 900004527 | H10: TP- GUSA | I10: 5002503 | J10: CONSTRUCTORA GUSA SA DE CV | K10: Z03 | L10: (AP) 15 Dias | M10: 10000375 | N10: Grava Triturada Granito 20 mm - 3/4" | O10: D853 | P10: MX-CED. MEXICALI | Q10: 20160301 | R10: 20281231 | S10: 20160901 | T10: 20241231 | U10: 133.4 | V10: MXN | W10: M3 | X10: 0 | Y10: MXN | Z10: M3 | AC10: 56103637 | AD10: 6622431540 | AE10: 2 | AF10: RECOGIDO | AG10: 1.46 | AH10: M3 | AI10: X | AJ10: 4 | AK10: V1 | AL10: 20230920 | AM10: D853-900004527-10000375
A11: 900005092D85310139786 | B11: 4600036854-20 | C11: 4600036854 | D11: 20 | E11: MXPO | F11: MXL | G11: 900005092 | H11: SF TP- SEXTIN MEXICALI | I11: 5042038 | J11: CONSTRUCTORA SEXTIN SA DE CV | K11: N120 | L11: (AP) NAFIN 120 Dias | M11: 10139786 | N11: ARENA CLASIFICADA RÍO MALLA 4 | O11: D853 | P11: MX-CED. MEXICALI | Q11: 20170210 | R11: 20241231 | S11: 20180501 | T11: 20241231 | U11: 50 | V11: MXN | W11: M3 | X11: 0 | Y11: MXN | Z11: M3 | AC11: 56103638 | AD11: 6622431540 | AE11: 1 | AF11: ENTREGADO | AG11: 1.535 | AH11: M3 | AI11: X | AJ11: 4 | AK11: V1 | AL11: 20230920 | AM11: D853-900005092-10139786
A12: 900006361D85310139786 | B12: 4600045827-20 | C12: 4600045827 | D12: 20 | E12: MXPO | F12: MXL | G12: 900006361 | H12: SF TP- MABUSA | I12: 5071161 | J12: BUSTAMANTE LOPEZ MARIA ANGELICA | K12: N90 | L12: (AP) NAFIN 90 Dias | M12: 10139786 | N12: ARENA CLASIFICADA RÍO MALLA 4 | O12: D853 | P12: MX-CED. MEXICALI | Q12: 20191025 | R12: 20241231 | S12: 20191025 | T12: 20241231 | U12: 100 | V12: MXN | W12: M3 | X12: 0 | Y12: MXN | Z12: M3 | AC12: 56103638 | AD12: 6622431540 | AE12: 1 | AF12: ENTREGADO | AG12: 1.535 | AH12: M3 | AI12: X | AJ12: 4 | AK12: V1 | AL12: 20230920 | AM12: D853-900006361-10139786
A13: 900007188D85310001455 | B13: 4600050169-20 | C13: 4600050169 | D13: 20 | E13: MXPO | F13: MXL | G13: 900007188 | H13: TP-FERNANDO WOOLFOLK | I13: 5081080 | J13: WOOLFOLK CARBALLO FERNANDO | K13: N90 | L13: (AP) NAFIN 90 Dias | M13: 10001455 | N13: Arena Clasificada Río Malla 4 | O13: D853 | P13: MX-CED. MEXICALI | Q13: 20210615 | R13: 20271231 | S13: 20211110 | T13: 20261231 | U13: 100 | V13: MXN | W13: M3 | X13: 0 | Y13: MXN | Z13: M3 | AC13: 56103638 | AD13: 6622431540 | AE13: 1 | AF13: ENTREGADO | AG13: 1.73 | AH13: M3 | AI13: X | AJ13: 4 | AK13: V1 | AL13: 20260127 | AM13: D853-900007188-10001455
A14: 900005092D85310133053 | B14: 4600036854-10 | C14: 4600036854 | D14: 10 | E14: MXPO | F14: MXL | G14: 900005092 | H14: SF TP- SEXTIN MEXICALI | I14: 5042038 | J14: CONSTRUCTORA SEXTIN SA DE CV | K14: N120 | L14: (AP) NAFIN 120 Dias | M14: 10133053 | N14: GRAVA TRITURADA GRANITO 20 MM - 3/4" | O14: D853 | P14: MX-CED. MEXICALI | Q14: 20170210 | R14: 20241231 | S14: 20170210 | T14: 20241231 | U14: 145 | V14: MXN | W14: M3 | X14: 0 | Y14: MXN | Z14: M3 | AC14: 56103637 | AD14: 6622431540 | AE14: 2 | AF14: RECOGIDO | AG14: 1.44 | AH14: M3 | AI14: X | AJ14: 4 | AK14: V1 | AL14: 20230920 | AM14: D853-900005092-10133053
A15: 900005983D85310133812 | B15: 4600044926-10 | C15: 4600044926 | D15: 10 | E15: MXPO | F15: MXL | G15: 900005983 | H15: SF TP-TRITECNO | I15: 5073743 | J15: TRITECNO SA DE CV | K15: N90 | L15: (AP) NAFIN 90 Dias | M15: 10133812 | N15: GRAVA TRITURADA GRANITO 20 MM - 3/4" | O15: D853 | P15: MX-CED. MEXICALI | Q15: 20190612 | R15: 20281231 | S15: 20190612 | T15: 20241231 | U15: 152.01 | V15: MXN | W15: M3 | X15: 0 | Y15: MXN | Z15: M3 | AC15: 56103637 | AD15: 6622431540 | AE15: 1 | AF15: ENTREGADO | AG15: 1.445 | AH15: M3 | AI15: X | AJ15: 4 | AK15: V1 | AL15: 20230920 | AM15: D853-900005983-10133812
A16: 900007188D85310213459 | B16: 4600050169-50 | C16: 4600050169 | D16: 50 | E16: MXPO | F16: MXL | G16: 900007188 | H16: TP-FERNANDO WOOLFOLK | I16: 5081080 | J16: WOOLFOLK CARBALLO FERNANDO | K16: N90 | L16: (AP) NAFIN 90 Dias | M16: 10213459 | N16: POLVO DE TRITURACION GRANITO | O16: D853 | P16: MX-CED. MEXICALI | Q16: 20210615 | R16: 20271231 | S16: 20220720 | T16: 20271231 | U16: 95 | V16: MXN | W16: M3 | X16: 0 | Y16: MXN | Z16: M3 | AC16: 56103638 | AD16: 6622431540 | AE16: 1 | AF16: ENTREGADO | AG16: 1.418 | AH16: M3 | AI16: X | AJ16: 4 | AK16: V1 | AL16: 20260127 | AM16: D853-900007188-10213459
A17: 900004527D85310065403 | B17: 4600033292-30 | C17: 4600033292 | D17: 30 | E17: MXPO | F17: MXL | G17: 900004527 | H17: TP- GUSA | I17: 5002503 | J17: CONSTRUCTORA GUSA SA DE CV | K17: Z03 | L17: (AP) 15 Dias | M17: 10065403 | N17: GRAVA TRITURADA GRANITO 40 MM - 1 1/2" | O17: D853 | P17: MX-CED. MEXICALI | Q17: 20160301 | R17: 20281231 | S17: 20160901 | T17: 20241231 | U17: 143.52 | V17: MXN | W17: M3 | X17: 0 | Y17: MXN | Z17: M3 | AC17: 56103637 | AD17: 6622431540 | AE17: 2 | AF17: RECOGIDO | AG17: 1.445 | AH17: M3 | AI17: X | AJ17: 4 | AK17: V1 | AL17: 20230920 | AM17: D853-900004527-10065403
... A19: 900007188D85310000166 | B19: 4600050169-70 | C19: 4600050169 | D19: 70 | E19: MXPO | F19: MXL | G19: 900007188 | H19: TP-FERNANDO WOOLFOLK | I19: 5081080 | J19: WOOLFOLK CARBALLO FERNANDO | K19: N90 | L19: (AP) NAFIN 90 Dias | M19: 10000166 | N19: Arena Clasificada Río Malla 4 | O19: D853 | P19: MX-CED. MEXICALI | Q19: 20210615 | R19: 20271231 | S19: 20240806 | T19: 20291231 | U19: 100 | V19: MXN | W19: M3 | X19: 0 | Y19: MXN | Z19: M3 | AC19: 56103638 | AD19: 6622431540 | AE19: 1 | AF19: ENTREGADO | AG19: 1.57 | AH19: M3 | AI19: X | AJ19: 4 | AK19: V1 | AL19: 20260127 | AM19: D853-900007188-10000166
A20: 900005992D8536659927110147091 | B20: 4600044220-10 | C20: 4600044220 | D20: 10 | E20: MXPO | F20: MXL | G20: 900005992 | H20: SF TP- ED MABUSA | I20: 5071161 | J20: BUSTAMANTE LOPEZ MARIA ANGELICA | K20: N90 | L20: (AP) NAFIN 90 Dias | M20: 10147091 | N20: TUCURUGUAY CLASIFICADO TIERRA | O20: D853 | P20: MX-CED. MEXICALI | Q20: 20190306 | R20: 20241231 | S20: 20190306 | T20: 20241231 | U20: 555 | V20: MXN | W20: M3 | X20: 270 | Y20: MXN | Z20: M3 | AA20: 66599271 | AB20: PE SAN MATIAS | AC20: 56103638 | AD20: 6622431540 | AE20: 4 | AF20: ENTREGA DIRECTA | AG20: 1.4 | AH20: M3 | AI20: X | AJ20: 4 | AK20: V1 | AL20: 20230920 | AM20: D853-900005992-66599271-10147091-4
A21: 900005378D8536645931410147091 | B21: 4600039737-10 | C21: 4600039737 | D21: 10 | E21: MXPO | F21: MXL | G21: 900005378 | H21: TP-ED GUSA MEXICALI | I21: 5002503 | J21: CONSTRUCTORA GUSA SA DE CV | K21: Z03 | L21: (AP) 15 Dias | M21: 10147091 | N21: TUCURUGUAY CLASIFICADO TIERRA | O21: D853 | P21: MX-CED. MEXICALI | Q21: 20170913 | R21: 20241231 | S21: 20170913 | T21: 20241231 | U21: 97 | V21: MXN | W21: M3 | X21: 30 | Y21: MXN | Z21: M3 | AA21: 66459314 | AC21: 56103638 | AD21: 6622431540 | AE21: 4 | AF21: ENTREGA DIRECTA | AG21: 1.4 | AH21: M3 | AI21: X | AJ21: 4 | AK21: V4 | AL21: 20230920 | AM21: D853-900005378-66459314-10147091-4
A22: 900005992D8536687949310139786 | B22: 4600044220-80 | C22: 4600044220 | D22: 80 | E22: MXPO | F22: MXL | G22: 900005992 | H22: SF TP- ED MABUSA | I22: 5071161 | J22: BUSTAMANTE LOPEZ MARIA ANGELICA | K22: N90 | L22: (AP) NAFIN 90 Dias | M22: 10139786 | N22: ARENA CLASIFICADA RÍO MALLA 4 | O22: D853 | P22: MX-CED. MEXICALI | Q22: 20190306 | R22: 20241231 | S22: 20200702 | T22: 20291231 | U22: 389 | V22: MXN | W22: M3 | X22: 299 | Y22: MXN | Z22: M3 | AA22: 66879493 | AB22: ASTEC PLANTA NICOYA | AC22: 56103638 | AD22: 6622431540 | AE22: 4 | AF22: ENTREGA DIRECTA | AG22: 1.535 | AH22: M3 | AI22: X | AJ22: 4 | AK22: V4 | AL22: 20230920 | AM22: D853-900005992-66879493-10139786-4
A23: 900005242D8536566053910148458 | B23: 4600038144-110 | C23: 4600038144 | D23: 110 | E23: MXPO | F23: MXL | G23: 900005242 | H23: SF TP-ED- SEXTIN MEXICALI | I23: 5042038 | J23: CONSTRUCTORA SEXTIN SA DE CV | K23: N120 | L23: (AP) NAFIN 120 Dias | M23: 10148458 | N23: GRAVA TRITURADA GRANITO 10 MM - 3/8" | O23: D853 | P23: MX-CED. MEXICALI | Q23: 20170530 | R23: 20241231 | S23: 20180301 | T23: 20241231 | U23: 331 | V23: MXN | W23: M3 | X23: 134 | Y23: MXN | Z23: M3 | AA23: 65660539 | AB23: OBR-AGR MAKRO-RUMOROSA (CAMT) | AC23: 56103637 | AD23: 6622431540 | AE23: 4 | AF23: ENTREGA DIRECTA | AG23: 1.486 | AH23: M3 | AI23: X | AJ23: 4 | AK23: V1 | AL23: 20230920 | AM23: D853-900005242-65660539-10148458-4
A24: 900002329D8536690576610140391 | B24: 4600028608-40 | C24: 4600028608 | D24: 40 | E24: MXPO | F24: M02 | G24: 900002329 | H24: SF TP-ED- ASFALTOS TECNICOS | I24: 5039266 | J24: ASFALTOS TECNICOS DE BAJA SA DE CV | K24: Z03 | L24: (AP) 15 Dias | M24: 10140391 | N24: ARENA CLASIFICADA RÍO MALLA 4 LAVADO | O24: D853 | P24: MX-CED. MEXICALI | Q24: 20141203 | R24: 20291231 | S24: 20201014 | T24: 20291231 | U24: 253 | V24: MXN | W24: M3 | X24: 153 | Y24: MXN | Z24: M3 | AA24: 66905766 | AB24: CONCRETOS HIGUERA | AC24: 56103638 | AD24: 6622431540 | AE24: 4 | AF24: ENTREGA DIRECTA | AG24: 1.531 | AH24: M3 | AI24: X | AJ24: 4 | AK24: V4 | AL24: 20230920 | AM24: D853-900002329-66905766-10140391-4
A25: 900005242D8536645785910148458 | B25: 4600038144-70 | C25: 4600038144 | D25: 70 | E25: MXPO | F25: MXL | G25: 900005242 | H25: SF TP-ED- SEXTIN MEXICALI | I25: 5042038 | J25: CONSTRUCTORA SEXTIN SA DE CV | K25: N120 | L25: (AP) NAFIN 120 Dias | M25: 10148458 | N25: GRAVA TRITURADA GRANITO 10 MM - 3/8" | O25: D853 | P25: MX-CED. MEXICALI | Q25: 20170530 | R25: 20241231 | S25: 20180312 | T25: 20241231 | U25: 331 | V25: MXN | W25: M3 | X25: 134 | Y25: MXN | Z25: M3 | AA25: 66457859 | AB25: TRITUASFALTOS TECATE-RUMOROSA (RFS) | AC25: 56103637 | AD25: 6622431540 | AE25: 4 | AF25: ENTREGA DIRECTA | AG25: 1.486 | AH25: M3 | AI25: X | AJ25: 4 | AK25: V1 | AL25: 20230920 | AM25: D853-900005242-66457859-10148458-4
A26: 900005992D8536665114010139786 | B26: 4600044220-70 | C26: 4600044220 | D26: 70 | E26: MXPO | F26: MXL | G26: 900005992 | H26: SF TP- ED MABUSA | I26: 5071161 | J26: BUSTAMANTE LOPEZ MARIA ANGELICA | K26: N90 | L26: (AP) NAFIN 90 Dias | M26: 10139786 | N26: ARENA CLASIFICADA RÍO MALLA 4 | O26: D853 | P26: MX-CED. MEXICALI | Q26: 20190306 | R26: 20241231 | S26: 20190306 | T26: 20241231 | U26: 339 | V26: MXN | W26: M3 | X26: 239 | Y26: MXN | Z26: M3 | AA26: 66651140 | AB26: ASTEC MXLI SILO 1 EJ. PUEBLA | AC26: 56103638 | AD26: 6622431540 | AE26: 4 | AF26: ENTREGA DIRECTA | AG26: 1.535 | AH26: M3 | AI26: X | AJ26: 4 | AK26: V1 | AL26: 20230920 | AM26: D853-900005992-66651140-10139786-4
A27: 900005242D8536500097110139786 | B27: 4600038144-130 | C27: 4600038144 | D27: 130 | E27: MXPO | F27: MXL | G27: 900005242 | H27: SF TP-ED- SEXTIN MEXICALI | I27: 5042038 | J27: CONSTRUCTORA SEXTIN SA DE CV | K27: N120 | L27: (AP) NAFIN 120 Dias | M27: 10139786 | N27: ARENA CLASIFICADA RÍO MALLA 4 | O27: D853 | P27: MX-CED. MEXICALI | Q27: 20170530 | R27: 20241231 | S27: 20180501 | T27: 20241231 | U27: 150 | V27: MXN | W27: M3 | X27: 97.2 | Y27: MXN | Z27: M3 | AA27: 65000971 | AB27: (P) BLOQUERA MODERNA, S.A. DE C.V.. | AC27: 56103638 | AD27: 6622431540 | AE27: 4 | AF27: ENTREGA DIRECTA | AG27: 1.535 | AH27: M3 | AI27: X | AJ27: 4 | AK27: V1 | AL27: 20230920 | AM27: D853-900005242-65000971-10139786-4
A28: 900005242D8536566053910133053 | B28: 4600038144-90 | C28: 4600038144 | D28: 90 | E28: MXPO | F28: MXL | G28: 900005242 | H28: SF TP-ED- SEXTIN MEXICALI | I28: 5042038 | J28: CONSTRUCTORA SEXTIN SA DE CV | K28: N120 | L28: (AP) NAFIN 120 Dias | M28: 10133053 | N28: GRAVA TRITURADA GRANITO 20 MM - 3/4" | O28: D853 | P28: MX-CED. MEXICALI | Q28: 20170530 | R28: 20241231 | S28: 20180301 | T28: 20241231 | U28: 315 | V28: MXN | W28: M3 | X28: 134.7 | Y28: MXN | Z28: M3 | AA28: 65660539 | AB28: OBR-AGR MAKRO-RUMOROSA (CAMT) | AC28: 56103637 | AD28: 6622431540 | AE28: 4 | AF28: ENTREGA DIRECTA | AG28: 1.44 | AH28: M3 | AI28: X | AJ28: 4 | AK28: V1 | AL28: 20230920 | AM28: D853-900005242-65660539-10133053-4
A29: 900005242D8536566053910065403 | B29: 4600038144-100 | C29: 4600038144 | D29: 100 | E29: MXPO | F29: MXL | G29: 900005242 | H29: SF TP-ED- SEXTIN MEXICALI | I29: 5042038 | J29: CONSTRUCTORA SEXTIN SA DE CV | K29: N120 | L29: (AP) NAFIN 120 Dias | M29: 10065403 | N29: GRAVA TRITURADA GRANITO 40 MM - 1 1/2" | O29: D853 | P29: MX-CED. MEXICALI | Q29: 20170530 | R29: 20241231 | S29: 20180301 | T29: 20241231 | U29: 315 | V29: MXN | W29: M3 | X29: 135.17 | Y29: MXN | Z29: M3 | AA29: 65660539 | AB29: OBR-AGR MAKRO-RUMOROSA (CAMT) | AC29: 56103637 | AD29: 6622431540 | AE29: 4 | AF29: ENTREGA DIRECTA | AG29: 1.445 | AH29: M3 | AI29: X | AJ29: 4 | AK29: V1 | AL29: 20230920 | AM29: D853-900005242-65660539-10065403-4
A30: 900002329D8536680652910140391 | B30: 4600028608-50 | C30: 4600028608 | D30: 50 | E30: MXPO | F30: M02 | G30: 900002329 | H30: SF TP-ED- ASFALTOS TECNICOS | I30: 5039266 | J30: ASFALTOS TECNICOS DE BAJA SA DE CV | K30: Z03 | L30: (AP) 15 Dias | M30: 10140391 | N30: ARENA CLASIFICADA RÍO MALLA 4 LAVADO | O30: D853 | P30: MX-CED. MEXICALI | Q30: 20141203 | R30: 20291231 | S30: 20210526 | T30: 20261231 | U30: 237.5 | V30: MXN | W30: M3 | X30: 127.5 | Y30: MXN | Z30: M3 | AA30: 66806529 | AB30: PLANTA GLUQIM (2) | AC30: 56103638 | AD30: 6622431540 | AE30: 4 | AF30: ENTREGA DIRECTA | AG30: 1.531 | AH30: M3 | AI30: X | AJ30: 4 | AK30: V4 | AL30: 20230920 | AM30: D853-900002329-66806529-10140391-4
A31: 900005242D8536645785910133053 | B31: 4600038144-50 | C31: 4600038144 | D31: 50 | E31: MXPO | F31: MXL | G31: 900005242 | H31: SF TP-ED- SEXTIN MEXICALI | I31: 5042038 | J31: CONSTRUCTORA SEXTIN SA DE CV | K31: N120 | L31: (AP) NAFIN 120 Dias | M31: 10133053 | N31: GRAVA TRITURADA GRANITO 20 MM - 3/4" | O31: D853 | P31: MX-CED. MEXICALI | Q31: 20170530 | R31: 20241231 | S31: 20180301 | T31: 20241231 | U31: 315 | V31: MXN | W31: M3 | X31: 134.7 | Y31: MXN | Z31: M3 | AA31: 66457859 | AB31: TRITUASFALTOS TECATE-RUMOROSA (RFS) | AC31: 56103637 | AD31: 6622431540 | AE31: 4 | AF31: ENTREGA DIRECTA | AG31: 1.44 | AH31: M3 | AI31: X | AJ31: 4 | AK31: V1 | AL31: 20230920 | AM31: D853-900005242-66457859-10133053-4
A32: 900005242D8536645785910065403 | B32: 4600038144-60 | C32: 4600038144 | D32: 60 | E32: MXPO | F32: MXL | G32: 900005242 | H32: SF TP-ED- SEXTIN MEXICALI | I32: 5042038 | J32: CONSTRUCTORA SEXTIN SA DE CV | K32: N120 | L32: (AP) NAFIN 120 Dias | M32: 10065403 | N32: GRAVA TRITURADA GRANITO 40 MM - 1 1/2" | O32: D853 | P32: MX-CED. MEXICALI | Q32: 20170530 | R32: 20241231 | S32: 20180301 | T32: 20241231 | U32: 315 | V32: MXN | W32: M3 | X32: 135.17 | Y32: MXN | Z32: M3 | AA32: 66457859 | AB32: TRITUASFALTOS TECATE-RUMOROSA (RFS) | AC32: 56103637 | AD32: 6622431540 | AE32: 4 | AF32: ENTREGA DIRECTA | AG32: 1.445 | AH32: M3 | AI32: X | AJ32: 4 | AK32: V1 | AL32: 20230920 | AM32: D853-900005242-66457859-10065403-4
A33: 900005242D8536566053910144288 | B33: 4600038144-80 | C33: 4600038144 | D33: 80 | E33: MXPO | F33: MXL | G33: 900005242 | H33: SF TP-ED- SEXTIN MEXICALI | I33: 5042038 | J33: CONSTRUCTORA SEXTIN SA DE CV | K33: N120 | L33: (AP) NAFIN 120 Dias | M33: 10144288 | N33: ARENA CLASIFICADA RÍO MALLA 4 - LAVADO | O33: D853 | P33: MX-CED. MEXICALI | Q33: 20170530 | R33: 20241231 | S33: 20180301 | T33: 20241231 | U33: 258 | V33: MXN | W33: M3 | X33: 132.36 | Y33: MXN | Z33: M3 | AA33: 65660539 | AB33: OBR-AGR MAKRO-RUMOROSA (CAMT) | AC33: 56103638 | AD33: 6622431540 | AE33: 4 | AF33: ENTREGA DIRECTA | AG33: 1.415 | AH33: M3 | AI33: X | AJ33: 4 | AK33: V1 | AL33: 20230920 | AM33: D853-900005242-65660539-10144288-4
... A36: 900005242D8536680465810144288 | B36: 4600038144-150 | C36: 4600038144 | D36: 150 | E36: MXPO | F36: MXL | G36: 900005242 | H36: SF TP-ED- SEXTIN MEXICALI | I36: 5042038 | J36: CONSTRUCTORA SEXTIN SA DE CV | K36: N120 | L36: (AP) NAFIN 120 Dias | M36: 10144288 | N36: ARENA CLASIFICADA RÍO MALLA 4 - LAVADO | O36: D853 | P36: MX-CED. MEXICALI | Q36: 20170530 | R36: 20241231 | S36: 20190926 | T36: 20241231 | U36: 188 | V36: MXN | W36: M3 | X36: 62.36 | Y36: MXN | Z36: M3 | AA36: 66804658 | AB36: I8 Concretos Holtec | AC36: 56103638 | AD36: 6622431540 | AE36: 4 | AF36: ENTREGA DIRECTA | AG36: 1.415 | AH36: M3 | AI36: X | AJ36: 4 | AK36: V1 | AL36: 20230920 | AM36: D853-900005242-66804658-10144288-4
A37: 900003677D85310003344 | B37: 4600071475-30 | C37: 4600071475 | D37: 30 | E37: MXPO | F37: MXL | G37: 900003677 | H37: TP-GRUPO TAPACHULA | I37: 5002293 | J37: CONSTRUCTORA GRUPO TAPACHULA SA DE | K37: Z09 | L37: (AP) 90 Dias | M37: 10003344 | N37: Grava Clasificada Río 20 mm - 3/4" | O37: D853 | P37: MX-CED. MEXICALI | Q37: 20250721 | R37: 20301231 | S37: 20250721 | T37: 20301231 | U37: 327.34 | V37: MXN | W37: M3 | X37: 0 | Y37: MXN | Z37: M3 | AC37: 56103637 | AD37: 6622431540 | AE37: 1 | AF37: ENTREGADO | AG37: 1.376 | AH37: M3 | AI37: X | AJ37: 4 | AK37: V4 | AL37: 20250728 | AM37: D853-900003677-10003344
A38: 900003677D85310133051 | B38: 4600071475-10 | C38: 4600071475 | D38: 10 | E38: MXPO | F38: MXL | G38: 900003677 | H38: TP-GRUPO TAPACHULA | I38: 5002293 | J38: CONSTRUCTORA GRUPO TAPACHULA SA DE | K38: Z09 | L38: (AP) 90 Dias | M38: 10133051 | N38: GRAVA RIO 10MM-3/8" | O38: D853 | P38: MX-CED. MEXICALI | Q38: 20250721 | R38: 20301231 | S38: 20250721 | T38: 20301231 | U38: 697.77 | V38: MXN | W38: M3 | X38: 0 | Y38: MXN | Z38: M3 | AC38: 56103637 | AD38: 6622431540 | AE38: 1 | AF38: ENTREGADO | AG38: 1.48 | AH38: M3 | AI38: X | AJ38: 4 | AK38: V4 | AL38: 20250728 | AM38: D853-900003677-10133051
A39: 900003677D85310000645 | B39: 4600071475-20 | C39: 4600071475 | D39: 20 | E39: MXPO | F39: MXL | G39: 900003677 | H39: TP-GRUPO TAPACHULA | I39: 5002293 | J39: CONSTRUCTORA GRUPO TAPACHULA SA DE | K39: Z09 | L39: (AP) 90 Dias | M39: 10000645 | N39: Arena Clasificada Río Malla 4 | O39: D853 | P39: MX-CED. MEXICALI | Q39: 20250721 | R39: 20301231 | S39: 20250721 | T39: 20301231 | U39: 290.99 | V39: MXN | W39: M3 | X39: 0 | Y39: MXN | Z39: M3 | AC39: 56103638 | AD39: 6622431540 | AE39: 1 | AF39: ENTREGADO | AG39: 1.62 | AH39: M3 | AI39: X | AJ39: 4 | AK39: V4 | AL39: 20250728 | AM39: D853-900003677-10000645
A40: 900006962D85310048271 | B40: 4600048632-10 | C40: 4600048632 | D40: 10 | E40: MXPO | F40: MXL | G40: 900006962 | H40: SF TP- ASFALTOS TECNICOS | I40: 5039266 | J40: ASFALTOS TECNICOS DE BAJA SA DE CV | K40: Z03 | L40: (AP) 15 Dias | M40: 10048271 | N40: Grava Triturada Granito 10 mm - 3/8" | O40: D853 | P40: MX-CED. MEXICALI | Q40: 20201207 | R40: 20291231 | S40: 20201207 | T40: 20291231 | U40: 188 | V40: MXN | W40: M3 | AC40: 56103637 | AD40: 6622431540 | AE40: 1 | AF40: ENTREGADO | AG40: 1.504 | AH40: M3 | AI40: X | AJ40: 4 | AK40: V4 | AL40: 20230920 | AM40: D853-900006962-10048271
A41: 900009025D8536732303210260652 | B41: 4600070533-80 | C41: 4600070533 | D41: 80 | E41: MXPO | F41: MXL | G41: 900009025 | H41: SF TP-ED FERNANDO WOOLFOLK | I41: 5081080 | J41: WOOLFOLK CARBALLO FERNANDO | K41: N90 | L41: (AP) NAFIN 90 Dias | M41: 10260652 | N41: ARENA CLASIFICADA RÍO #4 LAVADA | O41: D853 | P41: MX-CED. MEXICALI | Q41: 20241108 | R41: 20291231 | S41: 20250604 | T41: 20301231 | U41: 245 | V41: MXN | W41: M3 | X41: 125 | Y41: MXN | Z41: M3 | AA41: 67323032 | AB41: JL PLANTA MEXICALI | AC41: 56103638 | AD41: 6622431540 | AE41: 4 | AF41: ENTREGA DIRECTA | AG41: 1.461 | AH41: M3 | AI41: X | AJ41: 4 | AK41: V1 | AL41: 20260127 | AM41: D853-900009025-67323032-10260652-4
A42: 900009025D8536732303210133053 | B42: 4600070533-50 | C42: 4600070533 | D42: 50 | E42: MXPO | F42: MXL | G42: 900009025 | H42: SF TP-ED FERNANDO WOOLFOLK | I42: 5081080 | J42: WOOLFOLK CARBALLO FERNANDO | K42: N90 | L42: (AP) NAFIN 90 Dias | M42: 10133053 | N42: GRAVA TRITURADA GRANITO 20 MM - 3/4" | O42: D853 | P42: MX-CED. MEXICALI | Q42: 20241108 | R42: 20291231 | S42: 20250604 | T42: 20301231 | U42: 305 | V42: MXN | W42: M3 | X42: 125 | Y42: MXN | Z42: M3 | AA42: 67323032 | AB42: JL PLANTA MEXICALI | AC42: 56103637 | AD42: 6622431540 | AE42: 4 | AF42: ENTREGA DIRECTA | AG42: 1.44 | AH42: M3 | AI42: X | AJ42: 4 | AK42: V1 | AL42: 20260127 | AM42: D853-900009025-67323032-10133053-4
A43: 900007188D85310048387 | B43: 4600050169-100 | C43: 4600050169 | D43: 100 | E43: MXPO | F43: MXL | G43: 900007188 | H43: TP-FERNANDO WOOLFOLK | I43: 5081080 | J43: WOOLFOLK CARBALLO FERNANDO | K43: N90 | L43: (AP) NAFIN 90 Dias | M43: 10048387 | N43: Grava Triturada Granito 10 mm - 3/8" | O43: D853 | P43: MX-CED. MEXICALI | Q43: 20210615 | R43: 20271231 | S43: 20250604 | T43: 20301231 | U43: 210 | V43: MXN | W43: M3 | X43: 0 | Y43: MXN | Z43: M3 | AC43: 56103637 | AD43: 6622431867 | AE43: 1 | AF43: ENTREGADO | AG43: 1.43 | AH43: M3 | AI43: X | AJ43: 4 | AK43: V1 | AL43: 20260127 | AM43: D853-900007188-10048387
...
