Workbook

Sheet Base Cedis D822
N1: VENTA | Q1: COSTO
A2: CONCAT1 | B2: CONCAT2 | C2: No. SF | D2: Nombre SF | E2: Cedis | F2: Destino | G2: Condicion de Expedicion | H2: Nombre Destino | I2: No. de material | J2: Nombre de material | K2: PV | L2: Inicio de vigencia | M2: Fin de vigencia | N2: Importe MP | O2: Importe Flete | P2: UM Venta | Q2: Importe Costo | R2: UM Costo | S2: Validacion 1 | T2: Validacion 2
A3: =CONCATENATE(C3,E3,F3,I3) | B3: =CONCATENATE(C3,E3,I3) | C3: 900000036 | D3: =IFERROR(VLOOKUP(C3,TRAOPE!$G:$H,2,0),"") | E3: D822 | F3: 66844588 | G3: =IFERROR(VLOOKUP(A3,Flete!$A:$E,5,0),"") | H3: =IFERROR(VLOOKUP(F3,TRAOPE!$AA:$AB,2,0),"") | I3: 10000624 | J3: =IFERROR(VLOOKUP(I3,Materiales!$A:$H,8,0),"") | K3: =IFERROR(VLOOKUP(I3,Materiales!$A:$G,7,0),"") | L3: 20190426 | M3: 20250127 | N3: 50.03 | O3: =IFERROR(VLOOKUP(A3,Flete!$A:$J,10,0),"") | P3: M3 | Q3: =IFERROR(IFERROR(VLOOKUP(A3,TRAOPE!$A:$U,21,0),VLOOKUP(B3,TRAOPE!$A:$U,21,0)),"") | R3: =IFERROR(IFERROR(VLOOKUP(A3,TRAOPE!$A:$W,23,0),VLOOKUP(B3,TRAOPE!$A:$W,23,0)),"") | S3: =IF(AND(P3="TN",R3="TN"),N3+N(O3),IF(G3&""="1",N(K3)*N3,(N3+N(O3))*N(K3))) | T3: =IF(Q3="","",Q3-S3)
A4: =CONCATENATE(C4,E4,F4,I4) | B4: =CONCATENATE(C4,E4,I4) | C4: 900000036 | D4: =IFERROR(VLOOKUP(C4,TRAOPE!$G:$H,2,0),"") | E4: D822 | F4: 66844588 | G4: =IFERROR(VLOOKUP(A4,Flete!$A:$E,5,0),"") | H4: =IFERROR(VLOOKUP(F4,TRAOPE!$AA:$AB,2,0),"") | I4: 10000630 | J4: =IFERROR(VLOOKUP(I4,Materiales!$A:$H,8,0),"") | K4: =IFERROR(VLOOKUP(I4,Materiales!$A:$G,7,0),"") | L4: 20190426 | M4: 20250127 | N4: 75.99 | O4: =IFERROR(VLOOKUP(A4,Flete!$A:$J,10,0),"") | P4: M3 | Q4: =IFERROR(IFERROR(VLOOKUP(A4,TRAOPE!$A:$U,21,0),VLOOKUP(B4,TRAOPE!$A:$U,21,0)),"") | R4: =IFERROR(IFERROR(VLOOKUP(A4,TRAOPE!$A:$W,23,0),VLOOKUP(B4,TRAOPE!$A:$W,23,0)),"") | S4: =IF(AND(P4="TN",R4="TN"),N4+N(O4),IF(G4&""="1",N(K4)*N4,(N4+N(O4))*N(K4))) | T4: =IF(Q4="","",Q4-S4)
A5: =CONCATENATE(C5,E5,F5,I5) | B5: =CONCATENATE(C5,E5,I5) | C5: 900000036 | D5: =IFERROR(VLOOKUP(C5,TRAOPE!$G:$H,2,0),"") | E5: D822 | F5: 66844588 | G5: =IFERROR(VLOOKUP(A5,Flete!$A:$E,5,0),"") | H5: =IFERROR(VLOOKUP(F5,TRAOPE!$AA:$AB,2,0),"") | I5: 10000811 | J5: =IFERROR(VLOOKUP(I5,Materiales!$A:$H,8,0),"") | K5: =IFERROR(VLOOKUP(I5,Materiales!$A:$G,7,0),"") | L5: 20190426 | M5: 20250127 | N5: 54.43 | O5: =IFERROR(VLOOKUP(A5,Flete!$A:$J,10,0),"") | P5: M3 | Q5: =IFERROR(IFERROR(VLOOKUP(A5,TRAOPE!$A:$U,21,0),VLOOKUP(B5,TRAOPE!$A:$U,21,0)),"") | R5: =IFERROR(IFERROR(VLOOKUP(A5,TRAOPE!$A:$W,23,0),VLOOKUP(B5,TRAOPE!$A:$W,23,0)),"") | S5: =IF(AND(P5="TN",R5="TN"),N5+N(O5),IF(G5&""="1",N(K5)*N5,(N5+N(O5))*N(K5))) | T5: =IF(Q5="","",Q5-S5)
A6: =CONCATENATE(C6,E6,F6,I6) | B6: =CONCATENATE(C6,E6,I6) | C6: 900000036 | D6: =IFERROR(VLOOKUP(C6,TRAOPE!$G:$H,2,0),"") | E6: D822 | F6: 66844588 | G6: =IFERROR(VLOOKUP(A6,Flete!$A:$E,5,0),"") | H6: =IFERROR(VLOOKUP(F6,TRAOPE!$AA:$AB,2,0),"") | I6: 10171624 | J6: =IFERROR(VLOOKUP(I6,Materiales!$A:$H,8,0),"") | K6: =IFERROR(VLOOKUP(I6,Materiales!$A:$G,7,0),"") | L6: 20190426 | M6: 20250127 | N6: 56.97 | O6: =IFERROR(VLOOKUP(A6,Flete!$A:$J,10,0),"") | P6: M3 | Q6: =IFERROR(IFERROR(VLOOKUP(A6,TRAOPE!$A:$U,21,0),VLOOKUP(B6,TRAOPE!$A:$U,21,0)),"") | R6: =IFERROR(IFERROR(VLOOKUP(A6,TRAOPE!$A:$W,23,0),VLOOKUP(B6,TRAOPE!$A:$W,23,0)),"") | S6: =IF(AND(P6="TN",R6="TN"),N6+N(O6),IF(G6&""="1",N(K6)*N6,(N6+N(O6))*N(K6))) | T6: =IF(Q6="","",Q6-S6)
A7: =CONCATENATE(C7,E7,F7,I7) | B7: =CONCATENATE(C7,E7,I7) | C7: 900005451 | D7: =IFERROR(VLOOKUP(C7,TRAOPE!$G:$H,2,0),"") | E7: D822 | F7: 65003945 | G7: =IFERROR(VLOOKUP(A7,Flete!$A:$E,5,0),"") | H7: =IFERROR(VLOOKUP(F7,TRAOPE!$AA:$AB,2,0),"") | I7: 10151420 | J7: =IFERROR(VLOOKUP(I7,Materiales!$A:$H,8,0),"") | K7: =IFERROR(VLOOKUP(I7,Materiales!$A:$G,7,0),"") | L7: 20190426 | M7: 20250127 | N7: 52000 | O7: =IFERROR(VLOOKUP(A7,Flete!$A:$J,10,0),"") | P7: TN | Q7: =IFERROR(IFERROR(VLOOKUP(A7,TRAOPE!$A:$U,21,0),VLOOKUP(B7,TRAOPE!$A:$U,21,0)),"") | R7: =IFERROR(IFERROR(VLOOKUP(A7,TRAOPE!$A:$W,23,0),VLOOKUP(B7,TRAOPE!$A:$W,23,0)),"") | S7: =IF(AND(P7="TN",R7="TN"),N7+N(O7),IF(G7&""="1",N(K7)*N7,(N7+N(O7))*N(K7))) | T7: =IF(Q7="","",Q7-S7)
A8: =CONCATENATE(C8,E8,F8,I8) | B8: =CONCATENATE(C8,E8,I8) | C8: 900005517 | D8: =IFERROR(VLOOKUP(C8,TRAOPE!$G:$H,2,0),"") | E8: D822 | F8: 65908426 | G8: =IFERROR(VLOOKUP(A8,Flete!$A:$E,5,0),"") | H8: =IFERROR(VLOOKUP(F8,TRAOPE!$AA:$AB,2,0),"") | I8: 10149996 | J8: =IFERROR(VLOOKUP(I8,Materiales!$A:$H,8,0),"") | K8: =IFERROR(VLOOKUP(I8,Materiales!$A:$G,7,0),"") | L8: 20190426 | M8: 20250127 | N8: 52000 | O8: =IFERROR(VLOOKUP(A8,Flete!$A:$J,10,0),"") | P8: TN | Q8: =IFERROR(IFERROR(VLOOKUP(A8,TRAOPE!$A:$U,21,0),VLOOKUP(B8,TRAOPE!$A:$U,21,0)),"") | R8: =IFERROR(IFERROR(VLOOKUP(A8,TRAOPE!$A:$W,23,0),VLOOKUP(B8,TRAOPE!$A:$W,23,0)),"") | S8: =IF(AND(P8="TN",R8="TN"),N8+N(O8),IF(G8&""="1",N(K8)*N8,(N8+N(O8))*N(K8))) | T8: =IF(Q8="","",Q8-S8)
A9: =CONCATENATE(C9,E9,F9,I9) | B9: =CONCATENATE(C9,E9,I9) | C9: 900005544 | D9: =IFERROR(VLOOKUP(C9,TRAOPE!$G:$H,2,0),"") | E9: D822 | F9: 65908426 | G9: =IFERROR(VLOOKUP(A9,Flete!$A:$E,5,0),"") | H9: =IFERROR(VLOOKUP(F9,TRAOPE!$AA:$AB,2,0),"") | I9: 10149996 | J9: =IFERROR(VLOOKUP(I9,Materiales!$A:$H,8,0),"") | K9: =IFERROR(VLOOKUP(I9,Materiales!$A:$G,7,0),"") | L9: 20190426 | M9: 20250127 | N9: 2600 | O9: =IFERROR(VLOOKUP(A9,Flete!$A:$J,10,0),"") | P9: TN | Q9: =IFERROR(IFERROR(VLOOKUP(A9,TRAOPE!$A:$U,21,0),VLOOKUP(B9,TRAOPE!$A:$U,21,0)),"") | R9: =IFERROR(IFERROR(VLOOKUP(A9,TRAOPE!$A:$W,23,0),VLOOKUP(B9,TRAOPE!$A:$W,23,0)),"") | S9: =IF(AND(P9="TN",R9="TN"),N9+N(O9),IF(G9&""="1",N(K9)*N9,(N9+N(O9))*N(K9))) | T9: =IF(Q9="","",Q9-S9)
A10: =CONCATENATE(C10,E10,F10,I10) | B10: =CONCATENATE(C10,E10,I10) | C10: 900007368 | D10: =IFERROR(VLOOKUP(C10,TRAOPE!$G:$H,2,0),"") | E10: D822 | F10: 66542531 | G10: =IFERROR(VLOOKUP(A10,Flete!$A:$E,5,0),"") | H10: =IFERROR(VLOOKUP(F10,TRAOPE!$AA:$AB,2,0),"") | I10: 10000430 | J10: =IFERROR(VLOOKUP(I10,Materiales!$A:$H,8,0),"") | K10: =IFERROR(VLOOKUP(I10,Materiales!$A:$G,7,0),"") | L10: 20190426 | M10: 20250127 | N10: 145 | O10: =IFERROR(VLOOKUP(A10,Flete!$A:$J,10,0),"") | P10: M3 | Q10: =IFERROR(IFERROR(VLOOKUP(A10,TRAOPE!$A:$U,21,0),VLOOKUP(B10,TRAOPE!$A:$U,21,0)),"") | R10: =IFERROR(IFERROR(VLOOKUP(A10,TRAOPE!$A:$W,23,0),VLOOKUP(B10,TRAOPE!$A:$W,23,0)),"") | S10: =IF(AND(P10="TN",R10="TN"),N10+N(O10),IF(G10&""="1",N(K10)*N10,(N10+N(O10))*N(K10))) | T10: =IF(Q10="","",Q10-S10)
A11: =CONCATENATE(C11,E11,F11,I11) | B11: =CONCATENATE(C11,E11,I11) | C11: 900007628 | D11: =IFERROR(VLOOKUP(C11,TRAOPE!$G:$H,2,0),"") | E11: D822 | F11: 66793832 | G11: =IFERROR(VLOOKUP(A11,Flete!$A:$E,5,0),"") | H11: =IFERROR(VLOOKUP(F11,TRAOPE!$AA:$AB,2,0),"") | I11: 10213469 | J11: =IFERROR(VLOOKUP(I11,Materiales!$A:$H,8,0),"") | K11: =IFERROR(VLOOKUP(I11,Materiales!$A:$G,7,0),"") | L11: 20190426 | M11: 20250127 | N11: 110 | O11: =IFERROR(VLOOKUP(A11,Flete!$A:$J,10,0),"") | P11: M3 | Q11: =IFERROR(IFERROR(VLOOKUP(A11,TRAOPE!$A:$U,21,0),VLOOKUP(B11,TRAOPE!$A:$U,21,0)),"") | R11: =IFERROR(IFERROR(VLOOKUP(A11,TRAOPE!$A:$W,23,0),VLOOKUP(B11,TRAOPE!$A:$W,23,0)),"") | S11: =IF(AND(P11="TN",R11="TN"),N11+N(O11),IF(G11&""="1",N(K11)*N11,(N11+N(O11))*N(K11))) | T11: =IF(Q11="","",Q11-S11)
A12: =CONCATENATE(C12,E12,F12,I12) | B12: =CONCATENATE(C12,E12,I12) | C12: 900007628 | D12: =IFERROR(VLOOKUP(C12,TRAOPE!$G:$H,2,0),"") | E12: D822 | F12: 67158638 | G12: =IFERROR(VLOOKUP(A12,Flete!$A:$E,5,0),"") | H12: =IFERROR(VLOOKUP(F12,TRAOPE!$AA:$AB,2,0),"") | I12: 10213469 | J12: =IFERROR(VLOOKUP(I12,Materiales!$A:$H,8,0),"") | K12: =IFERROR(VLOOKUP(I12,Materiales!$A:$G,7,0),"") | L12: 20190426 | M12: 20250127 | N12: 124 | O12: =IFERROR(VLOOKUP(A12,Flete!$A:$J,10,0),"") | P12: M3 | Q12: =IFERROR(IFERROR(VLOOKUP(A12,TRAOPE!$A:$U,21,0),VLOOKUP(B12,TRAOPE!$A:$U,21,0)),"") | R12: =IFERROR(IFERROR(VLOOKUP(A12,TRAOPE!$A:$W,23,0),VLOOKUP(B12,TRAOPE!$A:$W,23,0)),"") | S12: =IF(AND(P12="TN",R12="TN"),N12+N(O12),IF(G12&""="1",N(K12)*N12,(N12+N(O12))*N(K12))) | T12: =IF(Q12="","",Q12-S12)
A13: =CONCATENATE(C13,E13,F13,I13) | B13: =CONCATENATE(C13,E13,I13) | C13: 900007628 | D13: =IFERROR(VLOOKUP(C13,TRAOPE!$G:$H,2,0),"") | E13: D822 | F13: 67158638 | G13: =IFERROR(VLOOKUP(A13,Flete!$A:$E,5,0),"") | H13: =IFERROR(VLOOKUP(F13,TRAOPE!$AA:$AB,2,0),"") | I13: 10213931 | J13: =IFERROR(VLOOKUP(I13,Materiales!$A:$H,8,0),"") | K13: =IFERROR(VLOOKUP(I13,Materiales!$A:$G,7,0),"") | L13: 20190426 | M13: 20250127 | N13: 364 | O13: =IFERROR(VLOOKUP(A13,Flete!$A:$J,10,0),"") | P13: M3 | Q13: =IFERROR(IFERROR(VLOOKUP(A13,TRAOPE!$A:$U,21,0),VLOOKUP(B13,TRAOPE!$A:$U,21,0)),"") | R13: =IFERROR(IFERROR(VLOOKUP(A13,TRAOPE!$A:$W,23,0),VLOOKUP(B13,TRAOPE!$A:$W,23,0)),"") | S13: =IF(AND(P13="TN",R13="TN"),N13+N(O13),IF(G13&""="1",N(K13)*N13,(N13+N(O13))*N(K13))) | T13: =IF(Q13="","",Q13-S13)
A14: =CONCATENATE(C14,E14,F14,I14) | B14: =CONCATENATE(C14,E14,I14) | C14: 900007628 | D14: =IFERROR(VLOOKUP(C14,TRAOPE!$G:$H,2,0),"") | E14: D822 | F14: 67169669 | G14: =IFERROR(VLOOKUP(A14,Flete!$A:$E,5,0),"") | H14: =IFERROR(VLOOKUP(F14,TRAOPE!$AA:$AB,2,0),"") | I14: 10213469 | J14: =IFERROR(VLOOKUP(I14,Materiales!$A:$H,8,0),"") | K14: =IFERROR(VLOOKUP(I14,Materiales!$A:$G,7,0),"") | L14: 20240619 | M14: 20251031 | N14: 120 | O14: =IFERROR(VLOOKUP(A14,Flete!$A:$J,10,0),"") | P14: M3 | Q14: =IFERROR(IFERROR(VLOOKUP(A14,TRAOPE!$A:$U,21,0),VLOOKUP(B14,TRAOPE!$A:$U,21,0)),"") | R14: =IFERROR(IFERROR(VLOOKUP(A14,TRAOPE!$A:$W,23,0),VLOOKUP(B14,TRAOPE!$A:$W,23,0)),"") | S14: =IF(AND(P14="TN",R14="TN"),N14+N(O14),IF(G14&""="1",N(K14)*N14,(N14+N(O14))*N(K14))) | T14: =IF(Q14="","",Q14-S14)
... A28: =CONCATENATE(C28,E28,F28,I28) | B28: =CONCATENATE(C28,E28,I28) | C28: 900008720 | D28: =IFERROR(VLOOKUP(C28,TRAOPE!$G:$H,2,0),"") | E28: D822 | F28: 66793832 | G28: =IFERROR(VLOOKUP(A28,Flete!$A:$E,5,0),"") | H28: =IFERROR(VLOOKUP(F28,TRAOPE!$AA:$AB,2,0),"") | I28: 10213469 | J28: =IFERROR(VLOOKUP(I28,Materiales!$A:$H,8,0),"") | K28: =IFERROR(VLOOKUP(I28,Materiales!$A:$G,7,0),"") | L28: 20250505 | M28: 20250507 | N28: 180 | O28: =IFERROR(VLOOKUP(A28,Flete!$A:$J,10,0),"") | P28: M3 | Q28: =IFERROR(IFERROR(VLOOKUP(A28,TRAOPE!$A:$U,21,0),VLOOKUP(B28,TRAOPE!$A:$U,21,0)),"") | R28: =IFERROR(IFERROR(VLOOKUP(A28,TRAOPE!$A:$W,23,0),VLOOKUP(B28,TRAOPE!$A:$W,23,0)),"") | S28: =IF(AND(P28="TN",R28="TN"),N28+N(O28),IF(G28&""="1",N(K28)*N28,(N28+N(O28))*N(K28))) | T28: =IF(Q28="","",Q28-S28)

Sheet MP
A1: No. SF | B1: Cedis | C1: Destino | D1: No. Material | E1: Nombre Material | F1: Importe MP | G1: Moneda | H1: Cantidad | I1: UM | J1: C | K1: Inicio Vigencia | L1: Fin Vigencia
A2: 900000036 | B2: D822 | C2: 66844588 | D2: 10000624 | F2: 50.03 | I2: M3 | K2: 20190426 | L2: 20250127
A3: 900000036 | B3: D822 | C3: 66844588 | D3: 10000630 | F3: 75.99 | I3: M3 | K3: 20190426 | L3: 20250127
A4: 900000036 | B4: D822 | C4: 66844588 | D4: 10000811 | F4: 54.43 | I4: M3 | K4: 20190426 | L4: 20250127
A5: 900000036 | B5: D822 | C5: 66844588 | D5: 10171624 | F5: 56.97 | I5: M3 | K5: 20190426 | L5: 20250127
A6: 900005451 | B6: D822 | C6: 65003945 | D6: 10151420 | F6: 52000 | I6: TN | K6: 20190426 | L6: 20250127
A7: 900005517 | B7: D822 | C7: 65908426 | D7: 10149996 | F7: 52000 | I7: TN | K7: 20190426 | L7: 20250127
A8: 900005544 | B8: D822 | C8: 65908426 | D8: 10149996 | F8: 2600 | I8: TN | K8: 20190426 | L8: 20250127
A9: 900007368 | B9: D822 | C9: 66542531 | D9: 10000430 | F9: 145 | I9: M3 | K9: 20190426 | L9: 20250127
A10: 900007628 | B10: D822 | C10: 66793832 | D10: 10213469 | F10: 110 | I10: M3 | K10: 20190426 | L10: 20250127
A11: 900007628 | B11: D822 | C11: 67158638 | D11: 10213469 | F11: 124 | I11: M3 | K11: 20190426 | L11: 20250127
A12: 900007628 | B12: D822 | C12: 67158638 | D12: 10213931 | F12: 364 | I12: M3 | K12: 20190426 | L12: 20250127
A13: 900007628 | B13: D822 | C13: 67169669 | D13: 10213469 | F13: 120 | I13: M3 | K13: 20240619 | L13: 20251031
... A27: 900008720 | B27: D822 | C27: 66793832 | D27: 10213469 | F27: 180 | I27: M3 | K27: 20250505 | L27: 20250507

Sheet Flete
A1: Concat1 | B1: No. SF | C1: Cedis | D1: Destino | E1: Cond. Exp. | F1: Material | H1: Nombre Material | J1: Importe Flete | K1: Moneda | L1: Cantidad | M1: UM | N1: C | P1: Inicio Vigencia | Q1: Fin Vigencia
A2: 900005330D8226571380810139741 | B2: 900005330 | C2: D822 | D2: 65713808 | E2: 2 | F2: 10139741 | J2: 0 | M2: TN | P2: 20190426 | Q2: 20250127
A3: 900007628D8226715863810213469 | B3: 900007628 | C3: D822 | D3: 67158638 | E3: 1 | F3: 10213469 | J3: 246 | M3: M3 | P3: 20190426 | Q3: 20250127
A4: 900007628D8226715863810213931 | B4: 900007628 | C4: D822 | D4: 67158638 | E4: 1 | F4: 10213931 | J4: 246 | M4: M3 | P4: 20190426 | Q4: 20250127
A5: 900008720D8226719855810213469 | B5: 900008720 | C5: D822 | D5: 67198558 | E5: 1 | F5: 10213469 | J5: 174.66 | M5: M3 | P5: 20230301 | Q5: 20251031
A6: 900008720D8226719855810237051 | B6: 900008720 | C6: D822 | D6: 67198558 | E6: 1 | F6: 10237051 | J6: 174.66 | M6: M3 | P6: 20230301 | Q6: 20251031
A7: 900009368D8226732317210237051 | B7: 900009368 | C7: D822 | D7: 67323172 | E7: 4 | F7: 10237051 | J7: 375 | M7: M3 | P7: 20251013 | Q7: 99991231
A8: 900009368D8226732317210237052 | B8: 900009368 | C8: D822 | D8: 67323172 | E8: 4 | F8: 10237052 | J8: 375 | M8: M3 | P8: 20251013 | Q8: 99991231

Sheet Materiales
A1: Material | B1: TpMt | C1: Denom | D1: UMA | E1: Contador | F1: UMB | G1: PV | H1: Nombre Material
A2: 10000001 | B2: ZFER | C2: 1000 | D2: M3 | E2: 1000 | F2: TN | G2: 1262 | H2: GRAVA ANDESITA 10 MM (3/8")
A3: 10000003 | B3: ZFER | C3: 1000 | D3: M3 | E3: 1000 | F3: TN | G3: 1443 | H3: GRAVA CALIZA 10 MM (3/8")
A4: 10000006 | B4: ZFER | C4: 1000 | D4: M3 | E4: 1000 | F4: TN | G4: 1490 | H4: GRAVA RIO 10 MM (3/8")
A5: 10000007 | B5: ZFER | C5: 1000 | D5: M3 | E5: 1000 | F5: TN | G5: 1488 | H5: GRAVA BASALTO 13 MM (1/2")
A6: 10000008 | B6: ZFER | C6: 1000 | D6: M3 | E6: 1000 | F6: TN | G6: 1358 | H6: GRAVA CALIZA 13 MM (1/2")
A7: 10000011 | B7: ZFER | C7: 1000 | D7: M3 | E7: 1000 | F7: TN | G7: 1323 | H7: GRAVA ANDESITA 20 MM (3/4")
A8: 10000013 | B8: ZFER | C8: 1000 | D8: M3 | E8: 1000 | F8: TN | G8: 1514 | H8: GRAVA BASALTO 20 MM (3/4")
A9: 10000014 | B9: ZFER | C9: 1000 | D9: M3 | E9: 1000 | F9: TN | G9: 1400 | H9: GRAVA CALIZA 20 MM (3/4")
A10: 10000015 | B10: ZFER | C10: 1000 | D10: M3 | E10: 1000 | F10: TN | G10: 1410 | H10: GRAVA GRANITO 20 MM (3/4")
A11: 10000017 | B11: ZFER | C11: 1000 | D11: M3 | E11: 1000 | F11: TN | G11: 1475 | H11: GRAVA RIOLITA 20 MM (3/4")
A12: 10000019 | B12: ZFER | C12: 1000 | D12: M3 | E12: 1000 | F12: TN | G12: 1515 | H12: GRAVA RIO 20 MM (3/4")
A13: 10000020 | B13: ZFER | C13: 1000 | D13: M3 | E13: 1 | F13: TN | G13: 1 | H13: GRAVA MAQUILA 40MM (1 1/2")
... A2291: 10268770 | B2291: ZFE3 | C2291: 1000 | D2291: M3 | E2291: 1000 | F2291: TN | G2291: 1240 | H2291: MP GRAVA TRIT CALIZA 40MM 1 1/2" - ESP
A2292: 10268901 | B2292: ZFE3 | C2292: 1000 | D2292: M3 | E2292: 1000 | G2292: 1560 | H2292: MP GRAVA ANDESITA GRIS 3/4" - CAPADA
A2293: 10267983 | C2293: 1000 | G2293: 1800 | H2293: ESCORIA ALTO HORNO 3/4
A2294: 10268996 | C2294: 1000 | G2294: 1329 | H2294: GRAVA TRITURADA CALIZA 40 MM - 11/2"
A2295: 10269072 | C2295: 1000 | G2295: 1700 | H2295: BASE HIDRÁULICA SCREEN
A2296: 10269225 | B2296: ZFE3 | C2296: 1000 | D2296: M3 | E2296: 1000 | G2296: 1289 | H2296: MP ARENA CALIZA LAVADA MALLA 4 - DELTA I
A2297: 10269245 | B2297: ZFE3 | C2297: 1000 | D2297: M3 | E2297: 1000 | G2297: 1410 | H2297: MP GRAVA TRITURADA CALIZA 3/8 - 10MM
A2298: 10269246 | B2298: ZFE3 | C2298: 1000 | D2298: M3 | E2298: 1000 | G2298: 1400 | H2298: MP GRAVA TRITURADA CALIZA 1 1/2 - 40MM
A2299: 10269247 | B2299: ZFE3 | C2299: 1000 | D2299: M3 | E2299: 1000 | G2299: 1560 | H2299: MP ARENA TRIT CALIZA M-4
A2300: 10270431 | B2300: ZFE3 | C2300: 1000 | D2300: M3 | E2300: 1000 | G2300: 1423 | H2300: MP GRAVA RIOLITA 13 MM - 1/2"
A2301: 10270898 | B2301: ZFE3 | C2301: 1000 | D2301: M3 | E2301: 1000 | G2301: 1551 | H2301: MP BASE H. TRIT. BASALTO 1 1/2" A FINOS
A2302: 10270911 | B2302: ZFE3 | C2302: 1000 | D2302: M3 | E2302: 1000 | G2302: 1360 | H2302: MP GRAVA TRIT. BASALTO 40 MM - 1 1/2"
A2303: 10270912 | B2303: ZFE3 | C2303: 1000 | D2303: M3 | E2303: 1000 | G2303: 1589 | H2303: MP ARENA TRIT. BASALTO MALLA 4
A2304: 10270913 | B2304: ZFE3 | C2304: 1000 | D2304: M3 | E2304: 1000 | G2304: 1395 | H2304: MP GRAVA TRIT. BASALTO 20 MM - 3/4
A2305: 10270914 | B2305: ZFE3 | C2305: 1000 | D2305: M3 | E2305: 1000 | G2305: 1623 | H2305: MP ARENA ANDESITA BC
A2306: 10270824 | B2306: M3 | C2306: 1000 | D2306: M3 | E2306: 10007640 | G2306: 1325 | H2306: MP ARENA TRITURADA CALIZA MALLA 5
A2307: 10270825 | B2307: M3 | C2307: 1000 | D2307: M3 | E2307: 10000003 | G2307: 1242 | H2307: MP GRAVA TRITURADA CALIZA 10MM (3/8”)
... A2319: 10272527 | B2319: ZFE3 | C2319: 1000 | D2319: M3 | E2319: 1000 | G2319: 1620 | H2319: CNC - NO CLASIFICADO
A2320: 10000332 | C2320: 1000 | D2320: M3 | E2320: 1000 | G2320: 800 | H2320: Grava Triturada Pomez - Jal 20 mm - 3/4"
A2321: 10273001 | B2321: ZFE3 | C2321: 1000 | D2321: M3 | E2321: 1000 | G2321: 1688 | H2321: MP ARENA TRIT. BASALTO MALLA 4
A2322: 10273002 | B2322: ZFE3 | C2322: 1000 | D2322: M3 | E2322: 1000 | G2322: 1466 | H2322: MP GRAVA TRIT. BASALTO 20 MM - 3/4"
A2323: 10273351 | B2323: ZFE3 | C2323: 1000 | D2323: M3 | E2323: 1000 | G2323: 1612 | H2323: MP ARENA TRIT. CALIZA MALLA 4
A2324: 10273352 | B2324: ZFE3 | C2324: 1000 | D2324: M3 | E2324: 1000 | G2324: 1492 | H2324: MP GRAVA TRIT. CALIZA 20 MM - 3/4"
A2325: 10271724 | B2325: ZFE3 | C2325: 1000 | D2325: M3 | E2325: 1000 | G2325: 1900 | H2325: MP RESIDUO DE CONCRETO
A2326: 10000677 | C2326: 1000 | D2326: M3 | G2326: 1164 | H2326: Grava Triturada Caliza 20 mm - 3/4"
A2327: 10274190 | B2327: ZFE3 | C2327: 1000 | D2327: M3 | E2327: 1000 | G2327: 1800 | H2327: MP BASE HIDRAULICA ANDESITA 70-30
A2328: 10274601 | B2328: ZFE3 | C2328: 1000 | D2328: M3 | E2328: 1000 | G2328: 1447 | H2328: MP ARENA BASALTO N° 4
...

Sheet TRAOPE
A1: Concat1 | B1: Contrato_Pos | C1: Doc. Compras | D1: Pos | E1: Org.compras | F1: Grp-Compr. | G1: Ship From | H1: Nombre SF | I1: Proveedor | J1: Nombre Prov | K1: Cond. Pago | L1: Descr. Cond Pago | M1: Material | N1: Descripción | O1: Centro | P1: Descripción Centro | Q1: In.perído validez | R1: Fin perído validez | S1: Válido de | T1: Validez a | U1: Precio neto pedido | V1: Moneda | W1: UM Precio Pedido | X1: Importe Condición | Y1: Moneda KONP | Z1: UM Ctd Base | AA1: Destino | AB1: Nombre Destino | AC1: Cuenta de mayor | AD1: Centro de costo | AE1: Cond. Exp. | AF1: Descr. Cond. Exp. | AG1: Peso Vol. | AH1: UMB | AI1: Ind. Oblig. Conf. Ped. | AJ1: Ctrl-Conf. | AK1: IVA | AL1: Modif_Date | AM1: Ruta
A2: 900007901D82210213931 | B2: 4600069319-10 | C2: 4600069319 | D2: 10 | E2: MXPO | F2: MXL | G2: 900007901 | H2: SF TP - AGREGADOS Y TRITURADOS | I2: 5036740 | J2: AGREGADOS Y TRITURADOS DEL PACIFICO | K2: Z03 | L2: (AP) 15 Dias | M2: 10213931 | N2: GRAVA RIO 20 MM (3/4") | O2: D822 | P2: MX-CED. ACAPULCO | Q2: 20240402 | R2: 20291231 | S2: 20240402 | T2: 20291231 | U2: 350 | V2: MXN | W2: M3 | X2: 0 | Y2: MXN | Z2: M3 | AC2: 56103637 | AD2: 6622121540 | AE2: 1 | AF2: ENTREGADO | AG2: 1.462 | AH2: M3 | AI2: X | AJ2: 4 | AK2: V4 | AL2: 20240403 | AM2: D822-900007901-10213931
A3: 900009368D8226732317210237051 | B3: 4600071708-10 | C3: 4600071708 | D3: 10 | E3: MXPO | F3: MXL | G3: 900009368 | H3: SF TP-ED PIEDRA DURA PAROTILLAS | I3: 5087603 | J3: PAPAGAYO CONSTRUCCIONES Y MAQUINARI | K3: N30 | L3: (AP) NAFIN 30 Dias | M3: 10237051 | N3: GRAVA RIO 20 MM | O3: D822 | P3: MX-CED. ACAPULCO | Q3: 20251013 | R3: 20301231 | S3: 20251013 | T3: 20301231 | U3: 575 | V3: MXN | W3: M3 | X3: 375 | Y3: MXN | Z3: M3 | AA3: 67323172 | AB3: CEMSA Acapulco Concretos Manzanillo | AC3: 56103637 | AD3: 6622121540 | AE3: 4 | AF3: ENTREGA DIRECTA | AG3: 1.468 | AH3: M3 | AI3: X | AJ3: 4 | AK3: V4 | AL3: 20251021 | AM3: D822-900009368-67323172-10237051-4
A4: 900009368D8226732317210237052 | B4: 4600071708-20 | C4: 4600071708 | D4: 20 | E4: MXPO | F4: MXL | G4: 900009368 | H4: SF TP-ED PIEDRA DURA PAROTILLAS | I4: 5087603 | J4: PAPAGAYO CONSTRUCCIONES Y MAQUINARI | K4: N30 | L4: (AP) NAFIN 30 Dias | M4: 10237052 | N4: GRAVA RIO 40 MM | O4: D822 | P4: MX-CED. ACAPULCO | Q4: 20251013 | R4: 20301231 | S4: 20251013 | T4: 20301231 | U4: 575 | V4: MXN | W4: M3 | X4: 375 | Y4: MXN | Z4: M3 | AA4: 67323172 | AB4: CEMSA Acapulco Concretos Manzanillo | AC4: 56103637 | AD4: 6622121540 | AE4: 4 | AF4: ENTREGA DIRECTA | AG4: 1.584 | AH4: M3 | AI4: X | AJ4: 4 | AK4: V4 | AL4: 20251021 | AM4: D822-900009368-67323172-10237052-4
A5: 900008720D82210237051 | B5: 4600069057-10 | C5: 4600069057 | D5: 10 | E5: MXPO | F5: MXL | G5: 900008720 | H5: SF TP-PIEDRA DURA PAROTILLAS | I5: 5087603 | J5: PAPAGAYO CONSTRUCCIONES Y MAQUINARI | K5: N30 | L5: (AP) NAFIN 30 Dias | M5: 10237051 | N5: GRAVA RIO 20 MM | O5: D822 | P5: MX-CED. ACAPULCO | Q5: 20240202 | R5: 20291231 | S5: 20240202 | T5: 20291231 | U5: 280 | V5: MXN | W5: M3 | X5: 0 | Y5: MXN | Z5: M3 | AC5: 56103637 | AD5: 6622121540 | AE5: 1 | AF5: ENTREGADO | AG5: 1.468 | AH5: M3 | AI5: X | AJ5: 4 | AK5: V4 | AL5: 20240206 | AM5: D822-900008720-10237051
A6: 900000036D82210000630 | B6: 4600046620-20 | C6: 4600046620 | D6: 20 | E6: MXPO | F6: MXL | G6: 900000036 | H6: SF PAPAGAYO | I6: 5001941 | J6: PAPAGAYO LA SABANA SA DE CV | K6: Z03 | L6: (AP) 15 Dias | M6: 10000630 | N6: Grava Triturada Caliza 13 mm - 1/2" | O6: D822 | P6: MX-CED. ACAPULCO | Q6: 20200220 | R6: 20301231 | S6: 20200220 | T6: 20301231 | U6: 1 | V6: MXN | W6: M3 | AC6: 56103637 | AD6: 6622121540 | AE6: 1 | AF6: ENTREGADO | AG6: 1.4 | AH6: M3 | AI6: X | AJ6: 4 | AK6: V4 | AL6: 20230920 | AM6: D822-900000036-10000630
A7: 900000036D82210000811 | B7: 4600046620-30 | C7: 4600046620 | D7: 30 | E7: MXPO | F7: MXL | G7: 900000036 | H7: SF PAPAGAYO | I7: 5001941 | J7: PAPAGAYO LA SABANA SA DE CV | K7: Z03 | L7: (AP) 15 Dias | M7: 10000811 | N7: Grava Triturada Caliza 20 mm - 3/4" | O7: D822 | P7: MX-CED. ACAPULCO | Q7: 20200220 | R7: 20301231 | S7: 20200220 | T7: 20301231 | U7: 1 | V7: MXN | W7: M3 | AC7: 56103637 | AD7: 6622121540 | AE7: 1 | AF7: ENTREGADO | AG7: 1.447 | AH7: M3 | AI7: X | AJ7: 4 | AK7: V4 | AL7: 20230920 | AM7: D822-900000036-10000811
A8: 900000036D82210000624 | B8: 4600046620-10 | C8: 4600046620 | D8: 10 | E8: MXPO | F8: MXL | G8: 900000036 | H8: SF PAPAGAYO | I8: 5001941 | J8: PAPAGAYO LA SABANA SA DE CV | K8: Z03 | L8: (AP) 15 Dias | M8: 10000624 | N8: Grava Triturada Caliza 40 mm - 1 1/2" | O8: D822 | P8: MX-CED. ACAPULCO | Q8: 20200220 | R8: 20301231 | S8: 20200220 | T8: 20301231 | U8: 1 | V8: MXN | W8: M3 | AC8: 56103637 | AD8: 6622121540 | AG8: 1.45 | AH8: M3 | AI8: X | AJ8: 4 | AK8: V4 | AL8: 20230920 | AM8: D822-900000036-10000624
A9: 900007368D82210000430 | B9: 4600052426-10 | C9: 4600052426 | D9: 10 | E9: MXPO | F9: MXL | G9: 900007368 | H9: SF TP-TANSEL GUERRERO | I9: 5082231 | J9: CONSTRUCCION Y AGREGADOS TANSEL SA | K9: Z09 | L9: (AP) 90 Dias | M9: 10000430 | N9: Grava Triturada Caliza 20 mm - 3/4" | O9: D822 | P9: MX-CED. ACAPULCO | Q9: 20210411 | R9: 20261231 | S9: 20210411 | T9: 20261231 | U9: 135 | V9: MXN | W9: M3 | X9: 0 | Y9: MXN | Z9: M3 | AC9: 56103637 | AD9: 6622121540 | AE9: 1 | AF9: ENTREGADO | AG9: 1.5 | AH9: M3 | AI9: X | AJ9: 4 | AK9: V4 | AL9: 20230920 | AM9: D822-900007368-10000430
A10: 900007628D82210213469 | B10: 4600057065-10 | C10: 4600057065 | D10: 10 | E10: MXPO | F10: MXL | G10: 900007628 | H10: SF TP-COSTA CHICA | I10: 5006364 | J10: AGREGADOS COSTA CHICA SA DE CV | K10: Z09 | L10: (AP) 90 Dias | M10: 10213469 | N10: ARENA DE RIO NO.4 | O10: D822 | P10: MX-CED. ACAPULCO | Q10: 20230328 | R10: 20281231 | S10: 20230328 | T10: 20281231 | U10: 100 | V10: MXN | W10: M3 | X10: 0 | Y10: MXN | Z10: M3 | AC10: 56103638 | AD10: 6622121540 | AE10: 1 | AF10: ENTREGADO | AG10: 1.38 | AH10: M3 | AI10: X | AJ10: 4 | AK10: V4 | AL10: 20230920 | AM10: D822-900007628-10213469
A11: 900008180D82210213469 | B11: 4600057370-10 | C11: 4600057370 | D11: 10 | E11: MXPO | F11: MXL | G11: 900008180 | H11: SF TP-CERRO DE PIEDRA | I11: 5041380 | J11: SANTOYO GALEANA MARIA MAGDALENA | K11: Z04 | L11: (AP) 30 Dias | M11: 10213469 | N11: ARENA DE RIO NO.4 | O11: D822 | P11: MX-CED. ACAPULCO | Q11: 20230426 | R11: 20281231 | S11: 20230426 | T11: 20281231 | U11: 110 | V11: MXN | W11: M3 | X11: 0 | Y11: MXN | Z11: M3 | AC11: 56103638 | AD11: 6622121540 | AE11: 1 | AF11: ENTREGADO | AG11: 1.38 | AH11: M3 | AI11: X | AJ11: 4 | AK11: V4 | AL11: 20230920 | AM11: D822-900008180-10213469
A12: 900007628D82210213931 | B12: 4600057065-20 | C12: 4600057065 | D12: 20 | E12: MXPO | F12: MXL | G12: 900007628 | H12: SF TP-COSTA CHICA | I12: 5006364 | J12: AGREGADOS COSTA CHICA SA DE CV | K12: Z09 | L12: (AP) 90 Dias | M12: 10213931 | N12: GRAVA RIO 20 MM (3/4") | O12: D822 | P12: MX-CED. ACAPULCO | Q12: 20230328 | R12: 20281231 | S12: 20230811 | T12: 20281231 | U12: 350 | V12: MXN | W12: M3 | X12: 0 | Y12: MXN | Z12: M3 | AC12: 56103637 | AD12: 6622121540 | AE12: 1 | AF12: ENTREGADO | AG12: 1.462 | AH12: M3 | AI12: X | AJ12: 4 | AK12: V4 | AL12: 20230920 | AM12: D822-900007628-10213931
A13: 900005330D82210139741 | B13: 4600039007-10 | C13: 4600039007 | D13: 10 | E13: MXPO | F13: MXL | G13: 900005330 | H13: TP-CEMEX CHINA | I13: 5059655 | J13: AJL CONCRETE SOLUTIONS SA DE CV | K13: N90 | L13: (AP) NAFIN 90 Dias | M13: 10139741 | N13: MICROSILICA | O13: D822 | P13: MX-CED. ACAPULCO | Q13: 20170728 | R13: 20291231 | S13: 20170728 | T13: 20241231 | U13: 410 | V13: USD | W13: TN | X13: 0 | Y13: USD | Z13: TN | AC13: 56103638 | AD13: 6622121540 | AE13: 1 | AF13: ENTREGADO | AG13: 1 | AH13: TO | AI13: X | AJ13: 4 | AK13: V4 | AL13: 20230920 | AM13: D822-900005330-10139741
A14: 900005224D82210139741 | B14: 4600037861-10 | C14: 4600037861 | D14: 10 | E14: MXPO | F14: MXL | G14: 900005224 | H14: TP-HOCESA | I14: 5006995 | J14: INDUSTRIAL HOCESA SA DE CV | K14: N120 | L14: (AP) NAFIN 120 Dias | M14: 10139741 | N14: MICROSILICA | O14: D822 | P14: MX-CED. ACAPULCO | Q14: 20170510 | R14: 20241231 | S14: 20170510 | T14: 20241231 | U14: 10065 | V14: MXN | W14: TN | X14: 0 | Y14: MXN | Z14: TN | AC14: 56103638 | AD14: 6622121540 | AE14: 2 | AF14: RECOGIDO | AG14: 1 | AH14: TO | AI14: X | AJ14: 4 | AK14: V4 | AL14: 20230920 | AM14: D822-900005224-10139741
A15: 900005812D82210151420 | B15: 4600042946-10 | C15: 4600042946 | D15: 10 | E15: MXPO | F15: MXL | G15: 900005812 | H15: SF TP-PROPEX FABRICS DE MEXICO | I15: 5005136 | J15: PROPEX FABRICS DE MEXICO SA DE CV | K15: Z09 | L15: (AP) 90 Dias | M15: 10151420 | N15: FIBRA POLIPROPILENO PARA CONCRETO | O15: D822 | P15: MX-CED. ACAPULCO | Q15: 20180913 | R15: 20241231 | S15: 20180912 | T15: 20241231 | U15: 60000 | V15: MXN | W15: TN | X15: 0 | Y15: MXN | Z15: TN | AC15: 56103591 | AD15: 6622121540 | AE15: 2 | AF15: RECOGIDO | AG15: 1 | AH15: TO | AI15: X | AJ15: 4 | AK15: V4 | AL15: 20230920 | AM15: D822-900005812-10151420
A16: 900005451D82210151420 | B16: 4600041352-10 | C16: 4600041352 | D16: 10 | E16: MXPO | F16: MXL | G16: 900005451 | H16: TP-COFISA | I16: 5001422 | J16: COFISA DE MONTERREY SA DE CV | K16: N120 | L16: (AP) NAFIN 120 Dias | M16: 10151420 | N16: FIBRA POLIPROPILENO PARA CONCRETO | O16: D822 | P16: MX-CED. ACAPULCO | Q16: 20180226 | R16: 20241231 | S16: 20180226 | T16: 20241231 | U16: 44630 | V16: MXN | W16: TN | X16: 0 | Y16: MXN | Z16: TN | AC16: 56103591 | AD16: 6622121540 | AE16: 2 | AF16: RECOGIDO | AG16: 1 | AH16: TO | AI16: X | AJ16: 4 | AK16: V4 | AL16: 20230920 | AM16: D822-900005451-10151420
A17: 900005544D82210149996 | B17: 4600041325-10 | C17: 4600041325 | D17: 10 | E17: MXPO | F17: MXL | G17: 900005544 | H17: TP-FAPSA 2 | I17: 5070357 | J17: JOSE DOMINGO GUTIERREZ SILVA | K17: Z03 | L17: (AP) 15 Dias | M17: 10149996 | N17: ARENA SILICA MALLA 30 ENSACADA | O17: D822 | P17: MX-CED. ACAPULCO | Q17: 20180223 | R17: 20241231 | S17: 20180223 | T17: 20241231 | U17: 42000 | V17: MXN | W17: TN | X17: 0 | Y17: MXN | Z17: TN | AC17: 56103638 | AD17: 6622121540 | AE17: 2 | AF17: RECOGIDO | AG17: 1 | AH17: TO | AI17: X | AJ17: 4 | AK17: V4 | AL17: 20230920 | AM17: D822-900005544-10149996
A18: 900005185D82210139741 | B18: 4600037793-10 | C18: 4600037793 | D18: 10 | E18: MXPO | F18: MXL | G18: 900005185 | H18: TP-ED EUCOMEX | I18: 5003465 | J18: EUCOMEX SA DE CV | K18: N120 | L18: (AP) NAFIN 120 Dias | M18: 10139741 | N18: MICROSILICA | O18: D822 | P18: MX-CED. ACAPULCO | Q18: 20170503 | R18: 20241231 | S18: 20170503 | T18: 20241231 | U18: 10573 | V18: MXN | W18: TN | X18: 0 | Y18: MXN | Z18: TN | AC18: 56103638 | AD18: 6622121540 | AE18: 2 | AF18: RECOGIDO | AG18: 1 | AH18: TO | AI18: X | AJ18: 4 | AK18: V4 | AL18: 20230920 | AM18: D822-900005185-10139741
A19: 900005191D82210139741 | B19: 4600037863-10 | C19: 4600037863 | D19: 10 | E19: MXPO | F19: MXL | G19: 900005191 | H19: TP-BASF MEXICANA | I19: 5014141 | J19: BASF MEXICANA SA DE CV | K19: N90 | L19: (AP) NAFIN 90 Dias | M19: 10139741 | N19: MICROSILICA | O19: D822 | P19: MX-CED. ACAPULCO | Q19: 20170510 | R19: 20241231 | S19: 20170510 | T19: 20241231 | U19: 21630 | V19: MXN | W19: TN | X19: 0 | Y19: MXN | Z19: TN | AC19: 56103638 | AD19: 6622121540 | AE19: 2 | AF19: RECOGIDO | AG19: 1 | AH19: TO | AI19: X | AJ19: 4 | AK19: V4 | AL19: 20230920 | AM19: D822-900005191-10139741
A20: 900005056D82210139741 | B20: 4600038055-10 | C20: 4600038055 | D20: 10 | E20: MXPO | F20: MXL | G20: 900005056 | H20: TP-AJL SILICA | I20: 5059655 | J20: AJL CONCRETE SOLUTIONS SA DE CV | K20: N90 | L20: (AP) NAFIN 90 Dias | M20: 10139741 | N20: MICROSILICA | O20: D822 | P20: MX-CED. ACAPULCO | Q20: 20170523 | R20: 20241231 | S20: 20170523 | T20: 20241231 | U20: 500 | V20: USD | W20: TN | X20: 0 | Y20: USD | Z20: TN | AC20: 56103638 | AD20: 6622121540 | AE20: 2 | AF20: RECOGIDO | AG20: 1 | AH20: TO | AI20: X | AJ20: 4 | AK20: V4 | AL20: 20230920 | AM20: D822-900005056-10139741
... A24: 900008720D82210213469 | B24: 4600069057-20 | C24: 4600069057 | D24: 20 | E24: MXPO | F24: MXL | G24: 900008720 | H24: SF TP-PIEDRA DURA PAROTILLAS | I24: 5087603 | J24: PAPAGAYO CONSTRUCCIONES Y MAQUINARI | K24: N30 | L24: (AP) NAFIN 30 Dias | M24: 10213469 | N24: ARENA DE RIO NO.4 | O24: D822 | P24: MX-CED. ACAPULCO | Q24: 20240202 | R24: 20291231 | S24: 20250314 | T24: 20301231 | U24: 160 | V24: MXN | W24: M3 | X24: 0 | Y24: MXN | Z24: M3 | AC24: 56103638 | AD24: 6622121540 | AE24: 1 | AF24: ENTREGADO | AG24: 1.38 | AH24: M3 | AI24: X | AJ24: 4 | AK24: V4 | AL24: 20250320 | AM24: D822-900008720-10213469
A25: 900000036D82210171624 | B25: 4600046620-40 | C25: 4600046620 | D25: 40 | E25: MXPO | F25: MXL | G25: 900000036 | H25: SF PAPAGAYO | I25: 5001941 | J25: PAPAGAYO LA SABANA SA DE CV | K25: Z03 | L25: (AP) 15 Dias | M25: 10171624 | N25: ARENA TRITURADA CALIZA MALLA 4 | O25: D822 | P25: MX-CED. ACAPULCO | Q25: 20200220 | R25: 20301231 | S25: 20200220 | T25: 20301231 | U25: 1 | V25: MXN | W25: M3 | AC25: 56103638 | AD25: 6622121540 | AE25: 1 | AF25: ENTREGADO | AG25: 1.675 | AH25: M3 | AI25: X | AJ25: 4 | AK25: V4 | AL25: 20230920 | AM25: D822-900000036-10171624
