Workbook

Sheet Base Cedis D820
N1: VENTA | Q1: COSTO
A2: CONCAT1 | B2: CONCAT2 | C2: No. SF | D2: Nombre SF | E2: Cedis | F2: Destino | G2: Condicion de Expedicion | H2: Nombre Destino | I2: No. de material | J2: Nombre de material | K2: PV | L2: Inicio de vigencia | M2: Fin de vigencia | N2: Importe MP | O2: Importe Flete | P2: UM Venta | Q2: Importe Costo | R2: UM Costo | S2: Validacion 1 | T2: Validacion 2
A3: =CONCATENATE(C3,E3,F3,I3) | B3: =CONCATENATE(C3,E3,I3) | C3: 900000406 | D3: =IFERROR(VLOOKUP(C3,TRAOPE!$G:$H,2,0),"") | E3: D820 | F3: 66083590 | G3: =IFERROR(VLOOKUP(A3,Flete!$A:$E,5,0),"") | H3: =IFERROR(VLOOKUP(F3,TRAOPE!$AA:$AB,2,0),"") | I3: 10000791 | J3: =IFERROR(VLOOKUP(I3,Materiales!$A:$H,8,0),"") | K3: =IFERROR(VLOOKUP(I3,Materiales!$A:$G,7,0),"") | L3: 20191211 | M3: 20251031 | N3: 145 | O3: =IFERROR(VLOOKUP(A3,Flete!$A:$J,10,0),"") | P3: M3 | Q3: =IFERROR(IFERROR(VLOOKUP(A3,TRAOPE!$A:$U,21,0),VLOOKUP(B3,TRAOPE!$A:$U,21,0)),"") | R3: =IFERROR(IFERROR(VLOOKUP(A3,TRAOPE!$A:$W,23,0),VLOOKUP(B3,TRAOPE!$A:$W,23,0)),"") | S3: =IF(AND(P3="TN",R3="TN"),N3+N(O3),IF(G3&""="1",N(K3)*N3,(N3+N(O3))*N(K3))) | T3: =IF(Q3="","",Q3-S3)
A4: =CONCATENATE(C4,E4,F4,I4) | B4: =CONCATENATE(C4,E4,I4) | C4: 900000406 | D4: =IFERROR(VLOOKUP(C4,TRAOPE!$G:$H,2,0),"") | E4: D820 | F4: 66436319 | G4: =IFERROR(VLOOKUP(A4,Flete!$A:$E,5,0),"") | H4: =IFERROR(VLOOKUP(F4,TRAOPE!$AA:$AB,2,0),"") | I4: 10000791 | J4: =IFERROR(VLOOKUP(I4,Materiales!$A:$H,8,0),"") | K4: =IFERROR(VLOOKUP(I4,Materiales!$A:$G,7,0),"") | L4: 20191211 | M4: 20251031 | N4: 140 | O4: =IFERROR(VLOOKUP(A4,Flete!$A:$J,10,0),"") | P4: M3 | Q4: =IFERROR(IFERROR(VLOOKUP(A4,TRAOPE!$A:$U,21,0),VLOOKUP(B4,TRAOPE!$A:$U,21,0)),"") | R4: =IFERROR(IFERROR(VLOOKUP(A4,TRAOPE!$A:$W,23,0),VLOOKUP(B4,TRAOPE!$A:$W,23,0)),"") | S4: =IF(AND(P4="TN",R4="TN"),N4+N(O4),IF(G4&""="1",N(K4)*N4,(N4+N(O4))*N(K4))) | T4: =IF(Q4="","",Q4-S4)
A5: =CONCATENATE(C5,E5,F5,I5) | B5: =CONCATENATE(C5,E5,I5) | C5: 900000406 | D5: =IFERROR(VLOOKUP(C5,TRAOPE!$G:$H,2,0),"") | E5: D820 | F5: 66436319 | G5: =IFERROR(VLOOKUP(A5,Flete!$A:$E,5,0),"") | H5: =IFERROR(VLOOKUP(F5,TRAOPE!$AA:$AB,2,0),"") | I5: 10065029 | J5: =IFERROR(VLOOKUP(I5,Materiales!$A:$H,8,0),"") | K5: =IFERROR(VLOOKUP(I5,Materiales!$A:$G,7,0),"") | L5: 20191211 | M5: 20251031 | N5: 140 | O5: =IFERROR(VLOOKUP(A5,Flete!$A:$J,10,0),"") | P5: M3 | Q5: =IFERROR(IFERROR(VLOOKUP(A5,TRAOPE!$A:$U,21,0),VLOOKUP(B5,TRAOPE!$A:$U,21,0)),"") | R5: =IFERROR(IFERROR(VLOOKUP(A5,TRAOPE!$A:$W,23,0),VLOOKUP(B5,TRAOPE!$A:$W,23,0)),"") | S5: =IF(AND(P5="TN",R5="TN"),N5+N(O5),IF(G5&""="1",N(K5)*N5,(N5+N(O5))*N(K5))) | T5: =IF(Q5="","",Q5-S5)
A6: =CONCATENATE(C6,E6,F6,I6) | B6: =CONCATENATE(C6,E6,I6) | C6: 900000406 | D6: =IFERROR(VLOOKUP(C6,TRAOPE!$G:$H,2,0),"") | E6: D820 | F6: 66436319 | G6: =IFERROR(VLOOKUP(A6,Flete!$A:$E,5,0),"") | H6: =IFERROR(VLOOKUP(F6,TRAOPE!$AA:$AB,2,0),"") | I6: 10112090 | J6: =IFERROR(VLOOKUP(I6,Materiales!$A:$H,8,0),"") | K6: =IFERROR(VLOOKUP(I6,Materiales!$A:$G,7,0),"") | L6: 20191211 | M6: 20251031 | N6: 144 | O6: =IFERROR(VLOOKUP(A6,Flete!$A:$J,10,0),"") | P6: M3 | Q6: =IFERROR(IFERROR(VLOOKUP(A6,TRAOPE!$A:$U,21,0),VLOOKUP(B6,TRAOPE!$A:$U,21,0)),"") | R6: =IFERROR(IFERROR(VLOOKUP(A6,TRAOPE!$A:$W,23,0),VLOOKUP(B6,TRAOPE!$A:$W,23,0)),"") | S6: =IF(AND(P6="TN",R6="TN"),N6+N(O6),IF(G6&""="1",N(K6)*N6,(N6+N(O6))*N(K6))) | T6: =IF(Q6="","",Q6-S6)
A7: =CONCATENATE(C7,E7,F7,I7) | B7: =CONCATENATE(C7,E7,I7) | C7: 900004183 | D7: =IFERROR(VLOOKUP(C7,TRAOPE!$G:$H,2,0),"") | E7: D820 | F7: 66195767 | G7: =IFERROR(VLOOKUP(A7,Flete!$A:$E,5,0),"") | H7: =IFERROR(VLOOKUP(F7,TRAOPE!$AA:$AB,2,0),"") | I7: 10000200 | J7: =IFERROR(VLOOKUP(I7,Materiales!$A:$H,8,0),"") | K7: =IFERROR(VLOOKUP(I7,Materiales!$A:$G,7,0),"") | L7: 20191211 | M7: 20251031 | N7: 350 | O7: =IFERROR(VLOOKUP(A7,Flete!$A:$J,10,0),"") | P7: M3 | Q7: =IFERROR(IFERROR(VLOOKUP(A7,TRAOPE!$A:$U,21,0),VLOOKUP(B7,TRAOPE!$A:$U,21,0)),"") | R7: =IFERROR(IFERROR(VLOOKUP(A7,TRAOPE!$A:$W,23,0),VLOOKUP(B7,TRAOPE!$A:$W,23,0)),"") | S7: =IF(AND(P7="TN",R7="TN"),N7+N(O7),IF(G7&""="1",N(K7)*N7,(N7+N(O7))*N(K7))) | T7: =IF(Q7="","",Q7-S7)
A8: =CONCATENATE(C8,E8,F8,I8) | B8: =CONCATENATE(C8,E8,I8) | C8: 900005257 | D8: =IFERROR(VLOOKUP(C8,TRAOPE!$G:$H,2,0),"") | E8: D820 | F8: 65013304 | G8: =IFERROR(VLOOKUP(A8,Flete!$A:$E,5,0),"") | H8: =IFERROR(VLOOKUP(F8,TRAOPE!$AA:$AB,2,0),"") | I8: 10112026 | J8: =IFERROR(VLOOKUP(I8,Materiales!$A:$H,8,0),"") | K8: =IFERROR(VLOOKUP(I8,Materiales!$A:$G,7,0),"") | L8: 20191211 | M8: 20251031 | N8: 235 | O8: =IFERROR(VLOOKUP(A8,Flete!$A:$J,10,0),"") | P8: M3 | Q8: =IFERROR(IFERROR(VLOOKUP(A8,TRAOPE!$A:$U,21,0),VLOOKUP(B8,TRAOPE!$A:$U,21,0)),"") | R8: =IFERROR(IFERROR(VLOOKUP(A8,TRAOPE!$A:$W,23,0),VLOOKUP(B8,TRAOPE!$A:$W,23,0)),"") | S8: =IF(AND(P8="TN",R8="TN"),N8+N(O8),IF(G8&""="1",N(K8)*N8,(N8+N(O8))*N(K8))) | T8: =IF(Q8="","",Q8-S8)
A9: =CONCATENATE(C9,E9,F9,I9) | B9: =CONCATENATE(C9,E9,I9) | C9: 900005257 | D9: =IFERROR(VLOOKUP(C9,TRAOPE!$G:$H,2,0),"") | E9: D820 | F9: 65160864 | G9: =IFERROR(VLOOKUP(A9,Flete!$A:$E,5,0),"") | H9: =IFERROR(VLOOKUP(F9,TRAOPE!$AA:$AB,2,0),"") | I9: 10112026 | J9: =IFERROR(VLOOKUP(I9,Materiales!$A:$H,8,0),"") | K9: =IFERROR(VLOOKUP(I9,Materiales!$A:$G,7,0),"") | L9: 20191211 | M9: 20251031 | N9: 154 | O9: =IFERROR(VLOOKUP(A9,Flete!$A:$J,10,0),"") | P9: M3 | Q9: =IFERROR(IFERROR(VLOOKUP(A9,TRAOPE!$A:$U,21,0),VLOOKUP(B9,TRAOPE!$A:$U,21,0)),"") | R9: =IFERROR(IFERROR(VLOOKUP(A9,TRAOPE!$A:$W,23,0),VLOOKUP(B9,TRAOPE!$A:$W,23,0)),"") | S9: =IF(AND(P9="TN",R9="TN"),N9+N(O9),IF(G9&""="1",N(K9)*N9,(N9+N(O9))*N(K9))) | T9: =IF(Q9="","",Q9-S9)
A10: =CONCATENATE(C10,E10,F10,I10) | B10: =CONCATENATE(C10,E10,I10) | C10: 900005257 | D10: =IFERROR(VLOOKUP(C10,TRAOPE!$G:$H,2,0),"") | E10: D820 | F10: 65160864 | G10: =IFERROR(VLOOKUP(A10,Flete!$A:$E,5,0),"") | H10: =IFERROR(VLOOKUP(F10,TRAOPE!$AA:$AB,2,0),"") | I10: 10115820 | J10: =IFERROR(VLOOKUP(I10,Materiales!$A:$H,8,0),"") | K10: =IFERROR(VLOOKUP(I10,Materiales!$A:$G,7,0),"") | L10: 20191211 | M10: 20251031 | N10: 164 | O10: =IFERROR(VLOOKUP(A10,Flete!$A:$J,10,0),"") | P10: M3 | Q10: =IFERROR(IFERROR(VLOOKUP(A10,TRAOPE!$A:$U,21,0),VLOOKUP(B10,TRAOPE!$A:$U,21,0)),"") | R10: =IFERROR(IFERROR(VLOOKUP(A10,TRAOPE!$A:$W,23,0),VLOOKUP(B10,TRAOPE!$A:$W,23,0)),"") | S10: =IF(AND(P10="TN",R10="TN"),N10+N(O10),IF(G10&""="1",N(K10)*N10,(N10+N(O10))*N(K10))) | T10: =IF(Q10="","",Q10-S10)
A11: =CONCATENATE(C11,E11,F11,I11) | B11: =CONCATENATE(C11,E11,I11) | C11: 900005257 | D11: =IFERROR(VLOOKUP(C11,TRAOPE!$G:$H,2,0),"") | E11: D820 | F11: 65160864 | G11: =IFERROR(VLOOKUP(A11,Flete!$A:$E,5,0),"") | H11: =IFERROR(VLOOKUP(F11,TRAOPE!$AA:$AB,2,0),"") | I11: 10115821 | J11: =IFERROR(VLOOKUP(I11,Materiales!$A:$H,8,0),"") | K11: =IFERROR(VLOOKUP(I11,Materiales!$A:$G,7,0),"") | L11: 20191211 | M11: 20251031 | N11: 154 | O11: =IFERROR(VLOOKUP(A11,Flete!$A:$J,10,0),"") | P11: M3 | Q11: =IFERROR(IFERROR(VLOOKUP(A11,TRAOPE!$A:$U,21,0),VLOOKUP(B11,TRAOPE!$A:$U,21,0)),"") | R11: =IFERROR(IFERROR(VLOOKUP(A11,TRAOPE!$A:$W,23,0),VLOOKUP(B11,TRAOPE!$A:$W,23,0)),"") | S11: =IF(AND(P11="TN",R11="TN"),N11+N(O11),IF(G11&""="1",N(K11)*N11,(N11+N(O11))*N(K11))) | T11: =IF(Q11="","",Q11-S11)
A12: =CONCATENATE(C12,E12,F12,I12) | B12: =CONCATENATE(C12,E12,I12) | C12: 900005257 | D12: =IFERROR(VLOOKUP(C12,TRAOPE!$G:$H,2,0),"") | E12: D820 | F12: 65302277 | G12: =IFERROR(VLOOKUP(A12,Flete!$A:$E,5,0),"") | H12: =IFERROR(VLOOKUP(F12,TRAOPE!$AA:$AB,2,0),"") | I12: 10112026 | J12: =IFERROR(VLOOKUP(I12,Materiales!$A:$H,8,0),"") | K12: =IFERROR(VLOOKUP(I12,Materiales!$A:$G,7,0),"") | L12: 20191211 | M12: 20251031 | N12: 133 | O12: =IFERROR(VLOOKUP(A12,Flete!$A:$J,10,0),"") | P12: M3 | Q12: =IFERROR(IFERROR(VLOOKUP(A12,TRAOPE!$A:$U,21,0),VLOOKUP(B12,TRAOPE!$A:$U,21,0)),"") | R12: =IFERROR(IFERROR(VLOOKUP(A12,TRAOPE!$A:$W,23,0),VLOOKUP(B12,TRAOPE!$A:$W,23,0)),"") | S12: =IF(AND(P12="TN",R12="TN"),N12+N(O12),IF(G12&""="1",N(K12)*N12,(N12+N(O12))*N(K12))) | T12: =IF(Q12="","",Q12-S12)
A13: =CONCATENATE(C13,E13,F13,I13) | B13: =CONCATENATE(C13,E13,I13) | C13: 900005257 | D13: =IFERROR(VLOOKUP(C13,TRAOPE!$G:$H,2,0),"") | E13: D820 | F13: 65302277 | G13: =IFERROR(VLOOKUP(A13,Flete!$A:$E,5,0),"") | H13: =IFERROR(VLOOKUP(F13,TRAOPE!$AA:$AB,2,0),"") | I13: 10115820 | J13: =IFERROR(VLOOKUP(I13,Materiales!$A:$H,8,0),"") | K13: =IFERROR(VLOOKUP(I13,Materiales!$A:$G,7,0),"") | L13: 20191211 | M13: 20251031 | N13: 149 | O13: =IFERROR(VLOOKUP(A13,Flete!$A:$J,10,0),"") | P13: M3 | Q13: =IFERROR(IFERROR(VLOOKUP(A13,TRAOPE!$A:$U,21,0),VLOOKUP(B13,TRAOPE!$A:$U,21,0)),"") | R13: =IFERROR(IFERROR(VLOOKUP(A13,TRAOPE!$A:$W,23,0),VLOOKUP(B13,TRAOPE!$A:$W,23,0)),"") | S13: =IF(AND(P13="TN",R13="TN"),N13+N(O13),IF(G13&""="1",N(K13)*N13,(N13+N(O13))*N(K13))) | T13: =IF(Q13="","",Q13-S13)
A14: =CONCATENATE(C14,E14,F14,I14) | B14: =CONCATENATE(C14,E14,I14) | C14: 900005257 | D14: =IFERROR(VLOOKUP(C14,TRAOPE!$G:$H,2,0),"") | E14: D820 | F14: 65302277 | G14: =IFERROR(VLOOKUP(A14,Flete!$A:$E,5,0),"") | H14: =IFERROR(VLOOKUP(F14,TRAOPE!$AA:$AB,2,0),"") | I14: 10115821 | J14: =IFERROR(VLOOKUP(I14,Materiales!$A:$H,8,0),"") | K14: =IFERROR(VLOOKUP(I14,Materiales!$A:$G,7,0),"") | L14: 20191211 | M14: 20251031 | N14: 133 | O14: =IFERROR(VLOOKUP(A14,Flete!$A:$J,10,0),"") | P14: M3 | Q14: =IFERROR(IFERROR(VLOOKUP(A14,TRAOPE!$A:$U,21,0),VLOOKUP(B14,TRAOPE!$A:$U,21,0)),"") | R14: =IFERROR(IFERROR(VLOOKUP(A14,TRAOPE!$A:$W,23,0),VLOOKUP(B14,TRAOPE!$A:$W,23,0)),"") | S14: =IF(AND(P14="TN",R14="TN"),N14+N(O14),IF(G14&""="1",N(K14)*N14,(N14+N(O14))*N(K14))) | T14: =IF(Q14="","",Q14-S14)
... A44: =CONCATENATE(C44,E44,F44,I44) | B44: =CONCATENATE(C44,E44,I44) | C44: 900005257 | D44: =IFERROR(VLOOKUP(C44,TRAOPE!$G:$H,2,0),"") | E44: D820 | F44: 65436011 | G44: =IFERROR(VLOOKUP(A44,Flete!$A:$E,5,0),"") | H44: =IFERROR(VLOOKUP(F44,TRAOPE!$AA:$AB,2,0),"") | I44: 10187515 | J44: =IFERROR(VLOOKUP(I44,Materiales!$A:$H,8,0),"") | K44: =IFERROR(VLOOKUP(I44,Materiales!$A:$G,7,0),"") | L44: 20250528 | M44: 20250710 | N44: 283 | O44: =IFERROR(VLOOKUP(A44,Flete!$A:$J,10,0),"") | P44: M3 | Q44: =IFERROR(IFERROR(VLOOKUP(A44,TRAOPE!$A:$U,21,0),VLOOKUP(B44,TRAOPE!$A:$U,21,0)),"") | R44: =IFERROR(IFERROR(VLOOKUP(A44,TRAOPE!$A:$W,23,0),VLOOKUP(B44,TRAOPE!$A:$W,23,0)),"") | S44: =IF(AND(P44="TN",R44="TN"),N44+N(O44),IF(G44&""="1",N(K44)*N44,(N44+N(O44))*N(K44))) | T44: =IF(Q44="","",Q44-S44)

Sheet MP
A1: No. SF | B1: Cedis | C1: Destino | D1: No. Material | E1: Nombre Material | F1: Importe MP | G1: Moneda | H1: Cantidad | I1: UM | J1: C | K1: Inicio Vigencia | L1: Fin Vigencia
A2: 900000406 | B2: D820 | C2: 66083590 | D2: 10000791 | F2: 145 | I2: M3 | K2: 20191211 | L2: 20251031
A3: 900000406 | B3: D820 | C3: 66436319 | D3: 10000791 | F3: 140 | I3: M3 | K3: 20191211 | L3: 20251031
A4: 900000406 | B4: D820 | C4: 66436319 | D4: 10065029 | F4: 140 | I4: M3 | K4: 20191211 | L4: 20251031
A5: 900000406 | B5: D820 | C5: 66436319 | D5: 10112090 | F5: 144 | I5: M3 | K5: 20191211 | L5: 20251031
A6: 900004183 | B6: D820 | C6: 66195767 | D6: 10000200 | F6: 350 | I6: M3 | K6: 20191211 | L6: 20251031
A7: 900005257 | B7: D820 | C7: 65013304 | D7: 10112026 | F7: 235 | I7: M3 | K7: 20191211 | L7: 20251031
A8: 900005257 | B8: D820 | C8: 65160864 | D8: 10112026 | F8: 154 | I8: M3 | K8: 20191211 | L8: 20251031
A9: 900005257 | B9: D820 | C9: 65160864 | D9: 10115820 | F9: 164 | I9: M3 | K9: 20191211 | L9: 20251031
A10: 900005257 | B10: D820 | C10: 65160864 | D10: 10115821 | F10: 154 | I10: M3 | K10: 20191211 | L10: 20251031
A11: 900005257 | B11: D820 | C11: 65302277 | D11: 10112026 | F11: 133 | I11: M3 | K11: 20191211 | L11: 20251031
A12: 900005257 | B12: D820 | C12: 65302277 | D12: 10115820 | F12: 149 | I12: M3 | K12: 20191211 | L12: 20251031
A13: 900005257 | B13: D820 | C13: 65302277 | D13: 10115821 | F13: 133 | I13: M3 | K13: 20191211 | L13: 20251031
... A43: 900005257 | B43: D820 | C43: 65436011 | D43: 10187515 | F43: 283 | I43: M3 | K43: 20250528 | L43: 20250710

Sheet Flete
A1: Concat1 | B1: No. SF | C1: Cedis | D1: Destino | E1: Cond. Exp. | F1: Material | H1: Nombre Material | J1: Importe Flete | K1: Moneda | L1: Cantidad | M1: UM | N1: C | P1: Inicio Vigencia | Q1: Fin Vigencia
A2: 900004183D8206619576710000200 | B2: 900004183 | C2: D820 | D2: 66195767 | E2: 4 | F2: 10000200 | J2: 200 | M2: M3 | P2: 20191211 | Q2: 20251031
A3: 900004611D8206500035310112026 | B3: 900004611 | C3: D820 | D3: 65000353 | E3: 1 | F3: 10112026 | J3: 99.13 | M3: M3 | P3: 20170210 | Q3: 99991231
A4: 900004611D8206500035310115821 | B4: 900004611 | C4: D820 | D4: 65000353 | E4: 1 | F4: 10115821 | J4: 95.47 | M4: M3 | P4: 20170210 | Q4: 99991231
A5: 900005257D8206501330410112026 | B5: 900005257 | C5: D820 | D5: 65013304 | E5: 4 | F5: 10112026 | J5: 115 | M5: M3 | P5: 20191211 | Q5: 20251031
A6: 900005257D8206501330410115821 | B6: 900005257 | C6: D820 | D6: 65013304 | E6: 4 | F6: 10115821 | J6: 115 | M6: M3 | P6: 20240320 | Q6: 99991231
A7: 900005257D8206501330410187515 | B7: 900005257 | C7: D820 | D7: 65013304 | E7: 4 | F7: 10187515 | J7: 115 | M7: M3 | P7: 20240320 | Q7: 99991231
A8: 900005257D8206516086410112026 | B8: 900005257 | C8: D820 | D8: 65160864 | E8: 4 | F8: 10112026 | J8: 85 | M8: M3 | P8: 20191211 | Q8: 20251031
A9: 900005257D8206516086410115820 | B9: 900005257 | C9: D820 | D9: 65160864 | E9: 4 | F9: 10115820 | J9: 85 | M9: M3 | P9: 20191211 | Q9: 20251031
A10: 900005257D8206516086410115821 | B10: 900005257 | C10: D820 | D10: 65160864 | E10: 4 | F10: 10115821 | J10: 85 | M10: M3 | P10: 20191211 | Q10: 20251031
A11: 900005257D8206530227710112026 | B11: 900005257 | C11: D820 | D11: 65302277 | E11: 4 | F11: 10112026 | J11: 100 | M11: M3 | P11: 20191211 | Q11: 20251031
A12: 900005257D8206530227710115820 | B12: 900005257 | C12: D820 | D12: 65302277 | E12: 4 | F12: 10115820 | J12: 100 | M12: M3 | P12: 20191211 | Q12: 20251031
A13: 900005257D8206530227710115821 | B13: 900005257 | C13: D820 | D13: 65302277 | E13: 4 | F13: 10115821 | J13: 100 | M13: M3 | P13: 20191211 | Q13: 20251031
... A40: 900005257D8206543601110187515 | B40: 900005257 | C40: D820 | D40: 65436011 | E40: 4 | F40: 10187515 | J40: 100 | M40: M3 | P40: 20230313 | Q40: 20250709

Sheet Materiales
A1: Material | B1: TpMt | C1: Denom | D1: UMA | E1: Contador | F1: UMB | G1: PV | H1: Nombre Material
A2: 10000001 | B2: ZFER | C2: 1000 | D2: M3 | E2: 1000 | F2: TN | G2: 1262 | H2: GRAVA ANDESITA 10 MM (3/8")
A3: 10000003 | B3: ZFER | C3: 1000 | D3: M3 | E3: 1000 | F3: TN | G3: 1443 | H3: GRAVA CALIZA 10 MM (3/8")
A4: 10000006 | B4: ZFER | C4: 1000 | D4: M3 | E4: 1000 | F4: TN | G4: 1490 | H4: GRAVA RIO 10 MM (3/8")
A5: 10000007 | B5: ZFER | C5: 1000 | D5: M3 | E5: 1000 | F5: TN | G5: 1488 | H5: GRAVA BASALTO 13 MM (1/2")
A6: 10000008 | B6: ZFER | C6: 1000 | D6: M3 | E6: 1000 | F6: TN | G6: 1358 | H6: GRAVA CALIZA 13 MM (1/2")
A7: 10000011 | B7: ZFER | C7: 1000 | D7: M3 | E7: 1000 | F7: TN | G7: 1323 | H7: GRAVA ANDESITA 20 MM (3/4")
A8: 10000013 | B8: ZFER | C8: 1000 | D8: M3 | E8: 1000 | F8: TN | G8: 1514 | H8: GRAVA BASALTO 20 MM (3/4")
A9: 10000014 | B9: ZFER | C9: 1000 | D9: M3 | E9: 1000 | F9: TN | G9: 1400 | H9: GRAVA CALIZA 20 MM (3/4")
A10: 10000015 | B10: ZFER | C10: 1000 | D10: M3 | E10: 1000 | F10: TN | G10: 1410 | H10: GRAVA GRANITO 20 MM (3/4")
A11: 10000017 | B11: ZFER | C11: 1000 | D11: M3 | E11: 1000 | F11: TN | G11: 1475 | H11: GRAVA RIOLITA 20 MM (3/4")
A12: 10000019 | B12: ZFER | C12: 1000 | D12: M3 | E12: 1000 | F12: TN | G12: 1515 | H12: GRAVA RIO 20 MM (3/4")
A13: 10000020 | B13: ZFER | C13: 1000 | D13: M3 | E13: 1 | F13: TN | G13: 1 | H13: GRAVA MAQUILA 40MM (1 1/2")
... A2291: 10268770 | B2291: ZFE3 | C2291: 1000 | D2291: M3 | E2291: 1000 | F2291: TN | G2291: 1240 | H2291: MP GRAVA TRIT CALIZA 40MM 1 1/2" - ESP
A2292: 10268901 | B2292: ZFE3 | C2292: 1000 | D2292: M3 | E2292: 1000 | G2292: 1560 | H2292: MP GRAVA ANDESITA GRIS 3/4" - CAPADA
A2293: 10267983 | C2293: 1000 | G2293: 1800 | H2293: ESCORIA ALTO HORNO 3/4
A2294: 10268996 | C2294: 1000 | G2294: 1329 | H2294: GRAVA TRITURADA CALIZA 40 MM - 11/2"
A2295: 10269072 | C2295: 1000 | G2295: 1700 | H2295: BASE HIDRÁULICA SCREEN
A2296: 10269225 | B2296: ZFE3 | C2296: 1000 | D2296: M3 | E2296: 1000 | G2296: 1289 | H2296: MP ARENA CALIZA LAVADA MALLA 4 - DELTA I
A2297: 10269245 | B2297: ZFE3 | C2297: 1000 | D2297: M3 | E2297: 1000 | G2297: 1410 | H2297: MP GRAVA TRITURADA CALIZA 3/8 - 10MM
A2298: 10269246 | B2298: ZFE3 | C2298: 1000 | D2298: M3 | E2298: 1000 | G2298: 1400 | H2298: MP GRAVA TRITURADA CALIZA 1 1/2 - 40MM
A2299: 10269247 | B2299: ZFE3 | C2299: 1000 | D2299: M3 | E2299: 1000 | G2299: 1560 | H2299: MP ARENA TRIT CALIZA M-4
A2300: 10270431 | B2300: ZFE3 | C2300: 1000 | D2300: M3 | E2300: 1000 | G2300: 1423 | H2300: MP GRAVA RIOLITA 13 MM - 1/2"
A2301: 10270898 | B2301: ZFE3 | C2301: 1000 | D2301: M3 | E2301: 1000 | G2301: 1551 | H2301: MP BASE H. TRIT. BASALTO 1 1/2" A FINOS
A2302: 10270911 | B2302: ZFE3 | C2302: 1000 | D2302: M3 | E2302: 1000 | G2302: 1360 | H2302: MP GRAVA TRIT. BASALTO 40 MM - 1 1/2"
A2303: 10270912 | B2303: ZFE3 | C2303: 1000 | D2303: M3 | E2303: 1000 | G2303: 1589 | H2303: MP ARENA TRIT. BASALTO MALLA 4
A2304: 10270913 | B2304: ZFE3 | C2304: 1000 | D2304: M3 | E2304: 1000 | G2304: 1395 | H2304: MP GRAVA TRIT. BASALTO 20 MM - 3/4
A2305: 10270914 | B2305: ZFE3 | C2305: 1000 | D2305: M3 | E2305: 1000 | G2305: 1623 | H2305: MP ARENA ANDESITA BC
A2306: 10270824 | B2306: M3 | C2306: 1000 | D2306: M3 | E2306: 10007640 | G2306: 1325 | H2306: MP ARENA TRITURADA CALIZA MALLA 5
A2307: 10270825 | B2307: M3 | C2307: 1000 | D2307: M3 | E2307: 10000003 | G2307: 1242 | H2307: MP GRAVA TRITURADA CALIZA 10MM (3/8”)
... A2319: 10272527 | B2319: ZFE3 | C2319: 1000 | D2319: M3 | E2319: 1000 | G2319: 1620 | H2319: CNC - NO CLASIFICADO
A2320: 10000332 | C2320: 1000 | D2320: M3 | E2320: 1000 | G2320: 800 | H2320: Grava Triturada Pomez - Jal 20 mm - 3/4"
A2321: 10273001 | B2321: ZFE3 | C2321: 1000 | D2321: M3 | E2321: 1000 | G2321: 1688 | H2321: MP ARENA TRIT. BASALTO MALLA 4
A2322: 10273002 | B2322: ZFE3 | C2322: 1000 | D2322: M3 | E2322: 1000 | G2322: 1466 | H2322: MP GRAVA TRIT. BASALTO 20 MM - 3/4"
A2323: 10273351 | B2323: ZFE3 | C2323: 1000 | D2323: M3 | E2323: 1000 | G2323: 1612 | H2323: MP ARENA TRIT. CALIZA MALLA 4
A2324: 10273352 | B2324: ZFE3 | C2324: 1000 | D2324: M3 | E2324: 1000 | G2324: 1492 | H2324: MP GRAVA TRIT. CALIZA 20 MM - 3/4"
A2325: 10271724 | B2325: ZFE3 | C2325: 1000 | D2325: M3 | E2325: 1000 | G2325: 1900 | H2325: MP RESIDUO DE CONCRETO
A2326: 10000677 | C2326: 1000 | D2326: M3 | G2326: 1164 | H2326: Grava Triturada Caliza 20 mm - 3/4"
A2327: 10274190 | B2327: ZFE3 | C2327: 1000 | D2327: M3 | E2327: 1000 | G2327: 1800 | H2327: MP BASE HIDRAULICA ANDESITA 70-30
A2328: 10274601 | B2328: ZFE3 | C2328: 1000 | D2328: M3 | E2328: 1000 | G2328: 1447 | H2328: MP ARENA BASALTO N° 4
...

Sheet TRAOPE
A1: Concat1 | B1: Contrato_Pos | C1: Doc. Compras | D1: Pos | E1: Org.compras | F1: Grp-Compr. | G1: Ship From | H1: Nombre SF | I1: Proveedor | J1: Nombre Prov | K1: Cond. Pago | L1: Descr. Cond Pago | M1: Material | N1: Descripción | O1: Centro | P1: Descripción Centro | Q1: In.perído validez | R1: Fin perído validez | S1: Válido de | T1: Validez a | U1: Precio neto pedido | V1: Moneda | W1: UM Precio Pedido | X1: Importe Condición | Y1: Moneda KONP | Z1: UM Ctd Base | AA1: Destino | AB1: Nombre Destino | AC1: Cuenta de mayor | AD1: Centro de costo | AE1: Cond. Exp. | AF1: Descr. Cond. Exp. | AG1: Peso Vol. | AH1: UMB | AI1: Ind. Oblig. Conf. Ped. | AJ1: Ctrl-Conf. | AK1: IVA | AL1: Modif_Date | AM1: Ruta
A2: 900004183D8206500035310000666 | B2: 4600030797-30 | C2: 4600030797 | D2: 30 | E2: MXPO | F2: MXL | G2: 900004183 | H2: TP- ED-MA. LOURDES ARRIAGA | I2: 5057706 | J2: ARRIAGA LAZO MARIA DE LOURDES | K2: N90 | L2: (AP) NAFIN 90 Dias | M2: 10000666 | N2: Grava Triturada Basalto 40 mm - 1 1/2" | O2: D820 | P2: MX-CED. AGUASCALIENTES | Q2: 20150604 | R2: 20281231 | S2: 20150901 | T2: 20241231 | U2: 190 | V2: MXN | W2: M3 | X2: 95 | Y2: MXN | Z2: M3 | AA2: 65000353 | AB2: CONCRETOS DE AGUASCALIENTES S.A. DE | AC2: 56103637 | AD2: 6622101540 | AE2: 4 | AF2: ENTREGA DIRECTA | AG2: 1.33 | AH2: M3 | AI2: X | AJ2: 4 | AK2: V4 | AL2: 20230920 | AM2: D820-900004183-65000353-10000666-4
A3: 900004183D8206500035310000755 | B3: 4600030797-20 | C3: 4600030797 | D3: 20 | E3: MXPO | F3: MXL | G3: 900004183 | H3: TP- ED-MA. LOURDES ARRIAGA | I3: 5057706 | J3: ARRIAGA LAZO MARIA DE LOURDES | K3: N90 | L3: (AP) NAFIN 90 Dias | M3: 10000755 | N3: Grava Triturada Basalto 20 mm - 3/4" | O3: D820 | P3: MX-CED. AGUASCALIENTES | Q3: 20150604 | R3: 20281231 | S3: 20150901 | T3: 20241231 | U3: 190 | V3: MXN | W3: M3 | X3: 95 | Y3: MXN | Z3: M3 | AA3: 65000353 | AB3: CONCRETOS DE AGUASCALIENTES S.A. DE | AC3: 56103637 | AD3: 6622101540 | AE3: 4 | AF3: ENTREGA DIRECTA | AG3: 1.33 | AH3: M3 | AI3: X | AJ3: 4 | AK3: V4 | AL3: 20230920 | AM3: D820-900004183-65000353-10000755-4
A4: 900002837D8206500035310000850 | B4: 4600042181-10 | C4: 4600042181 | D4: 10 | E4: MXPO | F4: MXL | G4: 900002837 | H4: TP-ED- GERARDO OROPEZA LOPEZ | I4: 5040860 | J4: OROPEZA LOPEZ GERARDO | K4: N90 | L4: (AP) NAFIN 90 Dias | M4: 10000850 | N4: Arena Clasificada Río Malla 4 | O4: D820 | P4: MX-CED. AGUASCALIENTES | Q4: 20180524 | R4: 20241231 | S4: 20180524 | T4: 20241231 | U4: 265 | V4: MXN | W4: M3 | X4: 135 | Y4: MXN | Z4: M3 | AA4: 65000353 | AB4: CONCRETOS DE AGUASCALIENTES S.A. DE | AC4: 56103638 | AD4: 6622101540 | AE4: 4 | AF4: ENTREGA DIRECTA | AG4: 1.356 | AH4: M3 | AI4: X | AJ4: 4 | AK4: V4 | AL4: 20230920 | AM4: D820-900002837-65000353-10000850-4
A5: 900005257D8206516086410112026 | B5: 4600041961-220 | C5: 4600041961 | D5: 220 | E5: MXPO | F5: MXL | G5: 900005257 | H5: SF TP - ED R & R | I5: 5068065 | J5: R R TRITURADOS SA DE CV | K5: N90 | L5: (AP) NAFIN 90 Dias | M5: 10112026 | N5: GRAVA TRITURADA CALIZA 40 MM - 1 1/2" | O5: D820 | P5: MX-CED. AGUASCALIENTES | Q5: 20180501 | R5: 20291231 | S5: 20201027 | T5: 20291231 | U5: 225 | V5: MXN | W5: M3 | X5: 85 | Y5: MXN | Z5: M3 | AA5: 65160864 | AB5: MARIO GARDUZA TOLEDO. | AC5: 56103637 | AD5: 6622101540 | AE5: 4 | AF5: ENTREGA DIRECTA | AG5: 1.358 | AH5: M3 | AI5: X | AJ5: 4 | AK5: V4 | AL5: 20230920 | AM5: D820-900005257-65160864-10112026-4
A6: 900005257D8206654551710115821 | B6: 4600041961-100 | C6: 4600041961 | D6: 100 | E6: MXPO | F6: MXL | G6: 900005257 | H6: SF TP - ED R & R | I6: 5068065 | J6: R R TRITURADOS SA DE CV | K6: N90 | L6: (AP) NAFIN 90 Dias | M6: 10115821 | N6: GRAVA TRITURADA CALIZA 20 MM - 3/4" | O6: D820 | P6: MX-CED. AGUASCALIENTES | Q6: 20180501 | R6: 20291231 | S6: 20180604 | T6: 20241231 | U6: 235 | V6: MXN | W6: M3 | X6: 95 | Y6: MXN | Z6: M3 | AA6: 66545517 | AB6: BENOL PLANTA AGS | AC6: 56103637 | AD6: 6622101540 | AE6: 4 | AF6: ENTREGA DIRECTA | AG6: 1.308 | AH6: M3 | AI6: X | AJ6: 4 | AK6: V4 | AL6: 20230920 | AM6: D820-900005257-66545517-10115821-4
A7: 900005257D8206649356410112026 | B7: 4600041961-250 | C7: 4600041961 | D7: 250 | E7: MXPO | F7: MXL | G7: 900005257 | H7: SF TP - ED R & R | I7: 5068065 | J7: R R TRITURADOS SA DE CV | K7: N90 | L7: (AP) NAFIN 90 Dias | M7: 10112026 | N7: GRAVA TRITURADA CALIZA 40 MM - 1 1/2" | O7: D820 | P7: MX-CED. AGUASCALIENTES | Q7: 20180501 | R7: 20291231 | S7: 20201027 | T7: 20291231 | U7: 225 | V7: MXN | W7: M3 | X7: 85 | Y7: MXN | Z7: M3 | AA7: 66493564 | AB7: PLANTA EJIDO EL REFUGIO | AC7: 56103637 | AD7: 6622101540 | AE7: 4 | AF7: ENTREGA DIRECTA | AG7: 1.358 | AH7: M3 | AI7: X | AJ7: 4 | AK7: V4 | AL7: 20230920 | AM7: D820-900005257-66493564-10112026-4
A8: 900005257D8206649356410115821 | B8: 4600041961-270 | C8: 4600041961 | D8: 270 | E8: MXPO | F8: MXL | G8: 900005257 | H8: SF TP - ED R & R | I8: 5068065 | J8: R R TRITURADOS SA DE CV | K8: N90 | L8: (AP) NAFIN 90 Dias | M8: 10115821 | N8: GRAVA TRITURADA CALIZA 20 MM - 3/4" | O8: D820 | P8: MX-CED. AGUASCALIENTES | Q8: 20180501 | R8: 20291231 | S8: 20201027 | T8: 20291231 | U8: 225 | V8: MXN | W8: M3 | X8: 85 | Y8: MXN | Z8: M3 | AA8: 66493564 | AB8: PLANTA EJIDO EL REFUGIO | AC8: 56103637 | AD8: 6622101540 | AE8: 4 | AF8: ENTREGA DIRECTA | AG8: 1.308 | AH8: M3 | AI8: X | AJ8: 4 | AK8: V4 | AL8: 20230920 | AM8: D820-900005257-66493564-10115821-4
A9: 900005257D8206516086410115821 | B9: 4600041961-240 | C9: 4600041961 | D9: 240 | E9: MXPO | F9: MXL | G9: 900005257 | H9: SF TP - ED R & R | I9: 5068065 | J9: R R TRITURADOS SA DE CV | K9: N90 | L9: (AP) NAFIN 90 Dias | M9: 10115821 | N9: GRAVA TRITURADA CALIZA 20 MM - 3/4" | O9: D820 | P9: MX-CED. AGUASCALIENTES | Q9: 20180501 | R9: 20291231 | S9: 20201027 | T9: 20291231 | U9: 225 | V9: MXN | W9: M3 | X9: 85 | Y9: MXN | Z9: M3 | AA9: 65160864 | AB9: MARIO GARDUZA TOLEDO. | AC9: 56103637 | AD9: 6622101540 | AE9: 4 | AF9: ENTREGA DIRECTA | AG9: 1.308 | AH9: M3 | AI9: X | AJ9: 4 | AK9: V4 | AL9: 20230920 | AM9: D820-900005257-65160864-10115821-4
A10: 900005257D8206649356410115820 | B10: 4600041961-260 | C10: 4600041961 | D10: 260 | E10: MXPO | F10: MXL | G10: 900005257 | H10: SF TP - ED R & R | I10: 5068065 | J10: R R TRITURADOS SA DE CV | K10: N90 | L10: (AP) NAFIN 90 Dias | M10: 10115820 | N10: ARENA TRITURADA CALIZA MALLA 4 | O10: D820 | P10: MX-CED. AGUASCALIENTES | Q10: 20180501 | R10: 20291231 | S10: 20201027 | T10: 20291231 | U10: 230 | V10: MXN | W10: M3 | X10: 85 | Y10: MXN | Z10: M3 | AA10: 66493564 | AB10: PLANTA EJIDO EL REFUGIO | AC10: 56103638 | AD10: 6622101540 | AE10: 4 | AF10: ENTREGA DIRECTA | AG10: 1.441 | AH10: M3 | AI10: X | AJ10: 4 | AK10: V4 | AL10: 20230920 | AM10: D820-900005257-66493564-10115820-4
A11: 900005257D8206690379010115820 | B11: 4600041961-280 | C11: 4600041961 | D11: 280 | E11: MXPO | F11: MXL | G11: 900005257 | H11: SF TP - ED R & R | I11: 5068065 | J11: R R TRITURADOS SA DE CV | K11: N90 | L11: (AP) NAFIN 90 Dias | M11: 10115820 | N11: ARENA TRITURADA CALIZA MALLA 4 | O11: D820 | P11: MX-CED. AGUASCALIENTES | Q11: 20180501 | R11: 20291231 | S11: 20201027 | T11: 20291231 | U11: 235 | V11: MXN | W11: M3 | X11: 85 | Y11: MXN | Z11: M3 | AA11: 66903790 | AB11: PLANTA 2 SIGLO XXl | AC11: 56103638 | AD11: 6622101540 | AE11: 4 | AF11: ENTREGA DIRECTA | AG11: 1.441 | AH11: M3 | AI11: X | AJ11: 4 | AK11: V4 | AL11: 20230920 | AM11: D820-900005257-66903790-10115820-4
A12: 900005257D8206654551710115820 | B12: 4600041961-90 | C12: 4600041961 | D12: 90 | E12: MXPO | F12: MXL | G12: 900005257 | H12: SF TP - ED R & R | I12: 5068065 | J12: R R TRITURADOS SA DE CV | K12: N90 | L12: (AP) NAFIN 90 Dias | M12: 10115820 | N12: ARENA TRITURADA CALIZA MALLA 4 | O12: D820 | P12: MX-CED. AGUASCALIENTES | Q12: 20180501 | R12: 20291231 | S12: 20180604 | T12: 20241231 | U12: 235 | V12: MXN | W12: M3 | X12: 95 | Y12: MXN | Z12: M3 | AA12: 66545517 | AB12: BENOL PLANTA AGS | AC12: 56103638 | AD12: 6622101540 | AE12: 4 | AF12: ENTREGA DIRECTA | AG12: 1.441 | AH12: M3 | AI12: X | AJ12: 4 | AK12: V4 | AL12: 20230920 | AM12: D820-900005257-66545517-10115820-4
A13: 900005257D8206654551710112026 | B13: 4600041961-110 | C13: 4600041961 | D13: 110 | E13: MXPO | F13: MXL | G13: 900005257 | H13: SF TP - ED R & R | I13: 5068065 | J13: R R TRITURADOS SA DE CV | K13: N90 | L13: (AP) NAFIN 90 Dias | M13: 10112026 | N13: GRAVA TRITURADA CALIZA 40 MM - 1 1/2" | O13: D820 | P13: MX-CED. AGUASCALIENTES | Q13: 20180501 | R13: 20291231 | S13: 20180604 | T13: 20241231 | U13: 235 | V13: MXN | W13: M3 | X13: 95 | Y13: MXN | Z13: M3 | AA13: 66545517 | AB13: BENOL PLANTA AGS | AC13: 56103637 | AD13: 6622101540 | AE13: 4 | AF13: ENTREGA DIRECTA | AG13: 1.358 | AH13: M3 | AI13: X | AJ13: 4 | AK13: V4 | AL13: 20230920 | AM13: D820-900005257-66545517-10112026-4
A14: 900005257D8206516086410115820 | B14: 4600041961-230 | C14: 4600041961 | D14: 230 | E14: MXPO | F14: MXL | G14: 900005257 | H14: SF TP - ED R & R | I14: 5068065 | J14: R R TRITURADOS SA DE CV | K14: N90 | L14: (AP) NAFIN 90 Dias | M14: 10115820 | N14: ARENA TRITURADA CALIZA MALLA 4 | O14: D820 | P14: MX-CED. AGUASCALIENTES | Q14: 20180501 | R14: 20291231 | S14: 20201027 | T14: 20291231 | U14: 230 | V14: MXN | W14: M3 | X14: 85 | Y14: MXN | Z14: M3 | AA14: 65160864 | AB14: MARIO GARDUZA TOLEDO. | AC14: 56103638 | AD14: 6622101540 | AE14: 4 | AF14: ENTREGA DIRECTA | AG14: 1.441 | AH14: M3 | AI14: X | AJ14: 4 | AK14: V4 | AL14: 20230920 | AM14: D820-900005257-65160864-10115820-4
A15: 900000406D82010065029 | B15: 4600041941-30 | C15: 4600041941 | D15: 30 | E15: MXPO | F15: MXL | G15: 900000406 | H15: TP- MEXICANA DE CALES | I15: 5001279 | J15: MEXICANA DE CALES SA DE CV | K15: Z03 | L15: (AP) 15 Dias | M15: 10065029 | N15: GRAVA TRITURADA CALIZA 10 MM - 3/8" | O15: D820 | P15: MX-CED. AGUASCALIENTES | Q15: 20180427 | R15: 20241231 | S15: 20180901 | T15: 20241231 | U15: 138 | V15: MXN | W15: M3 | X15: 0 | Y15: MXN | Z15: M3 | AC15: 56103637 | AD15: 6622101540 | AE15: 1 | AF15: ENTREGADO | AG15: 1.479 | AH15: M3 | AI15: X | AJ15: 4 | AK15: V4 | AL15: 20230920 | AM15: D820-900000406-10065029
A16: 900000406D82010112090 | B16: 4600041941-40 | C16: 4600041941 | D16: 40 | E16: MXPO | F16: MXL | G16: 900000406 | H16: TP- MEXICANA DE CALES | I16: 5001279 | J16: MEXICANA DE CALES SA DE CV | K16: Z03 | L16: (AP) 15 Dias | M16: 10112090 | N16: GRAVA TRITURADA CALIZA 20 MM - 3/4" | O16: D820 | P16: MX-CED. AGUASCALIENTES | Q16: 20180427 | R16: 20241231 | S16: 20180901 | T16: 20241231 | U16: 133.98 | V16: MXN | W16: M3 | X16: 0 | Y16: MXN | Z16: M3 | AC16: 56103637 | AD16: 6622101540 | AE16: 1 | AF16: ENTREGADO | AG16: 1.389 | AH16: M3 | AI16: X | AJ16: 4 | AK16: V4 | AL16: 20230920 | AM16: D820-900000406-10112090
A17: 900000406D82010000621 | B17: 4600041941-20 | C17: 4600041941 | D17: 20 | E17: MXPO | F17: MXL | G17: 900000406 | H17: TP- MEXICANA DE CALES | I17: 5001279 | J17: MEXICANA DE CALES SA DE CV | K17: Z03 | L17: (AP) 15 Dias | M17: 10000621 | N17: Grava Triturada Caliza 40 mm - 1 1/2" | O17: D820 | P17: MX-CED. AGUASCALIENTES | Q17: 20180427 | R17: 20241231 | S17: 20180901 | T17: 20241231 | U17: 192.5 | V17: MXN | W17: M3 | X17: 0 | Y17: MXN | Z17: M3 | AC17: 56103637 | AD17: 6622101540 | AE17: 1 | AF17: ENTREGADO | AG17: 1.49 | AH17: M3 | AI17: X | AJ17: 4 | AK17: V4 | AL17: 20230920 | AM17: D820-900000406-10000621
A18: 900000406D82010000791 | B18: 4600041941-10 | C18: 4600041941 | D18: 10 | E18: MXPO | F18: MXL | G18: 900000406 | H18: TP- MEXICANA DE CALES | I18: 5001279 | J18: MEXICANA DE CALES SA DE CV | K18: Z03 | L18: (AP) 15 Dias | M18: 10000791 | N18: Arena Triturada Caliza Malla 4 | O18: D820 | P18: MX-CED. AGUASCALIENTES | Q18: 20180427 | R18: 20241231 | S18: 20180901 | T18: 20241231 | U18: 130.77 | V18: MXN | W18: M3 | X18: 0 | Y18: MXN | Z18: M3 | AC18: 56103638 | AD18: 6622101540 | AE18: 1 | AF18: ENTREGADO | AG18: 1.408 | AH18: M3 | AI18: X | AJ18: 4 | AK18: V4 | AL18: 20230920 | AM18: D820-900000406-10000791
A19: 900005257D8206629152410115821 | B19: 4600041961-10 | C19: 4600041961 | D19: 10 | E19: MXPO | F19: MXL | G19: 900005257 | H19: SF TP - ED R & R | I19: 5068065 | J19: R R TRITURADOS SA DE CV | K19: N90 | L19: (AP) NAFIN 90 Dias | M19: 10115821 | N19: GRAVA TRITURADA CALIZA 20 MM - 3/4" | O19: D820 | P19: MX-CED. AGUASCALIENTES | Q19: 20180501 | R19: 20291231 | S19: 20180501 | T19: 20241231 | U19: 218 | V19: MXN | W19: M3 | X19: 78 | Y19: MXN | Z19: M3 | AA19: 66291524 | AB19: K&S CONCRETOS S.A. DE C.V. | AC19: 56103637 | AD19: 6622101540 | AE19: 4 | AF19: ENTREGA DIRECTA | AG19: 1.308 | AH19: M3 | AI19: X | AJ19: 4 | AK19: V4 | AL19: 20230920 | AM19: D820-900005257-66291524-10115821-4
A20: 900005257D8206645773910115821 | B20: 4600041961-70 | C20: 4600041961 | D20: 70 | E20: MXPO | F20: MXL | G20: 900005257 | H20: SF TP - ED R & R | I20: 5068065 | J20: R R TRITURADOS SA DE CV | K20: N90 | L20: (AP) NAFIN 90 Dias | M20: 10115821 | N20: GRAVA TRITURADA CALIZA 20 MM - 3/4" | O20: D820 | P20: MX-CED. AGUASCALIENTES | Q20: 20180501 | R20: 20291231 | S20: 20180507 | T20: 20241231 | U20: 218 | V20: MXN | W20: M3 | X20: 78 | Y20: MXN | Z20: M3 | AA20: 66457739 | AB20: GRUPO CONSTRUCTOR MAYESJA | AC20: 56103637 | AD20: 6622101540 | AE20: 4 | AF20: ENTREGA DIRECTA | AG20: 1.308 | AH20: M3 | AI20: X | AJ20: 4 | AK20: V4 | AL20: 20230920 | AM20: D820-900005257-66457739-10115821-4
A21: 900005257D8206629152410112026 | B21: 4600041961-20 | C21: 4600041961 | D21: 20 | E21: MXPO | F21: MXL | G21: 900005257 | H21: SF TP - ED R & R | I21: 5068065 | J21: R R TRITURADOS SA DE CV | K21: N90 | L21: (AP) NAFIN 90 Dias | M21: 10112026 | N21: GRAVA TRITURADA CALIZA 40 MM - 1 1/2" | O21: D820 | P21: MX-CED. AGUASCALIENTES | Q21: 20180501 | R21: 20291231 | S21: 20180501 | T21: 20241231 | U21: 218 | V21: MXN | W21: M3 | X21: 78 | Y21: MXN | Z21: M3 | AA21: 66291524 | AB21: K&S CONCRETOS S.A. DE C.V. | AC21: 56103637 | AD21: 6622101540 | AE21: 4 | AF21: ENTREGA DIRECTA | AG21: 1.358 | AH21: M3 | AI21: X | AJ21: 4 | AK21: V4 | AL21: 20230920 | AM21: D820-900005257-66291524-10112026-4
A22: 900005257D8206645773910112026 | B22: 4600041961-80 | C22: 4600041961 | D22: 80 | E22: MXPO | F22: MXL | G22: 900005257 | H22: SF TP - ED R & R | I22: 5068065 | J22: R R TRITURADOS SA DE CV | K22: N90 | L22: (AP) NAFIN 90 Dias | M22: 10112026 | N22: GRAVA TRITURADA CALIZA 40 MM - 1 1/2" | O22: D820 | P22: MX-CED. AGUASCALIENTES | Q22: 20180501 | R22: 20291231 | S22: 20180507 | T22: 20241231 | U22: 218 | V22: MXN | W22: M3 | X22: 78 | Y22: MXN | Z22: M3 | AA22: 66457739 | AB22: GRUPO CONSTRUCTOR MAYESJA | AC22: 56103637 | AD22: 6622101540 | AE22: 4 | AF22: ENTREGA DIRECTA | AG22: 1.358 | AH22: M3 | AI22: X | AJ22: 4 | AK22: V4 | AL22: 20230920 | AM22: D820-900005257-66457739-10112026-4
A23: 900005257D8206690379010187515 | B23: 4600041961-310 | C23: 4600041961 | D23: 310 | E23: MXPO | F23: MXL | G23: 900005257 | H23: SF TP - ED R & R | I23: 5068065 | J23: R R TRITURADOS SA DE CV | K23: N90 | L23: (AP) NAFIN 90 Dias | M23: 10187515 | N23: ARENA TRITURADA CALIZA MALLA 4 | O23: D820 | P23: MX-CED. AGUASCALIENTES | Q23: 20180501 | R23: 20291231 | S23: 20210927 | T23: 20261231 | U23: 246.75 | V23: MXN | W23: M3 | X23: 96 | Y23: MXN | Z23: M3 | AA23: 66903790 | AB23: PLANTA 2 SIGLO XXl | AC23: 56103638 | AD23: 6622101540 | AE23: 4 | AF23: ENTREGA DIRECTA | AG23: 1.75 | AH23: M3 | AI23: X | AJ23: 4 | AK23: V4 | AL23: 20230920 | AM23: D820-900005257-66903790-10187515-4
A24: 900006398D8206543601110171540 | B24: 4600046174-10 | C24: 4600046174 | D24: 10 | E24: MXPO | F24: MXL | G24: 900006398 | H24: SF TP-ED- IMHASA | I24: 5075596 | J24: CONSTRUCTORA DE REFRESQUEROS | K24: Z09 | L24: (AP) 90 Dias | M24: 10171540 | N24: ARENA TRITURADA CALIZA MALLA 4 | O24: D820 | P24: MX-CED. AGUASCALIENTES | Q24: 20191212 | R24: 20241231 | S24: 20191212 | T24: 20241231 | U24: 240 | V24: MXN | W24: M3 | X24: 68 | Y24: MXN | Z24: M3 | AA24: 65436011 | AB24: MATRA CONCRETOS SA DE CV. | AC24: 56103638 | AD24: 6622101540 | AE24: 4 | AF24: ENTREGA DIRECTA | AG24: 1.52 | AH24: M3 | AI24: X | AJ24: 4 | AK24: V4 | AL24: 20230920 | AM24: D820-900006398-65436011-10171540-4
A25: 900005257D8206700865310187515 | B25: 4600041961-340 | C25: 4600041961 | D25: 340 | E25: MXPO | F25: MXL | G25: 900005257 | H25: SF TP - ED R & R | I25: 5068065 | J25: R R TRITURADOS SA DE CV | K25: N90 | L25: (AP) NAFIN 90 Dias | M25: 10187515 | N25: ARENA TRITURADA CALIZA MALLA 4 | O25: D820 | P25: MX-CED. AGUASCALIENTES | Q25: 20180501 | R25: 20291231 | S25: 20210927 | T25: 20261231 | U25: 246.75 | V25: MXN | W25: M3 | X25: 96 | Y25: MXN | Z25: M3 | AA25: 67008653 | AB25: PLANTA 2 SIGLO XXI (AGG) | AC25: 56103638 | AD25: 6622101540 | AE25: 4 | AF25: ENTREGA DIRECTA | AG25: 1.75 | AH25: M3 | AI25: X | AJ25: 4 | AK25: V4 | AL25: 20230920 | AM25: D820-900005257-67008653-10187515-4
A26: 900005257D8206690379010115821 | B26: 4600041961-320 | C26: 4600041961 | D26: 320 | E26: MXPO | F26: MXL | G26: 900005257 | H26: SF TP - ED R & R | I26: 5068065 | J26: R R TRITURADOS SA DE CV | K26: N90 | L26: (AP) NAFIN 90 Dias | M26: 10115821 | N26: GRAVA TRITURADA CALIZA 20 MM - 3/4" | O26: D820 | P26: MX-CED. AGUASCALIENTES | Q26: 20180501 | R26: 20291231 | S26: 20210927 | T26: 20261231 | U26: 241.5 | V26: MXN | W26: M3 | X26: 96 | Y26: MXN | Z26: M3 | AA26: 66903790 | AB26: PLANTA 2 SIGLO XXl | AC26: 56103637 | AD26: 6622101540 | AE26: 4 | AF26: ENTREGA DIRECTA | AG26: 1.308 | AH26: M3 | AI26: X | AJ26: 4 | AK26: V4 | AL26: 20230920 | AM26: D820-900005257-66903790-10115821-4
A27: 900006398D8206543601110171541 | B27: 4600046174-20 | C27: 4600046174 | D27: 20 | E27: MXPO | F27: MXL | G27: 900006398 | H27: SF TP-ED- IMHASA | I27: 5075596 | J27: CONSTRUCTORA DE REFRESQUEROS | K27: Z09 | L27: (AP) 90 Dias | M27: 10171541 | N27: GRAVA TRITURADA CALIZA 20 MM - 3/4" | O27: D820 | P27: MX-CED. AGUASCALIENTES | Q27: 20191212 | R27: 20241231 | S27: 20191212 | T27: 20241231 | U27: 240 | V27: MXN | W27: M3 | X27: 68 | Y27: MXN | Z27: M3 | AA27: 65436011 | AB27: MATRA CONCRETOS SA DE CV. | AC27: 56103637 | AD27: 6622101540 | AE27: 4 | AF27: ENTREGA DIRECTA | AG27: 1.29 | AH27: M3 | AI27: X | AJ27: 4 | AK27: V4 | AL27: 20230920 | AM27: D820-900006398-65436011-10171541-4
A28: 900005257D8206690379010112026 | B28: 4600041961-330 | C28: 4600041961 | D28: 330 | E28: MXPO | F28: MXL | G28: 900005257 | H28: SF TP - ED R & R | I28: 5068065 | J28: R R TRITURADOS SA DE CV | K28: N90 | L28: (AP) NAFIN 90 Dias | M28: 10112026 | N28: GRAVA TRITURADA CALIZA 40 MM - 1 1/2" | O28: D820 | P28: MX-CED. AGUASCALIENTES | Q28: 20180501 | R28: 20291231 | S28: 20210927 | T28: 20261231 | U28: 241.5 | V28: MXN | W28: M3 | X28: 96 | Y28: MXN | Z28: M3 | AA28: 66903790 | AB28: PLANTA 2 SIGLO XXl | AC28: 56103637 | AD28: 6622101540 | AE28: 4 | AF28: ENTREGA DIRECTA | AG28: 1.358 | AH28: M3 | AI28: X | AJ28: 4 | AK28: V4 | AL28: 20230920 | AM28: D820-900005257-66903790-10112026-4
A29: 900005257D8206700865310115821 | B29: 4600041961-350 | C29: 4600041961 | D29: 350 | E29: MXPO | F29: MXL | G29: 900005257 | H29: SF TP - ED R & R | I29: 5068065 | J29: R R TRITURADOS SA DE CV | K29: N90 | L29: (AP) NAFIN 90 Dias | M29: 10115821 | N29: GRAVA TRITURADA CALIZA 20 MM - 3/4" | O29: D820 | P29: MX-CED. AGUASCALIENTES | Q29: 20180501 | R29: 20291231 | S29: 20210927 | T29: 20261231 | U29: 241.5 | V29: MXN | W29: M3 | X29: 96 | Y29: MXN | Z29: M3 | AA29: 67008653 | AB29: PLANTA 2 SIGLO XXI (AGG) | AC29: 56103637 | AD29: 6622101540 | AE29: 4 | AF29: ENTREGA DIRECTA | AG29: 1.308 | AH29: M3 | AI29: X | AJ29: 4 | AK29: V4 | AL29: 20230920 | AM29: D820-900005257-67008653-10115821-4
A30: 900005257D8206700865310112026 | B30: 4600041961-360 | C30: 4600041961 | D30: 360 | E30: MXPO | F30: MXL | G30: 900005257 | H30: SF TP - ED R & R | I30: 5068065 | J30: R R TRITURADOS SA DE CV | K30: N90 | L30: (AP) NAFIN 90 Dias | M30: 10112026 | N30: GRAVA TRITURADA CALIZA 40 MM - 1 1/2" | O30: D820 | P30: MX-CED. AGUASCALIENTES | Q30: 20180501 | R30: 20291231 | S30: 20210927 | T30: 20261231 | U30: 241.5 | V30: MXN | W30: M3 | X30: 96 | Y30: MXN | Z30: M3 | AA30: 67008653 | AB30: PLANTA 2 SIGLO XXI (AGG) | AC30: 56103637 | AD30: 6622101540 | AE30: 4 | AF30: ENTREGA DIRECTA | AG30: 1.358 | AH30: M3 | AI30: X | AJ30: 4 | AK30: V4 | AL30: 20230920 | AM30: D820-900005257-67008653-10112026-4
... A61: 900005257D8206721548510187515 | B61: 4600041961-410 | C61: 4600041961 | D61: 410 | E61: MXPO | F61: MXL | G61: 900005257 | H61: SF TP - ED R & R | I61: 5068065 | J61: R R TRITURADOS SA DE CV | K61: N90 | L61: (AP) NAFIN 90 Dias | M61: 10187515 | N61: ARENA TRITURADA CALIZA MALLA 4 | O61: D820 | P61: MX-CED. AGUASCALIENTES | Q61: 20180501 | R61: 20291231 | S61: 20240320 | T61: 20291231 | U61: 365 | V61: MXN | W61: M3 | X61: 150 | Y61: MXN | Z61: M3 | AA61: 67215485 | AB61: PLANTA PARQUE INDUSTRIAL SIGLO XXI | AC61: 56103638 | AD61: 6622101540 | AE61: 4 | AF61: ENTREGA DIRECTA | AG61: 1.75 | AH61: M3 | AI61: X | AJ61: 4 | AK61: V4 | AL61: 20240325 | AM61: D820-900005257-67215485-10187515-4
