Workbook

Sheet Materiales,canteras
A1: No. Cantera | B1: Nombre Cantera | C1: Material | D1: Denominación | E1: PV
A2: D813 | B2: MX-CANTERA SAN VICENTE | C2: 10000252 | D2: Grava Triturada Andesita 10 mm | E2: 1.234
A3: D813 | B3: MX-CANTERA SAN VICENTE | C3: 10000253 | D3: Grava Triturada Andesita 20 mm | E3: 1.385
A4: D813 | B4: MX-CANTERA SAN VICENTE | C4: 10000255 | D4: Arena Triturada Andesita Malla | E4: 1.535
A5: D813 | B5: MX-CANTERA SAN VICENTE | C5: 10001091 | D5: Balasto Triturado Andesita 150 | E5: 1.4
A6: D813 | B6: MX-CANTERA SAN VICENTE | C6: 10002350 | D6: Grava Triturada Andesita 10mm- | E6: 1.246
A7: D813 | B7: MX-CANTERA SAN VICENTE | C7: 10029946 | D7: Arena Triturada Andesita Malla | E7: 1.494
A8: D813 | B8: MX-CANTERA SAN VICENTE | C8: 10032959 | D8: Grava Triturada Andesita 50 mm | E8: 1.279
A9: D813 | B9: MX-CANTERA SAN VICENTE | C9: 10000305 | D9: Tepetate Clasificado Tierra | E9: 1.3
A10: D861 | B10: MX-CANTERA QUERETARO | C10: 10000229 | D10: Grava Triturada Basalto 10 mm | E10: 1.522
A11: D861 | B11: MX-CANTERA QUERETARO | C11: 10000231 | D11: Grava Triturada Basalto 20 mm | E11: 1.565
A12: D861 | B12: MX-CANTERA QUERETARO | C12: 10000233 | D12: Grava Triturada Basalto 40 mm | E12: 1.456
A13: D861 | B13: MX-CANTERA QUERETARO | C13: 10000311 | D13: Arena Triturada Basalto Malla | E13: 1.651
... A111: D917 | B111: MX-CANTERA VALLES AGG | C111: 10248659 | D111: ARENA NO. 4 | E111: 1.673
A112: D824 | B112: MX-CANTERA LEON | C112: 10023108 | D112: =VLOOKUP(C112,'[1]Precio Base '!$D$2:$E$22,2,FALSE) -> Base H Triturada Basalto 1 1/2" a Finos | E112: 1.969
A113: DU07 | B113: MX-CANCÚN III | C113: 10000195 | D113: GRAVA TRITURADA CALIZA 20 MM - 3/4"–CAPA | E113: 1.201
A114: D824 | B114: MX-CANTERA LEON | C114: 10001077 | D114: Crudo Basalto | E114: 1.35
A115: D824 | B115: MX-CANTERA LEON | C115: 10191647 | D115: BALASTO 6# A 3# | E115: 1.441
A116: D824 | B116: MX-CANTERA LEON | C116: 10000289 | D116: Desperdicio Triturado Basalto | E116: 1.55
A117: D816 | B117: MX-CANTERA MONTERREY | C117: 10000248 | D117: Sub-base Triturado Caliza 1 1/2" a Finos | E117: 1.821
A118: D816 | B118: MX-CANTERA MONTERREY | C118: 10269042 | D118: NO CLASIFICADO BALASTO B9 | E118: 1.456
A119: D893 | B119: MX-CANTERA TIJUANA II | C119: 10038957 | D119: Arena Triturada Caliza Block | E119: 1.687
A120: D902 | B120: MX-CALKINI | C120: 10269105 | D120: BALASTO DE 2 ½” DESPERDICIO | E120: 1.494
A121: D816 | B121: MX-CANTERA MONTERREY | C121: 10001222 | D121: Mixto Grava 3/4 - Arena 4 | E121: 1.613
A122: D879 | B122: EPV AGG TAMUIN | C122: 10258182 | D122: SOBRETAMAÑO ROCA NATURAL DE 0.5 A 0.80TN | E122: 1.625
A123: D879 | B123: EPV AGG TAMUIN | C123: 10258183 | D123: SOBRETAMAÑO ROCA NATURAL DE 0.8 A 1.2 TN | E123: 1.625
A124: D879 | B124: EPV AGG TAMUIN | C124: 10258184 | D124: SOBRETAMAÑO ROCA NATURAL DE 0.2 A 0.56TN | E124: 1.625
... A131: D816 | B131: MX-CANTERA MONTERREY | C131: 10148824 | D131: BALASTO PIEDRA CALIZA 4"-6" | E131: 1.5
C132: 10038955 | D132: Base H Triturada Caliza 1 1/2" a Finos | E132: 1.925
A133: D864 | B133: MX-CANTERA CERRO JARDIN | C133: 10279531 | D133: CRUDO CALIZA TIPO B | E133: 1.5

Sheet NO MODIFICAR
A1: No. Cantera | B1: Nombre Cantera | F1: No. Cantera | G1: Nombre Cantera | J1: Nombre Cantera | K1: No. Cantera
A2: D813 | B2: MX-CANTERA SAN VICENTE | C2: c | D2: CENTRO | E2: TN | F2: D813 | G2: MX-CANTERA SAN VICENTE | H2: CENTRO | J2: MX-CANTERA SAN VICENTE | K2: D813
A3: D816 | B3: MX-CANTERA MONTERREY | C3: n | D3: SURESTE | E3: M3 | F3: D861 | G3: MX-CANTERA QUERETARO | H3: CENTRO | J3: MX-CANTERA QUERETARO | K3: D861
A4: D824 | B4: MX-CANTERA LEON | C4: n | F4: D864 | G4: MX-CANTERA CERRO JARDIN | H4: CENTRO | J4: MX-CANTERA CERRO JARDIN | K4: D864
A5: D852 | B5: MX-CANTERA TORREON II | C5: n | F5: D873 | G5: MX-VIRTUAL VALLEJO | H5: CENTRO | J5: MX-VIRTUAL VALLEJO | K5: D873
A6: D861 | B6: MX-CANTERA QUERETARO | C6: c | F6: D902 | G6: MX-CALKINI | H6: SURESTE | J6: MX-CALKINI | K6: D902
A7: D863 | B7: MX-CANTERA TAMUIN | C7: n | F7: DU07 | G7: MX-CANCÚN III | H7: SURESTE | J7: MX-CANCÚN III | K7: DU07
A8: D864 | B8: MX-CANTERA CERRO JARDIN | C8: c | F8: D816 | G8: MX-CANTERA MONTERREY | H8: NORESTE | J8: MX-CANTERA MONTERREY | K8: D816
A9: D866 | B9: MX-CANTERA PONCITLAN | C9: n | F9: D893 | G9: CANTERA TIJUANA II | H9: NORESTE | J9: CANTERA TIJUANA II | K9: D893
A10: D873 | B10: MX-VIRTUAL VALLEJO | C10: c | F10: D917 | G10: MX-CANTERA VALLES AGG | H10: NORESTE | J10: MX-CANTERA VALLES AGG | K10: D917
A11: D893 | B11: MX-CANTERA TIJUANA II | C11: n | F11: D824 | G11: MX-CANTERA LEON | H11: NORESTE | J11: MX-CANTERA PONCITLAN | K11: D866
A12: D902 | B12: MX-CALKINI | C12: c | F12: D866 | G12: MX-CANTERA PONCITLAN | H12: NORESTE | J12: MX-CANTERA TORREON II | K12: D852
A13: D917 | B13: MX-CANTERA VALLES AGG | C13: n | F13: D852 | G13: MX-CANTERA TORREON II | H13: NORESTE | J13: MX-CANTERA LEON | K13: D824
A14: DU07 | B14: MX-CANCÚN III | C14: c | F14: D863 | G14: MX-CANTERA TAMUIN | H14: NORESTE | J14: MX-CANTERA TAMUIN | K14: D863
F15: D815 | G15: CANTERA TESISTAN | H15: NORESTE
F16: D879 | G16: EPV AGG TAMUIN | H16: NORESTE

Sheet Formato Alta Precio
A1: No. | B1: Mes de solicitud | C1: Llave | D1: Centro | E1: Nombre planta | F1: Nueva ZONA | G1: Dest.mercancías | H1: Nombre del Destinatario | I1: Material | J1: Nombre de Material | K1: PV | L1: Precio solicitado | M1: UM | N1: Válido de | O1: Validez a | P1: desc prod | Q1: desc Tamaño | R1: Desc Contado | S1: Precio de lista | T1: GAP | U1: Precio Final Sistema | V1: Flete | W1: Modalidad (01 Entregado,02 Recogido) | X1: Precio Total | Y1: VOBO SOLICITADO | Z1: Precio Referencia | AA1: % de Descuento | AB1: Validación 1 | AC1: Validación 2 | AD1: Observaciones
A2: 1 | C2: =_xlfn.CONCAT($C$1,D2,G2,I2,W2) -> LlaveD86466883318100010731 | D2: =VLOOKUP(E2,'NO MODIFICAR'!J:K,2,0) -> D864 | E2: MX-CANTERA CERRO JARDIN | F2: =VLOOKUP(D2,'NO MODIFICAR'!F:H,3,0) -> CENTRO | G2: 66883318 | H2: CONCRETOS HIDALGO | I2: 10001073 | J2: =VLOOKUP(I2,'Materiales,canteras'!C:D,2,0) -> Arena Triturada Caliza Malla 4 | K2: =VLOOKUP(I2,'Materiales,canteras'!C:E,3,0) -> 1.56 | L2: 115.46 | M2: TN | N2: =TODAY() -> 46267 | O2: 31.12.9999 | S2: 150 | T2: =L2-S2 -> -34.54 | U2: =L2 -> 115.46 | V2: 76 | W2: 1 | X2: =V2+U2 -> 191.46 | Y2: =IF(+VLOOKUP(I2,P.Referencia!E:S,3,FALSE)<=L2,"Champion","Gerente") -> #N/A | Z2: =VLOOKUP(I2,P.Referencia!E:S,3,0) -> #N/A | AA2: =(Z2-U2)/U2 -> #N/A | AB2: =U2*AA2 -> #N/A | AC2: =U2+AB2 -> #N/A
A3: 2 | C3: =_xlfn.CONCAT($C$1,D3,G3,I3,W3) -> LlaveD86466883318100002361 | D3: =VLOOKUP(E3,'NO MODIFICAR'!J:K,2,0) -> D864 | E3: MX-CANTERA CERRO JARDIN | F3: =VLOOKUP(D3,'NO MODIFICAR'!F:H,3,0) -> CENTRO | G3: 66883318 | H3: CONCRETOS HIDALGO | I3: 10000236 | J3: =VLOOKUP(I3,'Materiales,canteras'!C:D,2,0) -> Grava Triturada Caliza 10 mm - | K3: =VLOOKUP(I3,'Materiales,canteras'!C:E,3,0) -> 1.41 | L3: 145 | M3: TN | N3: =TODAY() -> 46267 | O3: 31.12.9999 | T3: =L3-S3 -> 145 | U3: =L3 -> 145 | V3: 76 | W3: 1 | X3: =V3+U3 -> 221 | Y3: =IF(+VLOOKUP(I3,P.Referencia!E:S,3,FALSE)<=L3,"Champion","Gerente") -> #N/A | Z3: =VLOOKUP(I3,P.Referencia!E:S,3,0) -> #N/A | AA3: =(Z3-U3)/U3 -> #N/A | AB3: =U3*AA3 -> #N/A | AC3: =U3+AB3 -> #N/A
A4: 3 | C4: =_xlfn.CONCAT($C$1,D4,G4,I4,W4) -> LlaveD86466883318100002401 | D4: =VLOOKUP(E4,'NO MODIFICAR'!J:K,2,0) -> D864 | E4: MX-CANTERA CERRO JARDIN | F4: =VLOOKUP(D4,'NO MODIFICAR'!F:H,3,0) -> CENTRO | G4: 66883318 | H4: CONCRETOS HIDALGO | I4: 10000240 | J4: =VLOOKUP(I4,'Materiales,canteras'!C:D,2,0) -> Grava Triturada Caliza 20 mm - | K4: =VLOOKUP(I4,'Materiales,canteras'!C:E,3,0) -> 1.462 | L4: 145 | M4: TN | N4: =TODAY() -> 46267 | O4: 31.12.9999 | T4: =L4-S4 -> 145 | U4: =L4 -> 145 | V4: 76 | W4: 1 | X4: =V4+U4 -> 221 | Y4: =IF(+VLOOKUP(I4,P.Referencia!E:S,3,FALSE)<=L4,"Champion","Gerente") -> #N/A | Z4: =VLOOKUP(I4,P.Referencia!E:S,3,0) -> #N/A | AA4: =(Z4-U4)/U4 -> #N/A | AB4: =U4*AA4 -> #N/A | AC4: =U4+AB4 -> #N/A
A5: 4 | C5: =_xlfn.CONCAT($C$1,D5,G5,I5,W5) -> LlaveD86466883318100002691 | D5: =VLOOKUP(E5,'NO MODIFICAR'!J:K,2,0) -> D864 | E5: MX-CANTERA CERRO JARDIN | F5: =VLOOKUP(D5,'NO MODIFICAR'!F:H,3,0) -> CENTRO | G5: 66883318 | H5: CONCRETOS HIDALGO | I5: 10000269 | J5: =VLOOKUP(I5,'Materiales,canteras'!C:D,2,0) -> Grava Triturada Caliza 13 mm - | K5: =VLOOKUP(I5,'Materiales,canteras'!C:E,3,0) -> 1.423 | L5: 161.2 | M5: TN | N5: =TODAY() -> 46267 | O5: 31.12.9999 | T5: =L5-S5 -> 161.2 | U5: =L5 -> 161.2 | V5: 76 | W5: 1 | X5: =V5+U5 -> 237.2 | Y5: =IF(+VLOOKUP(I5,P.Referencia!E:S,3,FALSE)<=L5,"Champion","Gerente") -> #N/A | Z5: =VLOOKUP(I5,P.Referencia!E:S,3,0) -> #N/A | AA5: =(Z5-U5)/U5 -> #N/A | AB5: =U5*AA5 -> #N/A | AC5: =U5+AB5 -> #N/A
A6: 5 | C6: =_xlfn.CONCAT($C$1,D6,G6,I6,W6) -> LlaveD86466883318100010741 | D6: =VLOOKUP(E6,'NO MODIFICAR'!J:K,2,0) -> D864 | E6: MX-CANTERA CERRO JARDIN | F6: =VLOOKUP(D6,'NO MODIFICAR'!F:H,3,0) -> CENTRO | G6: 66883318 | H6: CONCRETOS HIDALGO | I6: 10001074 | J6: =VLOOKUP(I6,'Materiales,canteras'!C:D,2,0) -> Grava Triturada Caliza 40 mm - | K6: =VLOOKUP(I6,'Materiales,canteras'!C:E,3,0) -> 1.4 | L6: 147 | M6: TN | N6: =TODAY() -> 46267 | O6: 31.12.9999 | T6: =L6-S6 -> 147 | U6: =L6 -> 147 | V6: 76 | W6: 1 | X6: =V6+U6 -> 223 | Y6: =IF(+VLOOKUP(I6,P.Referencia!E:S,3,FALSE)<=L6,"Champion","Gerente") -> #N/A | Z6: =VLOOKUP(I6,P.Referencia!E:S,3,0) -> #N/A | AA6: =(Z6-U6)/U6 -> #N/A | AB6: =U6*AA6 -> #N/A | AC6: =U6+AB6 -> #N/A
A7: 6 | C7: =_xlfn.CONCAT($C$1,D7,G7,I7,W7) -> LlaveD86167316915100002902 | D7: =VLOOKUP(E7,'NO MODIFICAR'!J:K,2,0) -> D861 | E7: MX-CANTERA QUERETARO | F7: =VLOOKUP(D7,'NO MODIFICAR'!F:H,3,0) -> CENTRO | G7: 67316915 | H7: PARQUE PYME RECOGIDO | I7: 10000290 | J7: =VLOOKUP(I7,'Materiales,canteras'!C:D,2,0) -> Polvos Triturado Basalto 3/4" | K7: =VLOOKUP(I7,'Materiales,canteras'!C:E,3,0) -> 1.372 | L7: 1.5 | M7: TN | N7: =TODAY() -> 46267 | O7: 31.12.9999 | S7: 25 | T7: =L7-S7 -> -23.5 | U7: =L7 -> 1.5 | V7: 0 | W7: 2 | X7: =V7+U7 -> 1.5 | Y7: =IF(+VLOOKUP(I7,P.Referencia!E:S,3,FALSE)<=L7,"Champion","Gerente") -> #N/A | Z7: =VLOOKUP(I7,P.Referencia!E:S,3,0) -> #N/A | AA7: =(Z7-U7)/U7 -> #N/A | AB7: =U7*AA7 -> #N/A | AC7: =U7+AB7 -> #N/A | AD7: PENDIENTE VOBO DE LALO LÓPEZ | AE7: CORREO SANDRA
A8: 7 | C8: =_xlfn.CONCAT($C$1,D8,G8,I8,W8) -> LlaveD86166781275100002901 | D8: =VLOOKUP(E8,'NO MODIFICAR'!J:K,2,0) -> D861 | E8: MX-CANTERA QUERETARO | F8: =VLOOKUP(D8,'NO MODIFICAR'!F:H,3,0) -> CENTRO | G8: 66781275 | H8: ASFALTO CAÑADA | I8: 10000290 | J8: =VLOOKUP(I8,'Materiales,canteras'!C:D,2,0) -> Polvos Triturado Basalto 3/4" | K8: =VLOOKUP(I8,'Materiales,canteras'!C:E,3,0) -> 1.372 | L8: 1 | M8: TN | N8: =TODAY() -> 46267 | O8: 31.12.9999 | S8: 25 | T8: =L8-S8 -> -24 | U8: =L8 -> 1 | V8: 66.49 | W8: 1 | X8: =V8+U8 -> 67.49 | Y8: =IF(+VLOOKUP(I8,P.Referencia!E:S,3,FALSE)<=L8,"Champion","Gerente") -> #N/A | Z8: =VLOOKUP(I8,P.Referencia!E:S,3,0) -> #N/A | AA8: =(Z8-U8)/U8 -> #N/A | AB8: =U8*AA8 -> #N/A | AC8: =U8+AB8 -> #N/A | AD8: PENDIENTE VOBO DE LALO LÓPEZ | AE8: CORREO CARLOS
A9: 8 | C9: =_xlfn.CONCAT($C$1,D9,G9,I9,W9) -> LlaveD86166617693100014501 | D9: =VLOOKUP(E9,'NO MODIFICAR'!J:K,2,0) -> D861 | E9: MX-CANTERA QUERETARO | F9: =VLOOKUP(D9,'NO MODIFICAR'!F:H,3,0) -> CENTRO | G9: 66617693 | H9: LA ROCA MAYORAZGO | I9: 10001450 | J9: =VLOOKUP(I9,'Materiales,canteras'!C:D,2,0) -> Base Hidraúlica Basalto de 1 /1/2 | K9: =VLOOKUP(I9,'Materiales,canteras'!C:E,3,0) -> 1.749 | L9: 218.28 | M9: TN | N9: =TODAY() -> 46267 | O9: 31.12.9999 | S9: 260 | T9: =L9-S9 -> -41.72 | U9: =L9 -> 218.28 | V9: 70 | W9: 1 | X9: =V9+U9 -> 288.28 | Y9: Gerente | Z9: 222 | AA9: =(Z9-U9)/U9 -> 0.017042331 | AB9: =U9*AA9 -> 3.72 | AC9: =U9+AB9 -> 222 | AD9: PENDIENTE VOBO DE JORGE/ RICARDO
A10: 9 | C10: =_xlfn.CONCAT($C$1,D10,G10,I10,W10) -> LlaveD86166617693100002311 | D10: =VLOOKUP(E10,'NO MODIFICAR'!J:K,2,0) -> D861 | E10: MX-CANTERA QUERETARO | F10: =VLOOKUP(D10,'NO MODIFICAR'!F:H,3,0) -> CENTRO | G10: 66617693 | H10: LA ROCA MAYORAZGO | I10: 10000231 | J10: =VLOOKUP(I10,'Materiales,canteras'!C:D,2,0) -> Grava Triturada Basalto 20 mm | K10: =VLOOKUP(I10,'Materiales,canteras'!C:E,3,0) -> 1.565 | L10: 203.9 | M10: TN | N10: =TODAY() -> 46267 | O10: 31.12.9999 | S10: 280 | T10: =L10-S10 -> -76.1 | U10: =L10 -> 203.9 | V10: 75.58 | W10: 1 | X10: =V10+U10 -> 279.48 | Y10: =IF(+VLOOKUP(I10,P.Referencia!E:S,3,FALSE)<=L10,"Champion","Gerente") -> #N/A | Z10: =VLOOKUP(I10,P.Referencia!E:S,3,0) -> #N/A | AA10: =(Z10-U10)/U10 -> #N/A | AB10: =U10*AA10 -> #N/A | AC10: =U10+AB10 -> #N/A | AD10: PENDIENTE VOBO DE JORGE/ RICARDO
A11: 10 | C11: =_xlfn.CONCAT($C$1,D11,G11,I11,W11) -> LlaveD81365014664100002551 | D11: =VLOOKUP(E11,'NO MODIFICAR'!J:K,2,0) -> D813 | E11: MX-CANTERA SAN VICENTE | F11: =VLOOKUP(D11,'NO MODIFICAR'!F:H,3,0) -> CENTRO | G11: 65014664 | H11: OBR-AGR IBM (DLC) | I11: 10000255 | J11: =VLOOKUP(I11,'Materiales,canteras'!C:D,2,0) -> Arena Triturada Andesita Malla | K11: =VLOOKUP(I11,'Materiales,canteras'!C:E,3,0) -> 1.535 | N11: =TODAY() -> 46267 | O11: 31.12.9999 | T11: =L11-S11 -> 0 | U11: =L11 -> 0 | V11: 58.73 | W11: 1 | X11: =V11+U11 -> 58.73 | Y11: =IF(+VLOOKUP(I11,P.Referencia!E:S,3,FALSE)<=L11,"Champion","Gerente") -> #N/A | Z11: =VLOOKUP(I11,P.Referencia!E:S,3,0) -> #N/A | AA11: =(Z11-U11)/U11 -> #N/A | AB11: =U11*AA11 -> #N/A | AC11: =U11+AB11 -> #N/A | AD11: SOLO PIDEN CAMBIO EN FLETE
A12: 11 | C12: =_xlfn.CONCAT($C$1,D12,G12,I12,W12) -> LlaveD86466828114100002362 | D12: =VLOOKUP(E12,'NO MODIFICAR'!J:K,2,0) -> D864 | E12: MX-CANTERA CERRO JARDIN | F12: =VLOOKUP(D12,'NO MODIFICAR'!F:H,3,0) -> CENTRO | G12: 66828114 | H12: CEMENTOS MOCTEZUMA | I12: 10000236 | J12: =VLOOKUP(I12,'Materiales,canteras'!C:D,2,0) -> Grava Triturada Caliza 10 mm - | K12: =VLOOKUP(I12,'Materiales,canteras'!C:E,3,0) -> 1.41 | L12: 157.2 | M12: TN | N12: =TODAY() -> 46267 | O12: 31.12.9999 | S12: 240 | T12: =L12-S12 -> -82.8 | U12: =L12 -> 157.2 | V12: 0 | W12: 2 | X12: =V12+U12 -> 157.2 | Y12: =IF(+VLOOKUP(I12,P.Referencia!E:S,3,FALSE)<=L12,"Champion","Gerente") -> #N/A | Z12: =VLOOKUP(I12,P.Referencia!E:S,3,0) -> #N/A | AA12: =(Z12-U12)/U12 -> #N/A | AB12: =U12*AA12 -> #N/A | AC12: =U12+AB12 -> #N/A
A13: 12 | C13: =_xlfn.CONCAT($C$1,D13,G13,I13,W13) -> LlaveD86167198586100031532 | D13: =VLOOKUP(E13,'NO MODIFICAR'!J:K,2,0) -> D861 | E13: MX-CANTERA QUERETARO | F13: =VLOOKUP(D13,'NO MODIFICAR'!F:H,3,0) -> CENTRO | G13: 67198586 | H13: CASETA | I13: 10003153 | J13: =VLOOKUP(I13,'Materiales,canteras'!C:D,2,0) -> Grava Triturada Basalto 13 mm | K13: =VLOOKUP(I13,'Materiales,canteras'!C:E,3,0) -> 1.546 | L13: 190 | M13: TN | N13: =TODAY() -> 46267 | O13: 31.12.9999 | S13: 270 | T13: =L13-S13 -> -80 | U13: =L13 -> 190 | V13: 0 | W13: 2 | X13: =V13+U13 -> 190 | Y13: =IF(+VLOOKUP(I13,P.Referencia!E:S,3,FALSE)<=L13,"Champion","Gerente") -> #N/A | Z13: =VLOOKUP(I13,P.Referencia!E:S,3,0) -> #N/A | AA13: =(Z13-U13)/U13 -> #N/A | AB13: =U13*AA13 -> #N/A | AC13: =U13+AB13 -> #N/A
A14: 13 | C14: =_xlfn.CONCAT($C$1,D14,G14,I14,W14) -> LlaveD86167198586100002312 | D14: =VLOOKUP(E14,'NO MODIFICAR'!J:K,2,0) -> D861 | E14: MX-CANTERA QUERETARO | F14: =VLOOKUP(D14,'NO MODIFICAR'!F:H,3,0) -> CENTRO | G14: 67198586 | H14: CASETA | I14: 10000231 | J14: =VLOOKUP(I14,'Materiales,canteras'!C:D,2,0) -> Grava Triturada Basalto 20 mm | K14: =VLOOKUP(I14,'Materiales,canteras'!C:E,3,0) -> 1.565 | L14: 190 | M14: TN | N14: =TODAY() -> 46267 | O14: 31.12.9999 | S14: 280 | T14: =L14-S14 -> -90 | U14: =L14 -> 190 | V14: 0 | W14: 2 | X14: =V14+U14 -> 190 | Y14: =IF(+VLOOKUP(I14,P.Referencia!E:S,3,FALSE)<=L14,"Champion","Gerente") -> #N/A | Z14: =VLOOKUP(I14,P.Referencia!E:S,3,0) -> #N/A | AA14: =(Z14-U14)/U14 -> #N/A | AB14: =U14*AA14 -> #N/A | AC14: =U14+AB14 -> #N/A
A15: 14 | C15: =_xlfn.CONCAT($C$1,D15,G15,I15,W15) -> LlaveD86167198586100002332 | D15: =VLOOKUP(E15,'NO MODIFICAR'!J:K,2,0) -> D861 | E15: MX-CANTERA QUERETARO | F15: =VLOOKUP(D15,'NO MODIFICAR'!F:H,3,0) -> CENTRO | G15: 67198586 | H15: CASETA | I15: 10000233 | J15: =VLOOKUP(I15,'Materiales,canteras'!C:D,2,0) -> Grava Triturada Basalto 40 mm | K15: =VLOOKUP(I15,'Materiales,canteras'!C:E,3,0) -> 1.456 | L15: 190 | M15: TN | N15: =TODAY() -> 46267 | O15: 31.12.9999 | S15: 282 | T15: =L15-S15 -> -92 | U15: =L15 -> 190 | V15: 0 | W15: 2 | X15: =V15+U15 -> 190 | Y15: =IF(+VLOOKUP(I15,P.Referencia!E:S,3,FALSE)<=L15,"Champion","Gerente") -> #N/A | Z15: =VLOOKUP(I15,P.Referencia!E:S,3,0) -> #N/A | AA15: =(Z15-U15)/U15 -> #N/A | AB15: =U15*AA15 -> #N/A | AC15: =U15+AB15 -> #N/A
A16: 15 | C16: =_xlfn.CONCAT($C$1,D16,G16,I16,W16) -> LlaveD86167198586100014502 | D16: =VLOOKUP(E16,'NO MODIFICAR'!J:K,2,0) -> D861 | E16: MX-CANTERA QUERETARO | F16: =VLOOKUP(D16,'NO MODIFICAR'!F:H,3,0) -> CENTRO | G16: 67198586 | H16: CASETA | I16: 10001450 | J16: =VLOOKUP(I16,'Materiales,canteras'!C:D,2,0) -> Base Hidraúlica Basalto de 1 /1/2 | K16: =VLOOKUP(I16,'Materiales,canteras'!C:E,3,0) -> 1.749 | L16: 185 | M16: TN | N16: =TODAY() -> 46267 | O16: 31.12.9999 | S16: 260 | T16: =L16-S16 -> -75 | U16: =L16 -> 185 | V16: 0 | W16: 2 | X16: =V16+U16 -> 185 | Y16: =IF(+VLOOKUP(I16,P.Referencia!E:S,3,FALSE)<=L16,"Champion","Gerente") -> #N/A | Z16: =VLOOKUP(I16,P.Referencia!E:S,3,0) -> #N/A | AA16: =(Z16-U16)/U16 -> #N/A | AB16: =U16*AA16 -> #N/A | AC16: =U16+AB16 -> #N/A
A17: 16 | C17: =_xlfn.CONCAT($C$1,D17,G17,I17,W17) -> LlaveDU0767133267100001032 | D17: =VLOOKUP(E17,'NO MODIFICAR'!J:K,2,0) -> DU07 | E17: MX-CANCÚN III | F17: =VLOOKUP(D17,'NO MODIFICAR'!F:H,3,0) -> SURESTE | G17: 67133267 | H17: Javer Kusamil 2025 | I17: 10000103 | J17: =VLOOKUP(I17,'Materiales,canteras'!C:D,2,0) -> Base H Triturada Caliza 1 1/2" a Finos | K17: =VLOOKUP(I17,'Materiales,canteras'!C:E,3,0) -> 1.462 | L17: 119.699 | M17: TN | N17: =TODAY() -> 46267 | O17: 31.12.9999 | S17: 150 | T17: =L17-S17 -> -30.301 | U17: =L17 -> 119.699 | V17: 0 | W17: 2 | X17: =V17+U17 -> 119.699 | Y17: =IF(+VLOOKUP(I17,P.Referencia!E:S,3,FALSE)<=L17,"Champion","Gerente") -> #N/A | Z17: =VLOOKUP(I17,P.Referencia!E:S,3,0) -> #N/A | AA17: =(Z17-U17)/U17 -> #N/A | AB17: =U17*AA17 -> #N/A | AC17: =U17+AB17 -> #N/A
A18: 17 | C18: =_xlfn.CONCAT($C$1,D18,G18,I18,W18) -> LlaveD81366472003100002552 | D18: =VLOOKUP(E18,'NO MODIFICAR'!J:K,2,0) -> D813 | E18: MX-CANTERA SAN VICENTE | F18: =VLOOKUP(D18,'NO MODIFICAR'!F:H,3,0) -> CENTRO | G18: 66472003 | H18: CONCRETOS PILARES PLANTA TONANITLA | I18: 10000255 | J18: =VLOOKUP(I18,'Materiales,canteras'!C:D,2,0) -> Arena Triturada Andesita Malla | K18: =VLOOKUP(I18,'Materiales,canteras'!C:E,3,0) -> 1.535 | L18: 100 | M18: TN | N18: =TODAY() -> 46267 | O18: 31.12.9999 | T18: =L18-S18 -> 100 | U18: =L18 -> 100 | V18: 0 | W18: 2 | X18: =V18+U18 -> 100 | Y18: =IF(+VLOOKUP(I18,P.Referencia!E:S,3,FALSE)<=L18,"Champion","Gerente") -> #N/A | Z18: =VLOOKUP(I18,P.Referencia!E:S,3,0) -> #N/A | AA18: =(Z18-U18)/U18 -> #N/A | AB18: =U18*AA18 -> #N/A | AC18: =U18+AB18 -> #N/A | AD18: QUEDO PENDIENTE YA QUE COMERCIAL VOLVERIA A REVISARLO
A19: 18 | C19: =_xlfn.CONCAT($C$1,D19,G19,I19,W19) -> LlaveD81366472003100002532 | D19: =VLOOKUP(E19,'NO MODIFICAR'!J:K,2,0) -> D813 | E19: MX-CANTERA SAN VICENTE | F19: =VLOOKUP(D19,'NO MODIFICAR'!F:H,3,0) -> CENTRO | G19: 66472003 | H19: CONCRETOS PILARES PLANTA TONANITLA | I19: 10000253 | J19: =VLOOKUP(I19,'Materiales,canteras'!C:D,2,0) -> Grava Triturada Andesita 20 mm | K19: =VLOOKUP(I19,'Materiales,canteras'!C:E,3,0) -> 1.385 | L19: 100 | M19: TN | N19: =TODAY() -> 46267 | O19: 31.12.9999 | T19: =L19-S19 -> 100 | U19: =L19 -> 100 | V19: 0 | W19: 2 | X19: =V19+U19 -> 100 | Y19: =IF(+VLOOKUP(I19,P.Referencia!E:S,3,FALSE)<=L19,"Champion","Gerente") -> #N/A | Z19: =VLOOKUP(I19,P.Referencia!E:S,3,0) -> #N/A | AA19: =(Z19-U19)/U19 -> #N/A | AB19: =U19*AA19 -> #N/A | AC19: =U19+AB19 -> #N/A | AD19: QUEDO PENDIENTE YA QUE COMERCIAL VOLVERIA A REVISARLO
A20: 19 | C20: =_xlfn.CONCAT($C$1,D20,G20,I20,W20) -> LlaveD81366440645100002552 | D20: =VLOOKUP(E20,'NO MODIFICAR'!J:K,2,0) -> D813 | E20: MX-CANTERA SAN VICENTE | F20: =VLOOKUP(D20,'NO MODIFICAR'!F:H,3,0) -> CENTRO | G20: 66440645 | H20: Concretos Pilares Planta Texcoco | I20: 10000255 | J20: =VLOOKUP(I20,'Materiales,canteras'!C:D,2,0) -> Arena Triturada Andesita Malla | K20: =VLOOKUP(I20,'Materiales,canteras'!C:E,3,0) -> 1.535 | L20: 100 | M20: TN | N20: =TODAY() -> 46267 | O20: 31.12.9999 | T20: =L20-S20 -> 100 | U20: =L20 -> 100 | V20: 0 | W20: 2 | X20: =V20+U20 -> 100 | Y20: =IF(+VLOOKUP(I20,P.Referencia!E:S,3,FALSE)<=L20,"Champion","Gerente") -> #N/A | Z20: =VLOOKUP(I20,P.Referencia!E:S,3,0) -> #N/A | AA20: =(Z20-U20)/U20 -> #N/A | AB20: =U20*AA20 -> #N/A | AC20: =U20+AB20 -> #N/A | AD20: QUEDO PENDIENTE YA QUE COMERCIAL VOLVERIA A REVISARLO
A21: 20 | C21: =_xlfn.CONCAT($C$1,D21,G21,I21,W21) -> LlaveD81366440645100002532 | D21: =VLOOKUP(E21,'NO MODIFICAR'!J:K,2,0) -> D813 | E21: MX-CANTERA SAN VICENTE | F21: =VLOOKUP(D21,'NO MODIFICAR'!F:H,3,0) -> CENTRO | G21: 66440645 | H21: Concretos Pilares Planta Texcoco | I21: 10000253 | J21: =VLOOKUP(I21,'Materiales,canteras'!C:D,2,0) -> Grava Triturada Andesita 20 mm | K21: =VLOOKUP(I21,'Materiales,canteras'!C:E,3,0) -> 1.385 | L21: 100 | M21: TN | N21: =TODAY() -> 46267 | O21: 31.12.9999 | T21: =L21-S21 -> 100 | U21: =L21 -> 100 | V21: 0 | W21: 2 | X21: =V21+U21 -> 100 | Y21: =IF(+VLOOKUP(I21,P.Referencia!E:S,3,FALSE)<=L21,"Champion","Gerente") -> #N/A | Z21: =VLOOKUP(I21,P.Referencia!E:S,3,0) -> #N/A | AA21: =(Z21-U21)/U21 -> #N/A | AB21: =U21*AA21 -> #N/A | AC21: =U21+AB21 -> #N/A | AD21: QUEDO PENDIENTE YA QUE COMERCIAL VOLVERIA A REVISARLO
A22: 21 | C22: =_xlfn.CONCAT($C$1,D22,G22,I22,W22) -> LlaveD86466472003100010732 | D22: =VLOOKUP(E22,'NO MODIFICAR'!J:K,2,0) -> D864 | E22: MX-CANTERA CERRO JARDIN | F22: =VLOOKUP(D22,'NO MODIFICAR'!F:H,3,0) -> CENTRO | G22: 66472003 | H22: CONCRETOS PILARES PLANTA TONANITLA | I22: 10001073 | J22: =VLOOKUP(I22,'Materiales,canteras'!C:D,2,0) -> Arena Triturada Caliza Malla 4 | K22: =VLOOKUP(I22,'Materiales,canteras'!C:E,3,0) -> 1.56 | L22: 95 | M22: TN | N22: =TODAY() -> 46267 | O22: 31.12.9999 | T22: =L22-S22 -> 95 | U22: =L22 -> 95 | V22: 0 | W22: 2 | X22: =V22+U22 -> 95 | Y22: =IF(+VLOOKUP(I22,P.Referencia!E:S,3,FALSE)<=L22,"Champion","Gerente") -> #N/A | Z22: =VLOOKUP(I22,P.Referencia!E:S,3,0) -> #N/A | AA22: =(Z22-U22)/U22 -> #N/A | AB22: =U22*AA22 -> #N/A | AC22: =U22+AB22 -> #N/A | AD22: QUEDO PENDIENTE YA QUE COMERCIAL VOLVERIA A REVISARLO
A23: 22 | C23: =_xlfn.CONCAT($C$1,D23,G23,I23,W23) -> LlaveD86466472003100002402 | D23: =VLOOKUP(E23,'NO MODIFICAR'!J:K,2,0) -> D864 | E23: MX-CANTERA CERRO JARDIN | F23: =VLOOKUP(D23,'NO MODIFICAR'!F:H,3,0) -> CENTRO | G23: 66472003 | H23: CONCRETOS PILARES PLANTA TONANITLA | I23: 10000240 | J23: =VLOOKUP(I23,'Materiales,canteras'!C:D,2,0) -> Grava Triturada Caliza 20 mm - | K23: =VLOOKUP(I23,'Materiales,canteras'!C:E,3,0) -> 1.462 | L23: 151 | M23: TN | N23: =TODAY() -> 46267 | O23: 31.12.9999 | T23: =L23-S23 -> 151 | U23: =L23 -> 151 | V23: 0 | W23: 2 | X23: =V23+U23 -> 151 | Y23: =IF(+VLOOKUP(I23,P.Referencia!E:S,3,FALSE)<=L23,"Champion","Gerente") -> #N/A | Z23: =VLOOKUP(I23,P.Referencia!E:S,3,0) -> #N/A | AA23: =(Z23-U23)/U23 -> #N/A | AB23: =U23*AA23 -> #N/A | AC23: =U23+AB23 -> #N/A | AD23: QUEDO PENDIENTE YA QUE COMERCIAL VOLVERIA A REVISARLO
A24: 23 | C24: =_xlfn.CONCAT($C$1,D24,G24,I24,W24) -> LlaveD86466440645100010732 | D24: =VLOOKUP(E24,'NO MODIFICAR'!J:K,2,0) -> D864 | E24: MX-CANTERA CERRO JARDIN | F24: =VLOOKUP(D24,'NO MODIFICAR'!F:H,3,0) -> CENTRO | G24: 66440645 | H24: Concretos Pilares Planta Texcoco | I24: 10001073 | J24: =VLOOKUP(I24,'Materiales,canteras'!C:D,2,0) -> Arena Triturada Caliza Malla 4 | K24: =VLOOKUP(I24,'Materiales,canteras'!C:E,3,0) -> 1.56 | L24: 95 | M24: TN | N24: =TODAY() -> 46267 | O24: 31.12.9999 | T24: =L24-S24 -> 95 | U24: =L24 -> 95 | V24: 0 | W24: 2 | X24: =V24+U24 -> 95 | Y24: =IF(+VLOOKUP(I24,P.Referencia!E:S,3,FALSE)<=L24,"Champion","Gerente") -> #N/A | Z24: =VLOOKUP(I24,P.Referencia!E:S,3,0) -> #N/A | AA24: =(Z24-U24)/U24 -> #N/A | AB24: =U24*AA24 -> #N/A | AC24: =U24+AB24 -> #N/A | AD24: QUEDO PENDIENTE YA QUE COMERCIAL VOLVERIA A REVISARLO
A25: 24 | C25: =_xlfn.CONCAT($C$1,D25,G25,I25,W25) -> LlaveD86466440645100002402 | D25: =VLOOKUP(E25,'NO MODIFICAR'!J:K,2,0) -> D864 | E25: MX-CANTERA CERRO JARDIN | F25: =VLOOKUP(D25,'NO MODIFICAR'!F:H,3,0) -> CENTRO | G25: 66440645 | H25: Concretos Pilares Planta Texcoco | I25: 10000240 | J25: =VLOOKUP(I25,'Materiales,canteras'!C:D,2,0) -> Grava Triturada Caliza 20 mm - | K25: =VLOOKUP(I25,'Materiales,canteras'!C:E,3,0) -> 1.462 | L25: 151 | M25: TN | N25: =TODAY() -> 46267 | O25: 31.12.9999 | T25: =L25-S25 -> 151 | U25: =L25 -> 151 | V25: 0 | W25: 2 | X25: =V25+U25 -> 151 | Y25: =IF(+VLOOKUP(I25,P.Referencia!E:S,3,FALSE)<=L25,"Champion","Gerente") -> #N/A | Z25: =VLOOKUP(I25,P.Referencia!E:S,3,0) -> #N/A | AA25: =(Z25-U25)/U25 -> #N/A | AB25: =U25*AA25 -> #N/A | AC25: =U25+AB25 -> #N/A | AD25: QUEDO PENDIENTE YA QUE COMERCIAL VOLVERIA A REVISARLO
A26: 25 | C26: =_xlfn.CONCAT($C$1,D26,G26,I26,W26) -> LlaveD86466857228100002402 | D26: =VLOOKUP(E26,'NO MODIFICAR'!J:K,2,0) -> D864 | E26: MX-CANTERA CERRO JARDIN | F26: =VLOOKUP(D26,'NO MODIFICAR'!F:H,3,0) -> CENTRO | G26: 66857228 | H26: PREFAMOVIL ZUMPANGO | I26: 10000240 | J26: =VLOOKUP(I26,'Materiales,canteras'!C:D,2,0) -> Grava Triturada Caliza 20 mm - | K26: =VLOOKUP(I26,'Materiales,canteras'!C:E,3,0) -> 1.462 | L26: 135 | M26: TN | N26: =TODAY() -> 46267 | O26: 31.12.9999 | S26: 280 | T26: =L26-S26 -> -145 | U26: =L26 -> 135 | V26: 0 | W26: 2 | X26: =V26+U26 -> 135 | Y26: =IF(+VLOOKUP(I26,P.Referencia!E:S,3,FALSE)<=L26,"Champion","Gerente") -> #N/A | Z26: =VLOOKUP(I26,P.Referencia!E:S,3,0) -> #N/A | AA26: =(Z26-U26)/U26 -> #N/A | AB26: =U26*AA26 -> #N/A | AC26: =U26+AB26 -> #N/A | AD26: PENDIENTE VOBO LALO Y RICARDO
A27: 26 | C27: =_xlfn.CONCAT($C$1,D27,G27,I27,W27) -> LlaveD86165612044100024991 | D27: =VLOOKUP(E27,'NO MODIFICAR'!J:K,2,0) -> D861 | E27: MX-CANTERA QUERETARO | F27: =VLOOKUP(D27,'NO MODIFICAR'!F:H,3,0) -> CENTRO | G27: 65612044 | H27: OBR-AGR EPCA (LOBS) | I27: 10002499 | J27: =VLOOKUP(I27,'Materiales,canteras'!C:D,2,0) -> Arena Triturada Basalto Malla 4 -Mezcla | K27: =VLOOKUP(I27,'Materiales,canteras'!C:E,3,0) -> 1.666 | L27: 168.62 | M27: TN | N27: =TODAY() -> 46267 | O27: 31.12.9999 | S27: 180 | T27: =L27-S27 -> -11.38 | U27: 168.62 | V27: 51.16 | W27: 1 | X27: =V27+U27 -> 219.78 | Y27: =IF(+VLOOKUP(I27,P.Referencia!E:S,3,FALSE)<=L27,"Champion","Gerente") -> #N/A | Z27: =VLOOKUP(I27,P.Referencia!E:S,3,0) -> #N/A | AA27: =(Z27-U27)/U27 -> #N/A | AB27: =U27*AA27 -> #N/A | AC27: =U27+AB27 -> #N/A | AD27: PENDIENTE VOBO DE RICARDO
A28: 27 | C28: =_xlfn.CONCAT($C$1,D28,G28,I28,W28) -> LlaveD81367019979100023501 | D28: =VLOOKUP(E28,'NO MODIFICAR'!J:K,2,0) -> D813 | E28: MX-CANTERA SAN VICENTE | F28: =VLOOKUP(D28,'NO MODIFICAR'!F:H,3,0) -> CENTRO | G28: 67019979 | H28: FORTALEZA VISE | I28: 10002350 | J28: =VLOOKUP(I28,'Materiales,canteras'!C:D,2,0) -> Grava Triturada Andesita 10mm- | K28: =VLOOKUP(I28,'Materiales,canteras'!C:E,3,0) -> 1.246 | L28: 120.49 | M28: TN | N28: =TODAY() -> 46267 | O28: 31.12.9999 | S28: 150 | T28: =L28-S28 -> -29.51 | U28: 120.49 | V28: 251.46 | W28: 1 | X28: =V28+U28 -> 371.95 | Y28: =IF(+VLOOKUP(I28,P.Referencia!E:S,3,FALSE)<=L28,"Champion","Gerente") -> #N/A | Z28: =VLOOKUP(I28,P.Referencia!E:S,3,0) -> #N/A | AA28: =(Z28-U28)/U28 -> #N/A | AB28: =U28*AA28 -> #N/A | AC28: =U28+AB28 -> #N/A
A29: 28 | C29: =_xlfn.CONCAT($C$1,D29,G29,I29,W29) -> LlaveD86167317983100002901 | D29: =VLOOKUP(E29,'NO MODIFICAR'!J:K,2,0) -> D861 | E29: MX-CANTERA QUERETARO | F29: =VLOOKUP(D29,'NO MODIFICAR'!F:H,3,0) -> CENTRO | G29: 67317983 | H29: EL CAMPANARIO | I29: 10000290 | J29: =VLOOKUP(I29,'Materiales,canteras'!C:D,2,0) -> Polvos Triturado Basalto 3/4" | K29: =VLOOKUP(I29,'Materiales,canteras'!C:E,3,0) -> 1.372 | L29: 1 | M29: TN | N29: =TODAY() -> 46267 | O29: 31.12.9999 | S29: 25 | T29: =L29-S29 -> -24 | U29: 1 | V29: 72.09 | W29: 1 | X29: =V29+U29 -> 73.09 | Y29: =IF(+VLOOKUP(I29,P.Referencia!E:S,3,FALSE)<=L29,"Champion","Gerente") -> #N/A | Z29: =VLOOKUP(I29,P.Referencia!E:S,3,0) -> #N/A | AA29: =(Z29-U29)/U29 -> #N/A | AB29: =U29*AA29 -> #N/A | AC29: =U29+AB29 -> #N/A | AD29: PENDIENTE VOBO DE RICARDO Y LALO
A30: 29 | C30: =_xlfn.CONCAT($C$1,D30,G30,I30,W30) -> LlaveD81366440645100002552 | D30: =VLOOKUP(E30,'NO MODIFICAR'!J:K,2,0) -> D813 | E30: MX-CANTERA SAN VICENTE | F30: =VLOOKUP(D30,'NO MODIFICAR'!F:H,3,0) -> CENTRO | G30: 66440645 | H30: Concretos Pilares S.A. De C.V. | I30: 10000255 | J30: =VLOOKUP(I30,'Materiales,canteras'!C:D,2,0) -> Arena Triturada Andesita Malla | K30: =VLOOKUP(I30,'Materiales,canteras'!C:E,3,0) -> 1.535 | L30: 100 | M30: TN | N30: =TODAY() -> 46267 | O30: 31.12.9999 | S30: 150 | T30: =L30-S30 -> -50 | U30: =L30 -> 100 | V30: 0 | W30: 2 | X30: =V30+U30 -> 100 | Y30: =IF(+VLOOKUP(I30,P.Referencia!E:S,3,FALSE)<=L30,"Champion","Gerente") -> #N/A | Z30: =VLOOKUP(I30,P.Referencia!E:S,3,0) -> #N/A | AA30: =(Z30-U30)/U30 -> #N/A | AB30: =U30*AA30 -> #N/A | AC30: =U30+AB30 -> #N/A
A31: 30 | C31: =_xlfn.CONCAT($C$1,D31,G31,I31,W31) -> LlaveD81366440645100002532 | D31: =VLOOKUP(E31,'NO MODIFICAR'!J:K,2,0) -> D813 | E31: MX-CANTERA SAN VICENTE | F31: =VLOOKUP(D31,'NO MODIFICAR'!F:H,3,0) -> CENTRO | G31: 66440645 | H31: Concretos Pilares S.A. De C.V. | I31: 10000253 | J31: =VLOOKUP(I31,'Materiales,canteras'!C:D,2,0) -> Grava Triturada Andesita 20 mm | K31: =VLOOKUP(I31,'Materiales,canteras'!C:E,3,0) -> 1.385 | L31: 100 | M31: TN | N31: =TODAY() -> 46267 | O31: 31.12.9999 | S31: 150 | T31: =L31-S31 -> -50 | U31: =L31 -> 100 | V31: 0 | W31: 2 | X31: =V31+U31 -> 100 | Y31: =IF(+VLOOKUP(I31,P.Referencia!E:S,3,FALSE)<=L31,"Champion","Gerente") -> #N/A | Z31: =VLOOKUP(I31,P.Referencia!E:S,3,0) -> #N/A | AA31: =(Z31-U31)/U31 -> #N/A | AB31: =U31*AA31 -> #N/A | AC31: =U31+AB31 -> #N/A
A32: 31 | C32: =_xlfn.CONCAT($C$1,D32,G32,I32,W32) -> LlaveD86466440645100010732 | D32: =VLOOKUP(E32,'NO MODIFICAR'!J:K,2,0) -> D864 | E32: MX-CANTERA CERRO JARDIN | F32: =VLOOKUP(D32,'NO MODIFICAR'!F:H,3,0) -> CENTRO | G32: 66440645 | H32: Concretos Pilares S.A. De C.V. | I32: 10001073 | J32: =VLOOKUP(I32,'Materiales,canteras'!C:D,2,0) -> Arena Triturada Caliza Malla 4 | K32: =VLOOKUP(I32,'Materiales,canteras'!C:E,3,0) -> 1.56 | L32: 95 | M32: TN | N32: =TODAY() -> 46267 | O32: 31.12.9999 | S32: 150 | T32: =L32-S32 -> -55 | U32: =L32 -> 95 | V32: 0 | W32: 2 | X32: =V32+U32 -> 95 | Y32: =IF(+VLOOKUP(I32,P.Referencia!E:S,3,FALSE)<=L32,"Champion","Gerente") -> #N/A | Z32: =VLOOKUP(I32,P.Referencia!E:S,3,0) -> #N/A | AA32: =(Z32-U32)/U32 -> #N/A | AB32: =U32*AA32 -> #N/A | AC32: =U32+AB32 -> #N/A
A33: 32 | C33: =_xlfn.CONCAT($C$1,D33,G33,I33,W33) -> LlaveD86466440645100002402 | D33: =VLOOKUP(E33,'NO MODIFICAR'!J:K,2,0) -> D864 | E33: MX-CANTERA CERRO JARDIN | F33: =VLOOKUP(D33,'NO MODIFICAR'!F:H,3,0) -> CENTRO | G33: 66440645 | H33: Concretos Pilares S.A. De C.V. | I33: 10000240 | J33: =VLOOKUP(I33,'Materiales,canteras'!C:D,2,0) -> Grava Triturada Caliza 20 mm - | K33: =VLOOKUP(I33,'Materiales,canteras'!C:E,3,0) -> 1.462 | L33: 151 | M33: TN | N33: =TODAY() -> 46267 | O33: 31.12.9999 | S33: 280 | T33: =L33-S33 -> -129 | U33: =L33 -> 151 | V33: 0 | W33: 2 | X33: =V33+U33 -> 151 | Y33: =IF(+VLOOKUP(I33,P.Referencia!E:S,3,FALSE)<=L33,"Champion","Gerente") -> #N/A | Z33: =VLOOKUP(I33,P.Referencia!E:S,3,0) -> #N/A | AA33: =(Z33-U33)/U33 -> #N/A | AB33: =U33*AA33 -> #N/A | AC33: =U33+AB33 -> #N/A
A34: 33 | C34: =_xlfn.CONCAT($C$1,D34,G34,I34,W34) -> LlaveD86467124204100002402 | D34: =VLOOKUP(E34,'NO MODIFICAR'!J:K,2,0) -> D864 | E34: MX-CANTERA CERRO JARDIN | F34: =VLOOKUP(D34,'NO MODIFICAR'!F:H,3,0) -> CENTRO | G34: 67124204 | H34: Agreg – Premoso | I34: 10000240 | J34: =VLOOKUP(I34,'Materiales,canteras'!C:D,2,0) -> Grava Triturada Caliza 20 mm - | K34: =VLOOKUP(I34,'Materiales,canteras'!C:E,3,0) -> 1.462 | L34: 130 | M34: TN | N34: =TODAY() -> 46267 | O34: 31.12.9999 | S34: 280 | T34: =L34-S34 -> -150 | U34: 130 | V34: 0 | W34: 2 | X34: =V34+U34 -> 130 | Y34: =IF(+VLOOKUP(I34,P.Referencia!E:S,3,FALSE)<=L34,"Champion","Gerente") -> #N/A | Z34: =VLOOKUP(I34,P.Referencia!E:S,3,0) -> #N/A | AA34: =(Z34-U34)/U34 -> #N/A | AB34: =U34*AA34 -> #N/A | AC34: =U34+AB34 -> #N/A
A35: 34 | C35: =_xlfn.CONCAT($C$1,D35,G35,I35,W35) -> LlaveD86467124204100010742 | D35: =VLOOKUP(E35,'NO MODIFICAR'!J:K,2,0) -> D864 | E35: MX-CANTERA CERRO JARDIN | F35: =VLOOKUP(D35,'NO MODIFICAR'!F:H,3,0) -> CENTRO | G35: 67124204 | H35: Agreg – Premoso | I35: 10001074 | J35: =VLOOKUP(I35,'Materiales,canteras'!C:D,2,0) -> Grava Triturada Caliza 40 mm - | K35: =VLOOKUP(I35,'Materiales,canteras'!C:E,3,0) -> 1.4 | L35: 130 | M35: TN | N35: =TODAY() -> 46267 | O35: 31.12.9999 | S35: 220 | T35: =L35-S35 -> -90 | U35: 130 | V35: 0 | W35: 2 | X35: =V35+U35 -> 130 | Y35: =IF(+VLOOKUP(I35,P.Referencia!E:S,3,FALSE)<=L35,"Champion","Gerente") -> #N/A | Z35: =VLOOKUP(I35,P.Referencia!E:S,3,0) -> #N/A | AA35: =(Z35-U35)/U35 -> #N/A | AB35: =U35*AA35 -> #N/A | AC35: =U35+AB35 -> #N/A
A36: 35 | C36: =_xlfn.CONCAT($C$1,D36,G36,I36,W36) -> LlaveD86167320246100002902 | D36: =VLOOKUP(E36,'NO MODIFICAR'!J:K,2,0) -> D861 | E36: MX-CANTERA QUERETARO | F36: =VLOOKUP(D36,'NO MODIFICAR'!F:H,3,0) -> CENTRO | G36: 67320246 | H36: AGACEL DESPOLVE | I36: 10000290 | J36: =VLOOKUP(I36,'Materiales,canteras'!C:D,2,0) -> Polvos Triturado Basalto 3/4" | K36: =VLOOKUP(I36,'Materiales,canteras'!C:E,3,0) -> 1.372 | L36: 1 | M36: TN | N36: =TODAY() -> 46267 | O36: 31.12.9999 | S36: 25 | T36: =L36-S36 -> -24 | U36: 1 | V36: 0 | W36: 2 | X36: =V36+U36 -> 1 | Y36: =IF(+VLOOKUP(I36,P.Referencia!E:S,3,FALSE)<=L36,"Champion","Gerente") -> #N/A | Z36: =VLOOKUP(I36,P.Referencia!E:S,3,0) -> #N/A | AA36: =(Z36-U36)/U36 -> #N/A | AB36: =U36*AA36 -> #N/A | AC36: =U36+AB36 -> #N/A
A37: 36 | C37: =_xlfn.CONCAT($C$1,D37,G37,I37,W37) -> LlaveD81366942072100002551 | D37: =VLOOKUP(E37,'NO MODIFICAR'!J:K,2,0) -> D813 | E37: MX-CANTERA SAN VICENTE | F37: =VLOOKUP(D37,'NO MODIFICAR'!F:H,3,0) -> CENTRO | G37: 66942072 | H37: Prebloquim | I37: 10000255 | J37: =VLOOKUP(I37,'Materiales,canteras'!C:D,2,0) -> Arena Triturada Andesita Malla | K37: =VLOOKUP(I37,'Materiales,canteras'!C:E,3,0) -> 1.535 | L37: 84 | M37: TN | N37: =TODAY() -> 46267 | O37: 31.12.9999 | S37: 150 | T37: =L37-S37 -> -66 | U37: 84 | V37: 143.32 | W37: 1 | X37: =V37+U37 -> 227.32 | Y37: =IF(+VLOOKUP(I37,P.Referencia!E:S,3,FALSE)<=L37,"Champion","Gerente") -> #N/A | Z37: =VLOOKUP(I37,P.Referencia!E:S,3,0) -> #N/A | AA37: =(Z37-U37)/U37 -> #N/A | AB37: =U37*AA37 -> #N/A | AC37: =U37+AB37 -> #N/A
A38: 37 | C38: =_xlfn.CONCAT($C$1,D38,G38,I38,W38) -> LlaveD86166838326100031532 | D38: =VLOOKUP(E38,'NO MODIFICAR'!J:K,2,0) -> D861 | E38: MX-CANTERA QUERETARO | F38: =VLOOKUP(D38,'NO MODIFICAR'!F:H,3,0) -> CENTRO | G38: 66838326 | H38: OBRA FORD | I38: 10003153 | J38: =VLOOKUP(I38,'Materiales,canteras'!C:D,2,0) -> Grava Triturada Basalto 13 mm | K38: =VLOOKUP(I38,'Materiales,canteras'!C:E,3,0) -> 1.546 | L38: 220 | M38: TN | N38: =TODAY() -> 46267 | O38: 31.12.9999 | S38: 270 | T38: =L38-S38 -> -50 | U38: 220 | V38: 0 | W38: 2 | X38: =V38+U38 -> 220 | Y38: =IF(+VLOOKUP(I38,P.Referencia!E:S,3,FALSE)<=L38,"Champion","Gerente") -> #N/A | Z38: =VLOOKUP(I38,P.Referencia!E:S,3,0) -> #N/A | AA38: =(Z38-U38)/U38 -> #N/A | AB38: =U38*AA38 -> #N/A | AC38: =U38+AB38 -> #N/A
A39: 38 | C39: =_xlfn.CONCAT($C$1,D39,G39,I39,W39) -> LlaveD86467320967100002402 | D39: =VLOOKUP(E39,'NO MODIFICAR'!J:K,2,0) -> D864 | E39: MX-CANTERA CERRO JARDIN | F39: =VLOOKUP(D39,'NO MODIFICAR'!F:H,3,0) -> CENTRO | G39: 67320967 | H39: CONSTRUCCIONES Y ASFALTOS | I39: 10000240 | J39: =VLOOKUP(I39,'Materiales,canteras'!C:D,2,0) -> Grava Triturada Caliza 20 mm - | K39: =VLOOKUP(I39,'Materiales,canteras'!C:E,3,0) -> 1.462 | L39: 130 | M39: TN | N39: =TODAY() -> 46267 | O39: 31.12.9999 | S39: 280 | T39: =L39-S39 -> -150 | U39: 130 | V39: 0 | W39: 2 | X39: =V39+U39 -> 130 | Y39: =IF(+VLOOKUP(I39,P.Referencia!E:S,3,FALSE)<=L39,"Champion","Gerente") -> #N/A | Z39: =VLOOKUP(I39,P.Referencia!E:S,3,0) -> #N/A | AA39: =(Z39-U39)/U39 -> #N/A | AB39: =U39*AA39 -> #N/A | AC39: =U39+AB39 -> #N/A
A40: 39 | C40: =_xlfn.CONCAT($C$1,D40,G40,I40,W40) -> LlaveD81367320967100002552 | D40: =VLOOKUP(E40,'NO MODIFICAR'!J:K,2,0) -> D813 | E40: MX-CANTERA SAN VICENTE | F40: =VLOOKUP(D40,'NO MODIFICAR'!F:H,3,0) -> CENTRO | G40: 67320967 | H40: CONSTRUCCIONES Y ASFALTOS | I40: 10000255 | J40: =VLOOKUP(I40,'Materiales,canteras'!C:D,2,0) -> Arena Triturada Andesita Malla | K40: =VLOOKUP(I40,'Materiales,canteras'!C:E,3,0) -> 1.535 | L40: 80 | M40: TN | N40: =TODAY() -> 46267 | O40: 31.12.9999 | S40: 150 | T40: =L40-S40 -> -70 | U40: 80 | V40: 0 | W40: 2 | X40: =V40+U40 -> 80 | Y40: =IF(+VLOOKUP(I40,P.Referencia!E:S,3,FALSE)<=L40,"Champion","Gerente") -> #N/A | Z40: =VLOOKUP(I40,P.Referencia!E:S,3,0) -> #N/A | AA40: =(Z40-U40)/U40 -> #N/A | AB40: =U40*AA40 -> #N/A | AC40: =U40+AB40 -> #N/A
...

Sheet Formato cambio
D2: PRECIOS DE VENTA
C7: Cambio en obra específica
C8: Org Vtas | D8: Sucursal obra | E8: Centro | F8: Material | G8: GAP Importe | H8: Clase condición | I8: flete | J8: Condición | K8: Modalidad
C9: 7180 | D9: 66823169 | E9: D816 | F9: 10001170 | G9: -45.22 | H9: =IF(G9<0,"YMC8","YMC9") -> YMC8 | I9: 0 | J9: =IF(I9>0,"ZMP1","0") -> 0 | K9: =IF(I9>0,"01","02") -> 02
C10: 7180 | D10: 66862802 | E10: D816 | F10: 10001170 | G10: -45.22 | H10: =IF(G10<0,"YMC8","YMC9") -> YMC8 | I10: 0 | J10: =IF(I10>0,"ZMP1","0") -> 0 | K10: =IF(I10>0,"01","02") -> 02

Sheet P.Referencia
J1: 0.04 | T1: RICARDO | U1: EDUARDO | V1: MARZO | W1: ABRIL | Y1: MAYO
A2: Región | B2: llave | C2: UO | D2: Cantera | E2: Material | F2: Material | H2: 46235 | I2: 46113 | J2: $precio26 | K2: $Enero26 | L2: $ Dic '25 | M2: $ Nov '25 | N2: $ Oct '25 | O2: $ Sep '25 | P2: $ Agosto '25 | Q2: $ Julio '25 | R2: $ Ref Junio '25 | S2: $ Ref May'25 | T2: 0.05 | U2: 0.1 | V2: Filial | W2: Filial | X2: Var | Y2: Filial | Z2: Var
A3: CENTRO | B3: =+C3&E3 -> D86410001073 | C3: D864 | D3: MX-CANTERA CERRO JARDIN | E3: 10001073 | F3: Arena Triturada Caliza Malla 4 | G3: =H3-I3 -> #N/A | H3: =VLOOKUP(E3,[2]Conciliacion!$H:$AC,22,0) -> #N/A | I3: =VLOOKUP(B3,'[3]Hoja2 (2)'!$A:$E,5,0) -> 91 | J3: =(L3*4%)+L3 -> 91 | K3: 91 | L3: =VLOOKUP(E3,[4]TRABAJO!$H:$S,9,0) -> 87.5 | M3: =VLOOKUP(E3,[5]TRABAJO!$F:$S,11,0) -> 87.5 | N3: =VLOOKUP(E3,[6]TRABAJO!$H:$S,9,0) -> 87.5 | O3: =VLOOKUP(B3,[7]TRABAJO!$C:$S,14,0) -> 87.5 | P3: =VLOOKUP(B3,[8]TRABAJO!$C:$S,14,0) -> 87.5 | Q3: =VLOOKUP(B3,[9]TRABAJO!$C:$S,14,0) -> 87.5 | R3: =VLOOKUP(B3,[10]TRABAJO!$C:$Q,15,0) -> 87.5 | S3: 87.48 | T3: =S3-(S3*5%) -> 83.106 | U3: =S3-(S3*10%) -> 78.732 | V3: =VLOOKUP(B3,'[11]ZICP-MARZO'!$B:$P,15,0) -> 91.48 | W3: =VLOOKUP(B3,[11]CONSOLIDADO_ABRIL!$B:$J,9,0) -> 91.48 | X3: =V3-W3 -> 0 | Y3: =VLOOKUP(B3,[11]CONSOLIDADO_MAYO!$B:$J,9,0) -> 87.48 | Z3: =S3-Y3 -> 0
A4: CENTRO | B4: =+C4&E4 -> D86410000236 | C4: D864 | D4: MX-CANTERA CERRO JARDIN | E4: 10000236 | F4: Grava Triturada Caliza 10 mm - 3/8" | G4: =H4-I4 -> #N/A | H4: =VLOOKUP(E4,[2]Conciliacion!$H:$AC,22,0) -> #N/A | I4: =VLOOKUP(B4,'[3]Hoja2 (2)'!$A:$E,5,0) -> 124.8 | J4: =(L4*4%)+L4 -> 124.8 | K4: 124.8 | L4: =VLOOKUP(E4,[4]TRABAJO!$H:$S,9,0) -> 120 | M4: =VLOOKUP(E4,[5]TRABAJO!$F:$S,11,0) -> 120 | N4: =VLOOKUP(E4,[6]TRABAJO!$H:$S,9,0) -> 120 | O4: =VLOOKUP(B4,[7]TRABAJO!$C:$S,14,0) -> 120 | P4: =VLOOKUP(B4,[8]TRABAJO!$C:$S,14,0) -> 120 | Q4: =VLOOKUP(B4,[9]TRABAJO!$C:$S,14,0) -> 120 | R4: =VLOOKUP(B4,[10]TRABAJO!$C:$Q,15,0) -> 120 | S4: 120.44 | T4: =S4-(S4*5%) -> 114.418 | U4: =S4-(S4*10%) -> 108.396 | V4: =VLOOKUP(B4,'[11]ZICP-MARZO'!$B:$P,15,0) -> 143.96 | W4: =VLOOKUP(B4,[11]CONSOLIDADO_ABRIL!$B:$J,9,0) -> 150.44 | X4: =V4-W4 -> -6.48 | Y4: =VLOOKUP(B4,[11]CONSOLIDADO_MAYO!$B:$J,9,0) -> 120.44 | Z4: =S4-Y4 -> 0
A5: CENTRO | B5: =+C5&E5 -> D86410000269 | C5: D864 | D5: MX-CANTERA CERRO JARDIN | E5: 10000269 | F5: Grava Triturada Caliza 13 mm - 1/2" | G5: =H5-I5 -> #N/A | H5: =VLOOKUP(E5,[2]Conciliacion!$H:$AC,22,0) -> #N/A | I5: =VLOOKUP(B5,'[3]Hoja2 (2)'!$A:$E,5,0) -> 142.48 | J5: =(L5*4%)+L5 -> 142.48 | K5: 142.48 | L5: =VLOOKUP(E5,[4]TRABAJO!$H:$S,9,0) -> 137 | M5: =VLOOKUP(E5,[5]TRABAJO!$F:$S,11,0) -> 137 | N5: =VLOOKUP(E5,[6]TRABAJO!$H:$S,9,0) -> 137 | O5: 137 | P5: 137 | Q5: =VLOOKUP(B5,[9]TRABAJO!$C:$S,14,0) -> 137 | R5: =VLOOKUP(B5,[10]TRABAJO!$C:$Q,15,0) -> 137 | S5: 131.2 | T5: =S5-(S5*5%) -> 124.64 | U5: =S5-(S5*10%) -> 118.08 | V5: =VLOOKUP(B5,'[11]ZICP-MARZO'!$B:$P,15,0) -> 151.8 | W5: =VLOOKUP(B5,[11]CONSOLIDADO_ABRIL!$B:$J,9,0) -> 167.34 | X5: =V5-W5 -> -15.54 | Y5: =VLOOKUP(B5,[11]CONSOLIDADO_MAYO!$B:$J,9,0) -> 131.2 | Z5: =S5-Y5 -> 0
A6: CENTRO | B6: =+C6&E6 -> D86410000240 | C6: D864 | D6: MX-CANTERA CERRO JARDIN | E6: 10000240 | F6: Grava Triturada Caliza 20 mm - 3/4" | G6: =H6-I6 -> #N/A | H6: =VLOOKUP(E6,[2]Conciliacion!$H:$AC,22,0) -> #N/A | I6: =VLOOKUP(B6,'[3]Hoja2 (2)'!$A:$E,5,0) -> 132.08 | J6: =(L6*4%)+L6 -> 132.08 | K6: 132.08 | L6: =VLOOKUP(E6,[4]TRABAJO!$H:$S,9,0) -> 127 | M6: =VLOOKUP(E6,[5]TRABAJO!$F:$S,11,0) -> 127 | N6: =VLOOKUP(E6,[6]TRABAJO!$H:$S,9,0) -> 127 | O6: =VLOOKUP(B6,[7]TRABAJO!$C:$S,14,0) -> 127 | P6: =VLOOKUP(B6,[8]TRABAJO!$C:$S,14,0) -> 127 | Q6: =VLOOKUP(B6,[9]TRABAJO!$C:$S,14,0) -> 127 | R6: =VLOOKUP(B6,[10]TRABAJO!$C:$Q,15,0) -> 127 | S6: 127.17 | T6: =S6-(S6*5%) -> 120.8115 | U6: =S6-(S6*10%) -> 114.453 | V6: =VLOOKUP(B6,'[11]ZICP-MARZO'!$B:$P,15,0) -> 150.4 | W6: =VLOOKUP(B6,[11]CONSOLIDADO_ABRIL!$B:$J,9,0) -> 157.17 | X6: =V6-W6 -> -6.77 | Y6: =VLOOKUP(B6,[11]CONSOLIDADO_MAYO!$B:$J,9,0) -> 127.17 | Z6: =S6-Y6 -> 0
A7: CENTRO | B7: =+C7&E7 -> D86410001074 | C7: D864 | D7: MX-CANTERA CERRO JARDIN | E7: 10001074 | F7: Grava Triturada Caliza 40 mm - 1 1/2" | G7: =H7-I7 -> #N/A | H7: =VLOOKUP(E7,[2]Conciliacion!$H:$AC,22,0) -> #N/A | I7: =VLOOKUP(B7,'[3]Hoja2 (2)'!$A:$E,5,0) -> 142.48 | J7: =(L7*4%)+L7 -> 142.48 | K7: 142.48 | L7: =VLOOKUP(E7,[4]TRABAJO!$H:$S,9,0) -> 137 | M7: =VLOOKUP(E7,[5]TRABAJO!$F:$S,11,0) -> 137 | N7: =VLOOKUP(E7,[6]TRABAJO!$H:$S,9,0) -> 137 | O7: =VLOOKUP(B7,[7]TRABAJO!$C:$S,14,0) -> 137 | P7: =VLOOKUP(B7,[8]TRABAJO!$C:$S,14,0) -> 137 | Q7: =VLOOKUP(B7,[9]TRABAJO!$C:$S,14,0) -> 137 | R7: =VLOOKUP(B7,[10]TRABAJO!$C:$Q,15,0) -> 137 | S7: 136.64 | T7: =S7-(S7*5%) -> 129.808 | U7: =S7-(S7*10%) -> 122.976 | V7: =VLOOKUP(B7,'[11]ZICP-MARZO'!$B:$P,15,0) -> 177.75 | W7: =VLOOKUP(B7,[11]CONSOLIDADO_ABRIL!$B:$J,9,0) -> 186.64 | X7: =V7-W7 -> -8.89 | Y7: =VLOOKUP(B7,[11]CONSOLIDADO_MAYO!$B:$J,9,0) -> 136.64 | Z7: =S7-Y7 -> 0
A8: CENTRO | B8: =+C8&E8 -> D86110000311 | C8: D861 | D8: MX-CANTERA QUERETARO | E8: 10000311 | F8: Arena Triturada Basalto Malla 4 | G8: =H8-I8 -> #N/A | H8: =VLOOKUP(E8,[2]Conciliacion!$H:$AC,22,0) -> #N/A | I8: =VLOOKUP(B8,'[3]Hoja2 (2)'!$A:$E,5,0) -> 191.26 | J8: 191.26 | K8: 191.26 | L8: =VLOOKUP(E8,[4]TRABAJO!$H:$S,9,0) -> #N/A | M8: =VLOOKUP(E8,[5]TRABAJO!$F:$S,11,0) -> 183.90002 | N8: =VLOOKUP(E8,[6]TRABAJO!$H:$S,9,0) -> 180 | O8: 180.59044 | P8: 180.59044 | Q8: =VLOOKUP(B8,[9]TRABAJO!$C:$S,14,0) -> 180.59044 | R8: =VLOOKUP(B8,[10]TRABAJO!$C:$Q,15,0) -> 184 | S8: 188 | T8: =S8-(S8*5%) -> 178.6 | U8: =S8-(S8*10%) -> 169.2 | V8: =VLOOKUP(B8,'[11]ZICP-MARZO'!$B:$P,15,0) -> 171.19 | W8: =VLOOKUP(B8,[11]CONSOLIDADO_ABRIL!$B:$J,9,0) -> 203.78 | X8: =V8-W8 -> -32.59 | Y8: =VLOOKUP(B8,[11]CONSOLIDADO_MAYO!$B:$J,9,0) -> 188 | Z8: =S8-Y8 -> 0
A9: CENTRO | B9: =+C9&E9 -> D86110000229 | C9: D861 | D9: MX-CANTERA QUERETARO | E9: 10000229 | F9: Grava Triturada Basalto 10 mm - 3/8" | G9: =H9-I9 -> #N/A | H9: =VLOOKUP(E9,[2]Conciliacion!$H:$AC,22,0) -> #N/A | I9: =VLOOKUP(B9,'[3]Hoja2 (2)'!$A:$E,5,0) -> 249.36 | J9: =(L9*4%)+L9 -> 249.3608 | K9: 249.39 | L9: =VLOOKUP(E9,[4]TRABAJO!$H:$S,9,0) -> 239.77 | M9: =VLOOKUP(E9,[5]TRABAJO!$F:$S,11,0) -> 239.77004 | N9: =VLOOKUP(E9,[6]TRABAJO!$H:$S,9,0) -> 239.76995 | O9: =VLOOKUP(B9,[7]TRABAJO!$C:$S,14,0) -> 239.77 | P9: =VLOOKUP(B9,[8]TRABAJO!$C:$S,14,0) -> 216 | Q9: =VLOOKUP(B9,[9]TRABAJO!$C:$S,14,0) -> 239.76995 | R9: =VLOOKUP(B9,[10]TRABAJO!$C:$Q,15,0) -> 239.77002 | S9: 216 | T9: =S9-(S9*5%) -> 205.2 | U9: =S9-(S9*10%) -> 194.4 | V9: =VLOOKUP(B9,'[11]ZICP-MARZO'!$B:$P,15,0) -> 225.14 | W9: =VLOOKUP(B9,[11]CONSOLIDADO_ABRIL!$B:$J,9,0) -> 239.77 | X9: =V9-W9 -> -14.63 | Y9: =VLOOKUP(B9,[11]CONSOLIDADO_MAYO!$B:$J,9,0) -> 216 | Z9: =S9-Y9 -> 0
A10: CENTRO | B10: =+C10&E10 -> D86110000231 | C10: D861 | D10: MX-CANTERA QUERETARO | E10: 10000231 | F10: Grava Triturada Basalto 20 mm - 3/4" | G10: =H10-I10 -> #N/A | H10: =VLOOKUP(E10,[2]Conciliacion!$H:$AC,22,0) -> #N/A | I10: =VLOOKUP(B10,'[3]Hoja2 (2)'!$A:$E,5,0) -> 224.62 | J10: =(L10*4%)+L10 -> 224.6192 | K10: 224.64 | L10: =VLOOKUP(E10,[4]TRABAJO!$H:$S,9,0) -> 215.98 | M10: =VLOOKUP(E10,[5]TRABAJO!$F:$S,11,0) -> 215.98 | N10: =VLOOKUP(E10,[6]TRABAJO!$H:$S,9,0) -> 215.98 | O10: =VLOOKUP(B10,[7]TRABAJO!$C:$S,14,0) -> 215.98 | P10: =VLOOKUP(B10,[8]TRABAJO!$C:$S,14,0) -> 215.98 | Q10: =VLOOKUP(B10,[9]TRABAJO!$C:$S,14,0) -> 215.98001 | R10: =VLOOKUP(B10,[10]TRABAJO!$C:$Q,15,0) -> 215.97999 | S10: 215.98 | T10: =S10-(S10*5%) -> 205.181 | U10: =S10-(S10*10%) -> 194.382 | V10: =VLOOKUP(B10,'[11]ZICP-MARZO'!$B:$P,15,0) -> 205.71 | W10: =VLOOKUP(B10,[11]CONSOLIDADO_ABRIL!$B:$J,9,0) -> 215.98 | X10: =V10-W10 -> -10.27 | Y10: =VLOOKUP(B10,[11]CONSOLIDADO_MAYO!$B:$J,9,0) -> 215.98 | Z10: =S10-Y10 -> -4.0712468e-06
A11: CENTRO | B11: =+C11&E11 -> D86110000233 | C11: D861 | D11: MX-CANTERA QUERETARO | E11: 10000233 | F11: Grava Triturada Basalto 40 mm - 1 1/2" | G11: =H11-I11 -> #N/A | H11: =VLOOKUP(E11,[2]Conciliacion!$H:$AC,22,0) -> #N/A | I11: =VLOOKUP(B11,'[3]Hoja2 (2)'!$A:$E,5,0) -> 224.62 | J11: =(L11*4%)+L11 -> 224.61919 | K11: 224.64 | L11: =VLOOKUP(E11,[4]TRABAJO!$H:$S,9,0) -> 215.97999 | M11: =VLOOKUP(E11,[5]TRABAJO!$F:$S,11,0) -> 215.97998 | N11: =VLOOKUP(E11,[6]TRABAJO!$H:$S,9,0) -> 178 | O11: =VLOOKUP(B11,[7]TRABAJO!$C:$S,14,0) -> 178 | P11: =VLOOKUP(B11,[8]TRABAJO!$C:$S,14,0) -> 178 | Q11: =VLOOKUP(B11,[9]TRABAJO!$C:$S,14,0) -> 215.98001 | R11: =VLOOKUP(B11,[10]TRABAJO!$C:$Q,15,0) -> 215.97998 | S11: 215.98 | T11: =S11-(S11*5%) -> 205.181 | U11: =S11-(S11*10%) -> 194.382 | V11: =VLOOKUP(B11,'[11]ZICP-MARZO'!$B:$P,15,0) -> 208.25 | W11: =VLOOKUP(B11,[11]CONSOLIDADO_ABRIL!$B:$J,9,0) -> 178 | X11: =V11-W11 -> 30.25 | Y11: =VLOOKUP(B11,[11]CONSOLIDADO_MAYO!$B:$J,9,0) -> 215.98 | Z11: =S11-Y11 -> -8.901153e-07
A12: CENTRO | B12: =+C12&E12 -> D81310000255 | C12: D813 | D12: MX-CANTERA SAN VICENTE | E12: 10000255 | F12: Arena Triturada Andesita Malla 4 | G12: =H12-I12 -> #N/A | H12: =VLOOKUP(E12,[2]Conciliacion!$H:$AC,22,0) -> #N/A | I12: =VLOOKUP(B12,'[3]Hoja2 (2)'!$A:$E,5,0) -> 108.31 | J12: =(L12*4%)+L12 -> 108.3056 | K12: 108.26 | L12: =VLOOKUP(E12,[4]TRABAJO!$H:$S,9,0) -> 104.14 | M12: =VLOOKUP(E12,[5]TRABAJO!$F:$S,11,0) -> 104.14001 | N12: =VLOOKUP(E12,[6]TRABAJO!$H:$S,9,0) -> 104.14 | O12: =VLOOKUP(B12,[7]TRABAJO!$C:$S,14,0) -> 104.1 | P12: =VLOOKUP(B12,[8]TRABAJO!$C:$S,14,0) -> 104.14001 | Q12: =VLOOKUP(B12,[9]TRABAJO!$C:$S,14,0) -> 104.14 | R12: =VLOOKUP(B12,[10]TRABAJO!$C:$Q,15,0) -> 104.14 | S12: 104.14 | T12: =S12-(S12*5%) -> 98.933 | U12: =S12-(S12*10%) -> 93.726 | V12: =VLOOKUP(B12,'[11]ZICP-MARZO'!$B:$P,15,0) -> 104.07 | W12: =VLOOKUP(B12,[11]CONSOLIDADO_ABRIL!$B:$J,9,0) -> 104.14 | X12: =V12-W12 -> -0.07 | Y12: =VLOOKUP(B12,[11]CONSOLIDADO_MAYO!$B:$J,9,0) -> 104.14 | Z12: =S12-Y12 -> 0
A13: CENTRO | B13: =+C13&E13 -> D81310002350 | C13: D813 | D13: MX-CANTERA SAN VICENTE | E13: 10002350 | F13: Grava Triturada Andesita 10mm-3/8" | G13: =H13-I13 -> #N/A | H13: =VLOOKUP(E13,[2]Conciliacion!$H:$AC,22,0) -> #N/A | I13: =VLOOKUP(B13,'[3]Hoja2 (2)'!$A:$E,5,0) -> 125.31 | J13: =(L13*4%)+L13 -> 125.30949 | K13: 125.32 | L13: =VLOOKUP(E13,[4]TRABAJO!$H:$S,9,0) -> 120.4899 | M13: =VLOOKUP(E13,[5]TRABAJO!$F:$S,11,0) -> 120.49001 | N13: =VLOOKUP(E13,[6]TRABAJO!$H:$S,9,0) -> 134.60003 | O13: =VLOOKUP(B13,[7]TRABAJO!$C:$S,14,0) -> 134.59999 | P13: =VLOOKUP(B13,[8]TRABAJO!$C:$S,14,0) -> 120.49003 | Q13: =VLOOKUP(B13,[9]TRABAJO!$C:$S,14,0) -> 120.48999 | R13: =VLOOKUP(B13,[10]TRABAJO!$C:$Q,15,0) -> 120.48998 | S13: 134.6 | T13: =S13-(S13*5%) -> 127.87 | U13: =S13-(S13*10%) -> 121.14 | V13: =VLOOKUP(B13,'[11]ZICP-MARZO'!$B:$P,15,0) -> 120.49 | W13: =VLOOKUP(B13,[11]CONSOLIDADO_ABRIL!$B:$J,9,0) -> 120.49 | X13: =V13-W13 -> 0 | Y13: =VLOOKUP(B13,[11]CONSOLIDADO_MAYO!$B:$J,9,0) -> 134.6 | Z13: =S13-Y13 -> 0
A14: CENTRO | B14: =+C14&E14 -> D81310000253 | C14: D813 | D14: MX-CANTERA SAN VICENTE | E14: 10000253 | F14: Grava Triturada Andesita 20 mm - 3/4" | G14: =H14-I14 -> #N/A | H14: =VLOOKUP(E14,[2]Conciliacion!$H:$AC,22,0) -> #N/A | I14: =VLOOKUP(B14,'[3]Hoja2 (2)'!$A:$E,5,0) -> 108.16 | J14: =(L14*4%)+L14 -> 108.16 | K14: 108.16 | L14: =VLOOKUP(E14,[4]TRABAJO!$H:$S,9,0) -> 104 | M14: =VLOOKUP(E14,[5]TRABAJO!$F:$S,11,0) -> 104 | N14: =VLOOKUP(E14,[6]TRABAJO!$H:$S,9,0) -> 104 | O14: =VLOOKUP(B14,[7]TRABAJO!$C:$S,14,0) -> 103.90003 | P14: =VLOOKUP(B14,[8]TRABAJO!$C:$S,14,0) -> 103.90001 | Q14: =VLOOKUP(B14,[9]TRABAJO!$C:$S,14,0) -> 103.90002 | R14: =VLOOKUP(B14,[10]TRABAJO!$C:$Q,15,0) -> 103.9 | S14: 103.90001 | T14: =S14-(S14*5%) -> 98.705014 | U14: =S14-(S14*10%) -> 93.510013 | V14: =VLOOKUP(B14,'[11]ZICP-MARZO'!$B:$P,15,0) -> 103.52 | W14: =VLOOKUP(B14,[11]CONSOLIDADO_ABRIL!$B:$J,9,0) -> 104 | X14: =V14-W14 -> -0.48 | Y14: =VLOOKUP(B14,[11]CONSOLIDADO_MAYO!$B:$J,9,0) -> 103.9 | Z14: =S14-Y14 -> 1.470278e-05
A15: CENTRO | B15: =+C15&E15 -> D87310001073 | C15: D873 | D15: MX-VIRTUAL VALLEJO | E15: 10001073 | F15: Arena Triturada Caliza Malla 4 | G15: =H15-I15 -> #N/A | H15: =VLOOKUP(E15,[2]Conciliacion!$H:$AC,22,0) -> #N/A | I15: =VLOOKUP(B15,'[3]Hoja2 (2)'!$A:$E,5,0) -> 208.28 | J15: 208.28 | L15: =VLOOKUP(E15,[4]TRABAJO!$H:$S,9,0) -> 87.5 | M15: =VLOOKUP(E15,[5]TRABAJO!$F:$S,11,0) -> 87.5 | N15: =VLOOKUP(E15,[6]TRABAJO!$H:$S,9,0) -> 87.5 | O15: =VLOOKUP(B15,[7]TRABAJO!$C:$S,14,0) -> 197.8 | P15: =VLOOKUP(B15,[8]TRABAJO!$C:$S,14,0) -> 197.8 | Q15: =VLOOKUP(B15,[9]TRABAJO!$C:$S,14,0) -> 197.8 | R15: =VLOOKUP(B15,[10]TRABAJO!$C:$Q,15,0) -> 197.8 | S15: 196.88 | T15: =S15-(S15*5%) -> 187.036 | U15: =S15-(S15*10%) -> 177.192 | V15: =VLOOKUP(B15,'[11]ZICP-MARZO'!$B:$P,15,0) -> 200.94 | W15: =VLOOKUP(B15,[11]CONSOLIDADO_ABRIL!$B:$J,9,0) -> 200.88 | X15: =V15-W15 -> 0.06 | Y15: =VLOOKUP(B15,[11]CONSOLIDADO_MAYO!$B:$J,9,0) -> 196.88 | Z15: =S15-Y15 -> 0
A16: CENTRO | B16: =+C16&E16 -> D87310000240 | C16: D873 | D16: MX-VIRTUAL VALLEJO | E16: 10000240 | F16: Grava Triturada Caliza 20 mm - 3/4" | G16: =H16-I16 -> #N/A | H16: =VLOOKUP(E16,[2]Conciliacion!$H:$AC,22,0) -> #N/A | I16: =VLOOKUP(B16,'[3]Hoja2 (2)'!$A:$E,5,0) -> 271.69 | J16: 271.69 | L16: =VLOOKUP(E16,[4]TRABAJO!$H:$S,9,0) -> 127 | M16: =VLOOKUP(E16,[5]TRABAJO!$F:$S,11,0) -> 127 | N16: =VLOOKUP(E16,[6]TRABAJO!$H:$S,9,0) -> 127 | O16: =VLOOKUP(B16,[7]TRABAJO!$C:$S,14,0) -> 258.77 | P16: =VLOOKUP(B16,[8]TRABAJO!$C:$S,14,0) -> 258.77 | Q16: =VLOOKUP(B16,[9]TRABAJO!$C:$S,14,0) -> 258.77 | R16: =VLOOKUP(B16,[10]TRABAJO!$C:$Q,15,0) -> 258.77 | S16: 259.67 | T16: =S16-(S16*5%) -> 246.6865 | U16: =S16-(S16*10%) -> 233.703 | V16: =VLOOKUP(B16,'[11]ZICP-MARZO'!$B:$P,15,0) -> 289.68 | W16: =VLOOKUP(B16,[11]CONSOLIDADO_ABRIL!$B:$J,9,0) -> 289.67 | X16: =V16-W16 -> 0.01 | Y16: =VLOOKUP(B16,[11]CONSOLIDADO_MAYO!$B:$J,9,0) -> 259.67 | Z16: =S16-Y16 -> 0
A17: NORESTE | B17: =+C17&E17 -> D82410000234 | C17: D824 | D17: MX-CANTERA LEON | E17: 10000234 | F17: Arena Triturada Basalto Malla 4 | G17: =H17-I17 -> #N/A | H17: =VLOOKUP(E17,[2]Conciliacion!$H:$AC,22,0) -> #N/A | I17: =VLOOKUP(B17,'[3]Hoja2 (2)'!$A:$E,5,0) -> 165.36 | J17: =(L17*4%)+L17 -> 165.36 | K17: 165.36 | L17: =VLOOKUP(E17,[4]TRABAJO!$H:$S,9,0) -> 159 | M17: =VLOOKUP(E17,[5]TRABAJO!$F:$S,11,0) -> 159 | N17: =VLOOKUP(E17,[6]TRABAJO!$H:$S,9,0) -> 159 | O17: =VLOOKUP(B17,[7]TRABAJO!$C:$S,14,0) -> 159 | P17: =VLOOKUP(B17,[8]TRABAJO!$C:$S,14,0) -> 159 | Q17: =VLOOKUP(B17,[9]TRABAJO!$C:$S,14,0) -> 159 | R17: =VLOOKUP(B17,[10]TRABAJO!$C:$Q,15,0) -> 159 | S17: 159 | T17: =(S17*5%)+S17 -> 166.95 | U17: =(S17*10%)+S17 -> 174.9 | V17: =VLOOKUP(B17,'[11]ZICP-MARZO'!$B:$P,15,0) -> #N/A | W17: =VLOOKUP(B17,[11]CONSOLIDADO_ABRIL!$B:$J,9,0) -> #N/A | X17: =V17-W17 -> #N/A | Y17: =VLOOKUP(B17,[11]CONSOLIDADO_MAYO!$B:$J,9,0) -> #N/A | Z17: =S17-Y17 -> #N/A
A18: NORESTE | B18: =+C18&E18 -> D82410000285 | C18: D824 | D18: MX-CANTERA LEON | E18: 10000285 | F18: Grava Triturada Basalto 10 mm - 3/8" | G18: =H18-I18 -> #N/A | H18: =VLOOKUP(E18,[2]Conciliacion!$H:$AC,22,0) -> #N/A | I18: =VLOOKUP(B18,'[3]Hoja2 (2)'!$A:$E,5,0) -> 182 | J18: =(L18*4%)+L18 -> 182 | K18: 182 | L18: =VLOOKUP(E18,[4]TRABAJO!$H:$S,9,0) -> 175 | M18: =VLOOKUP(E18,[5]TRABAJO!$F:$S,11,0) -> 175 | N18: =VLOOKUP(E18,[6]TRABAJO!$H:$S,9,0) -> 175 | O18: =VLOOKUP(B18,[7]TRABAJO!$C:$S,14,0) -> 175 | P18: =VLOOKUP(B18,[8]TRABAJO!$C:$S,14,0) -> 175 | Q18: =VLOOKUP(B18,[9]TRABAJO!$C:$S,14,0) -> 175 | R18: =VLOOKUP(B18,[10]TRABAJO!$C:$Q,15,0) -> 175 | S18: 175 | T18: =(S18*5%)+S18 -> 183.75 | U18: =(S18*10%)+S18 -> 192.5 | V18: =VLOOKUP(B18,'[11]ZICP-MARZO'!$B:$P,15,0) -> #N/A | W18: =VLOOKUP(B18,[11]CONSOLIDADO_ABRIL!$B:$J,9,0) -> #N/A | X18: =V18-W18 -> #N/A | Y18: =VLOOKUP(B18,[11]CONSOLIDADO_MAYO!$B:$J,9,0) -> #N/A | Z18: =S18-Y18 -> #N/A
A19: NORESTE | B19: =+C19&E19 -> D82410000284 | C19: D824 | D19: MX-CANTERA LEON | E19: 10000284 | F19: Grava Triturada Basalto 20 mm - 3/4" | G19: =H19-I19 -> #N/A | H19: =VLOOKUP(E19,[2]Conciliacion!$H:$AC,22,0) -> #N/A | I19: =VLOOKUP(B19,'[3]Hoja2 (2)'!$A:$E,5,0) -> 182 | J19: =(L19*4%)+L19 -> 182 | K19: 182 | L19: =VLOOKUP(E19,[4]TRABAJO!$H:$S,9,0) -> 175 | M19: =VLOOKUP(E19,[5]TRABAJO!$F:$S,11,0) -> 175 | N19: =VLOOKUP(E19,[6]TRABAJO!$H:$S,9,0) -> 175 | O19: =VLOOKUP(B19,[7]TRABAJO!$C:$S,14,0) -> 175 | P19: =VLOOKUP(B19,[8]TRABAJO!$C:$S,14,0) -> 175 | Q19: =VLOOKUP(B19,[9]TRABAJO!$C:$S,14,0) -> 175 | R19: =VLOOKUP(B19,[10]TRABAJO!$C:$Q,15,0) -> 175 | S19: 175 | T19: =(S19*5%)+S19 -> 183.75 | U19: =(S19*10%)+S19 -> 192.5 | V19: =VLOOKUP(B19,'[11]ZICP-MARZO'!$B:$P,15,0) -> #N/A | W19: =VLOOKUP(B19,[11]CONSOLIDADO_ABRIL!$B:$J,9,0) -> #N/A | X19: =V19-W19 -> #N/A | Y19: =VLOOKUP(B19,[11]CONSOLIDADO_MAYO!$B:$J,9,0) -> #N/A | Z19: =S19-Y19 -> #N/A
A20: NORESTE | B20: =+C20&E20 -> D82410000287 | C20: D824 | D20: MX-CANTERA LEON | E20: 10000287 | F20: Grava Triturada Basalto 40 mm - 1 1/2" | G20: =H20-I20 -> #N/A | H20: =VLOOKUP(E20,[2]Conciliacion!$H:$AC,22,0) -> #N/A | I20: =VLOOKUP(B20,'[3]Hoja2 (2)'!$A:$E,5,0) -> 182 | J20: =(L20*4%)+L20 -> 182 | K20: 182 | L20: =VLOOKUP(E20,[4]TRABAJO!$H:$S,9,0) -> 175 | M20: =VLOOKUP(E20,[5]TRABAJO!$F:$S,11,0) -> 175 | N20: =VLOOKUP(E20,[6]TRABAJO!$H:$S,9,0) -> 175 | O20: =VLOOKUP(B20,[7]TRABAJO!$C:$S,14,0) -> 211 | P20: =VLOOKUP(B20,[8]TRABAJO!$C:$S,14,0) -> 211.04 | Q20: =VLOOKUP(B20,[9]TRABAJO!$C:$S,14,0) -> 175 | R20: =VLOOKUP(B20,[10]TRABAJO!$C:$Q,15,0) -> 175 | S20: 175 | T20: =(S20*5%)+S20 -> 183.75 | U20: =(S20*10%)+S20 -> 192.5 | V20: =VLOOKUP(B20,'[11]ZICP-MARZO'!$B:$P,15,0) -> #N/A | W20: =VLOOKUP(B20,[11]CONSOLIDADO_ABRIL!$B:$J,9,0) -> #N/A | X20: =V20-W20 -> #N/A | Y20: =VLOOKUP(B20,[11]CONSOLIDADO_MAYO!$B:$J,9,0) -> #N/A | Z20: =S20-Y20 -> #N/A
A21: NORESTE | B21: =+C21&E21 -> D81610000124 | C21: D816 | D21: MX-CANTERA MONTERREY | E21: 10000124 | F21: Arena Triturada Caliza Malla 4 | G21: =H21-I21 -> #N/A | H21: =VLOOKUP(E21,[2]Conciliacion!$H:$AC,22,0) -> #N/A | I21: =VLOOKUP(B21,'[3]Hoja2 (2)'!$A:$E,5,0) -> 284.44 | J21: =(L21*4%)+L21 -> 284.44 | K21: 283.92 | L21: =VLOOKUP(E21,[4]TRABAJO!$H:$S,9,0) -> 273.5 | M21: =VLOOKUP(E21,[5]TRABAJO!$F:$S,11,0) -> 273.5 | N21: =VLOOKUP(E21,[6]TRABAJO!$H:$S,9,0) -> 273.5 | O21: =VLOOKUP(B21,[7]TRABAJO!$C:$S,14,0) -> 273.5 | P21: 339.91 | Q21: =VLOOKUP(B21,[9]TRABAJO!$C:$S,14,0) -> #N/A | R21: =VLOOKUP(B21,[10]TRABAJO!$C:$Q,15,0) -> 273.5 | S21: 273.5 | T21: =(S21*5%)+S21 -> 287.175 | U21: =(S21*10%)+S21 -> 300.85 | V21: =VLOOKUP(B21,'[11]ZICP-MARZO'!$B:$P,15,0) -> #N/A | W21: =VLOOKUP(B21,[11]CONSOLIDADO_ABRIL!$B:$J,9,0) -> #N/A | X21: =V21-W21 -> #N/A | Y21: =VLOOKUP(B21,[11]CONSOLIDADO_MAYO!$B:$J,9,0) -> #N/A | Z21: =S21-Y21 -> #N/A
A22: NORESTE | B22: =+C22&E22 -> D81610164169 | C22: D816 | D22: MX-CANTERA MONTERREY | E22: 10164169 | F22: ARENA TRITURADA CALIZA MALLA 4 B47 FILIA | G22: =H22-I22 -> #N/A | H22: =VLOOKUP(E22,[2]Conciliacion!$H:$AC,22,0) -> #N/A | I22: =VLOOKUP(B22,'[3]Hoja2 (2)'!$A:$E,5,0) -> 284.44 | J22: =(L22*4%)+L22 -> 284.44 | K22: 337.48 | L22: 273.5 | M22: =VLOOKUP(E22,[5]TRABAJO!$F:$S,11,0) -> 273.5 | N22: =VLOOKUP(E22,[6]TRABAJO!$H:$S,9,0) -> #N/A | O22: =VLOOKUP(B22,[7]TRABAJO!$C:$S,14,0) -> 273.5 | P22: =VLOOKUP(B22,[8]TRABAJO!$C:$S,14,0) -> 273.5 | Q22: =VLOOKUP(B22,[9]TRABAJO!$C:$S,14,0) -> 273.5 | R22: ,15,0 | S22: 273.5 | T22: =(S22*5%)+S22 -> 287.175 | U22: =(S22*10%)+S22 -> 300.85 | V22: =VLOOKUP(B22,'[11]ZICP-MARZO'!$B:$P,15,0) -> #N/A | W22: =VLOOKUP(B22,[11]CONSOLIDADO_ABRIL!$B:$J,9,0) -> #N/A | X22: =V22-W22 -> #N/A | Y22: =VLOOKUP(B22,[11]CONSOLIDADO_MAYO!$B:$J,9,0) -> #N/A | Z22: =S22-Y22 -> #N/A
A23: NORESTE | B23: =+C23&E23 -> D81610000260 | C23: D816 | D23: MX-CANTERA MONTERREY | E23: 10000260 | F23: Arena Triturada Caliza Malla 5 | G23: =H23-I23 -> #N/A | H23: =VLOOKUP(E23,[2]Conciliacion!$H:$AC,22,0) -> #N/A | I23: =VLOOKUP(B23,'[3]Hoja2 (2)'!$A:$E,5,0) -> 320.32 | J23: =(L23*4%)+L23 -> 320.32 | K23: 320.32 | L23: =VLOOKUP(E23,[4]TRABAJO!$H:$S,9,0) -> 308 | M23: =VLOOKUP(E23,[5]TRABAJO!$F:$S,11,0) -> 308 | N23: 308 | O23: =VLOOKUP(B23,[7]TRABAJO!$C:$S,14,0) -> 395.87464 | P23: =VLOOKUP(B23,[8]TRABAJO!$C:$S,14,0) -> 379.08993 | Q23: =VLOOKUP(B23,[9]TRABAJO!$C:$S,14,0) -> 395.87464 | R23: =VLOOKUP(B23,[10]TRABAJO!$C:$Q,15,0) -> 388.22985 | S23: 388 | T23: =(S23*5%)+S23 -> 407.4 | U23: =(S23*10%)+S23 -> 426.8 | V23: =VLOOKUP(B23,'[11]ZICP-MARZO'!$B:$P,15,0) -> #N/A | W23: =VLOOKUP(B23,[11]CONSOLIDADO_ABRIL!$B:$J,9,0) -> #N/A | X23: =V23-W23 -> #N/A | Y23: =VLOOKUP(B23,[11]CONSOLIDADO_MAYO!$B:$J,9,0) -> #N/A | Z23: =S23-Y23 -> #N/A
A24: NORESTE | B24: =+C24&E24 -> D81610000237 | C24: D816 | D24: MX-CANTERA MONTERREY | E24: 10000237 | F24: Grava Triturada Caliza 10 mm - 3/8" | G24: =H24-I24 -> #N/A | H24: =VLOOKUP(E24,[2]Conciliacion!$H:$AC,22,0) -> #N/A | I24: =VLOOKUP(B24,'[3]Hoja2 (2)'!$A:$E,5,0) -> 294.32 | J24: =(L24*4%)+L24 -> 294.32 | K24: 280.8 | L24: =VLOOKUP(E24,[4]TRABAJO!$H:$S,9,0) -> 283 | M24: =VLOOKUP(E24,[5]TRABAJO!$F:$S,11,0) -> 270 | N24: =VLOOKUP(E24,[6]TRABAJO!$H:$S,9,0) -> 283 | O24: =VLOOKUP(B24,[7]TRABAJO!$C:$S,14,0) -> 335.61 | P24: =VLOOKUP(B24,[8]TRABAJO!$C:$S,14,0) -> 282.6 | Q24: =VLOOKUP(B24,[9]TRABAJO!$C:$S,14,0) -> 282.6 | R24: =VLOOKUP(B24,[10]TRABAJO!$C:$Q,15,0) -> 282.6 | S24: 282.6 | T24: =(S24*5%)+S24 -> 296.73 | U24: =(S24*10%)+S24 -> 310.86 | V24: =VLOOKUP(B24,'[11]ZICP-MARZO'!$B:$P,15,0) -> #N/A | W24: =VLOOKUP(B24,[11]CONSOLIDADO_ABRIL!$B:$J,9,0) -> #N/A | X24: =V24-W24 -> #N/A | Y24: =VLOOKUP(B24,[11]CONSOLIDADO_MAYO!$B:$J,9,0) -> #N/A | Z24: =S24-Y24 -> #N/A
