Workbook

Sheet Base Cedis D898
N1: VENTA | Q1: COSTO
A2: CONCAT1 | B2: CONCAT2 | C2: No. SF | D2: Nombre SF | E2: Cedis | F2: Destino | G2: Condicion de Expedicion | H2: Nombre Destino | I2: No. de material | J2: Nombre de material | K2: PV | L2: Inicio de vigencia | M2: Fin de vigencia | N2: Importe MP | O2: Importe Flete | P2: UM Venta | Q2: Importe Costo | R2: UM Costo | S2: Validacion 1 | T2: Validacion 2
A3: =CONCATENATE(C3,E3,F3,I3) | B3: =CONCATENATE(C3,E3,I3) | C3: 900007345 | D3: =IFERROR(VLOOKUP(C3,TRAOPE!$G:$H,2,0),"") | E3: D898 | F3: DE81 | G3: =IFERROR(VLOOKUP(A3,Flete!$A:$E,5,0),"") | H3: =IFERROR(VLOOKUP(F3,TRAOPE!$AA:$AB,2,0),"") | I3: 10154700 | J3: =IFERROR(VLOOKUP(I3,Materiales!$A:$H,8,0),"") | K3: =IFERROR(VLOOKUP(I3,Materiales!$A:$G,7,0),"") | L3: 20220516 | M3: 20240531 | N3: 98.94 | O3: =IFERROR(VLOOKUP(A3,Flete!$A:$J,10,0),"") | P3: TN | Q3: =IFERROR(IFERROR(VLOOKUP(A3,TRAOPE!$A:$U,21,0),VLOOKUP(B3,TRAOPE!$A:$U,21,0)),"") | R3: =IFERROR(IFERROR(VLOOKUP(A3,TRAOPE!$A:$W,23,0),VLOOKUP(B3,TRAOPE!$A:$W,23,0)),"") | S3: =IF(AND(P3="TN",R3="TN"),N3+N(O3),IF(G3&""="1",N(K3)*N3,(N3+N(O3))*N(K3))) | T3: =IF(Q3="","",Q3-S3)
A4: =CONCATENATE(C4,E4,F4,I4) | B4: =CONCATENATE(C4,E4,I4) | C4: 900007345 | D4: =IFERROR(VLOOKUP(C4,TRAOPE!$G:$H,2,0),"") | E4: D898 | F4: DE82 | G4: =IFERROR(VLOOKUP(A4,Flete!$A:$E,5,0),"") | H4: =IFERROR(VLOOKUP(F4,TRAOPE!$AA:$AB,2,0),"") | I4: 10154700 | J4: =IFERROR(VLOOKUP(I4,Materiales!$A:$H,8,0),"") | K4: =IFERROR(VLOOKUP(I4,Materiales!$A:$G,7,0),"") | L4: 20220516 | M4: 20240531 | N4: 98.94 | O4: =IFERROR(VLOOKUP(A4,Flete!$A:$J,10,0),"") | P4: TN | Q4: =IFERROR(IFERROR(VLOOKUP(A4,TRAOPE!$A:$U,21,0),VLOOKUP(B4,TRAOPE!$A:$U,21,0)),"") | R4: =IFERROR(IFERROR(VLOOKUP(A4,TRAOPE!$A:$W,23,0),VLOOKUP(B4,TRAOPE!$A:$W,23,0)),"") | S4: =IF(AND(P4="TN",R4="TN"),N4+N(O4),IF(G4&""="1",N(K4)*N4,(N4+N(O4))*N(K4))) | T4: =IF(Q4="","",Q4-S4)
A5: =CONCATENATE(C5,E5,F5,I5) | B5: =CONCATENATE(C5,E5,I5) | C5: 900007345 | D5: =IFERROR(VLOOKUP(C5,TRAOPE!$G:$H,2,0),"") | E5: D898 | F5: DE83 | G5: =IFERROR(VLOOKUP(A5,Flete!$A:$E,5,0),"") | H5: =IFERROR(VLOOKUP(F5,TRAOPE!$AA:$AB,2,0),"") | I5: 10154700 | J5: =IFERROR(VLOOKUP(I5,Materiales!$A:$H,8,0),"") | K5: =IFERROR(VLOOKUP(I5,Materiales!$A:$G,7,0),"") | L5: 20220516 | M5: 20240531 | N5: 98.94 | O5: =IFERROR(VLOOKUP(A5,Flete!$A:$J,10,0),"") | P5: TN | Q5: =IFERROR(IFERROR(VLOOKUP(A5,TRAOPE!$A:$U,21,0),VLOOKUP(B5,TRAOPE!$A:$U,21,0)),"") | R5: =IFERROR(IFERROR(VLOOKUP(A5,TRAOPE!$A:$W,23,0),VLOOKUP(B5,TRAOPE!$A:$W,23,0)),"") | S5: =IF(AND(P5="TN",R5="TN"),N5+N(O5),IF(G5&""="1",N(K5)*N5,(N5+N(O5))*N(K5))) | T5: =IF(Q5="","",Q5-S5)
A6: =CONCATENATE(C6,E6,F6,I6) | B6: =CONCATENATE(C6,E6,I6) | C6: 900004896 | D6: =IFERROR(VLOOKUP(C6,TRAOPE!$G:$H,2,0),"") | E6: D898 | F6: 66262957 | G6: =IFERROR(VLOOKUP(A6,Flete!$A:$E,5,0),"") | H6: =IFERROR(VLOOKUP(F6,TRAOPE!$AA:$AB,2,0),"") | I6: 10127817 | J6: =IFERROR(VLOOKUP(I6,Materiales!$A:$H,8,0),"") | K6: =IFERROR(VLOOKUP(I6,Materiales!$A:$G,7,0),"") | L6: 20190426 | M6: 20250127 | N6: 84.73 | O6: =IFERROR(VLOOKUP(A6,Flete!$A:$J,10,0),"") | P6: M3 | Q6: =IFERROR(IFERROR(VLOOKUP(A6,TRAOPE!$A:$U,21,0),VLOOKUP(B6,TRAOPE!$A:$U,21,0)),"") | R6: =IFERROR(IFERROR(VLOOKUP(A6,TRAOPE!$A:$W,23,0),VLOOKUP(B6,TRAOPE!$A:$W,23,0)),"") | S6: =IF(AND(P6="TN",R6="TN"),N6+N(O6),IF(G6&""="1",N(K6)*N6,(N6+N(O6))*N(K6))) | T6: =IF(Q6="","",Q6-S6)
A7: =CONCATENATE(C7,E7,F7,I7) | B7: =CONCATENATE(C7,E7,I7) | C7: 900004896 | D7: =IFERROR(VLOOKUP(C7,TRAOPE!$G:$H,2,0),"") | E7: D898 | F7: 66263174 | G7: =IFERROR(VLOOKUP(A7,Flete!$A:$E,5,0),"") | H7: =IFERROR(VLOOKUP(F7,TRAOPE!$AA:$AB,2,0),"") | I7: 10127817 | J7: =IFERROR(VLOOKUP(I7,Materiales!$A:$H,8,0),"") | K7: =IFERROR(VLOOKUP(I7,Materiales!$A:$G,7,0),"") | L7: 20190426 | M7: 20250127 | N7: 84.73 | O7: =IFERROR(VLOOKUP(A7,Flete!$A:$J,10,0),"") | P7: M3 | Q7: =IFERROR(IFERROR(VLOOKUP(A7,TRAOPE!$A:$U,21,0),VLOOKUP(B7,TRAOPE!$A:$U,21,0)),"") | R7: =IFERROR(IFERROR(VLOOKUP(A7,TRAOPE!$A:$W,23,0),VLOOKUP(B7,TRAOPE!$A:$W,23,0)),"") | S7: =IF(AND(P7="TN",R7="TN"),N7+N(O7),IF(G7&""="1",N(K7)*N7,(N7+N(O7))*N(K7))) | T7: =IF(Q7="","",Q7-S7)
A8: =CONCATENATE(C8,E8,F8,I8) | B8: =CONCATENATE(C8,E8,I8) | C8: 900004897 | D8: =IFERROR(VLOOKUP(C8,TRAOPE!$G:$H,2,0),"") | E8: D898 | F8: 65890865 | G8: =IFERROR(VLOOKUP(A8,Flete!$A:$E,5,0),"") | H8: =IFERROR(VLOOKUP(F8,TRAOPE!$AA:$AB,2,0),"") | I8: 10128599 | J8: =IFERROR(VLOOKUP(I8,Materiales!$A:$H,8,0),"") | K8: =IFERROR(VLOOKUP(I8,Materiales!$A:$G,7,0),"") | L8: 20190426 | M8: 20250127 | N8: 137.71 | O8: =IFERROR(VLOOKUP(A8,Flete!$A:$J,10,0),"") | P8: M3 | Q8: =IFERROR(IFERROR(VLOOKUP(A8,TRAOPE!$A:$U,21,0),VLOOKUP(B8,TRAOPE!$A:$U,21,0)),"") | R8: =IFERROR(IFERROR(VLOOKUP(A8,TRAOPE!$A:$W,23,0),VLOOKUP(B8,TRAOPE!$A:$W,23,0)),"") | S8: =IF(AND(P8="TN",R8="TN"),N8+N(O8),IF(G8&""="1",N(K8)*N8,(N8+N(O8))*N(K8))) | T8: =IF(Q8="","",Q8-S8)
A9: =CONCATENATE(C9,E9,F9,I9) | B9: =CONCATENATE(C9,E9,I9) | C9: 900004897 | D9: =IFERROR(VLOOKUP(C9,TRAOPE!$G:$H,2,0),"") | E9: D898 | F9: 65890865 | G9: =IFERROR(VLOOKUP(A9,Flete!$A:$E,5,0),"") | H9: =IFERROR(VLOOKUP(F9,TRAOPE!$AA:$AB,2,0),"") | I9: 10128742 | J9: =IFERROR(VLOOKUP(I9,Materiales!$A:$H,8,0),"") | K9: =IFERROR(VLOOKUP(I9,Materiales!$A:$G,7,0),"") | L9: 20190426 | M9: 20250127 | N9: 134.71 | O9: =IFERROR(VLOOKUP(A9,Flete!$A:$J,10,0),"") | P9: M3 | Q9: =IFERROR(IFERROR(VLOOKUP(A9,TRAOPE!$A:$U,21,0),VLOOKUP(B9,TRAOPE!$A:$U,21,0)),"") | R9: =IFERROR(IFERROR(VLOOKUP(A9,TRAOPE!$A:$W,23,0),VLOOKUP(B9,TRAOPE!$A:$W,23,0)),"") | S9: =IF(AND(P9="TN",R9="TN"),N9+N(O9),IF(G9&""="1",N(K9)*N9,(N9+N(O9))*N(K9))) | T9: =IF(Q9="","",Q9-S9)
A10: =CONCATENATE(C10,E10,F10,I10) | B10: =CONCATENATE(C10,E10,I10) | C10: 900004897 | D10: =IFERROR(VLOOKUP(C10,TRAOPE!$G:$H,2,0),"") | E10: D898 | F10: 65890865 | G10: =IFERROR(VLOOKUP(A10,Flete!$A:$E,5,0),"") | H10: =IFERROR(VLOOKUP(F10,TRAOPE!$AA:$AB,2,0),"") | I10: 10128754 | J10: =IFERROR(VLOOKUP(I10,Materiales!$A:$H,8,0),"") | K10: =IFERROR(VLOOKUP(I10,Materiales!$A:$G,7,0),"") | L10: 20190426 | M10: 20250127 | N10: 129 | O10: =IFERROR(VLOOKUP(A10,Flete!$A:$J,10,0),"") | P10: M3 | Q10: =IFERROR(IFERROR(VLOOKUP(A10,TRAOPE!$A:$U,21,0),VLOOKUP(B10,TRAOPE!$A:$U,21,0)),"") | R10: =IFERROR(IFERROR(VLOOKUP(A10,TRAOPE!$A:$W,23,0),VLOOKUP(B10,TRAOPE!$A:$W,23,0)),"") | S10: =IF(AND(P10="TN",R10="TN"),N10+N(O10),IF(G10&""="1",N(K10)*N10,(N10+N(O10))*N(K10))) | T10: =IF(Q10="","",Q10-S10)
A11: =CONCATENATE(C11,E11,F11,I11) | B11: =CONCATENATE(C11,E11,I11) | C11: 900004897 | D11: =IFERROR(VLOOKUP(C11,TRAOPE!$G:$H,2,0),"") | E11: D898 | F11: 66424253 | G11: =IFERROR(VLOOKUP(A11,Flete!$A:$E,5,0),"") | H11: =IFERROR(VLOOKUP(F11,TRAOPE!$AA:$AB,2,0),"") | I11: 10128742 | J11: =IFERROR(VLOOKUP(I11,Materiales!$A:$H,8,0),"") | K11: =IFERROR(VLOOKUP(I11,Materiales!$A:$G,7,0),"") | L11: 20190426 | M11: 20250127 | N11: 160 | O11: =IFERROR(VLOOKUP(A11,Flete!$A:$J,10,0),"") | P11: M3 | Q11: =IFERROR(IFERROR(VLOOKUP(A11,TRAOPE!$A:$U,21,0),VLOOKUP(B11,TRAOPE!$A:$U,21,0)),"") | R11: =IFERROR(IFERROR(VLOOKUP(A11,TRAOPE!$A:$W,23,0),VLOOKUP(B11,TRAOPE!$A:$W,23,0)),"") | S11: =IF(AND(P11="TN",R11="TN"),N11+N(O11),IF(G11&""="1",N(K11)*N11,(N11+N(O11))*N(K11))) | T11: =IF(Q11="","",Q11-S11)
A12: =CONCATENATE(C12,E12,F12,I12) | B12: =CONCATENATE(C12,E12,I12) | C12: 900004947 | D12: =IFERROR(VLOOKUP(C12,TRAOPE!$G:$H,2,0),"") | E12: D898 | F12: 65011170 | G12: =IFERROR(VLOOKUP(A12,Flete!$A:$E,5,0),"") | H12: =IFERROR(VLOOKUP(F12,TRAOPE!$AA:$AB,2,0),"") | I12: 10136048 | J12: =IFERROR(VLOOKUP(I12,Materiales!$A:$H,8,0),"") | K12: =IFERROR(VLOOKUP(I12,Materiales!$A:$G,7,0),"") | L12: 20190426 | M12: 20250127 | N12: 180 | O12: =IFERROR(VLOOKUP(A12,Flete!$A:$J,10,0),"") | P12: M3 | Q12: =IFERROR(IFERROR(VLOOKUP(A12,TRAOPE!$A:$U,21,0),VLOOKUP(B12,TRAOPE!$A:$U,21,0)),"") | R12: =IFERROR(IFERROR(VLOOKUP(A12,TRAOPE!$A:$W,23,0),VLOOKUP(B12,TRAOPE!$A:$W,23,0)),"") | S12: =IF(AND(P12="TN",R12="TN"),N12+N(O12),IF(G12&""="1",N(K12)*N12,(N12+N(O12))*N(K12))) | T12: =IF(Q12="","",Q12-S12)
A13: =CONCATENATE(C13,E13,F13,I13) | B13: =CONCATENATE(C13,E13,I13) | C13: 900004947 | D13: =IFERROR(VLOOKUP(C13,TRAOPE!$G:$H,2,0),"") | E13: D898 | F13: 65011170 | G13: =IFERROR(VLOOKUP(A13,Flete!$A:$E,5,0),"") | H13: =IFERROR(VLOOKUP(F13,TRAOPE!$AA:$AB,2,0),"") | I13: 10136049 | J13: =IFERROR(VLOOKUP(I13,Materiales!$A:$H,8,0),"") | K13: =IFERROR(VLOOKUP(I13,Materiales!$A:$G,7,0),"") | L13: 20190426 | M13: 20250127 | N13: 190 | O13: =IFERROR(VLOOKUP(A13,Flete!$A:$J,10,0),"") | P13: M3 | Q13: =IFERROR(IFERROR(VLOOKUP(A13,TRAOPE!$A:$U,21,0),VLOOKUP(B13,TRAOPE!$A:$U,21,0)),"") | R13: =IFERROR(IFERROR(VLOOKUP(A13,TRAOPE!$A:$W,23,0),VLOOKUP(B13,TRAOPE!$A:$W,23,0)),"") | S13: =IF(AND(P13="TN",R13="TN"),N13+N(O13),IF(G13&""="1",N(K13)*N13,(N13+N(O13))*N(K13))) | T13: =IF(Q13="","",Q13-S13)
A14: =CONCATENATE(C14,E14,F14,I14) | B14: =CONCATENATE(C14,E14,I14) | C14: 900004947 | D14: =IFERROR(VLOOKUP(C14,TRAOPE!$G:$H,2,0),"") | E14: D898 | F14: 65011170 | G14: =IFERROR(VLOOKUP(A14,Flete!$A:$E,5,0),"") | H14: =IFERROR(VLOOKUP(F14,TRAOPE!$AA:$AB,2,0),"") | I14: 10136441 | J14: =IFERROR(VLOOKUP(I14,Materiales!$A:$H,8,0),"") | K14: =IFERROR(VLOOKUP(I14,Materiales!$A:$G,7,0),"") | L14: 20190426 | M14: 20250127 | N14: 180 | O14: =IFERROR(VLOOKUP(A14,Flete!$A:$J,10,0),"") | P14: M3 | Q14: =IFERROR(IFERROR(VLOOKUP(A14,TRAOPE!$A:$U,21,0),VLOOKUP(B14,TRAOPE!$A:$U,21,0)),"") | R14: =IFERROR(IFERROR(VLOOKUP(A14,TRAOPE!$A:$W,23,0),VLOOKUP(B14,TRAOPE!$A:$W,23,0)),"") | S14: =IF(AND(P14="TN",R14="TN"),N14+N(O14),IF(G14&""="1",N(K14)*N14,(N14+N(O14))*N(K14))) | T14: =IF(Q14="","",Q14-S14)
... A72: =CONCATENATE(C72,E72,F72,I72) | B72: =CONCATENATE(C72,E72,I72) | C72: 900004947 | D72: =IFERROR(VLOOKUP(C72,TRAOPE!$G:$H,2,0),"") | E72: D898 | F72: 65784437 | G72: =IFERROR(VLOOKUP(A72,Flete!$A:$E,5,0),"") | H72: =IFERROR(VLOOKUP(F72,TRAOPE!$AA:$AB,2,0),"") | I72: 10136441 | J72: =IFERROR(VLOOKUP(I72,Materiales!$A:$H,8,0),"") | K72: =IFERROR(VLOOKUP(I72,Materiales!$A:$G,7,0),"") | L72: 20250528 | M72: 20250710 | N72: 197.4 | O72: =IFERROR(VLOOKUP(A72,Flete!$A:$J,10,0),"") | P72: M3 | Q72: =IFERROR(IFERROR(VLOOKUP(A72,TRAOPE!$A:$U,21,0),VLOOKUP(B72,TRAOPE!$A:$U,21,0)),"") | R72: =IFERROR(IFERROR(VLOOKUP(A72,TRAOPE!$A:$W,23,0),VLOOKUP(B72,TRAOPE!$A:$W,23,0)),"") | S72: =IF(AND(P72="TN",R72="TN"),N72+N(O72),IF(G72&""="1",N(K72)*N72,(N72+N(O72))*N(K72))) | T72: =IF(Q72="","",Q72-S72)

Sheet MP
A1: No. SF | B1: Cedis | C1: Destino | D1: No. Material | E1: Nombre Material | F1: Importe MP | G1: Moneda | H1: Cantidad | I1: UM | J1: C | K1: Inicio Vigencia | L1: Fin Vigencia
A2: 900007345 | B2: D898 | C2: DE81 | D2: 10154700 | F2: 98.94 | I2: TN | K2: 20220516 | L2: 20240531
A3: 900007345 | B3: D898 | C3: DE82 | D3: 10154700 | F3: 98.94 | I3: TN | K3: 20220516 | L3: 20240531
A4: 900007345 | B4: D898 | C4: DE83 | D4: 10154700 | F4: 98.94 | I4: TN | K4: 20220516 | L4: 20240531
A5: 900004896 | B5: D898 | C5: 66262957 | D5: 10127817 | F5: 84.73 | I5: M3 | K5: 20190426 | L5: 20250127
A6: 900004896 | B6: D898 | C6: 66263174 | D6: 10127817 | F6: 84.73 | I6: M3 | K6: 20190426 | L6: 20250127
A7: 900004897 | B7: D898 | C7: 65890865 | D7: 10128599 | F7: 137.71 | I7: M3 | K7: 20190426 | L7: 20250127
A8: 900004897 | B8: D898 | C8: 65890865 | D8: 10128742 | F8: 134.71 | I8: M3 | K8: 20190426 | L8: 20250127
A9: 900004897 | B9: D898 | C9: 65890865 | D9: 10128754 | F9: 129 | I9: M3 | K9: 20190426 | L9: 20250127
A10: 900004897 | B10: D898 | C10: 66424253 | D10: 10128742 | F10: 160 | I10: M3 | K10: 20190426 | L10: 20250127
A11: 900004947 | B11: D898 | C11: 65011170 | D11: 10136048 | F11: 180 | I11: M3 | K11: 20190426 | L11: 20250127
A12: 900004947 | B12: D898 | C12: 65011170 | D12: 10136049 | F12: 190 | I12: M3 | K12: 20190426 | L12: 20250127
A13: 900004947 | B13: D898 | C13: 65011170 | D13: 10136441 | F13: 180 | I13: M3 | K13: 20190426 | L13: 20250127
... A71: 900004947 | B71: D898 | C71: 65784437 | D71: 10136441 | F71: 197.4 | I71: M3 | K71: 20250528 | L71: 20250710

Sheet Flete
A1: Concat1 | B1: No. SF | C1: Cedis | D1: Destino | E1: Cond. Exp. | F1: Material | H1: Nombre Material | J1: Importe Flete | K1: Moneda | L1: Cantidad | M1: UM | N1: C | P1: Inicio Vigencia | Q1: Fin Vigencia
A2: 900004896D8986626295710127817 | B2: 900004896 | C2: D898 | D2: 66262957 | E2: 1 | F2: 10127817 | J2: 226.98 | M2: M3 | P2: 20190426 | Q2: 20250127
A3: 900004896D8986626317410127817 | B3: 900004896 | C3: D898 | D3: 66263174 | E3: 1 | F3: 10127817 | J3: 244.14 | M3: M3 | P3: 20190426 | Q3: 20250127
A4: 900004897D8986589086510128599 | B4: 900004897 | C4: D898 | D4: 65890865 | E4: 1 | F4: 10128599 | J4: 83.14 | M4: M3 | P4: 20190426 | Q4: 20250127
A5: 900004897D8986589086510128742 | B5: 900004897 | C5: D898 | D5: 65890865 | E5: 1 | F5: 10128742 | J5: 83.14 | M5: M3 | P5: 20190426 | Q5: 20250127
A6: 900004897D8986589086510128754 | B6: 900004897 | C6: D898 | D6: 65890865 | E6: 1 | F6: 10128754 | J6: 83.14 | M6: M3 | P6: 20190426 | Q6: 20250127
A7: 900004897D8986642425310128742 | B7: 900004897 | C7: D898 | D7: 66424253 | E7: 1 | F7: 10128742 | J7: 191.62 | M7: M3 | P7: 20190426 | Q7: 20250127
A8: 900004947D8986589086510136048 | B8: 900004947 | C8: D898 | D8: 65890865 | E8: 1 | F8: 10136048 | J8: 83.14 | M8: M3 | P8: 20190426 | Q8: 20250127
A9: 900004947D8986589086510136049 | B9: 900004947 | C9: D898 | D9: 65890865 | E9: 1 | F9: 10136049 | J9: 83.14 | M9: M3 | P9: 20190426 | Q9: 20250127
A10: 900004947D8986589086510136441 | B10: 900004947 | C10: D898 | D10: 65890865 | E10: 1 | F10: 10136441 | J10: 83.14 | M10: M3 | P10: 20190426 | Q10: 20250127
A11: 900004947D8986642425310136441 | B11: 900004947 | C11: D898 | D11: 66424253 | E11: 1 | F11: 10136441 | J11: 191.62 | M11: M3 | P11: 20190426 | Q11: 20250127
A12: 900004947D8986645398210145986 | B12: 900004947 | C12: D898 | D12: 66453982 | E12: 1 | F12: 10145986 | J12: 128.57 | M12: M3 | P12: 20190426 | Q12: 20250127
A13: 900004947D8986682183410000432 | B13: 900004947 | C13: D898 | D13: 66821834 | E13: 1 | F13: 10000432 | J13: 100 | M13: M3 | P13: 20190426 | Q13: 20250127
... A27: 900009575D8986738180510128597 | B27: 900009575 | C27: D898 | D27: 67381805 | E27: 4 | F27: 10128597 | J27: 72 | M27: M3 | P27: 20260701 | Q27: 99991231

Sheet Materiales
A1: Material | B1: TpMt | C1: Denom | D1: UMA | E1: Contador | F1: UMB | G1: PV | H1: Nombre Material
A2: 10000001 | B2: ZFER | C2: 1000 | D2: M3 | E2: 1000 | F2: TN | G2: 1262 | H2: GRAVA ANDESITA 10 MM (3/8")
A3: 10000003 | B3: ZFER | C3: 1000 | D3: M3 | E3: 1000 | F3: TN | G3: 1443 | H3: GRAVA CALIZA 10 MM (3/8")
A4: 10000006 | B4: ZFER | C4: 1000 | D4: M3 | E4: 1000 | F4: TN | G4: 1490 | H4: GRAVA RIO 10 MM (3/8")
A5: 10000007 | B5: ZFER | C5: 1000 | D5: M3 | E5: 1000 | F5: TN | G5: 1488 | H5: GRAVA BASALTO 13 MM (1/2")
A6: 10000008 | B6: ZFER | C6: 1000 | D6: M3 | E6: 1000 | F6: TN | G6: 1358 | H6: GRAVA CALIZA 13 MM (1/2")
A7: 10000011 | B7: ZFER | C7: 1000 | D7: M3 | E7: 1000 | F7: TN | G7: 1323 | H7: GRAVA ANDESITA 20 MM (3/4")
A8: 10000013 | B8: ZFER | C8: 1000 | D8: M3 | E8: 1000 | F8: TN | G8: 1514 | H8: GRAVA BASALTO 20 MM (3/4")
A9: 10000014 | B9: ZFER | C9: 1000 | D9: M3 | E9: 1000 | F9: TN | G9: 1400 | H9: GRAVA CALIZA 20 MM (3/4")
A10: 10000015 | B10: ZFER | C10: 1000 | D10: M3 | E10: 1000 | F10: TN | G10: 1410 | H10: GRAVA GRANITO 20 MM (3/4")
A11: 10000017 | B11: ZFER | C11: 1000 | D11: M3 | E11: 1000 | F11: TN | G11: 1475 | H11: GRAVA RIOLITA 20 MM (3/4")
A12: 10000019 | B12: ZFER | C12: 1000 | D12: M3 | E12: 1000 | F12: TN | G12: 1515 | H12: GRAVA RIO 20 MM (3/4")
A13: 10000020 | B13: ZFER | C13: 1000 | D13: M3 | E13: 1 | F13: TN | G13: 1 | H13: GRAVA MAQUILA 40MM (1 1/2")
... A2291: 10268770 | B2291: ZFE3 | C2291: 1000 | D2291: M3 | E2291: 1000 | F2291: TN | G2291: 1240 | H2291: MP GRAVA TRIT CALIZA 40MM 1 1/2" - ESP
A2292: 10268901 | B2292: ZFE3 | C2292: 1000 | D2292: M3 | E2292: 1000 | G2292: 1560 | H2292: MP GRAVA ANDESITA GRIS 3/4" - CAPADA
A2293: 10267983 | C2293: 1000 | G2293: 1800 | H2293: ESCORIA ALTO HORNO 3/4
A2294: 10268996 | C2294: 1000 | G2294: 1329 | H2294: GRAVA TRITURADA CALIZA 40 MM - 11/2"
A2295: 10269072 | C2295: 1000 | G2295: 1700 | H2295: BASE HIDRÁULICA SCREEN
A2296: 10269225 | B2296: ZFE3 | C2296: 1000 | D2296: M3 | E2296: 1000 | G2296: 1289 | H2296: MP ARENA CALIZA LAVADA MALLA 4 - DELTA I
A2297: 10269245 | B2297: ZFE3 | C2297: 1000 | D2297: M3 | E2297: 1000 | G2297: 1410 | H2297: MP GRAVA TRITURADA CALIZA 3/8 - 10MM
A2298: 10269246 | B2298: ZFE3 | C2298: 1000 | D2298: M3 | E2298: 1000 | G2298: 1400 | H2298: MP GRAVA TRITURADA CALIZA 1 1/2 - 40MM
A2299: 10269247 | B2299: ZFE3 | C2299: 1000 | D2299: M3 | E2299: 1000 | G2299: 1560 | H2299: MP ARENA TRIT CALIZA M-4
A2300: 10270431 | B2300: ZFE3 | C2300: 1000 | D2300: M3 | E2300: 1000 | G2300: 1423 | H2300: MP GRAVA RIOLITA 13 MM - 1/2"
A2301: 10270898 | B2301: ZFE3 | C2301: 1000 | D2301: M3 | E2301: 1000 | G2301: 1551 | H2301: MP BASE H. TRIT. BASALTO 1 1/2" A FINOS
A2302: 10270911 | B2302: ZFE3 | C2302: 1000 | D2302: M3 | E2302: 1000 | G2302: 1360 | H2302: MP GRAVA TRIT. BASALTO 40 MM - 1 1/2"
A2303: 10270912 | B2303: ZFE3 | C2303: 1000 | D2303: M3 | E2303: 1000 | G2303: 1589 | H2303: MP ARENA TRIT. BASALTO MALLA 4
A2304: 10270913 | B2304: ZFE3 | C2304: 1000 | D2304: M3 | E2304: 1000 | G2304: 1395 | H2304: MP GRAVA TRIT. BASALTO 20 MM - 3/4
A2305: 10270914 | B2305: ZFE3 | C2305: 1000 | D2305: M3 | E2305: 1000 | G2305: 1623 | H2305: MP ARENA ANDESITA BC
A2306: 10270824 | B2306: M3 | C2306: 1000 | D2306: M3 | E2306: 10007640 | G2306: 1325 | H2306: MP ARENA TRITURADA CALIZA MALLA 5
A2307: 10270825 | B2307: M3 | C2307: 1000 | D2307: M3 | E2307: 10000003 | G2307: 1242 | H2307: MP GRAVA TRITURADA CALIZA 10MM (3/8”)
... A2319: 10272527 | B2319: ZFE3 | C2319: 1000 | D2319: M3 | E2319: 1000 | G2319: 1620 | H2319: CNC - NO CLASIFICADO
A2320: 10000332 | C2320: 1000 | D2320: M3 | E2320: 1000 | G2320: 800 | H2320: Grava Triturada Pomez - Jal 20 mm - 3/4"
A2321: 10273001 | B2321: ZFE3 | C2321: 1000 | D2321: M3 | E2321: 1000 | G2321: 1688 | H2321: MP ARENA TRIT. BASALTO MALLA 4
A2322: 10273002 | B2322: ZFE3 | C2322: 1000 | D2322: M3 | E2322: 1000 | G2322: 1466 | H2322: MP GRAVA TRIT. BASALTO 20 MM - 3/4"
A2323: 10273351 | B2323: ZFE3 | C2323: 1000 | D2323: M3 | E2323: 1000 | G2323: 1612 | H2323: MP ARENA TRIT. CALIZA MALLA 4
A2324: 10273352 | B2324: ZFE3 | C2324: 1000 | D2324: M3 | E2324: 1000 | G2324: 1492 | H2324: MP GRAVA TRIT. CALIZA 20 MM - 3/4"
A2325: 10271724 | B2325: ZFE3 | C2325: 1000 | D2325: M3 | E2325: 1000 | G2325: 1900 | H2325: MP RESIDUO DE CONCRETO
A2326: 10000677 | C2326: 1000 | D2326: M3 | G2326: 1164 | H2326: Grava Triturada Caliza 20 mm - 3/4"
A2327: 10274190 | B2327: ZFE3 | C2327: 1000 | D2327: M3 | E2327: 1000 | G2327: 1800 | H2327: MP BASE HIDRAULICA ANDESITA 70-30
A2328: 10274601 | B2328: ZFE3 | C2328: 1000 | D2328: M3 | E2328: 1000 | G2328: 1447 | H2328: MP ARENA BASALTO N° 4
...

Sheet TRAOPE
A1: Concat1 | B1: Contrato_Pos | C1: Doc. Compras | D1: Pos | E1: Org.compras | F1: Grp-Compr. | G1: Ship From | H1: Nombre SF | I1: Proveedor | J1: Nombre Prov | K1: Cond. Pago | L1: Descr. Cond Pago | M1: Material | N1: Descripción | O1: Centro | P1: Descripción Centro | Q1: In.perído validez | R1: Fin perído validez | S1: Válido de | T1: Validez a | U1: Precio neto pedido | V1: Moneda | W1: UM Precio Pedido | X1: Importe Condición | Y1: Moneda KONP | Z1: UM Ctd Base | AA1: Destino | AB1: Nombre Destino | AC1: Cuenta de mayor | AD1: Centro de costo | AE1: Cond. Exp. | AF1: Descr. Cond. Exp. | AG1: Peso Vol. | AH1: UMB | AI1: Ind. Oblig. Conf. Ped. | AJ1: Ctrl-Conf. | AK1: IVA | AL1: Modif_Date | AM1: Ruta
A2: 900009575D8986738180510128597 | B2: 4600072351-10 | C2: 4600072351 | D2: 10 | E2: MXPO | F2: MXL | G2: 900009575 | H2: SF TP-ED EL NARANJITO | I2: 5001837 | J2: SINDICATO DE TRAB DE CRIBAS CLASIF | K2: Z03 | L2: (AP) 15 Dias | M2: 10128597 | N2: GRAVA TRITURADA RIO 20 MM - 3/4" | O2: D898 | P2: MX-CED. MICHOACAN | Q2: 20260701 | R2: 20301231 | S2: 20260701 | T2: 20301231 | U2: 575 | V2: MXN | W2: M3 | X2: 72 | Y2: MXN | Z2: M3 | AA2: 67381805 | AB2: AGREGADOS PLANTA GAMI PLC | AC2: 56103637 | AD2: 6622841540 | AE2: 4 | AF2: ENTREGA DIRECTA | AG2: 1.531 | AH2: M3 | AI2: X | AJ2: 4 | AK2: V4 | AL2: 20260707 | AM2: D898-900009575-67381805-10128597-4
A3: 900009575D8986738180510128595 | B3: 4600072351-20 | C3: 4600072351 | D3: 20 | E3: MXPO | F3: MXL | G3: 900009575 | H3: SF TP-ED EL NARANJITO | I3: 5001837 | J3: SINDICATO DE TRAB DE CRIBAS CLASIF | K3: Z03 | L3: (AP) 15 Dias | M3: 10128595 | N3: ARENA CLASIFICADA RIO MALLA 4 | O3: D898 | P3: MX-CED. MICHOACAN | Q3: 20260701 | R3: 20301231 | S3: 20260701 | T3: 20301231 | U3: 575 | V3: MXN | W3: M3 | X3: 72 | Y3: MXN | Z3: M3 | AA3: 67381805 | AB3: AGREGADOS PLANTA GAMI PLC | AC3: 56103638 | AD3: 6622841540 | AE3: 4 | AF3: ENTREGA DIRECTA | AG3: 1.575 | AH3: M3 | AI3: X | AJ3: 4 | AK3: V4 | AL3: 20260707 | AM3: D898-900009575-67381805-10128595-4
A4: 900006937D89810194398 | B4: 4600071219-10 | C4: 4600071219 | D4: 10 | E4: MXPO | F4: MXL | G4: 900006937 | H4: SF TP-CONSTRU VARGAS | I4: 5079830 | J4: CONSTRU VARGAS SA DE CV | K4: Z09 | L4: (AP) 90 Dias | M4: 10194398 | N4: ARENA CRIBADA VOLCANICA MALLA 4 | O4: D898 | P4: MX-CED. MICHOACAN | Q4: 20250507 | R4: 20301231 | S4: 20250507 | T4: 20301231 | U4: 168 | V4: MXN | W4: M3 | X4: 0 | Y4: MXN | Z4: M3 | AC4: 56103638 | AD4: 6622841540 | AE4: 1 | AF4: ENTREGADO | AG4: 1.443 | AH4: M3 | AI4: X | AJ4: 4 | AK4: V4 | AL4: 20250509 | AM4: D898-900006937-10194398
A5: 900004947D89810136047 | B5: 4600035702-10 | C5: 4600035702 | D5: 10 | E5: MXPO | F5: MXL | G5: 900004947 | H5: TP-TRICKAL | I5: 5065198 | J5: TRITURADOS PETREOS TRICKAL | K5: Z07 | L5: (AP) 60 Dias | M5: 10136047 | N5: ARENA TRITURADA BASALTO MALLA 4 | O5: D898 | P5: MX-CED. MICHOACAN | Q5: 20161027 | R5: 20261231 | S5: 20190215 | T5: 20241231 | U5: 130 | V5: MXN | W5: M3 | X5: 0 | Y5: MXN | Z5: M3 | AC5: 56103638 | AD5: 6622841540 | AE5: 1 | AF5: ENTREGADO | AG5: 1.516 | AH5: M3 | AI5: X | AJ5: 4 | AK5: V4 | AL5: 20230920 | AM5: D898-900004947-10136047
A6: 900004947D89810145986 | B6: 4600035702-80 | C6: 4600035702 | D6: 80 | E6: MXPO | F6: MXL | G6: 900004947 | H6: TP-TRICKAL | I6: 5065198 | J6: TRITURADOS PETREOS TRICKAL | K6: Z07 | L6: (AP) 60 Dias | M6: 10145986 | N6: PIEDRA PICADA DE 30 CM A 60 CM | O6: D898 | P6: MX-CED. MICHOACAN | Q6: 20161027 | R6: 20261231 | S6: 20181023 | T6: 20241231 | U6: 150 | V6: MXN | W6: M3 | X6: 0 | Y6: MXN | Z6: M3 | AC6: 56103637 | AD6: 6622841540 | AE6: 1 | AF6: ENTREGADO | AG6: 1.5 | AH6: M3 | AI6: X | AJ6: 4 | AK6: V4 | AL6: 20230920 | AM6: D898-900004947-10145986
A7: 900004947D89810159061 | B7: 4600035702-90 | C7: 4600035702 | D7: 90 | E7: MXPO | F7: MXL | G7: 900004947 | H7: TP-TRICKAL | I7: 5065198 | J7: TRITURADOS PETREOS TRICKAL | K7: Z07 | L7: (AP) 60 Dias | M7: 10159061 | N7: SUB-BALASTO TRITURADO BASALTO | O7: D898 | P7: MX-CED. MICHOACAN | Q7: 20161027 | R7: 20261231 | S7: 20180928 | T7: 20241231 | U7: 170 | V7: MXN | W7: M3 | X7: 0 | Y7: MXN | Z7: M3 | AC7: 56103590 | AD7: 6622841540 | AE7: 1 | AF7: ENTREGADO | AG7: 1.6 | AH7: M3 | AI7: X | AJ7: 4 | AK7: V4 | AL7: 20230920 | AM7: D898-900004947-10159061
A8: 900005871D89810127817 | B8: 4600043362-10 | C8: 4600043362 | D8: 10 | E8: MXPO | F8: MXL | G8: 900005871 | H8: SF TP-MARCO III | I8: 5073739 | J8: ESCOBEDO HERNANDEZ HECTOR | K8: Z00 | L8: (AP) Pagadero Inmediatamente | M8: 10127817 | N8: ARENA CLASIFICADA VOLCANICA MALLA 4 | O8: D898 | P8: MX-CED. MICHOACAN | Q8: 20181112 | R8: 20241231 | S8: 20190212 | T8: 20241231 | U8: 108 | V8: MXN | W8: M3 | X8: 0 | Y8: MXN | Z8: M3 | AC8: 56103638 | AD8: 6622841540 | AE8: 1 | AF8: ENTREGADO | AG8: 1.517 | AH8: M3 | AI8: X | AJ8: 4 | AK8: V4 | AL8: 20230920 | AM8: D898-900005871-10127817
A9: 900005431D89810128599 | B9: 4600041059-20 | C9: 4600041059 | D9: 20 | E9: MXPO | F9: MXL | G9: 900005431 | H9: TP-MESON NUEVO II | I9: 5041348 | J9: GRUPO EDIFICADOR GENESIS SA DE CV | K9: Z03 | L9: (AP) 15 Dias | M9: 10128599 | N9: GRAVA TRITURADA BASALTO 10 MM - 3/8" | O9: D898 | P9: MX-CED. MICHOACAN | Q9: 20180130 | R9: 20241231 | S9: 20190201 | T9: 20241231 | U9: 176 | V9: MXN | W9: M3 | X9: 0 | Y9: MXN | Z9: M3 | AC9: 56103637 | AD9: 6622841540 | AE9: 1 | AF9: ENTREGADO | AG9: 1.48 | AH9: M3 | AI9: X | AJ9: 4 | AK9: V4 | AL9: 20230920 | AM9: D898-900005431-10128599
A10: 900005380D89810127817 | B10: 4600042857-10 | C10: 4600042857 | D10: 10 | E10: MXPO | F10: MXL | G10: 900005380 | H10: TP-MARCO II | I10: 5069139 | J10: HUIPE MADRIGAL JUAN | K10: Z04 | L10: (AP) 30 Dias | M10: 10127817 | N10: ARENA CLASIFICADA VOLCANICA MALLA 4 | O10: D898 | P10: MX-CED. MICHOACAN | Q10: 20180829 | R10: 20241231 | S10: 20180829 | T10: 20241231 | U10: 103 | V10: MXN | W10: M3 | X10: 0 | Y10: MXN | Z10: M3 | AC10: 56103638 | AD10: 6622841540 | AE10: 1 | AF10: ENTREGADO | AG10: 1.517 | AH10: M3 | AI10: X | AJ10: 4 | AK10: V4 | AL10: 20230920 | AM10: D898-900005380-10127817
A11: 900004947D89810145835 | B11: 4600035702-70 | C11: 4600035702 | D11: 70 | E11: MXPO | F11: MXL | G11: 900004947 | H11: TP-TRICKAL | I11: 5065198 | J11: TRITURADOS PETREOS TRICKAL | K11: Z07 | L11: (AP) 60 Dias | M11: 10145835 | N11: BALASTO TRITURADO BASALTO | O11: D898 | P11: MX-CED. MICHOACAN | Q11: 20161027 | R11: 20261231 | S11: 20191108 | T11: 20241231 | U11: 153 | V11: MXN | W11: M3 | X11: 0 | Y11: MXN | Z11: M3 | AC11: 56103591 | AD11: 6622841540 | AE11: 1 | AF11: ENTREGADO | AG11: 1.38 | AH11: M3 | AI11: X | AJ11: 4 | AK11: V4 | AL11: 20230920 | AM11: D898-900004947-10145835
A12: 900005598D89810128749 | B12: 4600041992-20 | C12: 4600041992 | D12: 20 | E12: MXPO | F12: MXL | G12: 900005598 | H12: TP-LA TAPATIA | I12: 5071134 | J12: TRITURADOS TAPATIA S DE RL DE CV | K12: Z09 | L12: (AP) 90 Dias | M12: 10128749 | N12: GRAVA TRITURADA BASALTO 20 MM - 3/4" | O12: D898 | P12: MX-CED. MICHOACAN | Q12: 20180503 | R12: 20241231 | S12: 20190201 | T12: 20241231 | U12: 170 | V12: MXN | W12: M3 | X12: 0 | Y12: MXN | Z12: M3 | AC12: 56103637 | AD12: 6622841540 | AE12: 1 | AF12: ENTREGADO | AG12: 1.312 | AH12: M3 | AI12: X | AJ12: 4 | AK12: V4 | AL12: 20230920 | AM12: D898-900005598-10128749
A13: 900005598D89810136047 | B13: 4600041992-30 | C13: 4600041992 | D13: 30 | E13: MXPO | F13: MXL | G13: 900005598 | H13: TP-LA TAPATIA | I13: 5071134 | J13: TRITURADOS TAPATIA S DE RL DE CV | K13: Z09 | L13: (AP) 90 Dias | M13: 10136047 | N13: ARENA TRITURADA BASALTO MALLA 4 | O13: D898 | P13: MX-CED. MICHOACAN | Q13: 20180503 | R13: 20241231 | S13: 20190201 | T13: 20241231 | U13: 170 | V13: MXN | W13: M3 | X13: 0 | Y13: MXN | Z13: M3 | AC13: 56103638 | AD13: 6622841540 | AE13: 1 | AF13: ENTREGADO | AG13: 1.516 | AH13: M3 | AI13: X | AJ13: 4 | AK13: V4 | AL13: 20230920 | AM13: D898-900005598-10136047
A14: 900005430D89810128742 | B14: 4600040287-20 | C14: 4600040287 | D14: 20 | E14: MXPO | F14: MXL | G14: 900005430 | H14: TC-MESON NUEVO II | I14: 5041348 | J14: GRUPO EDIFICADOR GENESIS SA DE CV | K14: Z03 | L14: (AP) 15 Dias | M14: 10128742 | N14: GRAVA TRITURADA BASALTO 20 MM - 3/4" | O14: D898 | P14: MX-CED. MICHOACAN | Q14: 20171101 | R14: 20241231 | S14: 20190201 | T14: 20241231 | U14: 166 | V14: MXN | W14: M3 | X14: 0 | Y14: MXN | Z14: M3 | AC14: 56103637 | AD14: 6622841540 | AE14: 1 | AF14: ENTREGADO | AG14: 1.411 | AH14: M3 | AI14: X | AJ14: 4 | AK14: V4 | AL14: 20230920 | AM14: D898-900005430-10128742
A15: 900004950D89810002802 | B15: 4600040990-10 | C15: 4600040990 | D15: 10 | E15: MXPO | F15: MXL | G15: 900004950 | H15: TP-BALM | I15: 5065535 | J15: PROYECTOS INTEGRALES DE | K15: Z09 | L15: (AP) 90 Dias | M15: 10002802 | N15: Arena Clasificada Río Malla 4 Lavado | O15: D898 | P15: MX-CED. MICHOACAN | Q15: 20180122 | R15: 20241231 | S15: 20180122 | T15: 20241231 | U15: 128 | V15: MXN | W15: M3 | X15: 0 | Y15: MXN | Z15: M3 | AC15: 56103638 | AD15: 6622841540 | AE15: 1 | AF15: ENTREGADO | AG15: 1.463 | AH15: M3 | AI15: X | AJ15: 4 | AK15: V4 | AL15: 20230920 | AM15: D898-900004950-10002802
... A24: 900005430D89810128754 | B24: 4600040287-30 | C24: 4600040287 | D24: 30 | E24: MXPO | F24: MXL | G24: 900005430 | H24: TC-MESON NUEVO II | I24: 5041348 | J24: GRUPO EDIFICADOR GENESIS SA DE CV | K24: Z03 | L24: (AP) 15 Dias | M24: 10128754 | N24: GRAVA TRITURADA BASALTO 40 MM - 1 1/2" | O24: D898 | P24: MX-CED. MICHOACAN | Q24: 20171101 | R24: 20241231 | S24: 20190201 | T24: 20241231 | U24: 166 | V24: MXN | W24: M3 | X24: 0 | Y24: MXN | Z24: M3 | AC24: 56103637 | AD24: 6622841540 | AE24: 1 | AF24: ENTREGADO | AG24: 1.47 | AH24: M3 | AI24: X | AJ24: 4 | AK24: V4 | AL24: 20230920 | AM24: D898-900005430-10128754
A25: 900006803D89810128748 | B25: 4600048015-10 | C25: 4600048015 | D25: 10 | E25: MXPO | F25: MXL | G25: 900006803 | H25: SF TP-VILLAMAR PLAYCON | I25: 5069613 | J25: CONSTRUCCIONES Y PROYECTOS PLAYCON | K25: N90 | L25: (AP) NAFIN 90 Dias | M25: 10128748 | N25: GRAVA TRITURADA BASALTO 20 MM - 3/4" | O25: D898 | P25: MX-CED. MICHOACAN | Q25: 20200910 | R25: 20291231 | S25: 20210205 | T25: 20291231 | U25: 186.68 | V25: MXN | W25: M3 | AC25: 56103637 | AD25: 6622841540 | AE25: 1 | AF25: ENTREGADO | AG25: 1.382 | AH25: M3 | AI25: X | AJ25: 4 | AK25: V4 | AL25: 20230920 | AM25: D898-900006803-10128748
A26: 900005545D89810136047 | B26: 4600041241-30 | C26: 4600041241 | D26: 30 | E26: MXPO | F26: MXL | G26: 900005545 | H26: TP-MACIAS | I26: 5005851 | J26: INFRAESTRUCTURA LOGISTICA SA DE CV | K26: N90 | L26: (AP) NAFIN 90 Dias | M26: 10136047 | N26: ARENA TRITURADA BASALTO MALLA 4 | O26: D898 | P26: MX-CED. MICHOACAN | Q26: 20180216 | R26: 20291231 | U26: 103.5 | V26: MXN | W26: M3 | AC26: 56103638 | AD26: 6622841540 | AE26: 1 | AF26: ENTREGADO | AG26: 1.516 | AH26: M3 | AI26: X | AJ26: 4 | AK26: V4 | AL26: 20230920 | AM26: D898-900005545-10136047
A27: 900004947D89810267899 | B27: 4600035702-100 | C27: 4600035702 | D27: 100 | E27: MXPO | F27: MXL | G27: 900004947 | H27: TP-TRICKAL | I27: 5065198 | J27: TRITURADOS PETREOS TRICKAL | K27: Z07 | L27: (AP) 60 Dias | M27: 10267899 | N27: MP ARENA TRIT. BASALTO 3/16 A FINOS | O27: D898 | P27: MX-CED. MICHOACAN | Q27: 20161027 | R27: 20261231 | S27: 20250623 | T27: 20301231 | U27: 120 | V27: MXN | W27: M3 | X27: 0 | Y27: MXN | Z27: M3 | AC27: 56103638 | AD27: 6622841540 | AE27: 1 | AF27: ENTREGADO | AG27: 1.58 | AH27: M3 | AI27: X | AJ27: 4 | AK27: V4 | AL27: 20250625 | AM27: D898-900004947-10267899
A28: 900004947D89810267961 | B28: 4600035702-110 | C28: 4600035702 | D28: 110 | E28: MXPO | F28: MXL | G28: 900004947 | H28: TP-TRICKAL | I28: 5065198 | J28: TRITURADOS PETREOS TRICKAL | K28: Z07 | L28: (AP) 60 Dias | M28: 10267961 | N28: MP ARENA TRIT. BASALTO 1/4 A FINOS | O28: D898 | P28: MX-CED. MICHOACAN | Q28: 20161027 | R28: 20261231 | S28: 20250623 | T28: 20301231 | U28: 120 | V28: MXN | W28: M3 | X28: 0 | Y28: MXN | Z28: M3 | AC28: 56103638 | AD28: 6622841540 | AE28: 1 | AF28: ENTREGADO | AG28: 1.616 | AH28: M3 | AI28: X | AJ28: 4 | AK28: V4 | AL28: 20250625 | AM28: D898-900004947-10267961
A29: 900004947D89810136049 | B29: 4600035702-30 | C29: 4600035702 | D29: 30 | E29: MXPO | F29: MXL | G29: 900004947 | H29: TP-TRICKAL | I29: 5065198 | J29: TRITURADOS PETREOS TRICKAL | K29: Z07 | L29: (AP) 60 Dias | M29: 10136049 | N29: GRAVA TRITURADA BASALTO 10 MM - 3/8" | O29: D898 | P29: MX-CED. MICHOACAN | Q29: 20161027 | R29: 20261231 | S29: 20260305 | T29: 20301231 | U29: 210 | V29: MXN | W29: M3 | X29: 0 | Y29: MXN | Z29: M3 | AC29: 56103637 | AD29: 6622841540 | AE29: 1 | AF29: ENTREGADO | AG29: 1.343 | AH29: M3 | AI29: X | AJ29: 4 | AK29: V4 | AL29: 20260309 | AM29: D898-900004947-10136049
A30: 900004947D89810136048 | B30: 4600035702-20 | C30: 4600035702 | D30: 20 | E30: MXPO | F30: MXL | G30: 900004947 | H30: TP-TRICKAL | I30: 5065198 | J30: TRITURADOS PETREOS TRICKAL | K30: Z07 | L30: (AP) 60 Dias | M30: 10136048 | N30: GRAVA TRITURADA BASALTO 40 MM - 1 1/2" | O30: D898 | P30: MX-CED. MICHOACAN | Q30: 20161027 | R30: 20261231 | S30: 20260305 | T30: 20301231 | U30: 220 | V30: MXN | W30: M3 | X30: 0 | Y30: MXN | Z30: M3 | AC30: 56103637 | AD30: 6622841540 | AE30: 1 | AF30: ENTREGADO | AG30: 1.37 | AH30: M3 | AI30: X | AJ30: 4 | AK30: V4 | AL30: 20260309 | AM30: D898-900004947-10136048
A31: 900004947D89810136441 | B31: 4600035702-40 | C31: 4600035702 | D31: 40 | E31: MXPO | F31: MXL | G31: 900004947 | H31: TP-TRICKAL | I31: 5065198 | J31: TRITURADOS PETREOS TRICKAL | K31: Z07 | L31: (AP) 60 Dias | M31: 10136441 | N31: GRAVA TRITURADA BASALTO 20 MM - 3/4" | O31: D898 | P31: MX-CED. MICHOACAN | Q31: 20161027 | R31: 20261231 | S31: 20260305 | T31: 20301231 | U31: 220 | V31: MXN | W31: M3 | X31: 0 | Y31: MXN | Z31: M3 | AC31: 56103637 | AD31: 6622841540 | AE31: 1 | AF31: ENTREGADO | AG31: 1.41 | AH31: M3 | AI31: X | AJ31: 4 | AK31: V4 | AL31: 20260309 | AM31: D898-900004947-10136441
A32: 900005545D89810000432 | B32: 4600041241-40 | C32: 4600041241 | D32: 40 | E32: MXPO | F32: MXL | G32: 900005545 | H32: TP-MACIAS | I32: 5005851 | J32: INFRAESTRUCTURA LOGISTICA SA DE CV | K32: N90 | L32: (AP) NAFIN 90 Dias | M32: 10000432 | N32: Base H Triturada Basalto 1 1/2" a Finos | O32: D898 | P32: MX-CED. MICHOACAN | Q32: 20180216 | R32: 20291231 | U32: 157.92 | V32: MXN | W32: M3 | AC32: 56103590 | AD32: 6622841540 | AE32: 1 | AF32: ENTREGADO | AG32: 1.6 | AH32: M3 | AI32: X | AJ32: 4 | AK32: V4 | AL32: 20230920 | AM32: D898-900005545-10000432
A33: 900005325D89810128752 | B33: 4600044556-10 | C33: 4600044556 | D33: 10 | E33: MXPO | F33: MXL | G33: 900005325 | H33: TP-ED GRAVASE PONCITLAN | I33: 5009010 | J33: GRAVASE SA DE CV | K33: Z04 | L33: (AP) 30 Dias | M33: 10128752 | N33: GRAVA TRITURADA BASALTO 40 MM - 1 1/2" | O33: D898 | P33: MX-CED. MICHOACAN | Q33: 20190401 | R33: 20241231 | S33: 20190401 | T33: 20241231 | U33: 104.22 | V33: MXN | W33: TN | X33: 0 | Y33: MXN | Z33: TN | AC33: 56103637 | AD33: 6622841540 | AE33: 1 | AF33: ENTREGADO | AG33: 1 | AH33: TO | AI33: X | AJ33: 4 | AK33: V4 | AL33: 20230920 | AM33: D898-900005325-10128752
A34: 900005545D89810128752 | B34: 4600041241-20 | C34: 4600041241 | D34: 20 | E34: MXPO | F34: MXL | G34: 900005545 | H34: TP-MACIAS | I34: 5005851 | J34: INFRAESTRUCTURA LOGISTICA SA DE CV | K34: N90 | L34: (AP) NAFIN 90 Dias | M34: 10128752 | N34: GRAVA TRITURADA BASALTO 40 MM - 1 1/2" | O34: D898 | P34: MX-CED. MICHOACAN | Q34: 20180216 | R34: 20291231 | U34: 193.66 | V34: MXN | W34: M3 | AC34: 56103637 | AD34: 6622841540 | AE34: 1 | AF34: ENTREGADO | AG34: 1.41 | AH34: M3 | AI34: X | AJ34: 4 | AK34: V4 | AL34: 20230920 | AM34: D898-900005545-10128752
A35: 900005545D89810128748 | B35: 4600041241-10 | C35: 4600041241 | D35: 10 | E35: MXPO | F35: MXL | G35: 900005545 | H35: TP-MACIAS | I35: 5005851 | J35: INFRAESTRUCTURA LOGISTICA SA DE CV | K35: N90 | L35: (AP) NAFIN 90 Dias | M35: 10128748 | N35: GRAVA TRITURADA BASALTO 20 MM - 3/4" | O35: D898 | P35: MX-CED. MICHOACAN | Q35: 20180216 | R35: 20291231 | S35: 20240910 | T35: 20291231 | U35: 295 | V35: MXN | W35: M3 | X35: 0 | Y35: MXN | Z35: M3 | AC35: 56103637 | AD35: 6622841540 | AE35: 1 | AF35: ENTREGADO | AG35: 1.382 | AH35: M3 | AI35: X | AJ35: 4 | AK35: V4 | AL35: 20240911 | AM35: D898-900005545-10128748
