Workbook

Sheet Base Cedis D865
N1: VENTA | Q1: COSTO
A2: CONCAT1 | B2: CONCAT2 | C2: No. SF | D2: Nombre SF | E2: Cedis | F2: Destino | G2: Condicion de Expedicion | H2: Nombre Destino | I2: No. de material | J2: Nombre de material | K2: PV | L2: Inicio de vigencia | M2: Fin de vigencia | N2: Importe MP | O2: Importe Flete | P2: UM Venta | Q2: Importe Costo | R2: UM Costo | S2: Validacion 1 | T2: Validacion 2
A3: =CONCATENATE(C3,E3,F3,I3) | B3: =CONCATENATE(C3,E3,I3) | C3: 900000540 | D3: =IFERROR(VLOOKUP(C3,TRAOPE!$G:$H,2,0),"") | E3: D865 | F3: 65014664 | G3: =IFERROR(VLOOKUP(A3,Flete!$A:$E,5,0),"") | H3: =IFERROR(VLOOKUP(F3,TRAOPE!$AA:$AB,2,0),"") | I3: 10000829 | J3: =IFERROR(VLOOKUP(I3,Materiales!$A:$H,8,0),"") | K3: =IFERROR(VLOOKUP(I3,Materiales!$A:$G,7,0),"") | L3: 20190426 | M3: 20250127 | N3: 51.84 | O3: =IFERROR(VLOOKUP(A3,Flete!$A:$J,10,0),"") | P3: M3 | Q3: =IFERROR(IFERROR(VLOOKUP(A3,TRAOPE!$A:$U,21,0),VLOOKUP(B3,TRAOPE!$A:$U,21,0)),"") | R3: =IFERROR(IFERROR(VLOOKUP(A3,TRAOPE!$A:$W,23,0),VLOOKUP(B3,TRAOPE!$A:$W,23,0)),"") | S3: =IF(AND(P3="TN",R3="TN"),N3+N(O3),IF(G3&""="1",N(K3)*N3,(N3+N(O3))*N(K3))) | T3: =IF(Q3="","",Q3-S3)
A4: =CONCATENATE(C4,E4,F4,I4) | B4: =CONCATENATE(C4,E4,I4) | C4: 900003877 | D4: =IFERROR(VLOOKUP(C4,TRAOPE!$G:$H,2,0),"") | E4: D865 | F4: 65944468 | G4: =IFERROR(VLOOKUP(A4,Flete!$A:$E,5,0),"") | H4: =IFERROR(VLOOKUP(F4,TRAOPE!$AA:$AB,2,0),"") | I4: 10000360 | J4: =IFERROR(VLOOKUP(I4,Materiales!$A:$H,8,0),"") | K4: =IFERROR(VLOOKUP(I4,Materiales!$A:$G,7,0),"") | L4: 20190426 | M4: 20250127 | N4: 153.7 | O4: =IFERROR(VLOOKUP(A4,Flete!$A:$J,10,0),"") | P4: M3 | Q4: =IFERROR(IFERROR(VLOOKUP(A4,TRAOPE!$A:$U,21,0),VLOOKUP(B4,TRAOPE!$A:$U,21,0)),"") | R4: =IFERROR(IFERROR(VLOOKUP(A4,TRAOPE!$A:$W,23,0),VLOOKUP(B4,TRAOPE!$A:$W,23,0)),"") | S4: =IF(AND(P4="TN",R4="TN"),N4+N(O4),IF(G4&""="1",N(K4)*N4,(N4+N(O4))*N(K4))) | T4: =IF(Q4="","",Q4-S4)
A5: =CONCATENATE(C5,E5,F5,I5) | B5: =CONCATENATE(C5,E5,I5) | C5: 900003877 | D5: =IFERROR(VLOOKUP(C5,TRAOPE!$G:$H,2,0),"") | E5: D865 | F5: 65944468 | G5: =IFERROR(VLOOKUP(A5,Flete!$A:$E,5,0),"") | H5: =IFERROR(VLOOKUP(F5,TRAOPE!$AA:$AB,2,0),"") | I5: 10000632 | J5: =IFERROR(VLOOKUP(I5,Materiales!$A:$H,8,0),"") | K5: =IFERROR(VLOOKUP(I5,Materiales!$A:$G,7,0),"") | L5: 20190426 | M5: 20250127 | N5: 163 | O5: =IFERROR(VLOOKUP(A5,Flete!$A:$J,10,0),"") | P5: M3 | Q5: =IFERROR(IFERROR(VLOOKUP(A5,TRAOPE!$A:$U,21,0),VLOOKUP(B5,TRAOPE!$A:$U,21,0)),"") | R5: =IFERROR(IFERROR(VLOOKUP(A5,TRAOPE!$A:$W,23,0),VLOOKUP(B5,TRAOPE!$A:$W,23,0)),"") | S5: =IF(AND(P5="TN",R5="TN"),N5+N(O5),IF(G5&""="1",N(K5)*N5,(N5+N(O5))*N(K5))) | T5: =IF(Q5="","",Q5-S5)
A6: =CONCATENATE(C6,E6,F6,I6) | B6: =CONCATENATE(C6,E6,I6) | C6: 900003877 | D6: =IFERROR(VLOOKUP(C6,TRAOPE!$G:$H,2,0),"") | E6: D865 | F6: 65944468 | G6: =IFERROR(VLOOKUP(A6,Flete!$A:$E,5,0),"") | H6: =IFERROR(VLOOKUP(F6,TRAOPE!$AA:$AB,2,0),"") | I6: 10000735 | J6: =IFERROR(VLOOKUP(I6,Materiales!$A:$H,8,0),"") | K6: =IFERROR(VLOOKUP(I6,Materiales!$A:$G,7,0),"") | L6: 20190426 | M6: 20250127 | N6: 148.35 | O6: =IFERROR(VLOOKUP(A6,Flete!$A:$J,10,0),"") | P6: M3 | Q6: =IFERROR(IFERROR(VLOOKUP(A6,TRAOPE!$A:$U,21,0),VLOOKUP(B6,TRAOPE!$A:$U,21,0)),"") | R6: =IFERROR(IFERROR(VLOOKUP(A6,TRAOPE!$A:$W,23,0),VLOOKUP(B6,TRAOPE!$A:$W,23,0)),"") | S6: =IF(AND(P6="TN",R6="TN"),N6+N(O6),IF(G6&""="1",N(K6)*N6,(N6+N(O6))*N(K6))) | T6: =IF(Q6="","",Q6-S6)
A7: =CONCATENATE(C7,E7,F7,I7) | B7: =CONCATENATE(C7,E7,I7) | C7: 900003877 | D7: =IFERROR(VLOOKUP(C7,TRAOPE!$G:$H,2,0),"") | E7: D865 | F7: 65944468 | G7: =IFERROR(VLOOKUP(A7,Flete!$A:$E,5,0),"") | H7: =IFERROR(VLOOKUP(F7,TRAOPE!$AA:$AB,2,0),"") | I7: 10047573 | J7: =IFERROR(VLOOKUP(I7,Materiales!$A:$H,8,0),"") | K7: =IFERROR(VLOOKUP(I7,Materiales!$A:$G,7,0),"") | L7: 20190426 | M7: 20250127 | N7: 81 | O7: =IFERROR(VLOOKUP(A7,Flete!$A:$J,10,0),"") | P7: M3 | Q7: =IFERROR(IFERROR(VLOOKUP(A7,TRAOPE!$A:$U,21,0),VLOOKUP(B7,TRAOPE!$A:$U,21,0)),"") | R7: =IFERROR(IFERROR(VLOOKUP(A7,TRAOPE!$A:$W,23,0),VLOOKUP(B7,TRAOPE!$A:$W,23,0)),"") | S7: =IF(AND(P7="TN",R7="TN"),N7+N(O7),IF(G7&""="1",N(K7)*N7,(N7+N(O7))*N(K7))) | T7: =IF(Q7="","",Q7-S7)
A8: =CONCATENATE(C8,E8,F8,I8) | B8: =CONCATENATE(C8,E8,I8) | C8: 900003877 | D8: =IFERROR(VLOOKUP(C8,TRAOPE!$G:$H,2,0),"") | E8: D865 | F8: 66542531 | G8: =IFERROR(VLOOKUP(A8,Flete!$A:$E,5,0),"") | H8: =IFERROR(VLOOKUP(F8,TRAOPE!$AA:$AB,2,0),"") | I8: 10000829 | J8: =IFERROR(VLOOKUP(I8,Materiales!$A:$H,8,0),"") | K8: =IFERROR(VLOOKUP(I8,Materiales!$A:$G,7,0),"") | L8: 20190426 | M8: 20250127 | N8: 49 | O8: =IFERROR(VLOOKUP(A8,Flete!$A:$J,10,0),"") | P8: M3 | Q8: =IFERROR(IFERROR(VLOOKUP(A8,TRAOPE!$A:$U,21,0),VLOOKUP(B8,TRAOPE!$A:$U,21,0)),"") | R8: =IFERROR(IFERROR(VLOOKUP(A8,TRAOPE!$A:$W,23,0),VLOOKUP(B8,TRAOPE!$A:$W,23,0)),"") | S8: =IF(AND(P8="TN",R8="TN"),N8+N(O8),IF(G8&""="1",N(K8)*N8,(N8+N(O8))*N(K8))) | T8: =IF(Q8="","",Q8-S8)
A9: =CONCATENATE(C9,E9,F9,I9) | B9: =CONCATENATE(C9,E9,I9) | C9: 900003877 | D9: =IFERROR(VLOOKUP(C9,TRAOPE!$G:$H,2,0),"") | E9: D865 | F9: 66566504 | G9: =IFERROR(VLOOKUP(A9,Flete!$A:$E,5,0),"") | H9: =IFERROR(VLOOKUP(F9,TRAOPE!$AA:$AB,2,0),"") | I9: 10000632 | J9: =IFERROR(VLOOKUP(I9,Materiales!$A:$H,8,0),"") | K9: =IFERROR(VLOOKUP(I9,Materiales!$A:$G,7,0),"") | L9: 20190426 | M9: 20250127 | N9: 147 | O9: =IFERROR(VLOOKUP(A9,Flete!$A:$J,10,0),"") | P9: M3 | Q9: =IFERROR(IFERROR(VLOOKUP(A9,TRAOPE!$A:$U,21,0),VLOOKUP(B9,TRAOPE!$A:$U,21,0)),"") | R9: =IFERROR(IFERROR(VLOOKUP(A9,TRAOPE!$A:$W,23,0),VLOOKUP(B9,TRAOPE!$A:$W,23,0)),"") | S9: =IF(AND(P9="TN",R9="TN"),N9+N(O9),IF(G9&""="1",N(K9)*N9,(N9+N(O9))*N(K9))) | T9: =IF(Q9="","",Q9-S9)
A10: =CONCATENATE(C10,E10,F10,I10) | B10: =CONCATENATE(C10,E10,I10) | C10: 900003877 | D10: =IFERROR(VLOOKUP(C10,TRAOPE!$G:$H,2,0),"") | E10: D865 | F10: 66604125 | G10: =IFERROR(VLOOKUP(A10,Flete!$A:$E,5,0),"") | H10: =IFERROR(VLOOKUP(F10,TRAOPE!$AA:$AB,2,0),"") | I10: 10000829 | J10: =IFERROR(VLOOKUP(I10,Materiales!$A:$H,8,0),"") | K10: =IFERROR(VLOOKUP(I10,Materiales!$A:$G,7,0),"") | L10: 20190426 | M10: 20250127 | N10: 49 | O10: =IFERROR(VLOOKUP(A10,Flete!$A:$J,10,0),"") | P10: M3 | Q10: =IFERROR(IFERROR(VLOOKUP(A10,TRAOPE!$A:$U,21,0),VLOOKUP(B10,TRAOPE!$A:$U,21,0)),"") | R10: =IFERROR(IFERROR(VLOOKUP(A10,TRAOPE!$A:$W,23,0),VLOOKUP(B10,TRAOPE!$A:$W,23,0)),"") | S10: =IF(AND(P10="TN",R10="TN"),N10+N(O10),IF(G10&""="1",N(K10)*N10,(N10+N(O10))*N(K10))) | T10: =IF(Q10="","",Q10-S10)
A11: =CONCATENATE(C11,E11,F11,I11) | B11: =CONCATENATE(C11,E11,I11) | C11: 900003877 | D11: =IFERROR(VLOOKUP(C11,TRAOPE!$G:$H,2,0),"") | E11: D865 | F11: 67098138 | G11: =IFERROR(VLOOKUP(A11,Flete!$A:$E,5,0),"") | H11: =IFERROR(VLOOKUP(F11,TRAOPE!$AA:$AB,2,0),"") | I11: 10000735 | J11: =IFERROR(VLOOKUP(I11,Materiales!$A:$H,8,0),"") | K11: =IFERROR(VLOOKUP(I11,Materiales!$A:$G,7,0),"") | L11: 20190426 | M11: 20250127 | N11: 350 | O11: =IFERROR(VLOOKUP(A11,Flete!$A:$J,10,0),"") | P11: M3 | Q11: =IFERROR(IFERROR(VLOOKUP(A11,TRAOPE!$A:$U,21,0),VLOOKUP(B11,TRAOPE!$A:$U,21,0)),"") | R11: =IFERROR(IFERROR(VLOOKUP(A11,TRAOPE!$A:$W,23,0),VLOOKUP(B11,TRAOPE!$A:$W,23,0)),"") | S11: =IF(AND(P11="TN",R11="TN"),N11+N(O11),IF(G11&""="1",N(K11)*N11,(N11+N(O11))*N(K11))) | T11: =IF(Q11="","",Q11-S11)
A12: =CONCATENATE(C12,E12,F12,I12) | B12: =CONCATENATE(C12,E12,I12) | C12: 900003877 | D12: =IFERROR(VLOOKUP(C12,TRAOPE!$G:$H,2,0),"") | E12: D865 | F12: 67098138 | G12: =IFERROR(VLOOKUP(A12,Flete!$A:$E,5,0),"") | H12: =IFERROR(VLOOKUP(F12,TRAOPE!$AA:$AB,2,0),"") | I12: 10047573 | J12: =IFERROR(VLOOKUP(I12,Materiales!$A:$H,8,0),"") | K12: =IFERROR(VLOOKUP(I12,Materiales!$A:$G,7,0),"") | L12: 20190426 | M12: 20250127 | N12: 100 | O12: =IFERROR(VLOOKUP(A12,Flete!$A:$J,10,0),"") | P12: M3 | Q12: =IFERROR(IFERROR(VLOOKUP(A12,TRAOPE!$A:$U,21,0),VLOOKUP(B12,TRAOPE!$A:$U,21,0)),"") | R12: =IFERROR(IFERROR(VLOOKUP(A12,TRAOPE!$A:$W,23,0),VLOOKUP(B12,TRAOPE!$A:$W,23,0)),"") | S12: =IF(AND(P12="TN",R12="TN"),N12+N(O12),IF(G12&""="1",N(K12)*N12,(N12+N(O12))*N(K12))) | T12: =IF(Q12="","",Q12-S12)
A13: =CONCATENATE(C13,E13,F13,I13) | B13: =CONCATENATE(C13,E13,I13) | C13: 900003877 | D13: =IFERROR(VLOOKUP(C13,TRAOPE!$G:$H,2,0),"") | E13: D865 | F13: 67159573 | G13: =IFERROR(VLOOKUP(A13,Flete!$A:$E,5,0),"") | H13: =IFERROR(VLOOKUP(F13,TRAOPE!$AA:$AB,2,0),"") | I13: 10000632 | J13: =IFERROR(VLOOKUP(I13,Materiales!$A:$H,8,0),"") | K13: =IFERROR(VLOOKUP(I13,Materiales!$A:$G,7,0),"") | L13: 20190426 | M13: 20250127 | N13: 291 | O13: =IFERROR(VLOOKUP(A13,Flete!$A:$J,10,0),"") | P13: M3 | Q13: =IFERROR(IFERROR(VLOOKUP(A13,TRAOPE!$A:$U,21,0),VLOOKUP(B13,TRAOPE!$A:$U,21,0)),"") | R13: =IFERROR(IFERROR(VLOOKUP(A13,TRAOPE!$A:$W,23,0),VLOOKUP(B13,TRAOPE!$A:$W,23,0)),"") | S13: =IF(AND(P13="TN",R13="TN"),N13+N(O13),IF(G13&""="1",N(K13)*N13,(N13+N(O13))*N(K13))) | T13: =IF(Q13="","",Q13-S13)
A14: =CONCATENATE(C14,E14,F14,I14) | B14: =CONCATENATE(C14,E14,I14) | C14: 900003877 | D14: =IFERROR(VLOOKUP(C14,TRAOPE!$G:$H,2,0),"") | E14: D865 | F14: 67159573 | G14: =IFERROR(VLOOKUP(A14,Flete!$A:$E,5,0),"") | H14: =IFERROR(VLOOKUP(F14,TRAOPE!$AA:$AB,2,0),"") | I14: 10000735 | J14: =IFERROR(VLOOKUP(I14,Materiales!$A:$H,8,0),"") | K14: =IFERROR(VLOOKUP(I14,Materiales!$A:$G,7,0),"") | L14: 20190426 | M14: 20250127 | N14: 341 | O14: =IFERROR(VLOOKUP(A14,Flete!$A:$J,10,0),"") | P14: M3 | Q14: =IFERROR(IFERROR(VLOOKUP(A14,TRAOPE!$A:$U,21,0),VLOOKUP(B14,TRAOPE!$A:$U,21,0)),"") | R14: =IFERROR(IFERROR(VLOOKUP(A14,TRAOPE!$A:$W,23,0),VLOOKUP(B14,TRAOPE!$A:$W,23,0)),"") | S14: =IF(AND(P14="TN",R14="TN"),N14+N(O14),IF(G14&""="1",N(K14)*N14,(N14+N(O14))*N(K14))) | T14: =IF(Q14="","",Q14-S14)
... A81: =CONCATENATE(C81,E81,F81,I81) | B81: =CONCATENATE(C81,E81,I81) | C81: 900008869 | D81: =IFERROR(VLOOKUP(C81,TRAOPE!$G:$H,2,0),"") | E81: D865 | F81: 67283503 | G81: =IFERROR(VLOOKUP(A81,Flete!$A:$E,5,0),"") | H81: =IFERROR(VLOOKUP(F81,TRAOPE!$AA:$AB,2,0),"") | I81: 10000623 | J81: =IFERROR(VLOOKUP(I81,Materiales!$A:$H,8,0),"") | K81: =IFERROR(VLOOKUP(I81,Materiales!$A:$G,7,0),"") | L81: 20240813 | M81: 20241108 | N81: 171 | O81: =IFERROR(VLOOKUP(A81,Flete!$A:$J,10,0),"") | P81: TN | Q81: =IFERROR(IFERROR(VLOOKUP(A81,TRAOPE!$A:$U,21,0),VLOOKUP(B81,TRAOPE!$A:$U,21,0)),"") | R81: =IFERROR(IFERROR(VLOOKUP(A81,TRAOPE!$A:$W,23,0),VLOOKUP(B81,TRAOPE!$A:$W,23,0)),"") | S81: =IF(AND(P81="TN",R81="TN"),N81+N(O81),IF(G81&""="1",N(K81)*N81,(N81+N(O81))*N(K81))) | T81: =IF(Q81="","",Q81-S81)

Sheet MP
A1: No. SF | B1: Cedis | C1: Destino | D1: No. Material | E1: Nombre Material | F1: Importe MP | G1: Moneda | H1: Cantidad | I1: UM | J1: C | K1: Inicio Vigencia | L1: Fin Vigencia
A2: 900000540 | B2: D865 | C2: 65014664 | D2: 10000829 | F2: 51.84 | I2: M3 | K2: 20190426 | L2: 20250127
A3: 900003877 | B3: D865 | C3: 65944468 | D3: 10000360 | F3: 153.7 | I3: M3 | K3: 20190426 | L3: 20250127
A4: 900003877 | B4: D865 | C4: 65944468 | D4: 10000632 | F4: 163 | I4: M3 | K4: 20190426 | L4: 20250127
A5: 900003877 | B5: D865 | C5: 65944468 | D5: 10000735 | F5: 148.35 | I5: M3 | K5: 20190426 | L5: 20250127
A6: 900003877 | B6: D865 | C6: 65944468 | D6: 10047573 | F6: 81 | I6: M3 | K6: 20190426 | L6: 20250127
A7: 900003877 | B7: D865 | C7: 66542531 | D7: 10000829 | F7: 49 | I7: M3 | K7: 20190426 | L7: 20250127
A8: 900003877 | B8: D865 | C8: 66566504 | D8: 10000632 | F8: 147 | I8: M3 | K8: 20190426 | L8: 20250127
A9: 900003877 | B9: D865 | C9: 66604125 | D9: 10000829 | F9: 49 | I9: M3 | K9: 20190426 | L9: 20250127
A10: 900003877 | B10: D865 | C10: 67098138 | D10: 10000735 | F10: 350 | I10: M3 | K10: 20190426 | L10: 20250127
A11: 900003877 | B11: D865 | C11: 67098138 | D11: 10047573 | F11: 100 | I11: M3 | K11: 20190426 | L11: 20250127
A12: 900003877 | B12: D865 | C12: 67159573 | D12: 10000632 | F12: 291 | I12: M3 | K12: 20190426 | L12: 20250127
A13: 900003877 | B13: D865 | C13: 67159573 | D13: 10000735 | F13: 341 | I13: M3 | K13: 20190426 | L13: 20250127
... A80: 900008869 | B80: D865 | C80: 67283503 | D80: 10000623 | F80: 171 | I80: TN | K80: 20240813 | L80: 20241108

Sheet Flete
A1: Concat1 | B1: No. SF | C1: Cedis | D1: Destino | E1: Cond. Exp. | F1: Material | H1: Nombre Material | J1: Importe Flete | K1: Moneda | L1: Cantidad | M1: UM | N1: C | P1: Inicio Vigencia | Q1: Fin Vigencia
A2: 900000540D8656501466410000829 | B2: 900000540 | C2: D865 | D2: 65014664 | E2: 1 | F2: 10000829 | J2: 211.09 | M2: M3 | P2: 20190426 | Q2: 20250127
A3: 900003877D8656594446810000360 | B3: 900003877 | C3: D865 | D3: 65944468 | E3: 1 | F3: 10000360 | J3: 70 | M3: M3 | P3: 20190426 | Q3: 20250127
A4: 900003877D8656594446810000632 | B4: 900003877 | C4: D865 | D4: 65944468 | E4: 1 | F4: 10000632 | J4: 70 | M4: M3 | P4: 20190426 | Q4: 20250127
A5: 900003877D8656594446810047573 | B5: 900003877 | C5: D865 | D5: 65944468 | E5: 1 | F5: 10047573 | J5: 70 | M5: M3 | P5: 20190426 | Q5: 20250127
A6: 900004446D8656594446810000829 | B6: 900004446 | C6: D865 | D6: 65944468 | E6: 1 | F6: 10000829 | J6: 115 | M6: M3 | P6: 20190426 | Q6: 20250127
A7: 900004447D8656501466410000160 | B7: 900004447 | C7: D865 | D7: 65014664 | E7: 1 | F7: 10000160 | J7: 237.18 | M7: M3 | P7: 20190426 | Q7: 20250127
A8: 900004447D8656501466410000829 | B8: 900004447 | C8: D865 | D8: 65014664 | E8: 1 | F8: 10000829 | J8: 237.18 | M8: M3 | P8: 20190426 | Q8: 20250127
A9: 900005785D8656656917410000394 | B9: 900005785 | C9: D865 | D9: 66569174 | E9: 4 | F9: 10000394 | J9: 119 | M9: M3 | P9: 20190426 | Q9: 20250127
A10: 900005792D8656656917410000284 | B10: 900005792 | C10: D865 | D10: 66569174 | E10: 4 | F10: 10000284 | J10: 44.5 | M10: M3 | P10: 20190426 | Q10: 20250127
A11: 900006123D865DE1210000651 | B11: 900006123 | C11: D865 | D11: DE12 | E11: 1 | F11: 10000651 | J11: 63.6 | M11: TN | P11: 20190517 | Q11: 20240710
A12: 900006123D865DE1310000651 | B12: 900006123 | C12: D865 | D12: DE13 | E12: 1 | F12: 10000651 | J12: 71.08 | M12: TN | P12: 20190517 | Q12: 20240710
A13: 900006123D865DE7310000651 | B13: 900006123 | C13: D865 | D13: DE73 | E13: 1 | F13: 10000651 | J13: 118.41 | M13: TN | P13: 20190517 | Q13: 20240710
... A23: 900008869D8656728350310000623 | B23: 900008869 | C23: D865 | D23: 67283503 | E23: 4 | F23: 10000623 | J23: 300 | M23: TN | P23: 20240921 | Q23: 99991231

Sheet Materiales
A1: Material | B1: TpMt | C1: Denom | D1: UMA | E1: Contador | F1: UMB | G1: PV | H1: Nombre Material
A2: 10000001 | B2: ZFER | C2: 1000 | D2: M3 | E2: 1000 | F2: TN | G2: 1262 | H2: GRAVA ANDESITA 10 MM (3/8")
A3: 10000003 | B3: ZFER | C3: 1000 | D3: M3 | E3: 1000 | F3: TN | G3: 1443 | H3: GRAVA CALIZA 10 MM (3/8")
A4: 10000006 | B4: ZFER | C4: 1000 | D4: M3 | E4: 1000 | F4: TN | G4: 1490 | H4: GRAVA RIO 10 MM (3/8")
A5: 10000007 | B5: ZFER | C5: 1000 | D5: M3 | E5: 1000 | F5: TN | G5: 1488 | H5: GRAVA BASALTO 13 MM (1/2")
A6: 10000008 | B6: ZFER | C6: 1000 | D6: M3 | E6: 1000 | F6: TN | G6: 1358 | H6: GRAVA CALIZA 13 MM (1/2")
A7: 10000011 | B7: ZFER | C7: 1000 | D7: M3 | E7: 1000 | F7: TN | G7: 1323 | H7: GRAVA ANDESITA 20 MM (3/4")
A8: 10000013 | B8: ZFER | C8: 1000 | D8: M3 | E8: 1000 | F8: TN | G8: 1514 | H8: GRAVA BASALTO 20 MM (3/4")
A9: 10000014 | B9: ZFER | C9: 1000 | D9: M3 | E9: 1000 | F9: TN | G9: 1400 | H9: GRAVA CALIZA 20 MM (3/4")
A10: 10000015 | B10: ZFER | C10: 1000 | D10: M3 | E10: 1000 | F10: TN | G10: 1410 | H10: GRAVA GRANITO 20 MM (3/4")
A11: 10000017 | B11: ZFER | C11: 1000 | D11: M3 | E11: 1000 | F11: TN | G11: 1475 | H11: GRAVA RIOLITA 20 MM (3/4")
A12: 10000019 | B12: ZFER | C12: 1000 | D12: M3 | E12: 1000 | F12: TN | G12: 1515 | H12: GRAVA RIO 20 MM (3/4")
A13: 10000020 | B13: ZFER | C13: 1000 | D13: M3 | E13: 1 | F13: TN | G13: 1 | H13: GRAVA MAQUILA 40MM (1 1/2")
... A2291: 10268770 | B2291: ZFE3 | C2291: 1000 | D2291: M3 | E2291: 1000 | F2291: TN | G2291: 1240 | H2291: MP GRAVA TRIT CALIZA 40MM 1 1/2" - ESP
A2292: 10268901 | B2292: ZFE3 | C2292: 1000 | D2292: M3 | E2292: 1000 | G2292: 1560 | H2292: MP GRAVA ANDESITA GRIS 3/4" - CAPADA
A2293: 10267983 | C2293: 1000 | G2293: 1800 | H2293: ESCORIA ALTO HORNO 3/4
A2294: 10268996 | C2294: 1000 | G2294: 1329 | H2294: GRAVA TRITURADA CALIZA 40 MM - 11/2"
A2295: 10269072 | C2295: 1000 | G2295: 1700 | H2295: BASE HIDRÁULICA SCREEN
A2296: 10269225 | B2296: ZFE3 | C2296: 1000 | D2296: M3 | E2296: 1000 | G2296: 1289 | H2296: MP ARENA CALIZA LAVADA MALLA 4 - DELTA I
A2297: 10269245 | B2297: ZFE3 | C2297: 1000 | D2297: M3 | E2297: 1000 | G2297: 1410 | H2297: MP GRAVA TRITURADA CALIZA 3/8 - 10MM
A2298: 10269246 | B2298: ZFE3 | C2298: 1000 | D2298: M3 | E2298: 1000 | G2298: 1400 | H2298: MP GRAVA TRITURADA CALIZA 1 1/2 - 40MM
A2299: 10269247 | B2299: ZFE3 | C2299: 1000 | D2299: M3 | E2299: 1000 | G2299: 1560 | H2299: MP ARENA TRIT CALIZA M-4
A2300: 10270431 | B2300: ZFE3 | C2300: 1000 | D2300: M3 | E2300: 1000 | G2300: 1423 | H2300: MP GRAVA RIOLITA 13 MM - 1/2"
A2301: 10270898 | B2301: ZFE3 | C2301: 1000 | D2301: M3 | E2301: 1000 | G2301: 1551 | H2301: MP BASE H. TRIT. BASALTO 1 1/2" A FINOS
A2302: 10270911 | B2302: ZFE3 | C2302: 1000 | D2302: M3 | E2302: 1000 | G2302: 1360 | H2302: MP GRAVA TRIT. BASALTO 40 MM - 1 1/2"
A2303: 10270912 | B2303: ZFE3 | C2303: 1000 | D2303: M3 | E2303: 1000 | G2303: 1589 | H2303: MP ARENA TRIT. BASALTO MALLA 4
A2304: 10270913 | B2304: ZFE3 | C2304: 1000 | D2304: M3 | E2304: 1000 | G2304: 1395 | H2304: MP GRAVA TRIT. BASALTO 20 MM - 3/4
A2305: 10270914 | B2305: ZFE3 | C2305: 1000 | D2305: M3 | E2305: 1000 | G2305: 1623 | H2305: MP ARENA ANDESITA BC
A2306: 10270824 | B2306: M3 | C2306: 1000 | D2306: M3 | E2306: 10007640 | G2306: 1325 | H2306: MP ARENA TRITURADA CALIZA MALLA 5
A2307: 10270825 | B2307: M3 | C2307: 1000 | D2307: M3 | E2307: 10000003 | G2307: 1242 | H2307: MP GRAVA TRITURADA CALIZA 10MM (3/8”)
... A2319: 10272527 | B2319: ZFE3 | C2319: 1000 | D2319: M3 | E2319: 1000 | G2319: 1620 | H2319: CNC - NO CLASIFICADO
A2320: 10000332 | C2320: 1000 | D2320: M3 | E2320: 1000 | G2320: 800 | H2320: Grava Triturada Pomez - Jal 20 mm - 3/4"
A2321: 10273001 | B2321: ZFE3 | C2321: 1000 | D2321: M3 | E2321: 1000 | G2321: 1688 | H2321: MP ARENA TRIT. BASALTO MALLA 4
A2322: 10273002 | B2322: ZFE3 | C2322: 1000 | D2322: M3 | E2322: 1000 | G2322: 1466 | H2322: MP GRAVA TRIT. BASALTO 20 MM - 3/4"
A2323: 10273351 | B2323: ZFE3 | C2323: 1000 | D2323: M3 | E2323: 1000 | G2323: 1612 | H2323: MP ARENA TRIT. CALIZA MALLA 4
A2324: 10273352 | B2324: ZFE3 | C2324: 1000 | D2324: M3 | E2324: 1000 | G2324: 1492 | H2324: MP GRAVA TRIT. CALIZA 20 MM - 3/4"
A2325: 10271724 | B2325: ZFE3 | C2325: 1000 | D2325: M3 | E2325: 1000 | G2325: 1900 | H2325: MP RESIDUO DE CONCRETO
A2326: 10000677 | C2326: 1000 | D2326: M3 | G2326: 1164 | H2326: Grava Triturada Caliza 20 mm - 3/4"
A2327: 10274190 | B2327: ZFE3 | C2327: 1000 | D2327: M3 | E2327: 1000 | G2327: 1800 | H2327: MP BASE HIDRAULICA ANDESITA 70-30
A2328: 10274601 | B2328: ZFE3 | C2328: 1000 | D2328: M3 | E2328: 1000 | G2328: 1447 | H2328: MP ARENA BASALTO N° 4
...

Sheet TRAOPE
A1: Concat1 | B1: Contrato_Pos | C1: Doc. Compras | D1: Pos | E1: Org.compras | F1: Grp-Compr. | G1: Ship From | H1: Nombre SF | I1: Proveedor | J1: Nombre Prov | K1: Cond. Pago | L1: Descr. Cond Pago | M1: Material | N1: Descripción | O1: Centro | P1: Descripción Centro | Q1: In.perído validez | R1: Fin perído validez | S1: Válido de | T1: Validez a | U1: Precio neto pedido | V1: Moneda | W1: UM Precio Pedido | X1: Importe Condición | Y1: Moneda KONP | Z1: UM Ctd Base | AA1: Destino | AB1: Nombre Destino | AC1: Cuenta de mayor | AD1: Centro de costo | AE1: Cond. Exp. | AF1: Descr. Cond. Exp. | AG1: Peso Vol. | AH1: UMB | AI1: Ind. Oblig. Conf. Ped. | AJ1: Ctrl-Conf. | AK1: IVA | AL1: Modif_Date | AM1: Ruta
A2: 900009140D8656737683010000623 | B2: 4600071388-40 | C2: 4600071388 | D2: 40 | E2: MXPO | F2: MXL | G2: 900009140 | H2: SF TP-ED CONCRETOS Y PAVIMENTOS | I2: 5089601 | J2: CONCRETOS Y PAVIMENTOS EXTERIORES S | K2: N90 | L2: (AP) NAFIN 90 Dias | M2: 10000623 | N2: Grava Triturada Caliza 10 mm - 3/8" | O2: D865 | P2: MX-CED. MORELOS | Q2: 20250627 | R2: 20301231 | S2: 20260727 | T2: 20301231 | U2: 627 | V2: MXN | W2: TN | X2: 440 | Y2: MXN | Z2: TN | AA2: 67376830 | AB2: HOLCIM XOCHITEPEC | AC2: 56103637 | AD2: 6622551540 | AE2: 4 | AF2: ENTREGA DIRECTA | AG2: 1 | AH2: TO | AI2: X | AJ2: 4 | AK2: V4 | AL2: 20260731 | AM2: D865-900009140-67376830-10000623-4
A3: 900003877D86510047573 | B3: 4600032991-10 | C3: 4600032991 | D3: 10 | E3: MXPO | F3: MXL | G3: 900003877 | H3: TP-MAT Y FORRAJES | I3: 5054376 | J3: DISTRIBUIDORA DE MATERIALES Y FORRA | K3: N15 | L3: (AP) NAFIN 15 Dias | M3: 10047573 | N3: Arena Triturada Caliza Malla 4 | O3: D865 | P3: MX-CED. MORELOS | Q3: 20160201 | R3: 20281231 | S3: 20230825 | T3: 20281231 | U3: 90 | V3: MXN | W3: M3 | X3: 0 | Y3: MXN | Z3: M3 | AC3: 56103638 | AD3: 6622551540 | AE3: 1 | AF3: ENTREGADO | AG3: 1.607 | AH3: M3 | AI3: X | AJ3: 4 | AK3: V4 | AL3: 20230920 | AM3: D865-900003877-10047573
A4: 900009140D8656724072910000623 | B4: 4600071388-20 | C4: 4600071388 | D4: 20 | E4: MXPO | F4: MXL | G4: 900009140 | H4: SF TP-ED CONCRETOS Y PAVIMENTOS | I4: 5089601 | J4: CONCRETOS Y PAVIMENTOS EXTERIORES S | K4: N90 | L4: (AP) NAFIN 90 Dias | M4: 10000623 | N4: Grava Triturada Caliza 10 mm - 3/8" | O4: D865 | P4: MX-CED. MORELOS | Q4: 20250627 | R4: 20301231 | S4: 20250627 | T4: 20301231 | U4: 475 | V4: MXN | W4: TN | X4: 360 | Y4: MXN | Z4: TN | AA4: 67240729 | AB4: COMOSA / SEPSA | AC4: 56103637 | AD4: 6622551540 | AE4: 4 | AF4: ENTREGA DIRECTA | AG4: 1 | AH4: TO | AI4: X | AJ4: 4 | AK4: V4 | AL4: 20250716 | AM4: D865-900009140-67240729-10000623-4
A5: 900004447D86510000829 | B5: 4600040010-10 | C5: 4600040010 | D5: 10 | E5: MXPO | F5: MXL | G5: 900004447 | H5: TP-CEKUR | I5: 5058788 | J5: INMOBILIARIA CEKUR S.A. DE C.V. | K5: Z06 | L5: (AP) 45 Dias | M5: 10000829 | N5: Arena Triturada Basalto Malla 5 | O5: D865 | P5: MX-CED. MORELOS | Q5: 20171010 | R5: 20241231 | S5: 20180209 | T5: 20241231 | U5: 50.68 | V5: MXN | W5: M3 | X5: 0 | Y5: MXN | Z5: M3 | AC5: 56103638 | AD5: 6622551540 | AE5: 2 | AF5: RECOGIDO | AG5: 1.43 | AH5: M3 | AI5: X | AJ5: 4 | AK5: V4 | AL5: 20230920 | AM5: D865-900004447-10000829
A6: 900003877D86510000829 | B6: 4600032991-60 | C6: 4600032991 | D6: 60 | E6: MXPO | F6: MXL | G6: 900003877 | H6: TP-MAT Y FORRAJES | I6: 5054376 | J6: DISTRIBUIDORA DE MATERIALES Y FORRA | K6: N15 | L6: (AP) NAFIN 15 Dias | M6: 10000829 | N6: Arena Triturada Basalto Malla 5 | O6: D865 | P6: MX-CED. MORELOS | Q6: 20160201 | R6: 20281231 | S6: 20190307 | T6: 20241231 | U6: 46.67 | V6: MXN | W6: M3 | X6: 0 | Y6: MXN | Z6: M3 | AC6: 56103638 | AD6: 6622551540 | AE6: 1 | AF6: ENTREGADO | AG6: 1.43 | AH6: M3 | AI6: X | AJ6: 4 | AK6: V4 | AL6: 20230920 | AM6: D865-900003877-10000829
A7: 900006766D86510000829 | B7: 4600053924-10 | C7: 4600053924 | D7: 10 | E7: MXPO | F7: MXL | G7: 900006766 | H7: SF TP-AGREGADOS DEL SUR | I7: 5078934 | J7: GARCIA CONCHA JANET | K7: Z09 | L7: (AP) 90 Dias | M7: 10000829 | N7: Arena Triturada Basalto Malla 5 | O7: D865 | P7: MX-CED. MORELOS | Q7: 20220516 | R7: 20271231 | S7: 20220513 | T7: 20271231 | U7: 65 | V7: MXN | W7: M3 | X7: 0 | Y7: MXN | Z7: M3 | AC7: 56103638 | AD7: 6622551540 | AE7: 1 | AF7: ENTREGADO | AG7: 1.43 | AH7: M3 | AI7: X | AJ7: 4 | AK7: V4 | AL7: 20230920 | AM7: D865-900006766-10000829
A8: 900005785D8656656917410000394 | B8: 4600042858-10 | C8: 4600042858 | D8: 10 | E8: MXPO | F8: MXL | G8: 900005785 | H8: SF TP-ED-ACAMILPA (SOTELO) | I8: 5058988 | J8: RAMIREZ CARIÑO MARIA DOLORES | K8: Z06 | L8: (AP) 45 Dias | M8: 10000394 | N8: Arena Triturada Andesita Malla 4 | O8: D865 | P8: MX-CED. MORELOS | Q8: 20180829 | R8: 20241231 | S8: 20180829 | T8: 20241231 | U8: 164.29 | V8: MXN | W8: M3 | X8: 119 | Y8: MXN | Z8: M3 | AA8: 66569174 | AB8: HOSPITAL GENERAL CUAUTLA (LAAJ) | AC8: 56103638 | AD8: 6622551540 | AE8: 4 | AF8: ENTREGA DIRECTA | AG8: 1.41 | AH8: M3 | AI8: X | AJ8: 4 | AK8: V4 | AL8: 20230920 | AM8: D865-900005785-66569174-10000394-4
A9: 900009140D8656724238510000623 | B9: 4600071388-30 | C9: 4600071388 | D9: 30 | E9: MXPO | F9: MXL | G9: 900009140 | H9: SF TP-ED CONCRETOS Y PAVIMENTOS | I9: 5089601 | J9: CONCRETOS Y PAVIMENTOS EXTERIORES S | K9: N90 | L9: (AP) NAFIN 90 Dias | M9: 10000623 | N9: Grava Triturada Caliza 10 mm - 3/8" | O9: D865 | P9: MX-CED. MORELOS | Q9: 20250627 | R9: 20301231 | S9: 20251029 | T9: 20301231 | U9: 400 | V9: MXN | W9: TN | X9: 310 | Y9: MXN | Z9: TN | AA9: 67242385 | AB9: COMOSA / CUERNAVACA | AC9: 56103637 | AD9: 6622551540 | AE9: 4 | AF9: ENTREGA DIRECTA | AG9: 1 | AH9: TO | AI9: X | AJ9: 4 | AK9: V4 | AL9: 20251204 | AM9: D865-900009140-67242385-10000623-4
A10: 900006255D86510047573 | B10: 4600055817-30 | C10: 4600055817 | D10: 30 | E10: MXPO | F10: MXL | G10: 900006255 | H10: SF TP-MAT Y FORRAJES YAUTEPEC | I10: 5054376 | J10: DISTRIBUIDORA DE MATERIALES Y FORRA | K10: N15 | L10: (AP) NAFIN 15 Dias | M10: 10047573 | N10: Arena Triturada Caliza Malla 4 | O10: D865 | P10: MX-CED. MORELOS | Q10: 20211122 | R10: 20281231 | S10: 20230825 | T10: 20281231 | U10: 90 | V10: MXN | W10: M3 | X10: 0 | Y10: MXN | Z10: M3 | AC10: 56103638 | AD10: 6622551540 | AE10: 1 | AF10: ENTREGADO | AG10: 1.607 | AH10: M3 | AI10: X | AJ10: 4 | AK10: V4 | AL10: 20230920 | AM10: D865-900006255-10047573
A11: 900004598D86510006150 | B11: 4600070492-20 | C11: 4600070492 | D11: 20 | E11: MXPO | F11: MXL | G11: 900004598 | H11: TP-GALEANA | I11: 5062433 | J11: CAMINOS Y PAVIMENTOS DEL | K11: Z06 | L11: (AP) 45 Dias | M11: 10006150 | N11: Grava Triturada Caliza 20 mm - 3/4" | O11: D865 | P11: MX-CED. MORELOS | Q11: 20241022 | R11: 20291231 | S11: 20241022 | T11: 20291231 | U11: 300 | V11: MXN | W11: M3 | X11: 0 | Y11: MXN | Z11: M3 | AC11: 56103637 | AD11: 6622551540 | AE11: 1 | AF11: ENTREGADO | AG11: 1.387 | AH11: M3 | AI11: X | AJ11: 4 | AK11: V4 | AL11: 20241104 | AM11: D865-900004598-10006150
A12: 900004598D86510047573 | B12: 4600070492-10 | C12: 4600070492 | D12: 10 | E12: MXPO | F12: MXL | G12: 900004598 | H12: TP-GALEANA | I12: 5062433 | J12: CAMINOS Y PAVIMENTOS DEL | K12: Z06 | L12: (AP) 45 Dias | M12: 10047573 | N12: Arena Triturada Caliza Malla 4 | O12: D865 | P12: MX-CED. MORELOS | Q12: 20241022 | R12: 20291231 | S12: 20241022 | T12: 20291231 | U12: 55 | V12: MXN | W12: M3 | X12: 0 | Y12: MXN | Z12: M3 | AC12: 56103638 | AD12: 6622551540 | AE12: 1 | AF12: ENTREGADO | AG12: 1.607 | AH12: M3 | AI12: X | AJ12: 4 | AK12: V4 | AL12: 20241104 | AM12: D865-900004598-10047573
A13: 900008869D8656724238510000623 | B13: 4600069828-30 | C13: 4600069828 | D13: 30 | E13: MXPO | F13: MXL | G13: 900008869 | H13: SF TP-ED CONTROL Y MANEJO OBRAS | I13: 5092110 | J13: CONTROL Y MANEJO DE OBRAS SA DE CV | K13: Z04 | L13: (AP) 30 Dias | M13: 10000623 | N13: Grava Triturada Caliza 10 mm - 3/8" | O13: D865 | P13: MX-CED. MORELOS | Q13: 20240701 | R13: 20291231 | S13: 20250219 | T13: 20301231 | U13: 445 | V13: MXN | W13: TN | X13: 310 | Y13: MXN | Z13: TN | AA13: 67242385 | AB13: COMOSA / CUERNAVACA | AC13: 56103637 | AD13: 6622551540 | AE13: 4 | AF13: ENTREGA DIRECTA | AG13: 1 | AH13: TO | AI13: X | AJ13: 4 | AK13: V4 | AL13: 20250224 | AM13: D865-900008869-67242385-10000623-4
A14: 900008869D8656728350310000623 | B14: 4600069828-40 | C14: 4600069828 | D14: 40 | E14: MXPO | F14: MXL | G14: 900008869 | H14: SF TP-ED CONTROL Y MANEJO OBRAS | I14: 5092110 | J14: CONTROL Y MANEJO DE OBRAS SA DE CV | K14: Z04 | L14: (AP) 30 Dias | M14: 10000623 | N14: Grava Triturada Caliza 10 mm - 3/8" | O14: D865 | P14: MX-CED. MORELOS | Q14: 20240701 | R14: 20291231 | S14: 20250219 | T14: 20301231 | U14: 470 | V14: MXN | W14: TN | X14: 310 | Y14: MXN | Z14: TN | AA14: 67283503 | AB14: COMOSA / CUAUTLA | AC14: 56103637 | AD14: 6622551540 | AE14: 4 | AF14: ENTREGA DIRECTA | AG14: 1 | AH14: TO | AI14: X | AJ14: 4 | AK14: V4 | AL14: 20250224 | AM14: D865-900008869-67283503-10000623-4
A15: 900008869D8656724238210000623 | B15: 4600069828-20 | C15: 4600069828 | D15: 20 | E15: MXPO | F15: MXL | G15: 900008869 | H15: SF TP-ED CONTROL Y MANEJO OBRAS | I15: 5092110 | J15: CONTROL Y MANEJO DE OBRAS SA DE CV | K15: Z04 | L15: (AP) 30 Dias | M15: 10000623 | N15: Grava Triturada Caliza 10 mm - 3/8" | O15: D865 | P15: MX-CED. MORELOS | Q15: 20240701 | R15: 20291231 | S15: 20250219 | T15: 20301231 | U15: 470 | V15: MXN | W15: TN | X15: 310 | Y15: MXN | Z15: TN | AA15: 67242382 | AB15: COMOSA / TEZOYUCA | AC15: 56103637 | AD15: 6622551540 | AE15: 4 | AF15: ENTREGA DIRECTA | AG15: 1 | AH15: TO | AI15: X | AJ15: 4 | AK15: V4 | AL15: 20250224 | AM15: D865-900008869-67242382-10000623-4
A16: 900008869D8656724072910000623 | B16: 4600069828-10 | C16: 4600069828 | D16: 10 | E16: MXPO | F16: MXL | G16: 900008869 | H16: SF TP-ED CONTROL Y MANEJO OBRAS | I16: 5092110 | J16: CONTROL Y MANEJO DE OBRAS SA DE CV | K16: Z04 | L16: (AP) 30 Dias | M16: 10000623 | N16: Grava Triturada Caliza 10 mm - 3/8" | O16: D865 | P16: MX-CED. MORELOS | Q16: 20240701 | R16: 20291231 | S16: 20250219 | T16: 20301231 | U16: 480 | V16: MXN | W16: TN | X16: 360 | Y16: MXN | Z16: TN | AA16: 67240729 | AB16: COMOSA / SEPSA | AC16: 56103637 | AD16: 6622551540 | AE16: 4 | AF16: ENTREGA DIRECTA | AG16: 1 | AH16: TO | AI16: X | AJ16: 4 | AK16: V4 | AL16: 20250224 | AM16: D865-900008869-67240729-10000623-4
A17: 900009140D8656728350310000623 | B17: 4600071388-10 | C17: 4600071388 | D17: 10 | E17: MXPO | F17: MXL | G17: 900009140 | H17: SF TP-ED CONCRETOS Y PAVIMENTOS | I17: 5089601 | J17: CONCRETOS Y PAVIMENTOS EXTERIORES S | K17: N90 | L17: (AP) NAFIN 90 Dias | M17: 10000623 | N17: Grava Triturada Caliza 10 mm - 3/8" | O17: D865 | P17: MX-CED. MORELOS | Q17: 20250627 | R17: 20301231 | S17: 20250708 | T17: 20301231 | U17: 460 | V17: MXN | W17: TN | X17: 310 | Y17: MXN | Z17: TN | AA17: 67283503 | AB17: COMOSA / CUAUTLA | AC17: 56103637 | AD17: 6622551540 | AE17: 4 | AF17: ENTREGA DIRECTA | AG17: 1 | AH17: TO | AI17: X | AJ17: 4 | AK17: V4 | AL17: 20250711 | AM17: D865-900009140-67283503-10000623-4
A18: 900007422D865EB3810000432 | B18: 4600057091-10 | C18: 4600057091 | D18: 10 | E18: MXPO | F18: MXL | G18: 900007422 | H18: SF TC-ED-TISCAREÑO | I18: 5071793 | J18: TISCAREÑO MALDONADO SAUL | K18: Z09 | L18: (AP) 90 Dias | M18: 10000432 | N18: Base H Triturada Basalto 1 1/2" a Finos | O18: D865 | P18: MX-CED. MORELOS | Q18: 20230329 | R18: 20281231 | S18: 20230329 | T18: 20281231 | U18: 185.71 | V18: MXN | W18: M3 | X18: 35.71 | Y18: MXN | Z18: M3 | AA18: EB38 | AB18: DEPOSITO CUAUTLA | AC18: 56103590 | AD18: 6622551540 | AE18: 4 | AF18: ENTREGA DIRECTA | AG18: 1.6 | AH18: M3 | AI18: X | AJ18: 4 | AK18: V4 | AL18: 20230920 | AM18: D865-900007422-EB38-10000432-4
A19: 900006255D86510000621 | B19: 4600055817-20 | C19: 4600055817 | D19: 20 | E19: MXPO | F19: MXL | G19: 900006255 | H19: SF TP-MAT Y FORRAJES YAUTEPEC | I19: 5054376 | J19: DISTRIBUIDORA DE MATERIALES Y FORRA | K19: N15 | L19: (AP) NAFIN 15 Dias | M19: 10000621 | N19: Grava Triturada Caliza 40 mm - 1 1/2" | O19: D865 | P19: MX-CED. MORELOS | Q19: 20211122 | R19: 20281231 | S19: 20230825 | T19: 20281231 | U19: 290 | V19: MXN | W19: M3 | X19: 0 | Y19: MXN | Z19: M3 | AC19: 56103637 | AD19: 6622551540 | AE19: 1 | AF19: ENTREGADO | AG19: 1.49 | AH19: M3 | AI19: X | AJ19: 4 | AK19: V4 | AL19: 20230920 | AM19: D865-900006255-10000621
A20: 900006255D86510006150 | B20: 4600055817-10 | C20: 4600055817 | D20: 10 | E20: MXPO | F20: MXL | G20: 900006255 | H20: SF TP-MAT Y FORRAJES YAUTEPEC | I20: 5054376 | J20: DISTRIBUIDORA DE MATERIALES Y FORRA | K20: N15 | L20: (AP) NAFIN 15 Dias | M20: 10006150 | N20: Grava Triturada Caliza 20 mm - 3/4" | O20: D865 | P20: MX-CED. MORELOS | Q20: 20211122 | R20: 20281231 | S20: 20230825 | T20: 20281231 | U20: 290 | V20: MXN | W20: M3 | X20: 0 | Y20: MXN | Z20: M3 | AC20: 56103637 | AD20: 6622551540 | AE20: 1 | AF20: ENTREGADO | AG20: 1.387 | AH20: M3 | AI20: X | AJ20: 4 | AK20: V4 | AL20: 20230920 | AM20: D865-900006255-10006150
A21: 900003877D86510000632 | B21: 4600032991-30 | C21: 4600032991 | D21: 30 | E21: MXPO | F21: MXL | G21: 900003877 | H21: TP-MAT Y FORRAJES | I21: 5054376 | J21: DISTRIBUIDORA DE MATERIALES Y FORRA | K21: N15 | L21: (AP) NAFIN 15 Dias | M21: 10000632 | N21: Grava Triturada Caliza 20 mm - 3/4" | O21: D865 | P21: MX-CED. MORELOS | Q21: 20160201 | R21: 20281231 | S21: 20230825 | T21: 20281231 | U21: 290 | V21: MXN | W21: M3 | X21: 0 | Y21: MXN | Z21: M3 | AC21: 56103637 | AD21: 6622551540 | AE21: 1 | AF21: ENTREGADO | AG21: 1.533 | AH21: M3 | AI21: X | AJ21: 4 | AK21: V4 | AL21: 20230920 | AM21: D865-900003877-10000632
A22: 900004240D86510000394 | B22: 4600031503-10 | C22: 4600031503 | D22: 10 | E22: MXPO | F22: MXL | G22: 900004240 | H22: TP-ACAMILPA (SOTELO) | I22: 5058988 | J22: RAMIREZ CARIÑO MARIA DOLORES | K22: Z06 | L22: (AP) 45 Dias | M22: 10000394 | N22: Arena Triturada Andesita Malla 4 | O22: D865 | P22: MX-CED. MORELOS | Q22: 20150701 | R22: 20281231 | S22: 20240221 | T22: 20291231 | U22: 65 | V22: MXN | W22: M3 | X22: 0 | Y22: MXN | Z22: M3 | AC22: 56103638 | AD22: 6622551540 | AE22: 1 | AF22: ENTREGADO | AG22: 1.41 | AH22: M3 | AI22: X | AJ22: 4 | AK22: V4 | AL22: 20240226 | AM22: D865-900004240-10000394
A23: 900004224D86510000284 | B23: 4600031364-10 | C23: 4600031364 | D23: 10 | E23: MXPO | F23: MXL | G23: 900004224 | H23: TP-EL PAPAYO | I23: 5055683 | J23: ROSA ELOISA TORRES | K23: Z07 | L23: (AP) 60 Dias | M23: 10000284 | N23: Grava Triturada Basalto 20 mm - 3/4" | O23: D865 | P23: MX-CED. MORELOS | Q23: 20150701 | R23: 20241231 | S23: 20180206 | T23: 20241231 | U23: 180 | V23: MXN | W23: M3 | X23: 0 | Y23: MXN | Z23: M3 | AC23: 56103637 | AD23: 6622551540 | AE23: 1 | AF23: ENTREGADO | AG23: 1.429 | AH23: M3 | AJ23: 4 | AK23: V4 | AL23: 20230920 | AM23: D865-900004224-10000284
A24: 900005655D86510000287 | B24: 4600055816-30 | C24: 4600055816 | D24: 30 | E24: MXPO | F24: MXL | G24: 900005655 | H24: TP-TISCAREÑO | I24: 5071793 | J24: TISCAREÑO MALDONADO SAUL | K24: Z09 | L24: (AP) 90 Dias | M24: 10000287 | N24: Grava Triturada Basalto 40 mm - 1 1/2" | O24: D865 | P24: MX-CED. MORELOS | Q24: 20211122 | R24: 20281231 | S24: 20211122 | T24: 20271231 | U24: 230 | V24: MXN | W24: M3 | X24: 0 | Y24: MXN | Z24: M3 | AC24: 56103637 | AD24: 6622551540 | AE24: 1 | AF24: ENTREGADO | AG24: 1.44 | AH24: M3 | AI24: X | AJ24: 4 | AL24: 20230920 | AM24: D865-900005655-10000287
A25: 900005655D86510000829 | B25: 4600055816-40 | C25: 4600055816 | D25: 40 | E25: MXPO | F25: MXL | G25: 900005655 | H25: TP-TISCAREÑO | I25: 5071793 | J25: TISCAREÑO MALDONADO SAUL | K25: Z09 | L25: (AP) 90 Dias | M25: 10000829 | N25: Arena Triturada Basalto Malla 5 | O25: D865 | P25: MX-CED. MORELOS | Q25: 20211122 | R25: 20281231 | S25: 20240604 | T25: 20291231 | U25: 130 | V25: MXN | W25: M3 | X25: 0 | Y25: MXN | Z25: M3 | AC25: 56103638 | AD25: 6622551540 | AE25: 1 | AF25: ENTREGADO | AG25: 1.43 | AH25: M3 | AI25: X | AJ25: 4 | AK25: V4 | AL25: 20240610 | AM25: D865-900005655-10000829
A26: 900004224D86510000857 | B26: 4600031364-30 | C26: 4600031364 | D26: 30 | E26: MXPO | F26: MXL | G26: 900004224 | H26: TP-EL PAPAYO | I26: 5055683 | J26: ROSA ELOISA TORRES | K26: Z07 | L26: (AP) 60 Dias | M26: 10000857 | N26: Arena Triturada Basalto Malla 4 | O26: D865 | P26: MX-CED. MORELOS | Q26: 20150701 | R26: 20241231 | S26: 20180206 | T26: 20241231 | U26: 130 | V26: MXN | W26: M3 | X26: 0 | Y26: MXN | Z26: M3 | AC26: 56103638 | AD26: 6622551540 | AE26: 1 | AF26: ENTREGADO | AG26: 1.51 | AH26: M3 | AJ26: 4 | AK26: V4 | AL26: 20230920 | AM26: D865-900004224-10000857
A27: 900004224D86510000229 | B27: 4600031364-20 | C27: 4600031364 | D27: 20 | E27: MXPO | F27: MXL | G27: 900004224 | H27: TP-EL PAPAYO | I27: 5055683 | J27: ROSA ELOISA TORRES | K27: Z07 | L27: (AP) 60 Dias | M27: 10000229 | N27: Grava Triturada Basalto 10 mm - 3/8" | O27: D865 | P27: MX-CED. MORELOS | Q27: 20150701 | R27: 20241231 | S27: 20180206 | T27: 20241231 | U27: 220 | V27: MXN | W27: M3 | X27: 0 | Y27: MXN | Z27: M3 | AC27: 56103637 | AD27: 6622551540 | AE27: 1 | AF27: ENTREGADO | AG27: 1.522 | AH27: M3 | AJ27: 4 | AK27: V4 | AL27: 20230920 | AM27: D865-900004224-10000229
A28: 900003877D86510000735 | B28: 4600032991-20 | C28: 4600032991 | D28: 20 | E28: MXPO | F28: MXL | G28: 900003877 | H28: TP-MAT Y FORRAJES | I28: 5054376 | J28: DISTRIBUIDORA DE MATERIALES Y FORRA | K28: N15 | L28: (AP) NAFIN 15 Dias | M28: 10000735 | N28: Grava Triturada Caliza 10 mm - 3/8" | O28: D865 | P28: MX-CED. MORELOS | Q28: 20160201 | R28: 20281231 | S28: 20230505 | T28: 20281231 | U28: 340 | V28: MXN | W28: M3 | X28: 0 | Y28: MXN | Z28: M3 | AC28: 56103637 | AD28: 6622551540 | AE28: 1 | AF28: ENTREGADO | AG28: 1.41 | AH28: M3 | AI28: X | AJ28: 4 | AK28: V4 | AL28: 20230920 | AM28: D865-900003877-10000735
A29: 900005655D86510000284 | B29: 4600055816-10 | C29: 4600055816 | D29: 10 | E29: MXPO | F29: MXL | G29: 900005655 | H29: TP-TISCAREÑO | I29: 5071793 | J29: TISCAREÑO MALDONADO SAUL | K29: Z09 | L29: (AP) 90 Dias | M29: 10000284 | N29: Grava Triturada Basalto 20 mm - 3/4" | O29: D865 | P29: MX-CED. MORELOS | Q29: 20211122 | R29: 20281231 | S29: 20211122 | T29: 20271231 | U29: 250 | V29: MXN | W29: M3 | X29: 0 | Y29: MXN | Z29: M3 | AC29: 56103637 | AD29: 6622551540 | AE29: 1 | AF29: ENTREGADO | AG29: 1.429 | AH29: M3 | AI29: X | AJ29: 4 | AK29: V4 | AL29: 20230920 | AM29: D865-900005655-10000284
A30: 900005655D86510000229 | B30: 4600055816-20 | C30: 4600055816 | D30: 20 | E30: MXPO | F30: MXL | G30: 900005655 | H30: TP-TISCAREÑO | I30: 5071793 | J30: TISCAREÑO MALDONADO SAUL | K30: Z09 | L30: (AP) 90 Dias | M30: 10000229 | N30: Grava Triturada Basalto 10 mm - 3/8" | O30: D865 | P30: MX-CED. MORELOS | Q30: 20211122 | R30: 20281231 | S30: 20211122 | T30: 20271231 | U30: 330 | V30: MXN | W30: M3 | X30: 0 | Y30: MXN | Z30: M3 | AC30: 56103637 | AD30: 6622551540 | AE30: 1 | AF30: ENTREGADO | AG30: 1.522 | AH30: M3 | AI30: X | AJ30: 4 | AK30: V4 | AL30: 20230920 | AM30: D865-900005655-10000229
A31: 900005792D8656656917410000284 | B31: 4600042867-10 | C31: 4600042867 | D31: 10 | E31: MXPO | F31: MXL | G31: 900005792 | H31: SF TP-ED-EL PAPAYO | I31: 5055683 | J31: ROSA ELOISA TORRES | K31: Z07 | L31: (AP) 60 Dias | M31: 10000284 | N31: Grava Triturada Basalto 20 mm - 3/4" | O31: D865 | P31: MX-CED. MORELOS | Q31: 20180830 | R31: 20241231 | S31: 20180830 | T31: 20241231 | U31: 220 | V31: MXN | W31: M3 | X31: 40 | Y31: MXN | Z31: M3 | AA31: 66569174 | AB31: HOSPITAL GENERAL CUAUTLA (LAAJ) | AC31: 56103637 | AD31: 6622551540 | AE31: 4 | AF31: ENTREGA DIRECTA | AG31: 1.429 | AH31: M3 | AI31: X | AJ31: 4 | AK31: V4 | AL31: 20230920 | AM31: D865-900005792-66569174-10000284-4
