Workbook

Sheet Base Cedis D836
N1: VENTA | Q1: COSTO
A2: CONCAT1 | B2: CONCAT2 | C2: No. SF | D2: Nombre SF | E2: Cedis | F2: Destino | G2: Condicion de Expedicion | H2: Nombre Destino | I2: No. de material | J2: Nombre de material | K2: PV | L2: Inicio de vigencia | M2: Fin de vigencia | N2: Importe MP | O2: Importe Flete | P2: UM Venta | Q2: Importe Costo | R2: UM Costo | S2: Validacion 1 | T2: Validacion 2
A3: =CONCATENATE(C3,E3,F3,I3) | B3: =CONCATENATE(C3,E3,I3) | C3: 900004323 | D3: =IFERROR(VLOOKUP(C3,TRAOPE!$G:$H,2,0),"") | E3: D836 | F3: 65292088 | G3: =IFERROR(VLOOKUP(A3,Flete!$A:$E,5,0),"") | H3: =IFERROR(VLOOKUP(F3,TRAOPE!$AA:$AB,2,0),"") | I3: 10003132 | J3: =IFERROR(VLOOKUP(I3,Materiales!$A:$H,8,0),"") | K3: =IFERROR(VLOOKUP(I3,Materiales!$A:$G,7,0),"") | L3: 20230323 | M3: 20230329 | N3: 130 | O3: =IFERROR(VLOOKUP(A3,Flete!$A:$J,10,0),"") | P3: M3 | Q3: =IFERROR(IFERROR(VLOOKUP(A3,TRAOPE!$A:$U,21,0),VLOOKUP(B3,TRAOPE!$A:$U,21,0)),"") | R3: =IFERROR(IFERROR(VLOOKUP(A3,TRAOPE!$A:$W,23,0),VLOOKUP(B3,TRAOPE!$A:$W,23,0)),"") | S3: =IF(AND(P3="TN",R3="TN"),N3+N(O3),IF(G3&""="1",N(K3)*N3,(N3+N(O3))*N(K3))) | T3: =IF(Q3="","",Q3-S3)
A4: =CONCATENATE(C4,E4,F4,I4) | B4: =CONCATENATE(C4,E4,I4) | C4: 900004077 | D4: =IFERROR(VLOOKUP(C4,TRAOPE!$G:$H,2,0),"") | E4: D836 | F4: 65002610 | G4: =IFERROR(VLOOKUP(A4,Flete!$A:$E,5,0),"") | H4: =IFERROR(VLOOKUP(F4,TRAOPE!$AA:$AB,2,0),"") | I4: 10002802 | J4: =IFERROR(VLOOKUP(I4,Materiales!$A:$H,8,0),"") | K4: =IFERROR(VLOOKUP(I4,Materiales!$A:$G,7,0),"") | L4: 20180910 | M4: 20240612 | N4: 140 | O4: =IFERROR(VLOOKUP(A4,Flete!$A:$J,10,0),"") | P4: M3 | Q4: =IFERROR(IFERROR(VLOOKUP(A4,TRAOPE!$A:$U,21,0),VLOOKUP(B4,TRAOPE!$A:$U,21,0)),"") | R4: =IFERROR(IFERROR(VLOOKUP(A4,TRAOPE!$A:$W,23,0),VLOOKUP(B4,TRAOPE!$A:$W,23,0)),"") | S4: =IF(AND(P4="TN",R4="TN"),N4+N(O4),IF(G4&""="1",N(K4)*N4,(N4+N(O4))*N(K4))) | T4: =IF(Q4="","",Q4-S4)
A5: =CONCATENATE(C5,E5,F5,I5) | B5: =CONCATENATE(C5,E5,I5) | C5: 900004077 | D5: =IFERROR(VLOOKUP(C5,TRAOPE!$G:$H,2,0),"") | E5: D836 | F5: 65016451 | G5: =IFERROR(VLOOKUP(A5,Flete!$A:$E,5,0),"") | H5: =IFERROR(VLOOKUP(F5,TRAOPE!$AA:$AB,2,0),"") | I5: 10002802 | J5: =IFERROR(VLOOKUP(I5,Materiales!$A:$H,8,0),"") | K5: =IFERROR(VLOOKUP(I5,Materiales!$A:$G,7,0),"") | L5: 20200117 | M5: 20240612 | N5: 147 | O5: =IFERROR(VLOOKUP(A5,Flete!$A:$J,10,0),"") | P5: M3 | Q5: =IFERROR(IFERROR(VLOOKUP(A5,TRAOPE!$A:$U,21,0),VLOOKUP(B5,TRAOPE!$A:$U,21,0)),"") | R5: =IFERROR(IFERROR(VLOOKUP(A5,TRAOPE!$A:$W,23,0),VLOOKUP(B5,TRAOPE!$A:$W,23,0)),"") | S5: =IF(AND(P5="TN",R5="TN"),N5+N(O5),IF(G5&""="1",N(K5)*N5,(N5+N(O5))*N(K5))) | T5: =IF(Q5="","",Q5-S5)
A6: =CONCATENATE(C6,E6,F6,I6) | B6: =CONCATENATE(C6,E6,I6) | C6: 900004077 | D6: =IFERROR(VLOOKUP(C6,TRAOPE!$G:$H,2,0),"") | E6: D836 | F6: 65094369 | G6: =IFERROR(VLOOKUP(A6,Flete!$A:$E,5,0),"") | H6: =IFERROR(VLOOKUP(F6,TRAOPE!$AA:$AB,2,0),"") | I6: 10002802 | J6: =IFERROR(VLOOKUP(I6,Materiales!$A:$H,8,0),"") | K6: =IFERROR(VLOOKUP(I6,Materiales!$A:$G,7,0),"") | L6: 20180910 | M6: 20240612 | N6: 140 | O6: =IFERROR(VLOOKUP(A6,Flete!$A:$J,10,0),"") | P6: M3 | Q6: =IFERROR(IFERROR(VLOOKUP(A6,TRAOPE!$A:$U,21,0),VLOOKUP(B6,TRAOPE!$A:$U,21,0)),"") | R6: =IFERROR(IFERROR(VLOOKUP(A6,TRAOPE!$A:$W,23,0),VLOOKUP(B6,TRAOPE!$A:$W,23,0)),"") | S6: =IF(AND(P6="TN",R6="TN"),N6+N(O6),IF(G6&""="1",N(K6)*N6,(N6+N(O6))*N(K6))) | T6: =IF(Q6="","",Q6-S6)
A7: =CONCATENATE(C7,E7,F7,I7) | B7: =CONCATENATE(C7,E7,I7) | C7: 900004077 | D7: =IFERROR(VLOOKUP(C7,TRAOPE!$G:$H,2,0),"") | E7: D836 | F7: 65232687 | G7: =IFERROR(VLOOKUP(A7,Flete!$A:$E,5,0),"") | H7: =IFERROR(VLOOKUP(F7,TRAOPE!$AA:$AB,2,0),"") | I7: 10002802 | J7: =IFERROR(VLOOKUP(I7,Materiales!$A:$H,8,0),"") | K7: =IFERROR(VLOOKUP(I7,Materiales!$A:$G,7,0),"") | L7: 20240423 | M7: 20240612 | N7: 160 | O7: =IFERROR(VLOOKUP(A7,Flete!$A:$J,10,0),"") | P7: M3 | Q7: =IFERROR(IFERROR(VLOOKUP(A7,TRAOPE!$A:$U,21,0),VLOOKUP(B7,TRAOPE!$A:$U,21,0)),"") | R7: =IFERROR(IFERROR(VLOOKUP(A7,TRAOPE!$A:$W,23,0),VLOOKUP(B7,TRAOPE!$A:$W,23,0)),"") | S7: =IF(AND(P7="TN",R7="TN"),N7+N(O7),IF(G7&""="1",N(K7)*N7,(N7+N(O7))*N(K7))) | T7: =IF(Q7="","",Q7-S7)
A8: =CONCATENATE(C8,E8,F8,I8) | B8: =CONCATENATE(C8,E8,I8) | C8: 900004077 | D8: =IFERROR(VLOOKUP(C8,TRAOPE!$G:$H,2,0),"") | E8: D836 | F8: 65246763 | G8: =IFERROR(VLOOKUP(A8,Flete!$A:$E,5,0),"") | H8: =IFERROR(VLOOKUP(F8,TRAOPE!$AA:$AB,2,0),"") | I8: 10002802 | J8: =IFERROR(VLOOKUP(I8,Materiales!$A:$H,8,0),"") | K8: =IFERROR(VLOOKUP(I8,Materiales!$A:$G,7,0),"") | L8: 20170101 | M8: 20240612 | N8: 128.8 | O8: =IFERROR(VLOOKUP(A8,Flete!$A:$J,10,0),"") | P8: M3 | Q8: =IFERROR(IFERROR(VLOOKUP(A8,TRAOPE!$A:$U,21,0),VLOOKUP(B8,TRAOPE!$A:$U,21,0)),"") | R8: =IFERROR(IFERROR(VLOOKUP(A8,TRAOPE!$A:$W,23,0),VLOOKUP(B8,TRAOPE!$A:$W,23,0)),"") | S8: =IF(AND(P8="TN",R8="TN"),N8+N(O8),IF(G8&""="1",N(K8)*N8,(N8+N(O8))*N(K8))) | T8: =IF(Q8="","",Q8-S8)
A9: =CONCATENATE(C9,E9,F9,I9) | B9: =CONCATENATE(C9,E9,I9) | C9: 900004077 | D9: =IFERROR(VLOOKUP(C9,TRAOPE!$G:$H,2,0),"") | E9: D836 | F9: 65251399 | G9: =IFERROR(VLOOKUP(A9,Flete!$A:$E,5,0),"") | H9: =IFERROR(VLOOKUP(F9,TRAOPE!$AA:$AB,2,0),"") | I9: 10002802 | J9: =IFERROR(VLOOKUP(I9,Materiales!$A:$H,8,0),"") | K9: =IFERROR(VLOOKUP(I9,Materiales!$A:$G,7,0),"") | L9: 20181116 | M9: 20240612 | N9: 140 | O9: =IFERROR(VLOOKUP(A9,Flete!$A:$J,10,0),"") | P9: M3 | Q9: =IFERROR(IFERROR(VLOOKUP(A9,TRAOPE!$A:$U,21,0),VLOOKUP(B9,TRAOPE!$A:$U,21,0)),"") | R9: =IFERROR(IFERROR(VLOOKUP(A9,TRAOPE!$A:$W,23,0),VLOOKUP(B9,TRAOPE!$A:$W,23,0)),"") | S9: =IF(AND(P9="TN",R9="TN"),N9+N(O9),IF(G9&""="1",N(K9)*N9,(N9+N(O9))*N(K9))) | T9: =IF(Q9="","",Q9-S9)
A10: =CONCATENATE(C10,E10,F10,I10) | B10: =CONCATENATE(C10,E10,I10) | C10: 900004077 | D10: =IFERROR(VLOOKUP(C10,TRAOPE!$G:$H,2,0),"") | E10: D836 | F10: 65346224 | G10: =IFERROR(VLOOKUP(A10,Flete!$A:$E,5,0),"") | H10: =IFERROR(VLOOKUP(F10,TRAOPE!$AA:$AB,2,0),"") | I10: 10002802 | J10: =IFERROR(VLOOKUP(I10,Materiales!$A:$H,8,0),"") | K10: =IFERROR(VLOOKUP(I10,Materiales!$A:$G,7,0),"") | L10: 20180206 | M10: 20240612 | N10: 140 | O10: =IFERROR(VLOOKUP(A10,Flete!$A:$J,10,0),"") | P10: M3 | Q10: =IFERROR(IFERROR(VLOOKUP(A10,TRAOPE!$A:$U,21,0),VLOOKUP(B10,TRAOPE!$A:$U,21,0)),"") | R10: =IFERROR(IFERROR(VLOOKUP(A10,TRAOPE!$A:$W,23,0),VLOOKUP(B10,TRAOPE!$A:$W,23,0)),"") | S10: =IF(AND(P10="TN",R10="TN"),N10+N(O10),IF(G10&""="1",N(K10)*N10,(N10+N(O10))*N(K10))) | T10: =IF(Q10="","",Q10-S10)
A11: =CONCATENATE(C11,E11,F11,I11) | B11: =CONCATENATE(C11,E11,I11) | C11: 900004077 | D11: =IFERROR(VLOOKUP(C11,TRAOPE!$G:$H,2,0),"") | E11: D836 | F11: 65387641 | G11: =IFERROR(VLOOKUP(A11,Flete!$A:$E,5,0),"") | H11: =IFERROR(VLOOKUP(F11,TRAOPE!$AA:$AB,2,0),"") | I11: 10002802 | J11: =IFERROR(VLOOKUP(I11,Materiales!$A:$H,8,0),"") | K11: =IFERROR(VLOOKUP(I11,Materiales!$A:$G,7,0),"") | L11: 20240423 | M11: 20240612 | N11: 160 | O11: =IFERROR(VLOOKUP(A11,Flete!$A:$J,10,0),"") | P11: M3 | Q11: =IFERROR(IFERROR(VLOOKUP(A11,TRAOPE!$A:$U,21,0),VLOOKUP(B11,TRAOPE!$A:$U,21,0)),"") | R11: =IFERROR(IFERROR(VLOOKUP(A11,TRAOPE!$A:$W,23,0),VLOOKUP(B11,TRAOPE!$A:$W,23,0)),"") | S11: =IF(AND(P11="TN",R11="TN"),N11+N(O11),IF(G11&""="1",N(K11)*N11,(N11+N(O11))*N(K11))) | T11: =IF(Q11="","",Q11-S11)
A12: =CONCATENATE(C12,E12,F12,I12) | B12: =CONCATENATE(C12,E12,I12) | C12: 900004077 | D12: =IFERROR(VLOOKUP(C12,TRAOPE!$G:$H,2,0),"") | E12: D836 | F12: 65565826 | G12: =IFERROR(VLOOKUP(A12,Flete!$A:$E,5,0),"") | H12: =IFERROR(VLOOKUP(F12,TRAOPE!$AA:$AB,2,0),"") | I12: 10002802 | J12: =IFERROR(VLOOKUP(I12,Materiales!$A:$H,8,0),"") | K12: =IFERROR(VLOOKUP(I12,Materiales!$A:$G,7,0),"") | L12: 20170101 | M12: 20240612 | N12: 132.25 | O12: =IFERROR(VLOOKUP(A12,Flete!$A:$J,10,0),"") | P12: M3 | Q12: =IFERROR(IFERROR(VLOOKUP(A12,TRAOPE!$A:$U,21,0),VLOOKUP(B12,TRAOPE!$A:$U,21,0)),"") | R12: =IFERROR(IFERROR(VLOOKUP(A12,TRAOPE!$A:$W,23,0),VLOOKUP(B12,TRAOPE!$A:$W,23,0)),"") | S12: =IF(AND(P12="TN",R12="TN"),N12+N(O12),IF(G12&""="1",N(K12)*N12,(N12+N(O12))*N(K12))) | T12: =IF(Q12="","",Q12-S12)
A13: =CONCATENATE(C13,E13,F13,I13) | B13: =CONCATENATE(C13,E13,I13) | C13: 900004077 | D13: =IFERROR(VLOOKUP(C13,TRAOPE!$G:$H,2,0),"") | E13: D836 | F13: 65729122 | G13: =IFERROR(VLOOKUP(A13,Flete!$A:$E,5,0),"") | H13: =IFERROR(VLOOKUP(F13,TRAOPE!$AA:$AB,2,0),"") | I13: 10002802 | J13: =IFERROR(VLOOKUP(I13,Materiales!$A:$H,8,0),"") | K13: =IFERROR(VLOOKUP(I13,Materiales!$A:$G,7,0),"") | L13: 20170101 | M13: 20240612 | N13: 132.25 | O13: =IFERROR(VLOOKUP(A13,Flete!$A:$J,10,0),"") | P13: M3 | Q13: =IFERROR(IFERROR(VLOOKUP(A13,TRAOPE!$A:$U,21,0),VLOOKUP(B13,TRAOPE!$A:$U,21,0)),"") | R13: =IFERROR(IFERROR(VLOOKUP(A13,TRAOPE!$A:$W,23,0),VLOOKUP(B13,TRAOPE!$A:$W,23,0)),"") | S13: =IF(AND(P13="TN",R13="TN"),N13+N(O13),IF(G13&""="1",N(K13)*N13,(N13+N(O13))*N(K13))) | T13: =IF(Q13="","",Q13-S13)
A14: =CONCATENATE(C14,E14,F14,I14) | B14: =CONCATENATE(C14,E14,I14) | C14: 900004077 | D14: =IFERROR(VLOOKUP(C14,TRAOPE!$G:$H,2,0),"") | E14: D836 | F14: 65908426 | G14: =IFERROR(VLOOKUP(A14,Flete!$A:$E,5,0),"") | H14: =IFERROR(VLOOKUP(F14,TRAOPE!$AA:$AB,2,0),"") | I14: 10002802 | J14: =IFERROR(VLOOKUP(I14,Materiales!$A:$H,8,0),"") | K14: =IFERROR(VLOOKUP(I14,Materiales!$A:$G,7,0),"") | L14: 20180206 | M14: 20240612 | N14: 140 | O14: =IFERROR(VLOOKUP(A14,Flete!$A:$J,10,0),"") | P14: M3 | Q14: =IFERROR(IFERROR(VLOOKUP(A14,TRAOPE!$A:$U,21,0),VLOOKUP(B14,TRAOPE!$A:$U,21,0)),"") | R14: =IFERROR(IFERROR(VLOOKUP(A14,TRAOPE!$A:$W,23,0),VLOOKUP(B14,TRAOPE!$A:$W,23,0)),"") | S14: =IF(AND(P14="TN",R14="TN"),N14+N(O14),IF(G14&""="1",N(K14)*N14,(N14+N(O14))*N(K14))) | T14: =IF(Q14="","",Q14-S14)
... A2984: =CONCATENATE(C2984,E2984,F2984,I2984) | B2984: =CONCATENATE(C2984,E2984,I2984) | C2984: 900009140 | D2984: =IFERROR(VLOOKUP(C2984,TRAOPE!$G:$H,2,0),"") | E2984: D836 | F2984: 66779276 | G2984: =IFERROR(VLOOKUP(A2984,Flete!$A:$E,5,0),"") | H2984: =IFERROR(VLOOKUP(F2984,TRAOPE!$AA:$AB,2,0),"") | I2984: 10184011 | J2984: =IFERROR(VLOOKUP(I2984,Materiales!$A:$H,8,0),"") | K2984: =IFERROR(VLOOKUP(I2984,Materiales!$A:$G,7,0),"") | L2984: 20250505 | M2984: 20250507 | N2984: 160 | O2984: =IFERROR(VLOOKUP(A2984,Flete!$A:$J,10,0),"") | P2984: TN | Q2984: =IFERROR(IFERROR(VLOOKUP(A2984,TRAOPE!$A:$U,21,0),VLOOKUP(B2984,TRAOPE!$A:$U,21,0)),"") | R2984: =IFERROR(IFERROR(VLOOKUP(A2984,TRAOPE!$A:$W,23,0),VLOOKUP(B2984,TRAOPE!$A:$W,23,0)),"") | S2984: =IF(AND(P2984="TN",R2984="TN"),N2984+N(O2984),IF(G2984&""="1",N(K2984)*N2984,(N2984+N(O2984))*N(K2984))) | T2984: =IF(Q2984="","",Q2984-S2984)

Sheet MP
A1: No. SF | B1: Cedis | C1: Destino | D1: No. Material | E1: Nombre Material | F1: Importe MP | G1: Moneda | H1: Cantidad | I1: UM | J1: C | K1: Inicio Vigencia | L1: Fin Vigencia
A2: 900004323 | B2: D836 | C2: 65292088 | D2: 10003132 | F2: 130 | I2: M3 | K2: 20230323 | L2: 20230329
A3: 900004077 | B3: D836 | C3: 65002610 | D3: 10002802 | F3: 140 | I3: M3 | K3: 20180910 | L3: 20240612
A4: 900004077 | B4: D836 | C4: 65016451 | D4: 10002802 | F4: 147 | I4: M3 | K4: 20200117 | L4: 20240612
A5: 900004077 | B5: D836 | C5: 65094369 | D5: 10002802 | F5: 140 | I5: M3 | K5: 20180910 | L5: 20240612
A6: 900004077 | B6: D836 | C6: 65232687 | D6: 10002802 | F6: 160 | I6: M3 | K6: 20240423 | L6: 20240612
A7: 900004077 | B7: D836 | C7: 65246763 | D7: 10002802 | F7: 128.8 | I7: M3 | K7: 20170101 | L7: 20240612
A8: 900004077 | B8: D836 | C8: 65251399 | D8: 10002802 | F8: 140 | I8: M3 | K8: 20181116 | L8: 20240612
A9: 900004077 | B9: D836 | C9: 65346224 | D9: 10002802 | F9: 140 | I9: M3 | K9: 20180206 | L9: 20240612
A10: 900004077 | B10: D836 | C10: 65387641 | D10: 10002802 | F10: 160 | I10: M3 | K10: 20240423 | L10: 20240612
A11: 900004077 | B11: D836 | C11: 65565826 | D11: 10002802 | F11: 132.25 | I11: M3 | K11: 20170101 | L11: 20240612
A12: 900004077 | B12: D836 | C12: 65729122 | D12: 10002802 | F12: 132.25 | I12: M3 | K12: 20170101 | L12: 20240612
A13: 900004077 | B13: D836 | C13: 65908426 | D13: 10002802 | F13: 140 | I13: M3 | K13: 20180206 | L13: 20240612
... A2983: 900009140 | B2983: D836 | C2983: 66779276 | D2983: 10184011 | F2983: 160 | I2983: TN | K2983: 20250505 | L2983: 20250507

Sheet Flete
A1: Concat1 | B1: No. SF | C1: Cedis | D1: Destino | E1: Cond. Exp. | F1: Material | H1: Nombre Material | J1: Importe Flete | K1: Moneda | L1: Cantidad | M1: UM | N1: C | P1: Inicio Vigencia | Q1: Fin Vigencia
A2: 900000034D8366505050710000757 | B2: 900000034 | C2: D836 | D2: 65050507 | E2: 1 | F2: 10000757 | J2: 31.18 | M2: TN | P2: 20111118 | Q2: 99991231
A3: 900000034D8366556580310000722 | B3: 900000034 | C3: D836 | D3: 65565803 | E3: 1 | F3: 10000722 | J3: 104 | M3: TN | P3: 20190426 | Q3: 20250127
A4: 900000034D8366592176410000623 | B4: 900000034 | C4: D836 | D4: 65921764 | E4: 1 | F4: 10000623 | J4: 103 | M4: M3 | P4: 20190426 | Q4: 20250127
A5: 900000080D8366579688210000357 | B5: 900000080 | C5: D836 | D5: 65796882 | E5: 1 | F5: 10000357 | J5: 53 | M5: TN | P5: 20190426 | Q5: 20250127
A6: 900000080D8366579688210000625 | B6: 900000080 | C6: D836 | D6: 65796882 | E6: 1 | F6: 10000625 | J6: 53 | M6: TN | P6: 20190426 | Q6: 20250127
A7: 900000080D8366579688210000627 | B7: 900000080 | C7: D836 | D7: 65796882 | E7: 1 | F7: 10000627 | J7: 53 | M7: TN | P7: 20190426 | Q7: 20250127
A8: 900000137D8366501515310000722 | B8: 900000137 | C8: D836 | D8: 65015153 | E8: 1 | F8: 10000722 | J8: 100.44 | M8: TN | P8: 20190426 | Q8: 20250127
A9: 900000137D8366506168510000624 | B9: 900000137 | C9: D836 | D9: 65061685 | E9: 1 | F9: 10000624 | J9: 108.12 | M9: M3 | P9: 20190426 | Q9: 20250127
A10: 900000137D8366506168510000722 | B10: 900000137 | C10: D836 | D10: 65061685 | E10: 1 | F10: 10000722 | J10: 108.12 | M10: M3 | P10: 20190426 | Q10: 20250127
A11: 900000137D8366508409110000630 | B11: 900000137 | C11: D836 | D11: 65084091 | E11: 1 | F11: 10000630 | J11: 50 | M11: TN | P11: 20190426 | Q11: 20250127
A12: 900000137D8366513461710000630 | B12: 900000137 | C12: D836 | D12: 65134617 | E12: 1 | F12: 10000630 | J12: 46.43 | M12: TN | P12: 20190426 | Q12: 20250127
A13: 900000137D8366524676310000624 | B13: 900000137 | C13: D836 | D13: 65246763 | E13: 1 | F13: 10000624 | J13: 107 | M13: M3 | P13: 20190426 | Q13: 20250127
... A1350: 900009140D8366677927610184011 | B1350: 900009140 | C1350: D836 | D1350: 66779276 | E1350: 4 | F1350: 10184011 | J1350: 200 | M1350: TN | P1350: 20250304 | Q1350: 20250507

Sheet Materiales
A1: Material | B1: TpMt | C1: Denom | D1: UMA | E1: Contador | F1: UMB | G1: PV | H1: Nombre Material
A2: 10000001 | B2: ZFER | C2: 1000 | D2: M3 | E2: 1000 | F2: TN | G2: 1262 | H2: GRAVA ANDESITA 10 MM (3/8")
A3: 10000003 | B3: ZFER | C3: 1000 | D3: M3 | E3: 1000 | F3: TN | G3: 1443 | H3: GRAVA CALIZA 10 MM (3/8")
A4: 10000006 | B4: ZFER | C4: 1000 | D4: M3 | E4: 1000 | F4: TN | G4: 1490 | H4: GRAVA RIO 10 MM (3/8")
A5: 10000007 | B5: ZFER | C5: 1000 | D5: M3 | E5: 1000 | F5: TN | G5: 1488 | H5: GRAVA BASALTO 13 MM (1/2")
A6: 10000008 | B6: ZFER | C6: 1000 | D6: M3 | E6: 1000 | F6: TN | G6: 1358 | H6: GRAVA CALIZA 13 MM (1/2")
A7: 10000011 | B7: ZFER | C7: 1000 | D7: M3 | E7: 1000 | F7: TN | G7: 1323 | H7: GRAVA ANDESITA 20 MM (3/4")
A8: 10000013 | B8: ZFER | C8: 1000 | D8: M3 | E8: 1000 | F8: TN | G8: 1514 | H8: GRAVA BASALTO 20 MM (3/4")
A9: 10000014 | B9: ZFER | C9: 1000 | D9: M3 | E9: 1000 | F9: TN | G9: 1400 | H9: GRAVA CALIZA 20 MM (3/4")
A10: 10000015 | B10: ZFER | C10: 1000 | D10: M3 | E10: 1000 | F10: TN | G10: 1410 | H10: GRAVA GRANITO 20 MM (3/4")
A11: 10000017 | B11: ZFER | C11: 1000 | D11: M3 | E11: 1000 | F11: TN | G11: 1475 | H11: GRAVA RIOLITA 20 MM (3/4")
A12: 10000019 | B12: ZFER | C12: 1000 | D12: M3 | E12: 1000 | F12: TN | G12: 1515 | H12: GRAVA RIO 20 MM (3/4")
A13: 10000020 | B13: ZFER | C13: 1000 | D13: M3 | E13: 1 | F13: TN | G13: 1 | H13: GRAVA MAQUILA 40MM (1 1/2")
... A2291: 10268770 | B2291: ZFE3 | C2291: 1000 | D2291: M3 | E2291: 1000 | F2291: TN | G2291: 1240 | H2291: MP GRAVA TRIT CALIZA 40MM 1 1/2" - ESP
A2292: 10268901 | B2292: ZFE3 | C2292: 1000 | D2292: M3 | E2292: 1000 | G2292: 1560 | H2292: MP GRAVA ANDESITA GRIS 3/4" - CAPADA
A2293: 10267983 | C2293: 1000 | G2293: 1800 | H2293: ESCORIA ALTO HORNO 3/4
A2294: 10268996 | C2294: 1000 | G2294: 1329 | H2294: GRAVA TRITURADA CALIZA 40 MM - 11/2"
A2295: 10269072 | C2295: 1000 | G2295: 1700 | H2295: BASE HIDRÁULICA SCREEN
A2296: 10269225 | B2296: ZFE3 | C2296: 1000 | D2296: M3 | E2296: 1000 | G2296: 1289 | H2296: MP ARENA CALIZA LAVADA MALLA 4 - DELTA I
A2297: 10269245 | B2297: ZFE3 | C2297: 1000 | D2297: M3 | E2297: 1000 | G2297: 1410 | H2297: MP GRAVA TRITURADA CALIZA 3/8 - 10MM
A2298: 10269246 | B2298: ZFE3 | C2298: 1000 | D2298: M3 | E2298: 1000 | G2298: 1400 | H2298: MP GRAVA TRITURADA CALIZA 1 1/2 - 40MM
A2299: 10269247 | B2299: ZFE3 | C2299: 1000 | D2299: M3 | E2299: 1000 | G2299: 1560 | H2299: MP ARENA TRIT CALIZA M-4
A2300: 10270431 | B2300: ZFE3 | C2300: 1000 | D2300: M3 | E2300: 1000 | G2300: 1423 | H2300: MP GRAVA RIOLITA 13 MM - 1/2"
A2301: 10270898 | B2301: ZFE3 | C2301: 1000 | D2301: M3 | E2301: 1000 | G2301: 1551 | H2301: MP BASE H. TRIT. BASALTO 1 1/2" A FINOS
A2302: 10270911 | B2302: ZFE3 | C2302: 1000 | D2302: M3 | E2302: 1000 | G2302: 1360 | H2302: MP GRAVA TRIT. BASALTO 40 MM - 1 1/2"
A2303: 10270912 | B2303: ZFE3 | C2303: 1000 | D2303: M3 | E2303: 1000 | G2303: 1589 | H2303: MP ARENA TRIT. BASALTO MALLA 4
A2304: 10270913 | B2304: ZFE3 | C2304: 1000 | D2304: M3 | E2304: 1000 | G2304: 1395 | H2304: MP GRAVA TRIT. BASALTO 20 MM - 3/4
A2305: 10270914 | B2305: ZFE3 | C2305: 1000 | D2305: M3 | E2305: 1000 | G2305: 1623 | H2305: MP ARENA ANDESITA BC
A2306: 10270824 | B2306: M3 | C2306: 1000 | D2306: M3 | E2306: 10007640 | G2306: 1325 | H2306: MP ARENA TRITURADA CALIZA MALLA 5
A2307: 10270825 | B2307: M3 | C2307: 1000 | D2307: M3 | E2307: 10000003 | G2307: 1242 | H2307: MP GRAVA TRITURADA CALIZA 10MM (3/8”)
... A2319: 10272527 | B2319: ZFE3 | C2319: 1000 | D2319: M3 | E2319: 1000 | G2319: 1620 | H2319: CNC - NO CLASIFICADO
A2320: 10000332 | C2320: 1000 | D2320: M3 | E2320: 1000 | G2320: 800 | H2320: Grava Triturada Pomez - Jal 20 mm - 3/4"
A2321: 10273001 | B2321: ZFE3 | C2321: 1000 | D2321: M3 | E2321: 1000 | G2321: 1688 | H2321: MP ARENA TRIT. BASALTO MALLA 4
A2322: 10273002 | B2322: ZFE3 | C2322: 1000 | D2322: M3 | E2322: 1000 | G2322: 1466 | H2322: MP GRAVA TRIT. BASALTO 20 MM - 3/4"
A2323: 10273351 | B2323: ZFE3 | C2323: 1000 | D2323: M3 | E2323: 1000 | G2323: 1612 | H2323: MP ARENA TRIT. CALIZA MALLA 4
A2324: 10273352 | B2324: ZFE3 | C2324: 1000 | D2324: M3 | E2324: 1000 | G2324: 1492 | H2324: MP GRAVA TRIT. CALIZA 20 MM - 3/4"
A2325: 10271724 | B2325: ZFE3 | C2325: 1000 | D2325: M3 | E2325: 1000 | G2325: 1900 | H2325: MP RESIDUO DE CONCRETO
A2326: 10000677 | C2326: 1000 | D2326: M3 | G2326: 1164 | H2326: Grava Triturada Caliza 20 mm - 3/4"
A2327: 10274190 | B2327: ZFE3 | C2327: 1000 | D2327: M3 | E2327: 1000 | G2327: 1800 | H2327: MP BASE HIDRAULICA ANDESITA 70-30
A2328: 10274601 | B2328: ZFE3 | C2328: 1000 | D2328: M3 | E2328: 1000 | G2328: 1447 | H2328: MP ARENA BASALTO N° 4
...

Sheet TRAOPE
A1: Concat1 | B1: Contrato_Pos | C1: Doc. Compras | D1: Pos | E1: Org.compras | F1: Grp-Compr. | G1: Ship From | H1: Nombre SF | I1: Proveedor | J1: Nombre Prov | K1: Cond. Pago | L1: Descr. Cond Pago | M1: Material | N1: Descripción | O1: Centro | P1: Descripción Centro | Q1: In.perído validez | R1: Fin perído validez | S1: Válido de | T1: Validez a | U1: Precio neto pedido | V1: Moneda | W1: UM Precio Pedido | X1: Importe Condición | Y1: Moneda KONP | Z1: UM Ctd Base | AA1: Destino | AB1: Nombre Destino | AC1: Cuenta de mayor | AD1: Centro de costo | AE1: Cond. Exp. | AF1: Descr. Cond. Exp. | AG1: Peso Vol. | AH1: UMB | AI1: Ind. Oblig. Conf. Ped. | AJ1: Ctrl-Conf. | AK1: IVA | AL1: Modif_Date | AM1: Ruta
A2: 900001074D83610276711 | B2: 4600027573-420 | C2: 4600027573 | D2: 420 | E2: MXPO | F2: M02 | G2: 900001074 | H2: TP-TRIVOMEX | I2: 5033501 | J2: TRITURADOS VOLCANICOS DE MEXICO | K2: Z04 | L2: (AP) 30 Dias | M2: 10276711 | N2: MP ARENA TRIT ANDESITA MALLA 4 FZ | O2: D836 | P2: MX-CED. CENTRO | Q2: 20140701 | R2: 20291231 | S2: 20260824 | T2: 20301231 | U2: 113 | V2: MXN | W2: M3 | X2: 0 | Y2: MXN | Z2: M3 | AC2: 56103638 | AD2: 6622261540 | AE2: 1 | AF2: ENTREGADO | AG2: 1.5 | AH2: M3 | AI2: X | AJ2: 4 | AK2: V4 | AL2: 20260827 | AM2: D836-900001074-10276711
A3: 900009460D83610277346 | B3: 4600071933-50 | C3: 4600071933 | D3: 50 | E3: MXPO | F3: MXL | G3: 900009460 | H3: SF TP-PITUFOS | I3: 5010165 | J3: AGREGADOS COMO S.A. DE C.V. | K3: N60 | L3: (AP) NAFIN 60 Dias | M3: 10277346 | N3: MP GRAVA TRIT. ANDESITA 10 MM - 3/8" FZ | O3: D836 | P3: MX-CED. CENTRO | Q3: 20260123 | R3: 20301231 | S3: 20260803 | T3: 20301231 | U3: 86.2 | V3: MXN | W3: M3 | X3: 0 | Y3: MXN | Z3: M3 | AC3: 56103637 | AD3: 6622261540 | AE3: 1 | AF3: ENTREGADO | AG3: 1.246 | AH3: M3 | AI3: X | AJ3: 4 | AK3: V4 | AL3: 20260806 | AM3: D836-900009460-10277346
A4: 900007320D83610000627 | B4: 4600052075-30 | C4: 4600052075 | D4: 30 | E4: MXPO | F4: MXL | G4: 900007320 | H4: SF TP-LOMA ANCHA SC | I4: 5047262 | J4: AGREGADOS PETREOS SAN CRISTOBAL | K4: Z03 | L4: (AP) 15 Dias | M4: 10000627 | N4: Grava Triturada Andesita 10 mm - 3/8" | O4: D836 | P4: MX-CED. CENTRO | Q4: 20210928 | R4: 20281231 | S4: 20260803 | T4: 20301231 | U4: 80 | V4: MXN | W4: M3 | X4: 0 | Y4: MXN | Z4: M3 | AC4: 56103637 | AD4: 6622261540 | AE4: 1 | AF4: ENTREGADO | AG4: 1.33 | AH4: M3 | AI4: X | AJ4: 4 | AK4: V4 | AL4: 20260806 | AM4: D836-900007320-10000627
A5: 900003609D83610000630 | B5: 4600027606-100 | C5: 4600027606 | D5: 100 | E5: MXPO | F5: M02 | G5: 900003609 | H5: TP-LA VALENCIANA | I5: 5005431 | J5: CANTERAS LA VALENCIANA SA DE CV | K5: Z03 | L5: (AP) 15 Dias | M5: 10000630 | N5: Grava Triturada Caliza 13 mm - 1/2" | O5: D836 | P5: MX-CED. CENTRO | Q5: 20141106 | R5: 20281231 | S5: 20260714 | T5: 20301231 | U5: 180 | V5: MXN | W5: M3 | X5: 0 | Y5: MXN | Z5: M3 | AC5: 56103637 | AD5: 6622261540 | AE5: 1 | AF5: ENTREGADO | AG5: 1.4 | AH5: M3 | AI5: X | AJ5: 4 | AK5: V4 | AL5: 20260717 | AM5: D836-900003609-10000630
A6: 900006005D83610280049 | B6: 4600044358-60 | C6: 4600044358 | D6: 60 | E6: MXPO | F6: MXL | G6: 900006005 | H6: SF TP-ESTRATEGIAS AVANZADAS | I6: 5049458 | J6: ESTRATEGIAS AVANZADAS PARA OBTEN | K6: Z03 | L6: (AP) 15 Dias | M6: 10280049 | N6: MP B. HID CALIZA 40% FINOS Y 60% GRUESOS | O6: D836 | P6: MX-CED. CENTRO | Q6: 20190325 | R6: 20241231 | S6: 20260709 | T6: 20301231 | U6: 106.13 | V6: MXN | W6: TN | X6: 0 | Y6: MXN | Z6: TN | AC6: 56103590 | AD6: 6622261540 | AE6: 1 | AF6: ENTREGADO | AG6: 1 | AH6: TO | AI6: X | AJ6: 4 | AK6: V4 | AL6: 20260710 | AM6: D836-900006005-10280049
A7: 900003599D8366738333710280049 | B7: 4600041240-130 | C7: 4600041240 | D7: 130 | E7: MXPO | F7: MXL | G7: 900003599 | H7: TP-ED-ESTRATEGIAS AVANZADAS | I7: 5049458 | J7: ESTRATEGIAS AVANZADAS PARA OBTEN | K7: Z03 | L7: (AP) 15 Dias | M7: 10280049 | N7: MP B. HID CALIZA 40% FINOS Y 60% GRUESOS | O7: D836 | P7: MX-CED. CENTRO | Q7: 20180215 | R7: 20301231 | S7: 20260709 | T7: 20301231 | U7: 138.67 | V7: MXN | W7: TN | X7: 71.67 | Y7: MXN | Z7: TN | AA7: 67383337 | AB7: ORIENTAL YUHON IT (DSF) | AC7: 56103590 | AD7: 6622261540 | AE7: 4 | AF7: ENTREGA DIRECTA | AG7: 1 | AH7: TO | AI7: X | AJ7: 4 | AK7: V4 | AL7: 20260713 | AM7: D836-900003599-67383337-10280049-4
A8: 900006371D8366709100410000357 | B8: 4600048255-210 | C8: 4600048255 | D8: 210 | E8: MXPO | F8: MXL | G8: 900006371 | H8: SF TP-ED-TRIVOMEX | I8: 5033501 | J8: TRITURADOS VOLCANICOS DE MEXICO | K8: Z04 | L8: (AP) 30 Dias | M8: 10000357 | N8: Grava Triturada Andesita 20 mm - 3/4" | O8: D836 | P8: MX-CED. CENTRO | Q8: 20201015 | R8: 20291231 | S8: 20221109 | T8: 20271231 | U8: 263 | V8: MXN | W8: M3 | X8: 160 | Y8: MXN | Z8: M3 | AA8: 67091004 | AB8: PARQUE NACIONAL DE JUSTICIA (FISCAL | AC8: 56103637 | AD8: 6622261540 | AE8: 4 | AF8: ENTREGA DIRECTA | AG8: 1.326 | AH8: M3 | AI8: X | AJ8: 4 | AK8: V4 | AL8: 20230920 | AM8: D836-900006371-67091004-10000357-4
A9: 900006824D8366500394510192944 | B9: 4600048689-30 | C9: 4600048689 | D9: 30 | E9: MXPO | F9: MXL | G9: 900006824 | H9: SF TP-ED-SAN JUAN (HUDASA) | I9: 5054686 | J9: GRUPO MERCANTIL HUDASA SA DE CV | K9: N90 | L9: (AP) NAFIN 90 Dias | M9: 10192944 | N9: GRAVA TRITURADA CALIZA 20 MM - 3/4" HD | O9: D836 | P9: MX-CED. CENTRO | Q9: 20201217 | R9: 20291231 | S9: 20220307 | T9: 20271231 | U9: 479.05 | V9: MXN | W9: M3 | X9: 350 | Y9: MXN | Z9: M3 | AA9: 65003945 | AB9: (P) OBR-AGR PREMEZCLADOS (RRL) | AC9: 56103637 | AD9: 6622261540 | AE9: 4 | AF9: ENTREGA DIRECTA | AG9: 1.462 | AH9: M3 | AI9: X | AJ9: 4 | AK9: V4 | AL9: 20230920 | AM9: D836-900006824-65003945-10192944-4
A10: 900006542D8366624059610000651 | B10: 4600047341-410 | C10: 4600047341 | D10: 410 | E10: MXPO | F10: MXL | G10: 900006542 | H10: TP-OLIELL TORTON | I10: 5048484 | J10: COMERCIALIZADORA Y TRANSPORTADORA O | K10: N90 | L10: (AP) NAFIN 90 Dias | M10: 10000651 | N10: Arena Triturada Andesita Malla 8 | O10: D836 | P10: MX-CED. CENTRO | Q10: 20200615 | R10: 20281231 | S10: 20210205 | T10: 20291231 | U10: 210 | V10: MXN | W10: M3 | X10: 135 | Y10: MXN | Z10: M3 | AA10: 66240596 | AB10: DISTRIBUIDOR MATERIALES TRONCOSO | AC10: 56103638 | AD10: 6622261540 | AE10: 4 | AF10: ENTREGA DIRECTA | AG10: 1.35 | AH10: M3 | AI10: X | AJ10: 4 | AK10: V4 | AL10: 20230920 | AM10: D836-900006542-66240596-10000651-4
A11: 900006542D8366688514410187953 | B11: 4600047341-170 | C11: 4600047341 | D11: 170 | E11: MXPO | F11: MXL | G11: 900006542 | H11: TP-OLIELL TORTON | I11: 5048484 | J11: COMERCIALIZADORA Y TRANSPORTADORA O | K11: N90 | L11: (AP) NAFIN 90 Dias | M11: 10187953 | N11: TEZONTLE 10" A FINOS - NG | O11: D836 | P11: MX-CED. CENTRO | Q11: 20200615 | R11: 20281231 | S11: 20200814 | T11: 20301231 | U11: 290 | V11: MXN | W11: M3 | X11: 230 | Y11: MXN | Z11: M3 | AA11: 66885144 | AB11: LA VICTORIA | AC11: 56103637 | AD11: 6622261540 | AE11: 4 | AF11: ENTREGA DIRECTA | AG11: 1.39 | AH11: M3 | AI11: X | AJ11: 4 | AK11: V4 | AL11: 20230920 | AM11: D836-900006542-66885144-10187953-4
A12: 900004077D8366683832610192909 | B12: 4600047844-430 | C12: 4600047844 | D12: 430 | E12: MXPO | F12: MXL | G12: 900004077 | H12: TP-SAN JUAN (HUDASA) | I12: 5054686 | J12: GRUPO MERCANTIL HUDASA SA DE CV | K12: Z06 | L12: (AP) 45 Dias | M12: 10192909 | N12: GRAVA TRITURADA ANDESITA 10 MM - 3/8" HD | O12: D836 | P12: MX-CED. CENTRO | Q12: 20200825 | R12: 20301231 | S12: 20220422 | T12: 20271231 | U12: 292.35 | V12: MXN | W12: TN | X12: 190 | Y12: MXN | Z12: TN | AA12: 66838326 | AB12: OBRA FORD | AC12: 56103637 | AD12: 6622261540 | AE12: 4 | AF12: ENTREGA DIRECTA | AG12: 1 | AH12: TO | AI12: X | AJ12: 4 | AK12: V4 | AL12: 20230920 | AM12: D836-900004077-66838326-10192909-4
A13: 900003592D83610000623 | B13: 4600056899-40 | C13: 4600056899 | D13: 40 | E13: MXPO | F13: MXL | G13: 900003592 | H13: TP-CAL DE APASCO | I13: 5002762 | J13: CAL DE APASCO SA | K13: N60 | L13: (AP) NAFIN 60 Dias | M13: 10000623 | N13: Grava Triturada Caliza 10 mm - 3/8" | O13: D836 | P13: MX-CED. CENTRO | Q13: 20230208 | R13: 20281231 | S13: 20250731 | T13: 20301231 | U13: 110 | V13: MXN | W13: TN | X13: 0 | Y13: MXN | Z13: TN | AC13: 56103637 | AD13: 6622261540 | AE13: 1 | AF13: ENTREGADO | AG13: 1 | AH13: TO | AI13: X | AJ13: 4 | AK13: V4 | AL13: 20250804 | AM13: D836-900003592-10000623
A14: 900003592D83610257024 | B14: 4600056899-30 | C14: 4600056899 | D14: 30 | E14: MXPO | F14: MXL | G14: 900003592 | H14: TP-CAL DE APASCO | I14: 5002762 | J14: CAL DE APASCO SA | K14: N60 | L14: (AP) NAFIN 60 Dias | M14: 10257024 | N14: ARENA TRITURADA CALIZA 4 | O14: D836 | P14: MX-CED. CENTRO | Q14: 20230208 | R14: 20281231 | S14: 20250731 | T14: 20301231 | U14: 115 | V14: MXN | W14: TN | X14: 0 | Y14: MXN | Z14: TN | AC14: 56103638 | AD14: 6622261540 | AE14: 1 | AF14: ENTREGADO | AG14: 1 | AH14: TO | AI14: X | AJ14: 4 | AK14: V4 | AL14: 20250804 | AM14: D836-900003592-10257024
A15: 900006824D8366649096010000623 | B15: 4600048689-10 | C15: 4600048689 | D15: 10 | E15: MXPO | F15: MXL | G15: 900006824 | H15: SF TP-ED-SAN JUAN (HUDASA) | I15: 5054686 | J15: GRUPO MERCANTIL HUDASA SA DE CV | K15: N90 | L15: (AP) NAFIN 90 Dias | M15: 10000623 | N15: Grava Triturada Caliza 10 mm - 3/8" | O15: D836 | P15: MX-CED. CENTRO | Q15: 20201217 | R15: 20291231 | S15: 20201217 | T15: 20291231 | U15: 240 | V15: MXN | W15: M3 | X15: 130 | Y15: MXN | Z15: M3 | AA15: 66490960 | AB15: OBR-AGR ARMACONCRETO HUEHUETOCA | AC15: 56103637 | AD15: 6622261540 | AE15: 4 | AF15: ENTREGA DIRECTA | AG15: 1.41 | AH15: M3 | AI15: X | AJ15: 4 | AK15: V4 | AL15: 20230920 | AM15: D836-900006824-66490960-10000623-4
A16: 900003786D8366656665210000635 | B16: 4600034392-70 | C16: 4600034392 | D16: 70 | E16: MXPO | F16: MXL | G16: 900003786 | H16: TP-TRIMCAV | I16: 5010147 | J16: TRITURACIONES DE MARMOL Y CALCIOS | K16: Z04 | L16: (AP) 30 Dias | M16: 10000635 | N16: Arena Triturada Marmol Malla 4 | O16: D836 | P16: MX-CED. CENTRO | Q16: 20160627 | R16: 20241231 | S16: 20180830 | T16: 20241231 | U16: 731.5 | V16: MXN | W16: TN | X16: 350 | Y16: MXN | Z16: TN | AA16: 66566652 | AB16: EDUARDO MOLINA #113 (OMC) | AC16: 56103638 | AD16: 6622261540 | AE16: 4 | AF16: ENTREGA DIRECTA | AG16: 1 | AH16: TO | AI16: X | AJ16: 4 | AK16: V4 | AL16: 20230920 | AM16: D836-900003786-66566652-10000635-4
A17: 900006542D8366691209010000206 | B17: 4600047341-240 | C17: 4600047341 | D17: 240 | E17: MXPO | F17: MXL | G17: 900006542 | H17: TP-OLIELL TORTON | I17: 5048484 | J17: COMERCIALIZADORA Y TRANSPORTADORA O | K17: N90 | L17: (AP) NAFIN 90 Dias | M17: 10000206 | N17: Tepetate Triturado Tierra NA | O17: D836 | P17: MX-CED. CENTRO | Q17: 20200615 | R17: 20281231 | S17: 20201030 | T17: 20291231 | U17: 125 | V17: MXN | W17: M3 | X17: 95 | Y17: MXN | Z17: M3 | AA17: 66912090 | AB17: PATIO TLALPIZAHUAC CHALCO | AC17: 56103695 | AD17: 6622261540 | AE17: 4 | AF17: ENTREGA DIRECTA | AG17: 1.249 | AH17: M3 | AI17: X | AJ17: 4 | AK17: V4 | AL17: 20230920 | AM17: D836-900006542-66912090-10000206-4
A18: 900006824D8366500394510192943 | B18: 4600048689-40 | C18: 4600048689 | D18: 40 | E18: MXPO | F18: MXL | G18: 900006824 | H18: SF TP-ED-SAN JUAN (HUDASA) | I18: 5054686 | J18: GRUPO MERCANTIL HUDASA SA DE CV | K18: N90 | L18: (AP) NAFIN 90 Dias | M18: 10192943 | N18: GRAVA TRITURADA CALIZA 40 MM - 1 1/2" HD | O18: D836 | P18: MX-CED. CENTRO | Q18: 20201217 | R18: 20291231 | S18: 20220307 | T18: 20271231 | U18: 489.5 | V18: MXN | W18: M3 | X18: 350 | Y18: MXN | Z18: M3 | AA18: 65003945 | AB18: (P) OBR-AGR PREMEZCLADOS (RRL) | AC18: 56103637 | AD18: 6622261540 | AE18: 4 | AF18: ENTREGA DIRECTA | AG18: 1.478 | AH18: M3 | AI18: X | AJ18: 4 | AK18: V4 | AL18: 20230920 | AM18: D836-900006824-65003945-10192943-4
A19: 900006542D8366624059610000160 | B19: 4600047341-390 | C19: 4600047341 | D19: 390 | E19: MXPO | F19: MXL | G19: 900006542 | H19: TP-OLIELL TORTON | I19: 5048484 | J19: COMERCIALIZADORA Y TRANSPORTADORA O | K19: N90 | L19: (AP) NAFIN 90 Dias | M19: 10000160 | N19: Arena Triturada Andesita Malla 4 | O19: D836 | P19: MX-CED. CENTRO | Q19: 20200615 | R19: 20281231 | S19: 20210205 | T19: 20291231 | U19: 235 | V19: MXN | W19: M3 | X19: 135 | Y19: MXN | Z19: M3 | AA19: 66240596 | AB19: DISTRIBUIDOR MATERIALES TRONCOSO | AC19: 56103638 | AD19: 6622261540 | AE19: 4 | AF19: ENTREGA DIRECTA | AG19: 1.409 | AH19: M3 | AI19: X | AJ19: 4 | AK19: V4 | AL19: 20230920 | AM19: D836-900006542-66240596-10000160-4
A20: 900006542D8366624059610000357 | B20: 4600047341-400 | C20: 4600047341 | D20: 400 | E20: MXPO | F20: MXL | G20: 900006542 | H20: TP-OLIELL TORTON | I20: 5048484 | J20: COMERCIALIZADORA Y TRANSPORTADORA O | K20: N90 | L20: (AP) NAFIN 90 Dias | M20: 10000357 | N20: Grava Triturada Andesita 20 mm - 3/4" | O20: D836 | P20: MX-CED. CENTRO | Q20: 20200615 | R20: 20281231 | S20: 20210205 | T20: 20291231 | U20: 245 | V20: MXN | W20: M3 | X20: 135 | Y20: MXN | Z20: M3 | AA20: 66240596 | AB20: DISTRIBUIDOR MATERIALES TRONCOSO | AC20: 56103637 | AD20: 6622261540 | AE20: 4 | AF20: ENTREGA DIRECTA | AG20: 1.326 | AH20: M3 | AI20: X | AJ20: 4 | AK20: V4 | AL20: 20230920 | AM20: D836-900006542-66240596-10000357-4
A21: 900004365D8366701980210000287 | B21: 4600053008-10 | C21: 4600053008 | D21: 10 | E21: MXPO | F21: MXL | G21: 900004365 | H21: TP-ED-DOS CERROS | I21: 5036168 | J21: TRITURADOS DOS CERROS SA DE CV | K21: Z04 | L21: (AP) 30 Dias | M21: 10000287 | N21: Grava Triturada Basalto 40 mm - 1 1/2" | O21: D836 | P21: MX-CED. CENTRO | Q21: 20220128 | R21: 20281231 | S21: 20220128 | T21: 20271231 | U21: 985.71 | V21: MXN | W21: M3 | X21: 500 | Y21: MXN | Z21: M3 | AA21: 67019802 | AB21: H colegio Militar E.2 | AC21: 56103637 | AD21: 6622261540 | AE21: 4 | AF21: ENTREGA DIRECTA | AG21: 1.44 | AH21: M3 | AI21: X | AJ21: 4 | AK21: V4 | AL21: 20230920 | AM21: D836-900004365-67019802-10000287-4
A22: 900006371D8366709100410019515 | B22: 4600048255-220 | C22: 4600048255 | D22: 220 | E22: MXPO | F22: MXL | G22: 900006371 | H22: SF TP-ED-TRIVOMEX | I22: 5033501 | J22: TRITURADOS VOLCANICOS DE MEXICO | K22: Z04 | L22: (AP) 30 Dias | M22: 10019515 | N22: Grava Triturada Tezontle 20mm - 3/4" | O22: D836 | P22: MX-CED. CENTRO | Q22: 20201015 | R22: 20291231 | S22: 20221109 | T22: 20271231 | U22: 255 | V22: MXN | W22: M3 | X22: 160 | Y22: MXN | Z22: M3 | AA22: 67091004 | AB22: PARQUE NACIONAL DE JUSTICIA (FISCAL | AC22: 56103637 | AD22: 6622261540 | AE22: 4 | AF22: ENTREGA DIRECTA | AG22: 1.3 | AH22: M3 | AI22: X | AJ22: 4 | AK22: V4 | AL22: 20230920 | AM22: D836-900006371-67091004-10019515-4
A23: 900004323D8366544038410000160 | B23: 4600039874-130 | C23: 4600039874 | D23: 130 | E23: MXPO | F23: MXL | G23: 900004323 | H23: TP-LAS TRANCAS | I23: 5047262 | J23: AGREGADOS PETREOS SAN CRISTOBAL | K23: Z03 | L23: (AP) 15 Dias | M23: 10000160 | N23: Arena Triturada Andesita Malla 4 | O23: D836 | P23: MX-CED. CENTRO | Q23: 20170927 | R23: 20281231 | S23: 20190822 | T23: 20241231 | U23: 176.5 | V23: MXN | W23: M3 | X23: 95 | Y23: MXN | Z23: M3 | AA23: 65440384 | AB23: INDUSTRIAL BLOQUERA MEXICANA SA DE | AC23: 56103638 | AD23: 6622261540 | AE23: 4 | AF23: ENTREGA DIRECTA | AG23: 1.409 | AH23: M3 | AI23: X | AJ23: 4 | AK23: V4 | AL23: 20230920 | AM23: D836-900004323-65440384-10000160-4
A24: 900006542D8366683856110000160 | B24: 4600047341-320 | C24: 4600047341 | D24: 320 | E24: MXPO | F24: MXL | G24: 900006542 | H24: TP-OLIELL TORTON | I24: 5048484 | J24: COMERCIALIZADORA Y TRANSPORTADORA O | K24: N90 | L24: (AP) NAFIN 90 Dias | M24: 10000160 | N24: Arena Triturada Andesita Malla 4 | O24: D836 | P24: MX-CED. CENTRO | Q24: 20200615 | R24: 20281231 | S24: 20201030 | T24: 20291231 | U24: 195 | V24: MXN | W24: M3 | X24: 95 | Y24: MXN | Z24: M3 | AA24: 66838561 | AB24: REMODELACION DE PATIO TLALPIZAHUAC | AC24: 56103638 | AD24: 6622261540 | AE24: 4 | AF24: ENTREGA DIRECTA | AG24: 1.409 | AH24: M3 | AI24: X | AJ24: 4 | AK24: V4 | AL24: 20230920 | AM24: D836-900006542-66838561-10000160-4
A25: 900007321D8366698265810216851 | B25: 4600052061-70 | C25: 4600052061 | D25: 70 | E25: MXPO | F25: MXL | G25: 900007321 | H25: SF TP-ED-LOMA ANCHA SC | I25: 5047262 | J25: AGREGADOS PETREOS SAN CRISTOBAL | K25: Z03 | L25: (AP) 15 Dias | M25: 10216851 | N25: BASE HIDRAÚLICA - TEPETATE NG | O25: D836 | P25: MX-CED. CENTRO | Q25: 20210928 | R25: 20291231 | S25: 20220527 | T25: 20271231 | U25: 150 | V25: MXN | W25: M3 | X25: 135 | Y25: MXN | Z25: M3 | AA25: 66982658 | AB25: I. ALJUCA ETAPA 2 (HTVM) | AC25: 56103590 | AD25: 6622261540 | AE25: 4 | AF25: ENTREGA DIRECTA | AG25: 1.249 | AH25: M3 | AI25: X | AJ25: 4 | AK25: V4 | AL25: 20230920 | AM25: D836-900007321-66982658-10216851-4
A26: 900006542D8366688696910000357 | B26: 4600047341-110 | C26: 4600047341 | D26: 110 | E26: MXPO | F26: MXL | G26: 900006542 | H26: TP-OLIELL TORTON | I26: 5048484 | J26: COMERCIALIZADORA Y TRANSPORTADORA O | K26: N90 | L26: (AP) NAFIN 90 Dias | M26: 10000357 | N26: Grava Triturada Andesita 20 mm - 3/4" | O26: D836 | P26: MX-CED. CENTRO | Q26: 20200615 | R26: 20281231 | S26: 20200729 | T26: 20301231 | U26: 300 | V26: MXN | W26: M3 | X26: 190 | Y26: MXN | Z26: M3 | AA26: 66886969 | AB26: HELM | AC26: 56103637 | AD26: 6622261540 | AE26: 4 | AF26: ENTREGA DIRECTA | AG26: 1.326 | AH26: M3 | AI26: X | AJ26: 4 | AK26: V4 | AL26: 20230920 | AM26: D836-900006542-66886969-10000357-4
... A37: 900004077D8366687461610192909 | B37: 4600047844-670 | C37: 4600047844 | D37: 670 | E37: MXPO | F37: MXL | G37: 900004077 | H37: TP-SAN JUAN (HUDASA) | I37: 5054686 | J37: GRUPO MERCANTIL HUDASA SA DE CV | K37: Z06 | L37: (AP) 45 Dias | M37: 10192909 | N37: GRAVA TRITURADA ANDESITA 10 MM - 3/8" HD | O37: D836 | P37: MX-CED. CENTRO | Q37: 20200825 | R37: 20301231 | S37: 20220422 | T37: 20271231 | U37: 292.35 | V37: MXN | W37: TN | X37: 190 | Y37: MXN | Z37: TN | AA37: 66874616 | AB37: FORD LOMAS VERDES | AC37: 56103637 | AD37: 6622261540 | AE37: 4 | AF37: ENTREGA DIRECTA | AG37: 1 | AH37: TO | AI37: X | AJ37: 4 | AK37: V4 | AL37: 20230920 | AM37: D836-900004077-66874616-10192909-4
A38: 900003592D83610000133 | B38: 4600056899-10 | C38: 4600056899 | D38: 10 | E38: MXPO | F38: MXL | G38: 900003592 | H38: TP-CAL DE APASCO | I38: 5002762 | J38: CAL DE APASCO SA | K38: N60 | L38: (AP) NAFIN 60 Dias | M38: 10000133 | N38: Grava Triturada Caliza 20 mm - 3/4" | O38: D836 | P38: MX-CED. CENTRO | Q38: 20230208 | R38: 20281231 | S38: 20250731 | T38: 20301231 | U38: 100 | V38: MXN | W38: TN | X38: 0 | Y38: MXN | Z38: TN | AC38: 56103637 | AD38: 6622261540 | AE38: 1 | AF38: ENTREGADO | AG38: 1 | AH38: TO | AI38: X | AJ38: 4 | AK38: V4 | AL38: 20250804 | AM38: D836-900003592-10000133
A39: 900006542D8366685220610000357 | B39: 4600047341-380 | C39: 4600047341 | D39: 380 | E39: MXPO | F39: MXL | G39: 900006542 | H39: TP-OLIELL TORTON | I39: 5048484 | J39: COMERCIALIZADORA Y TRANSPORTADORA O | K39: N90 | L39: (AP) NAFIN 90 Dias | M39: 10000357 | N39: Grava Triturada Andesita 20 mm - 3/4" | O39: D836 | P39: MX-CED. CENTRO | Q39: 20200615 | R39: 20281231 | S39: 20210120 | T39: 20291231 | U39: 270 | V39: MXN | W39: M3 | X39: 160 | Y39: MXN | Z39: M3 | AA39: 66852206 | AB39: VT01802 CPI DR. VERTIZ | AC39: 56103637 | AD39: 6622261540 | AE39: 4 | AF39: ENTREGA DIRECTA | AG39: 1.326 | AH39: M3 | AI39: X | AJ39: 4 | AK39: V4 | AL39: 20230920 | AM39: D836-900006542-66852206-10000357-4
A40: 900004365D8366698265810215930 | B40: 4600053008-30 | C40: 4600053008 | D40: 30 | E40: MXPO | F40: MXL | G40: 900004365 | H40: TP-ED-DOS CERROS | I40: 5036168 | J40: TRITURADOS DOS CERROS SA DE CV | K40: Z04 | L40: (AP) 30 Dias | M40: 10215930 | N40: BASE HIDRAÚLICA NG | O40: D836 | P40: MX-CED. CENTRO | Q40: 20220128 | R40: 20281231 | S40: 20220525 | T40: 20271231 | U40: 150 | V40: MXN | W40: M3 | X40: 135 | Y40: MXN | Z40: M3 | AA40: 66982658 | AB40: I. ALJUCA ETAPA 2 (HTVM) | AC40: 56103590 | AD40: 6622261540 | AE40: 4 | AF40: ENTREGA DIRECTA | AG40: 1.249 | AH40: M3 | AI40: X | AJ40: 4 | AK40: V4 | AL40: 20230920 | AM40: D836-900004365-66982658-10215930-4
A41: 900003609D83610147486 | B41: 4600027606-210 | C41: 4600027606 | D41: 210 | E41: MXPO | F41: M02 | G41: 900003609 | H41: TP-LA VALENCIANA | I41: 5005431 | J41: CANTERAS LA VALENCIANA SA DE CV | K41: Z03 | L41: (AP) 15 Dias | M41: 10147486 | N41: BALASTO TRITURADO | O41: D836 | P41: MX-CED. CENTRO | Q41: 20141106 | R41: 20281231 | S41: 20250613 | T41: 20301231 | U41: 154.24 | V41: MXN | W41: M3 | X41: 0 | Y41: MXN | Z41: M3 | AC41: 56103591 | AD41: 6622261540 | AE41: 1 | AF41: ENTREGADO | AG41: 1.56 | AH41: M3 | AI41: X | AJ41: 4 | AK41: V4 | AL41: 20250618 | AM41: D836-900003609-10147486
A42: 900006542D8366685220610000160 | B42: 4600047341-370 | C42: 4600047341 | D42: 370 | E42: MXPO | F42: MXL | G42: 900006542 | H42: TP-OLIELL TORTON | I42: 5048484 | J42: COMERCIALIZADORA Y TRANSPORTADORA O | K42: N90 | L42: (AP) NAFIN 90 Dias | M42: 10000160 | N42: Arena Triturada Andesita Malla 4 | O42: D836 | P42: MX-CED. CENTRO | Q42: 20200615 | R42: 20281231 | S42: 20210120 | T42: 20291231 | U42: 260 | V42: MXN | W42: M3 | X42: 160 | Y42: MXN | Z42: M3 | AA42: 66852206 | AB42: VT01802 CPI DR. VERTIZ | AC42: 56103638 | AD42: 6622261540 | AE42: 4 | AF42: ENTREGA DIRECTA | AG42: 1.409 | AH42: M3 | AI42: X | AJ42: 4 | AK42: V4 | AL42: 20230920 | AM42: D836-900006542-66852206-10000160-4
A43: 900006542D8366688514410175723 | B43: 4600047341-160 | C43: 4600047341 | D43: 160 | E43: MXPO | F43: MXL | G43: 900006542 | H43: TP-OLIELL TORTON | I43: 5048484 | J43: COMERCIALIZADORA Y TRANSPORTADORA O | K43: N90 | L43: (AP) NAFIN 90 Dias | M43: 10175723 | N43: BASE HIDRAULICA ANDESITA DE 1 1/2" A FIN | O43: D836 | P43: MX-CED. CENTRO | Q43: 20200615 | R43: 20281231 | S43: 20200813 | T43: 20301231 | U43: 310 | V43: MXN | W43: M3 | X43: 190 | Y43: MXN | Z43: M3 | AA43: 66885144 | AB43: LA VICTORIA | AC43: 56103590 | AD43: 6622261540 | AE43: 4 | AF43: ENTREGA DIRECTA | AG43: 1.65 | AH43: M3 | AI43: X | AJ43: 4 | AK43: V4 | AL43: 20230920 | AM43: D836-900006542-66885144-10175723-4
A44: 900004077D8366687461610192940 | B44: 4600047844-620 | C44: 4600047844 | D44: 620 | E44: MXPO | F44: MXL | G44: 900004077 | H44: TP-SAN JUAN (HUDASA) | I44: 5054686 | J44: GRUPO MERCANTIL HUDASA SA DE CV | K44: Z06 | L44: (AP) 45 Dias | M44: 10192940 | N44: GRAVA TRITURADA ANDESITA 20 MM - 3/4" HD | O44: D836 | P44: MX-CED. CENTRO | Q44: 20200825 | R44: 20301231 | S44: 20220420 | T44: 20271231 | U44: 283.3 | V44: MXN | W44: TN | X44: 190 | Y44: MXN | Z44: TN | AA44: 66874616 | AB44: FORD LOMAS VERDES | AC44: 56103637 | AD44: 6622261540 | AE44: 4 | AF44: ENTREGA DIRECTA | AG44: 1 | AH44: TO | AI44: X | AJ44: 4 | AK44: V4 | AL44: 20230920 | AM44: D836-900004077-66874616-10192940-4
A45: 900006185D8366683068310000160 | B45: 4600045002-110 | C45: 4600045002 | D45: 110 | E45: MXPO | F45: MXL | G45: 900006185 | H45: TP-ED-OLIELL ALMACÉN | I45: 5048484 | J45: COMERCIALIZADORA Y TRANSPORTADORA O | K45: Z00 | L45: (AP) Pagadero Inmediatamente | M45: 10000160 | N45: Arena Triturada Andesita Malla 4 | O45: D836 | P45: MX-CED. CENTRO | Q45: 20190628 | R45: 20281231 | S45: 20200325 | T45: 20291231 | U45: 862 | V45: MXN | W45: TN | X45: 431 | Y45: MXN | Z45: TN | AA45: 66830683 | AB45: MITLA 240 (LRR) | AC45: 56103638 | AD45: 6622261540 | AE45: 4 | AF45: ENTREGA DIRECTA | AG45: 1 | AH45: TO | AI45: X | AJ45: 4 | AK45: V4 | AL45: 20230920 | AM45: D836-900006185-66830683-10000160-4
A46: 900006185D8366685220610000357 | B46: 4600045002-180 | C46: 4600045002 | D46: 180 | E46: MXPO | F46: MXL | G46: 900006185 | H46: TP-ED-OLIELL ALMACÉN | I46: 5048484 | J46: COMERCIALIZADORA Y TRANSPORTADORA O | K46: Z00 | L46: (AP) Pagadero Inmediatamente | M46: 10000357 | N46: Grava Triturada Andesita 20 mm - 3/4" | O46: D836 | P46: MX-CED. CENTRO | Q46: 20190628 | R46: 20281231 | S46: 20200401 | T46: 20291231 | U46: 862 | V46: MXN | W46: M3 | X46: 431 | Y46: MXN | Z46: M3 | AA46: 66852206 | AB46: VT01802 CPI DR. VERTIZ | AC46: 56103637 | AD46: 6622261540 | AE46: 4 | AF46: ENTREGA DIRECTA | AG46: 1.326 | AH46: M3 | AI46: X | AJ46: 4 | AK46: V4 | AL46: 20230920 | AM46: D836-900006185-66852206-10000357-4
A47: 900006185D8366685220610000160 | B47: 4600045002-170 | C47: 4600045002 | D47: 170 | E47: MXPO | F47: MXL | G47: 900006185 | H47: TP-ED-OLIELL ALMACÉN | I47: 5048484 | J47: COMERCIALIZADORA Y TRANSPORTADORA O | K47: Z00 | L47: (AP) Pagadero Inmediatamente | M47: 10000160 | N47: Arena Triturada Andesita Malla 4 | O47: D836 | P47: MX-CED. CENTRO | Q47: 20190628 | R47: 20281231 | S47: 20200401 | T47: 20291231 | U47: 862 | V47: MXN | W47: M3 | X47: 431 | Y47: MXN | Z47: M3 | AA47: 66852206 | AB47: VT01802 CPI DR. VERTIZ | AC47: 56103638 | AD47: 6622261540 | AE47: 4 | AF47: ENTREGA DIRECTA | AG47: 1.409 | AH47: M3 | AI47: X | AJ47: 4 | AK47: V4 | AL47: 20230920 | AM47: D836-900006185-66852206-10000160-4
A48: 900006185D8366699032210000651 | B48: 4600045002-340 | C48: 4600045002 | D48: 340 | E48: MXPO | F48: MXL | G48: 900006185 | H48: TP-ED-OLIELL ALMACÉN | I48: 5048484 | J48: COMERCIALIZADORA Y TRANSPORTADORA O | K48: Z00 | L48: (AP) Pagadero Inmediatamente | M48: 10000651 | N48: Arena Triturada Andesita Malla 8 | O48: D836 | P48: MX-CED. CENTRO | Q48: 20190628 | R48: 20281231 | S48: 20210721 | T48: 20261231 | U48: 1470 | V48: MXN | W48: M3 | X48: 220 | Y48: MXN | Z48: M3 | AA48: 66990322 | AB48: Londres 208 | AC48: 56103638 | AD48: 6622261540 | AE48: 4 | AF48: ENTREGA DIRECTA | AG48: 1.35 | AH48: M3 | AI48: X | AJ48: 4 | AK48: V4 | AL48: 20230920 | AM48: D836-900006185-66990322-10000651-4
A49: 900006185D8366683068310000357 | B49: 4600045002-120 | C49: 4600045002 | D49: 120 | E49: MXPO | F49: MXL | G49: 900006185 | H49: TP-ED-OLIELL ALMACÉN | I49: 5048484 | J49: COMERCIALIZADORA Y TRANSPORTADORA O | K49: Z00 | L49: (AP) Pagadero Inmediatamente | M49: 10000357 | N49: Grava Triturada Andesita 20 mm - 3/4" | O49: D836 | P49: MX-CED. CENTRO | Q49: 20190628 | R49: 20281231 | S49: 20200325 | T49: 20291231 | U49: 862 | V49: MXN | W49: TN | X49: 431 | Y49: MXN | Z49: TN | AA49: 66830683 | AB49: MITLA 240 (LRR) | AC49: 56103637 | AD49: 6622261540 | AE49: 4 | AF49: ENTREGA DIRECTA | AG49: 1 | AH49: TO | AI49: X | AJ49: 4 | AK49: V4 | AL49: 20230920 | AM49: D836-900006185-66830683-10000357-4
A50: 900006185D8366684714410000357 | B50: 4600045002-140 | C50: 4600045002 | D50: 140 | E50: MXPO | F50: MXL | G50: 900006185 | H50: TP-ED-OLIELL ALMACÉN | I50: 5048484 | J50: COMERCIALIZADORA Y TRANSPORTADORA O | K50: Z00 | L50: (AP) Pagadero Inmediatamente | M50: 10000357 | N50: Grava Triturada Andesita 20 mm - 3/4" | O50: D836 | P50: MX-CED. CENTRO | Q50: 20190628 | R50: 20281231 | S50: 20200325 | T50: 20291231 | U50: 862 | V50: MXN | W50: TN | X50: 431 | Y50: MXN | Z50: TN | AA50: 66847144 | AB50: VERTIZ 1301 (LRR) | AC50: 56103637 | AD50: 6622261540 | AE50: 4 | AF50: ENTREGA DIRECTA | AG50: 1.326 | AH50: M3 | AI50: X | AJ50: 4 | AK50: V4 | AL50: 20230920 | AM50: D836-900006185-66847144-10000357-4
...
