Workbook

Sheet Base Cedis D860
N1: VENTA | Q1: COSTO
A2: CONCAT1 | B2: CONCAT2 | C2: No. SF | D2: Nombre SF | E2: Cedis | F2: Destino | G2: Condicion de Expedicion | H2: Nombre Destino | I2: No. de material | J2: Nombre de material | K2: PV | L2: Inicio de vigencia | M2: Fin de vigencia | N2: Importe MP | O2: Importe Flete | P2: UM Venta | Q2: Importe Costo | R2: UM Costo | S2: Validacion 1 | T2: Validacion 2
A3: =CONCATENATE(C3,E3,F3,I3) | B3: =CONCATENATE(C3,E3,I3) | C3: 900007612 | D3: =IFERROR(VLOOKUP(C3,TRAOPE!$G:$H,2,0),"") | E3: D860 | F3: 66958065 | G3: =IFERROR(VLOOKUP(A3,Flete!$A:$E,5,0),"") | H3: =IFERROR(VLOOKUP(F3,TRAOPE!$AA:$AB,2,0),"") | I3: 10052402 | J3: =IFERROR(VLOOKUP(I3,Materiales!$A:$H,8,0),"") | K3: =IFERROR(VLOOKUP(I3,Materiales!$A:$G,7,0),"") | L3: 20240403 | M3: 20240529 | N3: 141.9 | O3: =IFERROR(VLOOKUP(A3,Flete!$A:$J,10,0),"") | P3: M3 | Q3: =IFERROR(IFERROR(VLOOKUP(A3,TRAOPE!$A:$U,21,0),VLOOKUP(B3,TRAOPE!$A:$U,21,0)),"") | R3: =IFERROR(IFERROR(VLOOKUP(A3,TRAOPE!$A:$W,23,0),VLOOKUP(B3,TRAOPE!$A:$W,23,0)),"") | S3: =IF(AND(P3="TN",R3="TN"),N3+N(O3),IF(G3&""="1",N(K3)*N3,(N3+N(O3))*N(K3))) | T3: =IF(Q3="","",Q3-S3)
A4: =CONCATENATE(C4,E4,F4,I4) | B4: =CONCATENATE(C4,E4,I4) | C4: 900007612 | D4: =IFERROR(VLOOKUP(C4,TRAOPE!$G:$H,2,0),"") | E4: D860 | F4: 66958065 | G4: =IFERROR(VLOOKUP(A4,Flete!$A:$E,5,0),"") | H4: =IFERROR(VLOOKUP(F4,TRAOPE!$AA:$AB,2,0),"") | I4: 10052405 | J4: =IFERROR(VLOOKUP(I4,Materiales!$A:$H,8,0),"") | K4: =IFERROR(VLOOKUP(I4,Materiales!$A:$G,7,0),"") | L4: 20240403 | M4: 20240529 | N4: 141.9 | O4: =IFERROR(VLOOKUP(A4,Flete!$A:$J,10,0),"") | P4: M3 | Q4: =IFERROR(IFERROR(VLOOKUP(A4,TRAOPE!$A:$U,21,0),VLOOKUP(B4,TRAOPE!$A:$U,21,0)),"") | R4: =IFERROR(IFERROR(VLOOKUP(A4,TRAOPE!$A:$W,23,0),VLOOKUP(B4,TRAOPE!$A:$W,23,0)),"") | S4: =IF(AND(P4="TN",R4="TN"),N4+N(O4),IF(G4&""="1",N(K4)*N4,(N4+N(O4))*N(K4))) | T4: =IF(Q4="","",Q4-S4)
A5: =CONCATENATE(C5,E5,F5,I5) | B5: =CONCATENATE(C5,E5,I5) | C5: 900007611 | D5: =IFERROR(VLOOKUP(C5,TRAOPE!$G:$H,2,0),"") | E5: D860 | F5: 67064029 | G5: =IFERROR(VLOOKUP(A5,Flete!$A:$E,5,0),"") | H5: =IFERROR(VLOOKUP(F5,TRAOPE!$AA:$AB,2,0),"") | I5: 10052404 | J5: =IFERROR(VLOOKUP(I5,Materiales!$A:$H,8,0),"") | K5: =IFERROR(VLOOKUP(I5,Materiales!$A:$G,7,0),"") | L5: 20240605 | M5: 20250825 | N5: 144 | O5: =IFERROR(VLOOKUP(A5,Flete!$A:$J,10,0),"") | P5: M3 | Q5: =IFERROR(IFERROR(VLOOKUP(A5,TRAOPE!$A:$U,21,0),VLOOKUP(B5,TRAOPE!$A:$U,21,0)),"") | R5: =IFERROR(IFERROR(VLOOKUP(A5,TRAOPE!$A:$W,23,0),VLOOKUP(B5,TRAOPE!$A:$W,23,0)),"") | S5: =IF(AND(P5="TN",R5="TN"),N5+N(O5),IF(G5&""="1",N(K5)*N5,(N5+N(O5))*N(K5))) | T5: =IF(Q5="","",Q5-S5)
A6: =CONCATENATE(C6,E6,F6,I6) | B6: =CONCATENATE(C6,E6,I6) | C6: 900003456 | D6: =IFERROR(VLOOKUP(C6,TRAOPE!$G:$H,2,0),"") | E6: D860 | F6: 66830361 | G6: =IFERROR(VLOOKUP(A6,Flete!$A:$E,5,0),"") | H6: =IFERROR(VLOOKUP(F6,TRAOPE!$AA:$AB,2,0),"") | I6: 10052407 | J6: =IFERROR(VLOOKUP(I6,Materiales!$A:$H,8,0),"") | K6: =IFERROR(VLOOKUP(I6,Materiales!$A:$G,7,0),"") | L6: 20221109 | M6: 20251031 | N6: 90 | O6: =IFERROR(VLOOKUP(A6,Flete!$A:$J,10,0),"") | P6: M3 | Q6: =IFERROR(IFERROR(VLOOKUP(A6,TRAOPE!$A:$U,21,0),VLOOKUP(B6,TRAOPE!$A:$U,21,0)),"") | R6: =IFERROR(IFERROR(VLOOKUP(A6,TRAOPE!$A:$W,23,0),VLOOKUP(B6,TRAOPE!$A:$W,23,0)),"") | S6: =IF(AND(P6="TN",R6="TN"),N6+N(O6),IF(G6&""="1",N(K6)*N6,(N6+N(O6))*N(K6))) | T6: =IF(Q6="","",Q6-S6)
A7: =CONCATENATE(C7,E7,F7,I7) | B7: =CONCATENATE(C7,E7,I7) | C7: 900003456 | D7: =IFERROR(VLOOKUP(C7,TRAOPE!$G:$H,2,0),"") | E7: D860 | F7: 66830361 | G7: =IFERROR(VLOOKUP(A7,Flete!$A:$E,5,0),"") | H7: =IFERROR(VLOOKUP(F7,TRAOPE!$AA:$AB,2,0),"") | I7: 10190637 | J7: =IFERROR(VLOOKUP(I7,Materiales!$A:$H,8,0),"") | K7: =IFERROR(VLOOKUP(I7,Materiales!$A:$G,7,0),"") | L7: 20221109 | M7: 20251031 | N7: 100 | O7: =IFERROR(VLOOKUP(A7,Flete!$A:$J,10,0),"") | P7: M3 | Q7: =IFERROR(IFERROR(VLOOKUP(A7,TRAOPE!$A:$U,21,0),VLOOKUP(B7,TRAOPE!$A:$U,21,0)),"") | R7: =IFERROR(IFERROR(VLOOKUP(A7,TRAOPE!$A:$W,23,0),VLOOKUP(B7,TRAOPE!$A:$W,23,0)),"") | S7: =IF(AND(P7="TN",R7="TN"),N7+N(O7),IF(G7&""="1",N(K7)*N7,(N7+N(O7))*N(K7))) | T7: =IF(Q7="","",Q7-S7)
A8: =CONCATENATE(C8,E8,F8,I8) | B8: =CONCATENATE(C8,E8,I8) | C8: 900005375 | D8: =IFERROR(VLOOKUP(C8,TRAOPE!$G:$H,2,0),"") | E8: D860 | F8: 65094171 | G8: =IFERROR(VLOOKUP(A8,Flete!$A:$E,5,0),"") | H8: =IFERROR(VLOOKUP(F8,TRAOPE!$AA:$AB,2,0),"") | I8: 10000176 | J8: =IFERROR(VLOOKUP(I8,Materiales!$A:$H,8,0),"") | K8: =IFERROR(VLOOKUP(I8,Materiales!$A:$G,7,0),"") | L8: 20221109 | M8: 20251031 | N8: 131.2 | O8: =IFERROR(VLOOKUP(A8,Flete!$A:$J,10,0),"") | P8: M3 | Q8: =IFERROR(IFERROR(VLOOKUP(A8,TRAOPE!$A:$U,21,0),VLOOKUP(B8,TRAOPE!$A:$U,21,0)),"") | R8: =IFERROR(IFERROR(VLOOKUP(A8,TRAOPE!$A:$W,23,0),VLOOKUP(B8,TRAOPE!$A:$W,23,0)),"") | S8: =IF(AND(P8="TN",R8="TN"),N8+N(O8),IF(G8&""="1",N(K8)*N8,(N8+N(O8))*N(K8))) | T8: =IF(Q8="","",Q8-S8)
A9: =CONCATENATE(C9,E9,F9,I9) | B9: =CONCATENATE(C9,E9,I9) | C9: 900005375 | D9: =IFERROR(VLOOKUP(C9,TRAOPE!$G:$H,2,0),"") | E9: D860 | F9: 65094171 | G9: =IFERROR(VLOOKUP(A9,Flete!$A:$E,5,0),"") | H9: =IFERROR(VLOOKUP(F9,TRAOPE!$AA:$AB,2,0),"") | I9: 10052402 | J9: =IFERROR(VLOOKUP(I9,Materiales!$A:$H,8,0),"") | K9: =IFERROR(VLOOKUP(I9,Materiales!$A:$G,7,0),"") | L9: 20221109 | M9: 20251031 | N9: 199.51 | O9: =IFERROR(VLOOKUP(A9,Flete!$A:$J,10,0),"") | P9: M3 | Q9: =IFERROR(IFERROR(VLOOKUP(A9,TRAOPE!$A:$U,21,0),VLOOKUP(B9,TRAOPE!$A:$U,21,0)),"") | R9: =IFERROR(IFERROR(VLOOKUP(A9,TRAOPE!$A:$W,23,0),VLOOKUP(B9,TRAOPE!$A:$W,23,0)),"") | S9: =IF(AND(P9="TN",R9="TN"),N9+N(O9),IF(G9&""="1",N(K9)*N9,(N9+N(O9))*N(K9))) | T9: =IF(Q9="","",Q9-S9)
A10: =CONCATENATE(C10,E10,F10,I10) | B10: =CONCATENATE(C10,E10,I10) | C10: 900005375 | D10: =IFERROR(VLOOKUP(C10,TRAOPE!$G:$H,2,0),"") | E10: D860 | F10: 65094171 | G10: =IFERROR(VLOOKUP(A10,Flete!$A:$E,5,0),"") | H10: =IFERROR(VLOOKUP(F10,TRAOPE!$AA:$AB,2,0),"") | I10: 10052405 | J10: =IFERROR(VLOOKUP(I10,Materiales!$A:$H,8,0),"") | K10: =IFERROR(VLOOKUP(I10,Materiales!$A:$G,7,0),"") | L10: 20221109 | M10: 20251031 | N10: 131.2 | O10: =IFERROR(VLOOKUP(A10,Flete!$A:$J,10,0),"") | P10: M3 | Q10: =IFERROR(IFERROR(VLOOKUP(A10,TRAOPE!$A:$U,21,0),VLOOKUP(B10,TRAOPE!$A:$U,21,0)),"") | R10: =IFERROR(IFERROR(VLOOKUP(A10,TRAOPE!$A:$W,23,0),VLOOKUP(B10,TRAOPE!$A:$W,23,0)),"") | S10: =IF(AND(P10="TN",R10="TN"),N10+N(O10),IF(G10&""="1",N(K10)*N10,(N10+N(O10))*N(K10))) | T10: =IF(Q10="","",Q10-S10)
A11: =CONCATENATE(C11,E11,F11,I11) | B11: =CONCATENATE(C11,E11,I11) | C11: 900005375 | D11: =IFERROR(VLOOKUP(C11,TRAOPE!$G:$H,2,0),"") | E11: D860 | F11: 65094171 | G11: =IFERROR(VLOOKUP(A11,Flete!$A:$E,5,0),"") | H11: =IFERROR(VLOOKUP(F11,TRAOPE!$AA:$AB,2,0),"") | I11: 10052407 | J11: =IFERROR(VLOOKUP(I11,Materiales!$A:$H,8,0),"") | K11: =IFERROR(VLOOKUP(I11,Materiales!$A:$G,7,0),"") | L11: 20221109 | M11: 20251031 | N11: 118.78 | O11: =IFERROR(VLOOKUP(A11,Flete!$A:$J,10,0),"") | P11: M3 | Q11: =IFERROR(IFERROR(VLOOKUP(A11,TRAOPE!$A:$U,21,0),VLOOKUP(B11,TRAOPE!$A:$U,21,0)),"") | R11: =IFERROR(IFERROR(VLOOKUP(A11,TRAOPE!$A:$W,23,0),VLOOKUP(B11,TRAOPE!$A:$W,23,0)),"") | S11: =IF(AND(P11="TN",R11="TN"),N11+N(O11),IF(G11&""="1",N(K11)*N11,(N11+N(O11))*N(K11))) | T11: =IF(Q11="","",Q11-S11)
A12: =CONCATENATE(C12,E12,F12,I12) | B12: =CONCATENATE(C12,E12,I12) | C12: 900005375 | D12: =IFERROR(VLOOKUP(C12,TRAOPE!$G:$H,2,0),"") | E12: D860 | F12: 65094171 | G12: =IFERROR(VLOOKUP(A12,Flete!$A:$E,5,0),"") | H12: =IFERROR(VLOOKUP(F12,TRAOPE!$AA:$AB,2,0),"") | I12: 10190637 | J12: =IFERROR(VLOOKUP(I12,Materiales!$A:$H,8,0),"") | K12: =IFERROR(VLOOKUP(I12,Materiales!$A:$G,7,0),"") | L12: 20221109 | M12: 20251031 | N12: 131.2 | O12: =IFERROR(VLOOKUP(A12,Flete!$A:$J,10,0),"") | P12: M3 | Q12: =IFERROR(IFERROR(VLOOKUP(A12,TRAOPE!$A:$U,21,0),VLOOKUP(B12,TRAOPE!$A:$U,21,0)),"") | R12: =IFERROR(IFERROR(VLOOKUP(A12,TRAOPE!$A:$W,23,0),VLOOKUP(B12,TRAOPE!$A:$W,23,0)),"") | S12: =IF(AND(P12="TN",R12="TN"),N12+N(O12),IF(G12&""="1",N(K12)*N12,(N12+N(O12))*N(K12))) | T12: =IF(Q12="","",Q12-S12)
A13: =CONCATENATE(C13,E13,F13,I13) | B13: =CONCATENATE(C13,E13,I13) | C13: 900005375 | D13: =IFERROR(VLOOKUP(C13,TRAOPE!$G:$H,2,0),"") | E13: D860 | F13: 65907412 | G13: =IFERROR(VLOOKUP(A13,Flete!$A:$E,5,0),"") | H13: =IFERROR(VLOOKUP(F13,TRAOPE!$AA:$AB,2,0),"") | I13: 10052402 | J13: =IFERROR(VLOOKUP(I13,Materiales!$A:$H,8,0),"") | K13: =IFERROR(VLOOKUP(I13,Materiales!$A:$G,7,0),"") | L13: 20221109 | M13: 20251031 | N13: 192.51 | O13: =IFERROR(VLOOKUP(A13,Flete!$A:$J,10,0),"") | P13: M3 | Q13: =IFERROR(IFERROR(VLOOKUP(A13,TRAOPE!$A:$U,21,0),VLOOKUP(B13,TRAOPE!$A:$U,21,0)),"") | R13: =IFERROR(IFERROR(VLOOKUP(A13,TRAOPE!$A:$W,23,0),VLOOKUP(B13,TRAOPE!$A:$W,23,0)),"") | S13: =IF(AND(P13="TN",R13="TN"),N13+N(O13),IF(G13&""="1",N(K13)*N13,(N13+N(O13))*N(K13))) | T13: =IF(Q13="","",Q13-S13)
A14: =CONCATENATE(C14,E14,F14,I14) | B14: =CONCATENATE(C14,E14,I14) | C14: 900005375 | D14: =IFERROR(VLOOKUP(C14,TRAOPE!$G:$H,2,0),"") | E14: D860 | F14: 65907412 | G14: =IFERROR(VLOOKUP(A14,Flete!$A:$E,5,0),"") | H14: =IFERROR(VLOOKUP(F14,TRAOPE!$AA:$AB,2,0),"") | I14: 10052405 | J14: =IFERROR(VLOOKUP(I14,Materiales!$A:$H,8,0),"") | K14: =IFERROR(VLOOKUP(I14,Materiales!$A:$G,7,0),"") | L14: 20221109 | M14: 20251031 | N14: 124.2 | O14: =IFERROR(VLOOKUP(A14,Flete!$A:$J,10,0),"") | P14: M3 | Q14: =IFERROR(IFERROR(VLOOKUP(A14,TRAOPE!$A:$U,21,0),VLOOKUP(B14,TRAOPE!$A:$U,21,0)),"") | R14: =IFERROR(IFERROR(VLOOKUP(A14,TRAOPE!$A:$W,23,0),VLOOKUP(B14,TRAOPE!$A:$W,23,0)),"") | S14: =IF(AND(P14="TN",R14="TN"),N14+N(O14),IF(G14&""="1",N(K14)*N14,(N14+N(O14))*N(K14))) | T14: =IF(Q14="","",Q14-S14)
... A196: =CONCATENATE(C196,E196,F196,I196) | B196: =CONCATENATE(C196,E196,I196) | C196: 900008951 | D196: =IFERROR(VLOOKUP(C196,TRAOPE!$G:$H,2,0),"") | E196: D860 | F196: 67310311 | G196: =IFERROR(VLOOKUP(A196,Flete!$A:$E,5,0),"") | H196: =IFERROR(VLOOKUP(F196,TRAOPE!$AA:$AB,2,0),"") | I196: 10262224 | J196: =IFERROR(VLOOKUP(I196,Materiales!$A:$H,8,0),"") | K196: =IFERROR(VLOOKUP(I196,Materiales!$A:$G,7,0),"") | L196: 20250505 | M196: 20250507 | N196: 136.8 | O196: =IFERROR(VLOOKUP(A196,Flete!$A:$J,10,0),"") | P196: M3 | Q196: =IFERROR(IFERROR(VLOOKUP(A196,TRAOPE!$A:$U,21,0),VLOOKUP(B196,TRAOPE!$A:$U,21,0)),"") | R196: =IFERROR(IFERROR(VLOOKUP(A196,TRAOPE!$A:$W,23,0),VLOOKUP(B196,TRAOPE!$A:$W,23,0)),"") | S196: =IF(AND(P196="TN",R196="TN"),N196+N(O196),IF(G196&""="1",N(K196)*N196,(N196+N(O196))*N(K196))) | T196: =IF(Q196="","",Q196-S196)

Sheet MP
A1: No. SF | B1: Cedis | C1: Destino | D1: No. Material | E1: Nombre Material | F1: Importe MP | G1: Moneda | H1: Cantidad | I1: UM | J1: C | K1: Inicio Vigencia | L1: Fin Vigencia
A2: 900007612 | B2: D860 | C2: 66958065 | D2: 10052402 | F2: 141.9 | I2: M3 | K2: 20240403 | L2: 20240529
A3: 900007612 | B3: D860 | C3: 66958065 | D3: 10052405 | F3: 141.9 | I3: M3 | K3: 20240403 | L3: 20240529
A4: 900007611 | B4: D860 | C4: 67064029 | D4: 10052404 | F4: 144 | I4: M3 | K4: 20240605 | L4: 20250825
A5: 900003456 | B5: D860 | C5: 66830361 | D5: 10052407 | F5: 90 | I5: M3 | K5: 20221109 | L5: 20251031
A6: 900003456 | B6: D860 | C6: 66830361 | D6: 10190637 | F6: 100 | I6: M3 | K6: 20221109 | L6: 20251031
A7: 900005375 | B7: D860 | C7: 65094171 | D7: 10000176 | F7: 131.2 | I7: M3 | K7: 20221109 | L7: 20251031
A8: 900005375 | B8: D860 | C8: 65094171 | D8: 10052402 | F8: 199.51 | I8: M3 | K8: 20221109 | L8: 20251031
A9: 900005375 | B9: D860 | C9: 65094171 | D9: 10052405 | F9: 131.2 | I9: M3 | K9: 20221109 | L9: 20251031
A10: 900005375 | B10: D860 | C10: 65094171 | D10: 10052407 | F10: 118.78 | I10: M3 | K10: 20221109 | L10: 20251031
A11: 900005375 | B11: D860 | C11: 65094171 | D11: 10190637 | F11: 131.2 | I11: M3 | K11: 20221109 | L11: 20251031
A12: 900005375 | B12: D860 | C12: 65907412 | D12: 10052402 | F12: 192.51 | I12: M3 | K12: 20221109 | L12: 20251031
A13: 900005375 | B13: D860 | C13: 65907412 | D13: 10052405 | F13: 124.2 | I13: M3 | K13: 20221109 | L13: 20251031
... A195: 900008951 | B195: D860 | C195: 67310311 | D195: 10262224 | F195: 136.8 | I195: M3 | K195: 20250505 | L195: 20250507

Sheet Flete
A1: Concat1 | B1: No. SF | C1: Cedis | D1: Destino | E1: Cond. Exp. | F1: Material | H1: Nombre Material | J1: Importe Flete | K1: Moneda | L1: Cantidad | M1: UM | N1: C | P1: Inicio Vigencia | Q1: Fin Vigencia
A2: 900005375D8606685476310052407 | B2: 900005375 | C2: D860 | D2: 66854763 | E2: 4 | F2: 10052407 | J2: 45 | M2: M3 | P2: 20200403 | Q2: 20251031
A3: 900005572D8606590741210052402 | B3: 900005572 | C3: D860 | D3: 65907412 | E3: 4 | F3: 10052402 | J3: 142.94 | M3: M3 | P3: 20200403 | Q3: 20251031
A4: 900005572D8606590741210052405 | B4: 900005572 | C4: D860 | D4: 65907412 | E4: 4 | F4: 10052405 | J4: 142.94 | M4: M3 | P4: 20200403 | Q4: 20251031
A5: 900005572D8606590741210052407 | B5: 900005572 | C5: D860 | D5: 65907412 | E5: 4 | F5: 10052407 | J5: 142.94 | M5: M3 | P5: 20200403 | Q5: 20251031
A6: 900005572D8606590741210190637 | B6: 900005572 | C6: D860 | D6: 65907412 | E6: 4 | F6: 10190637 | J6: 142.94 | M6: M3 | P6: 20200403 | Q6: 20251031
A7: 900005572D8606648110910190637 | B7: 900005572 | C7: D860 | D7: 66481109 | E7: 4 | F7: 10190637 | J7: 142.94 | M7: M3 | P7: 20200403 | Q7: 20251031
A8: 900005572D8606678354810052407 | B8: 900005572 | C8: D860 | D8: 66783548 | E8: 4 | F8: 10052407 | J8: 100 | M8: M3 | P8: 20200403 | Q8: 20251031
A9: 900005572D8606678354810190637 | B9: 900005572 | C9: D860 | D9: 66783548 | E9: 4 | F9: 10190637 | J9: 100 | M9: M3 | P9: 20200403 | Q9: 20251031
A10: 900005572D8606683351310000176 | B10: 900005572 | C10: D860 | D10: 66833513 | E10: 4 | F10: 10000176 | J10: 100 | M10: M3 | P10: 20200403 | Q10: 20251031
A11: 900005572D8606683351310052407 | B11: 900005572 | C11: D860 | D11: 66833513 | E11: 4 | F11: 10052407 | J11: 100 | M11: M3 | P11: 20200403 | Q11: 20251031
A12: 900005572D8606683351310190637 | B12: 900005572 | C12: D860 | D12: 66833513 | E12: 4 | F12: 10190637 | J12: 100 | M12: M3 | P12: 20200403 | Q12: 20251031
A13: 900005572D8606684587610052402 | B13: 900005572 | C13: D860 | D13: 66845876 | E13: 4 | F13: 10052402 | J13: 113 | M13: M3 | P13: 20200403 | Q13: 20251031
... A106: 900007611D8606711881910052407 | B106: 900007611 | C106: D860 | D106: 67118819 | E106: 4 | F106: 10052407 | J106: 129 | M106: M3 | P106: 20240706 | Q106: 20240814

Sheet Materiales
A1: Material | B1: TpMt | C1: Denom | D1: UMA | E1: Contador | F1: UMB | G1: PV | H1: Nombre Material
A2: 10000001 | B2: ZFER | C2: 1000 | D2: M3 | E2: 1000 | F2: TN | G2: 1262 | H2: GRAVA ANDESITA 10 MM (3/8")
A3: 10000003 | B3: ZFER | C3: 1000 | D3: M3 | E3: 1000 | F3: TN | G3: 1443 | H3: GRAVA CALIZA 10 MM (3/8")
A4: 10000006 | B4: ZFER | C4: 1000 | D4: M3 | E4: 1000 | F4: TN | G4: 1490 | H4: GRAVA RIO 10 MM (3/8")
A5: 10000007 | B5: ZFER | C5: 1000 | D5: M3 | E5: 1000 | F5: TN | G5: 1488 | H5: GRAVA BASALTO 13 MM (1/2")
A6: 10000008 | B6: ZFER | C6: 1000 | D6: M3 | E6: 1000 | F6: TN | G6: 1358 | H6: GRAVA CALIZA 13 MM (1/2")
A7: 10000011 | B7: ZFER | C7: 1000 | D7: M3 | E7: 1000 | F7: TN | G7: 1323 | H7: GRAVA ANDESITA 20 MM (3/4")
A8: 10000013 | B8: ZFER | C8: 1000 | D8: M3 | E8: 1000 | F8: TN | G8: 1514 | H8: GRAVA BASALTO 20 MM (3/4")
A9: 10000014 | B9: ZFER | C9: 1000 | D9: M3 | E9: 1000 | F9: TN | G9: 1400 | H9: GRAVA CALIZA 20 MM (3/4")
A10: 10000015 | B10: ZFER | C10: 1000 | D10: M3 | E10: 1000 | F10: TN | G10: 1410 | H10: GRAVA GRANITO 20 MM (3/4")
A11: 10000017 | B11: ZFER | C11: 1000 | D11: M3 | E11: 1000 | F11: TN | G11: 1475 | H11: GRAVA RIOLITA 20 MM (3/4")
A12: 10000019 | B12: ZFER | C12: 1000 | D12: M3 | E12: 1000 | F12: TN | G12: 1515 | H12: GRAVA RIO 20 MM (3/4")
A13: 10000020 | B13: ZFER | C13: 1000 | D13: M3 | E13: 1 | F13: TN | G13: 1 | H13: GRAVA MAQUILA 40MM (1 1/2")
... A2291: 10268770 | B2291: ZFE3 | C2291: 1000 | D2291: M3 | E2291: 1000 | F2291: TN | G2291: 1240 | H2291: MP GRAVA TRIT CALIZA 40MM 1 1/2" - ESP
A2292: 10268901 | B2292: ZFE3 | C2292: 1000 | D2292: M3 | E2292: 1000 | G2292: 1560 | H2292: MP GRAVA ANDESITA GRIS 3/4" - CAPADA
A2293: 10267983 | C2293: 1000 | G2293: 1800 | H2293: ESCORIA ALTO HORNO 3/4
A2294: 10268996 | C2294: 1000 | G2294: 1329 | H2294: GRAVA TRITURADA CALIZA 40 MM - 11/2"
A2295: 10269072 | C2295: 1000 | G2295: 1700 | H2295: BASE HIDRÁULICA SCREEN
A2296: 10269225 | B2296: ZFE3 | C2296: 1000 | D2296: M3 | E2296: 1000 | G2296: 1289 | H2296: MP ARENA CALIZA LAVADA MALLA 4 - DELTA I
A2297: 10269245 | B2297: ZFE3 | C2297: 1000 | D2297: M3 | E2297: 1000 | G2297: 1410 | H2297: MP GRAVA TRITURADA CALIZA 3/8 - 10MM
A2298: 10269246 | B2298: ZFE3 | C2298: 1000 | D2298: M3 | E2298: 1000 | G2298: 1400 | H2298: MP GRAVA TRITURADA CALIZA 1 1/2 - 40MM
A2299: 10269247 | B2299: ZFE3 | C2299: 1000 | D2299: M3 | E2299: 1000 | G2299: 1560 | H2299: MP ARENA TRIT CALIZA M-4
A2300: 10270431 | B2300: ZFE3 | C2300: 1000 | D2300: M3 | E2300: 1000 | G2300: 1423 | H2300: MP GRAVA RIOLITA 13 MM - 1/2"
A2301: 10270898 | B2301: ZFE3 | C2301: 1000 | D2301: M3 | E2301: 1000 | G2301: 1551 | H2301: MP BASE H. TRIT. BASALTO 1 1/2" A FINOS
A2302: 10270911 | B2302: ZFE3 | C2302: 1000 | D2302: M3 | E2302: 1000 | G2302: 1360 | H2302: MP GRAVA TRIT. BASALTO 40 MM - 1 1/2"
A2303: 10270912 | B2303: ZFE3 | C2303: 1000 | D2303: M3 | E2303: 1000 | G2303: 1589 | H2303: MP ARENA TRIT. BASALTO MALLA 4
A2304: 10270913 | B2304: ZFE3 | C2304: 1000 | D2304: M3 | E2304: 1000 | G2304: 1395 | H2304: MP GRAVA TRIT. BASALTO 20 MM - 3/4
A2305: 10270914 | B2305: ZFE3 | C2305: 1000 | D2305: M3 | E2305: 1000 | G2305: 1623 | H2305: MP ARENA ANDESITA BC
A2306: 10270824 | B2306: M3 | C2306: 1000 | D2306: M3 | E2306: 10007640 | G2306: 1325 | H2306: MP ARENA TRITURADA CALIZA MALLA 5
A2307: 10270825 | B2307: M3 | C2307: 1000 | D2307: M3 | E2307: 10000003 | G2307: 1242 | H2307: MP GRAVA TRITURADA CALIZA 10MM (3/8”)
... A2319: 10272527 | B2319: ZFE3 | C2319: 1000 | D2319: M3 | E2319: 1000 | G2319: 1620 | H2319: CNC - NO CLASIFICADO
A2320: 10000332 | C2320: 1000 | D2320: M3 | E2320: 1000 | G2320: 800 | H2320: Grava Triturada Pomez - Jal 20 mm - 3/4"
A2321: 10273001 | B2321: ZFE3 | C2321: 1000 | D2321: M3 | E2321: 1000 | G2321: 1688 | H2321: MP ARENA TRIT. BASALTO MALLA 4
A2322: 10273002 | B2322: ZFE3 | C2322: 1000 | D2322: M3 | E2322: 1000 | G2322: 1466 | H2322: MP GRAVA TRIT. BASALTO 20 MM - 3/4"
A2323: 10273351 | B2323: ZFE3 | C2323: 1000 | D2323: M3 | E2323: 1000 | G2323: 1612 | H2323: MP ARENA TRIT. CALIZA MALLA 4
A2324: 10273352 | B2324: ZFE3 | C2324: 1000 | D2324: M3 | E2324: 1000 | G2324: 1492 | H2324: MP GRAVA TRIT. CALIZA 20 MM - 3/4"
A2325: 10271724 | B2325: ZFE3 | C2325: 1000 | D2325: M3 | E2325: 1000 | G2325: 1900 | H2325: MP RESIDUO DE CONCRETO
A2326: 10000677 | C2326: 1000 | D2326: M3 | G2326: 1164 | H2326: Grava Triturada Caliza 20 mm - 3/4"
A2327: 10274190 | B2327: ZFE3 | C2327: 1000 | D2327: M3 | E2327: 1000 | G2327: 1800 | H2327: MP BASE HIDRAULICA ANDESITA 70-30
A2328: 10274601 | B2328: ZFE3 | C2328: 1000 | D2328: M3 | E2328: 1000 | G2328: 1447 | H2328: MP ARENA BASALTO N° 4
...

Sheet TRAOPE
A1: Concat1 | B1: Contrato_Pos | C1: Doc. Compras | D1: Pos | E1: Org.compras | F1: Grp-Compr. | G1: Ship From | H1: Nombre SF | I1: Proveedor | J1: Nombre Prov | K1: Cond. Pago | L1: Descr. Cond Pago | M1: Material | N1: Descripción | O1: Centro | P1: Descripción Centro | Q1: In.perído validez | R1: Fin perído validez | S1: Válido de | T1: Validez a | U1: Precio neto pedido | V1: Moneda | W1: UM Precio Pedido | X1: Importe Condición | Y1: Moneda KONP | Z1: UM Ctd Base | AA1: Destino | AB1: Nombre Destino | AC1: Cuenta de mayor | AD1: Centro de costo | AE1: Cond. Exp. | AF1: Descr. Cond. Exp. | AG1: Peso Vol. | AH1: UMB | AI1: Ind. Oblig. Conf. Ped. | AJ1: Ctrl-Conf. | AK1: IVA | AL1: Modif_Date | AM1: Ruta
A2: 900007611D8606738237310190637 | B2: 4600053981-500 | C2: 4600053981 | D2: 500 | E2: MXPO | F2: MXL | G2: 900007611 | H2: SF TP-ED-GOMOSA | I2: 5083069 | J2: GOMO DESARROLLOS Y MATERIALES S DE | K2: Z09 | L2: (AP) 90 Dias | M2: 10190637 | N2: GRAVA CLASIFICADA RIOLITA 20 MM (3/4") | O2: D860 | P2: MX-CED. HERMOSILLO | Q2: 20220512 | R2: 20291231 | S2: 20260716 | T2: 20301231 | U2: 231.67 | V2: MXN | W2: M3 | X2: 86.67 | Y2: MXN | Z2: M3 | AA2: 67382373 | AB2: CONCRETOS BALUARTE HERMOSILLO | AC2: 56103637 | AD2: 6622501540 | AE2: 4 | AF2: ENTREGA DIRECTA | AG2: 1.445 | AH2: M3 | AI2: X | AJ2: 4 | AK2: V4 | AL2: 20260721 | AM2: D860-900007611-67382373-10190637-4
A3: 900007611D8606738237310052402 | B3: 4600053981-490 | C3: 4600053981 | D3: 490 | E3: MXPO | F3: MXL | G3: 900007611 | H3: SF TP-ED-GOMOSA | I3: 5083069 | J3: GOMO DESARROLLOS Y MATERIALES S DE | K3: Z09 | L3: (AP) 90 Dias | M3: 10052402 | N3: Grava Riolita 10 MM (3/8") | O3: D860 | P3: MX-CED. HERMOSILLO | Q3: 20220512 | R3: 20291231 | S3: 20260716 | T3: 20301231 | U3: 286.67 | V3: MXN | W3: M3 | X3: 86.67 | Y3: MXN | Z3: M3 | AA3: 67382373 | AB3: CONCRETOS BALUARTE HERMOSILLO | AC3: 56103637 | AD3: 6622501540 | AE3: 4 | AF3: ENTREGA DIRECTA | AG3: 1.52 | AH3: M3 | AI3: X | AJ3: 4 | AK3: V4 | AL3: 20260721 | AM3: D860-900007611-67382373-10052402-4
A4: 900007611D8606738237310052407 | B4: 4600053981-510 | C4: 4600053981 | D4: 510 | E4: MXPO | F4: MXL | G4: 900007611 | H4: SF TP-ED-GOMOSA | I4: 5083069 | J4: GOMO DESARROLLOS Y MATERIALES S DE | K4: Z09 | L4: (AP) 90 Dias | M4: 10052407 | N4: Arena Triturada Rio Malla 4 | O4: D860 | P4: MX-CED. HERMOSILLO | Q4: 20220512 | R4: 20291231 | S4: 20260716 | T4: 20301231 | U4: 216.67 | V4: MXN | W4: M3 | X4: 86.67 | Y4: MXN | Z4: M3 | AA4: 67382373 | AB4: CONCRETOS BALUARTE HERMOSILLO | AC4: 56103638 | AD4: 6622501540 | AE4: 4 | AF4: ENTREGA DIRECTA | AG4: 1.51 | AH4: M3 | AI4: X | AJ4: 4 | AK4: V4 | AL4: 20260721 | AM4: D860-900007611-67382373-10052407-4
A5: 900007611D8606711881910052405 | B5: 4600053981-330 | C5: 4600053981 | D5: 330 | E5: MXPO | F5: MXL | G5: 900007611 | H5: SF TP-ED-GOMOSA | I5: 5083069 | J5: GOMO DESARROLLOS Y MATERIALES S DE | K5: Z09 | L5: (AP) 90 Dias | M5: 10052405 | N5: Grava Riolita 40 MM (1 1/2") | O5: D860 | P5: MX-CED. HERMOSILLO | Q5: 20220512 | R5: 20291231 | S5: 20240528 | T5: 20291231 | U5: 226.66 | V5: MXN | W5: M3 | X5: 106.66 | Y5: MXN | Z5: M3 | AA5: 67118819 | AB5: GIDERENO SONORA (MEZTA) | AC5: 56103637 | AD5: 6622501540 | AE5: 4 | AF5: ENTREGA DIRECTA | AG5: 1.48 | AH5: M3 | AI5: X | AJ5: 4 | AK5: V4 | AL5: 20240531 | AM5: D860-900007611-67118819-10052405-4
A6: 900007611D8606711881910052404 | B6: 4600053981-340 | C6: 4600053981 | D6: 340 | E6: MXPO | F6: MXL | G6: 900007611 | H6: SF TP-ED-GOMOSA | I6: 5083069 | J6: GOMO DESARROLLOS Y MATERIALES S DE | K6: Z09 | L6: (AP) 90 Dias | M6: 10052404 | N6: Grava Riolita 20 MM (3/4") | O6: D860 | P6: MX-CED. HERMOSILLO | Q6: 20220512 | R6: 20291231 | S6: 20240528 | T6: 20291231 | U6: 229.66 | V6: MXN | W6: M3 | X6: 106.66 | Y6: MXN | Z6: M3 | AA6: 67118819 | AB6: GIDERENO SONORA (MEZTA) | AC6: 56103637 | AD6: 6622501540 | AE6: 4 | AF6: ENTREGA DIRECTA | AG6: 1.445 | AH6: M3 | AI6: X | AJ6: 4 | AK6: V4 | AL6: 20240531 | AM6: D860-900007611-67118819-10052404-4
A7: 900007611D8606654082210052407 | B7: 4600053981-140 | C7: 4600053981 | D7: 140 | E7: MXPO | F7: MXL | G7: 900007611 | H7: SF TP-ED-GOMOSA | I7: 5083069 | J7: GOMO DESARROLLOS Y MATERIALES S DE | K7: Z09 | L7: (AP) 90 Dias | M7: 10052407 | N7: Arena Triturada Rio Malla 4 | O7: D860 | P7: MX-CED. HERMOSILLO | Q7: 20220512 | R7: 20291231 | S7: 20230629 | T7: 20281231 | U7: 205 | V7: MXN | W7: M3 | X7: 85 | Y7: MXN | Z7: M3 | AA7: 66540822 | AB7: ALTA CALIDAD EN CONCRETOS PLANTA | AC7: 56103638 | AD7: 6622501540 | AE7: 4 | AF7: ENTREGA DIRECTA | AG7: 1.51 | AH7: M3 | AI7: X | AJ7: 4 | AK7: V4 | AL7: 20230920 | AM7: D860-900007611-66540822-10052407-4
A8: 900007611D8606685656210052404 | B8: 4600053981-380 | C8: 4600053981 | D8: 380 | E8: MXPO | F8: MXL | G8: 900007611 | H8: SF TP-ED-GOMOSA | I8: 5083069 | J8: GOMO DESARROLLOS Y MATERIALES S DE | K8: Z09 | L8: (AP) 90 Dias | M8: 10052404 | N8: Grava Riolita 20 MM (3/4") | O8: D860 | P8: MX-CED. HERMOSILLO | Q8: 20220512 | R8: 20291231 | S8: 20240528 | T8: 20291231 | U8: 229.66 | V8: MXN | W8: M3 | X8: 106.66 | Y8: MXN | Z8: M3 | AA8: 66856562 | AB8: CONSTRUSELECT MEZTA SONORA | AC8: 56103637 | AD8: 6622501540 | AE8: 4 | AF8: ENTREGA DIRECTA | AG8: 1.445 | AH8: M3 | AI8: X | AJ8: 4 | AK8: V4 | AL8: 20240531 | AM8: D860-900007611-66856562-10052404-4
A9: 900007611D8606711881910052407 | B9: 4600053981-360 | C9: 4600053981 | D9: 360 | E9: MXPO | F9: MXL | G9: 900007611 | H9: SF TP-ED-GOMOSA | I9: 5083069 | J9: GOMO DESARROLLOS Y MATERIALES S DE | K9: Z09 | L9: (AP) 90 Dias | M9: 10052407 | N9: Arena Triturada Rio Malla 4 | O9: D860 | P9: MX-CED. HERMOSILLO | Q9: 20220512 | R9: 20291231 | S9: 20240528 | T9: 20291231 | U9: 218.66 | V9: MXN | W9: M3 | X9: 106.66 | Y9: MXN | Z9: M3 | AA9: 67118819 | AB9: GIDERENO SONORA (MEZTA) | AC9: 56103638 | AD9: 6622501540 | AE9: 4 | AF9: ENTREGA DIRECTA | AG9: 1.51 | AH9: M3 | AI9: X | AJ9: 4 | AK9: V4 | AL9: 20240531 | AM9: D860-900007611-67118819-10052407-4
A10: 900007611D8606685656210052402 | B10: 4600053981-390 | C10: 4600053981 | D10: 390 | E10: MXPO | F10: MXL | G10: 900007611 | H10: SF TP-ED-GOMOSA | I10: 5083069 | J10: GOMO DESARROLLOS Y MATERIALES S DE | K10: Z09 | L10: (AP) 90 Dias | M10: 10052402 | N10: Grava Riolita 10 MM (3/8") | O10: D860 | P10: MX-CED. HERMOSILLO | Q10: 20220512 | R10: 20291231 | S10: 20240528 | T10: 20291231 | U10: 235.66 | V10: MXN | W10: M3 | X10: 106.66 | Y10: MXN | Z10: M3 | AA10: 66856562 | AB10: CONSTRUSELECT MEZTA SONORA | AC10: 56103637 | AD10: 6622501540 | AE10: 4 | AF10: ENTREGA DIRECTA | AG10: 1.52 | AH10: M3 | AI10: X | AJ10: 4 | AK10: V4 | AL10: 20240531 | AM10: D860-900007611-66856562-10052402-4
A11: 900007611D8606689613610052407 | B11: 4600053981-320 | C11: 4600053981 | D11: 320 | E11: MXPO | F11: MXL | G11: 900007611 | H11: SF TP-ED-GOMOSA | I11: 5083069 | J11: GOMO DESARROLLOS Y MATERIALES S DE | K11: Z09 | L11: (AP) 90 Dias | M11: 10052407 | N11: Arena Triturada Rio Malla 4 | O11: D860 | P11: MX-CED. HERMOSILLO | Q11: 20220512 | R11: 20291231 | S11: 20240528 | T11: 20291231 | U11: 218.66 | V11: MXN | W11: M3 | X11: 106.66 | Y11: MXN | Z11: M3 | AA11: 66896136 | AB11: MEZTA CORPORATIVO HERMOSILLO (AGG) | AC11: 56103638 | AD11: 6622501540 | AE11: 4 | AF11: ENTREGA DIRECTA | AG11: 1.51 | AH11: M3 | AI11: X | AJ11: 4 | AK11: V4 | AL11: 20240531 | AM11: D860-900007611-66896136-10052407-4
A12: 900007611D8606685656210052405 | B12: 4600053981-370 | C12: 4600053981 | D12: 370 | E12: MXPO | F12: MXL | G12: 900007611 | H12: SF TP-ED-GOMOSA | I12: 5083069 | J12: GOMO DESARROLLOS Y MATERIALES S DE | K12: Z09 | L12: (AP) 90 Dias | M12: 10052405 | N12: Grava Riolita 40 MM (1 1/2") | O12: D860 | P12: MX-CED. HERMOSILLO | Q12: 20220512 | R12: 20291231 | S12: 20240528 | T12: 20291231 | U12: 226.66 | V12: MXN | W12: M3 | X12: 106.66 | Y12: MXN | Z12: M3 | AA12: 66856562 | AB12: CONSTRUSELECT MEZTA SONORA | AC12: 56103637 | AD12: 6622501540 | AE12: 4 | AF12: ENTREGA DIRECTA | AG12: 1.48 | AH12: M3 | AI12: X | AJ12: 4 | AK12: V4 | AL12: 20240531 | AM12: D860-900007611-66856562-10052405-4
A13: 900007611D8606685656210052407 | B13: 4600053981-400 | C13: 4600053981 | D13: 400 | E13: MXPO | F13: MXL | G13: 900007611 | H13: SF TP-ED-GOMOSA | I13: 5083069 | J13: GOMO DESARROLLOS Y MATERIALES S DE | K13: Z09 | L13: (AP) 90 Dias | M13: 10052407 | N13: Arena Triturada Rio Malla 4 | O13: D860 | P13: MX-CED. HERMOSILLO | Q13: 20220512 | R13: 20291231 | S13: 20240528 | T13: 20291231 | U13: 218.66 | V13: MXN | W13: M3 | X13: 106.66 | Y13: MXN | Z13: M3 | AA13: 66856562 | AB13: CONSTRUSELECT MEZTA SONORA | AC13: 56103638 | AD13: 6622501540 | AE13: 4 | AF13: ENTREGA DIRECTA | AG13: 1.51 | AH13: M3 | AI13: X | AJ13: 4 | AK13: V4 | AL13: 20240531 | AM13: D860-900007611-66856562-10052407-4
... A17: 900007611D8606689613610052404 | B17: 4600053981-300 | C17: 4600053981 | D17: 300 | E17: MXPO | F17: MXL | G17: 900007611 | H17: SF TP-ED-GOMOSA | I17: 5083069 | J17: GOMO DESARROLLOS Y MATERIALES S DE | K17: Z09 | L17: (AP) 90 Dias | M17: 10052404 | N17: Grava Riolita 20 MM (3/4") | O17: D860 | P17: MX-CED. HERMOSILLO | Q17: 20220512 | R17: 20291231 | S17: 20240528 | T17: 20291231 | U17: 229.66 | V17: MXN | W17: M3 | X17: 106.66 | Y17: MXN | Z17: M3 | AA17: 66896136 | AB17: MEZTA CORPORATIVO HERMOSILLO (AGG) | AC17: 56103637 | AD17: 6622501540 | AE17: 4 | AF17: ENTREGA DIRECTA | AG17: 1.445 | AH17: M3 | AI17: X | AJ17: 4 | AK17: V4 | AL17: 20240531 | AM17: D860-900007611-66896136-10052404-4
A18: 900005375D86010052402 | B18: 4600039662-30 | C18: 4600039662 | D18: 30 | E18: MXPO | F18: MXL | G18: 900005375 | H18: SF TP- PROPESO | I18: 5001601 | J18: PRODUCTOS PETREOS DE SONORA SA DE | K18: Z03 | L18: (AP) 15 Dias | M18: 10052402 | N18: Grava Riolita 10 MM (3/8") | O18: D860 | P18: MX-CED. HERMOSILLO | Q18: 20170906 | R18: 20261231 | S18: 20250502 | T18: 20301231 | U18: 188.6 | V18: MXN | W18: M3 | X18: 0 | Y18: MXN | Z18: M3 | AC18: 56103637 | AD18: 6622501540 | AE18: 1 | AF18: ENTREGADO | AG18: 1.52 | AH18: M3 | AI18: X | AJ18: 4 | AK18: V4 | AL18: 20250502 | AM18: D860-900005375-10052402
A19: 900005375D86010190637 | B19: 4600039662-80 | C19: 4600039662 | D19: 80 | E19: MXPO | F19: MXL | G19: 900005375 | H19: SF TP- PROPESO | I19: 5001601 | J19: PRODUCTOS PETREOS DE SONORA SA DE | K19: Z03 | L19: (AP) 15 Dias | M19: 10190637 | N19: GRAVA CLASIFICADA RIOLITA 20 MM (3/4") | O19: D860 | P19: MX-CED. HERMOSILLO | Q19: 20170906 | R19: 20261231 | S19: 20250502 | T19: 20301231 | U19: 120 | V19: MXN | W19: M3 | X19: 0 | Y19: MXN | Z19: M3 | AC19: 56103637 | AD19: 6622501540 | AE19: 1 | AF19: ENTREGADO | AG19: 1.445 | AH19: M3 | AI19: X | AJ19: 4 | AK19: V4 | AL19: 20250502 | AM19: D860-900005375-10190637
A20: 900005375D86010052405 | B20: 4600039662-10 | C20: 4600039662 | D20: 10 | E20: MXPO | F20: MXL | G20: 900005375 | H20: SF TP- PROPESO | I20: 5001601 | J20: PRODUCTOS PETREOS DE SONORA SA DE | K20: Z03 | L20: (AP) 15 Dias | M20: 10052405 | N20: Grava Riolita 40 MM (1 1/2") | O20: D860 | P20: MX-CED. HERMOSILLO | Q20: 20170906 | R20: 20261231 | S20: 20250502 | T20: 20301231 | U20: 110 | V20: MXN | W20: M3 | X20: 0 | Y20: MXN | Z20: M3 | AC20: 56103637 | AD20: 6622501540 | AE20: 1 | AF20: ENTREGADO | AG20: 1.48 | AH20: M3 | AI20: X | AJ20: 4 | AK20: V4 | AL20: 20250502 | AM20: D860-900005375-10052405
A21: 900005572D8606678354810190637 | B21: 4600041494-550 | C21: 4600041494 | D21: 550 | E21: MXPO | F21: MXL | G21: 900005572 | H21: TP- ED- PROPESO | I21: 5001601 | J21: PRODUCTOS PETREOS DE SONORA SA DE | K21: Z03 | L21: (AP) 15 Dias | M21: 10190637 | N21: GRAVA CLASIFICADA RIOLITA 20 MM (3/4") | O21: D860 | P21: MX-CED. HERMOSILLO | Q21: 20180308 | R21: 20281231 | U21: 208 | V21: MXN | W21: M3 | AA21: 66783548 | AB21: BODEGA AURRERA BLVD MUSARO (EIAA) | AC21: 56103637 | AD21: 6622501540 | AE21: 4 | AF21: ENTREGA DIRECTA | AG21: 1.445 | AH21: M3 | AI21: X | AJ21: 4 | AK21: V4 | AL21: 20230920 | AM21: D860-900005572-66783548-10190637-4
A22: 900005572D8606590741210190637 | B22: 4600041494-500 | C22: 4600041494 | D22: 500 | E22: MXPO | F22: MXL | G22: 900005572 | H22: TP- ED- PROPESO | I22: 5001601 | J22: PRODUCTOS PETREOS DE SONORA SA DE | K22: Z03 | L22: (AP) 15 Dias | M22: 10190637 | N22: GRAVA CLASIFICADA RIOLITA 20 MM (3/4") | O22: D860 | P22: MX-CED. HERMOSILLO | Q22: 20180308 | R22: 20281231 | U22: 242.94 | V22: MXN | W22: M3 | AA22: 65907412 | AB22: VTL URBANIZACIONES MEZAMEX | AC22: 56103637 | AD22: 6622501540 | AE22: 4 | AF22: ENTREGA DIRECTA | AG22: 1.445 | AH22: M3 | AI22: X | AJ22: 4 | AK22: V4 | AL22: 20230920 | AM22: D860-900005572-65907412-10190637-4
A23: 900003456D86010190637 | B23: 4600046484-30 | C23: 4600046484 | D23: 30 | E23: MXPO | F23: MXL | G23: 900003456 | H23: TP -PROPESO ZATO | I23: 5001601 | J23: PRODUCTOS PETREOS DE SONORA SA DE | K23: Z03 | L23: (AP) 15 Dias | M23: 10190637 | N23: GRAVA CLASIFICADA RIOLITA 20 MM (3/4") | O23: D860 | P23: MX-CED. HERMOSILLO | Q23: 20200130 | R23: 20241231 | S23: 20201112 | T23: 20291231 | U23: 92 | V23: MXN | W23: M3 | AC23: 56103637 | AD23: 6622501540 | AE23: 1 | AF23: ENTREGADO | AG23: 1.445 | AH23: M3 | AI23: X | AJ23: 4 | AK23: V4 | AL23: 20230920 | AM23: D860-900003456-10190637
A24: 900005375D86010000176 | B24: 4600039662-50 | C24: 4600039662 | D24: 50 | E24: MXPO | F24: MXL | G24: 900005375 | H24: SF TP- PROPESO | I24: 5001601 | J24: PRODUCTOS PETREOS DE SONORA SA DE | K24: Z03 | L24: (AP) 15 Dias | M24: 10000176 | N24: Base H Clasificada Río 1 1/2" a Finos | O24: D860 | P24: MX-CED. HERMOSILLO | Q24: 20170906 | R24: 20261231 | S24: 20180803 | T24: 20241231 | U24: 100 | V24: MXN | W24: M3 | X24: 0 | Y24: MXN | Z24: M3 | AC24: 56103590 | AD24: 6622501540 | AE24: 1 | AF24: ENTREGADO | AG24: 1.6 | AH24: M3 | AI24: X | AJ24: 4 | AK24: V4 | AL24: 20230920 | AM24: D860-900005375-10000176
A25: 900005375D86010000661 | B25: 4600039662-70 | C25: 4600039662 | D25: 70 | E25: MXPO | F25: MXL | G25: 900005375 | H25: SF TP- PROPESO | I25: 5001601 | J25: PRODUCTOS PETREOS DE SONORA SA DE | K25: Z03 | L25: (AP) 15 Dias | M25: 10000661 | N25: Sobretamaño Triturado Basalto | O25: D860 | P25: MX-CED. HERMOSILLO | Q25: 20170906 | R25: 20261231 | S25: 20190415 | T25: 20241231 | U25: 91.8 | V25: MXN | W25: M3 | X25: 0 | Y25: MXN | Z25: M3 | AC25: 56103636 | AD25: 6622501540 | AE25: 1 | AF25: ENTREGADO | AG25: 1.47 | AH25: M3 | AI25: X | AJ25: 4 | AK25: V4 | AL25: 20230920 | AM25: D860-900005375-10000661
A26: 900003456D86010052407 | B26: 4600046484-10 | C26: 4600046484 | D26: 10 | E26: MXPO | F26: MXL | G26: 900003456 | H26: TP -PROPESO ZATO | I26: 5001601 | J26: PRODUCTOS PETREOS DE SONORA SA DE | K26: Z03 | L26: (AP) 15 Dias | M26: 10052407 | N26: Arena Triturada Rio Malla 4 | O26: D860 | P26: MX-CED. HERMOSILLO | Q26: 20200130 | R26: 20241231 | S26: 20190128 | T26: 20241231 | U26: 82 | V26: MXN | W26: M3 | X26: 0 | Y26: MXN | Z26: M3 | AC26: 56103638 | AD26: 6622501540 | AE26: 1 | AF26: ENTREGADO | AG26: 1.51 | AH26: M3 | AI26: X | AJ26: 4 | AK26: V4 | AL26: 20230920 | AM26: D860-900003456-10052407
A27: 900007612D86010190637 | B27: 4600053982-80 | C27: 4600053982 | D27: 80 | E27: MXPO | F27: MXL | G27: 900007612 | H27: SF TP-GOMOSA | I27: 5083069 | J27: GOMO DESARROLLOS Y MATERIALES S DE | K27: Z09 | L27: (AP) 90 Dias | M27: 10190637 | N27: GRAVA CLASIFICADA RIOLITA 20 MM (3/4") | O27: D860 | P27: MX-CED. HERMOSILLO | Q27: 20220512 | R27: 20291231 | S27: 20220820 | T27: 20271231 | U27: 110 | V27: MXN | W27: M3 | X27: 0 | Y27: MXN | Z27: M3 | AC27: 56103637 | AD27: 6622501540 | AE27: 1 | AF27: ENTREGADO | AG27: 1.445 | AH27: M3 | AI27: X | AJ27: 4 | AK27: V4 | AL27: 20230920 | AM27: D860-900007612-10190637
A28: 900007612D86010208119 | B28: 4600053982-30 | C28: 4600053982 | D28: 30 | E28: MXPO | F28: MXL | G28: 900007612 | H28: SF TP-GOMOSA | I28: 5083069 | J28: GOMO DESARROLLOS Y MATERIALES S DE | K28: Z09 | L28: (AP) 90 Dias | M28: 10208119 | N28: ARENA DE RIO 50% - POLVO TRITURADO GRANI | O28: D860 | P28: MX-CED. HERMOSILLO | Q28: 20220512 | R28: 20291231 | S28: 20220601 | T28: 20271231 | U28: 130 | V28: MXN | W28: M3 | X28: 0 | Y28: MXN | Z28: M3 | AC28: 56103638 | AD28: 6622501540 | AE28: 1 | AF28: ENTREGADO | AG28: 1.565 | AH28: M3 | AI28: X | AJ28: 4 | AK28: V4 | AL28: 20230920 | AM28: D860-900007612-10208119
A29: 900007612D86010190772 | B29: 4600053982-110 | C29: 4600053982 | D29: 110 | E29: MXPO | F29: MXL | G29: 900007612 | H29: SF TP-GOMOSA | I29: 5083069 | J29: GOMO DESARROLLOS Y MATERIALES S DE | K29: Z09 | L29: (AP) 90 Dias | M29: 10190772 | N29: MATERIAL DE EXTRACCION DE BANCO | O29: D860 | P29: MX-CED. HERMOSILLO | Q29: 20220512 | R29: 20291231 | S29: 20220901 | T29: 20271231 | U29: 270 | V29: MXN | W29: M3 | X29: 0 | Y29: MXN | Z29: M3 | AC29: 56103636 | AD29: 6622501867 | AE29: 1 | AF29: ENTREGADO | AG29: 1.5 | AH29: M3 | AI29: X | AJ29: 4 | AK29: V4 | AL29: 20230920 | AM29: D860-900007612-10190772
A30: 900005572D8606651576710000661 | B30: 4600041494-40 | C30: 4600041494 | D30: 40 | E30: MXPO | F30: MXL | G30: 900005572 | H30: TP- ED- PROPESO | I30: 5001601 | J30: PRODUCTOS PETREOS DE SONORA SA DE | K30: Z03 | L30: (AP) 15 Dias | M30: 10000661 | N30: Sobretamaño Triturado Basalto | O30: D860 | P30: MX-CED. HERMOSILLO | Q30: 20180308 | R30: 20281231 | S30: 20190415 | T30: 20241231 | U30: 194.4 | V30: MXN | W30: M3 | X30: 102.6 | Y30: MXN | Z30: M3 | AA30: 66515767 | AC30: 56103636 | AD30: 6622501540 | AE30: 4 | AF30: ENTREGA DIRECTA | AG30: 1.47 | AH30: M3 | AI30: X | AJ30: 4 | AK30: V4 | AL30: 20230920 | AM30: D860-900005572-66515767-10000661-4
A31: 900007611D8606654082210052402 | B31: 4600053981-150 | C31: 4600053981 | D31: 150 | E31: MXPO | F31: MXL | G31: 900007611 | H31: SF TP-ED-GOMOSA | I31: 5083069 | J31: GOMO DESARROLLOS Y MATERIALES S DE | K31: Z09 | L31: (AP) 90 Dias | M31: 10052402 | N31: Grava Riolita 10 MM (3/8") | O31: D860 | P31: MX-CED. HERMOSILLO | Q31: 20220512 | R31: 20291231 | S31: 20230629 | T31: 20281231 | U31: 216 | V31: MXN | W31: M3 | X31: 51 | Y31: MXN | Z31: M3 | AA31: 66540822 | AB31: ALTA CALIDAD EN CONCRETOS PLANTA | AC31: 56103637 | AD31: 6622501540 | AE31: 4 | AF31: ENTREGA DIRECTA | AG31: 1.52 | AH31: M3 | AI31: X | AJ31: 4 | AK31: V4 | AL31: 20230920 | AM31: D860-900007611-66540822-10052402-4
A32: 900005572D8606654697410052407 | B32: 4600041494-170 | C32: 4600041494 | D32: 170 | E32: MXPO | F32: MXL | G32: 900005572 | H32: TP- ED- PROPESO | I32: 5001601 | J32: PRODUCTOS PETREOS DE SONORA SA DE | K32: Z03 | L32: (AP) 15 Dias | M32: 10052407 | N32: Arena Triturada Rio Malla 4 | O32: D860 | P32: MX-CED. HERMOSILLO | Q32: 20180308 | R32: 20281231 | S32: 20180606 | T32: 20241231 | U32: 265 | V32: MXN | W32: M3 | X32: 173 | Y32: MXN | Z32: M3 | AA32: 66546974 | AB32: AVAKO PREFABRICADOS PLANTA HERMOSIL | AC32: 56103638 | AD32: 6622501540 | AE32: 4 | AF32: ENTREGA DIRECTA | AG32: 1.51 | AH32: M3 | AI32: X | AJ32: 4 | AK32: V4 | AL32: 20230920 | AM32: D860-900005572-66546974-10052407-4
A33: 900005572D8606687759010052407 | B33: 4600041494-340 | C33: 4600041494 | D33: 340 | E33: MXPO | F33: MXL | G33: 900005572 | H33: TP- ED- PROPESO | I33: 5001601 | J33: PRODUCTOS PETREOS DE SONORA SA DE | K33: Z03 | L33: (AP) 15 Dias | M33: 10052407 | N33: Arena Triturada Rio Malla 4 | O33: D860 | P33: MX-CED. HERMOSILLO | Q33: 20180308 | R33: 20281231 | S33: 20300101 | T33: 99991231 | U33: 210.2 | V33: MXN | W33: M3 | X33: 113 | Y33: MXN | Z33: M3 | AA33: 66877590 | AB33: VT02302 FRACC. AZORES (JVM) | AC33: 56103638 | AD33: 6622501540 | AE33: 4 | AF33: ENTREGA DIRECTA | AG33: 1.51 | AH33: M3 | AI33: X | AJ33: 4 | AK33: V4 | AL33: 20230920 | AM33: D860-900005572-66877590-10052407-4
A34: 900005572D8606654697410052405 | B34: 4600041494-200 | C34: 4600041494 | D34: 200 | E34: MXPO | F34: MXL | G34: 900005572 | H34: TP- ED- PROPESO | I34: 5001601 | J34: PRODUCTOS PETREOS DE SONORA SA DE | K34: Z03 | L34: (AP) 15 Dias | M34: 10052405 | N34: Grava Riolita 40 MM (1 1/2") | O34: D860 | P34: MX-CED. HERMOSILLO | Q34: 20180308 | R34: 20281231 | S34: 20180606 | T34: 20241231 | U34: 273 | V34: MXN | W34: M3 | X34: 173 | Y34: MXN | Z34: M3 | AA34: 66546974 | AB34: AVAKO PREFABRICADOS PLANTA HERMOSIL | AC34: 56103637 | AD34: 6622501540 | AE34: 4 | AF34: ENTREGA DIRECTA | AG34: 1.48 | AH34: M3 | AI34: X | AJ34: 4 | AK34: V4 | AL34: 20230920 | AM34: D860-900005572-66546974-10052405-4
A35: 900005572D8606654697410052402 | B35: 4600041494-180 | C35: 4600041494 | D35: 180 | E35: MXPO | F35: MXL | G35: 900005572 | H35: TP- ED- PROPESO | I35: 5001601 | J35: PRODUCTOS PETREOS DE SONORA SA DE | K35: Z03 | L35: (AP) 15 Dias | M35: 10052402 | N35: Grava Riolita 10 MM (3/8") | O35: D860 | P35: MX-CED. HERMOSILLO | Q35: 20180308 | R35: 20281231 | S35: 20180606 | T35: 20241231 | U35: 323 | V35: MXN | W35: M3 | X35: 173 | Y35: MXN | Z35: M3 | AA35: 66546974 | AB35: AVAKO PREFABRICADOS PLANTA HERMOSIL | AC35: 56103637 | AD35: 6622501540 | AE35: 4 | AF35: ENTREGA DIRECTA | AG35: 1.52 | AH35: M3 | AI35: X | AJ35: 4 | AK35: V4 | AL35: 20230920 | AM35: D860-900005572-66546974-10052402-4
A36: 900005572D8606659739110052402 | B36: 4600041494-240 | C36: 4600041494 | D36: 240 | E36: MXPO | F36: MXL | G36: 900005572 | H36: TP- ED- PROPESO | I36: 5001601 | J36: PRODUCTOS PETREOS DE SONORA SA DE | K36: Z03 | L36: (AP) 15 Dias | M36: 10052402 | N36: Grava Riolita 10 MM (3/8") | O36: D860 | P36: MX-CED. HERMOSILLO | Q36: 20180308 | R36: 20281231 | S36: 20190315 | T36: 20241231 | U36: 210.6 | V36: MXN | W36: M3 | X36: 102.6 | Y36: MXN | Z36: M3 | AA36: 66597391 | AB36: CEDIS MODELO (EIAA) | AC36: 56103637 | AD36: 6622501540 | AE36: 4 | AF36: ENTREGA DIRECTA | AG36: 1.52 | AH36: M3 | AI36: X | AJ36: 4 | AK36: V4 | AL36: 20230920 | AM36: D860-900005572-66597391-10052402-4
A37: 900005572D8606659739110000661 | B37: 4600041494-260 | C37: 4600041494 | D37: 260 | E37: MXPO | F37: MXL | G37: 900005572 | H37: TP- ED- PROPESO | I37: 5001601 | J37: PRODUCTOS PETREOS DE SONORA SA DE | K37: Z03 | L37: (AP) 15 Dias | M37: 10000661 | N37: Sobretamaño Triturado Basalto | O37: D860 | P37: MX-CED. HERMOSILLO | Q37: 20180308 | R37: 20281231 | S37: 20190415 | T37: 20241231 | U37: 194.4 | V37: MXN | W37: M3 | X37: 102.6 | Y37: MXN | Z37: M3 | AA37: 66597391 | AB37: CEDIS MODELO (EIAA) | AC37: 56103636 | AD37: 6622501540 | AE37: 4 | AF37: ENTREGA DIRECTA | AG37: 1.47 | AH37: M3 | AI37: X | AJ37: 4 | AK37: V4 | AL37: 20230920 | AM37: D860-900005572-66597391-10000661-4
A38: 900005572D8606687759010052402 | B38: 4600041494-350 | C38: 4600041494 | D38: 350 | E38: MXPO | F38: MXL | G38: 900005572 | H38: TP- ED- PROPESO | I38: 5001601 | J38: PRODUCTOS PETREOS DE SONORA SA DE | K38: Z03 | L38: (AP) 15 Dias | M38: 10052402 | N38: Grava Riolita 10 MM (3/8") | O38: D860 | P38: MX-CED. HERMOSILLO | Q38: 20180308 | R38: 20281231 | S38: 20300101 | T38: 99991231 | U38: 296.6 | V38: MXN | W38: M3 | X38: 113 | Y38: MXN | Z38: M3 | AA38: 66877590 | AB38: VT02302 FRACC. AZORES (JVM) | AC38: 56103637 | AD38: 6622501540 | AE38: 4 | AF38: ENTREGA DIRECTA | AG38: 1.52 | AH38: M3 | AI38: X | AJ38: 4 | AK38: V4 | AL38: 20230920 | AM38: D860-900005572-66877590-10052402-4
A39: 900005572D8606651576710052407 | B39: 4600041494-10 | C39: 4600041494 | D39: 10 | E39: MXPO | F39: MXL | G39: 900005572 | H39: TP- ED- PROPESO | I39: 5001601 | J39: PRODUCTOS PETREOS DE SONORA SA DE | K39: Z03 | L39: (AP) 15 Dias | M39: 10052407 | N39: Arena Triturada Rio Malla 4 | O39: D860 | P39: MX-CED. HERMOSILLO | Q39: 20180308 | R39: 20281231 | S39: 20190415 | T39: 20241231 | U39: 199.8 | V39: MXN | W39: M3 | X39: 102.6 | Y39: MXN | Z39: M3 | AA39: 66515767 | AC39: 56103638 | AD39: 6622501540 | AE39: 4 | AF39: ENTREGA DIRECTA | AG39: 1.51 | AH39: M3 | AI39: X | AJ39: 4 | AK39: V4 | AL39: 20230920 | AM39: D860-900005572-66515767-10052407-4
A40: 900007611D8606687759010052407 | B40: 4600053981-70 | C40: 4600053981 | D40: 70 | E40: MXPO | F40: MXL | G40: 900007611 | H40: SF TP-ED-GOMOSA | I40: 5083069 | J40: GOMO DESARROLLOS Y MATERIALES S DE | K40: Z09 | L40: (AP) 90 Dias | M40: 10052407 | N40: Arena Triturada Rio Malla 4 | O40: D860 | P40: MX-CED. HERMOSILLO | Q40: 20220512 | R40: 20291231 | S40: 20220727 | T40: 20271231 | U40: 229 | V40: MXN | W40: M3 | X40: 129 | Y40: MXN | Z40: M3 | AA40: 66877590 | AB40: VT02302 FRACC. AZORES (JVM) | AC40: 56103638 | AD40: 6622501540 | AE40: 4 | AF40: ENTREGA DIRECTA | AG40: 1.51 | AH40: M3 | AI40: X | AJ40: 4 | AK40: V4 | AL40: 20230920 | AM40: D860-900007611-66877590-10052407-4
A41: 900007611D8606687759010190637 | B41: 4600053981-90 | C41: 4600053981 | D41: 90 | E41: MXPO | F41: MXL | G41: 900007611 | H41: SF TP-ED-GOMOSA | I41: 5083069 | J41: GOMO DESARROLLOS Y MATERIALES S DE | K41: Z09 | L41: (AP) 90 Dias | M41: 10190637 | N41: GRAVA CLASIFICADA RIOLITA 20 MM (3/4") | O41: D860 | P41: MX-CED. HERMOSILLO | Q41: 20220512 | R41: 20291231 | S41: 20220727 | T41: 20271231 | U41: 239 | V41: MXN | W41: M3 | X41: 129 | Y41: MXN | Z41: M3 | AA41: 66877590 | AB41: VT02302 FRACC. AZORES (JVM) | AC41: 56103637 | AD41: 6622501540 | AE41: 4 | AF41: ENTREGA DIRECTA | AG41: 1.445 | AH41: M3 | AI41: X | AJ41: 4 | AK41: V4 | AL41: 20230920 | AM41: D860-900007611-66877590-10190637-4
A42: 900007611D8606654082210052404 | B42: 4600053981-120 | C42: 4600053981 | D42: 120 | E42: MXPO | F42: MXL | G42: 900007611 | H42: SF TP-ED-GOMOSA | I42: 5083069 | J42: GOMO DESARROLLOS Y MATERIALES S DE | K42: Z09 | L42: (AP) 90 Dias | M42: 10052404 | N42: Grava Riolita 20 MM (3/4") | O42: D860 | P42: MX-CED. HERMOSILLO | Q42: 20220512 | R42: 20291231 | S42: 20230629 | T42: 20281231 | U42: 216 | V42: MXN | W42: M3 | X42: 96 | Y42: MXN | Z42: M3 | AA42: 66540822 | AB42: ALTA CALIDAD EN CONCRETOS PLANTA | AC42: 56103637 | AD42: 6622501540 | AE42: 4 | AF42: ENTREGA DIRECTA | AG42: 1.445 | AH42: M3 | AI42: X | AJ42: 4 | AK42: V4 | AL42: 20230920 | AM42: D860-900007611-66540822-10052404-4
A43: 900007611D8606654082210052405 | B43: 4600053981-130 | C43: 4600053981 | D43: 130 | E43: MXPO | F43: MXL | G43: 900007611 | H43: SF TP-ED-GOMOSA | I43: 5083069 | J43: GOMO DESARROLLOS Y MATERIALES S DE | K43: Z09 | L43: (AP) 90 Dias | M43: 10052405 | N43: Grava Riolita 40 MM (1 1/2") | O43: D860 | P43: MX-CED. HERMOSILLO | Q43: 20220512 | R43: 20291231 | S43: 20230629 | T43: 20281231 | U43: 216 | V43: MXN | W43: M3 | X43: 96 | Y43: MXN | Z43: M3 | AA43: 66540822 | AB43: ALTA CALIDAD EN CONCRETOS PLANTA | AC43: 56103637 | AD43: 6622501540 | AE43: 4 | AF43: ENTREGA DIRECTA | AG43: 1.48 | AH43: M3 | AI43: X | AJ43: 4 | AK43: V4 | AL43: 20230920 | AM43: D860-900007611-66540822-10052405-4
...
