Workbook

Sheet Base Cedis DU12
N1: VENTA | Q1: COSTO
A2: CONCAT1 | B2: CONCAT2 | C2: No. SF | D2: Nombre SF | E2: Cedis | F2: Destino | G2: Condicion de Expedicion | H2: Nombre Destino | I2: No. de material | J2: Nombre de material | K2: PV | L2: Inicio de vigencia | M2: Fin de vigencia | N2: Importe MP | O2: Importe Flete | P2: UM Venta | Q2: Importe Costo | R2: UM Costo | S2: Validacion 1 | T2: Validacion 2
A3: =CONCATENATE(C3,E3,F3,I3) | B3: =CONCATENATE(C3,E3,I3) | C3: 900007337 | D3: =IFERROR(VLOOKUP(C3,TRAOPE!$G:$H,2,0),"") | E3: DU12 | F3: EB06 | G3: =IFERROR(VLOOKUP(A3,Flete!$A:$E,5,0),"") | H3: =IFERROR(VLOOKUP(F3,TRAOPE!$AA:$AB,2,0),"") | I3: 10203226 | J3: =IFERROR(VLOOKUP(I3,Materiales!$A:$H,8,0),"") | K3: =IFERROR(VLOOKUP(I3,Materiales!$A:$G,7,0),"") | L3: 20250701 | M3: 20251030 | N3: 3350 | O3: =IFERROR(VLOOKUP(A3,Flete!$A:$J,10,0),"") | P3: TN | Q3: =IFERROR(IFERROR(VLOOKUP(A3,TRAOPE!$A:$U,21,0),VLOOKUP(B3,TRAOPE!$A:$U,21,0)),"") | R3: =IFERROR(IFERROR(VLOOKUP(A3,TRAOPE!$A:$W,23,0),VLOOKUP(B3,TRAOPE!$A:$W,23,0)),"") | S3: =IF(AND(P3="TN",R3="TN"),N3+N(O3),IF(G3&""="1",N(K3)*N3,(N3+N(O3))*N(K3))) | T3: =IF(Q3="","",Q3-S3)
A4: =CONCATENATE(C4,E4,F4,I4) | B4: =CONCATENATE(C4,E4,I4) | C4: 900007337 | D4: =IFERROR(VLOOKUP(C4,TRAOPE!$G:$H,2,0),"") | E4: DU12 | F4: EB06 | G4: =IFERROR(VLOOKUP(A4,Flete!$A:$E,5,0),"") | H4: =IFERROR(VLOOKUP(F4,TRAOPE!$AA:$AB,2,0),"") | I4: 10203227 | J4: =IFERROR(VLOOKUP(I4,Materiales!$A:$H,8,0),"") | K4: =IFERROR(VLOOKUP(I4,Materiales!$A:$G,7,0),"") | L4: 20250701 | M4: 20251030 | N4: 3350 | O4: =IFERROR(VLOOKUP(A4,Flete!$A:$J,10,0),"") | P4: TN | Q4: =IFERROR(IFERROR(VLOOKUP(A4,TRAOPE!$A:$U,21,0),VLOOKUP(B4,TRAOPE!$A:$U,21,0)),"") | R4: =IFERROR(IFERROR(VLOOKUP(A4,TRAOPE!$A:$W,23,0),VLOOKUP(B4,TRAOPE!$A:$W,23,0)),"") | S4: =IF(AND(P4="TN",R4="TN"),N4+N(O4),IF(G4&""="1",N(K4)*N4,(N4+N(O4))*N(K4))) | T4: =IF(Q4="","",Q4-S4)
A5: =CONCATENATE(C5,E5,F5,I5) | B5: =CONCATENATE(C5,E5,I5) | C5: 900007337 | D5: =IFERROR(VLOOKUP(C5,TRAOPE!$G:$H,2,0),"") | E5: DU12 | F5: EB06 | G5: =IFERROR(VLOOKUP(A5,Flete!$A:$E,5,0),"") | H5: =IFERROR(VLOOKUP(F5,TRAOPE!$AA:$AB,2,0),"") | I5: 10203228 | J5: =IFERROR(VLOOKUP(I5,Materiales!$A:$H,8,0),"") | K5: =IFERROR(VLOOKUP(I5,Materiales!$A:$G,7,0),"") | L5: 20250701 | M5: 20251030 | N5: 3350 | O5: =IFERROR(VLOOKUP(A5,Flete!$A:$J,10,0),"") | P5: TN | Q5: =IFERROR(IFERROR(VLOOKUP(A5,TRAOPE!$A:$U,21,0),VLOOKUP(B5,TRAOPE!$A:$U,21,0)),"") | R5: =IFERROR(IFERROR(VLOOKUP(A5,TRAOPE!$A:$W,23,0),VLOOKUP(B5,TRAOPE!$A:$W,23,0)),"") | S5: =IF(AND(P5="TN",R5="TN"),N5+N(O5),IF(G5&""="1",N(K5)*N5,(N5+N(O5))*N(K5))) | T5: =IF(Q5="","",Q5-S5)
A6: =CONCATENATE(C6,E6,F6,I6) | B6: =CONCATENATE(C6,E6,I6) | C6: 900007337 | D6: =IFERROR(VLOOKUP(C6,TRAOPE!$G:$H,2,0),"") | E6: DU12 | F6: EB06 | G6: =IFERROR(VLOOKUP(A6,Flete!$A:$E,5,0),"") | H6: =IFERROR(VLOOKUP(F6,TRAOPE!$AA:$AB,2,0),"") | I6: 10203229 | J6: =IFERROR(VLOOKUP(I6,Materiales!$A:$H,8,0),"") | K6: =IFERROR(VLOOKUP(I6,Materiales!$A:$G,7,0),"") | L6: 20250701 | M6: 20251030 | N6: 5550 | O6: =IFERROR(VLOOKUP(A6,Flete!$A:$J,10,0),"") | P6: TN | Q6: =IFERROR(IFERROR(VLOOKUP(A6,TRAOPE!$A:$U,21,0),VLOOKUP(B6,TRAOPE!$A:$U,21,0)),"") | R6: =IFERROR(IFERROR(VLOOKUP(A6,TRAOPE!$A:$W,23,0),VLOOKUP(B6,TRAOPE!$A:$W,23,0)),"") | S6: =IF(AND(P6="TN",R6="TN"),N6+N(O6),IF(G6&""="1",N(K6)*N6,(N6+N(O6))*N(K6))) | T6: =IF(Q6="","",Q6-S6)
A7: =CONCATENATE(C7,E7,F7,I7) | B7: =CONCATENATE(C7,E7,I7) | C7: 900007337 | D7: =IFERROR(VLOOKUP(C7,TRAOPE!$G:$H,2,0),"") | E7: DU12 | F7: EB06 | G7: =IFERROR(VLOOKUP(A7,Flete!$A:$E,5,0),"") | H7: =IFERROR(VLOOKUP(F7,TRAOPE!$AA:$AB,2,0),"") | I7: 10204240 | J7: =IFERROR(VLOOKUP(I7,Materiales!$A:$H,8,0),"") | K7: =IFERROR(VLOOKUP(I7,Materiales!$A:$G,7,0),"") | L7: 20250701 | M7: 20251030 | N7: 5550 | O7: =IFERROR(VLOOKUP(A7,Flete!$A:$J,10,0),"") | P7: TN | Q7: =IFERROR(IFERROR(VLOOKUP(A7,TRAOPE!$A:$U,21,0),VLOOKUP(B7,TRAOPE!$A:$U,21,0)),"") | R7: =IFERROR(IFERROR(VLOOKUP(A7,TRAOPE!$A:$W,23,0),VLOOKUP(B7,TRAOPE!$A:$W,23,0)),"") | S7: =IF(AND(P7="TN",R7="TN"),N7+N(O7),IF(G7&""="1",N(K7)*N7,(N7+N(O7))*N(K7))) | T7: =IF(Q7="","",Q7-S7)
A8: =CONCATENATE(C8,E8,F8,I8) | B8: =CONCATENATE(C8,E8,I8) | C8: 900007337 | D8: =IFERROR(VLOOKUP(C8,TRAOPE!$G:$H,2,0),"") | E8: DU12 | F8: EB06 | G8: =IFERROR(VLOOKUP(A8,Flete!$A:$E,5,0),"") | H8: =IFERROR(VLOOKUP(F8,TRAOPE!$AA:$AB,2,0),"") | I8: 10204241 | J8: =IFERROR(VLOOKUP(I8,Materiales!$A:$H,8,0),"") | K8: =IFERROR(VLOOKUP(I8,Materiales!$A:$G,7,0),"") | L8: 20250701 | M8: 20251030 | N8: 5550 | O8: =IFERROR(VLOOKUP(A8,Flete!$A:$J,10,0),"") | P8: TN | Q8: =IFERROR(IFERROR(VLOOKUP(A8,TRAOPE!$A:$U,21,0),VLOOKUP(B8,TRAOPE!$A:$U,21,0)),"") | R8: =IFERROR(IFERROR(VLOOKUP(A8,TRAOPE!$A:$W,23,0),VLOOKUP(B8,TRAOPE!$A:$W,23,0)),"") | S8: =IF(AND(P8="TN",R8="TN"),N8+N(O8),IF(G8&""="1",N(K8)*N8,(N8+N(O8))*N(K8))) | T8: =IF(Q8="","",Q8-S8)
A9: =CONCATENATE(C9,E9,F9,I9) | B9: =CONCATENATE(C9,E9,I9) | C9: 900007337 | D9: =IFERROR(VLOOKUP(C9,TRAOPE!$G:$H,2,0),"") | E9: DU12 | F9: EB06 | G9: =IFERROR(VLOOKUP(A9,Flete!$A:$E,5,0),"") | H9: =IFERROR(VLOOKUP(F9,TRAOPE!$AA:$AB,2,0),"") | I9: 10204242 | J9: =IFERROR(VLOOKUP(I9,Materiales!$A:$H,8,0),"") | K9: =IFERROR(VLOOKUP(I9,Materiales!$A:$G,7,0),"") | L9: 20250701 | M9: 20251030 | N9: 5550 | O9: =IFERROR(VLOOKUP(A9,Flete!$A:$J,10,0),"") | P9: TN | Q9: =IFERROR(IFERROR(VLOOKUP(A9,TRAOPE!$A:$U,21,0),VLOOKUP(B9,TRAOPE!$A:$U,21,0)),"") | R9: =IFERROR(IFERROR(VLOOKUP(A9,TRAOPE!$A:$W,23,0),VLOOKUP(B9,TRAOPE!$A:$W,23,0)),"") | S9: =IF(AND(P9="TN",R9="TN"),N9+N(O9),IF(G9&""="1",N(K9)*N9,(N9+N(O9))*N(K9))) | T9: =IF(Q9="","",Q9-S9)
A10: =CONCATENATE(C10,E10,F10,I10) | B10: =CONCATENATE(C10,E10,I10) | C10: 900007337 | D10: =IFERROR(VLOOKUP(C10,TRAOPE!$G:$H,2,0),"") | E10: DU12 | F10: EB06 | G10: =IFERROR(VLOOKUP(A10,Flete!$A:$E,5,0),"") | H10: =IFERROR(VLOOKUP(F10,TRAOPE!$AA:$AB,2,0),"") | I10: 10204243 | J10: =IFERROR(VLOOKUP(I10,Materiales!$A:$H,8,0),"") | K10: =IFERROR(VLOOKUP(I10,Materiales!$A:$G,7,0),"") | L10: 20250701 | M10: 20251030 | N10: 5550 | O10: =IFERROR(VLOOKUP(A10,Flete!$A:$J,10,0),"") | P10: TN | Q10: =IFERROR(IFERROR(VLOOKUP(A10,TRAOPE!$A:$U,21,0),VLOOKUP(B10,TRAOPE!$A:$U,21,0)),"") | R10: =IFERROR(IFERROR(VLOOKUP(A10,TRAOPE!$A:$W,23,0),VLOOKUP(B10,TRAOPE!$A:$W,23,0)),"") | S10: =IF(AND(P10="TN",R10="TN"),N10+N(O10),IF(G10&""="1",N(K10)*N10,(N10+N(O10))*N(K10))) | T10: =IF(Q10="","",Q10-S10)
A11: =CONCATENATE(C11,E11,F11,I11) | B11: =CONCATENATE(C11,E11,I11) | C11: 900007337 | D11: =IFERROR(VLOOKUP(C11,TRAOPE!$G:$H,2,0),"") | E11: DU12 | F11: EB06 | G11: =IFERROR(VLOOKUP(A11,Flete!$A:$E,5,0),"") | H11: =IFERROR(VLOOKUP(F11,TRAOPE!$AA:$AB,2,0),"") | I11: 10204244 | J11: =IFERROR(VLOOKUP(I11,Materiales!$A:$H,8,0),"") | K11: =IFERROR(VLOOKUP(I11,Materiales!$A:$G,7,0),"") | L11: 20250701 | M11: 20251030 | N11: 5550 | O11: =IFERROR(VLOOKUP(A11,Flete!$A:$J,10,0),"") | P11: TN | Q11: =IFERROR(IFERROR(VLOOKUP(A11,TRAOPE!$A:$U,21,0),VLOOKUP(B11,TRAOPE!$A:$U,21,0)),"") | R11: =IFERROR(IFERROR(VLOOKUP(A11,TRAOPE!$A:$W,23,0),VLOOKUP(B11,TRAOPE!$A:$W,23,0)),"") | S11: =IF(AND(P11="TN",R11="TN"),N11+N(O11),IF(G11&""="1",N(K11)*N11,(N11+N(O11))*N(K11))) | T11: =IF(Q11="","",Q11-S11)
A12: =CONCATENATE(C12,E12,F12,I12) | B12: =CONCATENATE(C12,E12,I12) | C12: 900007337 | D12: =IFERROR(VLOOKUP(C12,TRAOPE!$G:$H,2,0),"") | E12: DU12 | F12: EB06 | G12: =IFERROR(VLOOKUP(A12,Flete!$A:$E,5,0),"") | H12: =IFERROR(VLOOKUP(F12,TRAOPE!$AA:$AB,2,0),"") | I12: 10204245 | J12: =IFERROR(VLOOKUP(I12,Materiales!$A:$H,8,0),"") | K12: =IFERROR(VLOOKUP(I12,Materiales!$A:$G,7,0),"") | L12: 20250701 | M12: 20251030 | N12: 5550 | O12: =IFERROR(VLOOKUP(A12,Flete!$A:$J,10,0),"") | P12: TN | Q12: =IFERROR(IFERROR(VLOOKUP(A12,TRAOPE!$A:$U,21,0),VLOOKUP(B12,TRAOPE!$A:$U,21,0)),"") | R12: =IFERROR(IFERROR(VLOOKUP(A12,TRAOPE!$A:$W,23,0),VLOOKUP(B12,TRAOPE!$A:$W,23,0)),"") | S12: =IF(AND(P12="TN",R12="TN"),N12+N(O12),IF(G12&""="1",N(K12)*N12,(N12+N(O12))*N(K12))) | T12: =IF(Q12="","",Q12-S12)
A13: =CONCATENATE(C13,E13,F13,I13) | B13: =CONCATENATE(C13,E13,I13) | C13: 900007337 | D13: =IFERROR(VLOOKUP(C13,TRAOPE!$G:$H,2,0),"") | E13: DU12 | F13: EB06 | G13: =IFERROR(VLOOKUP(A13,Flete!$A:$E,5,0),"") | H13: =IFERROR(VLOOKUP(F13,TRAOPE!$AA:$AB,2,0),"") | I13: 10204246 | J13: =IFERROR(VLOOKUP(I13,Materiales!$A:$H,8,0),"") | K13: =IFERROR(VLOOKUP(I13,Materiales!$A:$G,7,0),"") | L13: 20250701 | M13: 20251030 | N13: 5550 | O13: =IFERROR(VLOOKUP(A13,Flete!$A:$J,10,0),"") | P13: TN | Q13: =IFERROR(IFERROR(VLOOKUP(A13,TRAOPE!$A:$U,21,0),VLOOKUP(B13,TRAOPE!$A:$U,21,0)),"") | R13: =IFERROR(IFERROR(VLOOKUP(A13,TRAOPE!$A:$W,23,0),VLOOKUP(B13,TRAOPE!$A:$W,23,0)),"") | S13: =IF(AND(P13="TN",R13="TN"),N13+N(O13),IF(G13&""="1",N(K13)*N13,(N13+N(O13))*N(K13))) | T13: =IF(Q13="","",Q13-S13)
A14: =CONCATENATE(C14,E14,F14,I14) | B14: =CONCATENATE(C14,E14,I14) | C14: 900007337 | D14: =IFERROR(VLOOKUP(C14,TRAOPE!$G:$H,2,0),"") | E14: DU12 | F14: EB06 | G14: =IFERROR(VLOOKUP(A14,Flete!$A:$E,5,0),"") | H14: =IFERROR(VLOOKUP(F14,TRAOPE!$AA:$AB,2,0),"") | I14: 10204247 | J14: =IFERROR(VLOOKUP(I14,Materiales!$A:$H,8,0),"") | K14: =IFERROR(VLOOKUP(I14,Materiales!$A:$G,7,0),"") | L14: 20250701 | M14: 20251030 | N14: 5550 | O14: =IFERROR(VLOOKUP(A14,Flete!$A:$J,10,0),"") | P14: TN | Q14: =IFERROR(IFERROR(VLOOKUP(A14,TRAOPE!$A:$U,21,0),VLOOKUP(B14,TRAOPE!$A:$U,21,0)),"") | R14: =IFERROR(IFERROR(VLOOKUP(A14,TRAOPE!$A:$W,23,0),VLOOKUP(B14,TRAOPE!$A:$W,23,0)),"") | S14: =IF(AND(P14="TN",R14="TN"),N14+N(O14),IF(G14&""="1",N(K14)*N14,(N14+N(O14))*N(K14))) | T14: =IF(Q14="","",Q14-S14)
... A41: =CONCATENATE(C41,E41,F41,I41) | B41: =CONCATENATE(C41,E41,I41) | C41: 900007337 | D41: =IFERROR(VLOOKUP(C41,TRAOPE!$G:$H,2,0),"") | E41: DU12 | F41: 65002221 | G41: =IFERROR(VLOOKUP(A41,Flete!$A:$E,5,0),"") | H41: =IFERROR(VLOOKUP(F41,TRAOPE!$AA:$AB,2,0),"") | I41: 10203229 | J41: =IFERROR(VLOOKUP(I41,Materiales!$A:$H,8,0),"") | K41: =IFERROR(VLOOKUP(I41,Materiales!$A:$G,7,0),"") | L41: 20240619 | M41: 20251031 | N41: 5550 | O41: =IFERROR(VLOOKUP(A41,Flete!$A:$J,10,0),"") | P41: TN | Q41: =IFERROR(IFERROR(VLOOKUP(A41,TRAOPE!$A:$U,21,0),VLOOKUP(B41,TRAOPE!$A:$U,21,0)),"") | R41: =IFERROR(IFERROR(VLOOKUP(A41,TRAOPE!$A:$W,23,0),VLOOKUP(B41,TRAOPE!$A:$W,23,0)),"") | S41: =IF(AND(P41="TN",R41="TN"),N41+N(O41),IF(G41&""="1",N(K41)*N41,(N41+N(O41))*N(K41))) | T41: =IF(Q41="","",Q41-S41)

Sheet MP
A1: No. SF | B1: Cedis | C1: Destino | D1: No. Material | E1: Nombre Material | F1: Importe MP | G1: Moneda | H1: Cantidad | I1: UM | J1: C | K1: Inicio Vigencia | L1: Fin Vigencia
A2: 900007337 | B2: DU12 | C2: EB06 | D2: 10203226 | F2: 3350 | I2: TN | K2: 20250701 | L2: 20251030
A3: 900007337 | B3: DU12 | C3: EB06 | D3: 10203227 | F3: 3350 | I3: TN | K3: 20250701 | L3: 20251030
A4: 900007337 | B4: DU12 | C4: EB06 | D4: 10203228 | F4: 3350 | I4: TN | K4: 20250701 | L4: 20251030
A5: 900007337 | B5: DU12 | C5: EB06 | D5: 10203229 | F5: 5550 | I5: TN | K5: 20250701 | L5: 20251030
A6: 900007337 | B6: DU12 | C6: EB06 | D6: 10204240 | F6: 5550 | I6: TN | K6: 20250701 | L6: 20251030
A7: 900007337 | B7: DU12 | C7: EB06 | D7: 10204241 | F7: 5550 | I7: TN | K7: 20250701 | L7: 20251030
A8: 900007337 | B8: DU12 | C8: EB06 | D8: 10204242 | F8: 5550 | I8: TN | K8: 20250701 | L8: 20251030
A9: 900007337 | B9: DU12 | C9: EB06 | D9: 10204243 | F9: 5550 | I9: TN | K9: 20250701 | L9: 20251030
A10: 900007337 | B10: DU12 | C10: EB06 | D10: 10204244 | F10: 5550 | I10: TN | K10: 20250701 | L10: 20251030
A11: 900007337 | B11: DU12 | C11: EB06 | D11: 10204245 | F11: 5550 | I11: TN | K11: 20250701 | L11: 20251030
A12: 900007337 | B12: DU12 | C12: EB06 | D12: 10204246 | F12: 5550 | I12: TN | K12: 20250701 | L12: 20251030
A13: 900007337 | B13: DU12 | C13: EB06 | D13: 10204247 | F13: 5550 | I13: TN | K13: 20250701 | L13: 20251030
... A40: 900007337 | B40: DU12 | C40: 65002221 | D40: 10203229 | F40: 5550 | I40: TN | K40: 20240619 | L40: 20251031

Sheet Flete
A1: Concat1 | B1: No. SF | C1: Cedis | D1: Destino | E1: Cond. Exp. | F1: Material | H1: Nombre Material | J1: Importe Flete | K1: Moneda | L1: Cantidad | M1: UM | N1: C | P1: Inicio Vigencia | Q1: Fin Vigencia
A2: 900007337DU12EB0610203226 | B2: 900007337 | C2: DU12 | D2: EB06 | E2: 1 | F2: 10203226 | J2: 3350 | M2: TN | P2: 20250401 | Q2: 20251031
A3: 900007337DU12EB0610203227 | B3: 900007337 | C3: DU12 | D3: EB06 | E3: 1 | F3: 10203227 | J3: 3350 | M3: TN | P3: 20250401 | Q3: 20251031
A4: 900007337DU12EB0610203228 | B4: 900007337 | C4: DU12 | D4: EB06 | E4: 1 | F4: 10203228 | J4: 3350 | M4: TN | P4: 20250401 | Q4: 20251031
A5: 900007337DU12EB0610203229 | B5: 900007337 | C5: DU12 | D5: EB06 | E5: 1 | F5: 10203229 | J5: 5550 | M5: TN | P5: 20250401 | Q5: 20251031
A6: 900007337DU12EB0610204240 | B6: 900007337 | C6: DU12 | D6: EB06 | E6: 1 | F6: 10204240 | J6: 5550 | M6: TN | P6: 20250401 | Q6: 20251031
A7: 900007337DU12EB0610204241 | B7: 900007337 | C7: DU12 | D7: EB06 | E7: 1 | F7: 10204241 | J7: 5550 | M7: TN | P7: 20250401 | Q7: 20251031
A8: 900007337DU12EB0610204242 | B8: 900007337 | C8: DU12 | D8: EB06 | E8: 1 | F8: 10204242 | J8: 5550 | M8: TN | P8: 20250401 | Q8: 20251031
A9: 900007337DU12EB0610204243 | B9: 900007337 | C9: DU12 | D9: EB06 | E9: 1 | F9: 10204243 | J9: 5550 | M9: TN | P9: 20250401 | Q9: 20251031
A10: 900007337DU12EB0610204244 | B10: 900007337 | C10: DU12 | D10: EB06 | E10: 1 | F10: 10204244 | J10: 5550 | M10: TN | P10: 20250401 | Q10: 20251031
A11: 900007337DU12EB0610204245 | B11: 900007337 | C11: DU12 | D11: EB06 | E11: 1 | F11: 10204245 | J11: 5550 | M11: TN | P11: 20250401 | Q11: 20251031
A12: 900007337DU12EB0610204246 | B12: 900007337 | C12: DU12 | D12: EB06 | E12: 1 | F12: 10204246 | J12: 5550 | M12: TN | P12: 20250401 | Q12: 20251031
A13: 900007337DU12EB0610204247 | B13: 900007337 | C13: DU12 | D13: EB06 | E13: 1 | F13: 10204247 | J13: 5550 | M13: TN | P13: 20250401 | Q13: 20251031
... A40: 900007337DU126500222110203229 | B40: 900007337 | C40: DU12 | D40: 65002221 | E40: 4 | F40: 10203229 | J40: 3450 | M40: TN | P40: 20230322 | Q40: 99991231

Sheet Materiales
A1: Material | B1: TpMt | C1: Denom | D1: UMA | E1: Contador | F1: UMB | G1: PV | H1: Nombre Material
A2: 10000001 | B2: ZFER | C2: 1000 | D2: M3 | E2: 1000 | F2: TN | G2: 1262 | H2: GRAVA ANDESITA 10 MM (3/8")
A3: 10000003 | B3: ZFER | C3: 1000 | D3: M3 | E3: 1000 | F3: TN | G3: 1443 | H3: GRAVA CALIZA 10 MM (3/8")
A4: 10000006 | B4: ZFER | C4: 1000 | D4: M3 | E4: 1000 | F4: TN | G4: 1490 | H4: GRAVA RIO 10 MM (3/8")
A5: 10000007 | B5: ZFER | C5: 1000 | D5: M3 | E5: 1000 | F5: TN | G5: 1488 | H5: GRAVA BASALTO 13 MM (1/2")
A6: 10000008 | B6: ZFER | C6: 1000 | D6: M3 | E6: 1000 | F6: TN | G6: 1358 | H6: GRAVA CALIZA 13 MM (1/2")
A7: 10000011 | B7: ZFER | C7: 1000 | D7: M3 | E7: 1000 | F7: TN | G7: 1323 | H7: GRAVA ANDESITA 20 MM (3/4")
A8: 10000013 | B8: ZFER | C8: 1000 | D8: M3 | E8: 1000 | F8: TN | G8: 1514 | H8: GRAVA BASALTO 20 MM (3/4")
A9: 10000014 | B9: ZFER | C9: 1000 | D9: M3 | E9: 1000 | F9: TN | G9: 1400 | H9: GRAVA CALIZA 20 MM (3/4")
A10: 10000015 | B10: ZFER | C10: 1000 | D10: M3 | E10: 1000 | F10: TN | G10: 1410 | H10: GRAVA GRANITO 20 MM (3/4")
A11: 10000017 | B11: ZFER | C11: 1000 | D11: M3 | E11: 1000 | F11: TN | G11: 1475 | H11: GRAVA RIOLITA 20 MM (3/4")
A12: 10000019 | B12: ZFER | C12: 1000 | D12: M3 | E12: 1000 | F12: TN | G12: 1515 | H12: GRAVA RIO 20 MM (3/4")
A13: 10000020 | B13: ZFER | C13: 1000 | D13: M3 | E13: 1 | F13: TN | G13: 1 | H13: GRAVA MAQUILA 40MM (1 1/2")
... A2291: 10268770 | B2291: ZFE3 | C2291: 1000 | D2291: M3 | E2291: 1000 | F2291: TN | G2291: 1240 | H2291: MP GRAVA TRIT CALIZA 40MM 1 1/2" - ESP
A2292: 10268901 | B2292: ZFE3 | C2292: 1000 | D2292: M3 | E2292: 1000 | G2292: 1560 | H2292: MP GRAVA ANDESITA GRIS 3/4" - CAPADA
A2293: 10267983 | C2293: 1000 | G2293: 1800 | H2293: ESCORIA ALTO HORNO 3/4
A2294: 10268996 | C2294: 1000 | G2294: 1329 | H2294: GRAVA TRITURADA CALIZA 40 MM - 11/2"
A2295: 10269072 | C2295: 1000 | G2295: 1700 | H2295: BASE HIDRÁULICA SCREEN
A2296: 10269225 | B2296: ZFE3 | C2296: 1000 | D2296: M3 | E2296: 1000 | G2296: 1289 | H2296: MP ARENA CALIZA LAVADA MALLA 4 - DELTA I
A2297: 10269245 | B2297: ZFE3 | C2297: 1000 | D2297: M3 | E2297: 1000 | G2297: 1410 | H2297: MP GRAVA TRITURADA CALIZA 3/8 - 10MM
A2298: 10269246 | B2298: ZFE3 | C2298: 1000 | D2298: M3 | E2298: 1000 | G2298: 1400 | H2298: MP GRAVA TRITURADA CALIZA 1 1/2 - 40MM
A2299: 10269247 | B2299: ZFE3 | C2299: 1000 | D2299: M3 | E2299: 1000 | G2299: 1560 | H2299: MP ARENA TRIT CALIZA M-4
A2300: 10270431 | B2300: ZFE3 | C2300: 1000 | D2300: M3 | E2300: 1000 | G2300: 1423 | H2300: MP GRAVA RIOLITA 13 MM - 1/2"
A2301: 10270898 | B2301: ZFE3 | C2301: 1000 | D2301: M3 | E2301: 1000 | G2301: 1551 | H2301: MP BASE H. TRIT. BASALTO 1 1/2" A FINOS
A2302: 10270911 | B2302: ZFE3 | C2302: 1000 | D2302: M3 | E2302: 1000 | G2302: 1360 | H2302: MP GRAVA TRIT. BASALTO 40 MM - 1 1/2"
A2303: 10270912 | B2303: ZFE3 | C2303: 1000 | D2303: M3 | E2303: 1000 | G2303: 1589 | H2303: MP ARENA TRIT. BASALTO MALLA 4
A2304: 10270913 | B2304: ZFE3 | C2304: 1000 | D2304: M3 | E2304: 1000 | G2304: 1395 | H2304: MP GRAVA TRIT. BASALTO 20 MM - 3/4
A2305: 10270914 | B2305: ZFE3 | C2305: 1000 | D2305: M3 | E2305: 1000 | G2305: 1623 | H2305: MP ARENA ANDESITA BC
A2306: 10270824 | B2306: M3 | C2306: 1000 | D2306: M3 | E2306: 10007640 | G2306: 1325 | H2306: MP ARENA TRITURADA CALIZA MALLA 5
A2307: 10270825 | B2307: M3 | C2307: 1000 | D2307: M3 | E2307: 10000003 | G2307: 1242 | H2307: MP GRAVA TRITURADA CALIZA 10MM (3/8”)
... A2319: 10272527 | B2319: ZFE3 | C2319: 1000 | D2319: M3 | E2319: 1000 | G2319: 1620 | H2319: CNC - NO CLASIFICADO
A2320: 10000332 | C2320: 1000 | D2320: M3 | E2320: 1000 | G2320: 800 | H2320: Grava Triturada Pomez - Jal 20 mm - 3/4"
A2321: 10273001 | B2321: ZFE3 | C2321: 1000 | D2321: M3 | E2321: 1000 | G2321: 1688 | H2321: MP ARENA TRIT. BASALTO MALLA 4
A2322: 10273002 | B2322: ZFE3 | C2322: 1000 | D2322: M3 | E2322: 1000 | G2322: 1466 | H2322: MP GRAVA TRIT. BASALTO 20 MM - 3/4"
A2323: 10273351 | B2323: ZFE3 | C2323: 1000 | D2323: M3 | E2323: 1000 | G2323: 1612 | H2323: MP ARENA TRIT. CALIZA MALLA 4
A2324: 10273352 | B2324: ZFE3 | C2324: 1000 | D2324: M3 | E2324: 1000 | G2324: 1492 | H2324: MP GRAVA TRIT. CALIZA 20 MM - 3/4"
A2325: 10271724 | B2325: ZFE3 | C2325: 1000 | D2325: M3 | E2325: 1000 | G2325: 1900 | H2325: MP RESIDUO DE CONCRETO
A2326: 10000677 | C2326: 1000 | D2326: M3 | G2326: 1164 | H2326: Grava Triturada Caliza 20 mm - 3/4"
A2327: 10274190 | B2327: ZFE3 | C2327: 1000 | D2327: M3 | E2327: 1000 | G2327: 1800 | H2327: MP BASE HIDRAULICA ANDESITA 70-30
A2328: 10274601 | B2328: ZFE3 | C2328: 1000 | D2328: M3 | E2328: 1000 | G2328: 1447 | H2328: MP ARENA BASALTO N° 4
...

Sheet TRAOPE
A1: Concat1 | B1: Contrato_Pos | C1: Doc. Compras | D1: Pos | E1: Org.compras | F1: Grp-Compr. | G1: Ship From | H1: Nombre SF | I1: Proveedor | J1: Nombre Prov | K1: Cond. Pago | L1: Descr. Cond Pago | M1: Material | N1: Descripción | O1: Centro | P1: Descripción Centro | Q1: In.perído validez | R1: Fin perído validez | S1: Válido de | T1: Validez a | U1: Precio neto pedido | V1: Moneda | W1: UM Precio Pedido | X1: Importe Condición | Y1: Moneda KONP | Z1: UM Ctd Base | AA1: Destino | AB1: Nombre Destino | AC1: Cuenta de mayor | AD1: Centro de costo | AE1: Cond. Exp. | AF1: Descr. Cond. Exp. | AG1: Peso Vol. | AH1: UMB | AI1: Ind. Oblig. Conf. Ped. | AJ1: Ctrl-Conf. | AK1: IVA | AL1: Modif_Date | AM1: Ruta
A2: 900007337DU126500222110203227 | B2: 4600068730-20 | C2: 4600068730 | D2: 20 | E2: MXPO | F2: MXL | G2: 900007337 | H2: SF TP-SACO MARMOL NEOGEM TORTON | I2: 5077008 | J2: TRANSPORTES LEAL DE VIZARRON SA DE | K2: Z04 | L2: (AP) 30 Dias | M2: 10203227 | N2: PIEDRA DECORATIVA MARMOL BLANCA 1 1/2" - | O2: DU12 | P2: MX-CEDIS NEOGEM | Q2: 20231101 | R2: 20281231 | S2: 20231101 | T2: 20281231 | U2: 4800 | V2: MXN | W2: TN | X2: 2400 | Y2: MXN | Z2: TN | AA2: 65002221 | AB2: MATERIALES LAS TORRES | AC2: 56103637 | AD2: 6622961540 | AE2: 4 | AF2: ENTREGA DIRECTA | AG2: 1 | AH2: TO | AI2: X | AJ2: 4 | AK2: V4 | AL2: 20231109 | AM2: DU12-900007337-65002221-10203227-4
A3: 900007337DU126500222110203226 | B3: 4600068730-10 | C3: 4600068730 | D3: 10 | E3: MXPO | F3: MXL | G3: 900007337 | H3: SF TP-SACO MARMOL NEOGEM TORTON | I3: 5077008 | J3: TRANSPORTES LEAL DE VIZARRON SA DE | K3: Z04 | L3: (AP) 30 Dias | M3: 10203226 | N3: PIEDRA DECORATIVA MARMOL BLANCA 1" - NG | O3: DU12 | P3: MX-CEDIS NEOGEM | Q3: 20231101 | R3: 20281231 | S3: 20231101 | T3: 20281231 | U3: 4800 | V3: MXN | W3: TN | X3: 2400 | Y3: MXN | Z3: TN | AA3: 65002221 | AB3: MATERIALES LAS TORRES | AC3: 56103637 | AD3: 6622961540 | AE3: 4 | AF3: ENTREGA DIRECTA | AG3: 1 | AH3: TO | AI3: X | AJ3: 4 | AK3: V4 | AL3: 20231109 | AM3: DU12-900007337-65002221-10203226-4
A4: 900007337DU126500222110203229 | B4: 4600068730-30 | C4: 4600068730 | D4: 30 | E4: MXPO | F4: MXL | G4: 900007337 | H4: SF TP-SACO MARMOL NEOGEM TORTON | I4: 5077008 | J4: TRANSPORTES LEAL DE VIZARRON SA DE | K4: Z04 | L4: (AP) 30 Dias | M4: 10203229 | N4: PIEDRA DECORATIVA MARMOL NEGRA 1" NG | O4: DU12 | P4: MX-CEDIS NEOGEM | Q4: 20231101 | R4: 20281231 | S4: 20231101 | T4: 20281231 | U4: 6900 | V4: MXN | W4: TN | X4: 3450 | Y4: MXN | Z4: TN | AA4: 65002221 | AB4: MATERIALES LAS TORRES | AC4: 56103637 | AD4: 6622961540 | AE4: 4 | AF4: ENTREGA DIRECTA | AG4: 1 | AH4: TO | AI4: X | AJ4: 4 | AK4: V4 | AL4: 20231109 | AM4: DU12-900007337-65002221-10203229-4
A5: 900007337DU12EB4710204246 | B5: 4600052162-230 | C5: 4600052162 | D5: 230 | E5: MXPO | F5: MXL | G5: 900007337 | H5: SF TP-SACO MARMOL NEOGEM TORTON | I5: 5077008 | J5: TRANSPORTES LEAL DE VIZARRON SA DE | K5: Z04 | L5: (AP) 30 Dias | M5: 10204246 | N5: PIEDRA DECORATIVA MARMOL ROSA 1 1/2" NG | O5: DU12 | P5: MX-CEDIS NEOGEM | Q5: 20211007 | R5: 20281231 | S5: 20230202 | T5: 20281231 | U5: 7400 | V5: MXN | W5: TN | X5: 3700 | Y5: MXN | Z5: TN | AA5: EB47 | AB5: DEPOSITO TOLUCA | AC5: 56103637 | AD5: 6622961540 | AE5: 4 | AF5: ENTREGA DIRECTA | AG5: 1 | AH5: TO | AI5: X | AJ5: 4 | AK5: V4 | AL5: 20230920 | AM5: DU12-900007337-EB47-10204246-4
A6: 900007337DU12EB4710204244 | B6: 4600052162-210 | C6: 4600052162 | D6: 210 | E6: MXPO | F6: MXL | G6: 900007337 | H6: SF TP-SACO MARMOL NEOGEM TORTON | I6: 5077008 | J6: TRANSPORTES LEAL DE VIZARRON SA DE | K6: Z04 | L6: (AP) 30 Dias | M6: 10204244 | N6: PIEDRA DECORATIVA MARMOL AMARILLA 2 1/2" | O6: DU12 | P6: MX-CEDIS NEOGEM | Q6: 20211007 | R6: 20281231 | S6: 20230202 | T6: 20281231 | U6: 7400 | V6: MXN | W6: TN | X6: 3700 | Y6: MXN | Z6: TN | AA6: EB47 | AB6: DEPOSITO TOLUCA | AC6: 56103637 | AD6: 6622961540 | AE6: 4 | AF6: ENTREGA DIRECTA | AG6: 1 | AH6: TO | AI6: X | AJ6: 4 | AK6: V4 | AL6: 20230920 | AM6: DU12-900007337-EB47-10204244-4
A7: 900007337DU12EB4710203226 | B7: 4600052162-130 | C7: 4600052162 | D7: 130 | E7: MXPO | F7: MXL | G7: 900007337 | H7: SF TP-SACO MARMOL NEOGEM TORTON | I7: 5077008 | J7: TRANSPORTES LEAL DE VIZARRON SA DE | K7: Z04 | L7: (AP) 30 Dias | M7: 10203226 | N7: PIEDRA DECORATIVA MARMOL BLANCA 1" - NG | O7: DU12 | P7: MX-CEDIS NEOGEM | Q7: 20211007 | R7: 20281231 | S7: 20230202 | T7: 20281231 | U7: 5200 | V7: MXN | W7: TN | X7: 2600 | Y7: MXN | Z7: TN | AA7: EB47 | AB7: DEPOSITO TOLUCA | AC7: 56103637 | AD7: 6622961540 | AE7: 4 | AF7: ENTREGA DIRECTA | AG7: 1 | AH7: TO | AI7: X | AJ7: 4 | AK7: V4 | AL7: 20230920 | AM7: DU12-900007337-EB47-10203226-4
A8: 900007337DU12EB4710204242 | B8: 4600052162-190 | C8: 4600052162 | D8: 190 | E8: MXPO | F8: MXL | G8: 900007337 | H8: SF TP-SACO MARMOL NEOGEM TORTON | I8: 5077008 | J8: TRANSPORTES LEAL DE VIZARRON SA DE | K8: Z04 | L8: (AP) 30 Dias | M8: 10204242 | N8: PIEDRA DECORATIVA MARMOL AMARILLA 1" NG | O8: DU12 | P8: MX-CEDIS NEOGEM | Q8: 20211007 | R8: 20281231 | S8: 20230202 | T8: 20281231 | U8: 7400 | V8: MXN | W8: TN | X8: 3700 | Y8: MXN | Z8: TN | AA8: EB47 | AB8: DEPOSITO TOLUCA | AC8: 56103637 | AD8: 6622961540 | AE8: 4 | AF8: ENTREGA DIRECTA | AG8: 1 | AH8: TO | AI8: X | AJ8: 4 | AK8: V4 | AL8: 20230920 | AM8: DU12-900007337-EB47-10204242-4
A9: 900007337DU12EB4710204240 | B9: 4600052162-180 | C9: 4600052162 | D9: 180 | E9: MXPO | F9: MXL | G9: 900007337 | H9: SF TP-SACO MARMOL NEOGEM TORTON | I9: 5077008 | J9: TRANSPORTES LEAL DE VIZARRON SA DE | K9: Z04 | L9: (AP) 30 Dias | M9: 10204240 | N9: PIEDRA DECORATIVA MARMOL NEGRA 2 1/2" NG | O9: DU12 | P9: MX-CEDIS NEOGEM | Q9: 20211007 | R9: 20281231 | S9: 20230202 | T9: 20281231 | U9: 7400 | V9: MXN | W9: TN | X9: 3700 | Y9: MXN | Z9: TN | AA9: EB47 | AB9: DEPOSITO TOLUCA | AC9: 56103637 | AD9: 6622961540 | AE9: 4 | AF9: ENTREGA DIRECTA | AG9: 1 | AH9: TO | AI9: X | AJ9: 4 | AK9: V4 | AL9: 20230920 | AM9: DU12-900007337-EB47-10204240-4
A10: 900007337DU12EB4710203227 | B10: 4600052162-140 | C10: 4600052162 | D10: 140 | E10: MXPO | F10: MXL | G10: 900007337 | H10: SF TP-SACO MARMOL NEOGEM TORTON | I10: 5077008 | J10: TRANSPORTES LEAL DE VIZARRON SA DE | K10: Z04 | L10: (AP) 30 Dias | M10: 10203227 | N10: PIEDRA DECORATIVA MARMOL BLANCA 1 1/2" - | O10: DU12 | P10: MX-CEDIS NEOGEM | Q10: 20211007 | R10: 20281231 | S10: 20230202 | T10: 20281231 | U10: 5200 | V10: MXN | W10: TN | X10: 2600 | Y10: MXN | Z10: TN | AA10: EB47 | AB10: DEPOSITO TOLUCA | AC10: 56103637 | AD10: 6622961540 | AE10: 4 | AF10: ENTREGA DIRECTA | AG10: 1 | AH10: TO | AI10: X | AJ10: 4 | AK10: V4 | AL10: 20230920 | AM10: DU12-900007337-EB47-10203227-4
A11: 900007337DU12EB4710203228 | B11: 4600052162-150 | C11: 4600052162 | D11: 150 | E11: MXPO | F11: MXL | G11: 900007337 | H11: SF TP-SACO MARMOL NEOGEM TORTON | I11: 5077008 | J11: TRANSPORTES LEAL DE VIZARRON SA DE | K11: Z04 | L11: (AP) 30 Dias | M11: 10203228 | N11: PIEDRA DECORATIVA MARMOL BLANCA 2 1/2" - | O11: DU12 | P11: MX-CEDIS NEOGEM | Q11: 20211007 | R11: 20281231 | S11: 20230202 | T11: 20281231 | U11: 5200 | V11: MXN | W11: TN | X11: 2600 | Y11: MXN | Z11: TN | AA11: EB47 | AB11: DEPOSITO TOLUCA | AC11: 56103637 | AD11: 6622961540 | AE11: 4 | AF11: ENTREGA DIRECTA | AG11: 1 | AH11: TO | AI11: X | AJ11: 4 | AK11: V4 | AL11: 20230920 | AM11: DU12-900007337-EB47-10203228-4
A12: 900007337DU12EB4710203229 | B12: 4600052162-160 | C12: 4600052162 | D12: 160 | E12: MXPO | F12: MXL | G12: 900007337 | H12: SF TP-SACO MARMOL NEOGEM TORTON | I12: 5077008 | J12: TRANSPORTES LEAL DE VIZARRON SA DE | K12: Z04 | L12: (AP) 30 Dias | M12: 10203229 | N12: PIEDRA DECORATIVA MARMOL NEGRA 1" NG | O12: DU12 | P12: MX-CEDIS NEOGEM | Q12: 20211007 | R12: 20281231 | S12: 20230202 | T12: 20281231 | U12: 7400 | V12: MXN | W12: TN | X12: 3700 | Y12: MXN | Z12: TN | AA12: EB47 | AB12: DEPOSITO TOLUCA | AC12: 56103637 | AD12: 6622961540 | AE12: 4 | AF12: ENTREGA DIRECTA | AG12: 1 | AH12: TO | AI12: X | AJ12: 4 | AK12: V4 | AL12: 20230920 | AM12: DU12-900007337-EB47-10203229-4
A13: 900007337DU12EB4710204243 | B13: 4600052162-200 | C13: 4600052162 | D13: 200 | E13: MXPO | F13: MXL | G13: 900007337 | H13: SF TP-SACO MARMOL NEOGEM TORTON | I13: 5077008 | J13: TRANSPORTES LEAL DE VIZARRON SA DE | K13: Z04 | L13: (AP) 30 Dias | M13: 10204243 | N13: PIEDRA DECORATIVA MARMOL AMARILLA 1 1/2" | O13: DU12 | P13: MX-CEDIS NEOGEM | Q13: 20211007 | R13: 20281231 | S13: 20230202 | T13: 20281231 | U13: 7400 | V13: MXN | W13: TN | X13: 3700 | Y13: MXN | Z13: TN | AA13: EB47 | AB13: DEPOSITO TOLUCA | AC13: 56103637 | AD13: 6622961540 | AE13: 4 | AF13: ENTREGA DIRECTA | AG13: 1 | AH13: TO | AI13: X | AJ13: 4 | AK13: V4 | AL13: 20230920 | AM13: DU12-900007337-EB47-10204243-4
... A16: 900007337DU12EB4710204245 | B16: 4600052162-220 | C16: 4600052162 | D16: 220 | E16: MXPO | F16: MXL | G16: 900007337 | H16: SF TP-SACO MARMOL NEOGEM TORTON | I16: 5077008 | J16: TRANSPORTES LEAL DE VIZARRON SA DE | K16: Z04 | L16: (AP) 30 Dias | M16: 10204245 | N16: PIEDRA DECORATIVA MARMOL ROSA 1" NG | O16: DU12 | P16: MX-CEDIS NEOGEM | Q16: 20211007 | R16: 20281231 | S16: 20230202 | T16: 20281231 | U16: 7400 | V16: MXN | W16: TN | X16: 3700 | Y16: MXN | Z16: TN | AA16: EB47 | AB16: DEPOSITO TOLUCA | AC16: 56103637 | AD16: 6622961540 | AE16: 4 | AF16: ENTREGA DIRECTA | AG16: 1 | AH16: TO | AI16: X | AJ16: 4 | AK16: V4 | AL16: 20230920 | AM16: DU12-900007337-EB47-10204245-4
A17: 900007337DU12EB0610204247 | B17: 4600052162-10 | C17: 4600052162 | D17: 10 | E17: MXPO | F17: MXL | G17: 900007337 | H17: SF TP-SACO MARMOL NEOGEM TORTON | I17: 5077008 | J17: TRANSPORTES LEAL DE VIZARRON SA DE | K17: Z04 | L17: (AP) 30 Dias | M17: 10204247 | N17: PIEDRA DECORATIVA MARMOL ROSAA 2 1/2" NG | O17: DU12 | P17: MX-CEDIS NEOGEM | Q17: 20211007 | R17: 20281231 | U17: 6900 | V17: MXN | W17: TN | AA17: EB06 | AB17: DEPOSITO QUERETARO | AC17: 56103637 | AD17: 6622961540 | AE17: 4 | AF17: ENTREGA DIRECTA | AG17: 1 | AH17: TO | AI17: X | AJ17: 4 | AK17: V4 | AL17: 20230920 | AM17: DU12-900007337-EB06-10204247-4
A18: 900007337DU12EB0610203227 | B18: 4600052162-110 | C18: 4600052162 | D18: 110 | E18: MXPO | F18: MXL | G18: 900007337 | H18: SF TP-SACO MARMOL NEOGEM TORTON | I18: 5077008 | J18: TRANSPORTES LEAL DE VIZARRON SA DE | K18: Z04 | L18: (AP) 30 Dias | M18: 10203227 | N18: PIEDRA DECORATIVA MARMOL BLANCA 1 1/2" - | O18: DU12 | P18: MX-CEDIS NEOGEM | Q18: 20211007 | R18: 20281231 | S18: 20211007 | T18: 20261231 | U18: 4800 | V18: MXN | W18: TN | X18: 2400 | Y18: MXN | Z18: TN | AA18: EB06 | AB18: DEPOSITO QUERETARO | AC18: 56103637 | AD18: 6622961540 | AE18: 4 | AF18: ENTREGA DIRECTA | AG18: 1 | AH18: TO | AI18: X | AJ18: 4 | AK18: V4 | AL18: 20230920 | AM18: DU12-900007337-EB06-10203227-4
A19: 900007338DU12EB0610204247 | B19: 4600052163-10 | C19: 4600052163 | D19: 10 | E19: MXPO | F19: MXL | G19: 900007338 | H19: SF TP-SACO MARMOL NEOGEM TRAILER | I19: 5077008 | J19: TRANSPORTES LEAL DE VIZARRON SA DE | K19: Z04 | L19: (AP) 30 Dias | M19: 10204247 | N19: PIEDRA DECORATIVA MARMOL ROSAA 2 1/2" NG | O19: DU12 | P19: MX-CEDIS NEOGEM | Q19: 20211007 | R19: 20261231 | S19: 20211007 | T19: 20261231 | U19: 6700 | V19: MXN | W19: TN | X19: 3350 | Y19: MXN | Z19: TN | AA19: EB06 | AB19: DEPOSITO QUERETARO | AC19: 56103637 | AD19: 6622961540 | AE19: 4 | AF19: ENTREGA DIRECTA | AG19: 1 | AH19: TO | AI19: X | AJ19: 4 | AK19: V4 | AL19: 20230920 | AM19: DU12-900007338-EB06-10204247-4
A20: 900007338DU12EB0610204246 | B20: 4600052163-20 | C20: 4600052163 | D20: 20 | E20: MXPO | F20: MXL | G20: 900007338 | H20: SF TP-SACO MARMOL NEOGEM TRAILER | I20: 5077008 | J20: TRANSPORTES LEAL DE VIZARRON SA DE | K20: Z04 | L20: (AP) 30 Dias | M20: 10204246 | N20: PIEDRA DECORATIVA MARMOL ROSA 1 1/2" NG | O20: DU12 | P20: MX-CEDIS NEOGEM | Q20: 20211007 | R20: 20261231 | S20: 20211007 | T20: 20261231 | U20: 6700 | V20: MXN | W20: TN | X20: 3350 | Y20: MXN | Z20: TN | AA20: EB06 | AB20: DEPOSITO QUERETARO | AC20: 56103637 | AD20: 6622961540 | AE20: 4 | AF20: ENTREGA DIRECTA | AG20: 1 | AH20: TO | AI20: X | AJ20: 4 | AK20: V4 | AL20: 20230920 | AM20: DU12-900007338-EB06-10204246-4
A21: 900007338DU12EB0610204243 | B21: 4600052163-50 | C21: 4600052163 | D21: 50 | E21: MXPO | F21: MXL | G21: 900007338 | H21: SF TP-SACO MARMOL NEOGEM TRAILER | I21: 5077008 | J21: TRANSPORTES LEAL DE VIZARRON SA DE | K21: Z04 | L21: (AP) 30 Dias | M21: 10204243 | N21: PIEDRA DECORATIVA MARMOL AMARILLA 1 1/2" | O21: DU12 | P21: MX-CEDIS NEOGEM | Q21: 20211007 | R21: 20261231 | S21: 20211007 | T21: 20261231 | U21: 6700 | V21: MXN | W21: TN | X21: 3350 | Y21: MXN | Z21: TN | AA21: EB06 | AB21: DEPOSITO QUERETARO | AC21: 56103637 | AD21: 6622961540 | AE21: 4 | AF21: ENTREGA DIRECTA | AG21: 1 | AH21: TO | AI21: X | AJ21: 4 | AK21: V4 | AL21: 20230920 | AM21: DU12-900007338-EB06-10204243-4
A22: 900007337DU12EB0610204244 | B22: 4600052162-40 | C22: 4600052162 | D22: 40 | E22: MXPO | F22: MXL | G22: 900007337 | H22: SF TP-SACO MARMOL NEOGEM TORTON | I22: 5077008 | J22: TRANSPORTES LEAL DE VIZARRON SA DE | K22: Z04 | L22: (AP) 30 Dias | M22: 10204244 | N22: PIEDRA DECORATIVA MARMOL AMARILLA 2 1/2" | O22: DU12 | P22: MX-CEDIS NEOGEM | Q22: 20211007 | R22: 20281231 | S22: 20211007 | T22: 20261231 | U22: 6900 | V22: MXN | W22: TN | X22: 3450 | Y22: MXN | Z22: TN | AA22: EB06 | AB22: DEPOSITO QUERETARO | AC22: 56103637 | AD22: 6622961540 | AE22: 4 | AF22: ENTREGA DIRECTA | AG22: 1 | AH22: TO | AI22: X | AJ22: 4 | AK22: V4 | AL22: 20230920 | AM22: DU12-900007337-EB06-10204244-4
A23: 900007337DU12EB0610203228 | B23: 4600052162-100 | C23: 4600052162 | D23: 100 | E23: MXPO | F23: MXL | G23: 900007337 | H23: SF TP-SACO MARMOL NEOGEM TORTON | I23: 5077008 | J23: TRANSPORTES LEAL DE VIZARRON SA DE | K23: Z04 | L23: (AP) 30 Dias | M23: 10203228 | N23: PIEDRA DECORATIVA MARMOL BLANCA 2 1/2" - | O23: DU12 | P23: MX-CEDIS NEOGEM | Q23: 20211007 | R23: 20281231 | S23: 20211007 | T23: 20261231 | U23: 4800 | V23: MXN | W23: TN | X23: 2400 | Y23: MXN | Z23: TN | AA23: EB06 | AB23: DEPOSITO QUERETARO | AC23: 56103637 | AD23: 6622961540 | AE23: 4 | AF23: ENTREGA DIRECTA | AG23: 1 | AH23: TO | AI23: X | AJ23: 4 | AK23: V4 | AL23: 20230920 | AM23: DU12-900007337-EB06-10203228-4
A24: 900007338DU12EB0610204245 | B24: 4600052163-30 | C24: 4600052163 | D24: 30 | E24: MXPO | F24: MXL | G24: 900007338 | H24: SF TP-SACO MARMOL NEOGEM TRAILER | I24: 5077008 | J24: TRANSPORTES LEAL DE VIZARRON SA DE | K24: Z04 | L24: (AP) 30 Dias | M24: 10204245 | N24: PIEDRA DECORATIVA MARMOL ROSA 1" NG | O24: DU12 | P24: MX-CEDIS NEOGEM | Q24: 20211007 | R24: 20261231 | S24: 20211007 | T24: 20261231 | U24: 6700 | V24: MXN | W24: TN | X24: 3350 | Y24: MXN | Z24: TN | AA24: EB06 | AB24: DEPOSITO QUERETARO | AC24: 56103637 | AD24: 6622961540 | AE24: 4 | AF24: ENTREGA DIRECTA | AG24: 1 | AH24: TO | AI24: X | AJ24: 4 | AK24: V4 | AL24: 20230920 | AM24: DU12-900007338-EB06-10204245-4
A25: 900007338DU12EB0610204241 | B25: 4600052163-80 | C25: 4600052163 | D25: 80 | E25: MXPO | F25: MXL | G25: 900007338 | H25: SF TP-SACO MARMOL NEOGEM TRAILER | I25: 5077008 | J25: TRANSPORTES LEAL DE VIZARRON SA DE | K25: Z04 | L25: (AP) 30 Dias | M25: 10204241 | N25: PIEDRA DECORATIVA MARMOL NEGRA 1 1/2" NG | O25: DU12 | P25: MX-CEDIS NEOGEM | Q25: 20211007 | R25: 20261231 | S25: 20211007 | T25: 20261231 | U25: 6700 | V25: MXN | W25: TN | X25: 3350 | Y25: MXN | Z25: TN | AA25: EB06 | AB25: DEPOSITO QUERETARO | AC25: 56103637 | AD25: 6622961540 | AE25: 4 | AF25: ENTREGA DIRECTA | AG25: 1 | AH25: TO | AI25: X | AJ25: 4 | AK25: V4 | AL25: 20230920 | AM25: DU12-900007338-EB06-10204241-4
A26: 900007337DU12EB0610203226 | B26: 4600052162-120 | C26: 4600052162 | D26: 120 | E26: MXPO | F26: MXL | G26: 900007337 | H26: SF TP-SACO MARMOL NEOGEM TORTON | I26: 5077008 | J26: TRANSPORTES LEAL DE VIZARRON SA DE | K26: Z04 | L26: (AP) 30 Dias | M26: 10203226 | N26: PIEDRA DECORATIVA MARMOL BLANCA 1" - NG | O26: DU12 | P26: MX-CEDIS NEOGEM | Q26: 20211007 | R26: 20281231 | S26: 20211007 | T26: 20261231 | U26: 4800 | V26: MXN | W26: TN | X26: 2400 | Y26: MXN | Z26: TN | AA26: EB06 | AB26: DEPOSITO QUERETARO | AC26: 56103637 | AD26: 6622961540 | AE26: 4 | AF26: ENTREGA DIRECTA | AG26: 1 | AH26: TO | AI26: X | AJ26: 4 | AK26: V4 | AL26: 20230920 | AM26: DU12-900007337-EB06-10203226-4
A27: 900007338DU12EB0610204242 | B27: 4600052163-60 | C27: 4600052163 | D27: 60 | E27: MXPO | F27: MXL | G27: 900007338 | H27: SF TP-SACO MARMOL NEOGEM TRAILER | I27: 5077008 | J27: TRANSPORTES LEAL DE VIZARRON SA DE | K27: Z04 | L27: (AP) 30 Dias | M27: 10204242 | N27: PIEDRA DECORATIVA MARMOL AMARILLA 1" NG | O27: DU12 | P27: MX-CEDIS NEOGEM | Q27: 20211007 | R27: 20261231 | S27: 20211007 | T27: 20261231 | U27: 6700 | V27: MXN | W27: TN | X27: 3350 | Y27: MXN | Z27: TN | AA27: EB06 | AB27: DEPOSITO QUERETARO | AC27: 56103637 | AD27: 6622961540 | AE27: 4 | AF27: ENTREGA DIRECTA | AG27: 1 | AH27: TO | AI27: X | AJ27: 4 | AK27: V4 | AL27: 20230920 | AM27: DU12-900007338-EB06-10204242-4
A28: 900007338DU12EB0610203228 | B28: 4600052163-100 | C28: 4600052163 | D28: 100 | E28: MXPO | F28: MXL | G28: 900007338 | H28: SF TP-SACO MARMOL NEOGEM TRAILER | I28: 5077008 | J28: TRANSPORTES LEAL DE VIZARRON SA DE | K28: Z04 | L28: (AP) 30 Dias | M28: 10203228 | N28: PIEDRA DECORATIVA MARMOL BLANCA 2 1/2" - | O28: DU12 | P28: MX-CEDIS NEOGEM | Q28: 20211007 | R28: 20261231 | S28: 20211007 | T28: 20261231 | U28: 4600 | V28: MXN | W28: TN | X28: 2300 | Y28: MXN | Z28: TN | AA28: EB06 | AB28: DEPOSITO QUERETARO | AC28: 56103637 | AD28: 6622961540 | AE28: 4 | AF28: ENTREGA DIRECTA | AG28: 1 | AH28: TO | AI28: X | AJ28: 4 | AK28: V4 | AL28: 20230920 | AM28: DU12-900007338-EB06-10203228-4
A29: 900007337DU12EB0610204246 | B29: 4600052162-20 | C29: 4600052162 | D29: 20 | E29: MXPO | F29: MXL | G29: 900007337 | H29: SF TP-SACO MARMOL NEOGEM TORTON | I29: 5077008 | J29: TRANSPORTES LEAL DE VIZARRON SA DE | K29: Z04 | L29: (AP) 30 Dias | M29: 10204246 | N29: PIEDRA DECORATIVA MARMOL ROSA 1 1/2" NG | O29: DU12 | P29: MX-CEDIS NEOGEM | Q29: 20211007 | R29: 20281231 | S29: 20211007 | T29: 20261231 | U29: 6900 | V29: MXN | W29: TN | X29: 3450 | Y29: MXN | Z29: TN | AA29: EB06 | AB29: DEPOSITO QUERETARO | AC29: 56103637 | AD29: 6622961540 | AE29: 4 | AF29: ENTREGA DIRECTA | AG29: 1 | AH29: TO | AI29: X | AJ29: 4 | AK29: V4 | AL29: 20230920 | AM29: DU12-900007337-EB06-10204246-4
... A40: 900007337DU12EB0610204242 | B40: 4600052162-60 | C40: 4600052162 | D40: 60 | E40: MXPO | F40: MXL | G40: 900007337 | H40: SF TP-SACO MARMOL NEOGEM TORTON | I40: 5077008 | J40: TRANSPORTES LEAL DE VIZARRON SA DE | K40: Z04 | L40: (AP) 30 Dias | M40: 10204242 | N40: PIEDRA DECORATIVA MARMOL AMARILLA 1" NG | O40: DU12 | P40: MX-CEDIS NEOGEM | Q40: 20211007 | R40: 20281231 | S40: 20211007 | T40: 20261231 | U40: 6900 | V40: MXN | W40: TN | X40: 3450 | Y40: MXN | Z40: TN | AA40: EB06 | AB40: DEPOSITO QUERETARO | AC40: 56103637 | AD40: 6622961540 | AE40: 4 | AF40: ENTREGA DIRECTA | AG40: 1 | AH40: TO | AI40: X | AJ40: 4 | AK40: V4 | AL40: 20230920 | AM40: DU12-900007337-EB06-10204242-4
