Workbook

Sheet Base Cedis DW67
N1: VENTA | Q1: COSTO
A2: CONCAT1 | B2: CONCAT2 | C2: No. SF | D2: Nombre SF | E2: Cedis | F2: Destino | G2: Condicion de Expedicion | H2: Nombre Destino | I2: No. de material | J2: Nombre de material | K2: PV | L2: Inicio de vigencia | M2: Fin de vigencia | N2: Importe MP | O2: Importe Flete | P2: UM Venta | Q2: Importe Costo | R2: UM Costo | S2: Validacion 1 | T2: Validacion 2
A3: =CONCATENATE(C3,E3,F3,I3) | B3: =CONCATENATE(C3,E3,I3) | C3: 900000000 | D3: =IFERROR(VLOOKUP(C3,TRAOPE!$G:$H,2,0),"") | E3: DW67 | F3: D180 | G3: =IFERROR(VLOOKUP(A3,Flete!$A:$E,5,0),"") | H3: =IFERROR(VLOOKUP(F3,TRAOPE!$AA:$AB,2,0),"") | I3: 10000178 | J3: =IFERROR(VLOOKUP(I3,Materiales!$A:$H,8,0),"") | K3: =IFERROR(VLOOKUP(I3,Materiales!$A:$G,7,0),"") | L3: 20220516 | M3: 20230511 | N3: 82.95 | O3: =IFERROR(VLOOKUP(A3,Flete!$A:$J,10,0),"") | P3: TN | Q3: =IFERROR(IFERROR(VLOOKUP(A3,TRAOPE!$A:$U,21,0),VLOOKUP(B3,TRAOPE!$A:$U,21,0)),"") | R3: =IFERROR(IFERROR(VLOOKUP(A3,TRAOPE!$A:$W,23,0),VLOOKUP(B3,TRAOPE!$A:$W,23,0)),"") | S3: =IF(AND(P3="TN",R3="TN"),N3+N(O3),IF(G3&""="1",N(K3)*N3,(N3+N(O3))*N(K3))) | T3: =IF(Q3="","",Q3-S3)
A4: =CONCATENATE(C4,E4,F4,I4) | B4: =CONCATENATE(C4,E4,I4) | C4: 900000000 | D4: =IFERROR(VLOOKUP(C4,TRAOPE!$G:$H,2,0),"") | E4: DW67 | F4: D180 | G4: =IFERROR(VLOOKUP(A4,Flete!$A:$E,5,0),"") | H4: =IFERROR(VLOOKUP(F4,TRAOPE!$AA:$AB,2,0),"") | I4: 10000826 | J4: =IFERROR(VLOOKUP(I4,Materiales!$A:$H,8,0),"") | K4: =IFERROR(VLOOKUP(I4,Materiales!$A:$G,7,0),"") | L4: 20220516 | M4: 20230511 | N4: 62.07 | O4: =IFERROR(VLOOKUP(A4,Flete!$A:$J,10,0),"") | P4: TN | Q4: =IFERROR(IFERROR(VLOOKUP(A4,TRAOPE!$A:$U,21,0),VLOOKUP(B4,TRAOPE!$A:$U,21,0)),"") | R4: =IFERROR(IFERROR(VLOOKUP(A4,TRAOPE!$A:$W,23,0),VLOOKUP(B4,TRAOPE!$A:$W,23,0)),"") | S4: =IF(AND(P4="TN",R4="TN"),N4+N(O4),IF(G4&""="1",N(K4)*N4,(N4+N(O4))*N(K4))) | T4: =IF(Q4="","",Q4-S4)
A5: =CONCATENATE(C5,E5,F5,I5) | B5: =CONCATENATE(C5,E5,I5) | C5: 900000000 | D5: =IFERROR(VLOOKUP(C5,TRAOPE!$G:$H,2,0),"") | E5: DW67 | F5: D302 | G5: =IFERROR(VLOOKUP(A5,Flete!$A:$E,5,0),"") | H5: =IFERROR(VLOOKUP(F5,TRAOPE!$AA:$AB,2,0),"") | I5: 10000139 | J5: =IFERROR(VLOOKUP(I5,Materiales!$A:$H,8,0),"") | K5: =IFERROR(VLOOKUP(I5,Materiales!$A:$G,7,0),"") | L5: 20220516 | M5: 20241113 | N5: 53.39 | O5: =IFERROR(VLOOKUP(A5,Flete!$A:$J,10,0),"") | P5: TN | Q5: =IFERROR(IFERROR(VLOOKUP(A5,TRAOPE!$A:$U,21,0),VLOOKUP(B5,TRAOPE!$A:$U,21,0)),"") | R5: =IFERROR(IFERROR(VLOOKUP(A5,TRAOPE!$A:$W,23,0),VLOOKUP(B5,TRAOPE!$A:$W,23,0)),"") | S5: =IF(AND(P5="TN",R5="TN"),N5+N(O5),IF(G5&""="1",N(K5)*N5,(N5+N(O5))*N(K5))) | T5: =IF(Q5="","",Q5-S5)
A6: =CONCATENATE(C6,E6,F6,I6) | B6: =CONCATENATE(C6,E6,I6) | C6: 900000000 | D6: =IFERROR(VLOOKUP(C6,TRAOPE!$G:$H,2,0),"") | E6: DW67 | F6: D302 | G6: =IFERROR(VLOOKUP(A6,Flete!$A:$E,5,0),"") | H6: =IFERROR(VLOOKUP(F6,TRAOPE!$AA:$AB,2,0),"") | I6: 10000178 | J6: =IFERROR(VLOOKUP(I6,Materiales!$A:$H,8,0),"") | K6: =IFERROR(VLOOKUP(I6,Materiales!$A:$G,7,0),"") | L6: 20240723 | M6: 99991231 | N6: 232.25 | O6: =IFERROR(VLOOKUP(A6,Flete!$A:$J,10,0),"") | P6: TN | Q6: =IFERROR(IFERROR(VLOOKUP(A6,TRAOPE!$A:$U,21,0),VLOOKUP(B6,TRAOPE!$A:$U,21,0)),"") | R6: =IFERROR(IFERROR(VLOOKUP(A6,TRAOPE!$A:$W,23,0),VLOOKUP(B6,TRAOPE!$A:$W,23,0)),"") | S6: =IF(AND(P6="TN",R6="TN"),N6+N(O6),IF(G6&""="1",N(K6)*N6,(N6+N(O6))*N(K6))) | T6: =IF(Q6="","",Q6-S6)
A7: =CONCATENATE(C7,E7,F7,I7) | B7: =CONCATENATE(C7,E7,I7) | C7: 900000000 | D7: =IFERROR(VLOOKUP(C7,TRAOPE!$G:$H,2,0),"") | E7: DW67 | F7: D302 | G7: =IFERROR(VLOOKUP(A7,Flete!$A:$E,5,0),"") | H7: =IFERROR(VLOOKUP(F7,TRAOPE!$AA:$AB,2,0),"") | I7: 10000398 | J7: =IFERROR(VLOOKUP(I7,Materiales!$A:$H,8,0),"") | K7: =IFERROR(VLOOKUP(I7,Materiales!$A:$G,7,0),"") | L7: 20220516 | M7: 20241113 | N7: 48.43 | O7: =IFERROR(VLOOKUP(A7,Flete!$A:$J,10,0),"") | P7: TN | Q7: =IFERROR(IFERROR(VLOOKUP(A7,TRAOPE!$A:$U,21,0),VLOOKUP(B7,TRAOPE!$A:$U,21,0)),"") | R7: =IFERROR(IFERROR(VLOOKUP(A7,TRAOPE!$A:$W,23,0),VLOOKUP(B7,TRAOPE!$A:$W,23,0)),"") | S7: =IF(AND(P7="TN",R7="TN"),N7+N(O7),IF(G7&""="1",N(K7)*N7,(N7+N(O7))*N(K7))) | T7: =IF(Q7="","",Q7-S7)
A8: =CONCATENATE(C8,E8,F8,I8) | B8: =CONCATENATE(C8,E8,I8) | C8: 900000000 | D8: =IFERROR(VLOOKUP(C8,TRAOPE!$G:$H,2,0),"") | E8: DW67 | F8: D302 | G8: =IFERROR(VLOOKUP(A8,Flete!$A:$E,5,0),"") | H8: =IFERROR(VLOOKUP(F8,TRAOPE!$AA:$AB,2,0),"") | I8: 10000541 | J8: =IFERROR(VLOOKUP(I8,Materiales!$A:$H,8,0),"") | K8: =IFERROR(VLOOKUP(I8,Materiales!$A:$G,7,0),"") | L8: 20250923 | M8: 99991231 | N8: 163.61 | O8: =IFERROR(VLOOKUP(A8,Flete!$A:$J,10,0),"") | P8: TN | Q8: =IFERROR(IFERROR(VLOOKUP(A8,TRAOPE!$A:$U,21,0),VLOOKUP(B8,TRAOPE!$A:$U,21,0)),"") | R8: =IFERROR(IFERROR(VLOOKUP(A8,TRAOPE!$A:$W,23,0),VLOOKUP(B8,TRAOPE!$A:$W,23,0)),"") | S8: =IF(AND(P8="TN",R8="TN"),N8+N(O8),IF(G8&""="1",N(K8)*N8,(N8+N(O8))*N(K8))) | T8: =IF(Q8="","",Q8-S8)
A9: =CONCATENATE(C9,E9,F9,I9) | B9: =CONCATENATE(C9,E9,I9) | C9: 900000000 | D9: =IFERROR(VLOOKUP(C9,TRAOPE!$G:$H,2,0),"") | E9: DW67 | F9: D302 | G9: =IFERROR(VLOOKUP(A9,Flete!$A:$E,5,0),"") | H9: =IFERROR(VLOOKUP(F9,TRAOPE!$AA:$AB,2,0),"") | I9: 10000826 | J9: =IFERROR(VLOOKUP(I9,Materiales!$A:$H,8,0),"") | K9: =IFERROR(VLOOKUP(I9,Materiales!$A:$G,7,0),"") | L9: 20250707 | M9: 99991231 | N9: 172.41 | O9: =IFERROR(VLOOKUP(A9,Flete!$A:$J,10,0),"") | P9: TN | Q9: =IFERROR(IFERROR(VLOOKUP(A9,TRAOPE!$A:$U,21,0),VLOOKUP(B9,TRAOPE!$A:$U,21,0)),"") | R9: =IFERROR(IFERROR(VLOOKUP(A9,TRAOPE!$A:$W,23,0),VLOOKUP(B9,TRAOPE!$A:$W,23,0)),"") | S9: =IF(AND(P9="TN",R9="TN"),N9+N(O9),IF(G9&""="1",N(K9)*N9,(N9+N(O9))*N(K9))) | T9: =IF(Q9="","",Q9-S9)
A10: =CONCATENATE(C10,E10,F10,I10) | B10: =CONCATENATE(C10,E10,I10) | C10: 900000000 | D10: =IFERROR(VLOOKUP(C10,TRAOPE!$G:$H,2,0),"") | E10: DW67 | F10: D310 | G10: =IFERROR(VLOOKUP(A10,Flete!$A:$E,5,0),"") | H10: =IFERROR(VLOOKUP(F10,TRAOPE!$AA:$AB,2,0),"") | I10: 10000178 | J10: =IFERROR(VLOOKUP(I10,Materiales!$A:$H,8,0),"") | K10: =IFERROR(VLOOKUP(I10,Materiales!$A:$G,7,0),"") | L10: 20220516 | M10: 20241113 | N10: 86 | O10: =IFERROR(VLOOKUP(A10,Flete!$A:$J,10,0),"") | P10: TN | Q10: =IFERROR(IFERROR(VLOOKUP(A10,TRAOPE!$A:$U,21,0),VLOOKUP(B10,TRAOPE!$A:$U,21,0)),"") | R10: =IFERROR(IFERROR(VLOOKUP(A10,TRAOPE!$A:$W,23,0),VLOOKUP(B10,TRAOPE!$A:$W,23,0)),"") | S10: =IF(AND(P10="TN",R10="TN"),N10+N(O10),IF(G10&""="1",N(K10)*N10,(N10+N(O10))*N(K10))) | T10: =IF(Q10="","",Q10-S10)
A11: =CONCATENATE(C11,E11,F11,I11) | B11: =CONCATENATE(C11,E11,I11) | C11: 900000000 | D11: =IFERROR(VLOOKUP(C11,TRAOPE!$G:$H,2,0),"") | E11: DW67 | F11: D310 | G11: =IFERROR(VLOOKUP(A11,Flete!$A:$E,5,0),"") | H11: =IFERROR(VLOOKUP(F11,TRAOPE!$AA:$AB,2,0),"") | I11: 10000398 | J11: =IFERROR(VLOOKUP(I11,Materiales!$A:$H,8,0),"") | K11: =IFERROR(VLOOKUP(I11,Materiales!$A:$G,7,0),"") | L11: 20220516 | M11: 20241113 | N11: 26.36 | O11: =IFERROR(VLOOKUP(A11,Flete!$A:$J,10,0),"") | P11: TN | Q11: =IFERROR(IFERROR(VLOOKUP(A11,TRAOPE!$A:$U,21,0),VLOOKUP(B11,TRAOPE!$A:$U,21,0)),"") | R11: =IFERROR(IFERROR(VLOOKUP(A11,TRAOPE!$A:$W,23,0),VLOOKUP(B11,TRAOPE!$A:$W,23,0)),"") | S11: =IF(AND(P11="TN",R11="TN"),N11+N(O11),IF(G11&""="1",N(K11)*N11,(N11+N(O11))*N(K11))) | T11: =IF(Q11="","",Q11-S11)
A12: =CONCATENATE(C12,E12,F12,I12) | B12: =CONCATENATE(C12,E12,I12) | C12: 900000000 | D12: =IFERROR(VLOOKUP(C12,TRAOPE!$G:$H,2,0),"") | E12: DW67 | F12: D310 | G12: =IFERROR(VLOOKUP(A12,Flete!$A:$E,5,0),"") | H12: =IFERROR(VLOOKUP(F12,TRAOPE!$AA:$AB,2,0),"") | I12: 10000541 | J12: =IFERROR(VLOOKUP(I12,Materiales!$A:$H,8,0),"") | K12: =IFERROR(VLOOKUP(I12,Materiales!$A:$G,7,0),"") | L12: 20220516 | M12: 20241113 | N12: 84.82 | O12: =IFERROR(VLOOKUP(A12,Flete!$A:$J,10,0),"") | P12: TN | Q12: =IFERROR(IFERROR(VLOOKUP(A12,TRAOPE!$A:$U,21,0),VLOOKUP(B12,TRAOPE!$A:$U,21,0)),"") | R12: =IFERROR(IFERROR(VLOOKUP(A12,TRAOPE!$A:$W,23,0),VLOOKUP(B12,TRAOPE!$A:$W,23,0)),"") | S12: =IF(AND(P12="TN",R12="TN"),N12+N(O12),IF(G12&""="1",N(K12)*N12,(N12+N(O12))*N(K12))) | T12: =IF(Q12="","",Q12-S12)
A13: =CONCATENATE(C13,E13,F13,I13) | B13: =CONCATENATE(C13,E13,I13) | C13: 900000000 | D13: =IFERROR(VLOOKUP(C13,TRAOPE!$G:$H,2,0),"") | E13: DW67 | F13: D310 | G13: =IFERROR(VLOOKUP(A13,Flete!$A:$E,5,0),"") | H13: =IFERROR(VLOOKUP(F13,TRAOPE!$AA:$AB,2,0),"") | I13: 10000826 | J13: =IFERROR(VLOOKUP(I13,Materiales!$A:$H,8,0),"") | K13: =IFERROR(VLOOKUP(I13,Materiales!$A:$G,7,0),"") | L13: 20220516 | M13: 20241113 | N13: 58.1 | O13: =IFERROR(VLOOKUP(A13,Flete!$A:$J,10,0),"") | P13: TN | Q13: =IFERROR(IFERROR(VLOOKUP(A13,TRAOPE!$A:$U,21,0),VLOOKUP(B13,TRAOPE!$A:$U,21,0)),"") | R13: =IFERROR(IFERROR(VLOOKUP(A13,TRAOPE!$A:$W,23,0),VLOOKUP(B13,TRAOPE!$A:$W,23,0)),"") | S13: =IF(AND(P13="TN",R13="TN"),N13+N(O13),IF(G13&""="1",N(K13)*N13,(N13+N(O13))*N(K13))) | T13: =IF(Q13="","",Q13-S13)
A14: =CONCATENATE(C14,E14,F14,I14) | B14: =CONCATENATE(C14,E14,I14) | C14: 900000037 | D14: =IFERROR(VLOOKUP(C14,TRAOPE!$G:$H,2,0),"") | E14: DW67 | F14: D180 | G14: =IFERROR(VLOOKUP(A14,Flete!$A:$E,5,0),"") | H14: =IFERROR(VLOOKUP(F14,TRAOPE!$AA:$AB,2,0),"") | I14: 10000139 | J14: =IFERROR(VLOOKUP(I14,Materiales!$A:$H,8,0),"") | K14: =IFERROR(VLOOKUP(I14,Materiales!$A:$G,7,0),"") | L14: 20220516 | M14: 20230511 | N14: 44.85 | O14: =IFERROR(VLOOKUP(A14,Flete!$A:$J,10,0),"") | P14: TN | Q14: =IFERROR(IFERROR(VLOOKUP(A14,TRAOPE!$A:$U,21,0),VLOOKUP(B14,TRAOPE!$A:$U,21,0)),"") | R14: =IFERROR(IFERROR(VLOOKUP(A14,TRAOPE!$A:$W,23,0),VLOOKUP(B14,TRAOPE!$A:$W,23,0)),"") | S14: =IF(AND(P14="TN",R14="TN"),N14+N(O14),IF(G14&""="1",N(K14)*N14,(N14+N(O14))*N(K14))) | T14: =IF(Q14="","",Q14-S14)
... A151: =CONCATENATE(C151,E151,F151,I151) | B151: =CONCATENATE(C151,E151,I151) | C151: 900009524 | D151: =IFERROR(VLOOKUP(C151,TRAOPE!$G:$H,2,0),"") | E151: DW67 | F151: D302 | G151: =IFERROR(VLOOKUP(A151,Flete!$A:$E,5,0),"") | H151: =IFERROR(VLOOKUP(F151,TRAOPE!$AA:$AB,2,0),"") | I151: 10217663 | J151: =IFERROR(VLOOKUP(I151,Materiales!$A:$H,8,0),"") | K151: =IFERROR(VLOOKUP(I151,Materiales!$A:$G,7,0),"") | L151: 20260804 | M151: 99991231 | N151: 82.42 | O151: =IFERROR(VLOOKUP(A151,Flete!$A:$J,10,0),"") | P151: TN | Q151: =IFERROR(IFERROR(VLOOKUP(A151,TRAOPE!$A:$U,21,0),VLOOKUP(B151,TRAOPE!$A:$U,21,0)),"") | R151: =IFERROR(IFERROR(VLOOKUP(A151,TRAOPE!$A:$W,23,0),VLOOKUP(B151,TRAOPE!$A:$W,23,0)),"") | S151: =IF(AND(P151="TN",R151="TN"),N151+N(O151),IF(G151&""="1",N(K151)*N151,(N151+N(O151))*N(K151))) | T151: =IF(Q151="","",Q151-S151)

Sheet MP
A1: No. SF | B1: Cedis | C1: Destino | D1: No. Material | E1: Nombre Material | F1: Importe MP | G1: Moneda | H1: Cantidad | I1: UM | J1: C | K1: Inicio Vigencia | L1: Fin Vigencia
A2: 900000000 | B2: DW67 | C2: D180 | D2: 10000178 | F2: 82.95 | I2: TN | K2: 20220516 | L2: 20230511
A3: 900000000 | B3: DW67 | C3: D180 | D3: 10000826 | F3: 62.07 | I3: TN | K3: 20220516 | L3: 20230511
A4: 900000000 | B4: DW67 | C4: D302 | D4: 10000139 | F4: 53.39 | I4: TN | K4: 20220516 | L4: 20241113
A5: 900000000 | B5: DW67 | C5: D302 | D5: 10000178 | F5: 232.25 | I5: TN | K5: 20240723 | L5: 99991231
A6: 900000000 | B6: DW67 | C6: D302 | D6: 10000398 | F6: 48.43 | I6: TN | K6: 20220516 | L6: 20241113
A7: 900000000 | B7: DW67 | C7: D302 | D7: 10000541 | F7: 163.61 | I7: TN | K7: 20250923 | L7: 99991231
A8: 900000000 | B8: DW67 | C8: D302 | D8: 10000826 | F8: 172.41 | I8: TN | K8: 20250707 | L8: 99991231
A9: 900000000 | B9: DW67 | C9: D310 | D9: 10000178 | F9: 86 | I9: TN | K9: 20220516 | L9: 20241113
A10: 900000000 | B10: DW67 | C10: D310 | D10: 10000398 | F10: 26.36 | I10: TN | K10: 20220516 | L10: 20241113
A11: 900000000 | B11: DW67 | C11: D310 | D11: 10000541 | F11: 84.82 | I11: TN | K11: 20220516 | L11: 20241113
A12: 900000000 | B12: DW67 | C12: D310 | D12: 10000826 | F12: 58.1 | I12: TN | K12: 20220516 | L12: 20241113
A13: 900000037 | B13: DW67 | C13: D180 | D13: 10000139 | F13: 44.85 | I13: TN | K13: 20220516 | L13: 20230511
... A150: 900009524 | B150: DW67 | C150: D302 | D150: 10217663 | F150: 82.42 | I150: TN | K150: 20260804 | L150: 99991231

Sheet Flete
A1: Concat1 | B1: No. SF | C1: Cedis | D1: Destino | E1: Cond. Exp. | F1: Material | H1: Nombre Material | J1: Importe Flete | K1: Moneda | L1: Cantidad | M1: UM | N1: C | P1: Inicio Vigencia | Q1: Fin Vigencia
A2: 900000000DW67D30210000139 | B2: 900000000 | C2: DW67 | D2: D302 | E2: 4 | F2: 10000139 | J2: 221.21 | M2: TN | P2: 20220516 | Q2: 99991231
A3: 900000000DW67D30210000178 | B3: 900000000 | C3: DW67 | D3: D302 | E3: 4 | F3: 10000178 | J3: 99.54 | M3: TN | P3: 20240723 | Q3: 99991231
A4: 900000000DW67D30210000398 | B4: 900000000 | C4: DW67 | D4: D302 | E4: 4 | F4: 10000398 | J4: 191.85 | M4: TN | P4: 20220516 | Q4: 20241113
A5: 900000000DW67D30210000541 | B5: 900000000 | C5: DW67 | D5: D302 | E5: 4 | F5: 10000541 | J5: 163.61 | M5: TN | P5: 20250923 | Q5: 99991231
A6: 900000000DW67D30210000826 | B6: 900000000 | C6: DW67 | D6: D302 | E6: 4 | F6: 10000826 | J6: 137.93 | M6: TN | P6: 20250707 | Q6: 99991231
A7: 900000000DW67D31010000178 | B7: 900000000 | C7: DW67 | D7: D310 | E7: 4 | F7: 10000178 | J7: 40.13 | M7: TN | P7: 20220516 | Q7: 20241113
A8: 900000000DW67D31010000398 | B8: 900000000 | C8: DW67 | D8: D310 | E8: 4 | F8: 10000398 | J8: 169.7 | M8: TN | P8: 20220516 | Q8: 20241113
A9: 900000000DW67D31010000541 | B9: 900000000 | C9: DW67 | D9: D310 | E9: 4 | F9: 10000541 | J9: 42.41 | M9: TN | P9: 20220516 | Q9: 20241113
A10: 900000000DW67D31010000826 | B10: 900000000 | C10: DW67 | D10: D310 | E10: 4 | F10: 10000826 | J10: 61.08 | M10: TN | P10: 20220516 | Q10: 20241113
A11: 900000037DW67D30210000139 | B11: 900000037 | C11: DW67 | D11: D302 | E11: 1 | F11: 10000139 | J11: 361.32 | M11: TN | P11: 20251229 | Q11: 99991231
A12: 900000037DW67D30210000140 | B12: 900000037 | C12: DW67 | D12: D302 | E12: 1 | F12: 10000140 | J12: 234.91 | M12: TN | P12: 20240726 | Q12: 20251031
A13: 900000037DW67D30210000444 | B13: 900000037 | C13: DW67 | D13: D302 | E13: 1 | F13: 10000444 | J13: 205.72 | M13: TN | P13: 20251229 | Q13: 99991231
... A118: DW67DW67D30210000139 | B118: DW67 | C118: DW67 | D118: D302 | E118: 1 | F118: 10000139 | J118: 246.55 | M118: TN | P118: 20220124 | Q118: 99991231

Sheet Materiales
A1: Material | B1: TpMt | C1: Denom | D1: UMA | E1: Contador | F1: UMB | G1: PV | H1: Nombre Material
A2: 10000001 | B2: ZFER | C2: 1000 | D2: M3 | E2: 1000 | F2: TN | G2: 1262 | H2: GRAVA ANDESITA 10 MM (3/8")
A3: 10000003 | B3: ZFER | C3: 1000 | D3: M3 | E3: 1000 | F3: TN | G3: 1443 | H3: GRAVA CALIZA 10 MM (3/8")
A4: 10000006 | B4: ZFER | C4: 1000 | D4: M3 | E4: 1000 | F4: TN | G4: 1490 | H4: GRAVA RIO 10 MM (3/8")
A5: 10000007 | B5: ZFER | C5: 1000 | D5: M3 | E5: 1000 | F5: TN | G5: 1488 | H5: GRAVA BASALTO 13 MM (1/2")
A6: 10000008 | B6: ZFER | C6: 1000 | D6: M3 | E6: 1000 | F6: TN | G6: 1358 | H6: GRAVA CALIZA 13 MM (1/2")
A7: 10000011 | B7: ZFER | C7: 1000 | D7: M3 | E7: 1000 | F7: TN | G7: 1323 | H7: GRAVA ANDESITA 20 MM (3/4")
A8: 10000013 | B8: ZFER | C8: 1000 | D8: M3 | E8: 1000 | F8: TN | G8: 1514 | H8: GRAVA BASALTO 20 MM (3/4")
A9: 10000014 | B9: ZFER | C9: 1000 | D9: M3 | E9: 1000 | F9: TN | G9: 1400 | H9: GRAVA CALIZA 20 MM (3/4")
A10: 10000015 | B10: ZFER | C10: 1000 | D10: M3 | E10: 1000 | F10: TN | G10: 1410 | H10: GRAVA GRANITO 20 MM (3/4")
A11: 10000017 | B11: ZFER | C11: 1000 | D11: M3 | E11: 1000 | F11: TN | G11: 1475 | H11: GRAVA RIOLITA 20 MM (3/4")
A12: 10000019 | B12: ZFER | C12: 1000 | D12: M3 | E12: 1000 | F12: TN | G12: 1515 | H12: GRAVA RIO 20 MM (3/4")
A13: 10000020 | B13: ZFER | C13: 1000 | D13: M3 | E13: 1 | F13: TN | G13: 1 | H13: GRAVA MAQUILA 40MM (1 1/2")
... A2291: 10268770 | B2291: ZFE3 | C2291: 1000 | D2291: M3 | E2291: 1000 | F2291: TN | G2291: 1240 | H2291: MP GRAVA TRIT CALIZA 40MM 1 1/2" - ESP
A2292: 10268901 | B2292: ZFE3 | C2292: 1000 | D2292: M3 | E2292: 1000 | G2292: 1560 | H2292: MP GRAVA ANDESITA GRIS 3/4" - CAPADA
A2293: 10267983 | C2293: 1000 | G2293: 1800 | H2293: ESCORIA ALTO HORNO 3/4
A2294: 10268996 | C2294: 1000 | G2294: 1329 | H2294: GRAVA TRITURADA CALIZA 40 MM - 11/2"
A2295: 10269072 | C2295: 1000 | G2295: 1700 | H2295: BASE HIDRÁULICA SCREEN
A2296: 10269225 | B2296: ZFE3 | C2296: 1000 | D2296: M3 | E2296: 1000 | G2296: 1289 | H2296: MP ARENA CALIZA LAVADA MALLA 4 - DELTA I
A2297: 10269245 | B2297: ZFE3 | C2297: 1000 | D2297: M3 | E2297: 1000 | G2297: 1410 | H2297: MP GRAVA TRITURADA CALIZA 3/8 - 10MM
A2298: 10269246 | B2298: ZFE3 | C2298: 1000 | D2298: M3 | E2298: 1000 | G2298: 1400 | H2298: MP GRAVA TRITURADA CALIZA 1 1/2 - 40MM
A2299: 10269247 | B2299: ZFE3 | C2299: 1000 | D2299: M3 | E2299: 1000 | G2299: 1560 | H2299: MP ARENA TRIT CALIZA M-4
A2300: 10270431 | B2300: ZFE3 | C2300: 1000 | D2300: M3 | E2300: 1000 | G2300: 1423 | H2300: MP GRAVA RIOLITA 13 MM - 1/2"
A2301: 10270898 | B2301: ZFE3 | C2301: 1000 | D2301: M3 | E2301: 1000 | G2301: 1551 | H2301: MP BASE H. TRIT. BASALTO 1 1/2" A FINOS
A2302: 10270911 | B2302: ZFE3 | C2302: 1000 | D2302: M3 | E2302: 1000 | G2302: 1360 | H2302: MP GRAVA TRIT. BASALTO 40 MM - 1 1/2"
A2303: 10270912 | B2303: ZFE3 | C2303: 1000 | D2303: M3 | E2303: 1000 | G2303: 1589 | H2303: MP ARENA TRIT. BASALTO MALLA 4
A2304: 10270913 | B2304: ZFE3 | C2304: 1000 | D2304: M3 | E2304: 1000 | G2304: 1395 | H2304: MP GRAVA TRIT. BASALTO 20 MM - 3/4
A2305: 10270914 | B2305: ZFE3 | C2305: 1000 | D2305: M3 | E2305: 1000 | G2305: 1623 | H2305: MP ARENA ANDESITA BC
A2306: 10270824 | B2306: M3 | C2306: 1000 | D2306: M3 | E2306: 10007640 | G2306: 1325 | H2306: MP ARENA TRITURADA CALIZA MALLA 5
A2307: 10270825 | B2307: M3 | C2307: 1000 | D2307: M3 | E2307: 10000003 | G2307: 1242 | H2307: MP GRAVA TRITURADA CALIZA 10MM (3/8”)
... A2319: 10272527 | B2319: ZFE3 | C2319: 1000 | D2319: M3 | E2319: 1000 | G2319: 1620 | H2319: CNC - NO CLASIFICADO
A2320: 10000332 | C2320: 1000 | D2320: M3 | E2320: 1000 | G2320: 800 | H2320: Grava Triturada Pomez - Jal 20 mm - 3/4"
A2321: 10273001 | B2321: ZFE3 | C2321: 1000 | D2321: M3 | E2321: 1000 | G2321: 1688 | H2321: MP ARENA TRIT. BASALTO MALLA 4
A2322: 10273002 | B2322: ZFE3 | C2322: 1000 | D2322: M3 | E2322: 1000 | G2322: 1466 | H2322: MP GRAVA TRIT. BASALTO 20 MM - 3/4"
A2323: 10273351 | B2323: ZFE3 | C2323: 1000 | D2323: M3 | E2323: 1000 | G2323: 1612 | H2323: MP ARENA TRIT. CALIZA MALLA 4
A2324: 10273352 | B2324: ZFE3 | C2324: 1000 | D2324: M3 | E2324: 1000 | G2324: 1492 | H2324: MP GRAVA TRIT. CALIZA 20 MM - 3/4"
A2325: 10271724 | B2325: ZFE3 | C2325: 1000 | D2325: M3 | E2325: 1000 | G2325: 1900 | H2325: MP RESIDUO DE CONCRETO
A2326: 10000677 | C2326: 1000 | D2326: M3 | G2326: 1164 | H2326: Grava Triturada Caliza 20 mm - 3/4"
A2327: 10274190 | B2327: ZFE3 | C2327: 1000 | D2327: M3 | E2327: 1000 | G2327: 1800 | H2327: MP BASE HIDRAULICA ANDESITA 70-30
A2328: 10274601 | B2328: ZFE3 | C2328: 1000 | D2328: M3 | E2328: 1000 | G2328: 1447 | H2328: MP ARENA BASALTO N° 4
...

Sheet TRAOPE
A1: Concat1 | B1: Contrato_Pos | C1: Doc. Compras | D1: Pos | E1: Org.compras | F1: Grp-Compr. | G1: Ship From | H1: Nombre SF | I1: Proveedor | J1: Nombre Prov | K1: Cond. Pago | L1: Descr. Cond Pago | M1: Material | N1: Descripción | O1: Centro | P1: Descripción Centro | Q1: In.perído validez | R1: Fin perído validez | S1: Válido de | T1: Validez a | U1: Precio neto pedido | V1: Moneda | W1: UM Precio Pedido | X1: Importe Condición | Y1: Moneda KONP | Z1: UM Ctd Base | AA1: Destino | AB1: Nombre Destino | AC1: Cuenta de mayor | AD1: Centro de costo | AE1: Cond. Exp. | AF1: Descr. Cond. Exp. | AG1: Peso Vol. | AH1: UMB | AI1: Ind. Oblig. Conf. Ped. | AJ1: Ctrl-Conf. | AK1: IVA | AL1: Modif_Date | AM1: Ruta
A2: 900003437DW67D30210000826 | B2: 4600050908-30 | C2: 4600050908 | D2: 30 | E2: MXPO | F2: MXL | G2: 900003437 | H2: TC-ED-RUIZ ROSET | I2: 5052648 | J2: RUIZ ROSET NICOLAS | K2: N90 | L2: (AP) NAFIN 90 Dias | M2: 10000826 | N2: Arena Clasificada Río Malla 4 | O2: DW67 | P2: MX-CED. VERACRUZ SUR | Q2: 20210712 | R2: 20281231 | S2: 20260724 | T2: 20301231 | U2: 450 | V2: MXN | W2: M3 | X2: 210 | Y2: MXN | Z2: M3 | AA2: D302 | AB2: PD0471 COATZACOALCOS | AC2: 56103638 | AD2: 6644231540 | AE2: 4 | AF2: ENTREGA DIRECTA | AG2: 1.45 | AH2: M3 | AI2: X | AJ2: 4 | AK2: V4 | AL2: 20260724 | AM2: DW67-900003437-D302-10000826-4
A3: 900003437DW67D30210000372 | B3: 4600050908-40 | C3: 4600050908 | D3: 40 | E3: MXPO | F3: MXL | G3: 900003437 | H3: TC-ED-RUIZ ROSET | I3: 5052648 | J3: RUIZ ROSET NICOLAS | K3: N90 | L3: (AP) NAFIN 90 Dias | M3: 10000372 | N3: Grava Triturada Caliza 20 mm - 3/4" | O3: DW67 | P3: MX-CED. VERACRUZ SUR | Q3: 20210712 | R3: 20281231 | S3: 20260724 | T3: 20301231 | U3: 760 | V3: MXN | W3: M3 | X3: 400 | Y3: MXN | Z3: M3 | AA3: D302 | AB3: PD0471 COATZACOALCOS | AC3: 56103637 | AD3: 6644231540 | AE3: 4 | AF3: ENTREGA DIRECTA | AG3: 1.448 | AH3: M3 | AI3: X | AJ3: 4 | AK3: V4 | AL3: 20260724 | AM3: DW67-900003437-D302-10000372-4
A4: 900009524DW67D30210217663 | B4: 4600072524-10 | C4: 4600072524 | D4: 10 | E4: MXPO | F4: MXL | G4: 900009524 | H4: SF TC-ED JPM EVELIO | I4: 5098111 | J4: PEREZ MORALES JONAS | K4: N90 | L4: (AP) NAFIN 90 Dias | M4: 10217663 | N4: ARENA CLASIFICADA RÍO MALLA 4 -TABASCO | O4: DW67 | P4: MX-CED. VERACRUZ SUR | Q4: 20260804 | R4: 20301231 | S4: 20260804 | T4: 20301231 | U4: 750 | V4: MXN | W4: M3 | X4: 630 | Y4: MXN | Z4: M3 | AA4: D302 | AB4: PD0471 COATZACOALCOS | AC4: 56103638 | AD4: 6644231540 | AE4: 4 | AF4: ENTREGA DIRECTA | AG4: 1.456 | AH4: M3 | AI4: X | AJ4: 4 | AK4: V4 | AL4: 20260810 | AM4: DW67-900009524-D302-10217663-4
A5: 900007052DW67D30210000372 | B5: 4600057703-20 | C5: 4600057703 | D5: 20 | E5: MXPO | F5: MXL | G5: 900007052 | H5: SF TC-ED-SAMUEL CARRASCO | I5: 5080454 | J5: CARRASCO ALCUDIA SAMUEL | K5: N90 | L5: (AP) NAFIN 90 Dias | M5: 10000372 | N5: Grava Triturada Caliza 20 mm - 3/4" | O5: DW67 | P5: MX-CED. VERACRUZ SUR | Q5: 20230605 | R5: 20291231 | S5: 20240207 | T5: 20291231 | U5: 910 | V5: MXN | W5: M3 | X5: 560 | Y5: MXN | Z5: M3 | AA5: D302 | AB5: PD0471 COATZACOALCOS | AC5: 56103637 | AD5: 6644231540 | AE5: 4 | AF5: ENTREGA DIRECTA | AG5: 1.448 | AH5: M3 | AI5: X | AJ5: 4 | AK5: V4 | AL5: 20240208 | AM5: DW67-900007052-D302-10000372-4
A6: 900007887DW67D30210000826 | B6: 4600055683-20 | C6: 4600055683 | D6: 20 | E6: MXPO | F6: MXL | G6: 900007887 | H6: SF TC-ED-COMAC | I6: 5086443 | J6: SANCHEZ MAYA CESAR OMAR | K6: Z09 | L6: (AP) 90 Dias | M6: 10000826 | N6: Arena Clasificada Río Malla 4 | O6: DW67 | P6: MX-CED. VERACRUZ SUR | Q6: 20221101 | R6: 20281231 | S6: 20230228 | T6: 20281231 | U6: 350 | V6: MXN | W6: M3 | X6: 160 | Y6: MXN | Z6: M3 | AA6: D302 | AB6: PD0471 COATZACOALCOS | AC6: 56103638 | AD6: 6644231540 | AE6: 4 | AF6: ENTREGA DIRECTA | AG6: 1.45 | AH6: M3 | AI6: X | AJ6: 4 | AK6: V4 | AL6: 20230920 | AM6: DW67-900007887-D302-10000826-4
A7: 900008330DW6710000372 | B7: 4600068565-10 | C7: 4600068565 | D7: 10 | E7: MXPO | F7: MXL | G7: 900008330 | H7: SF TC-HOLCIM RZ | I7: 5075390 | J7: CORPORACION ANRROCA SA DE CV | K7: E90 | L7: (AP) E-FACTOR 90 Dias | M7: 10000372 | N7: Grava Triturada Caliza 20 mm - 3/4" | O7: DW67 | P7: MX-CED. VERACRUZ SUR | Q7: 20231003 | R7: 20281231 | S7: 20231003 | T7: 20281231 | U7: 350 | V7: MXN | W7: M3 | X7: 0 | Y7: MXN | Z7: M3 | AC7: 56103637 | AD7: 6644231540 | AE7: 1 | AF7: ENTREGADO | AG7: 1.448 | AH7: M3 | AI7: X | AJ7: 4 | AK7: V4 | AL7: 20231005 | AM7: DW67-900008330-10000372
A8: 900007800DW67D30210000541 | B8: 4600069204-40 | C8: 4600069204 | D8: 40 | E8: MXPO | F8: MXL | G8: 900007800 | H8: SF TC-ED-CLAKAR | I8: 5086783 | J8: CLA KAR COMPAÑIA DEL SURESTE SA DE | K8: N30 | L8: (AP) NAFIN 30 Dias | M8: 10000541 | N8: Grava Clasificada Río 10 mm - 3/8" | O8: DW67 | P8: MX-CED. VERACRUZ SUR | Q8: 20240229 | R8: 20291231 | S8: 20250905 | T8: 20301231 | U8: 550 | V8: MXN | W8: M3 | X8: 250 | Y8: MXN | Z8: M3 | AA8: D302 | AB8: PD0471 COATZACOALCOS | AC8: 56103637 | AD8: 6644231540 | AE8: 4 | AF8: ENTREGA DIRECTA | AG8: 1.528 | AH8: M3 | AI8: X | AJ8: 4 | AK8: V4 | AL8: 20251219 | AM8: DW67-900007800-D302-10000541-4
A9: 900000000DW67D30210000826 | B9: 4600069852-20 | C9: 4600069852 | D9: 20 | E9: MXPO | F9: MXL | G9: 900000000 | H9: TC-ED-LAZCANO HUERTA | I9: 5000326 | J9: LAZCANO HUERTA ROCIO NANCY | K9: N90 | L9: (AP) NAFIN 90 Dias | M9: 10000826 | N9: Arena Clasificada Río Malla 4 | O9: DW67 | P9: MX-CED. VERACRUZ SUR | Q9: 20240713 | R9: 20291231 | S9: 20250707 | T9: 20301231 | U9: 450 | V9: MXN | W9: M3 | X9: 200 | Y9: MXN | Z9: M3 | AA9: D302 | AB9: PD0471 COATZACOALCOS | AC9: 56103638 | AD9: 6644231540 | AE9: 4 | AF9: ENTREGA DIRECTA | AG9: 1.45 | AH9: M3 | AI9: X | AJ9: 4 | AK9: V4 | AL9: 20250718 | AM9: DW67-900000000-D302-10000826-4
A10: 900000037DW6710000140 | B10: 4600050878-30 | C10: 4600050878 | D10: 30 | E10: MXPO | F10: MXL | G10: 900000037 | H10: TC-THOME VILLALBA | I10: 5001984 | J10: TRITURADOS THOME VILLALBA SA DE CV | K10: Z09 | L10: (AP) 90 Dias | M10: 10000140 | N10: Grava Triturada Andesita 40 mm - 1 1/2" | O10: DW67 | P10: MX-CED. VERACRUZ SUR | Q10: 20210712 | R10: 20291231 | S10: 20220301 | T10: 20271231 | U10: 70 | V10: MXN | W10: M3 | X10: 0 | Y10: MXN | Z10: M3 | AC10: 56103637 | AD10: 6644231540 | AE10: 1 | AF10: ENTREGADO | AG10: 1.29 | AH10: M3 | AI10: X | AJ10: 4 | AK10: V4 | AL10: 20230920 | AM10: DW67-900000037-10000140
A11: 900002895DW6710000139 | B11: 4600054321-10 | C11: 4600054321 | D11: 10 | E11: MXPO | F11: MXL | G11: 900002895 | H11: TC-TRIDE | I11: 5051728 | J11: TRITURADOS LAS DERRUMBADAS SA DE CV | K11: N90 | L11: (AP) NAFIN 90 Dias | M11: 10000139 | N11: Grava Triturada Andesita 20 mm - 3/4" | O11: DW67 | P11: MX-CED. VERACRUZ SUR | Q11: 20220624 | R11: 20271231 | S11: 20220624 | T11: 20271231 | U11: 74 | V11: MXN | W11: M3 | X11: 0 | Y11: MXN | Z11: M3 | AC11: 56103637 | AD11: 6644231540 | AE11: 1 | AF11: ENTREGADO | AG11: 1.311 | AH11: M3 | AI11: X | AJ11: 4 | AK11: V4 | AL11: 20230920 | AM11: DW67-900002895-10000139
A12: 900003903DW6710000826 | B12: 4600050911-30 | C12: 4600050911 | D12: 30 | E12: MXPO | F12: MXL | G12: 900003903 | H12: TC ESCUDERO AGUILAR | I12: 5014480 | J12: ESCUDERO AGUILAR ANDRES | K12: N90 | L12: (AP) NAFIN 90 Dias | M12: 10000826 | N12: Arena Clasificada Río Malla 4 | O12: DW67 | P12: MX-CED. VERACRUZ SUR | Q12: 20210712 | R12: 20261231 | S12: 20221012 | T12: 20271231 | U12: 53 | V12: MXN | W12: M3 | X12: 0 | Y12: MXN | Z12: M3 | AC12: 56103638 | AD12: 6644231540 | AE12: 1 | AF12: ENTREGADO | AG12: 1.45 | AH12: M3 | AI12: X | AJ12: 4 | AK12: V4 | AL12: 20230920 | AM12: DW67-900003903-10000826
A13: 900002349DW6710000396 | B13: 4600053766-10 | C13: 4600053766 | D13: 10 | E13: MXPO | F13: MXL | G13: 900002349 | H13: TC-TAPSA | I13: 5041736 | J13: TRITURADOS Y AGREGADOS DE PUEBLA | K13: N90 | L13: (AP) NAFIN 90 Dias | M13: 10000396 | N13: Grava Triturada Caliza 20 mm - 3/4" | O13: DW67 | P13: MX-CED. VERACRUZ SUR | Q13: 20220421 | R13: 20271231 | S13: 20220808 | T13: 20271231 | U13: 135.45 | V13: MXN | W13: M3 | X13: 0 | Y13: MXN | Z13: M3 | AC13: 56103637 | AD13: 6644231540 | AE13: 1 | AF13: ENTREGADO | AG13: 1.382 | AH13: M3 | AI13: X | AJ13: 4 | AK13: V4 | AL13: 20230920 | AM13: DW67-900002349-10000396
A14: 900005921DW6710001652 | B14: 4600050942-20 | C14: 4600050942 | D14: 20 | E14: MXPO | F14: MXL | G14: 900005921 | H14: SF TC – LOS HUMEROS | I14: 5074803 | J14: MELO SOLEDAD JOSE CRUZ | K14: N60 | L14: (AP) NAFIN 60 Dias | M14: 10001652 | N14: Grava Triturada Andesita 13 mm - 1/2" | O14: DW67 | P14: MX-CED. VERACRUZ SUR | Q14: 20210712 | R14: 20261231 | S14: 20211002 | T14: 20261231 | U14: 70 | V14: MXN | W14: M3 | X14: 0 | Y14: MXN | Z14: M3 | AC14: 56103637 | AD14: 6644231540 | AE14: 1 | AF14: ENTREGADO | AG14: 1.234 | AH14: M3 | AI14: X | AJ14: 4 | AK14: V4 | AL14: 20230920 | AM14: DW67-900005921-10001652
A15: 900007979DW67D30210000372 | B15: 4600056318-40 | C15: 4600056318 | D15: 40 | E15: MXPO | F15: MXL | G15: 900007979 | H15: SF TC-ED-CLAKAR 210 PROY JAGUAR | I15: 5086783 | J15: CLA KAR COMPAÑIA DEL SURESTE SA DE | K15: N30 | L15: (AP) NAFIN 30 Dias | M15: 10000372 | N15: Grava Triturada Caliza 20 mm - 3/4" | O15: DW67 | P15: MX-CED. VERACRUZ SUR | Q15: 20230124 | R15: 20291231 | S15: 20230124 | T15: 20271231 | U15: 900 | V15: MXN | W15: M3 | X15: 600 | Y15: MXN | Z15: M3 | AA15: D302 | AB15: PD0471 COATZACOALCOS | AC15: 56103637 | AD15: 6644231540 | AE15: 4 | AF15: ENTREGA DIRECTA | AG15: 1.448 | AH15: M3 | AI15: X | AJ15: 4 | AK15: V4 | AL15: 20230920 | AM15: DW67-900007979-D302-10000372-4
A16: 900003437DW67D30210000139 | B16: 4600050908-20 | C16: 4600050908 | D16: 20 | E16: MXPO | F16: MXL | G16: 900003437 | H16: TC-ED-RUIZ ROSET | I16: 5052648 | J16: RUIZ ROSET NICOLAS | K16: N90 | L16: (AP) NAFIN 90 Dias | M16: 10000139 | N16: Grava Triturada Andesita 20 mm - 3/4" | O16: DW67 | P16: MX-CED. VERACRUZ SUR | Q16: 20210712 | R16: 20281231 | S16: 20230526 | T16: 20281231 | U16: 1150 | V16: MXN | W16: M3 | X16: 1060 | Y16: MXN | Z16: M3 | AA16: D302 | AB16: PD0471 COATZACOALCOS | AC16: 56103637 | AD16: 6644231540 | AE16: 4 | AF16: ENTREGA DIRECTA | AG16: 1.311 | AH16: M3 | AI16: X | AJ16: 4 | AK16: V4 | AL16: 20230920 | AM16: DW67-900003437-D302-10000139-4
A17: 900008910DW67D30210223313 | B17: 4600069981-40 | C17: 4600069981 | D17: 40 | E17: MXPO | F17: MXL | G17: 900008910 | H17: SF TC-ED OPERAMAC MGM | I17: 5093910 | J17: GUTIERREZ MARTINEZ MAYEL | K17: Z09 | L17: (AP) 90 Dias | M17: 10223313 | N17: ARENA SILICA NG | O17: DW67 | P17: MX-CED. VERACRUZ SUR | Q17: 20240731 | R17: 20291231 | S17: 20250109 | T17: 20291231 | U17: 486 | V17: MXN | W17: M3 | X17: 283 | Y17: MXN | Z17: M3 | AA17: D302 | AB17: PD0471 COATZACOALCOS | AC17: 56103638 | AD17: 6644231540 | AE17: 4 | AF17: ENTREGA DIRECTA | AG17: 1.45 | AH17: M3 | AI17: X | AJ17: 4 | AK17: V4 | AL17: 20250113 | AM17: DW67-900008910-D302-10223313-4
A18: 900009192DW67D30210000623 | B18: 4600071195-20 | C18: 4600071195 | D18: 20 | E18: MXPO | F18: MXL | G18: 900009192 | H18: SF TC-ED TECHNO | I18: 5095150 | J18: TECHNO CONSTRUCCIONES Y SUMINISTROS | K18: N90 | L18: (AP) NAFIN 90 Dias | M18: 10000623 | N18: Grava Triturada Caliza 10 mm - 3/8" | O18: DW67 | P18: MX-CED. VERACRUZ SUR | Q18: 20250502 | R18: 20301231 | S18: 20250724 | T18: 20301231 | U18: 1150 | V18: MXN | W18: M3 | X18: 730 | Y18: MXN | Z18: M3 | AA18: D302 | AB18: PD0471 COATZACOALCOS | AC18: 56103637 | AD18: 6644231540 | AE18: 4 | AF18: ENTREGA DIRECTA | AG18: 1.41 | AH18: M3 | AI18: X | AJ18: 4 | AK18: V4 | AL18: 20250729 | AM18: DW67-900009192-D302-10000623-4
A19: 900008972DW67D30210000826 | B19: 4600070645-20 | C19: 4600070645 | D19: 20 | E19: MXPO | F19: MXL | G19: 900008972 | H19: SF TC-ED MGM HATO | I19: 5093910 | J19: GUTIERREZ MARTINEZ MAYEL | K19: N90 | L19: (AP) NAFIN 90 Dias | M19: 10000826 | N19: Arena Clasificada Río Malla 4 | O19: DW67 | P19: MX-CED. VERACRUZ SUR | Q19: 20241209 | R19: 20291231 | S19: 20250109 | T19: 20291231 | U19: 450 | V19: MXN | W19: M3 | X19: 258 | Y19: MXN | Z19: M3 | AA19: D302 | AB19: PD0471 COATZACOALCOS | AC19: 56103638 | AD19: 6644231540 | AE19: 4 | AF19: ENTREGA DIRECTA | AG19: 1.45 | AH19: M3 | AI19: X | AJ19: 4 | AK19: V4 | AL19: 20250113 | AM19: DW67-900008972-D302-10000826-4
A20: 900000000DW67D30210000178 | B20: 4600069852-30 | C20: 4600069852 | D20: 30 | E20: MXPO | F20: MXL | G20: 900000000 | H20: TC-ED-LAZCANO HUERTA | I20: 5000326 | J20: LAZCANO HUERTA ROCIO NANCY | K20: N90 | L20: (AP) NAFIN 90 Dias | M20: 10000178 | N20: Grava Clasificada Río 20 mm - 3/4" | O20: DW67 | P20: MX-CED. VERACRUZ SUR | Q20: 20240713 | R20: 20291231 | S20: 20240723 | T20: 20291231 | U20: 500 | V20: MXN | W20: M3 | X20: 150 | Y20: MXN | Z20: M3 | AA20: D302 | AB20: PD0471 COATZACOALCOS | AC20: 56103637 | AD20: 6644231540 | AE20: 4 | AF20: ENTREGA DIRECTA | AG20: 1.507 | AH20: M3 | AI20: X | AJ20: 4 | AK20: V4 | AL20: 20240725 | AM20: DW67-900000000-D302-10000178-4
A21: 900007715DW67D30210210039 | B21: 4600071196-10 | C21: 4600071196 | D21: 10 | E21: MXPO | F21: MXL | G21: 900007715 | H21: SF TC-ED-SAMUEL CARRASCO14 | I21: 5080454 | J21: CARRASCO ALCUDIA SAMUEL | K21: N90 | L21: (AP) NAFIN 90 Dias | M21: 10210039 | N21: ARENA CLASIFICADA RÍO MALLA 4 | O21: DW67 | P21: MX-CED. VERACRUZ SUR | Q21: 20250502 | R21: 20301231 | S21: 20250502 | T21: 20301231 | U21: 500 | V21: MXN | W21: M3 | X21: 415 | Y21: MXN | Z21: M3 | AA21: D302 | AB21: PD0471 COATZACOALCOS | AC21: 56103638 | AD21: 6644231540 | AE21: 4 | AF21: ENTREGA DIRECTA | AG21: 1.485 | AH21: M3 | AI21: X | AJ21: 4 | AK21: V4 | AL21: 20250505 | AM21: DW67-900007715-D302-10210039-4
A22: 900009192DW67D30210210039 | B22: 4600071195-10 | C22: 4600071195 | D22: 10 | E22: MXPO | F22: MXL | G22: 900009192 | H22: SF TC-ED TECHNO | I22: 5095150 | J22: TECHNO CONSTRUCCIONES Y SUMINISTROS | K22: N90 | L22: (AP) NAFIN 90 Dias | M22: 10210039 | N22: ARENA CLASIFICADA RÍO MALLA 4 | O22: DW67 | P22: MX-CED. VERACRUZ SUR | Q22: 20250502 | R22: 20301231 | S22: 20250502 | T22: 20301231 | U22: 500 | V22: MXN | W22: M3 | X22: 415 | Y22: MXN | Z22: M3 | AA22: D302 | AB22: PD0471 COATZACOALCOS | AC22: 56103638 | AD22: 6644231540 | AE22: 4 | AF22: ENTREGA DIRECTA | AG22: 1.485 | AH22: M3 | AI22: X | AJ22: 4 | AK22: V4 | AL22: 20250505 | AM22: DW67-900009192-D302-10210039-4
A23: 900008972DW67D30210255395 | B23: 4600070645-10 | C23: 4600070645 | D23: 10 | E23: MXPO | F23: MXL | G23: 900008972 | H23: SF TC-ED MGM HATO | I23: 5093910 | J23: GUTIERREZ MARTINEZ MAYEL | K23: N90 | L23: (AP) NAFIN 90 Dias | M23: 10255395 | N23: GRAVA TRITURADA CALIZA 20 MM - 3/4" | O23: DW67 | P23: MX-CED. VERACRUZ SUR | Q23: 20241209 | R23: 20291231 | S23: 20241209 | T23: 20291231 | U23: 636 | V23: MXN | W23: M3 | X23: 286 | Y23: MXN | Z23: M3 | AA23: D302 | AB23: PD0471 COATZACOALCOS | AC23: 56103637 | AD23: 6644231540 | AE23: 4 | AF23: ENTREGA DIRECTA | AG23: 1.448 | AH23: M3 | AI23: X | AJ23: 4 | AK23: V4 | AL23: 20241212 | AM23: DW67-900008972-D302-10255395-4
A24: 900008910DW67D30210255395 | B24: 4600069981-30 | C24: 4600069981 | D24: 30 | E24: MXPO | F24: MXL | G24: 900008910 | H24: SF TC-ED OPERAMAC MGM | I24: 5093910 | J24: GUTIERREZ MARTINEZ MAYEL | K24: Z09 | L24: (AP) 90 Dias | M24: 10255395 | N24: GRAVA TRITURADA CALIZA 20 MM - 3/4" | O24: DW67 | P24: MX-CED. VERACRUZ SUR | Q24: 20240731 | R24: 20291231 | S24: 20241209 | T24: 20291231 | U24: 1110 | V24: MXN | W24: M3 | X24: 760 | Y24: MXN | Z24: M3 | AA24: D302 | AB24: PD0471 COATZACOALCOS | AC24: 56103637 | AD24: 6644231540 | AE24: 4 | AF24: ENTREGA DIRECTA | AG24: 1.448 | AH24: M3 | AI24: X | AJ24: 4 | AK24: V4 | AL24: 20241212 | AM24: DW67-900008910-D302-10255395-4
A25: 900007979DW67D30210000178 | B25: 4600056318-10 | C25: 4600056318 | D25: 10 | E25: MXPO | F25: MXL | G25: 900007979 | H25: SF TC-ED-CLAKAR 210 PROY JAGUAR | I25: 5086783 | J25: CLA KAR COMPAÑIA DEL SURESTE SA DE | K25: N30 | L25: (AP) NAFIN 30 Dias | M25: 10000178 | N25: Grava Clasificada Río 20 mm - 3/4" | O25: DW67 | P25: MX-CED. VERACRUZ SUR | Q25: 20230124 | R25: 20291231 | S25: 20240715 | T25: 20291231 | U25: 580 | V25: MXN | W25: M3 | X25: 230 | Y25: MXN | Z25: M3 | AA25: D302 | AB25: PD0471 COATZACOALCOS | AC25: 56103637 | AD25: 6644231540 | AE25: 4 | AF25: ENTREGA DIRECTA | AG25: 1.507 | AH25: M3 | AI25: X | AJ25: 4 | AK25: V4 | AL25: 20240731 | AM25: DW67-900007979-D302-10000178-4
A26: 900007979DW67D30210000826 | B26: 4600056318-20 | C26: 4600056318 | D26: 20 | E26: MXPO | F26: MXL | G26: 900007979 | H26: SF TC-ED-CLAKAR 210 PROY JAGUAR | I26: 5086783 | J26: CLA KAR COMPAÑIA DEL SURESTE SA DE | K26: N30 | L26: (AP) NAFIN 30 Dias | M26: 10000826 | N26: Arena Clasificada Río Malla 4 | O26: DW67 | P26: MX-CED. VERACRUZ SUR | Q26: 20230124 | R26: 20291231 | S26: 20240715 | T26: 20291231 | U26: 545 | V26: MXN | W26: M3 | X26: 250 | Y26: MXN | Z26: M3 | AA26: D302 | AB26: PD0471 COATZACOALCOS | AC26: 56103638 | AD26: 6644231540 | AE26: 4 | AF26: ENTREGA DIRECTA | AG26: 1.45 | AH26: M3 | AI26: X | AJ26: 4 | AK26: V4 | AL26: 20240731 | AM26: DW67-900007979-D302-10000826-4
... A32: 900006500DW67D30210000826 | B32: 4600069832-10 | C32: 4600069832 | D32: 10 | E32: MXPO | F32: MXL | G32: 900006500 | H32: TC-ED- HATO GONZALEZ | I32: 5077743 | J32: ORTIZ GONZALEZ GUSTAVO ADOLFO | K32: Z09 | L32: (AP) 90 Dias | M32: 10000826 | N32: Arena Clasificada Río Malla 4 | O32: DW67 | P32: MX-CED. VERACRUZ SUR | Q32: 20240705 | R32: 20291231 | S32: 20260115 | T32: 20301231 | U32: 426.4 | V32: MXN | W32: M3 | X32: 196.4 | Y32: MXN | Z32: M3 | AA32: D302 | AB32: PD0471 COATZACOALCOS | AC32: 56103638 | AD32: 6644231540 | AE32: 4 | AF32: ENTREGA DIRECTA | AG32: 1.45 | AH32: M3 | AI32: X | AJ32: 4 | AK32: V4 | AL32: 20260204 | AM32: DW67-900006500-D302-10000826-4
A33: 900000037DW6710000139 | B33: 4600050878-20 | C33: 4600050878 | D33: 20 | E33: MXPO | F33: MXL | G33: 900000037 | H33: TC-THOME VILLALBA | I33: 5001984 | J33: TRITURADOS THOME VILLALBA SA DE CV | K33: Z09 | L33: (AP) 90 Dias | M33: 10000139 | N33: Grava Triturada Andesita 20 mm - 3/4" | O33: DW67 | P33: MX-CED. VERACRUZ SUR | Q33: 20210712 | R33: 20291231 | S33: 20240101 | T33: 20291231 | U33: 95 | V33: MXN | W33: M3 | X33: 0 | Y33: MXN | Z33: M3 | AC33: 56103637 | AD33: 6644231540 | AE33: 1 | AF33: ENTREGADO | AG33: 1.311 | AH33: M3 | AI33: X | AJ33: 4 | AK33: V4 | AL33: 20240212 | AM33: DW67-900000037-10000139
A34: 900000743DW6710000561 | B34: 4600050890-10 | C34: 4600050890 | D34: 10 | E34: MXPO | F34: MXL | G34: 900000743 | H34: TC SIGSA | I34: 5021622 | J34: SERVICIOS DE INGENIERIA DEL GOLFO | K34: N60 | L34: (AP) NAFIN 60 Dias | M34: 10000561 | N34: Grava Triturada Caliza 20 mm - 3/4" | O34: DW67 | P34: MX-CED. VERACRUZ SUR | Q34: 20210712 | R34: 20291231 | S34: 20251103 | T34: 20301231 | U34: 320 | V34: MXN | W34: M3 | X34: 0 | Y34: MXN | Z34: M3 | AC34: 56103637 | AD34: 6644231540 | AE34: 1 | AF34: ENTREGADO | AG34: 1.43 | AH34: M3 | AI34: X | AJ34: 4 | AK34: V4 | AL34: 20251104 | AM34: DW67-900000743-10000561
A35: 900000037DW6710000444 | B35: 4600050878-10 | C35: 4600050878 | D35: 10 | E35: MXPO | F35: MXL | G35: 900000037 | H35: TC-THOME VILLALBA | I35: 5001984 | J35: TRITURADOS THOME VILLALBA SA DE CV | K35: Z09 | L35: (AP) 90 Dias | M35: 10000444 | N35: Arena Triturada Andesita Malla 4 | O35: DW67 | P35: MX-CED. VERACRUZ SUR | Q35: 20210712 | R35: 20291231 | S35: 20240101 | T35: 20291231 | U35: 90 | V35: MXN | W35: M3 | X35: 0 | Y35: MXN | Z35: M3 | AC35: 56103638 | AD35: 6644231540 | AE35: 1 | AF35: ENTREGADO | AG35: 1.473 | AH35: M3 | AI35: X | AJ35: 4 | AK35: V4 | AL35: 20240212 | AM35: DW67-900000037-10000444
A36: 900005534DW6710000139 | B36: 4600050931-10 | C36: 4600050931 | D36: 10 | E36: MXPO | F36: MXL | G36: 900005534 | H36: TC-THOME COATZACOALCOS | I36: 5001984 | J36: TRITURADOS THOME VILLALBA SA DE CV | K36: Z09 | L36: (AP) 90 Dias | M36: 10000139 | N36: Grava Triturada Andesita 20 mm - 3/4" | O36: DW67 | P36: MX-CED. VERACRUZ SUR | Q36: 20210712 | R36: 20291231 | S36: 20240101 | T36: 20291231 | U36: 95 | V36: MXN | W36: M3 | X36: 0 | Y36: MXN | Z36: M3 | AC36: 56103637 | AD36: 6644231540 | AE36: 1 | AF36: ENTREGADO | AG36: 1.311 | AH36: M3 | AI36: X | AJ36: 4 | AK36: V4 | AL36: 20240212 | AM36: DW67-900005534-10000139
A37: 900007052DW67D30210000398 | B37: 4600057703-10 | C37: 4600057703 | D37: 10 | E37: MXPO | F37: MXL | G37: 900007052 | H37: SF TC-ED-SAMUEL CARRASCO | I37: 5080454 | J37: CARRASCO ALCUDIA SAMUEL | K37: N90 | L37: (AP) NAFIN 90 Dias | M37: 10000398 | N37: Grava Triturada Andesita 20 mm - 3/4" | O37: DW67 | P37: MX-CED. VERACRUZ SUR | Q37: 20230605 | R37: 20291231 | S37: 20241030 | T37: 20291231 | U37: 580 | V37: MXN | W37: M3 | X37: 495 | Y37: MXN | Z37: M3 | AA37: D302 | AB37: PD0471 COATZACOALCOS | AC37: 56103637 | AD37: 6644231540 | AE37: 4 | AF37: ENTREGA DIRECTA | AG37: 1.311 | AH37: M3 | AI37: X | AJ37: 4 | AK37: V4 | AL37: 20241031 | AM37: DW67-900007052-D302-10000398-4
A38: 900008910DW67D30210000826 | B38: 4600069981-10 | C38: 4600069981 | D38: 10 | E38: MXPO | F38: MXL | G38: 900008910 | H38: SF TC-ED OPERAMAC MGM | I38: 5093910 | J38: GUTIERREZ MARTINEZ MAYEL | K38: Z09 | L38: (AP) 90 Dias | M38: 10000826 | N38: Arena Clasificada Río Malla 4 | O38: DW67 | P38: MX-CED. VERACRUZ SUR | Q38: 20240731 | R38: 20291231 | S38: 20240731 | T38: 20291231 | U38: 450 | V38: MXN | W38: M3 | X38: 150 | Y38: MXN | Z38: M3 | AA38: D302 | AB38: PD0471 COATZACOALCOS | AC38: 56103638 | AD38: 6644231540 | AE38: 4 | AF38: ENTREGA DIRECTA | AG38: 1.45 | AH38: M3 | AI38: X | AJ38: 4 | AK38: V4 | AL38: 20240805 | AM38: DW67-900008910-D302-10000826-4
A39: 900008972DW67D30210000178 | B39: 4600070645-30 | C39: 4600070645 | D39: 30 | E39: MXPO | F39: MXL | G39: 900008972 | H39: SF TC-ED MGM HATO | I39: 5093910 | J39: GUTIERREZ MARTINEZ MAYEL | K39: N90 | L39: (AP) NAFIN 90 Dias | M39: 10000178 | N39: Grava Clasificada Río 20 mm - 3/4" | O39: DW67 | P39: MX-CED. VERACRUZ SUR | Q39: 20241209 | R39: 20291231 | S39: 20250902 | T39: 20301231 | U39: 590 | V39: MXN | W39: M3 | X39: 230 | Y39: MXN | Z39: M3 | AA39: D302 | AB39: PD0471 COATZACOALCOS | AC39: 56103637 | AD39: 6644231540 | AE39: 4 | AF39: ENTREGA DIRECTA | AG39: 1.507 | AH39: M3 | AI39: X | AJ39: 4 | AK39: V4 | AL39: 20250922 | AM39: DW67-900008972-D302-10000178-4
A40: 900007952DW6710210039 | B40: 4600056122-10 | C40: 4600056122 | D40: 10 | E40: MXPO | F40: MXL | G40: 900007952 | H40: SF TC-BANCO GARCIA | I40: 5067302 | J40: GARCIA BALTAZAR MIGUEL | K40: N90 | L40: (AP) NAFIN 90 Dias | M40: 10210039 | N40: ARENA CLASIFICADA RÍO MALLA 4 | O40: DW67 | P40: MX-CED. VERACRUZ SUR | Q40: 20230106 | R40: 20271231 | S40: 20230106 | T40: 20271231 | U40: 57 | V40: MXN | W40: M3 | X40: 0 | Y40: MXN | Z40: M3 | AC40: 56103638 | AD40: 6644231540 | AE40: 1 | AF40: ENTREGADO | AG40: 1.485 | AH40: M3 | AI40: X | AJ40: 4 | AK40: V4 | AL40: 20230920 | AM40: DW67-900007952-10210039
A41: 900007992DW6710000826 | B41: 4600056140-10 | C41: 4600056140 | D41: 10 | E41: MXPO | F41: MXL | G41: 900007992 | H41: SF TC-CLAKAR 210 | I41: 5086783 | J41: CLA KAR COMPAÑIA DEL SURESTE SA DE | K41: N30 | L41: (AP) NAFIN 30 Dias | M41: 10000826 | N41: Arena Clasificada Río Malla 4 | O41: DW67 | P41: MX-CED. VERACRUZ SUR | Q41: 20230110 | R41: 20271231 | S41: 20230110 | T41: 20271231 | U41: 210 | V41: MXN | W41: M3 | X41: 0 | Y41: MXN | Z41: M3 | AC41: 56103638 | AD41: 6644231540 | AE41: 1 | AF41: ENTREGADO | AG41: 1.45 | AH41: M3 | AI41: X | AJ41: 4 | AK41: V4 | AL41: 20230920 | AM41: DW67-900007992-10000826
A42: 900008331DW67D30210000372 | B42: 4600069361-10 | C42: 4600069361 | D42: 10 | E42: MXPO | F42: MXL | G42: 900008331 | H42: SF TC-ED-HOLCIM RZ | I42: 5075390 | J42: CORPORACION ANRROCA SA DE CV | K42: E90 | L42: (AP) E-FACTOR 90 Dias | M42: 10000372 | N42: Grava Triturada Caliza 20 mm - 3/4" | O42: DW67 | P42: MX-CED. VERACRUZ SUR | Q42: 20240409 | R42: 20291231 | S42: 20240409 | T42: 20291231 | U42: 950 | V42: MXN | W42: M3 | X42: 600 | Y42: MXN | Z42: M3 | AA42: D302 | AB42: PD0471 COATZACOALCOS | AC42: 56103637 | AD42: 6644231540 | AE42: 4 | AF42: ENTREGA DIRECTA | AG42: 1.448 | AH42: M3 | AI42: X | AJ42: 4 | AK42: V4 | AL42: 20240413 | AM42: DW67-900008331-D302-10000372-4
A43: 900005921DW6710000139 | B43: 4600050942-10 | C43: 4600050942 | D43: 10 | E43: MXPO | F43: MXL | G43: 900005921 | H43: SF TC – LOS HUMEROS | I43: 5074803 | J43: MELO SOLEDAD JOSE CRUZ | K43: N60 | L43: (AP) NAFIN 60 Dias | M43: 10000139 | N43: Grava Triturada Andesita 20 mm - 3/4" | O43: DW67 | P43: MX-CED. VERACRUZ SUR | Q43: 20210712 | R43: 20261231 | S43: 20210712 | T43: 20220123 | U43: 65 | V43: MXN | W43: M3 | X43: 0 | Y43: MXN | Z43: M3 | AC43: 56103637 | AD43: 6644231540 | AE43: 1 | AF43: ENTREGADO | AG43: 1.311 | AH43: M3 | AI43: X | AJ43: 4 | AK43: V4 | AL43: 20230920 | AM43: DW67-900005921-10000139
A44: 900000037DW6710000548 | B44: 4600050878-40 | C44: 4600050878 | D44: 40 | E44: MXPO | F44: MXL | G44: 900000037 | H44: TC-THOME VILLALBA | I44: 5001984 | J44: TRITURADOS THOME VILLALBA SA DE CV | K44: Z09 | L44: (AP) 90 Dias | M44: 10000548 | N44: Grava Triturada Andesita 10 mm - 3/8" | O44: DW67 | P44: MX-CED. VERACRUZ SUR | Q44: 20210712 | R44: 20291231 | S44: 20210712 | T44: 20251231 | U44: 47.3 | V44: MXN | W44: M3 | X44: 0 | Y44: MXN | Z44: M3 | AC44: 56103637 | AD44: 6644231540 | AE44: 1 | AF44: ENTREGADO | AG44: 1.315 | AH44: M3 | AI44: X | AJ44: 4 | AK44: V4 | AL44: 20230920 | AM44: DW67-900000037-10000548
A45: 900006027DW67D30210000826 | B45: 4600050948-10 | C45: 4600050948 | D45: 10 | E45: MXPO | F45: MXL | G45: 900006027 | H45: SF TC-ED-CARRILLO RUIZ | I45: 5011523 | J45: RUIZ CARRILLO AZYADETH | K45: N90 | L45: (AP) NAFIN 90 Dias | M45: 10000826 | N45: Arena Clasificada Río Malla 4 | O45: DW67 | P45: MX-CED. VERACRUZ SUR | Q45: 20210712 | R45: 20291231 | S45: 20260501 | T45: 20301231 | U45: 378 | V45: MXN | W45: M3 | X45: 163 | Y45: MXN | Z45: M3 | AA45: D302 | AB45: PD0471 COATZACOALCOS | AC45: 56103638 | AD45: 6644231540 | AE45: 4 | AF45: ENTREGA DIRECTA | AG45: 1.45 | AH45: M3 | AI45: X | AJ45: 4 | AK45: V4 | AL45: 20260523 | AM45: DW67-900006027-D302-10000826-4
...
