Workbook

Sheet Base Cedis D848
N1: VENTA | Q1: COSTO
A2: CONCAT1 | B2: CONCAT2 | C2: No. SF | D2: Nombre SF | E2: Cedis | F2: Destino | G2: Condicion de Expedicion | H2: Nombre Destino | I2: No. de material | J2: Nombre de material | K2: PV | L2: Inicio de vigencia | M2: Fin de vigencia | N2: Importe MP | O2: Importe Flete | P2: UM Venta | Q2: Importe Costo | R2: UM Costo | S2: Validacion 1 | T2: Validacion 2
A3: =CONCATENATE(C3,E3,F3,I3) | B3: =CONCATENATE(C3,E3,I3) | C3: 900000138 | D3: =IFERROR(VLOOKUP(C3,TRAOPE!$G:$H,2,0),"") | E3: D848 | F3: 66540419 | G3: =IFERROR(VLOOKUP(A3,Flete!$A:$E,5,0),"") | H3: =IFERROR(VLOOKUP(F3,TRAOPE!$AA:$AB,2,0),"") | I3: 10000141 | J3: =IFERROR(VLOOKUP(I3,Materiales!$A:$H,8,0),"") | K3: =IFERROR(VLOOKUP(I3,Materiales!$A:$G,7,0),"") | L3: 20191211 | M3: 20251031 | N3: 105 | O3: =IFERROR(VLOOKUP(A3,Flete!$A:$J,10,0),"") | P3: TN | Q3: =IFERROR(IFERROR(VLOOKUP(A3,TRAOPE!$A:$U,21,0),VLOOKUP(B3,TRAOPE!$A:$U,21,0)),"") | R3: =IFERROR(IFERROR(VLOOKUP(A3,TRAOPE!$A:$W,23,0),VLOOKUP(B3,TRAOPE!$A:$W,23,0)),"") | S3: =IF(AND(P3="TN",R3="TN"),N3+N(O3),IF(G3&""="1",N(K3)*N3,(N3+N(O3))*N(K3))) | T3: =IF(Q3="","",Q3-S3)
A4: =CONCATENATE(C4,E4,F4,I4) | B4: =CONCATENATE(C4,E4,I4) | C4: 900000138 | D4: =IFERROR(VLOOKUP(C4,TRAOPE!$G:$H,2,0),"") | E4: D848 | F4: 66540419 | G4: =IFERROR(VLOOKUP(A4,Flete!$A:$E,5,0),"") | H4: =IFERROR(VLOOKUP(F4,TRAOPE!$AA:$AB,2,0),"") | I4: 10000402 | J4: =IFERROR(VLOOKUP(I4,Materiales!$A:$H,8,0),"") | K4: =IFERROR(VLOOKUP(I4,Materiales!$A:$G,7,0),"") | L4: 20191211 | M4: 20251031 | N4: 105 | O4: =IFERROR(VLOOKUP(A4,Flete!$A:$J,10,0),"") | P4: TN | Q4: =IFERROR(IFERROR(VLOOKUP(A4,TRAOPE!$A:$U,21,0),VLOOKUP(B4,TRAOPE!$A:$U,21,0)),"") | R4: =IFERROR(IFERROR(VLOOKUP(A4,TRAOPE!$A:$W,23,0),VLOOKUP(B4,TRAOPE!$A:$W,23,0)),"") | S4: =IF(AND(P4="TN",R4="TN"),N4+N(O4),IF(G4&""="1",N(K4)*N4,(N4+N(O4))*N(K4))) | T4: =IF(Q4="","",Q4-S4)
A5: =CONCATENATE(C5,E5,F5,I5) | B5: =CONCATENATE(C5,E5,I5) | C5: 900000138 | D5: =IFERROR(VLOOKUP(C5,TRAOPE!$G:$H,2,0),"") | E5: D848 | F5: 66540419 | G5: =IFERROR(VLOOKUP(A5,Flete!$A:$E,5,0),"") | H5: =IFERROR(VLOOKUP(F5,TRAOPE!$AA:$AB,2,0),"") | I5: 10000404 | J5: =IFERROR(VLOOKUP(I5,Materiales!$A:$H,8,0),"") | K5: =IFERROR(VLOOKUP(I5,Materiales!$A:$G,7,0),"") | L5: 20191211 | M5: 20251031 | N5: 105 | O5: =IFERROR(VLOOKUP(A5,Flete!$A:$J,10,0),"") | P5: TN | Q5: =IFERROR(IFERROR(VLOOKUP(A5,TRAOPE!$A:$U,21,0),VLOOKUP(B5,TRAOPE!$A:$U,21,0)),"") | R5: =IFERROR(IFERROR(VLOOKUP(A5,TRAOPE!$A:$W,23,0),VLOOKUP(B5,TRAOPE!$A:$W,23,0)),"") | S5: =IF(AND(P5="TN",R5="TN"),N5+N(O5),IF(G5&""="1",N(K5)*N5,(N5+N(O5))*N(K5))) | T5: =IF(Q5="","",Q5-S5)
A6: =CONCATENATE(C6,E6,F6,I6) | B6: =CONCATENATE(C6,E6,I6) | C6: 900000138 | D6: =IFERROR(VLOOKUP(C6,TRAOPE!$G:$H,2,0),"") | E6: D848 | F6: 66540419 | G6: =IFERROR(VLOOKUP(A6,Flete!$A:$E,5,0),"") | H6: =IFERROR(VLOOKUP(F6,TRAOPE!$AA:$AB,2,0),"") | I6: 10000407 | J6: =IFERROR(VLOOKUP(I6,Materiales!$A:$H,8,0),"") | K6: =IFERROR(VLOOKUP(I6,Materiales!$A:$G,7,0),"") | L6: 20191211 | M6: 20251031 | N6: 105 | O6: =IFERROR(VLOOKUP(A6,Flete!$A:$J,10,0),"") | P6: TN | Q6: =IFERROR(IFERROR(VLOOKUP(A6,TRAOPE!$A:$U,21,0),VLOOKUP(B6,TRAOPE!$A:$U,21,0)),"") | R6: =IFERROR(IFERROR(VLOOKUP(A6,TRAOPE!$A:$W,23,0),VLOOKUP(B6,TRAOPE!$A:$W,23,0)),"") | S6: =IF(AND(P6="TN",R6="TN"),N6+N(O6),IF(G6&""="1",N(K6)*N6,(N6+N(O6))*N(K6))) | T6: =IF(Q6="","",Q6-S6)
A7: =CONCATENATE(C7,E7,F7,I7) | B7: =CONCATENATE(C7,E7,I7) | C7: 900000138 | D7: =IFERROR(VLOOKUP(C7,TRAOPE!$G:$H,2,0),"") | E7: D848 | F7: 66540419 | G7: =IFERROR(VLOOKUP(A7,Flete!$A:$E,5,0),"") | H7: =IFERROR(VLOOKUP(F7,TRAOPE!$AA:$AB,2,0),"") | I7: 10000859 | J7: =IFERROR(VLOOKUP(I7,Materiales!$A:$H,8,0),"") | K7: =IFERROR(VLOOKUP(I7,Materiales!$A:$G,7,0),"") | L7: 20191211 | M7: 20251031 | N7: 105 | O7: =IFERROR(VLOOKUP(A7,Flete!$A:$J,10,0),"") | P7: TN | Q7: =IFERROR(IFERROR(VLOOKUP(A7,TRAOPE!$A:$U,21,0),VLOOKUP(B7,TRAOPE!$A:$U,21,0)),"") | R7: =IFERROR(IFERROR(VLOOKUP(A7,TRAOPE!$A:$W,23,0),VLOOKUP(B7,TRAOPE!$A:$W,23,0)),"") | S7: =IF(AND(P7="TN",R7="TN"),N7+N(O7),IF(G7&""="1",N(K7)*N7,(N7+N(O7))*N(K7))) | T7: =IF(Q7="","",Q7-S7)
A8: =CONCATENATE(C8,E8,F8,I8) | B8: =CONCATENATE(C8,E8,I8) | C8: 900000138 | D8: =IFERROR(VLOOKUP(C8,TRAOPE!$G:$H,2,0),"") | E8: D848 | F8: 66632312 | G8: =IFERROR(VLOOKUP(A8,Flete!$A:$E,5,0),"") | H8: =IFERROR(VLOOKUP(F8,TRAOPE!$AA:$AB,2,0),"") | I8: 10000141 | J8: =IFERROR(VLOOKUP(I8,Materiales!$A:$H,8,0),"") | K8: =IFERROR(VLOOKUP(I8,Materiales!$A:$G,7,0),"") | L8: 20191211 | M8: 20251031 | N8: 99.45 | O8: =IFERROR(VLOOKUP(A8,Flete!$A:$J,10,0),"") | P8: TN | Q8: =IFERROR(IFERROR(VLOOKUP(A8,TRAOPE!$A:$U,21,0),VLOOKUP(B8,TRAOPE!$A:$U,21,0)),"") | R8: =IFERROR(IFERROR(VLOOKUP(A8,TRAOPE!$A:$W,23,0),VLOOKUP(B8,TRAOPE!$A:$W,23,0)),"") | S8: =IF(AND(P8="TN",R8="TN"),N8+N(O8),IF(G8&""="1",N(K8)*N8,(N8+N(O8))*N(K8))) | T8: =IF(Q8="","",Q8-S8)
A9: =CONCATENATE(C9,E9,F9,I9) | B9: =CONCATENATE(C9,E9,I9) | C9: 900000138 | D9: =IFERROR(VLOOKUP(C9,TRAOPE!$G:$H,2,0),"") | E9: D848 | F9: 66632312 | G9: =IFERROR(VLOOKUP(A9,Flete!$A:$E,5,0),"") | H9: =IFERROR(VLOOKUP(F9,TRAOPE!$AA:$AB,2,0),"") | I9: 10000402 | J9: =IFERROR(VLOOKUP(I9,Materiales!$A:$H,8,0),"") | K9: =IFERROR(VLOOKUP(I9,Materiales!$A:$G,7,0),"") | L9: 20191211 | M9: 20251031 | N9: 100.5 | O9: =IFERROR(VLOOKUP(A9,Flete!$A:$J,10,0),"") | P9: TN | Q9: =IFERROR(IFERROR(VLOOKUP(A9,TRAOPE!$A:$U,21,0),VLOOKUP(B9,TRAOPE!$A:$U,21,0)),"") | R9: =IFERROR(IFERROR(VLOOKUP(A9,TRAOPE!$A:$W,23,0),VLOOKUP(B9,TRAOPE!$A:$W,23,0)),"") | S9: =IF(AND(P9="TN",R9="TN"),N9+N(O9),IF(G9&""="1",N(K9)*N9,(N9+N(O9))*N(K9))) | T9: =IF(Q9="","",Q9-S9)
A10: =CONCATENATE(C10,E10,F10,I10) | B10: =CONCATENATE(C10,E10,I10) | C10: 900000138 | D10: =IFERROR(VLOOKUP(C10,TRAOPE!$G:$H,2,0),"") | E10: D848 | F10: 66632312 | G10: =IFERROR(VLOOKUP(A10,Flete!$A:$E,5,0),"") | H10: =IFERROR(VLOOKUP(F10,TRAOPE!$AA:$AB,2,0),"") | I10: 10000404 | J10: =IFERROR(VLOOKUP(I10,Materiales!$A:$H,8,0),"") | K10: =IFERROR(VLOOKUP(I10,Materiales!$A:$G,7,0),"") | L10: 20191211 | M10: 20251031 | N10: 99.45 | O10: =IFERROR(VLOOKUP(A10,Flete!$A:$J,10,0),"") | P10: TN | Q10: =IFERROR(IFERROR(VLOOKUP(A10,TRAOPE!$A:$U,21,0),VLOOKUP(B10,TRAOPE!$A:$U,21,0)),"") | R10: =IFERROR(IFERROR(VLOOKUP(A10,TRAOPE!$A:$W,23,0),VLOOKUP(B10,TRAOPE!$A:$W,23,0)),"") | S10: =IF(AND(P10="TN",R10="TN"),N10+N(O10),IF(G10&""="1",N(K10)*N10,(N10+N(O10))*N(K10))) | T10: =IF(Q10="","",Q10-S10)
A11: =CONCATENATE(C11,E11,F11,I11) | B11: =CONCATENATE(C11,E11,I11) | C11: 900000138 | D11: =IFERROR(VLOOKUP(C11,TRAOPE!$G:$H,2,0),"") | E11: D848 | F11: 66632312 | G11: =IFERROR(VLOOKUP(A11,Flete!$A:$E,5,0),"") | H11: =IFERROR(VLOOKUP(F11,TRAOPE!$AA:$AB,2,0),"") | I11: 10000407 | J11: =IFERROR(VLOOKUP(I11,Materiales!$A:$H,8,0),"") | K11: =IFERROR(VLOOKUP(I11,Materiales!$A:$G,7,0),"") | L11: 20191211 | M11: 20251031 | N11: 99.45 | O11: =IFERROR(VLOOKUP(A11,Flete!$A:$J,10,0),"") | P11: TN | Q11: =IFERROR(IFERROR(VLOOKUP(A11,TRAOPE!$A:$U,21,0),VLOOKUP(B11,TRAOPE!$A:$U,21,0)),"") | R11: =IFERROR(IFERROR(VLOOKUP(A11,TRAOPE!$A:$W,23,0),VLOOKUP(B11,TRAOPE!$A:$W,23,0)),"") | S11: =IF(AND(P11="TN",R11="TN"),N11+N(O11),IF(G11&""="1",N(K11)*N11,(N11+N(O11))*N(K11))) | T11: =IF(Q11="","",Q11-S11)
A12: =CONCATENATE(C12,E12,F12,I12) | B12: =CONCATENATE(C12,E12,I12) | C12: 900000138 | D12: =IFERROR(VLOOKUP(C12,TRAOPE!$G:$H,2,0),"") | E12: D848 | F12: 66632312 | G12: =IFERROR(VLOOKUP(A12,Flete!$A:$E,5,0),"") | H12: =IFERROR(VLOOKUP(F12,TRAOPE!$AA:$AB,2,0),"") | I12: 10000859 | J12: =IFERROR(VLOOKUP(I12,Materiales!$A:$H,8,0),"") | K12: =IFERROR(VLOOKUP(I12,Materiales!$A:$G,7,0),"") | L12: 20191211 | M12: 20251031 | N12: 100.5 | O12: =IFERROR(VLOOKUP(A12,Flete!$A:$J,10,0),"") | P12: TN | Q12: =IFERROR(IFERROR(VLOOKUP(A12,TRAOPE!$A:$U,21,0),VLOOKUP(B12,TRAOPE!$A:$U,21,0)),"") | R12: =IFERROR(IFERROR(VLOOKUP(A12,TRAOPE!$A:$W,23,0),VLOOKUP(B12,TRAOPE!$A:$W,23,0)),"") | S12: =IF(AND(P12="TN",R12="TN"),N12+N(O12),IF(G12&""="1",N(K12)*N12,(N12+N(O12))*N(K12))) | T12: =IF(Q12="","",Q12-S12)
A13: =CONCATENATE(C13,E13,F13,I13) | B13: =CONCATENATE(C13,E13,I13) | C13: 900000138 | D13: =IFERROR(VLOOKUP(C13,TRAOPE!$G:$H,2,0),"") | E13: D848 | F13: 66632312 | G13: =IFERROR(VLOOKUP(A13,Flete!$A:$E,5,0),"") | H13: =IFERROR(VLOOKUP(F13,TRAOPE!$AA:$AB,2,0),"") | I13: 10087726 | J13: =IFERROR(VLOOKUP(I13,Materiales!$A:$H,8,0),"") | K13: =IFERROR(VLOOKUP(I13,Materiales!$A:$G,7,0),"") | L13: 20191211 | M13: 20251031 | N13: 99.45 | O13: =IFERROR(VLOOKUP(A13,Flete!$A:$J,10,0),"") | P13: TN | Q13: =IFERROR(IFERROR(VLOOKUP(A13,TRAOPE!$A:$U,21,0),VLOOKUP(B13,TRAOPE!$A:$U,21,0)),"") | R13: =IFERROR(IFERROR(VLOOKUP(A13,TRAOPE!$A:$W,23,0),VLOOKUP(B13,TRAOPE!$A:$W,23,0)),"") | S13: =IF(AND(P13="TN",R13="TN"),N13+N(O13),IF(G13&""="1",N(K13)*N13,(N13+N(O13))*N(K13))) | T13: =IF(Q13="","",Q13-S13)
A14: =CONCATENATE(C14,E14,F14,I14) | B14: =CONCATENATE(C14,E14,I14) | C14: 900000138 | D14: =IFERROR(VLOOKUP(C14,TRAOPE!$G:$H,2,0),"") | E14: D848 | F14: 66817822 | G14: =IFERROR(VLOOKUP(A14,Flete!$A:$E,5,0),"") | H14: =IFERROR(VLOOKUP(F14,TRAOPE!$AA:$AB,2,0),"") | I14: 10000141 | J14: =IFERROR(VLOOKUP(I14,Materiales!$A:$H,8,0),"") | K14: =IFERROR(VLOOKUP(I14,Materiales!$A:$G,7,0),"") | L14: 20191211 | M14: 20251031 | N14: 114.07 | O14: =IFERROR(VLOOKUP(A14,Flete!$A:$J,10,0),"") | P14: TN | Q14: =IFERROR(IFERROR(VLOOKUP(A14,TRAOPE!$A:$U,21,0),VLOOKUP(B14,TRAOPE!$A:$U,21,0)),"") | R14: =IFERROR(IFERROR(VLOOKUP(A14,TRAOPE!$A:$W,23,0),VLOOKUP(B14,TRAOPE!$A:$W,23,0)),"") | S14: =IF(AND(P14="TN",R14="TN"),N14+N(O14),IF(G14&""="1",N(K14)*N14,(N14+N(O14))*N(K14))) | T14: =IF(Q14="","",Q14-S14)
... A141: =CONCATENATE(C141,E141,F141,I141) | B141: =CONCATENATE(C141,E141,I141) | C141: 900004960 | D141: =IFERROR(VLOOKUP(C141,TRAOPE!$G:$H,2,0),"") | E141: D848 | F141: 66655116 | G141: =IFERROR(VLOOKUP(A141,Flete!$A:$E,5,0),"") | H141: =IFERROR(VLOOKUP(F141,TRAOPE!$AA:$AB,2,0),"") | I141: 10132162 | J141: =IFERROR(VLOOKUP(I141,Materiales!$A:$H,8,0),"") | K141: =IFERROR(VLOOKUP(I141,Materiales!$A:$G,7,0),"") | L141: 20200604 | M141: 99991231 | N141: 135 | O141: =IFERROR(VLOOKUP(A141,Flete!$A:$J,10,0),"") | P141: TN | Q141: =IFERROR(IFERROR(VLOOKUP(A141,TRAOPE!$A:$U,21,0),VLOOKUP(B141,TRAOPE!$A:$U,21,0)),"") | R141: =IFERROR(IFERROR(VLOOKUP(A141,TRAOPE!$A:$W,23,0),VLOOKUP(B141,TRAOPE!$A:$W,23,0)),"") | S141: =IF(AND(P141="TN",R141="TN"),N141+N(O141),IF(G141&""="1",N(K141)*N141,(N141+N(O141))*N(K141))) | T141: =IF(Q141="","",Q141-S141)

Sheet MP
A1: No. SF | B1: Cedis | C1: Destino | D1: No. Material | E1: Nombre Material | F1: Importe MP | G1: Moneda | H1: Cantidad | I1: UM | J1: C | K1: Inicio Vigencia | L1: Fin Vigencia
A2: 900000138 | B2: D848 | C2: 66540419 | D2: 10000141 | F2: 105 | I2: TN | K2: 20191211 | L2: 20251031
A3: 900000138 | B3: D848 | C3: 66540419 | D3: 10000402 | F3: 105 | I3: TN | K3: 20191211 | L3: 20251031
A4: 900000138 | B4: D848 | C4: 66540419 | D4: 10000404 | F4: 105 | I4: TN | K4: 20191211 | L4: 20251031
A5: 900000138 | B5: D848 | C5: 66540419 | D5: 10000407 | F5: 105 | I5: TN | K5: 20191211 | L5: 20251031
A6: 900000138 | B6: D848 | C6: 66540419 | D6: 10000859 | F6: 105 | I6: TN | K6: 20191211 | L6: 20251031
A7: 900000138 | B7: D848 | C7: 66632312 | D7: 10000141 | F7: 99.45 | I7: TN | K7: 20191211 | L7: 20251031
A8: 900000138 | B8: D848 | C8: 66632312 | D8: 10000402 | F8: 100.5 | I8: TN | K8: 20191211 | L8: 20251031
A9: 900000138 | B9: D848 | C9: 66632312 | D9: 10000404 | F9: 99.45 | I9: TN | K9: 20191211 | L9: 20251031
A10: 900000138 | B10: D848 | C10: 66632312 | D10: 10000407 | F10: 99.45 | I10: TN | K10: 20191211 | L10: 20251031
A11: 900000138 | B11: D848 | C11: 66632312 | D11: 10000859 | F11: 100.5 | I11: TN | K11: 20191211 | L11: 20251031
A12: 900000138 | B12: D848 | C12: 66632312 | D12: 10087726 | F12: 99.45 | I12: TN | K12: 20191211 | L12: 20251031
A13: 900000138 | B13: D848 | C13: 66817822 | D13: 10000141 | F13: 114.07 | I13: TN | K13: 20191211 | L13: 20251031
... A140: 900004960 | B140: D848 | C140: 66655116 | D140: 10132162 | F140: 135 | I140: TN | K140: 20200604 | L140: 99991231

Sheet Flete
A1: Concat1 | B1: No. SF | C1: Cedis | D1: Destino | E1: Cond. Exp. | F1: Material | H1: Nombre Material | J1: Importe Flete | K1: Moneda | L1: Cantidad | M1: UM | N1: C | P1: Inicio Vigencia | Q1: Fin Vigencia
A2: 900000138D8486654041910000141 | B2: 900000138 | C2: D848 | D2: 66540419 | E2: 4 | F2: 10000141 | J2: 220 | M2: TN | P2: 20191211 | Q2: 20251031
A3: 900000138D8486654041910000402 | B3: 900000138 | C3: D848 | D3: 66540419 | E3: 4 | F3: 10000402 | J3: 220 | M3: TN | P3: 20191211 | Q3: 20251031
A4: 900000138D8486654041910000404 | B4: 900000138 | C4: D848 | D4: 66540419 | E4: 4 | F4: 10000404 | J4: 220 | M4: TN | P4: 20191211 | Q4: 20251031
A5: 900000138D8486654041910000407 | B5: 900000138 | C5: D848 | D5: 66540419 | E5: 4 | F5: 10000407 | J5: 220 | M5: TN | P5: 20191211 | Q5: 20251031
A6: 900000138D8486654041910000859 | B6: 900000138 | C6: D848 | D6: 66540419 | E6: 4 | F6: 10000859 | J6: 220 | M6: TN | P6: 20191211 | Q6: 20251031
A7: 900000138D8486663231210000141 | B7: 900000138 | C7: D848 | D7: 66632312 | E7: 4 | F7: 10000141 | J7: 99 | M7: TN | P7: 20191211 | Q7: 20251031
A8: 900000138D8486663231210000402 | B8: 900000138 | C8: D848 | D8: 66632312 | E8: 4 | F8: 10000402 | J8: 99 | M8: TN | P8: 20191211 | Q8: 20251031
A9: 900000138D8486663231210000404 | B9: 900000138 | C9: D848 | D9: 66632312 | E9: 4 | F9: 10000404 | J9: 99 | M9: TN | P9: 20191211 | Q9: 20251031
A10: 900000138D8486663231210000407 | B10: 900000138 | C10: D848 | D10: 66632312 | E10: 4 | F10: 10000407 | J10: 99 | M10: TN | P10: 20191211 | Q10: 20251031
A11: 900000138D8486663231210000859 | B11: 900000138 | C11: D848 | D11: 66632312 | E11: 4 | F11: 10000859 | J11: 99 | M11: TN | P11: 20191211 | Q11: 20251031
A12: 900000138D8486663231210087726 | B12: 900000138 | C12: D848 | D12: 66632312 | E12: 4 | F12: 10087726 | J12: 99 | M12: TN | P12: 20191211 | Q12: 20251031
A13: 900000138D8486681782210000141 | B13: 900000138 | C13: D848 | D13: 66817822 | E13: 4 | F13: 10000141 | J13: 220 | M13: TN | P13: 20191211 | Q13: 20251031
... A108: 900004960D8486665511610132162 | B108: 900004960 | C108: D848 | D108: 66655116 | E108: 4 | F108: 10132162 | J108: 210 | M108: TN | P108: 20200604 | Q108: 99991231

Sheet Materiales
A1: Material | B1: TpMt | C1: Denom | D1: UMA | E1: Contador | F1: UMB | G1: PV | H1: Nombre Material
A2: 10000001 | B2: ZFER | C2: 1000 | D2: M3 | E2: 1000 | F2: TN | G2: 1262 | H2: GRAVA ANDESITA 10 MM (3/8")
A3: 10000003 | B3: ZFER | C3: 1000 | D3: M3 | E3: 1000 | F3: TN | G3: 1443 | H3: GRAVA CALIZA 10 MM (3/8")
A4: 10000006 | B4: ZFER | C4: 1000 | D4: M3 | E4: 1000 | F4: TN | G4: 1490 | H4: GRAVA RIO 10 MM (3/8")
A5: 10000007 | B5: ZFER | C5: 1000 | D5: M3 | E5: 1000 | F5: TN | G5: 1488 | H5: GRAVA BASALTO 13 MM (1/2")
A6: 10000008 | B6: ZFER | C6: 1000 | D6: M3 | E6: 1000 | F6: TN | G6: 1358 | H6: GRAVA CALIZA 13 MM (1/2")
A7: 10000011 | B7: ZFER | C7: 1000 | D7: M3 | E7: 1000 | F7: TN | G7: 1323 | H7: GRAVA ANDESITA 20 MM (3/4")
A8: 10000013 | B8: ZFER | C8: 1000 | D8: M3 | E8: 1000 | F8: TN | G8: 1514 | H8: GRAVA BASALTO 20 MM (3/4")
A9: 10000014 | B9: ZFER | C9: 1000 | D9: M3 | E9: 1000 | F9: TN | G9: 1400 | H9: GRAVA CALIZA 20 MM (3/4")
A10: 10000015 | B10: ZFER | C10: 1000 | D10: M3 | E10: 1000 | F10: TN | G10: 1410 | H10: GRAVA GRANITO 20 MM (3/4")
A11: 10000017 | B11: ZFER | C11: 1000 | D11: M3 | E11: 1000 | F11: TN | G11: 1475 | H11: GRAVA RIOLITA 20 MM (3/4")
A12: 10000019 | B12: ZFER | C12: 1000 | D12: M3 | E12: 1000 | F12: TN | G12: 1515 | H12: GRAVA RIO 20 MM (3/4")
A13: 10000020 | B13: ZFER | C13: 1000 | D13: M3 | E13: 1 | F13: TN | G13: 1 | H13: GRAVA MAQUILA 40MM (1 1/2")
... A2291: 10268770 | B2291: ZFE3 | C2291: 1000 | D2291: M3 | E2291: 1000 | F2291: TN | G2291: 1240 | H2291: MP GRAVA TRIT CALIZA 40MM 1 1/2" - ESP
A2292: 10268901 | B2292: ZFE3 | C2292: 1000 | D2292: M3 | E2292: 1000 | G2292: 1560 | H2292: MP GRAVA ANDESITA GRIS 3/4" - CAPADA
A2293: 10267983 | C2293: 1000 | G2293: 1800 | H2293: ESCORIA ALTO HORNO 3/4
A2294: 10268996 | C2294: 1000 | G2294: 1329 | H2294: GRAVA TRITURADA CALIZA 40 MM - 11/2"
A2295: 10269072 | C2295: 1000 | G2295: 1700 | H2295: BASE HIDRÁULICA SCREEN
A2296: 10269225 | B2296: ZFE3 | C2296: 1000 | D2296: M3 | E2296: 1000 | G2296: 1289 | H2296: MP ARENA CALIZA LAVADA MALLA 4 - DELTA I
A2297: 10269245 | B2297: ZFE3 | C2297: 1000 | D2297: M3 | E2297: 1000 | G2297: 1410 | H2297: MP GRAVA TRITURADA CALIZA 3/8 - 10MM
A2298: 10269246 | B2298: ZFE3 | C2298: 1000 | D2298: M3 | E2298: 1000 | G2298: 1400 | H2298: MP GRAVA TRITURADA CALIZA 1 1/2 - 40MM
A2299: 10269247 | B2299: ZFE3 | C2299: 1000 | D2299: M3 | E2299: 1000 | G2299: 1560 | H2299: MP ARENA TRIT CALIZA M-4
A2300: 10270431 | B2300: ZFE3 | C2300: 1000 | D2300: M3 | E2300: 1000 | G2300: 1423 | H2300: MP GRAVA RIOLITA 13 MM - 1/2"
A2301: 10270898 | B2301: ZFE3 | C2301: 1000 | D2301: M3 | E2301: 1000 | G2301: 1551 | H2301: MP BASE H. TRIT. BASALTO 1 1/2" A FINOS
A2302: 10270911 | B2302: ZFE3 | C2302: 1000 | D2302: M3 | E2302: 1000 | G2302: 1360 | H2302: MP GRAVA TRIT. BASALTO 40 MM - 1 1/2"
A2303: 10270912 | B2303: ZFE3 | C2303: 1000 | D2303: M3 | E2303: 1000 | G2303: 1589 | H2303: MP ARENA TRIT. BASALTO MALLA 4
A2304: 10270913 | B2304: ZFE3 | C2304: 1000 | D2304: M3 | E2304: 1000 | G2304: 1395 | H2304: MP GRAVA TRIT. BASALTO 20 MM - 3/4
A2305: 10270914 | B2305: ZFE3 | C2305: 1000 | D2305: M3 | E2305: 1000 | G2305: 1623 | H2305: MP ARENA ANDESITA BC
A2306: 10270824 | B2306: M3 | C2306: 1000 | D2306: M3 | E2306: 10007640 | G2306: 1325 | H2306: MP ARENA TRITURADA CALIZA MALLA 5
A2307: 10270825 | B2307: M3 | C2307: 1000 | D2307: M3 | E2307: 10000003 | G2307: 1242 | H2307: MP GRAVA TRITURADA CALIZA 10MM (3/8”)
... A2319: 10272527 | B2319: ZFE3 | C2319: 1000 | D2319: M3 | E2319: 1000 | G2319: 1620 | H2319: CNC - NO CLASIFICADO
A2320: 10000332 | C2320: 1000 | D2320: M3 | E2320: 1000 | G2320: 800 | H2320: Grava Triturada Pomez - Jal 20 mm - 3/4"
A2321: 10273001 | B2321: ZFE3 | C2321: 1000 | D2321: M3 | E2321: 1000 | G2321: 1688 | H2321: MP ARENA TRIT. BASALTO MALLA 4
A2322: 10273002 | B2322: ZFE3 | C2322: 1000 | D2322: M3 | E2322: 1000 | G2322: 1466 | H2322: MP GRAVA TRIT. BASALTO 20 MM - 3/4"
A2323: 10273351 | B2323: ZFE3 | C2323: 1000 | D2323: M3 | E2323: 1000 | G2323: 1612 | H2323: MP ARENA TRIT. CALIZA MALLA 4
A2324: 10273352 | B2324: ZFE3 | C2324: 1000 | D2324: M3 | E2324: 1000 | G2324: 1492 | H2324: MP GRAVA TRIT. CALIZA 20 MM - 3/4"
A2325: 10271724 | B2325: ZFE3 | C2325: 1000 | D2325: M3 | E2325: 1000 | G2325: 1900 | H2325: MP RESIDUO DE CONCRETO
A2326: 10000677 | C2326: 1000 | D2326: M3 | G2326: 1164 | H2326: Grava Triturada Caliza 20 mm - 3/4"
A2327: 10274190 | B2327: ZFE3 | C2327: 1000 | D2327: M3 | E2327: 1000 | G2327: 1800 | H2327: MP BASE HIDRAULICA ANDESITA 70-30
A2328: 10274601 | B2328: ZFE3 | C2328: 1000 | D2328: M3 | E2328: 1000 | G2328: 1447 | H2328: MP ARENA BASALTO N° 4
...

Sheet TRAOPE
A1: Concat1 | B1: Contrato_Pos | C1: Doc. Compras | D1: Pos | E1: Org.compras | F1: Grp-Compr. | G1: Ship From | H1: Nombre SF | I1: Proveedor | J1: Nombre Prov | K1: Cond. Pago | L1: Descr. Cond Pago | M1: Material | N1: Descripción | O1: Centro | P1: Descripción Centro | Q1: In.perído validez | R1: Fin perído validez | S1: Válido de | T1: Validez a | U1: Precio neto pedido | V1: Moneda | W1: UM Precio Pedido | X1: Importe Condición | Y1: Moneda KONP | Z1: UM Ctd Base | AA1: Destino | AB1: Nombre Destino | AC1: Cuenta de mayor | AD1: Centro de costo | AE1: Cond. Exp. | AF1: Descr. Cond. Exp. | AG1: Peso Vol. | AH1: UMB | AI1: Ind. Oblig. Conf. Ped. | AJ1: Ctrl-Conf. | AK1: IVA | AL1: Modif_Date | AM1: Ruta
A2: 900000138D8486710185410087726 | B2: 4600042903-550 | C2: 4600042903 | D2: 550 | E2: MXPO | F2: MXL | G2: 900000138 | H2: TP- ED GRAMOL | I2: 5005459 | J2: TRITURADOS GRAMOL SA DE CV | K2: Z04 | L2: (AP) 30 Dias | M2: 10087726 | N2: BASE HIDRAULICA CALIZA 50% EQ. ARENA SCT | O2: D848 | P2: MX-CED. SALTILLO | Q2: 20180901 | R2: 20281231 | S2: 20230302 | T2: 20281231 | U2: 178.21 | V2: MXN | W2: TN | X2: 57 | Y2: MXN | Z2: TN | AA2: 67101854 | AB2: Ampliación Emerson | AC2: 56103590 | AD2: 6622381540 | AE2: 4 | AF2: ENTREGA DIRECTA | AG2: 1 | AH2: TO | AI2: X | AJ2: 4 | AK2: V4 | AL2: 20230920 | AM2: D848-900000138-67101854-10087726-4
A3: 900000138D8486732549110000859 | B3: 4600042903-730 | C3: 4600042903 | D3: 730 | E3: MXPO | F3: MXL | G3: 900000138 | H3: TP- ED GRAMOL | I3: 5005459 | J3: TRITURADOS GRAMOL SA DE CV | K3: Z04 | L3: (AP) 30 Dias | M3: 10000859 | N3: Arena Triturada Caliza Malla 5 | O3: D848 | P3: MX-CED. SALTILLO | Q3: 20180901 | R3: 20281231 | S3: 20260227 | T3: 20301231 | U3: 337 | V3: MXN | W3: TN | X3: 147 | Y3: MXN | Z3: TN | AA3: 67325491 | AB3: BLOCK CERESO | AC3: 56103638 | AD3: 6622381540 | AE3: 4 | AF3: ENTREGA DIRECTA | AG3: 1 | AH3: TO | AI3: X | AJ3: 4 | AK3: V4 | AL3: 20260303 | AM3: D848-900000138-67325491-10000859-4
A4: 900000138D8486732549110000402 | B4: 4600042903-720 | C4: 4600042903 | D4: 720 | E4: MXPO | F4: MXL | G4: 900000138 | H4: TP- ED GRAMOL | I4: 5005459 | J4: TRITURADOS GRAMOL SA DE CV | K4: Z04 | L4: (AP) 30 Dias | M4: 10000402 | N4: Arena Triturada Caliza Malla 4 | O4: D848 | P4: MX-CED. SALTILLO | Q4: 20180901 | R4: 20281231 | S4: 20260227 | T4: 20301231 | U4: 337 | V4: MXN | W4: TN | X4: 147 | Y4: MXN | Z4: TN | AA4: 67325491 | AB4: BLOCK CERESO | AC4: 56103638 | AD4: 6622381540 | AE4: 4 | AF4: ENTREGA DIRECTA | AG4: 1 | AH4: TO | AI4: X | AJ4: 4 | AK4: V4 | AL4: 20260303 | AM4: D848-900000138-67325491-10000402-4
A5: 900000138D8486732549110000407 | B5: 4600042903-740 | C5: 4600042903 | D5: 740 | E5: MXPO | F5: MXL | G5: 900000138 | H5: TP- ED GRAMOL | I5: 5005459 | J5: TRITURADOS GRAMOL SA DE CV | K5: Z04 | L5: (AP) 30 Dias | M5: 10000407 | N5: Grava Triturada Caliza 10 mm - 3/8" | O5: D848 | P5: MX-CED. SALTILLO | Q5: 20180901 | R5: 20281231 | S5: 20260227 | T5: 20301231 | U5: 337 | V5: MXN | W5: TN | X5: 147 | Y5: MXN | Z5: TN | AA5: 67325491 | AB5: BLOCK CERESO | AC5: 56103637 | AD5: 6622381540 | AE5: 4 | AF5: ENTREGA DIRECTA | AG5: 1 | AH5: TO | AI5: X | AJ5: 4 | AK5: V4 | AL5: 20260303 | AM5: D848-900000138-67325491-10000407-4
A6: 900006565D84810087726 | B6: 4600046992-60 | C6: 4600046992 | D6: 60 | E6: MXPO | F6: MXL | G6: 900006565 | H6: SF TP-GRAMOL RECOGIDO | I6: 5005459 | J6: TRITURADOS GRAMOL SA DE CV | K6: Z04 | L6: (AP) 30 Dias | M6: 10087726 | N6: BASE HIDRAULICA CALIZA 50% EQ. ARENA SCT | O6: D848 | P6: MX-CED. SALTILLO | Q6: 20200416 | R6: 20291231 | S6: 20260527 | T6: 20301231 | U6: 195 | V6: MXN | W6: TN | X6: 0 | Y6: MXN | Z6: TN | AC6: 56103590 | AD6: 6622381540 | AE6: 2 | AF6: RECOGIDO | AG6: 1 | AH6: TO | AI6: X | AJ6: 4 | AK6: V4 | AL6: 20260528 | AM6: D848-900006565-10087726
A7: 900006565D84810000404 | B7: 4600046992-30 | C7: 4600046992 | D7: 30 | E7: MXPO | F7: MXL | G7: 900006565 | H7: SF TP-GRAMOL RECOGIDO | I7: 5005459 | J7: TRITURADOS GRAMOL SA DE CV | K7: Z04 | L7: (AP) 30 Dias | M7: 10000404 | N7: Grava Triturada Caliza 20 mm - 3/4" | O7: D848 | P7: MX-CED. SALTILLO | Q7: 20200416 | R7: 20291231 | S7: 20260527 | T7: 20301231 | U7: 195 | V7: MXN | W7: TN | X7: 0 | Y7: MXN | Z7: TN | AC7: 56103637 | AD7: 6622381540 | AE7: 2 | AF7: RECOGIDO | AG7: 1 | AH7: TO | AI7: X | AJ7: 4 | AK7: V4 | AL7: 20260528 | AM7: D848-900006565-10000404
A8: 900000138D8486737808510087726 | B8: 4600042903-970 | C8: 4600042903 | D8: 970 | E8: MXPO | F8: MXL | G8: 900000138 | H8: TP- ED GRAMOL | I8: 5005459 | J8: TRITURADOS GRAMOL SA DE CV | K8: Z04 | L8: (AP) 30 Dias | M8: 10087726 | N8: BASE HIDRAULICA CALIZA 50% EQ. ARENA SCT | O8: D848 | P8: MX-CED. SALTILLO | Q8: 20180901 | R8: 20281231 | S8: 20260527 | T8: 20301231 | U8: 220 | V8: MXN | W8: TN | X8: 25 | Y8: MXN | Z8: TN | AA8: 67378085 | AB8: HOLDING PLANTA DURMIENTES ARTEAGA | AC8: 56103590 | AD8: 6622381540 | AE8: 4 | AF8: ENTREGA DIRECTA | AG8: 1 | AH8: TO | AI8: X | AJ8: 4 | AK8: V4 | AL8: 20260528 | AM8: D848-900000138-67378085-10087726-4
A9: 900006565D84810128836 | B9: 4600046992-70 | C9: 4600046992 | D9: 70 | E9: MXPO | F9: MXL | G9: 900006565 | H9: SF TP-GRAMOL RECOGIDO | I9: 5005459 | J9: TRITURADOS GRAMOL SA DE CV | K9: Z04 | L9: (AP) 30 Dias | M9: 10128836 | N9: MIXTO - ARENA4/GRAVA 20 | O9: D848 | P9: MX-CED. SALTILLO | Q9: 20200416 | R9: 20291231 | S9: 20260527 | T9: 20301231 | U9: 195 | V9: MXN | W9: TN | X9: 0 | Y9: MXN | Z9: TN | AC9: 56103590 | AD9: 6622381540 | AE9: 2 | AF9: RECOGIDO | AG9: 1 | AH9: TO | AI9: X | AJ9: 4 | AK9: V4 | AL9: 20260528 | AM9: D848-900006565-10128836
A10: 900000138D8486737808510000402 | B10: 4600042903-910 | C10: 4600042903 | D10: 910 | E10: MXPO | F10: MXL | G10: 900000138 | H10: TP- ED GRAMOL | I10: 5005459 | J10: TRITURADOS GRAMOL SA DE CV | K10: Z04 | L10: (AP) 30 Dias | M10: 10000402 | N10: Arena Triturada Caliza Malla 4 | O10: D848 | P10: MX-CED. SALTILLO | Q10: 20180901 | R10: 20281231 | S10: 20260527 | T10: 20301231 | U10: 220 | V10: MXN | W10: TN | X10: 25 | Y10: MXN | Z10: TN | AA10: 67378085 | AB10: HOLDING PLANTA DURMIENTES ARTEAGA | AC10: 56103638 | AD10: 6622381540 | AE10: 4 | AF10: ENTREGA DIRECTA | AG10: 1 | AH10: TO | AI10: X | AJ10: 4 | AK10: V4 | AL10: 20260528 | AM10: D848-900000138-67378085-10000402-4
A11: 900006565D84810000407 | B11: 4600046992-50 | C11: 4600046992 | D11: 50 | E11: MXPO | F11: MXL | G11: 900006565 | H11: SF TP-GRAMOL RECOGIDO | I11: 5005459 | J11: TRITURADOS GRAMOL SA DE CV | K11: Z04 | L11: (AP) 30 Dias | M11: 10000407 | N11: Grava Triturada Caliza 10 mm - 3/8" | O11: D848 | P11: MX-CED. SALTILLO | Q11: 20200416 | R11: 20291231 | S11: 20260527 | T11: 20301231 | U11: 195 | V11: MXN | W11: TN | X11: 0 | Y11: MXN | Z11: TN | AC11: 56103637 | AD11: 6622381540 | AE11: 2 | AF11: RECOGIDO | AG11: 1 | AH11: TO | AI11: X | AJ11: 4 | AK11: V4 | AL11: 20260528 | AM11: D848-900006565-10000407
A12: 900000138D8486737808510000407 | B12: 4600042903-960 | C12: 4600042903 | D12: 960 | E12: MXPO | F12: MXL | G12: 900000138 | H12: TP- ED GRAMOL | I12: 5005459 | J12: TRITURADOS GRAMOL SA DE CV | K12: Z04 | L12: (AP) 30 Dias | M12: 10000407 | N12: Grava Triturada Caliza 10 mm - 3/8" | O12: D848 | P12: MX-CED. SALTILLO | Q12: 20180901 | R12: 20281231 | S12: 20260527 | T12: 20301231 | U12: 220 | V12: MXN | W12: TN | X12: 25 | Y12: MXN | Z12: TN | AA12: 67378085 | AB12: HOLDING PLANTA DURMIENTES ARTEAGA | AC12: 56103637 | AD12: 6622381540 | AE12: 4 | AF12: ENTREGA DIRECTA | AG12: 1 | AH12: TO | AI12: X | AJ12: 4 | AK12: V4 | AL12: 20260528 | AM12: D848-900000138-67378085-10000407-4
A13: 900006565D84810000141 | B13: 4600046992-40 | C13: 4600046992 | D13: 40 | E13: MXPO | F13: MXL | G13: 900006565 | H13: SF TP-GRAMOL RECOGIDO | I13: 5005459 | J13: TRITURADOS GRAMOL SA DE CV | K13: Z04 | L13: (AP) 30 Dias | M13: 10000141 | N13: Grava Triturada Caliza 40 mm - 1 1/2" | O13: D848 | P13: MX-CED. SALTILLO | Q13: 20200416 | R13: 20291231 | S13: 20260527 | T13: 20301231 | U13: 195 | V13: MXN | W13: TN | X13: 0 | Y13: MXN | Z13: TN | AC13: 56103637 | AD13: 6622381540 | AE13: 2 | AF13: RECOGIDO | AG13: 1 | AH13: TO | AI13: X | AJ13: 4 | AK13: V4 | AL13: 20260528 | AM13: D848-900006565-10000141
A14: 900000138D8486737808510000141 | B14: 4600042903-950 | C14: 4600042903 | D14: 950 | E14: MXPO | F14: MXL | G14: 900000138 | H14: TP- ED GRAMOL | I14: 5005459 | J14: TRITURADOS GRAMOL SA DE CV | K14: Z04 | L14: (AP) 30 Dias | M14: 10000141 | N14: Grava Triturada Caliza 40 mm - 1 1/2" | O14: D848 | P14: MX-CED. SALTILLO | Q14: 20180901 | R14: 20281231 | S14: 20260527 | T14: 20301231 | U14: 220 | V14: MXN | W14: TN | X14: 25 | Y14: MXN | Z14: TN | AA14: 67378085 | AB14: HOLDING PLANTA DURMIENTES ARTEAGA | AC14: 56103637 | AD14: 6622381540 | AE14: 4 | AF14: ENTREGA DIRECTA | AG14: 1 | AH14: TO | AI14: X | AJ14: 4 | AK14: V4 | AL14: 20260528 | AM14: D848-900000138-67378085-10000141-4
A15: 900006565D84810000402 | B15: 4600046992-10 | C15: 4600046992 | D15: 10 | E15: MXPO | F15: MXL | G15: 900006565 | H15: SF TP-GRAMOL RECOGIDO | I15: 5005459 | J15: TRITURADOS GRAMOL SA DE CV | K15: Z04 | L15: (AP) 30 Dias | M15: 10000402 | N15: Arena Triturada Caliza Malla 4 | O15: D848 | P15: MX-CED. SALTILLO | Q15: 20200416 | R15: 20291231 | S15: 20260527 | T15: 20301231 | U15: 195 | V15: MXN | W15: TN | X15: 0 | Y15: MXN | Z15: TN | AC15: 56103638 | AD15: 6622381540 | AE15: 2 | AF15: RECOGIDO | AG15: 1 | AH15: TO | AI15: X | AJ15: 4 | AK15: V4 | AL15: 20260528 | AM15: D848-900006565-10000402
A16: 900000138D8486737808510000859 | B16: 4600042903-920 | C16: 4600042903 | D16: 920 | E16: MXPO | F16: MXL | G16: 900000138 | H16: TP- ED GRAMOL | I16: 5005459 | J16: TRITURADOS GRAMOL SA DE CV | K16: Z04 | L16: (AP) 30 Dias | M16: 10000859 | N16: Arena Triturada Caliza Malla 5 | O16: D848 | P16: MX-CED. SALTILLO | Q16: 20180901 | R16: 20281231 | S16: 20260527 | T16: 20301231 | U16: 220 | V16: MXN | W16: TN | X16: 25 | Y16: MXN | Z16: TN | AA16: 67378085 | AB16: HOLDING PLANTA DURMIENTES ARTEAGA | AC16: 56103638 | AD16: 6622381540 | AE16: 4 | AF16: ENTREGA DIRECTA | AG16: 1 | AH16: TO | AI16: X | AJ16: 4 | AK16: V4 | AL16: 20260528 | AM16: D848-900000138-67378085-10000859-4
A17: 900006565D84810000859 | B17: 4600046992-20 | C17: 4600046992 | D17: 20 | E17: MXPO | F17: MXL | G17: 900006565 | H17: SF TP-GRAMOL RECOGIDO | I17: 5005459 | J17: TRITURADOS GRAMOL SA DE CV | K17: Z04 | L17: (AP) 30 Dias | M17: 10000859 | N17: Arena Triturada Caliza Malla 5 | O17: D848 | P17: MX-CED. SALTILLO | Q17: 20200416 | R17: 20291231 | S17: 20260527 | T17: 20301231 | U17: 195 | V17: MXN | W17: TN | X17: 0 | Y17: MXN | Z17: TN | AC17: 56103638 | AD17: 6622381540 | AE17: 2 | AF17: RECOGIDO | AG17: 1 | AH17: TO | AI17: X | AJ17: 4 | AK17: V4 | AL17: 20260528 | AM17: D848-900006565-10000859
A18: 900000138D8486737808510128836 | B18: 4600042903-930 | C18: 4600042903 | D18: 930 | E18: MXPO | F18: MXL | G18: 900000138 | H18: TP- ED GRAMOL | I18: 5005459 | J18: TRITURADOS GRAMOL SA DE CV | K18: Z04 | L18: (AP) 30 Dias | M18: 10128836 | N18: MIXTO - ARENA4/GRAVA 20 | O18: D848 | P18: MX-CED. SALTILLO | Q18: 20180901 | R18: 20281231 | S18: 20260527 | T18: 20301231 | U18: 220 | V18: MXN | W18: TN | X18: 25 | Y18: MXN | Z18: TN | AA18: 67378085 | AB18: HOLDING PLANTA DURMIENTES ARTEAGA | AC18: 56103590 | AD18: 6622381540 | AE18: 4 | AF18: ENTREGA DIRECTA | AG18: 1 | AH18: TO | AI18: X | AJ18: 4 | AK18: V4 | AL18: 20260528 | AM18: D848-900000138-67378085-10128836-4
A19: 900000138D8486737808510000404 | B19: 4600042903-940 | C19: 4600042903 | D19: 940 | E19: MXPO | F19: MXL | G19: 900000138 | H19: TP- ED GRAMOL | I19: 5005459 | J19: TRITURADOS GRAMOL SA DE CV | K19: Z04 | L19: (AP) 30 Dias | M19: 10000404 | N19: Grava Triturada Caliza 20 mm - 3/4" | O19: D848 | P19: MX-CED. SALTILLO | Q19: 20180901 | R19: 20281231 | S19: 20260527 | T19: 20301231 | U19: 220 | V19: MXN | W19: TN | X19: 25 | Y19: MXN | Z19: TN | AA19: 67378085 | AB19: HOLDING PLANTA DURMIENTES ARTEAGA | AC19: 56103637 | AD19: 6622381540 | AE19: 4 | AF19: ENTREGA DIRECTA | AG19: 1 | AH19: TO | AI19: X | AJ19: 4 | AK19: V4 | AL19: 20260528 | AM19: D848-900000138-67378085-10000404-4
A20: 900000138D8486732049710000402 | B20: 4600042903-760 | C20: 4600042903 | D20: 760 | E20: MXPO | F20: MXL | G20: 900000138 | H20: TP- ED GRAMOL | I20: 5005459 | J20: TRITURADOS GRAMOL SA DE CV | K20: Z04 | L20: (AP) 30 Dias | M20: 10000402 | N20: Arena Triturada Caliza Malla 4 | O20: D848 | P20: MX-CED. SALTILLO | Q20: 20180901 | R20: 20281231 | S20: 20260410 | T20: 20301231 | U20: 243 | V20: MXN | W20: TN | X20: 53 | Y20: MXN | Z20: TN | AA20: 67320497 | AB20: CONCRETOS HUASTECA SLW | AC20: 56103638 | AD20: 6622381540 | AE20: 4 | AF20: ENTREGA DIRECTA | AG20: 1 | AH20: TO | AI20: X | AJ20: 4 | AK20: V4 | AL20: 20260414 | AM20: D848-900000138-67320497-10000402-4
A21: 900000138D8486732049710000859 | B21: 4600042903-780 | C21: 4600042903 | D21: 780 | E21: MXPO | F21: MXL | G21: 900000138 | H21: TP- ED GRAMOL | I21: 5005459 | J21: TRITURADOS GRAMOL SA DE CV | K21: Z04 | L21: (AP) 30 Dias | M21: 10000859 | N21: Arena Triturada Caliza Malla 5 | O21: D848 | P21: MX-CED. SALTILLO | Q21: 20180901 | R21: 20281231 | S21: 20260410 | T21: 20301231 | U21: 243 | V21: MXN | W21: TN | X21: 53 | Y21: MXN | Z21: TN | AA21: 67320497 | AB21: CONCRETOS HUASTECA SLW | AC21: 56103638 | AD21: 6622381540 | AE21: 4 | AF21: ENTREGA DIRECTA | AG21: 1 | AH21: TO | AI21: X | AJ21: 4 | AK21: V4 | AL21: 20260414 | AM21: D848-900000138-67320497-10000859-4
A22: 900000138D8486732049710000407 | B22: 4600042903-770 | C22: 4600042903 | D22: 770 | E22: MXPO | F22: MXL | G22: 900000138 | H22: TP- ED GRAMOL | I22: 5005459 | J22: TRITURADOS GRAMOL SA DE CV | K22: Z04 | L22: (AP) 30 Dias | M22: 10000407 | N22: Grava Triturada Caliza 10 mm - 3/8" | O22: D848 | P22: MX-CED. SALTILLO | Q22: 20180901 | R22: 20281231 | S22: 20260410 | T22: 20301231 | U22: 243 | V22: MXN | W22: TN | X22: 53 | Y22: MXN | Z22: TN | AA22: 67320497 | AB22: CONCRETOS HUASTECA SLW | AC22: 56103637 | AD22: 6622381540 | AE22: 4 | AF22: ENTREGA DIRECTA | AG22: 1 | AH22: TO | AI22: X | AJ22: 4 | AK22: V4 | AL22: 20260414 | AM22: D848-900000138-67320497-10000407-4
A23: 900000138D8486732049710000404 | B23: 4600042903-800 | C23: 4600042903 | D23: 800 | E23: MXPO | F23: MXL | G23: 900000138 | H23: TP- ED GRAMOL | I23: 5005459 | J23: TRITURADOS GRAMOL SA DE CV | K23: Z04 | L23: (AP) 30 Dias | M23: 10000404 | N23: Grava Triturada Caliza 20 mm - 3/4" | O23: D848 | P23: MX-CED. SALTILLO | Q23: 20180901 | R23: 20281231 | S23: 20260410 | T23: 20301231 | U23: 243 | V23: MXN | W23: TN | X23: 53 | Y23: MXN | Z23: TN | AA23: 67320497 | AB23: CONCRETOS HUASTECA SLW | AC23: 56103637 | AD23: 6622381540 | AE23: 4 | AF23: ENTREGA DIRECTA | AG23: 1 | AH23: TO | AI23: X | AJ23: 4 | AK23: V4 | AL23: 20260414 | AM23: D848-900000138-67320497-10000404-4
A24: 900000138D8486732049710087726 | B24: 4600042903-790 | C24: 4600042903 | D24: 790 | E24: MXPO | F24: MXL | G24: 900000138 | H24: TP- ED GRAMOL | I24: 5005459 | J24: TRITURADOS GRAMOL SA DE CV | K24: Z04 | L24: (AP) 30 Dias | M24: 10087726 | N24: BASE HIDRAULICA CALIZA 50% EQ. ARENA SCT | O24: D848 | P24: MX-CED. SALTILLO | Q24: 20180901 | R24: 20281231 | S24: 20260410 | T24: 20301231 | U24: 243 | V24: MXN | W24: TN | X24: 53 | Y24: MXN | Z24: TN | AA24: 67320497 | AB24: CONCRETOS HUASTECA SLW | AC24: 56103590 | AD24: 6622381540 | AE24: 4 | AF24: ENTREGA DIRECTA | AG24: 1 | AH24: TO | AI24: X | AJ24: 4 | AK24: V4 | AL24: 20260414 | AM24: D848-900000138-67320497-10087726-4
A25: 900000138D8486732049710000141 | B25: 4600042903-750 | C25: 4600042903 | D25: 750 | E25: MXPO | F25: MXL | G25: 900000138 | H25: TP- ED GRAMOL | I25: 5005459 | J25: TRITURADOS GRAMOL SA DE CV | K25: Z04 | L25: (AP) 30 Dias | M25: 10000141 | N25: Grava Triturada Caliza 40 mm - 1 1/2" | O25: D848 | P25: MX-CED. SALTILLO | Q25: 20180901 | R25: 20281231 | S25: 20260410 | T25: 20301231 | U25: 243 | V25: MXN | W25: TN | X25: 53 | Y25: MXN | Z25: TN | AA25: 67320497 | AB25: CONCRETOS HUASTECA SLW | AC25: 56103637 | AD25: 6622381540 | AE25: 4 | AF25: ENTREGA DIRECTA | AG25: 1 | AH25: TO | AI25: X | AJ25: 4 | AK25: V4 | AL25: 20260414 | AM25: D848-900000138-67320497-10000141-4
A26: 900000138D8486716638210087726 | B26: 4600042903-610 | C26: 4600042903 | D26: 610 | E26: MXPO | F26: MXL | G26: 900000138 | H26: TP- ED GRAMOL | I26: 5005459 | J26: TRITURADOS GRAMOL SA DE CV | K26: Z04 | L26: (AP) 30 Dias | M26: 10087726 | N26: BASE HIDRAULICA CALIZA 50% EQ. ARENA SCT | O26: D848 | P26: MX-CED. SALTILLO | Q26: 20180901 | R26: 20281231 | S26: 20230814 | T26: 20271231 | U26: 236.21 | V26: MXN | W26: TN | X26: 115 | Y26: MXN | Z26: TN | AA26: 67166382 | AB26: CEMSA RAMOS ARIZPE | AC26: 56103590 | AD26: 6622381540 | AE26: 4 | AF26: ENTREGA DIRECTA | AG26: 1 | AH26: TO | AI26: X | AJ26: 4 | AK26: V4 | AL26: 20230920 | AM26: D848-900000138-67166382-10087726-4
A27: 900000138D8486716638210000141 | B27: 4600042903-590 | C27: 4600042903 | D27: 590 | E27: MXPO | F27: MXL | G27: 900000138 | H27: TP- ED GRAMOL | I27: 5005459 | J27: TRITURADOS GRAMOL SA DE CV | K27: Z04 | L27: (AP) 30 Dias | M27: 10000141 | N27: Grava Triturada Caliza 40 mm - 1 1/2" | O27: D848 | P27: MX-CED. SALTILLO | Q27: 20180901 | R27: 20281231 | S27: 20230814 | T27: 20271231 | U27: 236.21 | V27: MXN | W27: TN | X27: 115 | Y27: MXN | Z27: TN | AA27: 67166382 | AB27: CEMSA RAMOS ARIZPE | AC27: 56103637 | AD27: 6622381540 | AE27: 4 | AF27: ENTREGA DIRECTA | AG27: 1 | AH27: TO | AI27: X | AJ27: 4 | AK27: V4 | AL27: 20230920 | AM27: D848-900000138-67166382-10000141-4
A28: 900000138D8486716638210000402 | B28: 4600042903-560 | C28: 4600042903 | D28: 560 | E28: MXPO | F28: MXL | G28: 900000138 | H28: TP- ED GRAMOL | I28: 5005459 | J28: TRITURADOS GRAMOL SA DE CV | K28: Z04 | L28: (AP) 30 Dias | M28: 10000402 | N28: Arena Triturada Caliza Malla 4 | O28: D848 | P28: MX-CED. SALTILLO | Q28: 20180901 | R28: 20281231 | S28: 20230814 | T28: 20271231 | U28: 237.3 | V28: MXN | W28: TN | X28: 115 | Y28: MXN | Z28: TN | AA28: 67166382 | AB28: CEMSA RAMOS ARIZPE | AC28: 56103638 | AD28: 6622381540 | AE28: 4 | AF28: ENTREGA DIRECTA | AG28: 1 | AH28: TO | AI28: X | AJ28: 4 | AK28: V4 | AL28: 20230920 | AM28: D848-900000138-67166382-10000402-4
A29: 900000138D8486716638210000404 | B29: 4600042903-580 | C29: 4600042903 | D29: 580 | E29: MXPO | F29: MXL | G29: 900000138 | H29: TP- ED GRAMOL | I29: 5005459 | J29: TRITURADOS GRAMOL SA DE CV | K29: Z04 | L29: (AP) 30 Dias | M29: 10000404 | N29: Grava Triturada Caliza 20 mm - 3/4" | O29: D848 | P29: MX-CED. SALTILLO | Q29: 20180901 | R29: 20281231 | S29: 20230814 | T29: 20271231 | U29: 236.21 | V29: MXN | W29: TN | X29: 115 | Y29: MXN | Z29: TN | AA29: 67166382 | AB29: CEMSA RAMOS ARIZPE | AC29: 56103637 | AD29: 6622381540 | AE29: 4 | AF29: ENTREGA DIRECTA | AG29: 1 | AH29: TO | AI29: X | AJ29: 4 | AK29: V4 | AL29: 20230920 | AM29: D848-900000138-67166382-10000404-4
... A103: 900000138D8486719783010000407 | B103: 4600042903-670 | C103: 4600042903 | D103: 670 | E103: MXPO | F103: MXL | G103: 900000138 | H103: TP- ED GRAMOL | I103: 5005459 | J103: TRITURADOS GRAMOL SA DE CV | K103: Z04 | L103: (AP) 30 Dias | M103: 10000407 | N103: Grava Triturada Caliza 10 mm - 3/8" | O103: D848 | P103: MX-CED. SALTILLO | Q103: 20180901 | R103: 20281231 | S103: 20230921 | T103: 20281231 | U103: 251.21 | V103: MXN | W103: TN | X103: 130 | Y103: MXN | Z103: TN | AA103: 67197830 | AB103: GC GENERAL MOTORS | AC103: 56103637 | AD103: 6622381540 | AE103: 4 | AF103: ENTREGA DIRECTA | AG103: 1 | AH103: TO | AI103: X | AJ103: 4 | AK103: V4 | AL103: 20230921 | AM103: D848-900000138-67197830-10000407-4
