Workbook

Sheet Base Cedis DW82
N1: VENTA | Q1: COSTO
A2: CONCAT1 | B2: CONCAT2 | C2: No. SF | D2: Nombre SF | E2: Cedis | F2: Destino | G2: Condicion de Expedicion | H2: Nombre Destino | I2: No. de material | J2: Nombre de material | K2: PV | L2: Inicio de vigencia | M2: Fin de vigencia | N2: Importe MP | O2: Importe Flete | P2: UM Venta | Q2: Importe Costo | R2: UM Costo | S2: Validacion 1 | T2: Validacion 2
A3: =CONCATENATE(C3,E3,F3,I3) | B3: =CONCATENATE(C3,E3,I3) | C3: 900000009 | D3: =IFERROR(VLOOKUP(C3,TRAOPE!$G:$H,2,0),"") | E3: DW82 | F3: D152 | G3: =IFERROR(VLOOKUP(A3,Flete!$A:$E,5,0),"") | H3: =IFERROR(VLOOKUP(F3,TRAOPE!$AA:$AB,2,0),"") | I3: 10000489 | J3: =IFERROR(VLOOKUP(I3,Materiales!$A:$H,8,0),"") | K3: =IFERROR(VLOOKUP(I3,Materiales!$A:$G,7,0),"") | L3: 20210801 | M3: 20250615 | N3: 72.9 | O3: =IFERROR(VLOOKUP(A3,Flete!$A:$J,10,0),"") | P3: TN | Q3: =IFERROR(IFERROR(VLOOKUP(A3,TRAOPE!$A:$U,21,0),VLOOKUP(B3,TRAOPE!$A:$U,21,0)),"") | R3: =IFERROR(IFERROR(VLOOKUP(A3,TRAOPE!$A:$W,23,0),VLOOKUP(B3,TRAOPE!$A:$W,23,0)),"") | S3: =IF(AND(P3="TN",R3="TN"),N3+N(O3),IF(G3&""="1",N(K3)*N3,(N3+N(O3))*N(K3))) | T3: =IF(Q3="","",Q3-S3)
A4: =CONCATENATE(C4,E4,F4,I4) | B4: =CONCATENATE(C4,E4,I4) | C4: 900000130 | D4: =IFERROR(VLOOKUP(C4,TRAOPE!$G:$H,2,0),"") | E4: DW82 | F4: D152 | G4: =IFERROR(VLOOKUP(A4,Flete!$A:$E,5,0),"") | H4: =IFERROR(VLOOKUP(F4,TRAOPE!$AA:$AB,2,0),"") | I4: 10000137 | J4: =IFERROR(VLOOKUP(I4,Materiales!$A:$H,8,0),"") | K4: =IFERROR(VLOOKUP(I4,Materiales!$A:$G,7,0),"") | L4: 20210801 | M4: 20250615 | N4: 152.02 | O4: =IFERROR(VLOOKUP(A4,Flete!$A:$J,10,0),"") | P4: TN | Q4: =IFERROR(IFERROR(VLOOKUP(A4,TRAOPE!$A:$U,21,0),VLOOKUP(B4,TRAOPE!$A:$U,21,0)),"") | R4: =IFERROR(IFERROR(VLOOKUP(A4,TRAOPE!$A:$W,23,0),VLOOKUP(B4,TRAOPE!$A:$W,23,0)),"") | S4: =IF(AND(P4="TN",R4="TN"),N4+N(O4),IF(G4&""="1",N(K4)*N4,(N4+N(O4))*N(K4))) | T4: =IF(Q4="","",Q4-S4)
A5: =CONCATENATE(C5,E5,F5,I5) | B5: =CONCATENATE(C5,E5,I5) | C5: 900000130 | D5: =IFERROR(VLOOKUP(C5,TRAOPE!$G:$H,2,0),"") | E5: DW82 | F5: D152 | G5: =IFERROR(VLOOKUP(A5,Flete!$A:$E,5,0),"") | H5: =IFERROR(VLOOKUP(F5,TRAOPE!$AA:$AB,2,0),"") | I5: 10000151 | J5: =IFERROR(VLOOKUP(I5,Materiales!$A:$H,8,0),"") | K5: =IFERROR(VLOOKUP(I5,Materiales!$A:$G,7,0),"") | L5: 20210801 | M5: 20250615 | N5: 152.85 | O5: =IFERROR(VLOOKUP(A5,Flete!$A:$J,10,0),"") | P5: TN | Q5: =IFERROR(IFERROR(VLOOKUP(A5,TRAOPE!$A:$U,21,0),VLOOKUP(B5,TRAOPE!$A:$U,21,0)),"") | R5: =IFERROR(IFERROR(VLOOKUP(A5,TRAOPE!$A:$W,23,0),VLOOKUP(B5,TRAOPE!$A:$W,23,0)),"") | S5: =IF(AND(P5="TN",R5="TN"),N5+N(O5),IF(G5&""="1",N(K5)*N5,(N5+N(O5))*N(K5))) | T5: =IF(Q5="","",Q5-S5)
A6: =CONCATENATE(C6,E6,F6,I6) | B6: =CONCATENATE(C6,E6,I6) | C6: 900000130 | D6: =IFERROR(VLOOKUP(C6,TRAOPE!$G:$H,2,0),"") | E6: DW82 | F6: D152 | G6: =IFERROR(VLOOKUP(A6,Flete!$A:$E,5,0),"") | H6: =IFERROR(VLOOKUP(F6,TRAOPE!$AA:$AB,2,0),"") | I6: 10000413 | J6: =IFERROR(VLOOKUP(I6,Materiales!$A:$H,8,0),"") | K6: =IFERROR(VLOOKUP(I6,Materiales!$A:$G,7,0),"") | L6: 20210801 | M6: 20250615 | N6: 120.12 | O6: =IFERROR(VLOOKUP(A6,Flete!$A:$J,10,0),"") | P6: TN | Q6: =IFERROR(IFERROR(VLOOKUP(A6,TRAOPE!$A:$U,21,0),VLOOKUP(B6,TRAOPE!$A:$U,21,0)),"") | R6: =IFERROR(IFERROR(VLOOKUP(A6,TRAOPE!$A:$W,23,0),VLOOKUP(B6,TRAOPE!$A:$W,23,0)),"") | S6: =IF(AND(P6="TN",R6="TN"),N6+N(O6),IF(G6&""="1",N(K6)*N6,(N6+N(O6))*N(K6))) | T6: =IF(Q6="","",Q6-S6)
A7: =CONCATENATE(C7,E7,F7,I7) | B7: =CONCATENATE(C7,E7,I7) | C7: 900000130 | D7: =IFERROR(VLOOKUP(C7,TRAOPE!$G:$H,2,0),"") | E7: DW82 | F7: D152 | G7: =IFERROR(VLOOKUP(A7,Flete!$A:$E,5,0),"") | H7: =IFERROR(VLOOKUP(F7,TRAOPE!$AA:$AB,2,0),"") | I7: 10000437 | J7: =IFERROR(VLOOKUP(I7,Materiales!$A:$H,8,0),"") | K7: =IFERROR(VLOOKUP(I7,Materiales!$A:$G,7,0),"") | L7: 20210801 | M7: 20250615 | N7: 125.62 | O7: =IFERROR(VLOOKUP(A7,Flete!$A:$J,10,0),"") | P7: TN | Q7: =IFERROR(IFERROR(VLOOKUP(A7,TRAOPE!$A:$U,21,0),VLOOKUP(B7,TRAOPE!$A:$U,21,0)),"") | R7: =IFERROR(IFERROR(VLOOKUP(A7,TRAOPE!$A:$W,23,0),VLOOKUP(B7,TRAOPE!$A:$W,23,0)),"") | S7: =IF(AND(P7="TN",R7="TN"),N7+N(O7),IF(G7&""="1",N(K7)*N7,(N7+N(O7))*N(K7))) | T7: =IF(Q7="","",Q7-S7)
A8: =CONCATENATE(C8,E8,F8,I8) | B8: =CONCATENATE(C8,E8,I8) | C8: 900005839 | D8: =IFERROR(VLOOKUP(C8,TRAOPE!$G:$H,2,0),"") | E8: DW82 | F8: D152 | G8: =IFERROR(VLOOKUP(A8,Flete!$A:$E,5,0),"") | H8: =IFERROR(VLOOKUP(F8,TRAOPE!$AA:$AB,2,0),"") | I8: 10000137 | J8: =IFERROR(VLOOKUP(I8,Materiales!$A:$H,8,0),"") | K8: =IFERROR(VLOOKUP(I8,Materiales!$A:$G,7,0),"") | L8: 20230629 | M8: 20240517 | N8: 154.92 | O8: =IFERROR(VLOOKUP(A8,Flete!$A:$J,10,0),"") | P8: TN | Q8: =IFERROR(IFERROR(VLOOKUP(A8,TRAOPE!$A:$U,21,0),VLOOKUP(B8,TRAOPE!$A:$U,21,0)),"") | R8: =IFERROR(IFERROR(VLOOKUP(A8,TRAOPE!$A:$W,23,0),VLOOKUP(B8,TRAOPE!$A:$W,23,0)),"") | S8: =IF(AND(P8="TN",R8="TN"),N8+N(O8),IF(G8&""="1",N(K8)*N8,(N8+N(O8))*N(K8))) | T8: =IF(Q8="","",Q8-S8)
A9: =CONCATENATE(C9,E9,F9,I9) | B9: =CONCATENATE(C9,E9,I9) | C9: 900005839 | D9: =IFERROR(VLOOKUP(C9,TRAOPE!$G:$H,2,0),"") | E9: DW82 | F9: D152 | G9: =IFERROR(VLOOKUP(A9,Flete!$A:$E,5,0),"") | H9: =IFERROR(VLOOKUP(F9,TRAOPE!$AA:$AB,2,0),"") | I9: 10000151 | J9: =IFERROR(VLOOKUP(I9,Materiales!$A:$H,8,0),"") | K9: =IFERROR(VLOOKUP(I9,Materiales!$A:$G,7,0),"") | L9: 20230629 | M9: 20240517 | N9: 144.14 | O9: =IFERROR(VLOOKUP(A9,Flete!$A:$J,10,0),"") | P9: TN | Q9: =IFERROR(IFERROR(VLOOKUP(A9,TRAOPE!$A:$U,21,0),VLOOKUP(B9,TRAOPE!$A:$U,21,0)),"") | R9: =IFERROR(IFERROR(VLOOKUP(A9,TRAOPE!$A:$W,23,0),VLOOKUP(B9,TRAOPE!$A:$W,23,0)),"") | S9: =IF(AND(P9="TN",R9="TN"),N9+N(O9),IF(G9&""="1",N(K9)*N9,(N9+N(O9))*N(K9))) | T9: =IF(Q9="","",Q9-S9)
A10: =CONCATENATE(C10,E10,F10,I10) | B10: =CONCATENATE(C10,E10,I10) | C10: 900005839 | D10: =IFERROR(VLOOKUP(C10,TRAOPE!$G:$H,2,0),"") | E10: DW82 | F10: D152 | G10: =IFERROR(VLOOKUP(A10,Flete!$A:$E,5,0),"") | H10: =IFERROR(VLOOKUP(F10,TRAOPE!$AA:$AB,2,0),"") | I10: 10000413 | J10: =IFERROR(VLOOKUP(I10,Materiales!$A:$H,8,0),"") | K10: =IFERROR(VLOOKUP(I10,Materiales!$A:$G,7,0),"") | L10: 20230629 | M10: 20240517 | N10: 161.51 | O10: =IFERROR(VLOOKUP(A10,Flete!$A:$J,10,0),"") | P10: TN | Q10: =IFERROR(IFERROR(VLOOKUP(A10,TRAOPE!$A:$U,21,0),VLOOKUP(B10,TRAOPE!$A:$U,21,0)),"") | R10: =IFERROR(IFERROR(VLOOKUP(A10,TRAOPE!$A:$W,23,0),VLOOKUP(B10,TRAOPE!$A:$W,23,0)),"") | S10: =IF(AND(P10="TN",R10="TN"),N10+N(O10),IF(G10&""="1",N(K10)*N10,(N10+N(O10))*N(K10))) | T10: =IF(Q10="","",Q10-S10)
A11: =CONCATENATE(C11,E11,F11,I11) | B11: =CONCATENATE(C11,E11,I11) | C11: 900005839 | D11: =IFERROR(VLOOKUP(C11,TRAOPE!$G:$H,2,0),"") | E11: DW82 | F11: D152 | G11: =IFERROR(VLOOKUP(A11,Flete!$A:$E,5,0),"") | H11: =IFERROR(VLOOKUP(F11,TRAOPE!$AA:$AB,2,0),"") | I11: 10000437 | J11: =IFERROR(VLOOKUP(I11,Materiales!$A:$H,8,0),"") | K11: =IFERROR(VLOOKUP(I11,Materiales!$A:$G,7,0),"") | L11: 20230629 | M11: 20240517 | N11: 159.05 | O11: =IFERROR(VLOOKUP(A11,Flete!$A:$J,10,0),"") | P11: TN | Q11: =IFERROR(IFERROR(VLOOKUP(A11,TRAOPE!$A:$U,21,0),VLOOKUP(B11,TRAOPE!$A:$U,21,0)),"") | R11: =IFERROR(IFERROR(VLOOKUP(A11,TRAOPE!$A:$W,23,0),VLOOKUP(B11,TRAOPE!$A:$W,23,0)),"") | S11: =IF(AND(P11="TN",R11="TN"),N11+N(O11),IF(G11&""="1",N(K11)*N11,(N11+N(O11))*N(K11))) | T11: =IF(Q11="","",Q11-S11)
A12: =CONCATENATE(C12,E12,F12,I12) | B12: =CONCATENATE(C12,E12,I12) | C12: 900005956 | D12: =IFERROR(VLOOKUP(C12,TRAOPE!$G:$H,2,0),"") | E12: DW82 | F12: D152 | G12: =IFERROR(VLOOKUP(A12,Flete!$A:$E,5,0),"") | H12: =IFERROR(VLOOKUP(F12,TRAOPE!$AA:$AB,2,0),"") | I12: 10164161 | J12: =IFERROR(VLOOKUP(I12,Materiales!$A:$H,8,0),"") | K12: =IFERROR(VLOOKUP(I12,Materiales!$A:$G,7,0),"") | L12: 20240429 | M12: 99991231 | N12: 184 | O12: =IFERROR(VLOOKUP(A12,Flete!$A:$J,10,0),"") | P12: TN | Q12: =IFERROR(IFERROR(VLOOKUP(A12,TRAOPE!$A:$U,21,0),VLOOKUP(B12,TRAOPE!$A:$U,21,0)),"") | R12: =IFERROR(IFERROR(VLOOKUP(A12,TRAOPE!$A:$W,23,0),VLOOKUP(B12,TRAOPE!$A:$W,23,0)),"") | S12: =IF(AND(P12="TN",R12="TN"),N12+N(O12),IF(G12&""="1",N(K12)*N12,(N12+N(O12))*N(K12))) | T12: =IF(Q12="","",Q12-S12)
A13: =CONCATENATE(C13,E13,F13,I13) | B13: =CONCATENATE(C13,E13,I13) | C13: 900006080 | D13: =IFERROR(VLOOKUP(C13,TRAOPE!$G:$H,2,0),"") | E13: DW82 | F13: D152 | G13: =IFERROR(VLOOKUP(A13,Flete!$A:$E,5,0),"") | H13: =IFERROR(VLOOKUP(F13,TRAOPE!$AA:$AB,2,0),"") | I13: 10164161 | J13: =IFERROR(VLOOKUP(I13,Materiales!$A:$H,8,0),"") | K13: =IFERROR(VLOOKUP(I13,Materiales!$A:$G,7,0),"") | L13: 20210801 | M13: 20250615 | N13: 105.7 | O13: =IFERROR(VLOOKUP(A13,Flete!$A:$J,10,0),"") | P13: TN | Q13: =IFERROR(IFERROR(VLOOKUP(A13,TRAOPE!$A:$U,21,0),VLOOKUP(B13,TRAOPE!$A:$U,21,0)),"") | R13: =IFERROR(IFERROR(VLOOKUP(A13,TRAOPE!$A:$W,23,0),VLOOKUP(B13,TRAOPE!$A:$W,23,0)),"") | S13: =IF(AND(P13="TN",R13="TN"),N13+N(O13),IF(G13&""="1",N(K13)*N13,(N13+N(O13))*N(K13))) | T13: =IF(Q13="","",Q13-S13)
A14: =CONCATENATE(C14,E14,F14,I14) | B14: =CONCATENATE(C14,E14,I14) | C14: 900006104 | D14: =IFERROR(VLOOKUP(C14,TRAOPE!$G:$H,2,0),"") | E14: DW82 | F14: D152 | G14: =IFERROR(VLOOKUP(A14,Flete!$A:$E,5,0),"") | H14: =IFERROR(VLOOKUP(F14,TRAOPE!$AA:$AB,2,0),"") | I14: 10000137 | J14: =IFERROR(VLOOKUP(I14,Materiales!$A:$H,8,0),"") | K14: =IFERROR(VLOOKUP(I14,Materiales!$A:$G,7,0),"") | L14: 20210801 | M14: 20250615 | N14: 108.68 | O14: =IFERROR(VLOOKUP(A14,Flete!$A:$J,10,0),"") | P14: TN | Q14: =IFERROR(IFERROR(VLOOKUP(A14,TRAOPE!$A:$U,21,0),VLOOKUP(B14,TRAOPE!$A:$U,21,0)),"") | R14: =IFERROR(IFERROR(VLOOKUP(A14,TRAOPE!$A:$W,23,0),VLOOKUP(B14,TRAOPE!$A:$W,23,0)),"") | S14: =IF(AND(P14="TN",R14="TN"),N14+N(O14),IF(G14&""="1",N(K14)*N14,(N14+N(O14))*N(K14))) | T14: =IF(Q14="","",Q14-S14)
... A50: =CONCATENATE(C50,E50,F50,I50) | B50: =CONCATENATE(C50,E50,I50) | C50: 900008991 | D50: =IFERROR(VLOOKUP(C50,TRAOPE!$G:$H,2,0),"") | E50: DW82 | F50: D152 | G50: =IFERROR(VLOOKUP(A50,Flete!$A:$E,5,0),"") | H50: =IFERROR(VLOOKUP(F50,TRAOPE!$AA:$AB,2,0),"") | I50: 10000437 | J50: =IFERROR(VLOOKUP(I50,Materiales!$A:$H,8,0),"") | K50: =IFERROR(VLOOKUP(I50,Materiales!$A:$G,7,0),"") | L50: 20210801 | M50: 20250615 | N50: 206.25 | O50: =IFERROR(VLOOKUP(A50,Flete!$A:$J,10,0),"") | P50: TN | Q50: =IFERROR(IFERROR(VLOOKUP(A50,TRAOPE!$A:$U,21,0),VLOOKUP(B50,TRAOPE!$A:$U,21,0)),"") | R50: =IFERROR(IFERROR(VLOOKUP(A50,TRAOPE!$A:$W,23,0),VLOOKUP(B50,TRAOPE!$A:$W,23,0)),"") | S50: =IF(AND(P50="TN",R50="TN"),N50+N(O50),IF(G50&""="1",N(K50)*N50,(N50+N(O50))*N(K50))) | T50: =IF(Q50="","",Q50-S50)

Sheet MP
A1: No. SF | B1: Cedis | C1: Destino | D1: No. Material | E1: Nombre Material | F1: Importe MP | G1: Moneda | H1: Cantidad | I1: UM | J1: C | K1: Inicio Vigencia | L1: Fin Vigencia
A2: 900000009 | B2: DW82 | C2: D152 | D2: 10000489 | F2: 72.9 | I2: TN | K2: 20210801 | L2: 20250615
A3: 900000130 | B3: DW82 | C3: D152 | D3: 10000137 | F3: 152.02 | I3: TN | K3: 20210801 | L3: 20250615
A4: 900000130 | B4: DW82 | C4: D152 | D4: 10000151 | F4: 152.85 | I4: TN | K4: 20210801 | L4: 20250615
A5: 900000130 | B5: DW82 | C5: D152 | D5: 10000413 | F5: 120.12 | I5: TN | K5: 20210801 | L5: 20250615
A6: 900000130 | B6: DW82 | C6: D152 | D6: 10000437 | F6: 125.62 | I6: TN | K6: 20210801 | L6: 20250615
A7: 900005839 | B7: DW82 | C7: D152 | D7: 10000137 | F7: 154.92 | I7: TN | K7: 20230629 | L7: 20240517
A8: 900005839 | B8: DW82 | C8: D152 | D8: 10000151 | F8: 144.14 | I8: TN | K8: 20230629 | L8: 20240517
A9: 900005839 | B9: DW82 | C9: D152 | D9: 10000413 | F9: 161.51 | I9: TN | K9: 20230629 | L9: 20240517
A10: 900005839 | B10: DW82 | C10: D152 | D10: 10000437 | F10: 159.05 | I10: TN | K10: 20230629 | L10: 20240517
A11: 900005956 | B11: DW82 | C11: D152 | D11: 10164161 | F11: 184 | I11: TN | K11: 20240429 | L11: 99991231
A12: 900006080 | B12: DW82 | C12: D152 | D12: 10164161 | F12: 105.7 | I12: TN | K12: 20210801 | L12: 20250615
A13: 900006104 | B13: DW82 | C13: D152 | D13: 10000137 | F13: 108.68 | I13: TN | K13: 20210801 | L13: 20250615
... A49: 900008991 | B49: DW82 | C49: D152 | D49: 10000437 | F49: 206.25 | I49: TN | K49: 20210801 | L49: 20250615

Sheet Flete
A1: Concat1 | B1: No. SF | C1: Cedis | D1: Destino | E1: Cond. Exp. | F1: Material | H1: Nombre Material | J1: Importe Flete | K1: Moneda | L1: Cantidad | M1: UM | N1: C | P1: Inicio Vigencia | Q1: Fin Vigencia
A2: 900000009DW82D15210000489 | B2: 900000009 | C2: DW82 | D2: D152 | E2: 1 | F2: 10000489 | J2: 582.48 | M2: TN | P2: 20210801 | Q2: 20250615
A3: 900000130DW82D15210000137 | B3: 900000130 | C3: DW82 | D3: D152 | E3: 1 | F3: 10000137 | J3: 47.06 | M3: TN | P3: 20210801 | Q3: 20250615
A4: 900000130DW82D15210000151 | B4: 900000130 | C4: DW82 | D4: D152 | E4: 1 | F4: 10000151 | J4: 47.06 | M4: TN | P4: 20210801 | Q4: 20250615
A5: 900000130DW82D15210000413 | B5: 900000130 | C5: DW82 | D5: D152 | E5: 1 | F5: 10000413 | J5: 47.06 | M5: TN | P5: 20210801 | Q5: 20250615
A6: 900000130DW82D15210000437 | B6: 900000130 | C6: DW82 | D6: D152 | E6: 1 | F6: 10000437 | J6: 47.06 | M6: TN | P6: 20210801 | Q6: 20250615
A7: 900005839DW82D15210000137 | B7: 900005839 | C7: DW82 | D7: D152 | E7: 4 | F7: 10000137 | J7: 60 | M7: TN | P7: 20230629 | Q7: 20240517
A8: 900005839DW82D15210000151 | B8: 900005839 | C8: DW82 | D8: D152 | E8: 4 | F8: 10000151 | J8: 60 | M8: TN | P8: 20230629 | Q8: 20240517
A9: 900005839DW82D15210000413 | B9: 900005839 | C9: DW82 | D9: D152 | E9: 4 | F9: 10000413 | J9: 60 | M9: TN | P9: 20230629 | Q9: 20240517
A10: 900005839DW82D15210000437 | B10: 900005839 | C10: DW82 | D10: D152 | E10: 4 | F10: 10000437 | J10: 60 | M10: TN | P10: 20230629 | Q10: 20240517
A11: 900005956DW82D15210164161 | B11: 900005956 | C11: DW82 | D11: D152 | E11: 4 | F11: 10164161 | J11: 46 | M11: TN | P11: 20240429 | Q11: 99991231
A12: 900006080DW82D15210164161 | B12: 900006080 | C12: DW82 | D12: D152 | E12: 4 | F12: 10164161 | J12: 14 | M12: TN | P12: 20210801 | Q12: 20250615
A13: 900006104DW82D15210000137 | B13: 900006104 | C13: DW82 | D13: D152 | E13: 1 | F13: 10000137 | J13: 30.25 | M13: TN | P13: 20210801 | Q13: 20250615
... A43: 900008991DW82D15210000437 | B43: 900008991 | C43: DW82 | D43: D152 | E43: 4 | F43: 10000437 | J43: 218.75 | M43: TN | P43: 20210801 | Q43: 20250615

Sheet Materiales
A1: Material | B1: TpMt | C1: Denom | D1: UMA | E1: Contador | F1: UMB | G1: PV | H1: Nombre Material
A2: 10000001 | B2: ZFER | C2: 1000 | D2: M3 | E2: 1000 | F2: TN | G2: 1262 | H2: GRAVA ANDESITA 10 MM (3/8")
A3: 10000003 | B3: ZFER | C3: 1000 | D3: M3 | E3: 1000 | F3: TN | G3: 1443 | H3: GRAVA CALIZA 10 MM (3/8")
A4: 10000006 | B4: ZFER | C4: 1000 | D4: M3 | E4: 1000 | F4: TN | G4: 1490 | H4: GRAVA RIO 10 MM (3/8")
A5: 10000007 | B5: ZFER | C5: 1000 | D5: M3 | E5: 1000 | F5: TN | G5: 1488 | H5: GRAVA BASALTO 13 MM (1/2")
A6: 10000008 | B6: ZFER | C6: 1000 | D6: M3 | E6: 1000 | F6: TN | G6: 1358 | H6: GRAVA CALIZA 13 MM (1/2")
A7: 10000011 | B7: ZFER | C7: 1000 | D7: M3 | E7: 1000 | F7: TN | G7: 1323 | H7: GRAVA ANDESITA 20 MM (3/4")
A8: 10000013 | B8: ZFER | C8: 1000 | D8: M3 | E8: 1000 | F8: TN | G8: 1514 | H8: GRAVA BASALTO 20 MM (3/4")
A9: 10000014 | B9: ZFER | C9: 1000 | D9: M3 | E9: 1000 | F9: TN | G9: 1400 | H9: GRAVA CALIZA 20 MM (3/4")
A10: 10000015 | B10: ZFER | C10: 1000 | D10: M3 | E10: 1000 | F10: TN | G10: 1410 | H10: GRAVA GRANITO 20 MM (3/4")
A11: 10000017 | B11: ZFER | C11: 1000 | D11: M3 | E11: 1000 | F11: TN | G11: 1475 | H11: GRAVA RIOLITA 20 MM (3/4")
A12: 10000019 | B12: ZFER | C12: 1000 | D12: M3 | E12: 1000 | F12: TN | G12: 1515 | H12: GRAVA RIO 20 MM (3/4")
A13: 10000020 | B13: ZFER | C13: 1000 | D13: M3 | E13: 1 | F13: TN | G13: 1 | H13: GRAVA MAQUILA 40MM (1 1/2")
... A2291: 10268770 | B2291: ZFE3 | C2291: 1000 | D2291: M3 | E2291: 1000 | F2291: TN | G2291: 1240 | H2291: MP GRAVA TRIT CALIZA 40MM 1 1/2" - ESP
A2292: 10268901 | B2292: ZFE3 | C2292: 1000 | D2292: M3 | E2292: 1000 | G2292: 1560 | H2292: MP GRAVA ANDESITA GRIS 3/4" - CAPADA
A2293: 10267983 | C2293: 1000 | G2293: 1800 | H2293: ESCORIA ALTO HORNO 3/4
A2294: 10268996 | C2294: 1000 | G2294: 1329 | H2294: GRAVA TRITURADA CALIZA 40 MM - 11/2"
A2295: 10269072 | C2295: 1000 | G2295: 1700 | H2295: BASE HIDRÁULICA SCREEN
A2296: 10269225 | B2296: ZFE3 | C2296: 1000 | D2296: M3 | E2296: 1000 | G2296: 1289 | H2296: MP ARENA CALIZA LAVADA MALLA 4 - DELTA I
A2297: 10269245 | B2297: ZFE3 | C2297: 1000 | D2297: M3 | E2297: 1000 | G2297: 1410 | H2297: MP GRAVA TRITURADA CALIZA 3/8 - 10MM
A2298: 10269246 | B2298: ZFE3 | C2298: 1000 | D2298: M3 | E2298: 1000 | G2298: 1400 | H2298: MP GRAVA TRITURADA CALIZA 1 1/2 - 40MM
A2299: 10269247 | B2299: ZFE3 | C2299: 1000 | D2299: M3 | E2299: 1000 | G2299: 1560 | H2299: MP ARENA TRIT CALIZA M-4
A2300: 10270431 | B2300: ZFE3 | C2300: 1000 | D2300: M3 | E2300: 1000 | G2300: 1423 | H2300: MP GRAVA RIOLITA 13 MM - 1/2"
A2301: 10270898 | B2301: ZFE3 | C2301: 1000 | D2301: M3 | E2301: 1000 | G2301: 1551 | H2301: MP BASE H. TRIT. BASALTO 1 1/2" A FINOS
A2302: 10270911 | B2302: ZFE3 | C2302: 1000 | D2302: M3 | E2302: 1000 | G2302: 1360 | H2302: MP GRAVA TRIT. BASALTO 40 MM - 1 1/2"
A2303: 10270912 | B2303: ZFE3 | C2303: 1000 | D2303: M3 | E2303: 1000 | G2303: 1589 | H2303: MP ARENA TRIT. BASALTO MALLA 4
A2304: 10270913 | B2304: ZFE3 | C2304: 1000 | D2304: M3 | E2304: 1000 | G2304: 1395 | H2304: MP GRAVA TRIT. BASALTO 20 MM - 3/4
A2305: 10270914 | B2305: ZFE3 | C2305: 1000 | D2305: M3 | E2305: 1000 | G2305: 1623 | H2305: MP ARENA ANDESITA BC
A2306: 10270824 | B2306: M3 | C2306: 1000 | D2306: M3 | E2306: 10007640 | G2306: 1325 | H2306: MP ARENA TRITURADA CALIZA MALLA 5
A2307: 10270825 | B2307: M3 | C2307: 1000 | D2307: M3 | E2307: 10000003 | G2307: 1242 | H2307: MP GRAVA TRITURADA CALIZA 10MM (3/8”)
... A2319: 10272527 | B2319: ZFE3 | C2319: 1000 | D2319: M3 | E2319: 1000 | G2319: 1620 | H2319: CNC - NO CLASIFICADO
A2320: 10000332 | C2320: 1000 | D2320: M3 | E2320: 1000 | G2320: 800 | H2320: Grava Triturada Pomez - Jal 20 mm - 3/4"
A2321: 10273001 | B2321: ZFE3 | C2321: 1000 | D2321: M3 | E2321: 1000 | G2321: 1688 | H2321: MP ARENA TRIT. BASALTO MALLA 4
A2322: 10273002 | B2322: ZFE3 | C2322: 1000 | D2322: M3 | E2322: 1000 | G2322: 1466 | H2322: MP GRAVA TRIT. BASALTO 20 MM - 3/4"
A2323: 10273351 | B2323: ZFE3 | C2323: 1000 | D2323: M3 | E2323: 1000 | G2323: 1612 | H2323: MP ARENA TRIT. CALIZA MALLA 4
A2324: 10273352 | B2324: ZFE3 | C2324: 1000 | D2324: M3 | E2324: 1000 | G2324: 1492 | H2324: MP GRAVA TRIT. CALIZA 20 MM - 3/4"
A2325: 10271724 | B2325: ZFE3 | C2325: 1000 | D2325: M3 | E2325: 1000 | G2325: 1900 | H2325: MP RESIDUO DE CONCRETO
A2326: 10000677 | C2326: 1000 | D2326: M3 | G2326: 1164 | H2326: Grava Triturada Caliza 20 mm - 3/4"
A2327: 10274190 | B2327: ZFE3 | C2327: 1000 | D2327: M3 | E2327: 1000 | G2327: 1800 | H2327: MP BASE HIDRAULICA ANDESITA 70-30
A2328: 10274601 | B2328: ZFE3 | C2328: 1000 | D2328: M3 | E2328: 1000 | G2328: 1447 | H2328: MP ARENA BASALTO N° 4
...

Sheet TRAOPE
A1: Concat1 | B1: Contrato_Pos | C1: Doc. Compras | D1: Pos | E1: Org.compras | F1: Grp-Compr. | G1: Ship From | H1: Nombre SF | I1: Proveedor | J1: Nombre Prov | K1: Cond. Pago | L1: Descr. Cond Pago | M1: Material | N1: Descripción | O1: Centro | P1: Descripción Centro | Q1: In.perído validez | R1: Fin perído validez | S1: Válido de | T1: Validez a | U1: Precio neto pedido | V1: Moneda | W1: UM Precio Pedido | X1: Importe Condición | Y1: Moneda KONP | Z1: UM Ctd Base | AA1: Destino | AB1: Nombre Destino | AC1: Cuenta de mayor | AD1: Centro de costo | AE1: Cond. Exp. | AF1: Descr. Cond. Exp. | AG1: Peso Vol. | AH1: UMB | AI1: Ind. Oblig. Conf. Ped. | AJ1: Ctrl-Conf. | AK1: IVA | AL1: Modif_Date | AM1: Ruta
A2: 900008815DW8210164161 | B2: 4600069665-40 | C2: 4600069665 | D2: 40 | E2: MXPO | F2: MXL | G2: 900008815 | H2: SF TC-PETROLOGIA E INGENIERIA | I2: 5093347 | J2: PETROLOGIA E INGENIERIA AVANZADA SA | K2: Z09 | L2: (AP) 90 Dias | M2: 10164161 | N2: ARENA CLASIFICADA RÍO MALLA 4 | O2: DW82 | P2: MX-CED. DURANGO | Q2: 20240606 | R2: 20291231 | S2: 20240606 | T2: 20291231 | U2: 315 | V2: MXN | W2: M3 | X2: 0 | Y2: MXN | Z2: M3 | AC2: 56103638 | AD2: 6644391540 | AE2: 1 | AF2: ENTREGADO | AG2: 1.35 | AH2: M3 | AI2: X | AJ2: 4 | AK2: V4 | AL2: 20240612 | AM2: DW82-900008815-10164161
A3: 900008815DW8210179731 | B3: 4600069665-30 | C3: 4600069665 | D3: 30 | E3: MXPO | F3: MXL | G3: 900008815 | H3: SF TC-PETROLOGIA E INGENIERIA | I3: 5093347 | J3: PETROLOGIA E INGENIERIA AVANZADA SA | K3: Z09 | L3: (AP) 90 Dias | M3: 10179731 | N3: BASE H TRITURADA BASALTO 1 1/2" A FINOS | O3: DW82 | P3: MX-CED. DURANGO | Q3: 20240606 | R3: 20291231 | S3: 20240606 | T3: 20291231 | U3: 205 | V3: MXN | W3: M3 | X3: 0 | Y3: MXN | Z3: M3 | AC3: 56103590 | AD3: 6644391540 | AE3: 1 | AF3: ENTREGADO | AG3: 1.619 | AH3: M3 | AI3: X | AJ3: 4 | AK3: V4 | AL3: 20240806 | AM3: DW82-900008815-10179731
A4: 900008685DW8210000437 | B4: 4600069266-10 | C4: 4600069266 | D4: 10 | E4: MXPO | F4: MXL | G4: 900008685 | H4: SF TC-GL ASFALTOS | I4: 5092668 | J4: GL ASFALTOS Y TRITURADOS SA DE CV | K4: Z04 | L4: (AP) 30 Dias | M4: 10000437 | N4: Grava Triturada Basalto 20 mm - 3/4" | O4: DW82 | P4: MX-CED. DURANGO | Q4: 20240315 | R4: 20291231 | S4: 20250717 | T4: 20301231 | U4: 165 | V4: MXN | W4: TN | X4: 0 | Y4: MXN | Z4: TN | AC4: 56103637 | AD4: 6644391540 | AE4: 1 | AF4: ENTREGADO | AG4: 1 | AH4: TO | AI4: X | AJ4: 4 | AK4: V4 | AL4: 20250729 | AM4: DW82-900008685-10000437
A5: 900008685DW8210000413 | B5: 4600069266-20 | C5: 4600069266 | D5: 20 | E5: MXPO | F5: MXL | G5: 900008685 | H5: SF TC-GL ASFALTOS | I5: 5092668 | J5: GL ASFALTOS Y TRITURADOS SA DE CV | K5: Z04 | L5: (AP) 30 Dias | M5: 10000413 | N5: Grava Triturada Basalto 40 mm - 1 1/2" | O5: DW82 | P5: MX-CED. DURANGO | Q5: 20240315 | R5: 20291231 | S5: 20250717 | T5: 20301231 | U5: 163 | V5: MXN | W5: TN | X5: 0 | Y5: MXN | Z5: TN | AC5: 56103637 | AD5: 6644391540 | AE5: 1 | AF5: ENTREGADO | AG5: 1 | AH5: TO | AI5: X | AJ5: 4 | AK5: V4 | AL5: 20250729 | AM5: DW82-900008685-10000413
A6: 900008685DW8210000137 | B6: 4600069266-40 | C6: 4600069266 | D6: 40 | E6: MXPO | F6: MXL | G6: 900008685 | H6: SF TC-GL ASFALTOS | I6: 5092668 | J6: GL ASFALTOS Y TRITURADOS SA DE CV | K6: Z04 | L6: (AP) 30 Dias | M6: 10000137 | N6: Arena Triturada Basalto Malla 5 | O6: DW82 | P6: MX-CED. DURANGO | Q6: 20240315 | R6: 20291231 | S6: 20250717 | T6: 20301231 | U6: 210 | V6: MXN | W6: TN | X6: 0 | Y6: MXN | Z6: TN | AC6: 56103638 | AD6: 6644391540 | AE6: 1 | AF6: ENTREGADO | AG6: 1 | AH6: TO | AI6: X | AJ6: 4 | AK6: V4 | AL6: 20250729 | AM6: DW82-900008685-10000137
A7: 900008817DW8210000413 | B7: 4600069514-50 | C7: 4600069514 | D7: 50 | E7: MXPO | F7: MXL | G7: 900008817 | H7: SF TC-REC PETROLOGIA E INGENIERIA | I7: 5093347 | J7: PETROLOGIA E INGENIERIA AVANZADA SA | K7: Z09 | L7: (AP) 90 Dias | M7: 10000413 | N7: Grava Triturada Basalto 40 mm - 1 1/2" | O7: DW82 | P7: MX-CED. DURANGO | Q7: 20240513 | R7: 20291231 | S7: 20240716 | T7: 20291231 | U7: 215 | V7: MXN | W7: M3 | X7: 0 | Y7: MXN | Z7: M3 | AC7: 56103637 | AD7: 6644391540 | AE7: 2 | AF7: RECOGIDO | AG7: 1.5 | AH7: M3 | AI7: X | AJ7: 4 | AK7: V4 | AL7: 20240717 | AM7: DW82-900008817-10000413
A8: 900008629DW82D15210000151 | B8: 4600068989-30 | C8: 4600068989 | D8: 30 | E8: MXPO | F8: MXL | G8: 900008629 | H8: SF TC-ED GL ASFALTOS | I8: 5092668 | J8: GL ASFALTOS Y TRITURADOS SA DE CV | K8: Z04 | L8: (AP) 30 Dias | M8: 10000151 | N8: Grava Triturada Basalto 10 mm - 3/8" | O8: DW82 | P8: MX-CED. DURANGO | Q8: 20240111 | R8: 20291231 | S8: 20250106 | T8: 20301231 | U8: 290.16 | V8: MXN | W8: TN | X8: 46.2 | Y8: MXN | Z8: TN | AA8: D152 | AB8: SICLO-PD034 DURANGO | AC8: 56103637 | AD8: 6644391540 | AE8: 4 | AF8: ENTREGA DIRECTA | AG8: 1 | AH8: TO | AI8: X | AJ8: 4 | AK8: V4 | AL8: 20250309 | AM8: DW82-900008629-D152-10000151-4
A9: 900008685DW8210000151 | B9: 4600069266-30 | C9: 4600069266 | D9: 30 | E9: MXPO | F9: MXL | G9: 900008685 | H9: SF TC-GL ASFALTOS | I9: 5092668 | J9: GL ASFALTOS Y TRITURADOS SA DE CV | K9: Z04 | L9: (AP) 30 Dias | M9: 10000151 | N9: Grava Triturada Basalto 10 mm - 3/8" | O9: DW82 | P9: MX-CED. DURANGO | Q9: 20240315 | R9: 20291231 | S9: 20250106 | T9: 20301231 | U9: 243.96 | V9: MXN | W9: TN | X9: 0 | Y9: MXN | Z9: TN | AC9: 56103637 | AD9: 6644391540 | AE9: 1 | AF9: ENTREGADO | AG9: 1 | AH9: TO | AI9: X | AJ9: 4 | AK9: V4 | AL9: 20250309 | AM9: DW82-900008685-10000151
A10: 900008815DW8210000413 | B10: 4600069665-90 | C10: 4600069665 | D10: 90 | E10: MXPO | F10: MXL | G10: 900008815 | H10: SF TC-PETROLOGIA E INGENIERIA | I10: 5093347 | J10: PETROLOGIA E INGENIERIA AVANZADA SA | K10: Z09 | L10: (AP) 90 Dias | M10: 10000413 | N10: Grava Triturada Basalto 40 mm - 1 1/2" | O10: DW82 | P10: MX-CED. DURANGO | Q10: 20240606 | R10: 20291231 | S10: 20250210 | T10: 20301231 | U10: 163.08 | V10: MXN | W10: TN | X10: 0 | Y10: MXN | Z10: TN | AC10: 56103637 | AD10: 6644391540 | AE10: 1 | AF10: ENTREGADO | AG10: 1 | AH10: TO | AI10: X | AJ10: 4 | AK10: V4 | AL10: 20250303 | AM10: DW82-900008815-10000413
A11: 900008815DW8210000137 | B11: 4600069665-100 | C11: 4600069665 | D11: 100 | E11: MXPO | F11: MXL | G11: 900008815 | H11: SF TC-PETROLOGIA E INGENIERIA | I11: 5093347 | J11: PETROLOGIA E INGENIERIA AVANZADA SA | K11: Z09 | L11: (AP) 90 Dias | M11: 10000137 | N11: Arena Triturada Basalto Malla 5 | O11: DW82 | P11: MX-CED. DURANGO | Q11: 20240606 | R11: 20291231 | S11: 20250210 | T11: 20301231 | U11: 210.6 | V11: MXN | W11: TN | X11: 0 | Y11: MXN | Z11: TN | AC11: 56103638 | AD11: 6644391540 | AE11: 1 | AF11: ENTREGADO | AG11: 1 | AH11: TO | AI11: X | AJ11: 4 | AK11: V4 | AL11: 20250303 | AM11: DW82-900008815-10000137
A12: 900008815DW8210000437 | B12: 4600069665-70 | C12: 4600069665 | D12: 70 | E12: MXPO | F12: MXL | G12: 900008815 | H12: SF TC-PETROLOGIA E INGENIERIA | I12: 5093347 | J12: PETROLOGIA E INGENIERIA AVANZADA SA | K12: Z09 | L12: (AP) 90 Dias | M12: 10000437 | N12: Grava Triturada Basalto 20 mm - 3/4" | O12: DW82 | P12: MX-CED. DURANGO | Q12: 20240606 | R12: 20291231 | S12: 20250210 | T12: 20301231 | U12: 165.24 | V12: MXN | W12: TN | X12: 0 | Y12: MXN | Z12: TN | AC12: 56103637 | AD12: 6644391540 | AE12: 1 | AF12: ENTREGADO | AG12: 1 | AH12: TO | AI12: X | AJ12: 4 | AK12: V4 | AL12: 20250303 | AM12: DW82-900008815-10000437
A13: 900008815DW8210000151 | B13: 4600069665-80 | C13: 4600069665 | D13: 80 | E13: MXPO | F13: MXL | G13: 900008815 | H13: SF TC-PETROLOGIA E INGENIERIA | I13: 5093347 | J13: PETROLOGIA E INGENIERIA AVANZADA SA | K13: Z09 | L13: (AP) 90 Dias | M13: 10000151 | N13: Grava Triturada Basalto 10 mm - 3/8" | O13: DW82 | P13: MX-CED. DURANGO | Q13: 20240606 | R13: 20291231 | S13: 20250210 | T13: 20301231 | U13: 237.6 | V13: MXN | W13: TN | X13: 0 | Y13: MXN | Z13: TN | AC13: 56103637 | AD13: 6644391540 | AE13: 1 | AF13: ENTREGADO | AG13: 1 | AH13: TO | AI13: X | AJ13: 4 | AK13: V4 | AL13: 20250303 | AM13: DW82-900008815-10000151
A14: 900008816DW82D15210164161 | B14: 4600069513-40 | C14: 4600069513 | D14: 40 | E14: MXPO | F14: MXL | G14: 900008816 | H14: SF TC-ED PETROLOGIA E INGENIERIA | I14: 5093347 | J14: PETROLOGIA E INGENIERIA AVANZADA SA | K14: Z09 | L14: (AP) 90 Dias | M14: 10164161 | N14: ARENA CLASIFICADA RÍO MALLA 4 | O14: DW82 | P14: MX-CED. DURANGO | Q14: 20240513 | R14: 20291231 | S14: 20240513 | T14: 20291231 | U14: 363.5 | V14: MXN | W14: M3 | X14: 48.5 | Y14: MXN | Z14: M3 | AA14: D152 | AB14: SICLO-PD034 DURANGO | AC14: 56103638 | AD14: 6644391540 | AE14: 4 | AF14: ENTREGA DIRECTA | AG14: 1.35 | AH14: M3 | AI14: X | AJ14: 4 | AK14: V4 | AL14: 20240515 | AM14: DW82-900008816-D152-10164161-4
A15: 900008816DW82D15210179731 | B15: 4600069513-30 | C15: 4600069513 | D15: 30 | E15: MXPO | F15: MXL | G15: 900008816 | H15: SF TC-ED PETROLOGIA E INGENIERIA | I15: 5093347 | J15: PETROLOGIA E INGENIERIA AVANZADA SA | K15: Z09 | L15: (AP) 90 Dias | M15: 10179731 | N15: BASE H TRITURADA BASALTO 1 1/2" A FINOS | O15: DW82 | P15: MX-CED. DURANGO | Q15: 20240513 | R15: 20291231 | S15: 20240513 | T15: 20291231 | U15: 253.5 | V15: MXN | W15: M3 | X15: 48.5 | Y15: MXN | Z15: M3 | AA15: D152 | AB15: SICLO-PD034 DURANGO | AC15: 56103590 | AD15: 6644391540 | AE15: 4 | AF15: ENTREGA DIRECTA | AG15: 1.619 | AH15: M3 | AI15: X | AJ15: 4 | AK15: V4 | AL15: 20241204 | AM15: DW82-900008816-D152-10179731-4
A16: 900008991DW82D15210000137 | B16: 4600070407-10 | C16: 4600070407 | D16: 10 | E16: MXPO | F16: MXL | G16: 900008991 | H16: SF TC-ED RIOGRAVA | I16: 5094376 | J16: HEIDE DYCK JOHAN | K16: Z09 | L16: (AP) 90 Dias | M16: 10000137 | N16: Arena Triturada Basalto Malla 5 | O16: DW82 | P16: MX-CED. DURANGO | Q16: 20241021 | R16: 20291231 | S16: 20241021 | T16: 20291231 | U16: 400.88 | V16: MXN | W16: TN | X16: 205.88 | Y16: MXN | Z16: TN | AA16: D152 | AB16: SICLO-PD034 DURANGO | AC16: 56103638 | AD16: 6644391540 | AE16: 4 | AF16: ENTREGA DIRECTA | AG16: 1 | AH16: TO | AI16: X | AJ16: 4 | AK16: V4 | AL16: 20241023 | AM16: DW82-900008991-D152-10000137-4
A17: 900008991DW82D15210000437 | B17: 4600070407-20 | C17: 4600070407 | D17: 20 | E17: MXPO | F17: MXL | G17: 900008991 | H17: SF TC-ED RIOGRAVA | I17: 5094376 | J17: HEIDE DYCK JOHAN | K17: Z09 | L17: (AP) 90 Dias | M17: 10000437 | N17: Grava Triturada Basalto 20 mm - 3/4" | O17: DW82 | P17: MX-CED. DURANGO | Q17: 20241021 | R17: 20291231 | S17: 20241021 | T17: 20291231 | U17: 425 | V17: MXN | W17: TN | X17: 218.75 | Y17: MXN | Z17: TN | AA17: D152 | AB17: SICLO-PD034 DURANGO | AC17: 56103637 | AD17: 6644391540 | AE17: 4 | AF17: ENTREGA DIRECTA | AG17: 1 | AH17: TO | AI17: X | AJ17: 4 | AK17: V4 | AL17: 20241023 | AM17: DW82-900008991-D152-10000437-4
A18: 900008629DW82D15210000437 | B18: 4600068989-10 | C18: 4600068989 | D18: 10 | E18: MXPO | F18: MXL | G18: 900008629 | H18: SF TC-ED GL ASFALTOS | I18: 5092668 | J18: GL ASFALTOS Y TRITURADOS SA DE CV | K18: Z04 | L18: (AP) 30 Dias | M18: 10000437 | N18: Grava Triturada Basalto 20 mm - 3/4" | O18: DW82 | P18: MX-CED. DURANGO | Q18: 20240111 | R18: 20291231 | S18: 20250717 | T18: 20301231 | U18: 211.2 | V18: MXN | W18: TN | X18: 46.2 | Y18: MXN | Z18: TN | AA18: D152 | AB18: SICLO-PD034 DURANGO | AC18: 56103637 | AD18: 6644391540 | AE18: 4 | AF18: ENTREGA DIRECTA | AG18: 1 | AH18: TO | AI18: X | AJ18: 4 | AK18: V4 | AL18: 20250731 | AM18: DW82-900008629-D152-10000437-4
A19: 900008629DW82D15210000413 | B19: 4600068989-20 | C19: 4600068989 | D19: 20 | E19: MXPO | F19: MXL | G19: 900008629 | H19: SF TC-ED GL ASFALTOS | I19: 5092668 | J19: GL ASFALTOS Y TRITURADOS SA DE CV | K19: Z04 | L19: (AP) 30 Dias | M19: 10000413 | N19: Grava Triturada Basalto 40 mm - 1 1/2" | O19: DW82 | P19: MX-CED. DURANGO | Q19: 20240111 | R19: 20291231 | S19: 20250717 | T19: 20301231 | U19: 209.2 | V19: MXN | W19: TN | X19: 46.2 | Y19: MXN | Z19: TN | AA19: D152 | AB19: SICLO-PD034 DURANGO | AC19: 56103637 | AD19: 6644391540 | AE19: 4 | AF19: ENTREGA DIRECTA | AG19: 1 | AH19: TO | AI19: X | AJ19: 4 | AK19: V4 | AL19: 20250731 | AM19: DW82-900008629-D152-10000413-4
A20: 900008817DW8210164161 | B20: 4600069514-40 | C20: 4600069514 | D20: 40 | E20: MXPO | F20: MXL | G20: 900008817 | H20: SF TC-REC PETROLOGIA E INGENIERIA | I20: 5093347 | J20: PETROLOGIA E INGENIERIA AVANZADA SA | K20: Z09 | L20: (AP) 90 Dias | M20: 10164161 | N20: ARENA CLASIFICADA RÍO MALLA 4 | O20: DW82 | P20: MX-CED. DURANGO | Q20: 20240513 | R20: 20291231 | S20: 20240513 | T20: 20291231 | U20: 315 | V20: MXN | W20: M3 | X20: 0 | Y20: MXN | Z20: M3 | AC20: 56103638 | AD20: 6644391540 | AE20: 2 | AF20: RECOGIDO | AG20: 1.35 | AH20: M3 | AI20: X | AJ20: 4 | AK20: V4 | AL20: 20240515 | AM20: DW82-900008817-10164161
A21: 900008629DW82D15210000137 | B21: 4600068989-40 | C21: 4600068989 | D21: 40 | E21: MXPO | F21: MXL | G21: 900008629 | H21: SF TC-ED GL ASFALTOS | I21: 5092668 | J21: GL ASFALTOS Y TRITURADOS SA DE CV | K21: Z04 | L21: (AP) 30 Dias | M21: 10000137 | N21: Arena Triturada Basalto Malla 5 | O21: DW82 | P21: MX-CED. DURANGO | Q21: 20240111 | R21: 20291231 | S21: 20250717 | T21: 20301231 | U21: 256.2 | V21: MXN | W21: TN | X21: 46.2 | Y21: MXN | Z21: TN | AA21: D152 | AB21: SICLO-PD034 DURANGO | AC21: 56103638 | AD21: 6644391540 | AE21: 4 | AF21: ENTREGA DIRECTA | AG21: 1 | AH21: TO | AI21: X | AJ21: 4 | AK21: V4 | AL21: 20250731 | AM21: DW82-900008629-D152-10000137-4
A22: 900008817DW8210000437 | B22: 4600069514-10 | C22: 4600069514 | D22: 10 | E22: MXPO | F22: MXL | G22: 900008817 | H22: SF TC-REC PETROLOGIA E INGENIERIA | I22: 5093347 | J22: PETROLOGIA E INGENIERIA AVANZADA SA | K22: Z09 | L22: (AP) 90 Dias | M22: 10000437 | N22: Grava Triturada Basalto 20 mm - 3/4" | O22: DW82 | P22: MX-CED. DURANGO | Q22: 20240513 | R22: 20291231 | S22: 20240513 | T22: 20291231 | U22: 210 | V22: MXN | W22: M3 | X22: 0 | Y22: MXN | Z22: M3 | AC22: 56103637 | AD22: 6644391540 | AE22: 2 | AF22: RECOGIDO | AG22: 1.505 | AH22: M3 | AI22: X | AJ22: 4 | AK22: V4 | AL22: 20240515 | AM22: DW82-900008817-10000437
A23: 900008817DW8210000137 | B23: 4600069514-60 | C23: 4600069514 | D23: 60 | E23: MXPO | F23: MXL | G23: 900008817 | H23: SF TC-REC PETROLOGIA E INGENIERIA | I23: 5093347 | J23: PETROLOGIA E INGENIERIA AVANZADA SA | K23: Z09 | L23: (AP) 90 Dias | M23: 10000137 | N23: Arena Triturada Basalto Malla 5 | O23: DW82 | P23: MX-CED. DURANGO | Q23: 20240513 | R23: 20291231 | S23: 20240716 | T23: 20291231 | U23: 315 | V23: MXN | W23: M3 | X23: 0 | Y23: MXN | Z23: M3 | AC23: 56103638 | AD23: 6644391540 | AE23: 2 | AF23: RECOGIDO | AG23: 1.7 | AH23: M3 | AI23: X | AJ23: 4 | AK23: V4 | AL23: 20240717 | AM23: DW82-900008817-10000137
A24: 900008817DW8210000151 | B24: 4600069514-20 | C24: 4600069514 | D24: 20 | E24: MXPO | F24: MXL | G24: 900008817 | H24: SF TC-REC PETROLOGIA E INGENIERIA | I24: 5093347 | J24: PETROLOGIA E INGENIERIA AVANZADA SA | K24: Z09 | L24: (AP) 90 Dias | M24: 10000151 | N24: Grava Triturada Basalto 10 mm - 3/8" | O24: DW82 | P24: MX-CED. DURANGO | Q24: 20240513 | R24: 20291231 | S24: 20240513 | T24: 20291231 | U24: 290 | V24: MXN | W24: M3 | X24: 0 | Y24: MXN | Z24: M3 | AC24: 56103637 | AD24: 6644391540 | AE24: 2 | AF24: RECOGIDO | AG24: 1.5 | AH24: M3 | AI24: X | AJ24: 4 | AK24: V4 | AL24: 20240515 | AM24: DW82-900008817-10000151
A25: 900008817DW8210179731 | B25: 4600069514-30 | C25: 4600069514 | D25: 30 | E25: MXPO | F25: MXL | G25: 900008817 | H25: SF TC-REC PETROLOGIA E INGENIERIA | I25: 5093347 | J25: PETROLOGIA E INGENIERIA AVANZADA SA | K25: Z09 | L25: (AP) 90 Dias | M25: 10179731 | N25: BASE H TRITURADA BASALTO 1 1/2" A FINOS | O25: DW82 | P25: MX-CED. DURANGO | Q25: 20240513 | R25: 20291231 | S25: 20240513 | T25: 20291231 | U25: 205 | V25: MXN | W25: M3 | X25: 0 | Y25: MXN | Z25: M3 | AC25: 56103590 | AD25: 6644391540 | AE25: 2 | AF25: RECOGIDO | AG25: 1.619 | AH25: M3 | AI25: X | AJ25: 4 | AK25: V4 | AL25: 20240606 | AM25: DW82-900008817-10179731
A26: 900005956DW82D15210164161 | B26: 4600050369-10 | C26: 4600050369 | D26: 10 | E26: MXPO | F26: MXL | G26: 900005956 | H26: SF TC- ED- HOMERO SAMUEL HERDANDEZ | I26: 5005214 | J26: HERNANDEZ TUERO HOMERO SAMUEL | K26: N90 | L26: (AP) NAFIN 90 Dias | M26: 10164161 | N26: ARENA CLASIFICADA RÍO MALLA 4 | O26: DW82 | P26: MX-CED. DURANGO | Q26: 20210801 | R26: 20291231 | S26: 20240429 | T26: 20291231 | U26: 230 | V26: MXN | W26: TN | X26: 46 | Y26: MXN | Z26: TN | AA26: D152 | AB26: SICLO-PD034 DURANGO | AC26: 56103638 | AD26: 6644391540 | AE26: 4 | AF26: ENTREGA DIRECTA | AG26: 1 | AH26: TO | AI26: X | AJ26: 4 | AK26: V4 | AL26: 20240524 | AM26: DW82-900005956-D152-10164161-4
A27: 900008816DW82D15210000413 | B27: 4600069513-100 | C27: 4600069513 | D27: 100 | E27: MXPO | F27: MXL | G27: 900008816 | H27: SF TC-ED PETROLOGIA E INGENIERIA | I27: 5093347 | J27: PETROLOGIA E INGENIERIA AVANZADA SA | K27: Z09 | L27: (AP) 90 Dias | M27: 10000413 | N27: Grava Triturada Basalto 40 mm - 1 1/2" | O27: DW82 | P27: MX-CED. DURANGO | Q27: 20240513 | R27: 20291231 | S27: 20250210 | T27: 20301231 | U27: 200.88 | V27: MXN | W27: TN | X27: 37.8 | Y27: MXN | Z27: TN | AA27: D152 | AB27: SICLO-PD034 DURANGO | AC27: 56103637 | AD27: 6644391540 | AE27: 4 | AF27: ENTREGA DIRECTA | AG27: 1 | AH27: TO | AI27: X | AJ27: 4 | AK27: V4 | AL27: 20250221 | AM27: DW82-900008816-D152-10000413-4
A28: 900008816DW82D15210000151 | B28: 4600069513-120 | C28: 4600069513 | D28: 120 | E28: MXPO | F28: MXL | G28: 900008816 | H28: SF TC-ED PETROLOGIA E INGENIERIA | I28: 5093347 | J28: PETROLOGIA E INGENIERIA AVANZADA SA | K28: Z09 | L28: (AP) 90 Dias | M28: 10000151 | N28: Grava Triturada Basalto 10 mm - 3/8" | O28: DW82 | P28: MX-CED. DURANGO | Q28: 20240513 | R28: 20291231 | S28: 20250210 | T28: 20301231 | U28: 278.06 | V28: MXN | W28: TN | X28: 40.46 | Y28: MXN | Z28: TN | AA28: D152 | AB28: SICLO-PD034 DURANGO | AC28: 56103637 | AD28: 6644391540 | AE28: 4 | AF28: ENTREGA DIRECTA | AG28: 1 | AH28: TO | AI28: X | AJ28: 4 | AK28: V4 | AL28: 20250221 | AM28: DW82-900008816-D152-10000151-4
A29: 900008816DW82D15210000437 | B29: 4600069513-90 | C29: 4600069513 | D29: 90 | E29: MXPO | F29: MXL | G29: 900008816 | H29: SF TC-ED PETROLOGIA E INGENIERIA | I29: 5093347 | J29: PETROLOGIA E INGENIERIA AVANZADA SA | K29: Z09 | L29: (AP) 90 Dias | M29: 10000437 | N29: Grava Triturada Basalto 20 mm - 3/4" | O29: DW82 | P29: MX-CED. DURANGO | Q29: 20240513 | R29: 20291231 | S29: 20250210 | T29: 20301231 | U29: 204.12 | V29: MXN | W29: TN | X29: 38.88 | Y29: MXN | Z29: TN | AA29: D152 | AB29: SICLO-PD034 DURANGO | AC29: 56103637 | AD29: 6644391540 | AE29: 4 | AF29: ENTREGA DIRECTA | AG29: 1 | AH29: TO | AI29: X | AJ29: 4 | AK29: V4 | AL29: 20250221 | AM29: DW82-900008816-D152-10000437-4
A30: 900008816DW82D15210000137 | B30: 4600069513-130 | C30: 4600069513 | D30: 130 | E30: MXPO | F30: MXL | G30: 900008816 | H30: SF TC-ED PETROLOGIA E INGENIERIA | I30: 5093347 | J30: PETROLOGIA E INGENIERIA AVANZADA SA | K30: Z09 | L30: (AP) 90 Dias | M30: 10000137 | N30: Arena Triturada Basalto Malla 5 | O30: DW82 | P30: MX-CED. DURANGO | Q30: 20240513 | R30: 20291231 | S30: 20250210 | T30: 20301231 | U30: 244.08 | V30: MXN | W30: TN | X30: 33.48 | Y30: MXN | Z30: TN | AA30: D152 | AB30: SICLO-PD034 DURANGO | AC30: 56103638 | AD30: 6644391540 | AE30: 4 | AF30: ENTREGA DIRECTA | AG30: 1 | AH30: TO | AI30: X | AJ30: 4 | AK30: V4 | AL30: 20250221 | AM30: DW82-900008816-D152-10000137-4
A31: 900007460DW8210164161 | B31: 4600052868-10 | C31: 4600052868 | D31: 10 | E31: MXPO | F31: MXL | G31: 900007460 | H31: SF TP-VTA CRUZADA SHHT | I31: 5005214 | J31: HERNANDEZ TUERO HOMERO SAMUEL | K31: N90 | L31: (AP) NAFIN 90 Dias | M31: 10164161 | N31: ARENA CLASIFICADA RÍO MALLA 4 | O31: DW82 | P31: MX-CED. DURANGO | Q31: 20220117 | R31: 20271231 | S31: 20220112 | T31: 20271231 | U31: 84.38 | V31: MXN | W31: TN | AC31: 56103638 | AD31: 6644391540 | AE31: 1 | AF31: ENTREGADO | AG31: 1 | AH31: TO | AI31: X | AJ31: 4 | AK31: V4 | AL31: 20230920 | AM31: DW82-900007460-10164161
