Workbook

Sheet Base Cedis DW94
N1: VENTA | Q1: COSTO
A2: CONCAT1 | B2: CONCAT2 | C2: No. SF | D2: Nombre SF | E2: Cedis | F2: Destino | G2: Condicion de Expedicion | H2: Nombre Destino | I2: No. de material | J2: Nombre de material | K2: PV | L2: Inicio de vigencia | M2: Fin de vigencia | N2: Importe MP | O2: Importe Flete | P2: UM Venta | Q2: Importe Costo | R2: UM Costo | S2: Validacion 1 | T2: Validacion 2
A3: =CONCATENATE(C3,E3,F3,I3) | B3: =CONCATENATE(C3,E3,I3) | C3: 900001969 | D3: =IFERROR(VLOOKUP(C3,TRAOPE!$G:$H,2,0),"") | E3: DW94 | F3: D685 | G3: =IFERROR(VLOOKUP(A3,Flete!$A:$E,5,0),"") | H3: =IFERROR(VLOOKUP(F3,TRAOPE!$AA:$AB,2,0),"") | I3: 10000635 | J3: =IFERROR(VLOOKUP(I3,Materiales!$A:$H,8,0),"") | K3: =IFERROR(VLOOKUP(I3,Materiales!$A:$G,7,0),"") | L3: 20230501 | M3: 20250131 | N3: 550 | O3: =IFERROR(VLOOKUP(A3,Flete!$A:$J,10,0),"") | P3: TN | Q3: =IFERROR(IFERROR(VLOOKUP(A3,TRAOPE!$A:$U,21,0),VLOOKUP(B3,TRAOPE!$A:$U,21,0)),"") | R3: =IFERROR(IFERROR(VLOOKUP(A3,TRAOPE!$A:$W,23,0),VLOOKUP(B3,TRAOPE!$A:$W,23,0)),"") | S3: =IF(AND(P3="TN",R3="TN"),N3+N(O3),IF(G3&""="1",N(K3)*N3,(N3+N(O3))*N(K3))) | T3: =IF(Q3="","",Q3-S3)
A4: =CONCATENATE(C4,E4,F4,I4) | B4: =CONCATENATE(C4,E4,I4) | C4: 900001969 | D4: =IFERROR(VLOOKUP(C4,TRAOPE!$G:$H,2,0),"") | E4: DW94 | F4: D685 | G4: =IFERROR(VLOOKUP(A4,Flete!$A:$E,5,0),"") | H4: =IFERROR(VLOOKUP(F4,TRAOPE!$AA:$AB,2,0),"") | I4: 10000643 | J4: =IFERROR(VLOOKUP(I4,Materiales!$A:$H,8,0),"") | K4: =IFERROR(VLOOKUP(I4,Materiales!$A:$G,7,0),"") | L4: 20230501 | M4: 20250131 | N4: 550 | O4: =IFERROR(VLOOKUP(A4,Flete!$A:$J,10,0),"") | P4: TN | Q4: =IFERROR(IFERROR(VLOOKUP(A4,TRAOPE!$A:$U,21,0),VLOOKUP(B4,TRAOPE!$A:$U,21,0)),"") | R4: =IFERROR(IFERROR(VLOOKUP(A4,TRAOPE!$A:$W,23,0),VLOOKUP(B4,TRAOPE!$A:$W,23,0)),"") | S4: =IF(AND(P4="TN",R4="TN"),N4+N(O4),IF(G4&""="1",N(K4)*N4,(N4+N(O4))*N(K4))) | T4: =IF(Q4="","",Q4-S4)
A5: =CONCATENATE(C5,E5,F5,I5) | B5: =CONCATENATE(C5,E5,I5) | C5: 900001969 | D5: =IFERROR(VLOOKUP(C5,TRAOPE!$G:$H,2,0),"") | E5: DW94 | F5: D685 | G5: =IFERROR(VLOOKUP(A5,Flete!$A:$E,5,0),"") | H5: =IFERROR(VLOOKUP(F5,TRAOPE!$AA:$AB,2,0),"") | I5: 10000655 | J5: =IFERROR(VLOOKUP(I5,Materiales!$A:$H,8,0),"") | K5: =IFERROR(VLOOKUP(I5,Materiales!$A:$G,7,0),"") | L5: 20230501 | M5: 20250131 | N5: 550 | O5: =IFERROR(VLOOKUP(A5,Flete!$A:$J,10,0),"") | P5: TN | Q5: =IFERROR(IFERROR(VLOOKUP(A5,TRAOPE!$A:$U,21,0),VLOOKUP(B5,TRAOPE!$A:$U,21,0)),"") | R5: =IFERROR(IFERROR(VLOOKUP(A5,TRAOPE!$A:$W,23,0),VLOOKUP(B5,TRAOPE!$A:$W,23,0)),"") | S5: =IF(AND(P5="TN",R5="TN"),N5+N(O5),IF(G5&""="1",N(K5)*N5,(N5+N(O5))*N(K5))) | T5: =IF(Q5="","",Q5-S5)
A6: =CONCATENATE(C6,E6,F6,I6) | B6: =CONCATENATE(C6,E6,I6) | C6: 900004696 | D6: =IFERROR(VLOOKUP(C6,TRAOPE!$G:$H,2,0),"") | E6: DW94 | F6: D683 | G6: =IFERROR(VLOOKUP(A6,Flete!$A:$E,5,0),"") | H6: =IFERROR(VLOOKUP(F6,TRAOPE!$AA:$AB,2,0),"") | I6: 10000523 | J6: =IFERROR(VLOOKUP(I6,Materiales!$A:$H,8,0),"") | K6: =IFERROR(VLOOKUP(I6,Materiales!$A:$G,7,0),"") | L6: 20230501 | M6: 20250131 | N6: 78.58 | O6: =IFERROR(VLOOKUP(A6,Flete!$A:$J,10,0),"") | P6: TN | Q6: =IFERROR(IFERROR(VLOOKUP(A6,TRAOPE!$A:$U,21,0),VLOOKUP(B6,TRAOPE!$A:$U,21,0)),"") | R6: =IFERROR(IFERROR(VLOOKUP(A6,TRAOPE!$A:$W,23,0),VLOOKUP(B6,TRAOPE!$A:$W,23,0)),"") | S6: =IF(AND(P6="TN",R6="TN"),N6+N(O6),IF(G6&""="1",N(K6)*N6,(N6+N(O6))*N(K6))) | T6: =IF(Q6="","",Q6-S6)
A7: =CONCATENATE(C7,E7,F7,I7) | B7: =CONCATENATE(C7,E7,I7) | C7: 900004696 | D7: =IFERROR(VLOOKUP(C7,TRAOPE!$G:$H,2,0),"") | E7: DW94 | F7: D683 | G7: =IFERROR(VLOOKUP(A7,Flete!$A:$E,5,0),"") | H7: =IFERROR(VLOOKUP(F7,TRAOPE!$AA:$AB,2,0),"") | I7: 10128740 | J7: =IFERROR(VLOOKUP(I7,Materiales!$A:$H,8,0),"") | K7: =IFERROR(VLOOKUP(I7,Materiales!$A:$G,7,0),"") | L7: 20230501 | M7: 20250131 | N7: 70.61 | O7: =IFERROR(VLOOKUP(A7,Flete!$A:$J,10,0),"") | P7: TN | Q7: =IFERROR(IFERROR(VLOOKUP(A7,TRAOPE!$A:$U,21,0),VLOOKUP(B7,TRAOPE!$A:$U,21,0)),"") | R7: =IFERROR(IFERROR(VLOOKUP(A7,TRAOPE!$A:$W,23,0),VLOOKUP(B7,TRAOPE!$A:$W,23,0)),"") | S7: =IF(AND(P7="TN",R7="TN"),N7+N(O7),IF(G7&""="1",N(K7)*N7,(N7+N(O7))*N(K7))) | T7: =IF(Q7="","",Q7-S7)
A8: =CONCATENATE(C8,E8,F8,I8) | B8: =CONCATENATE(C8,E8,I8) | C8: 900004698 | D8: =IFERROR(VLOOKUP(C8,TRAOPE!$G:$H,2,0),"") | E8: DW94 | F8: D683 | G8: =IFERROR(VLOOKUP(A8,Flete!$A:$E,5,0),"") | H8: =IFERROR(VLOOKUP(F8,TRAOPE!$AA:$AB,2,0),"") | I8: 10128599 | J8: =IFERROR(VLOOKUP(I8,Materiales!$A:$H,8,0),"") | K8: =IFERROR(VLOOKUP(I8,Materiales!$A:$G,7,0),"") | L8: 20230501 | M8: 20250131 | N8: 87.85 | O8: =IFERROR(VLOOKUP(A8,Flete!$A:$J,10,0),"") | P8: TN | Q8: =IFERROR(IFERROR(VLOOKUP(A8,TRAOPE!$A:$U,21,0),VLOOKUP(B8,TRAOPE!$A:$U,21,0)),"") | R8: =IFERROR(IFERROR(VLOOKUP(A8,TRAOPE!$A:$W,23,0),VLOOKUP(B8,TRAOPE!$A:$W,23,0)),"") | S8: =IF(AND(P8="TN",R8="TN"),N8+N(O8),IF(G8&""="1",N(K8)*N8,(N8+N(O8))*N(K8))) | T8: =IF(Q8="","",Q8-S8)
A9: =CONCATENATE(C9,E9,F9,I9) | B9: =CONCATENATE(C9,E9,I9) | C9: 900004698 | D9: =IFERROR(VLOOKUP(C9,TRAOPE!$G:$H,2,0),"") | E9: DW94 | F9: D683 | G9: =IFERROR(VLOOKUP(A9,Flete!$A:$E,5,0),"") | H9: =IFERROR(VLOOKUP(F9,TRAOPE!$AA:$AB,2,0),"") | I9: 10128754 | J9: =IFERROR(VLOOKUP(I9,Materiales!$A:$H,8,0),"") | K9: =IFERROR(VLOOKUP(I9,Materiales!$A:$G,7,0),"") | L9: 20230501 | M9: 20250131 | N9: 81.64 | O9: =IFERROR(VLOOKUP(A9,Flete!$A:$J,10,0),"") | P9: TN | Q9: =IFERROR(IFERROR(VLOOKUP(A9,TRAOPE!$A:$U,21,0),VLOOKUP(B9,TRAOPE!$A:$U,21,0)),"") | R9: =IFERROR(IFERROR(VLOOKUP(A9,TRAOPE!$A:$W,23,0),VLOOKUP(B9,TRAOPE!$A:$W,23,0)),"") | S9: =IF(AND(P9="TN",R9="TN"),N9+N(O9),IF(G9&""="1",N(K9)*N9,(N9+N(O9))*N(K9))) | T9: =IF(Q9="","",Q9-S9)
A10: =CONCATENATE(C10,E10,F10,I10) | B10: =CONCATENATE(C10,E10,I10) | C10: 900004698 | D10: =IFERROR(VLOOKUP(C10,TRAOPE!$G:$H,2,0),"") | E10: DW94 | F10: D685 | G10: =IFERROR(VLOOKUP(A10,Flete!$A:$E,5,0),"") | H10: =IFERROR(VLOOKUP(F10,TRAOPE!$AA:$AB,2,0),"") | I10: 10128599 | J10: =IFERROR(VLOOKUP(I10,Materiales!$A:$H,8,0),"") | K10: =IFERROR(VLOOKUP(I10,Materiales!$A:$G,7,0),"") | L10: 20230501 | M10: 20250131 | N10: 87.84 | O10: =IFERROR(VLOOKUP(A10,Flete!$A:$J,10,0),"") | P10: TN | Q10: =IFERROR(IFERROR(VLOOKUP(A10,TRAOPE!$A:$U,21,0),VLOOKUP(B10,TRAOPE!$A:$U,21,0)),"") | R10: =IFERROR(IFERROR(VLOOKUP(A10,TRAOPE!$A:$W,23,0),VLOOKUP(B10,TRAOPE!$A:$W,23,0)),"") | S10: =IF(AND(P10="TN",R10="TN"),N10+N(O10),IF(G10&""="1",N(K10)*N10,(N10+N(O10))*N(K10))) | T10: =IF(Q10="","",Q10-S10)
A11: =CONCATENATE(C11,E11,F11,I11) | B11: =CONCATENATE(C11,E11,I11) | C11: 900004698 | D11: =IFERROR(VLOOKUP(C11,TRAOPE!$G:$H,2,0),"") | E11: DW94 | F11: D685 | G11: =IFERROR(VLOOKUP(A11,Flete!$A:$E,5,0),"") | H11: =IFERROR(VLOOKUP(F11,TRAOPE!$AA:$AB,2,0),"") | I11: 10128754 | J11: =IFERROR(VLOOKUP(I11,Materiales!$A:$H,8,0),"") | K11: =IFERROR(VLOOKUP(I11,Materiales!$A:$G,7,0),"") | L11: 20230501 | M11: 20250131 | N11: 81.63 | O11: =IFERROR(VLOOKUP(A11,Flete!$A:$J,10,0),"") | P11: TN | Q11: =IFERROR(IFERROR(VLOOKUP(A11,TRAOPE!$A:$U,21,0),VLOOKUP(B11,TRAOPE!$A:$U,21,0)),"") | R11: =IFERROR(IFERROR(VLOOKUP(A11,TRAOPE!$A:$W,23,0),VLOOKUP(B11,TRAOPE!$A:$W,23,0)),"") | S11: =IF(AND(P11="TN",R11="TN"),N11+N(O11),IF(G11&""="1",N(K11)*N11,(N11+N(O11))*N(K11))) | T11: =IF(Q11="","",Q11-S11)
A12: =CONCATENATE(C12,E12,F12,I12) | B12: =CONCATENATE(C12,E12,I12) | C12: 900004699 | D12: =IFERROR(VLOOKUP(C12,TRAOPE!$G:$H,2,0),"") | E12: DW94 | F12: D686 | G12: =IFERROR(VLOOKUP(A12,Flete!$A:$E,5,0),"") | H12: =IFERROR(VLOOKUP(F12,TRAOPE!$AA:$AB,2,0),"") | I12: 10128748 | J12: =IFERROR(VLOOKUP(I12,Materiales!$A:$H,8,0),"") | K12: =IFERROR(VLOOKUP(I12,Materiales!$A:$G,7,0),"") | L12: 20230501 | M12: 20250131 | N12: 128.73 | O12: =IFERROR(VLOOKUP(A12,Flete!$A:$J,10,0),"") | P12: TN | Q12: =IFERROR(IFERROR(VLOOKUP(A12,TRAOPE!$A:$U,21,0),VLOOKUP(B12,TRAOPE!$A:$U,21,0)),"") | R12: =IFERROR(IFERROR(VLOOKUP(A12,TRAOPE!$A:$W,23,0),VLOOKUP(B12,TRAOPE!$A:$W,23,0)),"") | S12: =IF(AND(P12="TN",R12="TN"),N12+N(O12),IF(G12&""="1",N(K12)*N12,(N12+N(O12))*N(K12))) | T12: =IF(Q12="","",Q12-S12)
A13: =CONCATENATE(C13,E13,F13,I13) | B13: =CONCATENATE(C13,E13,I13) | C13: 900004699 | D13: =IFERROR(VLOOKUP(C13,TRAOPE!$G:$H,2,0),"") | E13: DW94 | F13: D686 | G13: =IFERROR(VLOOKUP(A13,Flete!$A:$E,5,0),"") | H13: =IFERROR(VLOOKUP(F13,TRAOPE!$AA:$AB,2,0),"") | I13: 10128752 | J13: =IFERROR(VLOOKUP(I13,Materiales!$A:$H,8,0),"") | K13: =IFERROR(VLOOKUP(I13,Materiales!$A:$G,7,0),"") | L13: 20230501 | M13: 20250131 | N13: 128.73 | O13: =IFERROR(VLOOKUP(A13,Flete!$A:$J,10,0),"") | P13: TN | Q13: =IFERROR(IFERROR(VLOOKUP(A13,TRAOPE!$A:$U,21,0),VLOOKUP(B13,TRAOPE!$A:$U,21,0)),"") | R13: =IFERROR(IFERROR(VLOOKUP(A13,TRAOPE!$A:$W,23,0),VLOOKUP(B13,TRAOPE!$A:$W,23,0)),"") | S13: =IF(AND(P13="TN",R13="TN"),N13+N(O13),IF(G13&""="1",N(K13)*N13,(N13+N(O13))*N(K13))) | T13: =IF(Q13="","",Q13-S13)
A14: =CONCATENATE(C14,E14,F14,I14) | B14: =CONCATENATE(C14,E14,I14) | C14: 900004700 | D14: =IFERROR(VLOOKUP(C14,TRAOPE!$G:$H,2,0),"") | E14: DW94 | F14: D686 | G14: =IFERROR(VLOOKUP(A14,Flete!$A:$E,5,0),"") | H14: =IFERROR(VLOOKUP(F14,TRAOPE!$AA:$AB,2,0),"") | I14: 10128740 | J14: =IFERROR(VLOOKUP(I14,Materiales!$A:$H,8,0),"") | K14: =IFERROR(VLOOKUP(I14,Materiales!$A:$G,7,0),"") | L14: 20250701 | M14: 20251031 | N14: 257 | O14: =IFERROR(VLOOKUP(A14,Flete!$A:$J,10,0),"") | P14: TN | Q14: =IFERROR(IFERROR(VLOOKUP(A14,TRAOPE!$A:$U,21,0),VLOOKUP(B14,TRAOPE!$A:$U,21,0)),"") | R14: =IFERROR(IFERROR(VLOOKUP(A14,TRAOPE!$A:$W,23,0),VLOOKUP(B14,TRAOPE!$A:$W,23,0)),"") | S14: =IF(AND(P14="TN",R14="TN"),N14+N(O14),IF(G14&""="1",N(K14)*N14,(N14+N(O14))*N(K14))) | T14: =IF(Q14="","",Q14-S14)
... A158: =CONCATENATE(C158,E158,F158,I158) | B158: =CONCATENATE(C158,E158,I158) | C158: 900009576 | D158: =IFERROR(VLOOKUP(C158,TRAOPE!$G:$H,2,0),"") | E158: DW94 | F158: D683 | G158: =IFERROR(VLOOKUP(A158,Flete!$A:$E,5,0),"") | H158: =IFERROR(VLOOKUP(F158,TRAOPE!$AA:$AB,2,0),"") | I158: 10280365 | J158: =IFERROR(VLOOKUP(I158,Materiales!$A:$H,8,0),"") | K158: =IFERROR(VLOOKUP(I158,Materiales!$A:$G,7,0),"") | L158: 20260720 | M158: 99991231 | N158: 215.86 | O158: =IFERROR(VLOOKUP(A158,Flete!$A:$J,10,0),"") | P158: TN | Q158: =IFERROR(IFERROR(VLOOKUP(A158,TRAOPE!$A:$U,21,0),VLOOKUP(B158,TRAOPE!$A:$U,21,0)),"") | R158: =IFERROR(IFERROR(VLOOKUP(A158,TRAOPE!$A:$W,23,0),VLOOKUP(B158,TRAOPE!$A:$W,23,0)),"") | S158: =IF(AND(P158="TN",R158="TN"),N158+N(O158),IF(G158&""="1",N(K158)*N158,(N158+N(O158))*N(K158))) | T158: =IF(Q158="","",Q158-S158)

Sheet MP
A1: No. SF | B1: Cedis | C1: Destino | D1: No. Material | E1: Nombre Material | F1: Importe MP | G1: Moneda | H1: Cantidad | I1: UM | J1: C | K1: Inicio Vigencia | L1: Fin Vigencia
A2: 900001969 | B2: DW94 | C2: D685 | D2: 10000635 | F2: 550 | I2: TN | K2: 20230501 | L2: 20250131
A3: 900001969 | B3: DW94 | C3: D685 | D3: 10000643 | F3: 550 | I3: TN | K3: 20230501 | L3: 20250131
A4: 900001969 | B4: DW94 | C4: D685 | D4: 10000655 | F4: 550 | I4: TN | K4: 20230501 | L4: 20250131
A5: 900004696 | B5: DW94 | C5: D683 | D5: 10000523 | F5: 78.58 | I5: TN | K5: 20230501 | L5: 20250131
A6: 900004696 | B6: DW94 | C6: D683 | D6: 10128740 | F6: 70.61 | I6: TN | K6: 20230501 | L6: 20250131
A7: 900004698 | B7: DW94 | C7: D683 | D7: 10128599 | F7: 87.85 | I7: TN | K7: 20230501 | L7: 20250131
A8: 900004698 | B8: DW94 | C8: D683 | D8: 10128754 | F8: 81.64 | I8: TN | K8: 20230501 | L8: 20250131
A9: 900004698 | B9: DW94 | C9: D685 | D9: 10128599 | F9: 87.84 | I9: TN | K9: 20230501 | L9: 20250131
A10: 900004698 | B10: DW94 | C10: D685 | D10: 10128754 | F10: 81.63 | I10: TN | K10: 20230501 | L10: 20250131
A11: 900004699 | B11: DW94 | C11: D686 | D11: 10128748 | F11: 128.73 | I11: TN | K11: 20230501 | L11: 20250131
A12: 900004699 | B12: DW94 | C12: D686 | D12: 10128752 | F12: 128.73 | I12: TN | K12: 20230501 | L12: 20250131
A13: 900004700 | B13: DW94 | C13: D686 | D13: 10128740 | F13: 257 | I13: TN | K13: 20250701 | L13: 20251031
... A157: 900009576 | B157: DW94 | C157: D683 | D157: 10280365 | F157: 215.86 | I157: TN | K157: 20260720 | L157: 99991231

Sheet Flete
A1: Concat1 | B1: No. SF | C1: Cedis | D1: Destino | E1: Cond. Exp. | F1: Material | H1: Nombre Material | J1: Importe Flete | K1: Moneda | L1: Cantidad | M1: UM | N1: C | P1: Inicio Vigencia | Q1: Fin Vigencia
A2: 900001969DW94D68510000635 | B2: 900001969 | C2: DW94 | D2: D685 | E2: 1 | F2: 10000635 | J2: 967 | M2: TN | P2: 20220331 | Q2: 20250131
A3: 900001969DW94D68510000643 | B3: 900001969 | C3: DW94 | D3: D685 | E3: 1 | F3: 10000643 | J3: 967 | M3: TN | P3: 20220331 | Q3: 20250131
A4: 900001969DW94D68510000655 | B4: 900001969 | C4: DW94 | D4: D685 | E4: 1 | F4: 10000655 | J4: 967 | M4: TN | P4: 20220331 | Q4: 20250131
A5: 900004699DW94D68610128748 | B5: 900004699 | C5: DW94 | D5: D686 | E5: 1 | F5: 10128748 | J5: 20 | M5: TN | P5: 20220331 | Q5: 20250131
A6: 900004699DW94D68610128752 | B6: 900004699 | C6: DW94 | D6: D686 | E6: 1 | F6: 10128752 | J6: 20 | M6: TN | P6: 20220331 | Q6: 20250131
A7: 900004700DW94D68610128740 | B7: 900004700 | C7: DW94 | D7: D686 | E7: 1 | F7: 10128740 | J7: 194.5 | M7: TN | P7: 20250401 | Q7: 20251031
A8: 900004700DW94D68610128743 | B8: 900004700 | C8: DW94 | D8: D686 | E8: 1 | F8: 10128743 | J8: 193 | M8: TN | P8: 20250401 | Q8: 20251031
A9: 900004700DW94D68610128752 | B9: 900004700 | C9: DW94 | D9: D686 | E9: 1 | F9: 10128752 | J9: 197.7 | M9: TN | P9: 20230626 | Q9: 99991231
A10: 900004701DW94D68610000523 | B10: 900004701 | C10: DW94 | D10: D686 | E10: 1 | F10: 10000523 | J10: 109.72 | M10: TN | P10: 20220331 | Q10: 20250131
A11: 900004701DW94D68610000754 | B11: 900004701 | C11: DW94 | D11: D686 | E11: 1 | F11: 10000754 | J11: 109.72 | M11: TN | P11: 20220331 | Q11: 20250131
A12: 900004701DW94D68610128740 | B12: 900004701 | C12: DW94 | D12: D686 | E12: 1 | F12: 10128740 | J12: 107.42 | M12: TN | P12: 20220331 | Q12: 20250131
A13: 900004701DW94D68610137435 | B13: 900004701 | C13: DW94 | D13: D686 | E13: 1 | F13: 10137435 | J13: 116.3 | M13: TN | P13: 20220331 | Q13: 20250131
... A141: 900009526DW94D68310277192 | B141: 900009526 | C141: DW94 | D141: D683 | E141: 1 | F141: 10277192 | J141: 51.71 | M141: TN | P141: 20260708 | Q141: 99991231

Sheet Materiales
A1: Material | B1: TpMt | C1: Denom | D1: UMA | E1: Contador | F1: UMB | G1: PV | H1: Nombre Material
A2: 10000001 | B2: ZFER | C2: 1000 | D2: M3 | E2: 1000 | F2: TN | G2: 1262 | H2: GRAVA ANDESITA 10 MM (3/8")
A3: 10000003 | B3: ZFER | C3: 1000 | D3: M3 | E3: 1000 | F3: TN | G3: 1443 | H3: GRAVA CALIZA 10 MM (3/8")
A4: 10000006 | B4: ZFER | C4: 1000 | D4: M3 | E4: 1000 | F4: TN | G4: 1490 | H4: GRAVA RIO 10 MM (3/8")
A5: 10000007 | B5: ZFER | C5: 1000 | D5: M3 | E5: 1000 | F5: TN | G5: 1488 | H5: GRAVA BASALTO 13 MM (1/2")
A6: 10000008 | B6: ZFER | C6: 1000 | D6: M3 | E6: 1000 | F6: TN | G6: 1358 | H6: GRAVA CALIZA 13 MM (1/2")
A7: 10000011 | B7: ZFER | C7: 1000 | D7: M3 | E7: 1000 | F7: TN | G7: 1323 | H7: GRAVA ANDESITA 20 MM (3/4")
A8: 10000013 | B8: ZFER | C8: 1000 | D8: M3 | E8: 1000 | F8: TN | G8: 1514 | H8: GRAVA BASALTO 20 MM (3/4")
A9: 10000014 | B9: ZFER | C9: 1000 | D9: M3 | E9: 1000 | F9: TN | G9: 1400 | H9: GRAVA CALIZA 20 MM (3/4")
A10: 10000015 | B10: ZFER | C10: 1000 | D10: M3 | E10: 1000 | F10: TN | G10: 1410 | H10: GRAVA GRANITO 20 MM (3/4")
A11: 10000017 | B11: ZFER | C11: 1000 | D11: M3 | E11: 1000 | F11: TN | G11: 1475 | H11: GRAVA RIOLITA 20 MM (3/4")
A12: 10000019 | B12: ZFER | C12: 1000 | D12: M3 | E12: 1000 | F12: TN | G12: 1515 | H12: GRAVA RIO 20 MM (3/4")
A13: 10000020 | B13: ZFER | C13: 1000 | D13: M3 | E13: 1 | F13: TN | G13: 1 | H13: GRAVA MAQUILA 40MM (1 1/2")
... A2291: 10268770 | B2291: ZFE3 | C2291: 1000 | D2291: M3 | E2291: 1000 | F2291: TN | G2291: 1240 | H2291: MP GRAVA TRIT CALIZA 40MM 1 1/2" - ESP
A2292: 10268901 | B2292: ZFE3 | C2292: 1000 | D2292: M3 | E2292: 1000 | G2292: 1560 | H2292: MP GRAVA ANDESITA GRIS 3/4" - CAPADA
A2293: 10267983 | C2293: 1000 | G2293: 1800 | H2293: ESCORIA ALTO HORNO 3/4
A2294: 10268996 | C2294: 1000 | G2294: 1329 | H2294: GRAVA TRITURADA CALIZA 40 MM - 11/2"
A2295: 10269072 | C2295: 1000 | G2295: 1700 | H2295: BASE HIDRÁULICA SCREEN
A2296: 10269225 | B2296: ZFE3 | C2296: 1000 | D2296: M3 | E2296: 1000 | G2296: 1289 | H2296: MP ARENA CALIZA LAVADA MALLA 4 - DELTA I
A2297: 10269245 | B2297: ZFE3 | C2297: 1000 | D2297: M3 | E2297: 1000 | G2297: 1410 | H2297: MP GRAVA TRITURADA CALIZA 3/8 - 10MM
A2298: 10269246 | B2298: ZFE3 | C2298: 1000 | D2298: M3 | E2298: 1000 | G2298: 1400 | H2298: MP GRAVA TRITURADA CALIZA 1 1/2 - 40MM
A2299: 10269247 | B2299: ZFE3 | C2299: 1000 | D2299: M3 | E2299: 1000 | G2299: 1560 | H2299: MP ARENA TRIT CALIZA M-4
A2300: 10270431 | B2300: ZFE3 | C2300: 1000 | D2300: M3 | E2300: 1000 | G2300: 1423 | H2300: MP GRAVA RIOLITA 13 MM - 1/2"
A2301: 10270898 | B2301: ZFE3 | C2301: 1000 | D2301: M3 | E2301: 1000 | G2301: 1551 | H2301: MP BASE H. TRIT. BASALTO 1 1/2" A FINOS
A2302: 10270911 | B2302: ZFE3 | C2302: 1000 | D2302: M3 | E2302: 1000 | G2302: 1360 | H2302: MP GRAVA TRIT. BASALTO 40 MM - 1 1/2"
A2303: 10270912 | B2303: ZFE3 | C2303: 1000 | D2303: M3 | E2303: 1000 | G2303: 1589 | H2303: MP ARENA TRIT. BASALTO MALLA 4
A2304: 10270913 | B2304: ZFE3 | C2304: 1000 | D2304: M3 | E2304: 1000 | G2304: 1395 | H2304: MP GRAVA TRIT. BASALTO 20 MM - 3/4
A2305: 10270914 | B2305: ZFE3 | C2305: 1000 | D2305: M3 | E2305: 1000 | G2305: 1623 | H2305: MP ARENA ANDESITA BC
A2306: 10270824 | B2306: M3 | C2306: 1000 | D2306: M3 | E2306: 10007640 | G2306: 1325 | H2306: MP ARENA TRITURADA CALIZA MALLA 5
A2307: 10270825 | B2307: M3 | C2307: 1000 | D2307: M3 | E2307: 10000003 | G2307: 1242 | H2307: MP GRAVA TRITURADA CALIZA 10MM (3/8”)
... A2319: 10272527 | B2319: ZFE3 | C2319: 1000 | D2319: M3 | E2319: 1000 | G2319: 1620 | H2319: CNC - NO CLASIFICADO
A2320: 10000332 | C2320: 1000 | D2320: M3 | E2320: 1000 | G2320: 800 | H2320: Grava Triturada Pomez - Jal 20 mm - 3/4"
A2321: 10273001 | B2321: ZFE3 | C2321: 1000 | D2321: M3 | E2321: 1000 | G2321: 1688 | H2321: MP ARENA TRIT. BASALTO MALLA 4
A2322: 10273002 | B2322: ZFE3 | C2322: 1000 | D2322: M3 | E2322: 1000 | G2322: 1466 | H2322: MP GRAVA TRIT. BASALTO 20 MM - 3/4"
A2323: 10273351 | B2323: ZFE3 | C2323: 1000 | D2323: M3 | E2323: 1000 | G2323: 1612 | H2323: MP ARENA TRIT. CALIZA MALLA 4
A2324: 10273352 | B2324: ZFE3 | C2324: 1000 | D2324: M3 | E2324: 1000 | G2324: 1492 | H2324: MP GRAVA TRIT. CALIZA 20 MM - 3/4"
A2325: 10271724 | B2325: ZFE3 | C2325: 1000 | D2325: M3 | E2325: 1000 | G2325: 1900 | H2325: MP RESIDUO DE CONCRETO
A2326: 10000677 | C2326: 1000 | D2326: M3 | G2326: 1164 | H2326: Grava Triturada Caliza 20 mm - 3/4"
A2327: 10274190 | B2327: ZFE3 | C2327: 1000 | D2327: M3 | E2327: 1000 | G2327: 1800 | H2327: MP BASE HIDRAULICA ANDESITA 70-30
A2328: 10274601 | B2328: ZFE3 | C2328: 1000 | D2328: M3 | E2328: 1000 | G2328: 1447 | H2328: MP ARENA BASALTO N° 4
...

Sheet TRAOPE
A1: Concat1 | B1: Contrato_Pos | C1: Doc. Compras | D1: Pos | E1: Org.compras | F1: Grp-Compr. | G1: Ship From | H1: Nombre SF | I1: Proveedor | J1: Nombre Prov | K1: Cond. Pago | L1: Descr. Cond Pago | M1: Material | N1: Descripción | O1: Centro | P1: Descripción Centro | Q1: In.perído validez | R1: Fin perído validez | S1: Válido de | T1: Validez a | U1: Precio neto pedido | V1: Moneda | W1: UM Precio Pedido | X1: Importe Condición | Y1: Moneda KONP | Z1: UM Ctd Base | AA1: Destino | AB1: Nombre Destino | AC1: Cuenta de mayor | AD1: Centro de costo | AE1: Cond. Exp. | AF1: Descr. Cond. Exp. | AG1: Peso Vol. | AH1: UMB | AI1: Ind. Oblig. Conf. Ped. | AJ1: Ctrl-Conf. | AK1: IVA | AL1: Modif_Date | AM1: Ruta
A2: 900009576DW9410280365 | B2: 4600072493-10 | C2: 4600072493 | D2: 10 | E2: MXPO | F2: MXL | G2: 900009576 | H2: SF TC- LA GOLETA II | I2: 5097962 | J2: PROYECTOS E INFRAESTRUCTURA ALVISA | K2: Z09 | L2: (AP) 90 Dias | M2: 10280365 | N2: MP GRAVA BASALTO 20 MM -3/4 | O2: DW94 | P2: MX-CED. MICHOACAN | Q2: 20260720 | R2: 20301231 | S2: 20260720 | T2: 20301231 | U2: 275 | V2: MXN | W2: M3 | X2: 0 | Y2: MXN | Z2: M3 | AC2: 56103637 | AD2: 6644841540 | AE2: 1 | AF2: ENTREGADO | AG2: 1.274 | AH2: M3 | AI2: X | AJ2: 4 | AK2: V4 | AL2: 20260723 | AM2: DW94-900009576-10280365
A3: 900005274DW9410000382 | B3: 4600072543-10 | C3: 4600072543 | D3: 10 | E3: MXPO | F3: MXL | G3: 900005274 | H3: TC - GRAKO | I3: 5065843 | J3: TRITURADOS GRAKO SA DE CV | K3: N90 | L3: (AP) NAFIN 90 Dias | M3: 10000382 | N3: Grava Triturada Basalto 20 mm - 3/4" | O3: DW94 | P3: MX-CED. MICHOACAN | Q3: 20260814 | R3: 20301231 | S3: 20260819 | T3: 20301231 | U3: 200 | V3: MXN | W3: TN | X3: 0 | Y3: MXN | Z3: TN | AC3: 56103637 | AD3: 6644841540 | AE3: 1 | AF3: ENTREGADO | AG3: 1 | AH3: TO | AI3: X | AJ3: 4 | AK3: V4 | AL3: 20260819 | AM3: DW94-900005274-10000382
A4: 900007669DW9410218321 | B4: 4600054461-30 | C4: 4600054461 | D4: 30 | E4: MXPO | F4: MXL | G4: 900007669 | H4: SF TC-GRAVASE VENUSTIANO CARRANZA | I4: 5009010 | J4: GRAVASE SA DE CV | K4: Z04 | L4: (AP) 30 Dias | M4: 10218321 | N4: GRAVA TRITURADA BASALTO 10 MM - 3/8" | O4: DW94 | P4: MX-CED. MICHOACAN | Q4: 20220708 | R4: 20271231 | S4: 20260715 | T4: 20301231 | U4: 285 | V4: MXN | W4: TN | X4: 0 | Y4: MXN | Z4: TN | AC4: 56103637 | AD4: 6644841540 | AE4: 1 | AF4: ENTREGADO | AG4: 1 | AH4: TO | AI4: X | AJ4: 4 | AK4: V4 | AL4: 20260717 | AM4: DW94-900007669-10218321
A5: 900004814DW9410128748 | B5: 4600056839-10 | C5: 4600056839 | D5: 10 | E5: MXPO | F5: MXL | G5: 900004814 | H5: TC-MACIAS | I5: 5005851 | J5: INFRAESTRUCTURA LOGISTICA SA DE CV | K5: N90 | L5: (AP) NAFIN 90 Dias | M5: 10128748 | N5: GRAVA TRITURADA BASALTO 20 MM - 3/4" | O5: DW94 | P5: MX-CED. MICHOACAN | Q5: 20230207 | R5: 20291231 | S5: 20250519 | T5: 20301231 | U5: 309.75 | V5: MXN | W5: M3 | X5: 0 | Y5: MXN | Z5: M3 | AC5: 56103637 | AD5: 6644841540 | AE5: 1 | AF5: ENTREGADO | AG5: 1.382 | AH5: M3 | AI5: X | AJ5: 4 | AK5: V4 | AL5: 20250619 | AM5: DW94-900004814-10128748
A6: 900005430DW9410128599 | B6: 4600050523-30 | C6: 4600050523 | D6: 30 | E6: MXPO | F6: MXL | G6: 900005430 | H6: TC-MESON NUEVO II | I6: 5041348 | J6: GRUPO EDIFICADOR GENESIS SA DE CV | K6: Z03 | L6: (AP) 15 Dias | M6: 10128599 | N6: GRAVA TRITURADA BASALTO 10 MM - 3/8" | O6: DW94 | P6: MX-CED. MICHOACAN | Q6: 20210712 | R6: 20281231 | S6: 20260401 | T6: 20301231 | U6: 155 | V6: MXN | W6: M3 | X6: 0 | Y6: MXN | Z6: M3 | AC6: 56103637 | AD6: 6644841540 | AE6: 1 | AF6: ENTREGADO | AG6: 1.48 | AH6: M3 | AI6: X | AJ6: 4 | AK6: V4 | AL6: 20260513 | AM6: DW94-900005430-10128599
A7: 900005430DW9410128754 | B7: 4600050523-20 | C7: 4600050523 | D7: 20 | E7: MXPO | F7: MXL | G7: 900005430 | H7: TC-MESON NUEVO II | I7: 5041348 | J7: GRUPO EDIFICADOR GENESIS SA DE CV | K7: Z03 | L7: (AP) 15 Dias | M7: 10128754 | N7: GRAVA TRITURADA BASALTO 40 MM - 1 1/2" | O7: DW94 | P7: MX-CED. MICHOACAN | Q7: 20210712 | R7: 20281231 | S7: 20260401 | T7: 20301231 | U7: 220 | V7: MXN | W7: M3 | X7: 0 | Y7: MXN | Z7: M3 | AC7: 56103637 | AD7: 6644841540 | AE7: 1 | AF7: ENTREGADO | AG7: 1.47 | AH7: M3 | AI7: X | AJ7: 4 | AK7: V4 | AL7: 20260513 | AM7: DW94-900005430-10128754
A8: 900005430DW9410128742 | B8: 4600050523-10 | C8: 4600050523 | D8: 10 | E8: MXPO | F8: MXL | G8: 900005430 | H8: TC-MESON NUEVO II | I8: 5041348 | J8: GRUPO EDIFICADOR GENESIS SA DE CV | K8: Z03 | L8: (AP) 15 Dias | M8: 10128742 | N8: GRAVA TRITURADA BASALTO 20 MM - 3/4" | O8: DW94 | P8: MX-CED. MICHOACAN | Q8: 20210712 | R8: 20281231 | S8: 20260401 | T8: 20301231 | U8: 220 | V8: MXN | W8: M3 | X8: 0 | Y8: MXN | Z8: M3 | AC8: 56103637 | AD8: 6644841540 | AE8: 1 | AF8: ENTREGADO | AG8: 1.411 | AH8: M3 | AI8: X | AJ8: 4 | AK8: V4 | AL8: 20260513 | AM8: DW94-900005430-10128742
A9: 900008611DW9410220303 | B9: 4600068698-10 | C9: 4600068698 | D9: 10 | E9: MXPO | F9: MXL | G9: 900008611 | H9: SF TC-MINA GOLIAT | I9: 5092090 | J9: URDERAL COMUNIDAD DE SAN BARTOLOME | K9: Z03 | L9: (AP) 15 Dias | M9: 10220303 | N9: ARENA CLASIFICADA RÍO MALLA 4 | O9: DW94 | P9: MX-CED. MICHOACAN | Q9: 20231030 | R9: 20281231 | S9: 20250701 | T9: 20301231 | U9: 155 | V9: MXN | W9: M3 | X9: 0 | Y9: MXN | Z9: M3 | AC9: 56103638 | AD9: 6644841540 | AE9: 1 | AF9: ENTREGADO | AG9: 1.229 | AH9: M3 | AI9: X | AJ9: 4 | AK9: V4 | AL9: 20250718 | AM9: DW94-900008611-10220303
A10: 900007196DW9410202731 | B10: 4600050803-40 | C10: 4600050803 | D10: 40 | E10: MXPO | F10: MXL | G10: 900007196 | H10: SF TC-VALLE DE SANTIAGO | I10: 5009038 | J10: ARENAS Y GRAVAS DE GUANAJUATO SA DE | K10: N90 | L10: (AP) NAFIN 90 Dias | M10: 10202731 | N10: ARENA CLASIFICADA VOLCANICA MALLA 4 | O10: DW94 | P10: MX-CED. MICHOACAN | Q10: 20210715 | R10: 20261231 | S10: 20250605 | T10: 20301231 | U10: 220 | V10: MXN | W10: M3 | X10: 0 | Y10: MXN | Z10: M3 | AC10: 56103638 | AD10: 6644841540 | AE10: 1 | AF10: ENTREGADO | AG10: 1.486 | AH10: M3 | AI10: X | AJ10: 4 | AK10: V4 | AL10: 20250611 | AM10: DW94-900007196-10202731
A11: 900005675DW9410146348 | B11: 4600050537-10 | C11: 4600050537 | D11: 10 | E11: MXPO | F11: MXL | G11: 900005675 | H11: TC-VILLAMAR PLAYCON | I11: 5069613 | J11: CONSTRUCCIONES Y PROYECTOS PLAYCON | K11: N90 | L11: (AP) NAFIN 90 Dias | M11: 10146348 | N11: GRAVA TRITURADA BASALTO 10 MM - 3/8" | O11: DW94 | P11: MX-CED. MICHOACAN | Q11: 20210712 | R11: 20261231 | S11: 20220601 | T11: 20270501 | U11: 200.4 | V11: MXN | W11: M3 | X11: 0 | Y11: MXN | Z11: M3 | AC11: 56103637 | AD11: 6644841540 | AE11: 1 | AF11: ENTREGADO | AG11: 1.35 | AH11: M3 | AI11: X | AJ11: 4 | AK11: V4 | AL11: 20230920 | AM11: DW94-900005675-10146348
A12: 900005489DW9410154700 | B12: 4600050526-10 | C12: 4600050526 | D12: 10 | E12: MXPO | F12: MXL | G12: 900005489 | H12: TC-PLAYCON | I12: 5069613 | J12: CONSTRUCCIONES Y PROYECTOS PLAYCON | K12: N90 | L12: (AP) NAFIN 90 Dias | M12: 10154700 | N12: ARENA CRIBADA VOLCANICA MALLA 4 | O12: DW94 | P12: MX-CED. MICHOACAN | Q12: 20210712 | R12: 20261231 | S12: 20211001 | T12: 20261231 | U12: 140 | V12: MXN | W12: M3 | X12: 0 | Y12: MXN | Z12: M3 | AC12: 56103638 | AD12: 6644841540 | AE12: 1 | AF12: ENTREGADO | AG12: 1.415 | AH12: M3 | AI12: X | AJ12: 4 | AK12: V4 | AL12: 20230920 | AM12: DW94-900005489-10154700
A13: 900005675DW9410128752 | B13: 4600050537-20 | C13: 4600050537 | D13: 20 | E13: MXPO | F13: MXL | G13: 900005675 | H13: TC-VILLAMAR PLAYCON | I13: 5069613 | J13: CONSTRUCCIONES Y PROYECTOS PLAYCON | K13: N90 | L13: (AP) NAFIN 90 Dias | M13: 10128752 | N13: GRAVA TRITURADA BASALTO 40 MM - 1 1/2" | O13: DW94 | P13: MX-CED. MICHOACAN | Q13: 20210712 | R13: 20261231 | S13: 20220601 | T13: 20270501 | U13: 200.4 | V13: MXN | W13: M3 | X13: 0 | Y13: MXN | Z13: M3 | AC13: 56103637 | AD13: 6644841540 | AE13: 1 | AF13: ENTREGADO | AG13: 1.41 | AH13: M3 | AI13: X | AJ13: 4 | AK13: V4 | AL13: 20230920 | AM13: DW94-900005675-10128752
... A36: 900009312DW9410271129 | B36: 4600071647-10 | C36: 4600071647 | D36: 10 | E36: MXPO | F36: MXL | G36: 900009312 | H36: SF TC-NOROTO | I36: 5096796 | J36: OROZCO SANCHEZ ESTEBAN | K36: Z09 | L36: (AP) 90 Dias | M36: 10271129 | N36: MP ARENA CRIBADA VOLCANICA MALLA 4 | O36: DW94 | P36: MX-CED. MICHOACAN | Q36: 20250923 | R36: 20301231 | S36: 20250923 | T36: 20301231 | U36: 240 | V36: MXN | W36: M3 | X36: 0 | Y36: MXN | Z36: M3 | AC36: 56103638 | AD36: 6644841540 | AE36: 1 | AF36: ENTREGADO | AG36: 1.512 | AH36: M3 | AI36: X | AJ36: 4 | AK36: V4 | AL36: 20250925 | AM36: DW94-900009312-10271129
A37: 900004703DW94D32110128597 | B37: 4600050514-70 | C37: 4600050514 | D37: 70 | E37: MXPO | F37: MXL | G37: 900004703 | H37: TC-ED-EL NARANJITO | I37: 5001837 | J37: SINDICATO DE TRAB DE CRIBAS CLASIF | K37: Z03 | L37: (AP) 15 Dias | M37: 10128597 | N37: GRAVA TRITURADA RIO 20 MM - 3/4" | O37: DW94 | P37: MX-CED. MICHOACAN | Q37: 20210712 | R37: 20291231 | S37: 20260617 | T37: 20301231 | U37: 575 | V37: MXN | W37: M3 | X37: 72 | Y37: MXN | Z37: M3 | AA37: D321 | AB37: PD0399 LAZARO CARDENAS 3 | AC37: 56103637 | AD37: 6644841540 | AE37: 4 | AF37: ENTREGA DIRECTA | AG37: 1.531 | AH37: M3 | AI37: X | AJ37: 4 | AK37: V4 | AL37: 20260625 | AM37: DW94-900004703-D321-10128597-4
A38: 900004703DW94D32110128596 | B38: 4600050514-60 | C38: 4600050514 | D38: 60 | E38: MXPO | F38: MXL | G38: 900004703 | H38: TC-ED-EL NARANJITO | I38: 5001837 | J38: SINDICATO DE TRAB DE CRIBAS CLASIF | K38: Z03 | L38: (AP) 15 Dias | M38: 10128596 | N38: GRAVA TRITURADA RIO 10 MM - 3/8" | O38: DW94 | P38: MX-CED. MICHOACAN | Q38: 20210712 | R38: 20291231 | S38: 20260617 | T38: 20301231 | U38: 697 | V38: MXN | W38: M3 | X38: 72 | Y38: MXN | Z38: M3 | AA38: D321 | AB38: PD0399 LAZARO CARDENAS 3 | AC38: 56103637 | AD38: 6644841540 | AE38: 4 | AF38: ENTREGA DIRECTA | AG38: 1.49 | AH38: M3 | AI38: X | AJ38: 4 | AK38: V4 | AL38: 20260625 | AM38: DW94-900004703-D321-10128596-4
A39: 900004703DW94D32110128598 | B39: 4600050514-80 | C39: 4600050514 | D39: 80 | E39: MXPO | F39: MXL | G39: 900004703 | H39: TC-ED-EL NARANJITO | I39: 5001837 | J39: SINDICATO DE TRAB DE CRIBAS CLASIF | K39: Z03 | L39: (AP) 15 Dias | M39: 10128598 | N39: GRAVA TRITURADA RIO 40 MM - 1 1/2" | O39: DW94 | P39: MX-CED. MICHOACAN | Q39: 20210712 | R39: 20291231 | S39: 20260617 | T39: 20301231 | U39: 543 | V39: MXN | W39: M3 | X39: 72 | Y39: MXN | Z39: M3 | AA39: D321 | AB39: PD0399 LAZARO CARDENAS 3 | AC39: 56103637 | AD39: 6644841540 | AE39: 4 | AF39: ENTREGA DIRECTA | AG39: 1.55 | AH39: M3 | AI39: X | AJ39: 4 | AK39: V4 | AL39: 20260625 | AM39: DW94-900004703-D321-10128598-4
A40: 900004703DW94D32110128595 | B40: 4600050514-50 | C40: 4600050514 | D40: 50 | E40: MXPO | F40: MXL | G40: 900004703 | H40: TC-ED-EL NARANJITO | I40: 5001837 | J40: SINDICATO DE TRAB DE CRIBAS CLASIF | K40: Z03 | L40: (AP) 15 Dias | M40: 10128595 | N40: ARENA CLASIFICADA RIO MALLA 4 | O40: DW94 | P40: MX-CED. MICHOACAN | Q40: 20210712 | R40: 20291231 | S40: 20260617 | T40: 20301231 | U40: 575 | V40: MXN | W40: M3 | X40: 72 | Y40: MXN | Z40: M3 | AA40: D321 | AB40: PD0399 LAZARO CARDENAS 3 | AC40: 56103638 | AD40: 6644841540 | AE40: 4 | AF40: ENTREGA DIRECTA | AG40: 1.575 | AH40: M3 | AI40: X | AJ40: 4 | AK40: V4 | AL40: 20260625 | AM40: DW94-900004703-D321-10128595-4
A41: 900004703DW94D68010128598 | B41: 4600050514-10 | C41: 4600050514 | D41: 10 | E41: MXPO | F41: MXL | G41: 900004703 | H41: TC-ED-EL NARANJITO | I41: 5001837 | J41: SINDICATO DE TRAB DE CRIBAS CLASIF | K41: Z03 | L41: (AP) 15 Dias | M41: 10128598 | N41: GRAVA TRITURADA RIO 40 MM - 1 1/2" | O41: DW94 | P41: MX-CED. MICHOACAN | Q41: 20210712 | R41: 20291231 | S41: 20260102 | T41: 20311231 | U41: 498 | V41: MXN | W41: M3 | X41: 238.49 | Y41: MXN | Z41: M3 | AA41: D680 | AB41: PD0626 LAZARO CARDENAS 2 | AC41: 56103637 | AD41: 6644841540 | AE41: 4 | AF41: ENTREGA DIRECTA | AG41: 1.55 | AH41: M3 | AI41: X | AJ41: 4 | AK41: V4 | AL41: 20260123 | AM41: DW94-900004703-D680-10128598-4
A42: 900007669DW9410000523 | B42: 4600054461-20 | C42: 4600054461 | D42: 20 | E42: MXPO | F42: MXL | G42: 900007669 | H42: SF TC-GRAVASE VENUSTIANO CARRANZA | I42: 5009010 | J42: GRAVASE SA DE CV | K42: Z04 | L42: (AP) 30 Dias | M42: 10000523 | N42: Grava Triturada Basalto 40 mm - 1 1/2" | O42: DW94 | P42: MX-CED. MICHOACAN | Q42: 20220708 | R42: 20271231 | S42: 20260301 | T42: 20301231 | U42: 190 | V42: MXN | W42: TN | X42: 0 | Y42: MXN | Z42: TN | AC42: 56103637 | AD42: 6644841540 | AE42: 1 | AF42: ENTREGADO | AG42: 1 | AH42: TO | AI42: X | AJ42: 4 | AK42: V4 | AL42: 20260408 | AM42: DW94-900007669-10000523
A43: 900004703DW94D68010128595 | B43: 4600050514-40 | C43: 4600050514 | D43: 40 | E43: MXPO | F43: MXL | G43: 900004703 | H43: TC-ED-EL NARANJITO | I43: 5001837 | J43: SINDICATO DE TRAB DE CRIBAS CLASIF | K43: Z03 | L43: (AP) 15 Dias | M43: 10128595 | N43: ARENA CLASIFICADA RIO MALLA 4 | O43: DW94 | P43: MX-CED. MICHOACAN | Q43: 20210712 | R43: 20291231 | S43: 20260102 | T43: 20311231 | U43: 530 | V43: MXN | W43: M3 | X43: 226.16 | Y43: MXN | Z43: M3 | AA43: D680 | AB43: PD0626 LAZARO CARDENAS 2 | AC43: 56103638 | AD43: 6644841540 | AE43: 4 | AF43: ENTREGA DIRECTA | AG43: 1.575 | AH43: M3 | AI43: X | AJ43: 4 | AK43: V4 | AL43: 20260123 | AM43: DW94-900004703-D680-10128595-4
A44: 900004703DW94D68010128596 | B44: 4600050514-30 | C44: 4600050514 | D44: 30 | E44: MXPO | F44: MXL | G44: 900004703 | H44: TC-ED-EL NARANJITO | I44: 5001837 | J44: SINDICATO DE TRAB DE CRIBAS CLASIF | K44: Z03 | L44: (AP) 15 Dias | M44: 10128596 | N44: GRAVA TRITURADA RIO 10 MM - 3/8" | O44: DW94 | P44: MX-CED. MICHOACAN | Q44: 20210712 | R44: 20291231 | S44: 20260102 | T44: 20311231 | U44: 652 | V44: MXN | W44: M3 | X44: 238.89 | Y44: MXN | Z44: M3 | AA44: D680 | AB44: PD0626 LAZARO CARDENAS 2 | AC44: 56103637 | AD44: 6644841540 | AE44: 4 | AF44: ENTREGA DIRECTA | AG44: 1.49 | AH44: M3 | AI44: X | AJ44: 4 | AK44: V4 | AL44: 20260123 | AM44: DW94-900004703-D680-10128596-4
A45: 900004703DW94D68010128597 | B45: 4600050514-20 | C45: 4600050514 | D45: 20 | E45: MXPO | F45: MXL | G45: 900004703 | H45: TC-ED-EL NARANJITO | I45: 5001837 | J45: SINDICATO DE TRAB DE CRIBAS CLASIF | K45: Z03 | L45: (AP) 15 Dias | M45: 10128597 | N45: GRAVA TRITURADA RIO 20 MM - 3/4" | O45: DW94 | P45: MX-CED. MICHOACAN | Q45: 20210712 | R45: 20291231 | S45: 20260102 | T45: 20311231 | U45: 530 | V45: MXN | W45: M3 | X45: 227 | Y45: MXN | Z45: M3 | AA45: D680 | AB45: PD0626 LAZARO CARDENAS 2 | AC45: 56103637 | AD45: 6644841540 | AE45: 4 | AF45: ENTREGA DIRECTA | AG45: 1.531 | AH45: M3 | AI45: X | AJ45: 4 | AK45: V4 | AL45: 20260123 | AM45: DW94-900004703-D680-10128597-4
A46: 900007669DW9410000754 | B46: 4600054461-10 | C46: 4600054461 | D46: 10 | E46: MXPO | F46: MXL | G46: 900007669 | H46: SF TC-GRAVASE VENUSTIANO CARRANZA | I46: 5009010 | J46: GRAVASE SA DE CV | K46: Z04 | L46: (AP) 30 Dias | M46: 10000754 | N46: Grava Triturada Basalto 20 mm - 3/4" | O46: DW94 | P46: MX-CED. MICHOACAN | Q46: 20220708 | R46: 20271231 | S46: 20260301 | T46: 20301231 | U46: 185 | V46: MXN | W46: TN | X46: 0 | Y46: MXN | Z46: TN | AC46: 56103637 | AD46: 6644841540 | AE46: 1 | AF46: ENTREGADO | AG46: 1 | AH46: TO | AI46: X | AJ46: 4 | AK46: V4 | AL46: 20260408 | AM46: DW94-900007669-10000754
A47: 900005599DW9410128749 | B47: 4600050533-10 | C47: 4600050533 | D47: 10 | E47: MXPO | F47: MXL | G47: 900005599 | H47: TC-LA TAPATIA | I47: 5071134 | J47: TRITURADOS TAPATIA S DE RL DE CV | K47: Z09 | L47: (AP) 90 Dias | M47: 10128749 | N47: GRAVA TRITURADA BASALTO 20 MM - 3/4" | O47: DW94 | P47: MX-CED. MICHOACAN | Q47: 20210712 | R47: 20291231 | S47: 20250215 | T47: 20301231 | U47: 232.76 | V47: MXN | W47: M3 | X47: 0 | Y47: MXN | Z47: M3 | AC47: 56103637 | AD47: 6644841540 | AE47: 1 | AF47: ENTREGADO | AG47: 1.312 | AH47: M3 | AI47: X | AJ47: 4 | AK47: V4 | AL47: 20250325 | AM47: DW94-900005599-10128749
A48: 900005599DW9410128751 | B48: 4600050533-20 | C48: 4600050533 | D48: 20 | E48: MXPO | F48: MXL | G48: 900005599 | H48: TC-LA TAPATIA | I48: 5071134 | J48: TRITURADOS TAPATIA S DE RL DE CV | K48: Z09 | L48: (AP) 90 Dias | M48: 10128751 | N48: GRAVA TRITURADA BASALTO 40 MM - 1 1/2" | O48: DW94 | P48: MX-CED. MICHOACAN | Q48: 20210712 | R48: 20291231 | S48: 20250215 | T48: 20301231 | U48: 232.76 | V48: MXN | W48: M3 | X48: 0 | Y48: MXN | Z48: M3 | AC48: 56103637 | AD48: 6644841540 | AE48: 1 | AF48: ENTREGADO | AG48: 1.25 | AH48: M3 | AI48: X | AJ48: 4 | AK48: V4 | AL48: 20250325 | AM48: DW94-900005599-10128751
A49: 900007928DW9410154700 | B49: 4600055815-10 | C49: 4600055815 | D49: 10 | E49: MXPO | F49: MXL | G49: 900007928 | H49: SF TC-K2 MINA EL DORADO | I49: 5078977 | J49: K2 ARQUITECTONICO SA DE CV | K49: N90 | L49: (AP) NAFIN 90 Dias | M49: 10154700 | N49: ARENA CRIBADA VOLCANICA MALLA 4 | O49: DW94 | P49: MX-CED. MICHOACAN | Q49: 20220901 | R49: 20271231 | S49: 20220901 | T49: 20271231 | U49: 140 | V49: MXN | W49: M3 | X49: 0 | Y49: MXN | Z49: M3 | AC49: 56103638 | AD49: 6644841540 | AE49: 1 | AF49: ENTREGADO | AG49: 1.415 | AH49: M3 | AI49: X | AJ49: 4 | AK49: V4 | AL49: 20230920 | AM49: DW94-900007928-10154700
A50: 900007928DW9410172195 | B50: 4600055815-20 | C50: 4600055815 | D50: 20 | E50: MXPO | F50: MXL | G50: 900007928 | H50: SF TC-K2 MINA EL DORADO | I50: 5078977 | J50: K2 ARQUITECTONICO SA DE CV | K50: N90 | L50: (AP) NAFIN 90 Dias | M50: 10172195 | N50: GRAVA CRIBADA VOLCÁNICA 20 MM - 3/4" | O50: DW94 | P50: MX-CED. MICHOACAN | Q50: 20220901 | R50: 20271231 | S50: 20220901 | T50: 20271231 | U50: 122.85 | V50: MXN | W50: M3 | X50: 0 | Y50: MXN | Z50: M3 | AC50: 56103637 | AD50: 6644841540 | AE50: 1 | AF50: ENTREGADO | AG50: 1.382 | AH50: M3 | AI50: X | AJ50: 4 | AK50: V4 | AL50: 20230920 | AM50: DW94-900007928-10172195
A51: 900008004DW9410128752 | B51: 4600056258-20 | C51: 4600056258 | D51: 20 | E51: MXPO | F51: MXL | G51: 900008004 | H51: SF TC-IRMU VILLAMAR | I51: 5087486 | J51: CONSTRUCTORA Y URBANIZADORA IRMU SA | K51: N90 | L51: (AP) NAFIN 90 Dias | M51: 10128752 | N51: GRAVA TRITURADA BASALTO 40 MM - 1 1/2" | O51: DW94 | P51: MX-CED. MICHOACAN | Q51: 20230101 | R51: 20271231 | S51: 20230101 | T51: 20271231 | U51: 200.4 | V51: MXN | W51: M3 | X51: 0 | Y51: MXN | Z51: M3 | AC51: 56103637 | AD51: 6644841540 | AE51: 1 | AF51: ENTREGADO | AG51: 1.41 | AH51: M3 | AI51: X | AJ51: 4 | AK51: V4 | AL51: 20230920 | AM51: DW94-900008004-10128752
A52: 900008003DW9410172195 | B52: 4600056257-20 | C52: 4600056257 | D52: 20 | E52: MXPO | F52: MXL | G52: 900008003 | H52: SF TC-IRMU EL DORADO | I52: 5087486 | J52: CONSTRUCTORA Y URBANIZADORA IRMU SA | K52: N90 | L52: (AP) NAFIN 90 Dias | M52: 10172195 | N52: GRAVA CRIBADA VOLCÁNICA 20 MM - 3/4" | O52: DW94 | P52: MX-CED. MICHOACAN | Q52: 20230101 | R52: 20271231 | S52: 20230101 | T52: 20271231 | U52: 122.85 | V52: MXN | W52: M3 | X52: 0 | Y52: MXN | Z52: M3 | AC52: 56103637 | AD52: 6644841540 | AE52: 1 | AF52: ENTREGADO | AG52: 1.382 | AH52: M3 | AI52: X | AJ52: 4 | AK52: V4 | AL52: 20230920 | AM52: DW94-900008003-10172195
A53: 900008004DW9410128748 | B53: 4600056258-10 | C53: 4600056258 | D53: 10 | E53: MXPO | F53: MXL | G53: 900008004 | H53: SF TC-IRMU VILLAMAR | I53: 5087486 | J53: CONSTRUCTORA Y URBANIZADORA IRMU SA | K53: N90 | L53: (AP) NAFIN 90 Dias | M53: 10128748 | N53: GRAVA TRITURADA BASALTO 20 MM - 3/4" | O53: DW94 | P53: MX-CED. MICHOACAN | Q53: 20230101 | R53: 20271231 | S53: 20230101 | T53: 20271231 | U53: 200.4 | V53: MXN | W53: M3 | X53: 0 | Y53: MXN | Z53: M3 | AC53: 56103637 | AD53: 6644841540 | AE53: 1 | AF53: ENTREGADO | AG53: 1.382 | AH53: M3 | AI53: X | AJ53: 4 | AK53: V4 | AL53: 20230920 | AM53: DW94-900008004-10128748
A54: 900008004DW9410146348 | B54: 4600056258-30 | C54: 4600056258 | D54: 30 | E54: MXPO | F54: MXL | G54: 900008004 | H54: SF TC-IRMU VILLAMAR | I54: 5087486 | J54: CONSTRUCTORA Y URBANIZADORA IRMU SA | K54: N90 | L54: (AP) NAFIN 90 Dias | M54: 10146348 | N54: GRAVA TRITURADA BASALTO 10 MM - 3/8" | O54: DW94 | P54: MX-CED. MICHOACAN | Q54: 20230101 | R54: 20271231 | S54: 20230101 | T54: 20271231 | U54: 200.4 | V54: MXN | W54: M3 | X54: 0 | Y54: MXN | Z54: M3 | AC54: 56103637 | AD54: 6644841540 | AE54: 1 | AF54: ENTREGADO | AG54: 1.35 | AH54: M3 | AI54: X | AJ54: 4 | AK54: V4 | AL54: 20230920 | AM54: DW94-900008004-10146348
A55: 900007335DW9410182604 | B55: 4600052127-60 | C55: 4600052127 | D55: 60 | E55: MXPO | F55: MXL | G55: 900007335 | H55: SF TC-VILLAMAR K2 | I55: 5078977 | J55: K2 ARQUITECTONICO SA DE CV | K55: N90 | L55: (AP) NAFIN 90 Dias | M55: 10182604 | N55: GRAVA TRITURADA VOLCÁNICA 10 MM - 3/8" | O55: DW94 | P55: MX-CED. MICHOACAN | Q55: 20210901 | R55: 20261231 | S55: 20221006 | T55: 20271231 | U55: 145.2 | V55: MXN | W55: TN | X55: 0 | Y55: MXN | Z55: TN | AC55: 56103637 | AD55: 6644841540 | AE55: 1 | AF55: ENTREGADO | AG55: 1 | AH55: TO | AI55: X | AJ55: 4 | AK55: V4 | AL55: 20230920 | AM55: DW94-900007335-10182604
A56: 900001969DW9410000635 | B56: 4600050496-30 | C56: 4600050496 | D56: 30 | E56: MXPO | F56: MXL | G56: 900001969 | H56: TC-TRIMCAV | I56: 5010147 | J56: TRITURACIONES DE MARMOL Y CALCIOS | K56: Z06 | L56: (AP) 45 Dias | M56: 10000635 | N56: Arena Triturada Marmol Malla 4 | O56: DW94 | P56: MX-CED. MICHOACAN | Q56: 20210712 | R56: 20261231 | S56: 20210712 | T56: 20261231 | U56: 550 | V56: MXN | W56: TN | X56: 0 | Y56: MXN | Z56: TN | AC56: 56103638 | AD56: 6644841540 | AE56: 1 | AF56: ENTREGADO | AG56: 1 | AH56: TO | AI56: X | AJ56: 4 | AK56: V4 | AL56: 20260108 | AM56: DW94-900001969-10000635
A57: 900005489DW9410182604 | B57: 4600050526-30 | C57: 4600050526 | D57: 30 | E57: MXPO | F57: MXL | G57: 900005489 | H57: TC-PLAYCON | I57: 5069613 | J57: CONSTRUCCIONES Y PROYECTOS PLAYCON | K57: N90 | L57: (AP) NAFIN 90 Dias | M57: 10182604 | N57: GRAVA TRITURADA VOLCÁNICA 10 MM - 3/8" | O57: DW94 | P57: MX-CED. MICHOACAN | Q57: 20210712 | R57: 20261231 | S57: 20210712 | T57: 20261231 | U57: 145.2 | V57: MXN | W57: TN | X57: 0 | Y57: MXN | Z57: TN | AC57: 56103637 | AD57: 6644841540 | AE57: 1 | AF57: ENTREGADO | AG57: 1 | AH57: TO | AI57: X | AJ57: 4 | AK57: V4 | AL57: 20260108 | AM57: DW94-900005489-10182604
... A60: 900001969DW9410000643 | B60: 4600050496-20 | C60: 4600050496 | D60: 20 | E60: MXPO | F60: MXL | G60: 900001969 | H60: TC-TRIMCAV | I60: 5010147 | J60: TRITURACIONES DE MARMOL Y CALCIOS | K60: Z06 | L60: (AP) 45 Dias | M60: 10000643 | N60: Grava Triturada Marmol 20 mm - 3/4" | O60: DW94 | P60: MX-CED. MICHOACAN | Q60: 20210712 | R60: 20261231 | S60: 20210712 | T60: 20261231 | U60: 550 | V60: MXN | W60: TN | X60: 0 | Y60: MXN | Z60: TN | AC60: 56103637 | AD60: 6644841540 | AE60: 1 | AF60: ENTREGADO | AG60: 1 | AH60: TO | AI60: X | AJ60: 4 | AK60: V4 | AL60: 20260108 | AM60: DW94-900001969-10000643
A61: 900008003DW9410154700 | B61: 4600056257-10 | C61: 4600056257 | D61: 10 | E61: MXPO | F61: MXL | G61: 900008003 | H61: SF TC-IRMU EL DORADO | I61: 5087486 | J61: CONSTRUCTORA Y URBANIZADORA IRMU SA | K61: N90 | L61: (AP) NAFIN 90 Dias | M61: 10154700 | N61: ARENA CRIBADA VOLCANICA MALLA 4 | O61: DW94 | P61: MX-CED. MICHOACAN | Q61: 20230101 | R61: 20271231 | U61: 140 | V61: MXN | W61: M3 | AC61: 56103638 | AD61: 6644841540 | AE61: 1 | AF61: ENTREGADO | AG61: 1.415 | AH61: M3 | AI61: X | AJ61: 4 | AK61: V4 | AL61: 20230920 | AM61: DW94-900008003-10154700
A62: 900009526DW9410276712 | B62: 4600072250-10 | C62: 4600072250 | D62: 10 | E62: MXPO | F62: MXL | G62: 900009526 | H62: SF TC- LA GOLETA | I62: 5097962 | J62: PROYECTOS E INFRAESTRUCTURA ALVISA | K62: Z09 | L62: (AP) 90 Dias | M62: 10276712 | N62: MP GRAVA TRIT BASALTO 20 MM (3/4") | O62: DW94 | P62: MX-CED. MICHOACAN | Q62: 20260513 | R62: 20301231 | S62: 20260513 | T62: 20301231 | U62: 235 | V62: MXN | W62: M3 | X62: 0 | Y62: MXN | Z62: M3 | AC62: 56103637 | AD62: 6644841540 | AE62: 1 | AF62: ENTREGADO | AG62: 1.274 | AH62: M3 | AI62: X | AJ62: 4 | AK62: V4 | AL62: 20260520 | AM62: DW94-900009526-10276712
A63: 900009526DW9410277192 | B63: 4600072250-20 | C63: 4600072250 | D63: 20 | E63: MXPO | F63: MXL | G63: 900009526 | H63: SF TC- LA GOLETA | I63: 5097962 | J63: PROYECTOS E INFRAESTRUCTURA ALVISA | K63: Z09 | L63: (AP) 90 Dias | M63: 10277192 | N63: MP GRAVA TRIT BASALTO 40 MM (1 1/2") | O63: DW94 | P63: MX-CED. MICHOACAN | Q63: 20260513 | R63: 20301231 | S63: 20260513 | T63: 20301231 | U63: 235 | V63: MXN | W63: M3 | X63: 0 | Y63: MXN | Z63: M3 | AC63: 56103637 | AD63: 6644841540 | AE63: 1 | AF63: ENTREGADO | AG63: 1.476 | AH63: M3 | AI63: X | AJ63: 4 | AK63: V4 | AL63: 20260520 | AM63: DW94-900009526-10277192
A64: 900005459DW94D68610128748 | B64: 4600050525-20 | C64: 4600050525 | D64: 20 | E64: MXPO | F64: MXL | G64: 900005459 | H64: TC-ED-MACIAS | I64: 5005851 | J64: INFRAESTRUCTURA LOGISTICA SA DE CV | K64: N90 | L64: (AP) NAFIN 90 Dias | M64: 10128748 | N64: GRAVA TRITURADA BASALTO 20 MM - 3/4" | O64: DW94 | P64: MX-CED. MICHOACAN | Q64: 20210712 | R64: 20271231 | S64: 20221210 | T64: 20271231 | U64: 350 | V64: MXN | W64: M3 | X64: 70 | Y64: MXN | Z64: M3 | AA64: D686 | AB64: PD0653 ZAMORA | AC64: 56103637 | AD64: 6644841540 | AE64: 4 | AF64: ENTREGA DIRECTA | AG64: 1.382 | AH64: M3 | AI64: X | AJ64: 4 | AK64: V4 | AL64: 20230920 | AM64: DW94-900005459-D686-10128748-4
...
