Workbook

Sheet Base Cedis D825
N1: VENTA | Q1: COSTO
A2: CONCAT1 | B2: CONCAT2 | C2: No. SF | D2: Nombre SF | E2: Cedis | F2: Destino | G2: Condicion de Expedicion | H2: Nombre Destino | I2: No. de material | J2: Nombre de material | K2: PV | L2: Inicio de vigencia | M2: Fin de vigencia | N2: Importe MP | O2: Importe Flete | P2: UM Venta | Q2: Importe Costo | R2: UM Costo | S2: Validacion 1 | T2: Validacion 2
A3: =CONCATENATE(C3,E3,F3,I3) | B3: =CONCATENATE(C3,E3,I3) | C3: 900006668 | D3: =IFERROR(VLOOKUP(C3,TRAOPE!$G:$H,2,0),"") | E3: D825 | F3: 66356823 | G3: =IFERROR(VLOOKUP(A3,Flete!$A:$E,5,0),"") | H3: =IFERROR(VLOOKUP(F3,TRAOPE!$AA:$AB,2,0),"") | I3: 10211341 | J3: =IFERROR(VLOOKUP(I3,Materiales!$A:$H,8,0),"") | K3: =IFERROR(VLOOKUP(I3,Materiales!$A:$G,7,0),"") | L3: 20230628 | M3: 20240507 | N3: 367.5 | O3: =IFERROR(VLOOKUP(A3,Flete!$A:$J,10,0),"") | P3: M3 | Q3: =IFERROR(IFERROR(VLOOKUP(A3,TRAOPE!$A:$U,21,0),VLOOKUP(B3,TRAOPE!$A:$U,21,0)),"") | R3: =IFERROR(IFERROR(VLOOKUP(A3,TRAOPE!$A:$W,23,0),VLOOKUP(B3,TRAOPE!$A:$W,23,0)),"") | S3: =IF(AND(P3="TN",R3="TN"),N3+N(O3),IF(G3&""="1",N(K3)*N3,(N3+N(O3))*N(K3))) | T3: =IF(Q3="","",Q3-S3)
A4: =CONCATENATE(C4,E4,F4,I4) | B4: =CONCATENATE(C4,E4,I4) | C4: 900006668 | D4: =IFERROR(VLOOKUP(C4,TRAOPE!$G:$H,2,0),"") | E4: D825 | F4: 67093770 | G4: =IFERROR(VLOOKUP(A4,Flete!$A:$E,5,0),"") | H4: =IFERROR(VLOOKUP(F4,TRAOPE!$AA:$AB,2,0),"") | I4: 10179731 | J4: =IFERROR(VLOOKUP(I4,Materiales!$A:$H,8,0),"") | K4: =IFERROR(VLOOKUP(I4,Materiales!$A:$G,7,0),"") | L4: 20221031 | M4: 20240507 | N4: 195 | O4: =IFERROR(VLOOKUP(A4,Flete!$A:$J,10,0),"") | P4: M3 | Q4: =IFERROR(IFERROR(VLOOKUP(A4,TRAOPE!$A:$U,21,0),VLOOKUP(B4,TRAOPE!$A:$U,21,0)),"") | R4: =IFERROR(IFERROR(VLOOKUP(A4,TRAOPE!$A:$W,23,0),VLOOKUP(B4,TRAOPE!$A:$W,23,0)),"") | S4: =IF(AND(P4="TN",R4="TN"),N4+N(O4),IF(G4&""="1",N(K4)*N4,(N4+N(O4))*N(K4))) | T4: =IF(Q4="","",Q4-S4)
A5: =CONCATENATE(C5,E5,F5,I5) | B5: =CONCATENATE(C5,E5,I5) | C5: 900006668 | D5: =IFERROR(VLOOKUP(C5,TRAOPE!$G:$H,2,0),"") | E5: D825 | F5: 67093770 | G5: =IFERROR(VLOOKUP(A5,Flete!$A:$E,5,0),"") | H5: =IFERROR(VLOOKUP(F5,TRAOPE!$AA:$AB,2,0),"") | I5: 10211341 | J5: =IFERROR(VLOOKUP(I5,Materiales!$A:$H,8,0),"") | K5: =IFERROR(VLOOKUP(I5,Materiales!$A:$G,7,0),"") | L5: 20221031 | M5: 20240507 | N5: 335 | O5: =IFERROR(VLOOKUP(A5,Flete!$A:$J,10,0),"") | P5: M3 | Q5: =IFERROR(IFERROR(VLOOKUP(A5,TRAOPE!$A:$U,21,0),VLOOKUP(B5,TRAOPE!$A:$U,21,0)),"") | R5: =IFERROR(IFERROR(VLOOKUP(A5,TRAOPE!$A:$W,23,0),VLOOKUP(B5,TRAOPE!$A:$W,23,0)),"") | S5: =IF(AND(P5="TN",R5="TN"),N5+N(O5),IF(G5&""="1",N(K5)*N5,(N5+N(O5))*N(K5))) | T5: =IF(Q5="","",Q5-S5)
A6: =CONCATENATE(C6,E6,F6,I6) | B6: =CONCATENATE(C6,E6,I6) | C6: 900007749 | D6: =IFERROR(VLOOKUP(C6,TRAOPE!$G:$H,2,0),"") | E6: D825 | F6: 67122724 | G6: =IFERROR(VLOOKUP(A6,Flete!$A:$E,5,0),"") | H6: =IFERROR(VLOOKUP(F6,TRAOPE!$AA:$AB,2,0),"") | I6: 10210657 | J6: =IFERROR(VLOOKUP(I6,Materiales!$A:$H,8,0),"") | K6: =IFERROR(VLOOKUP(I6,Materiales!$A:$G,7,0),"") | L6: 20221027 | M6: 20240507 | N6: 365 | O6: =IFERROR(VLOOKUP(A6,Flete!$A:$J,10,0),"") | P6: M3 | Q6: =IFERROR(IFERROR(VLOOKUP(A6,TRAOPE!$A:$U,21,0),VLOOKUP(B6,TRAOPE!$A:$U,21,0)),"") | R6: =IFERROR(IFERROR(VLOOKUP(A6,TRAOPE!$A:$W,23,0),VLOOKUP(B6,TRAOPE!$A:$W,23,0)),"") | S6: =IF(AND(P6="TN",R6="TN"),N6+N(O6),IF(G6&""="1",N(K6)*N6,(N6+N(O6))*N(K6))) | T6: =IF(Q6="","",Q6-S6)
A7: =CONCATENATE(C7,E7,F7,I7) | B7: =CONCATENATE(C7,E7,I7) | C7: 900000651 | D7: =IFERROR(VLOOKUP(C7,TRAOPE!$G:$H,2,0),"") | E7: D825 | F7: 66948640 | G7: =IFERROR(VLOOKUP(A7,Flete!$A:$E,5,0),"") | H7: =IFERROR(VLOOKUP(F7,TRAOPE!$AA:$AB,2,0),"") | I7: 10052400 | J7: =IFERROR(VLOOKUP(I7,Materiales!$A:$H,8,0),"") | K7: =IFERROR(VLOOKUP(I7,Materiales!$A:$G,7,0),"") | L7: 20221109 | M7: 20251031 | N7: 296.53 | O7: =IFERROR(VLOOKUP(A7,Flete!$A:$J,10,0),"") | P7: TN | Q7: =IFERROR(IFERROR(VLOOKUP(A7,TRAOPE!$A:$U,21,0),VLOOKUP(B7,TRAOPE!$A:$U,21,0)),"") | R7: =IFERROR(IFERROR(VLOOKUP(A7,TRAOPE!$A:$W,23,0),VLOOKUP(B7,TRAOPE!$A:$W,23,0)),"") | S7: =IF(AND(P7="TN",R7="TN"),N7+N(O7),IF(G7&""="1",N(K7)*N7,(N7+N(O7))*N(K7))) | T7: =IF(Q7="","",Q7-S7)
A8: =CONCATENATE(C8,E8,F8,I8) | B8: =CONCATENATE(C8,E8,I8) | C8: 900000651 | D8: =IFERROR(VLOOKUP(C8,TRAOPE!$G:$H,2,0),"") | E8: D825 | F8: 67089986 | G8: =IFERROR(VLOOKUP(A8,Flete!$A:$E,5,0),"") | H8: =IFERROR(VLOOKUP(F8,TRAOPE!$AA:$AB,2,0),"") | I8: 10001078 | J8: =IFERROR(VLOOKUP(I8,Materiales!$A:$H,8,0),"") | K8: =IFERROR(VLOOKUP(I8,Materiales!$A:$G,7,0),"") | L8: 20221109 | M8: 20251031 | N8: 60 | O8: =IFERROR(VLOOKUP(A8,Flete!$A:$J,10,0),"") | P8: M3 | Q8: =IFERROR(IFERROR(VLOOKUP(A8,TRAOPE!$A:$U,21,0),VLOOKUP(B8,TRAOPE!$A:$U,21,0)),"") | R8: =IFERROR(IFERROR(VLOOKUP(A8,TRAOPE!$A:$W,23,0),VLOOKUP(B8,TRAOPE!$A:$W,23,0)),"") | S8: =IF(AND(P8="TN",R8="TN"),N8+N(O8),IF(G8&""="1",N(K8)*N8,(N8+N(O8))*N(K8))) | T8: =IF(Q8="","",Q8-S8)
A9: =CONCATENATE(C9,E9,F9,I9) | B9: =CONCATENATE(C9,E9,I9) | C9: 900004527 | D9: =IFERROR(VLOOKUP(C9,TRAOPE!$G:$H,2,0),"") | E9: D825 | F9: 66273342 | G9: =IFERROR(VLOOKUP(A9,Flete!$A:$E,5,0),"") | H9: =IFERROR(VLOOKUP(F9,TRAOPE!$AA:$AB,2,0),"") | I9: 10125120 | J9: =IFERROR(VLOOKUP(I9,Materiales!$A:$H,8,0),"") | K9: =IFERROR(VLOOKUP(I9,Materiales!$A:$G,7,0),"") | L9: 20221109 | M9: 20251031 | N9: 265 | O9: =IFERROR(VLOOKUP(A9,Flete!$A:$J,10,0),"") | P9: M3 | Q9: =IFERROR(IFERROR(VLOOKUP(A9,TRAOPE!$A:$U,21,0),VLOOKUP(B9,TRAOPE!$A:$U,21,0)),"") | R9: =IFERROR(IFERROR(VLOOKUP(A9,TRAOPE!$A:$W,23,0),VLOOKUP(B9,TRAOPE!$A:$W,23,0)),"") | S9: =IF(AND(P9="TN",R9="TN"),N9+N(O9),IF(G9&""="1",N(K9)*N9,(N9+N(O9))*N(K9))) | T9: =IF(Q9="","",Q9-S9)
A10: =CONCATENATE(C10,E10,F10,I10) | B10: =CONCATENATE(C10,E10,I10) | C10: 900004527 | D10: =IFERROR(VLOOKUP(C10,TRAOPE!$G:$H,2,0),"") | E10: D825 | F10: 66650126 | G10: =IFERROR(VLOOKUP(A10,Flete!$A:$E,5,0),"") | H10: =IFERROR(VLOOKUP(F10,TRAOPE!$AA:$AB,2,0),"") | I10: 10125120 | J10: =IFERROR(VLOOKUP(I10,Materiales!$A:$H,8,0),"") | K10: =IFERROR(VLOOKUP(I10,Materiales!$A:$G,7,0),"") | L10: 20221109 | M10: 20251031 | N10: 180.87 | O10: =IFERROR(VLOOKUP(A10,Flete!$A:$J,10,0),"") | P10: TN | Q10: =IFERROR(IFERROR(VLOOKUP(A10,TRAOPE!$A:$U,21,0),VLOOKUP(B10,TRAOPE!$A:$U,21,0)),"") | R10: =IFERROR(IFERROR(VLOOKUP(A10,TRAOPE!$A:$W,23,0),VLOOKUP(B10,TRAOPE!$A:$W,23,0)),"") | S10: =IF(AND(P10="TN",R10="TN"),N10+N(O10),IF(G10&""="1",N(K10)*N10,(N10+N(O10))*N(K10))) | T10: =IF(Q10="","",Q10-S10)
A11: =CONCATENATE(C11,E11,F11,I11) | B11: =CONCATENATE(C11,E11,I11) | C11: 900004527 | D11: =IFERROR(VLOOKUP(C11,TRAOPE!$G:$H,2,0),"") | E11: D825 | F11: 66650126 | G11: =IFERROR(VLOOKUP(A11,Flete!$A:$E,5,0),"") | H11: =IFERROR(VLOOKUP(F11,TRAOPE!$AA:$AB,2,0),"") | I11: 10137462 | J11: =IFERROR(VLOOKUP(I11,Materiales!$A:$H,8,0),"") | K11: =IFERROR(VLOOKUP(I11,Materiales!$A:$G,7,0),"") | L11: 20221109 | M11: 20251031 | N11: 236.46 | O11: =IFERROR(VLOOKUP(A11,Flete!$A:$J,10,0),"") | P11: TN | Q11: =IFERROR(IFERROR(VLOOKUP(A11,TRAOPE!$A:$U,21,0),VLOOKUP(B11,TRAOPE!$A:$U,21,0)),"") | R11: =IFERROR(IFERROR(VLOOKUP(A11,TRAOPE!$A:$W,23,0),VLOOKUP(B11,TRAOPE!$A:$W,23,0)),"") | S11: =IF(AND(P11="TN",R11="TN"),N11+N(O11),IF(G11&""="1",N(K11)*N11,(N11+N(O11))*N(K11))) | T11: =IF(Q11="","",Q11-S11)
A12: =CONCATENATE(C12,E12,F12,I12) | B12: =CONCATENATE(C12,E12,I12) | C12: 900004527 | D12: =IFERROR(VLOOKUP(C12,TRAOPE!$G:$H,2,0),"") | E12: D825 | F12: 66650242 | G12: =IFERROR(VLOOKUP(A12,Flete!$A:$E,5,0),"") | H12: =IFERROR(VLOOKUP(F12,TRAOPE!$AA:$AB,2,0),"") | I12: 10137462 | J12: =IFERROR(VLOOKUP(I12,Materiales!$A:$H,8,0),"") | K12: =IFERROR(VLOOKUP(I12,Materiales!$A:$G,7,0),"") | L12: 20221109 | M12: 20251031 | N12: 323.95 | O12: =IFERROR(VLOOKUP(A12,Flete!$A:$J,10,0),"") | P12: M3 | Q12: =IFERROR(IFERROR(VLOOKUP(A12,TRAOPE!$A:$U,21,0),VLOOKUP(B12,TRAOPE!$A:$U,21,0)),"") | R12: =IFERROR(IFERROR(VLOOKUP(A12,TRAOPE!$A:$W,23,0),VLOOKUP(B12,TRAOPE!$A:$W,23,0)),"") | S12: =IF(AND(P12="TN",R12="TN"),N12+N(O12),IF(G12&""="1",N(K12)*N12,(N12+N(O12))*N(K12))) | T12: =IF(Q12="","",Q12-S12)
A13: =CONCATENATE(C13,E13,F13,I13) | B13: =CONCATENATE(C13,E13,I13) | C13: 900004527 | D13: =IFERROR(VLOOKUP(C13,TRAOPE!$G:$H,2,0),"") | E13: D825 | F13: 66650326 | G13: =IFERROR(VLOOKUP(A13,Flete!$A:$E,5,0),"") | H13: =IFERROR(VLOOKUP(F13,TRAOPE!$AA:$AB,2,0),"") | I13: 10137462 | J13: =IFERROR(VLOOKUP(I13,Materiales!$A:$H,8,0),"") | K13: =IFERROR(VLOOKUP(I13,Materiales!$A:$G,7,0),"") | L13: 20221109 | M13: 20251031 | N13: 324.25 | O13: =IFERROR(VLOOKUP(A13,Flete!$A:$J,10,0),"") | P13: M3 | Q13: =IFERROR(IFERROR(VLOOKUP(A13,TRAOPE!$A:$U,21,0),VLOOKUP(B13,TRAOPE!$A:$U,21,0)),"") | R13: =IFERROR(IFERROR(VLOOKUP(A13,TRAOPE!$A:$W,23,0),VLOOKUP(B13,TRAOPE!$A:$W,23,0)),"") | S13: =IF(AND(P13="TN",R13="TN"),N13+N(O13),IF(G13&""="1",N(K13)*N13,(N13+N(O13))*N(K13))) | T13: =IF(Q13="","",Q13-S13)
A14: =CONCATENATE(C14,E14,F14,I14) | B14: =CONCATENATE(C14,E14,I14) | C14: 900004527 | D14: =IFERROR(VLOOKUP(C14,TRAOPE!$G:$H,2,0),"") | E14: D825 | F14: 66650366 | G14: =IFERROR(VLOOKUP(A14,Flete!$A:$E,5,0),"") | H14: =IFERROR(VLOOKUP(F14,TRAOPE!$AA:$AB,2,0),"") | I14: 10165992 | J14: =IFERROR(VLOOKUP(I14,Materiales!$A:$H,8,0),"") | K14: =IFERROR(VLOOKUP(I14,Materiales!$A:$G,7,0),"") | L14: 20221109 | M14: 20251031 | N14: 259.99 | O14: =IFERROR(VLOOKUP(A14,Flete!$A:$J,10,0),"") | P14: M3 | Q14: =IFERROR(IFERROR(VLOOKUP(A14,TRAOPE!$A:$U,21,0),VLOOKUP(B14,TRAOPE!$A:$U,21,0)),"") | R14: =IFERROR(IFERROR(VLOOKUP(A14,TRAOPE!$A:$W,23,0),VLOOKUP(B14,TRAOPE!$A:$W,23,0)),"") | S14: =IF(AND(P14="TN",R14="TN"),N14+N(O14),IF(G14&""="1",N(K14)*N14,(N14+N(O14))*N(K14))) | T14: =IF(Q14="","",Q14-S14)
... A398: =CONCATENATE(C398,E398,F398,I398) | B398: =CONCATENATE(C398,E398,I398) | C398: 900007937 | D398: =IFERROR(VLOOKUP(C398,TRAOPE!$G:$H,2,0),"") | E398: D825 | F398: 67076920 | G398: =IFERROR(VLOOKUP(A398,Flete!$A:$E,5,0),"") | H398: =IFERROR(VLOOKUP(F398,TRAOPE!$AA:$AB,2,0),"") | I398: 10211341 | J398: =IFERROR(VLOOKUP(I398,Materiales!$A:$H,8,0),"") | K398: =IFERROR(VLOOKUP(I398,Materiales!$A:$G,7,0),"") | L398: 20220708 | M398: 20251031 | N398: 442 | O398: =IFERROR(VLOOKUP(A398,Flete!$A:$J,10,0),"") | P398: M3 | Q398: =IFERROR(IFERROR(VLOOKUP(A398,TRAOPE!$A:$U,21,0),VLOOKUP(B398,TRAOPE!$A:$U,21,0)),"") | R398: =IFERROR(IFERROR(VLOOKUP(A398,TRAOPE!$A:$W,23,0),VLOOKUP(B398,TRAOPE!$A:$W,23,0)),"") | S398: =IF(AND(P398="TN",R398="TN"),N398+N(O398),IF(G398&""="1",N(K398)*N398,(N398+N(O398))*N(K398))) | T398: =IF(Q398="","",Q398-S398)

Sheet MP
A1: No. SF | B1: Cedis | C1: Destino | D1: No. Material | E1: Nombre Material | F1: Importe MP | G1: Moneda | H1: Cantidad | I1: UM | J1: C | K1: Inicio Vigencia | L1: Fin Vigencia
A2: 900006668 | B2: D825 | C2: 66356823 | D2: 10211341 | F2: 367.5 | I2: M3 | K2: 20230628 | L2: 20240507
A3: 900006668 | B3: D825 | C3: 67093770 | D3: 10179731 | F3: 195 | I3: M3 | K3: 20221031 | L3: 20240507
A4: 900006668 | B4: D825 | C4: 67093770 | D4: 10211341 | F4: 335 | I4: M3 | K4: 20221031 | L4: 20240507
A5: 900007749 | B5: D825 | C5: 67122724 | D5: 10210657 | F5: 365 | I5: M3 | K5: 20221027 | L5: 20240507
A6: 900000651 | B6: D825 | C6: 66948640 | D6: 10052400 | F6: 296.53 | I6: TN | K6: 20221109 | L6: 20251031
A7: 900000651 | B7: D825 | C7: 67089986 | D7: 10001078 | F7: 60 | I7: M3 | K7: 20221109 | L7: 20251031
A8: 900004527 | B8: D825 | C8: 66273342 | D8: 10125120 | F8: 265 | I8: M3 | K8: 20221109 | L8: 20251031
A9: 900004527 | B9: D825 | C9: 66650126 | D9: 10125120 | F9: 180.87 | I9: TN | K9: 20221109 | L9: 20251031
A10: 900004527 | B10: D825 | C10: 66650126 | D10: 10137462 | F10: 236.46 | I10: TN | K10: 20221109 | L10: 20251031
A11: 900004527 | B11: D825 | C11: 66650242 | D11: 10137462 | F11: 323.95 | I11: M3 | K11: 20221109 | L11: 20251031
A12: 900004527 | B12: D825 | C12: 66650326 | D12: 10137462 | F12: 324.25 | I12: M3 | K12: 20221109 | L12: 20251031
A13: 900004527 | B13: D825 | C13: 66650366 | D13: 10165992 | F13: 259.99 | I13: M3 | K13: 20221109 | L13: 20251031
... A397: 900007937 | B397: D825 | C397: 67076920 | D397: 10211341 | F397: 442 | I397: M3 | K397: 20220708 | L397: 20251031

Sheet Flete
A1: Concat1 | B1: No. SF | C1: Cedis | D1: Destino | E1: Cond. Exp. | F1: Material | H1: Nombre Material | J1: Importe Flete | K1: Moneda | L1: Cantidad | M1: UM | N1: C | P1: Inicio Vigencia | Q1: Fin Vigencia
A2: 900001046D8256534030010000354 | B2: 900001046 | C2: D825 | D2: 65340300 | E2: 1 | F2: 10000354 | J2: 37.24 | M2: TN | P2: 20150101 | Q2: 99991231
A3: 900001046D8256534030110000354 | B3: 900001046 | C3: D825 | D3: 65340301 | E3: 1 | F3: 10000354 | J3: 13.79 | M3: TN | P3: 20150101 | Q3: 99991231
A4: 900001046D8256540828310000354 | B4: 900001046 | C4: D825 | D4: 65408283 | E4: 1 | F4: 10000354 | J4: 51.73 | M4: M3 | P4: 20150101 | Q4: 99991231
A5: 900001046D8256596943810000354 | B5: 900001046 | C5: D825 | D5: 65969438 | E5: 1 | F5: 10000354 | J5: 45 | M5: M3 | P5: 20150301 | Q5: 99991231
A6: 900004527D8256538137810110794 | B6: 900004527 | C6: D825 | D6: 65381378 | E6: 1 | F6: 10110794 | J6: 90.09 | M6: M3 | P6: 20170210 | Q6: 99991231
A7: 900004527D8256665012610125120 | B7: 900004527 | C7: D825 | D7: 66650126 | E7: 1 | F7: 10125120 | J7: 53.3 | M7: TN | P7: 20210424 | Q7: 99991231
A8: 900004527D8256665012610137462 | B8: 900004527 | C8: D825 | D8: 66650126 | E8: 1 | F8: 10137462 | J8: 53.3 | M8: TN | P8: 20210424 | Q8: 99991231
A9: 900004527D8256665024210137462 | B9: 900004527 | C9: D825 | D9: 66650242 | E9: 1 | F9: 10137462 | J9: 98.01 | M9: M3 | P9: 20210424 | Q9: 99991231
A10: 900004527D8256665032610137462 | B10: 900004527 | C10: D825 | D10: 66650326 | E10: 1 | F10: 10137462 | J10: 52.39 | M10: M3 | P10: 20210424 | Q10: 99991231
A11: 900004527D8256665069610188311 | B11: 900004527 | C11: D825 | D11: 66650696 | E11: 1 | F11: 10188311 | J11: 66.17 | M11: M3 | P11: 20210424 | Q11: 99991231
A12: 900004527D8256665524310110794 | B12: 900004527 | C12: D825 | D12: 66655243 | E12: 1 | F12: 10110794 | J12: 36.26 | M12: M3 | P12: 20210424 | Q12: 99991231
A13: 900004527D8256665524310137462 | B13: 900004527 | C13: D825 | D13: 66655243 | E13: 1 | F13: 10137462 | J13: 42.32 | M13: M3 | P13: 20210424 | Q13: 99991231
... A181: 900007936D8256722980710139747 | B181: 900007936 | C181: D825 | D181: 67229807 | E181: 1 | F181: 10139747 | J181: 419.62 | M181: M3 | P181: 20240423 | Q181: 99991231

Sheet Materiales
A1: Material | B1: TpMt | C1: Denom | D1: UMA | E1: Contador | F1: UMB | G1: PV | H1: Nombre Material
A2: 10000001 | B2: ZFER | C2: 1000 | D2: M3 | E2: 1000 | F2: TN | G2: 1262 | H2: GRAVA ANDESITA 10 MM (3/8")
A3: 10000003 | B3: ZFER | C3: 1000 | D3: M3 | E3: 1000 | F3: TN | G3: 1443 | H3: GRAVA CALIZA 10 MM (3/8")
A4: 10000006 | B4: ZFER | C4: 1000 | D4: M3 | E4: 1000 | F4: TN | G4: 1490 | H4: GRAVA RIO 10 MM (3/8")
A5: 10000007 | B5: ZFER | C5: 1000 | D5: M3 | E5: 1000 | F5: TN | G5: 1488 | H5: GRAVA BASALTO 13 MM (1/2")
A6: 10000008 | B6: ZFER | C6: 1000 | D6: M3 | E6: 1000 | F6: TN | G6: 1358 | H6: GRAVA CALIZA 13 MM (1/2")
A7: 10000011 | B7: ZFER | C7: 1000 | D7: M3 | E7: 1000 | F7: TN | G7: 1323 | H7: GRAVA ANDESITA 20 MM (3/4")
A8: 10000013 | B8: ZFER | C8: 1000 | D8: M3 | E8: 1000 | F8: TN | G8: 1514 | H8: GRAVA BASALTO 20 MM (3/4")
A9: 10000014 | B9: ZFER | C9: 1000 | D9: M3 | E9: 1000 | F9: TN | G9: 1400 | H9: GRAVA CALIZA 20 MM (3/4")
A10: 10000015 | B10: ZFER | C10: 1000 | D10: M3 | E10: 1000 | F10: TN | G10: 1410 | H10: GRAVA GRANITO 20 MM (3/4")
A11: 10000017 | B11: ZFER | C11: 1000 | D11: M3 | E11: 1000 | F11: TN | G11: 1475 | H11: GRAVA RIOLITA 20 MM (3/4")
A12: 10000019 | B12: ZFER | C12: 1000 | D12: M3 | E12: 1000 | F12: TN | G12: 1515 | H12: GRAVA RIO 20 MM (3/4")
A13: 10000020 | B13: ZFER | C13: 1000 | D13: M3 | E13: 1 | F13: TN | G13: 1 | H13: GRAVA MAQUILA 40MM (1 1/2")
... A2291: 10268770 | B2291: ZFE3 | C2291: 1000 | D2291: M3 | E2291: 1000 | F2291: TN | G2291: 1240 | H2291: MP GRAVA TRIT CALIZA 40MM 1 1/2" - ESP
A2292: 10268901 | B2292: ZFE3 | C2292: 1000 | D2292: M3 | E2292: 1000 | G2292: 1560 | H2292: MP GRAVA ANDESITA GRIS 3/4" - CAPADA
A2293: 10267983 | C2293: 1000 | G2293: 1800 | H2293: ESCORIA ALTO HORNO 3/4
A2294: 10268996 | C2294: 1000 | G2294: 1329 | H2294: GRAVA TRITURADA CALIZA 40 MM - 11/2"
A2295: 10269072 | C2295: 1000 | G2295: 1700 | H2295: BASE HIDRÁULICA SCREEN
A2296: 10269225 | B2296: ZFE3 | C2296: 1000 | D2296: M3 | E2296: 1000 | G2296: 1289 | H2296: MP ARENA CALIZA LAVADA MALLA 4 - DELTA I
A2297: 10269245 | B2297: ZFE3 | C2297: 1000 | D2297: M3 | E2297: 1000 | G2297: 1410 | H2297: MP GRAVA TRITURADA CALIZA 3/8 - 10MM
A2298: 10269246 | B2298: ZFE3 | C2298: 1000 | D2298: M3 | E2298: 1000 | G2298: 1400 | H2298: MP GRAVA TRITURADA CALIZA 1 1/2 - 40MM
A2299: 10269247 | B2299: ZFE3 | C2299: 1000 | D2299: M3 | E2299: 1000 | G2299: 1560 | H2299: MP ARENA TRIT CALIZA M-4
A2300: 10270431 | B2300: ZFE3 | C2300: 1000 | D2300: M3 | E2300: 1000 | G2300: 1423 | H2300: MP GRAVA RIOLITA 13 MM - 1/2"
A2301: 10270898 | B2301: ZFE3 | C2301: 1000 | D2301: M3 | E2301: 1000 | G2301: 1551 | H2301: MP BASE H. TRIT. BASALTO 1 1/2" A FINOS
A2302: 10270911 | B2302: ZFE3 | C2302: 1000 | D2302: M3 | E2302: 1000 | G2302: 1360 | H2302: MP GRAVA TRIT. BASALTO 40 MM - 1 1/2"
A2303: 10270912 | B2303: ZFE3 | C2303: 1000 | D2303: M3 | E2303: 1000 | G2303: 1589 | H2303: MP ARENA TRIT. BASALTO MALLA 4
A2304: 10270913 | B2304: ZFE3 | C2304: 1000 | D2304: M3 | E2304: 1000 | G2304: 1395 | H2304: MP GRAVA TRIT. BASALTO 20 MM - 3/4
A2305: 10270914 | B2305: ZFE3 | C2305: 1000 | D2305: M3 | E2305: 1000 | G2305: 1623 | H2305: MP ARENA ANDESITA BC
A2306: 10270824 | B2306: M3 | C2306: 1000 | D2306: M3 | E2306: 10007640 | G2306: 1325 | H2306: MP ARENA TRITURADA CALIZA MALLA 5
A2307: 10270825 | B2307: M3 | C2307: 1000 | D2307: M3 | E2307: 10000003 | G2307: 1242 | H2307: MP GRAVA TRITURADA CALIZA 10MM (3/8”)
... A2319: 10272527 | B2319: ZFE3 | C2319: 1000 | D2319: M3 | E2319: 1000 | G2319: 1620 | H2319: CNC - NO CLASIFICADO
A2320: 10000332 | C2320: 1000 | D2320: M3 | E2320: 1000 | G2320: 800 | H2320: Grava Triturada Pomez - Jal 20 mm - 3/4"
A2321: 10273001 | B2321: ZFE3 | C2321: 1000 | D2321: M3 | E2321: 1000 | G2321: 1688 | H2321: MP ARENA TRIT. BASALTO MALLA 4
A2322: 10273002 | B2322: ZFE3 | C2322: 1000 | D2322: M3 | E2322: 1000 | G2322: 1466 | H2322: MP GRAVA TRIT. BASALTO 20 MM - 3/4"
A2323: 10273351 | B2323: ZFE3 | C2323: 1000 | D2323: M3 | E2323: 1000 | G2323: 1612 | H2323: MP ARENA TRIT. CALIZA MALLA 4
A2324: 10273352 | B2324: ZFE3 | C2324: 1000 | D2324: M3 | E2324: 1000 | G2324: 1492 | H2324: MP GRAVA TRIT. CALIZA 20 MM - 3/4"
A2325: 10271724 | B2325: ZFE3 | C2325: 1000 | D2325: M3 | E2325: 1000 | G2325: 1900 | H2325: MP RESIDUO DE CONCRETO
A2326: 10000677 | C2326: 1000 | D2326: M3 | G2326: 1164 | H2326: Grava Triturada Caliza 20 mm - 3/4"
A2327: 10274190 | B2327: ZFE3 | C2327: 1000 | D2327: M3 | E2327: 1000 | G2327: 1800 | H2327: MP BASE HIDRAULICA ANDESITA 70-30
A2328: 10274601 | B2328: ZFE3 | C2328: 1000 | D2328: M3 | E2328: 1000 | G2328: 1447 | H2328: MP ARENA BASALTO N° 4
...

Sheet TRAOPE
A1: Concat1 | B1: Contrato_Pos | C1: Doc. Compras | D1: Pos | E1: Org.compras | F1: Grp-Compr. | G1: Ship From | H1: Nombre SF | I1: Proveedor | J1: Nombre Prov | K1: Cond. Pago | L1: Descr. Cond Pago | M1: Material | N1: Descripción | O1: Centro | P1: Descripción Centro | Q1: In.perído validez | R1: Fin perído validez | S1: Válido de | T1: Validez a | U1: Precio neto pedido | V1: Moneda | W1: UM Precio Pedido | X1: Importe Condición | Y1: Moneda KONP | Z1: UM Ctd Base | AA1: Destino | AB1: Nombre Destino | AC1: Cuenta de mayor | AD1: Centro de costo | AE1: Cond. Exp. | AF1: Descr. Cond. Exp. | AG1: Peso Vol. | AH1: UMB | AI1: Ind. Oblig. Conf. Ped. | AJ1: Ctrl-Conf. | AK1: IVA | AL1: Modif_Date | AM1: Ruta
A2: 900007935D8256665022910139747 | B2: 4600057825-150 | C2: 4600057825 | D2: 150 | E2: MXPO | F2: MXL | G2: 900007935 | H2: SF TP-ED LUGA-OLGUIN | I2: 5087532 | J2: LUGA AUTO TRANSPORTES SA DE CV | K2: N90 | L2: (AP) NAFIN 90 Dias | M2: 10139747 | N2: ARENA CLASIFICADA RIO MALLA 4 | O2: D825 | P2: MX-CED. GOLFO DE CALIFORNIA | Q2: 20230619 | R2: 20291231 | S2: 20260813 | T2: 20301231 | U2: 345 | V2: MXN | W2: M3 | X2: 139 | Y2: MXN | Z2: M3 | AA2: 66650229 | AB2: I8 OBR-AGR UNICONCRETOS SA DE CV | AC2: 56103638 | AD2: 6622151540 | AE2: 4 | AF2: ENTREGA DIRECTA | AG2: 1.45 | AH2: M3 | AI2: X | AJ2: 4 | AK2: V4 | AL2: 20260817 | AM2: D825-900007935-66650229-10139747-4
A3: 900007935D8256722980710139747 | B3: 4600057825-50 | C3: 4600057825 | D3: 50 | E3: MXPO | F3: MXL | G3: 900007935 | H3: SF TP-ED LUGA-OLGUIN | I3: 5087532 | J3: LUGA AUTO TRANSPORTES SA DE CV | K3: N90 | L3: (AP) NAFIN 90 Dias | M3: 10139747 | N3: ARENA CLASIFICADA RIO MALLA 4 | O3: D825 | P3: MX-CED. GOLFO DE CALIFORNIA | Q3: 20230619 | R3: 20291231 | S3: 20240529 | T3: 20291231 | U3: 406 | V3: MXN | W3: M3 | X3: 200 | Y3: MXN | Z3: M3 | AA3: 67229807 | AB3: DC CONCRETOS CAÑON DEL MATADERO | AC3: 56103638 | AD3: 6622151540 | AE3: 4 | AF3: ENTREGA DIRECTA | AG3: 1.45 | AH3: M3 | AI3: X | AJ3: 4 | AK3: V4 | AL3: 20250402 | AM3: D825-900007935-67229807-10139747-4
A4: 900006891D8256665012610139747 | B4: 4600048585-30 | C4: 4600048585 | D4: 30 | E4: MXPO | F4: MXL | G4: 900006891 | H4: SF TP-ED-TRAZO | I4: 5078812 | J4: TRAZO DEL NORESTE SRL DE CV | K4: N90 | L4: (AP) NAFIN 90 Dias | M4: 10139747 | N4: ARENA CLASIFICADA RIO MALLA 4 | O4: D825 | P4: MX-CED. GOLFO DE CALIFORNIA | Q4: 20201203 | R4: 20291231 | S4: 20210415 | T4: 20251231 | U4: 250 | V4: MXN | W4: M3 | X4: 135 | Y4: MXN | Z4: M3 | AA4: 66650126 | AB4: I8 CONCRETOS T Y G SA DE CV | AC4: 56103638 | AD4: 6622151540 | AE4: 4 | AF4: ENTREGA DIRECTA | AG4: 1.45 | AH4: M3 | AI4: X | AJ4: 4 | AK4: V4 | AL4: 20230920 | AM4: D825-900006891-66650126-10139747-4
A5: 900007935D8256715474310024382 | B5: 4600057825-10 | C5: 4600057825 | D5: 10 | E5: MXPO | F5: MXL | G5: 900007935 | H5: SF TP-ED LUGA-OLGUIN | I5: 5087532 | J5: LUGA AUTO TRANSPORTES SA DE CV | K5: N90 | L5: (AP) NAFIN 90 Dias | M5: 10024382 | N5: Grava Triturada Basalto 20 mm - 3/4" | O5: D825 | P5: MX-CED. GOLFO DE CALIFORNIA | Q5: 20230619 | R5: 20291231 | S5: 20230619 | T5: 20281231 | U5: 360 | V5: MXN | W5: M3 | X5: 130 | Y5: MXN | Z5: M3 | AA5: 67154743 | AB5: Terraplen Proyecto Estrella (dg) | AC5: 56103637 | AD5: 6622151867 | AE5: 4 | AF5: ENTREGA DIRECTA | AG5: 1.457 | AH5: M3 | AI5: X | AJ5: 4 | AK5: V4 | AL5: 20250402 | AM5: D825-900007935-67154743-10024382-4
A6: 900007775D82510217514 | B6: 4600055301-10 | C6: 4600055301 | D6: 10 | E6: MXPO | F6: MXL | G6: 900007775 | H6: SF TP- VTA CRUZADA CEBREROS | I6: 5083830 | J6: CEBRERO AMADOR CHRISTIAN ARIEL | K6: Z09 | L6: (AP) 90 Dias | M6: 10217514 | N6: ECOBASE | O6: D825 | P6: MX-CED. GOLFO DE CALIFORNIA | Q6: 20220926 | R6: 20271231 | S6: 20260512 | T6: 20301231 | U6: 60 | V6: MXN | W6: M3 | X6: 0 | Y6: MXN | Z6: M3 | AC6: 56103590 | AD6: 6622151540 | AE6: 1 | AF6: ENTREGADO | AG6: 1.5 | AH6: M3 | AI6: X | AJ6: 4 | AK6: V4 | AL6: 20260518 | AM6: D825-900007775-10217514
A7: 900006667D8256665032610275058 | B7: 4600069592-180 | C7: 4600069592 | D7: 180 | E7: MXPO | F7: MXL | G7: 900006667 | H7: SF TP-ED TRITURADOS ROCA | I7: 5078620 | J7: TRITURADOS ROCA DE BC SA DE CV | K7: N90 | L7: (AP) NAFIN 90 Dias | M7: 10275058 | N7: MP GRAVA TRIT. BASALTO 40-4MM - 1 1/2" | O7: D825 | P7: MX-CED. GOLFO DE CALIFORNIA | Q7: 20240527 | R7: 20291231 | S7: 20260611 | T7: 20301231 | U7: 286 | V7: MXN | W7: TN | X7: 68 | Y7: MXN | Z7: TN | AA7: 66650326 | AB7: I8 FRACC. PUERTA PLATA | AC7: 56103637 | AD7: 6622151540 | AE7: 4 | AF7: ENTREGA DIRECTA | AG7: 1 | AH7: TO | AI7: X | AJ7: 4 | AK7: V1 | AL7: 20260615 | AM7: D825-900006667-66650326-10275058-4
A8: 900007936D82510139747 | B8: 4600069433-10 | C8: 4600069433 | D8: 10 | E8: MXPO | F8: MXL | G8: 900007936 | H8: SF TP-LUGA-OLGUIN | I8: 5087532 | J8: LUGA AUTO TRANSPORTES SA DE CV | K8: N90 | L8: (AP) NAFIN 90 Dias | M8: 10139747 | N8: ARENA CLASIFICADA RIO MALLA 4 | O8: D825 | P8: MX-CED. GOLFO DE CALIFORNIA | Q8: 20240423 | R8: 20291231 | S8: 20240423 | T8: 20291231 | U8: 206 | V8: MXN | W8: M3 | X8: 0 | Y8: MXN | Z8: M3 | AC8: 56103638 | AD8: 6622151540 | AE8: 1 | AF8: ENTREGADO | AG8: 1.45 | AH8: M3 | AI8: X | AJ8: 4 | AK8: V4 | AL8: 20250402 | AM8: D825-900007936-10139747
A9: 900007935D8256723172410139747 | B9: 4600057825-70 | C9: 4600057825 | D9: 70 | E9: MXPO | F9: MXL | G9: 900007935 | H9: SF TP-ED LUGA-OLGUIN | I9: 5087532 | J9: LUGA AUTO TRANSPORTES SA DE CV | K9: N90 | L9: (AP) NAFIN 90 Dias | M9: 10139747 | N9: ARENA CLASIFICADA RIO MALLA 4 | O9: D825 | P9: MX-CED. GOLFO DE CALIFORNIA | Q9: 20230619 | R9: 20291231 | S9: 20240423 | T9: 20291231 | U9: 421 | V9: MXN | W9: M3 | X9: 215 | Y9: MXN | Z9: M3 | AA9: 67231724 | AB9: COMSA CAÑON DEL MATADERO | AC9: 56103638 | AD9: 6622151540 | AE9: 4 | AF9: ENTREGA DIRECTA | AG9: 1.45 | AH9: M3 | AI9: X | AJ9: 4 | AK9: V4 | AL9: 20250402 | AM9: D825-900007935-67231724-10139747-4
A10: 900007935D8256723163310139747 | B10: 4600057825-60 | C10: 4600057825 | D10: 60 | E10: MXPO | F10: MXL | G10: 900007935 | H10: SF TP-ED LUGA-OLGUIN | I10: 5087532 | J10: LUGA AUTO TRANSPORTES SA DE CV | K10: N90 | L10: (AP) NAFIN 90 Dias | M10: 10139747 | N10: ARENA CLASIFICADA RIO MALLA 4 | O10: D825 | P10: MX-CED. GOLFO DE CALIFORNIA | Q10: 20230619 | R10: 20291231 | S10: 20240423 | T10: 20291231 | U10: 379 | V10: MXN | W10: M3 | X10: 173 | Y10: MXN | Z10: M3 | AA10: 67231633 | AB10: COMSA OTAY | AC10: 56103638 | AD10: 6622151540 | AE10: 4 | AF10: ENTREGA DIRECTA | AG10: 1.45 | AH10: M3 | AI10: X | AJ10: 4 | AK10: V4 | AL10: 20250402 | AM10: D825-900007935-67231633-10139747-4
A11: 900004527D82510171201 | B11: 4600033292-140 | C11: 4600033292 | D11: 140 | E11: MXPO | F11: MXL | G11: 900004527 | H11: TP- GUSA | I11: 5002503 | J11: CONSTRUCTORA GUSA SA DE CV | K11: Z03 | L11: (AP) 15 Dias | M11: 10171201 | N11: ARENA CLASIFICADA BASALTO MALLA 4 | O11: D825 | P11: MX-CED. GOLFO DE CALIFORNIA | Q11: 20160301 | R11: 20281231 | S11: 20220101 | T11: 20251231 | U11: 91.08 | V11: MXN | W11: M3 | X11: 0 | Y11: MXN | Z11: M3 | AC11: 56103638 | AD11: 6622151540 | AE11: 1 | AF11: ENTREGADO | AG11: 1.511 | AH11: M3 | AI11: X | AJ11: 4 | AK11: V1 | AL11: 20230920 | AM11: D825-900004527-10171201
A12: 900005099D82510141536 | B12: 4600037066-30 | C12: 4600037066 | D12: 30 | E12: MXPO | F12: MXL | G12: 900005099 | H12: TP- JL CONCRETOS Y AGREGADOS | I12: 5066849 | J12: JL CONCRETOS Y AGREGADOS SR L DE CV | K12: Z09 | L12: (AP) 90 Dias | M12: 10141536 | N12: GRAVA TRITURADA BASALTO 20 MM - 3/4" | O12: D825 | P12: MX-CED. GOLFO DE CALIFORNIA | Q12: 20170306 | R12: 20241231 | S12: 20170320 | T12: 20241231 | U12: 145 | V12: MXN | W12: M3 | X12: 0 | Y12: MXN | Z12: M3 | AC12: 56103637 | AD12: 6622151540 | AE12: 1 | AF12: ENTREGADO | AG12: 1.38 | AH12: M3 | AI12: X | AJ12: 4 | AK12: V1 | AL12: 20230920 | AM12: D825-900005099-10141536
A13: 900005099D82510141571 | B13: 4600037066-10 | C13: 4600037066 | D13: 10 | E13: MXPO | F13: MXL | G13: 900005099 | H13: TP- JL CONCRETOS Y AGREGADOS | I13: 5066849 | J13: JL CONCRETOS Y AGREGADOS SR L DE CV | K13: Z09 | L13: (AP) 90 Dias | M13: 10141571 | N13: POLVO TRITURADO BASALTO | O13: D825 | P13: MX-CED. GOLFO DE CALIFORNIA | Q13: 20170306 | R13: 20241231 | S13: 20170306 | T13: 20241231 | U13: 80 | V13: MXN | W13: M3 | X13: 0 | Y13: MXN | Z13: M3 | AC13: 56103638 | AD13: 6622151540 | AE13: 1 | AF13: ENTREGADO | AG13: 1.34 | AH13: M3 | AI13: X | AJ13: 4 | AK13: V1 | AL13: 20230920 | AM13: D825-900005099-10141571
A14: 900004527D82510165992 | B14: 4600033292-160 | C14: 4600033292 | D14: 160 | E14: MXPO | F14: MXL | G14: 900004527 | H14: TP- GUSA | I14: 5002503 | J14: CONSTRUCTORA GUSA SA DE CV | K14: Z03 | L14: (AP) 15 Dias | M14: 10165992 | N14: GRAVA TRITURADA BASALTO 13 MM - 1/2" | O14: D825 | P14: MX-CED. GOLFO DE CALIFORNIA | Q14: 20160301 | R14: 20281231 | S14: 20200511 | T14: 20291231 | U14: 239.2 | V14: MXN | W14: M3 | X14: 0 | Y14: MXN | Z14: M3 | AC14: 56103637 | AD14: 6622151867 | AE14: 1 | AF14: ENTREGADO | AG14: 1.226 | AH14: M3 | AI14: X | AJ14: 4 | AK14: V1 | AL14: 20230920 | AM14: D825-900004527-10165992
A15: 900004848D82510139747 | B15: 4600035173-20 | C15: 4600035173 | D15: 20 | E15: MXPO | F15: MXL | G15: 900004848 | H15: TP- CONSTRUCTORA SEXTIN VALLE | I15: 5042038 | J15: CONSTRUCTORA SEXTIN SA DE CV | K15: N120 | L15: (AP) NAFIN 120 Dias | M15: 10139747 | N15: ARENA CLASIFICADA RIO MALLA 4 | O15: D825 | P15: MX-CED. GOLFO DE CALIFORNIA | Q15: 20160831 | R15: 20241231 | S15: 20210415 | T15: 20241231 | U15: 140 | V15: MXN | W15: M3 | X15: 0 | Y15: MXN | Z15: M3 | AC15: 56103638 | AD15: 6622151540 | AE15: 1 | AF15: ENTREGADO | AG15: 1.45 | AH15: M3 | AI15: X | AJ15: 4 | AK15: V1 | AL15: 20230920 | AM15: D825-900004848-10139747
A16: 900005099D82510141537 | B16: 4600037066-40 | C16: 4600037066 | D16: 40 | E16: MXPO | F16: MXL | G16: 900005099 | H16: TP- JL CONCRETOS Y AGREGADOS | I16: 5066849 | J16: JL CONCRETOS Y AGREGADOS SR L DE CV | K16: Z09 | L16: (AP) 90 Dias | M16: 10141537 | N16: GRAVA TRITURADA BASALTO 40 MM - 1 1/2" | O16: D825 | P16: MX-CED. GOLFO DE CALIFORNIA | Q16: 20170306 | R16: 20241231 | S16: 20180724 | T16: 20241231 | U16: 141.5 | V16: MXN | W16: M3 | X16: 0 | Y16: MXN | Z16: M3 | AC16: 56103637 | AD16: 6622151540 | AE16: 1 | AF16: ENTREGADO | AG16: 1.421 | AH16: M3 | AI16: X | AJ16: 4 | AK16: V1 | AL16: 20230920 | AM16: D825-900005099-10141537
A17: 900004527D82510153332 | B17: 4600033292-100 | C17: 4600033292 | D17: 100 | E17: MXPO | F17: MXL | G17: 900004527 | H17: TP- GUSA | I17: 5002503 | J17: CONSTRUCTORA GUSA SA DE CV | K17: Z03 | L17: (AP) 15 Dias | M17: 10153332 | N17: GRAVA TRITURADA BASALTO 40 MM - 1 1/2" | O17: D825 | P17: MX-CED. GOLFO DE CALIFORNIA | Q17: 20160301 | R17: 20281231 | S17: 20220801 | T17: 20271231 | U17: 300 | V17: MXN | W17: M3 | X17: 0 | Y17: MXN | Z17: M3 | AC17: 56103637 | AD17: 6622151540 | AE17: 1 | AF17: ENTREGADO | AG17: 1.5 | AH17: M3 | AI17: X | AJ17: 4 | AK17: V1 | AL17: 20230920 | AM17: D825-900004527-10153332
A18: 900004527D82510137462 | B18: 4600033292-180 | C18: 4600033292 | D18: 180 | E18: MXPO | F18: MXL | G18: 900004527 | H18: TP- GUSA | I18: 5002503 | J18: CONSTRUCTORA GUSA SA DE CV | K18: Z03 | L18: (AP) 15 Dias | M18: 10137462 | N18: GRAVA TRITURADA BASALTO 10 MM - 3/8" | O18: D825 | P18: MX-CED. GOLFO DE CALIFORNIA | Q18: 20160301 | R18: 20281231 | S18: 20220801 | T18: 20271231 | U18: 369 | V18: MXN | W18: M3 | X18: 0 | Y18: MXN | Z18: M3 | AC18: 56103637 | AD18: 6622151540 | AE18: 1 | AF18: ENTREGADO | AG18: 1.37 | AH18: M3 | AI18: X | AJ18: 4 | AK18: V1 | AL18: 20230920 | AM18: D825-900004527-10137462
A19: 900005099D82510179731 | B19: 4600037066-50 | C19: 4600037066 | D19: 50 | E19: MXPO | F19: MXL | G19: 900005099 | H19: TP- JL CONCRETOS Y AGREGADOS | I19: 5066849 | J19: JL CONCRETOS Y AGREGADOS SR L DE CV | K19: Z09 | L19: (AP) 90 Dias | M19: 10179731 | N19: BASE H TRITURADA BASALTO 1 1/2" A FINOS | O19: D825 | P19: MX-CED. GOLFO DE CALIFORNIA | Q19: 20170306 | R19: 20241231 | S19: 20200108 | T19: 20291231 | U19: 144.09 | V19: MXN | W19: M3 | X19: 0 | Y19: MXN | Z19: M3 | AC19: 56103590 | AD19: 6622151540 | AE19: 1 | AF19: ENTREGADO | AG19: 1.619 | AH19: M3 | AI19: X | AJ19: 4 | AK19: V1 | AL19: 20230920 | AM19: D825-900005099-10179731
A20: 900005187D82510147585 | B20: 4600044437-10 | C20: 4600044437 | D20: 10 | E20: MXPO | F20: MXL | G20: 900005187 | H20: TP- DECOP CONSTRUCTORA | I20: 5057105 | J20: DECOP CONSTRUCTORA S A DE CV | K20: N120 | L20: (AP) NAFIN 120 Dias | M20: 10147585 | N20: TUCURUGUAY TRITURADO GRANITO | O20: D825 | P20: MX-CED. GOLFO DE CALIFORNIA | Q20: 20190401 | R20: 20241231 | S20: 20190401 | T20: 20241231 | U20: 30.8 | V20: MXN | W20: M3 | X20: 0 | Y20: MXN | Z20: M3 | AC20: 56103638 | AD20: 6622151540 | AE20: 1 | AF20: ENTREGADO | AG20: 1.4 | AH20: M3 | AI20: X | AJ20: 4 | AK20: V4 | AL20: 20230920 | AM20: D825-900005187-10147585
A21: 900006873D82510000191 | B21: 4600048798-20 | C21: 4600048798 | D21: 20 | E21: MXPO | F21: MXL | G21: 900006873 | H21: SF TP-LO INFRA EL REFUGIO | I21: 5078800 | J21: LO INFRAESTRUCTURA S DE RL DE CV | K21: N30 | L21: (AP) NAFIN 30 Dias | M21: 10000191 | N21: Grava Triturada Basalto 20 mm - 3/4" | O21: D825 | P21: MX-CED. GOLFO DE CALIFORNIA | Q21: 20210106 | R21: 20291231 | S21: 20220215 | T21: 20271231 | U21: 220 | V21: MXN | W21: M3 | X21: 0 | Y21: MXN | Z21: M3 | AC21: 56103637 | AD21: 6622151540 | AE21: 1 | AF21: ENTREGADO | AG21: 1.41 | AH21: M3 | AI21: X | AJ21: 4 | AK21: V4 | AL21: 20230920 | AM21: D825-900006873-10000191
A22: 900004527D82510125120 | B22: 4600033292-190 | C22: 4600033292 | D22: 190 | E22: MXPO | F22: MXL | G22: 900004527 | H22: TP- GUSA | I22: 5002503 | J22: CONSTRUCTORA GUSA SA DE CV | K22: Z03 | L22: (AP) 15 Dias | M22: 10125120 | N22: GRAVA TRITURADA BASALTO 20 MM (3/4") | O22: D825 | P22: MX-CED. GOLFO DE CALIFORNIA | Q22: 20160301 | R22: 20281231 | S22: 20230718 | T22: 20281231 | U22: 300 | V22: MXN | W22: M3 | X22: 0 | Y22: MXN | Z22: M3 | AC22: 56103637 | AD22: 6622151540 | AE22: 1 | AF22: ENTREGADO | AG22: 1.402 | AH22: M3 | AI22: X | AJ22: 4 | AK22: V1 | AL22: 20230920 | AM22: D825-900004527-10125120
... A29: 900007330D82510152920 | B29: 4600052083-20 | C29: 4600052083 | D29: 20 | E29: MXPO | F29: MXL | G29: 900007330 | H29: SF TP-RECOGIDO-APR | I29: 5081100 | J29: APR OBRAS Y AGREGADOS S DE RL DE CV | K29: N90 | L29: (AP) NAFIN 90 Dias | M29: 10152920 | N29: POLVO TRITURADO GRANITO | O29: D825 | P29: MX-CED. GOLFO DE CALIFORNIA | Q29: 20211001 | R29: 20261231 | S29: 20210930 | T29: 20251231 | U29: 40 | V29: MXN | W29: M3 | X29: 0 | Y29: MXN | Z29: M3 | AC29: 56103591 | AD29: 6622151540 | AE29: 2 | AF29: RECOGIDO | AG29: 1.615 | AH29: M3 | AI29: X | AJ29: 4 | AK29: V4 | AL29: 20230920 | AM29: D825-900007330-10152920
A30: 900005121D8256665012610139747 | B30: 4600047224-10 | C30: 4600047224 | D30: 10 | E30: MXPO | F30: MXL | G30: 900005121 | H30: TP- SEXTIN TIJUANA | I30: 5042038 | J30: CONSTRUCTORA SEXTIN SA DE CV | K30: N120 | L30: (AP) NAFIN 120 Dias | M30: 10139747 | N30: ARENA CLASIFICADA RIO MALLA 4 | O30: D825 | P30: MX-CED. GOLFO DE CALIFORNIA | Q30: 20200527 | R30: 20301231 | S30: 20200527 | T30: 20301231 | U30: 228 | V30: MXN | W30: M3 | X30: 108 | Y30: MXN | Z30: M3 | AA30: 66650126 | AB30: I8 CONCRETOS T Y G SA DE CV | AC30: 56103638 | AD30: 6622151540 | AE30: 4 | AF30: ENTREGA DIRECTA | AG30: 1.45 | AH30: M3 | AI30: X | AJ30: 4 | AK30: V1 | AL30: 20230920 | AM30: D825-900005121-66650126-10139747-4
A31: 900005281D8256665044910184157 | B31: 4600038431-80 | C31: 4600038431 | D31: 80 | E31: MXPO | F31: MXL | G31: 900005281 | H31: TP- ED PETREOS LA PURISIMA | I31: 5011228 | J31: PETREOS LA PURISIMA SA DE CV | K31: N90 | L31: (AP) NAFIN 90 Dias | M31: 10184157 | N31: GRAVA TRITURADA BASALTO 20 MM - 3/4" | O31: D825 | P31: MX-CED. GOLFO DE CALIFORNIA | Q31: 20170616 | R31: 20291231 | S31: 20200824 | T31: 20291231 | U31: 330 | V31: MXN | W31: M3 | X31: 108 | Y31: MXN | Z31: M3 | AA31: 66650449 | AB31: I8 CONCRETOS FLOMEX | AC31: 56103637 | AD31: 6622151540 | AE31: 4 | AF31: ENTREGA DIRECTA | AG31: 1.383 | AH31: M3 | AI31: X | AJ31: 4 | AK31: V4 | AL31: 20230920 | AM31: D825-900005281-66650449-10184157-4
A32: 900005281D8256705909710137462 | B32: 4600038431-120 | C32: 4600038431 | D32: 120 | E32: MXPO | F32: MXL | G32: 900005281 | H32: TP- ED PETREOS LA PURISIMA | I32: 5011228 | J32: PETREOS LA PURISIMA SA DE CV | K32: N90 | L32: (AP) NAFIN 90 Dias | M32: 10137462 | N32: GRAVA TRITURADA BASALTO 10 MM - 3/8" | O32: D825 | P32: MX-CED. GOLFO DE CALIFORNIA | Q32: 20170616 | R32: 20291231 | S32: 20220505 | T32: 20271231 | U32: 360 | V32: MXN | W32: M3 | X32: 65 | Y32: MXN | Z32: M3 | AA32: 67059097 | AB32: PUERTA PLATA (dg) | AC32: 56103637 | AD32: 6622151540 | AE32: 4 | AF32: ENTREGA DIRECTA | AG32: 1.37 | AH32: M3 | AI32: X | AJ32: 4 | AK32: V4 | AL32: 20230920 | AM32: D825-900005281-67059097-10137462-4
A33: 900005281D8256694864010052400 | B33: 4600038431-140 | C33: 4600038431 | D33: 140 | E33: MXPO | F33: MXL | G33: 900005281 | H33: TP- ED PETREOS LA PURISIMA | I33: 5011228 | J33: PETREOS LA PURISIMA SA DE CV | K33: N90 | L33: (AP) NAFIN 90 Dias | M33: 10052400 | N33: Arena Clasificada Río Malla 4 - Lavado | O33: D825 | P33: MX-CED. GOLFO DE CALIFORNIA | Q33: 20170616 | R33: 20291231 | S33: 20221028 | T33: 20271231 | U33: 269.58 | V33: MXN | W33: M3 | X33: 134 | Y33: MXN | Z33: M3 | AA33: 66948640 | AB33: WESTLAKE ROYAL MEXICO | AC33: 56103638 | AD33: 6622151867 | AE33: 4 | AF33: ENTREGA DIRECTA | AG33: 1.655 | AH33: M3 | AI33: X | AJ33: 4 | AK33: V4 | AL33: 20230920 | AM33: D825-900005281-66948640-10052400-4
A34: 900007935D8256713962210139747 | B34: 4600057825-30 | C34: 4600057825 | D34: 30 | E34: MXPO | F34: MXL | G34: 900007935 | H34: SF TP-ED LUGA-OLGUIN | I34: 5087532 | J34: LUGA AUTO TRANSPORTES SA DE CV | K34: N90 | L34: (AP) NAFIN 90 Dias | M34: 10139747 | N34: ARENA CLASIFICADA RIO MALLA 4 | O34: D825 | P34: MX-CED. GOLFO DE CALIFORNIA | Q34: 20230619 | R34: 20291231 | S34: 20230720 | T34: 20281231 | U34: 415 | V34: MXN | W34: M3 | X34: 219 | Y34: MXN | Z34: M3 | AA34: 67139622 | AB34: CPI VILLAS VGD (FA) | AC34: 56103638 | AD34: 6622151540 | AE34: 4 | AF34: ENTREGA DIRECTA | AG34: 1.45 | AH34: M3 | AI34: X | AJ34: 4 | AK34: V4 | AL34: 20250402 | AM34: D825-900007935-67139622-10139747-4
A35: 900006891D8256698692410179731 | B35: 4600048585-60 | C35: 4600048585 | D35: 60 | E35: MXPO | F35: MXL | G35: 900006891 | H35: SF TP-ED-TRAZO | I35: 5078812 | J35: TRAZO DEL NORESTE SRL DE CV | K35: N90 | L35: (AP) NAFIN 90 Dias | M35: 10179731 | N35: BASE H TRITURADA BASALTO 1 1/2" A FINOS | O35: D825 | P35: MX-CED. GOLFO DE CALIFORNIA | Q35: 20201203 | R35: 20291231 | S35: 20210721 | T35: 20251231 | U35: 321 | V35: MXN | W35: M3 | X35: 131 | Y35: MXN | Z35: M3 | AA35: 66986924 | AB35: AY CALLE PADRE KINO SALVATIERRA(LHC | AC35: 56103590 | AD35: 6622151540 | AE35: 4 | AF35: ENTREGA DIRECTA | AG35: 1.619 | AH35: M3 | AI35: X | AJ35: 4 | AK35: V4 | AL35: 20230920 | AM35: D825-900006891-66986924-10179731-4
A36: 900007935D8256734153110125120 | B36: 4600057825-140 | C36: 4600057825 | D36: 140 | E36: MXPO | F36: MXL | G36: 900007935 | H36: SF TP-ED LUGA-OLGUIN | I36: 5087532 | J36: LUGA AUTO TRANSPORTES SA DE CV | K36: N90 | L36: (AP) NAFIN 90 Dias | M36: 10125120 | N36: GRAVA TRITURADA BASALTO 20 MM (3/4") | O36: D825 | P36: MX-CED. GOLFO DE CALIFORNIA | Q36: 20230619 | R36: 20291231 | S36: 20260225 | T36: 20301231 | U36: 380 | V36: MXN | W36: M3 | X36: 75 | Y36: MXN | Z36: M3 | AA36: 67341531 | AB36: PROSPERITY SPEC 09 GAAB | AC36: 56103637 | AD36: 6622151540 | AE36: 4 | AF36: ENTREGA DIRECTA | AG36: 1.35 | AH36: M3 | AI36: X | AJ36: 4 | AK36: V4 | AL36: 20260227 | AM36: D825-900007935-67341531-10125120-4
A37: 900000651D82510052400 | B37: 4600047841-40 | C37: 4600047841 | D37: 40 | E37: MXPO | F37: MXL | G37: 900000651 | H37: SF TP PETREOS LA PURISIMA | I37: 5011228 | J37: PETREOS LA PURISIMA SA DE CV | K37: N90 | L37: (AP) NAFIN 90 Dias | M37: 10052400 | N37: Arena Clasificada Río Malla 4 - Lavado | O37: D825 | P37: MX-CED. GOLFO DE CALIFORNIA | Q37: 20200824 | R37: 20261231 | S37: 20250512 | T37: 20301231 | U37: 226.34 | V37: MXN | W37: M3 | X37: 0 | Y37: MXN | Z37: M3 | AC37: 56103638 | AD37: 6622151867 | AE37: 1 | AF37: ENTREGADO | AG37: 1.655 | AH37: M3 | AI37: X | AJ37: 4 | AK37: V4 | AL37: 20250604 | AM37: D825-900000651-10052400
A38: 900007935D8256515636510139747 | B38: 4600057825-130 | C38: 4600057825 | D38: 130 | E38: MXPO | F38: MXL | G38: 900007935 | H38: SF TP-ED LUGA-OLGUIN | I38: 5087532 | J38: LUGA AUTO TRANSPORTES SA DE CV | K38: N90 | L38: (AP) NAFIN 90 Dias | M38: 10139747 | N38: ARENA CLASIFICADA RIO MALLA 4 | O38: D825 | P38: MX-CED. GOLFO DE CALIFORNIA | Q38: 20230619 | R38: 20291231 | S38: 20260213 | T38: 20301231 | U38: 390 | V38: MXN | W38: M3 | X38: 184 | Y38: MXN | Z38: M3 | AA38: 65156365 | AB38: PROMEXMA TIJUANA | AC38: 56103638 | AD38: 6622151540 | AE38: 4 | AF38: ENTREGA DIRECTA | AG38: 1.45 | AH38: M3 | AI38: X | AJ38: 4 | AK38: V4 | AL38: 20260306 | AM38: D825-900007935-65156365-10139747-4
A39: 900006667D8256702277910211341 | B39: 4600069592-160 | C39: 4600069592 | D39: 160 | E39: MXPO | F39: MXL | G39: 900006667 | H39: SF TP-ED TRITURADOS ROCA | I39: 5078620 | J39: TRITURADOS ROCA DE BC SA DE CV | K39: N90 | L39: (AP) NAFIN 90 Dias | M39: 10211341 | N39: GRAVA TRITURADA BASALTO 10 MM - 3/8" | O39: D825 | P39: MX-CED. GOLFO DE CALIFORNIA | Q39: 20240527 | R39: 20291231 | S39: 20260429 | T39: 20301231 | U39: 367 | V39: MXN | W39: TN | X39: 55 | Y39: MXN | Z39: TN | AA39: 67022779 | AB39: SOLIDBLOCK SA DE CV | AC39: 56103637 | AD39: 6622151867 | AE39: 4 | AF39: ENTREGA DIRECTA | AG39: 1 | AH39: TO | AI39: X | AJ39: 4 | AK39: V1 | AL39: 20260505 | AM39: D825-900006667-67022779-10211341-4
A40: 900006667D8256733352910211341 | B40: 4600069592-120 | C40: 4600069592 | D40: 120 | E40: MXPO | F40: MXL | G40: 900006667 | H40: SF TP-ED TRITURADOS ROCA | I40: 5078620 | J40: TRITURADOS ROCA DE BC SA DE CV | K40: N90 | L40: (AP) NAFIN 90 Dias | M40: 10211341 | N40: GRAVA TRITURADA BASALTO 10 MM - 3/8" | O40: D825 | P40: MX-CED. GOLFO DE CALIFORNIA | Q40: 20240527 | R40: 20291231 | S40: 20260429 | T40: 20301231 | U40: 352 | V40: MXN | W40: TN | X40: 40 | Y40: MXN | Z40: TN | AA40: 67333529 | AB40: MAT BLOQUE | AC40: 56103637 | AD40: 6622151867 | AE40: 4 | AF40: ENTREGA DIRECTA | AG40: 1 | AH40: TO | AI40: X | AJ40: 4 | AK40: V1 | AL40: 20260505 | AM40: D825-900006667-67333529-10211341-4
A41: 900006667D8256723796910211341 | B41: 4600069592-140 | C41: 4600069592 | D41: 140 | E41: MXPO | F41: MXL | G41: 900006667 | H41: SF TP-ED TRITURADOS ROCA | I41: 5078620 | J41: TRITURADOS ROCA DE BC SA DE CV | K41: N90 | L41: (AP) NAFIN 90 Dias | M41: 10211341 | N41: GRAVA TRITURADA BASALTO 10 MM - 3/8" | O41: D825 | P41: MX-CED. GOLFO DE CALIFORNIA | Q41: 20240527 | R41: 20291231 | S41: 20260429 | T41: 20301231 | U41: 347 | V41: MXN | W41: TN | X41: 35 | Y41: MXN | Z41: TN | AA41: 67237969 | AB41: BLOQUERA CEMENQUIN | AC41: 56103637 | AD41: 6622151867 | AE41: 4 | AF41: ENTREGA DIRECTA | AG41: 1 | AH41: TO | AI41: X | AJ41: 4 | AK41: V1 | AL41: 20260505 | AM41: D825-900006667-67237969-10211341-4
A42: 900006667D8256733352910274601 | B42: 4600069592-130 | C42: 4600069592 | D42: 130 | E42: MXPO | F42: MXL | G42: 900006667 | H42: SF TP-ED TRITURADOS ROCA | I42: 5078620 | J42: TRITURADOS ROCA DE BC SA DE CV | K42: N90 | L42: (AP) NAFIN 90 Dias | M42: 10274601 | N42: MP ARENA BASALTO N° 4 | O42: D825 | P42: MX-CED. GOLFO DE CALIFORNIA | Q42: 20240527 | R42: 20291231 | S42: 20260429 | T42: 20301231 | U42: 163 | V42: MXN | W42: TN | X42: 40 | Y42: MXN | Z42: TN | AA42: 67333529 | AB42: MAT BLOQUE | AC42: 56103638 | AD42: 6622151540 | AE42: 4 | AF42: ENTREGA DIRECTA | AG42: 1 | AH42: TO | AI42: X | AJ42: 4 | AK42: V1 | AL42: 20260505 | AM42: D825-900006667-67333529-10274601-4
A43: 900006667D8256723796910274601 | B43: 4600069592-150 | C43: 4600069592 | D43: 150 | E43: MXPO | F43: MXL | G43: 900006667 | H43: SF TP-ED TRITURADOS ROCA | I43: 5078620 | J43: TRITURADOS ROCA DE BC SA DE CV | K43: N90 | L43: (AP) NAFIN 90 Dias | M43: 10274601 | N43: MP ARENA BASALTO N° 4 | O43: D825 | P43: MX-CED. GOLFO DE CALIFORNIA | Q43: 20240527 | R43: 20291231 | S43: 20260429 | T43: 20301231 | U43: 158 | V43: MXN | W43: TN | X43: 35 | Y43: MXN | Z43: TN | AA43: 67237969 | AB43: BLOQUERA CEMENQUIN | AC43: 56103638 | AD43: 6622151540 | AE43: 4 | AF43: ENTREGA DIRECTA | AG43: 1 | AH43: TO | AI43: X | AJ43: 4 | AK43: V1 | AL43: 20260505 | AM43: D825-900006667-67237969-10274601-4
A44: 900006667D8256702277910274601 | B44: 4600069592-170 | C44: 4600069592 | D44: 170 | E44: MXPO | F44: MXL | G44: 900006667 | H44: SF TP-ED TRITURADOS ROCA | I44: 5078620 | J44: TRITURADOS ROCA DE BC SA DE CV | K44: N90 | L44: (AP) NAFIN 90 Dias | M44: 10274601 | N44: MP ARENA BASALTO N° 4 | O44: D825 | P44: MX-CED. GOLFO DE CALIFORNIA | Q44: 20240527 | R44: 20291231 | S44: 20260429 | T44: 20301231 | U44: 178 | V44: MXN | W44: TN | X44: 55 | Y44: MXN | Z44: TN | AA44: 67022779 | AB44: SOLIDBLOCK SA DE CV | AC44: 56103638 | AD44: 6622151540 | AE44: 4 | AF44: ENTREGA DIRECTA | AG44: 1 | AH44: TO | AI44: X | AJ44: 4 | AK44: V1 | AL44: 20260505 | AM44: D825-900006667-67022779-10274601-4
A45: 900007935D8256719543210139747 | B45: 4600057825-80 | C45: 4600057825 | D45: 80 | E45: MXPO | F45: MXL | G45: 900007935 | H45: SF TP-ED LUGA-OLGUIN | I45: 5087532 | J45: LUGA AUTO TRANSPORTES SA DE CV | K45: N90 | L45: (AP) NAFIN 90 Dias | M45: 10139747 | N45: ARENA CLASIFICADA RIO MALLA 4 | O45: D825 | P45: MX-CED. GOLFO DE CALIFORNIA | Q45: 20230619 | R45: 20291231 | S45: 20240701 | T45: 20291231 | U45: 358 | V45: MXN | W45: M3 | X45: 152 | Y45: MXN | Z45: M3 | AA45: 67195432 | AB45: EL CAÑON SUC OTAY | AC45: 56103638 | AD45: 6622151540 | AE45: 4 | AF45: ENTREGA DIRECTA | AG45: 1.45 | AH45: M3 | AI45: X | AJ45: 4 | AK45: V4 | AL45: 20250402 | AM45: D825-900007935-67195432-10139747-4
A46: 900005281D8256722980810052400 | B46: 4600038431-150 | C46: 4600038431 | D46: 150 | E46: MXPO | F46: MXL | G46: 900005281 | H46: TP- ED PETREOS LA PURISIMA | I46: 5011228 | J46: PETREOS LA PURISIMA SA DE CV | K46: N90 | L46: (AP) NAFIN 90 Dias | M46: 10052400 | N46: Arena Clasificada Río Malla 4 - Lavado | O46: D825 | P46: MX-CED. GOLFO DE CALIFORNIA | Q46: 20170616 | R46: 20291231 | S46: 20240603 | T46: 20291231 | U46: 376.34 | V46: MXN | W46: M3 | X46: 150 | Y46: MXN | Z46: M3 | AA46: 67229808 | AB46: DC CONCRETOS VALLE REDONDO | AC46: 56103638 | AD46: 6622151867 | AE46: 4 | AF46: ENTREGA DIRECTA | AG46: 1.655 | AH46: M3 | AI46: X | AJ46: 4 | AK46: V4 | AL46: 20240606 | AM46: D825-900005281-67229808-10052400-4
...
