Workbook

Sheet Base Cedis DW60
N1: VENTA | Q1: COSTO
A2: CONCAT1 | B2: CONCAT2 | C2: No. SF | D2: Nombre SF | E2: Cedis | F2: Destino | G2: Condicion de Expedicion | H2: Nombre Destino | I2: No. de material | J2: Nombre de material | K2: PV | L2: Inicio de vigencia | M2: Fin de vigencia | N2: Importe MP | O2: Importe Flete | P2: UM Venta | Q2: Importe Costo | R2: UM Costo | S2: Validacion 1 | T2: Validacion 2
A3: =CONCATENATE(C3,E3,F3,I3) | B3: =CONCATENATE(C3,E3,I3) | C3: 900000529 | D3: =IFERROR(VLOOKUP(C3,TRAOPE!$G:$H,2,0),"") | E3: DW60 | F3: D006 | G3: =IFERROR(VLOOKUP(A3,Flete!$A:$E,5,0),"") | H3: =IFERROR(VLOOKUP(F3,TRAOPE!$AA:$AB,2,0),"") | I3: 10000531 | J3: =IFERROR(VLOOKUP(I3,Materiales!$A:$H,8,0),"") | K3: =IFERROR(VLOOKUP(I3,Materiales!$A:$G,7,0),"") | L3: 20210620 | M3: 20251031 | N3: 71.43 | O3: =IFERROR(VLOOKUP(A3,Flete!$A:$J,10,0),"") | P3: TN | Q3: =IFERROR(IFERROR(VLOOKUP(A3,TRAOPE!$A:$U,21,0),VLOOKUP(B3,TRAOPE!$A:$U,21,0)),"") | R3: =IFERROR(IFERROR(VLOOKUP(A3,TRAOPE!$A:$W,23,0),VLOOKUP(B3,TRAOPE!$A:$W,23,0)),"") | S3: =IF(AND(P3="TN",R3="TN"),N3+N(O3),IF(G3&""="1",N(K3)*N3,(N3+N(O3))*N(K3))) | T3: =IF(Q3="","",Q3-S3)
A4: =CONCATENATE(C4,E4,F4,I4) | B4: =CONCATENATE(C4,E4,I4) | C4: 900000529 | D4: =IFERROR(VLOOKUP(C4,TRAOPE!$G:$H,2,0),"") | E4: DW60 | F4: D006 | G4: =IFERROR(VLOOKUP(A4,Flete!$A:$E,5,0),"") | H4: =IFERROR(VLOOKUP(F4,TRAOPE!$AA:$AB,2,0),"") | I4: 10170258 | J4: =IFERROR(VLOOKUP(I4,Materiales!$A:$H,8,0),"") | K4: =IFERROR(VLOOKUP(I4,Materiales!$A:$G,7,0),"") | L4: 20210620 | M4: 20251031 | N4: 57.37 | O4: =IFERROR(VLOOKUP(A4,Flete!$A:$J,10,0),"") | P4: TN | Q4: =IFERROR(IFERROR(VLOOKUP(A4,TRAOPE!$A:$U,21,0),VLOOKUP(B4,TRAOPE!$A:$U,21,0)),"") | R4: =IFERROR(IFERROR(VLOOKUP(A4,TRAOPE!$A:$W,23,0),VLOOKUP(B4,TRAOPE!$A:$W,23,0)),"") | S4: =IF(AND(P4="TN",R4="TN"),N4+N(O4),IF(G4&""="1",N(K4)*N4,(N4+N(O4))*N(K4))) | T4: =IF(Q4="","",Q4-S4)
A5: =CONCATENATE(C5,E5,F5,I5) | B5: =CONCATENATE(C5,E5,I5) | C5: 900000529 | D5: =IFERROR(VLOOKUP(C5,TRAOPE!$G:$H,2,0),"") | E5: DW60 | F5: D006 | G5: =IFERROR(VLOOKUP(A5,Flete!$A:$E,5,0),"") | H5: =IFERROR(VLOOKUP(F5,TRAOPE!$AA:$AB,2,0),"") | I5: 10170354 | J5: =IFERROR(VLOOKUP(I5,Materiales!$A:$H,8,0),"") | K5: =IFERROR(VLOOKUP(I5,Materiales!$A:$G,7,0),"") | L5: 20210620 | M5: 20251031 | N5: 69.23 | O5: =IFERROR(VLOOKUP(A5,Flete!$A:$J,10,0),"") | P5: TN | Q5: =IFERROR(IFERROR(VLOOKUP(A5,TRAOPE!$A:$U,21,0),VLOOKUP(B5,TRAOPE!$A:$U,21,0)),"") | R5: =IFERROR(IFERROR(VLOOKUP(A5,TRAOPE!$A:$W,23,0),VLOOKUP(B5,TRAOPE!$A:$W,23,0)),"") | S5: =IF(AND(P5="TN",R5="TN"),N5+N(O5),IF(G5&""="1",N(K5)*N5,(N5+N(O5))*N(K5))) | T5: =IF(Q5="","",Q5-S5)
A6: =CONCATENATE(C6,E6,F6,I6) | B6: =CONCATENATE(C6,E6,I6) | C6: 900000529 | D6: =IFERROR(VLOOKUP(C6,TRAOPE!$G:$H,2,0),"") | E6: DW60 | F6: D006 | G6: =IFERROR(VLOOKUP(A6,Flete!$A:$E,5,0),"") | H6: =IFERROR(VLOOKUP(F6,TRAOPE!$AA:$AB,2,0),"") | I6: 10188535 | J6: =IFERROR(VLOOKUP(I6,Materiales!$A:$H,8,0),"") | K6: =IFERROR(VLOOKUP(I6,Materiales!$A:$G,7,0),"") | L6: 20250513 | M6: 99991231 | N6: 58.66 | O6: =IFERROR(VLOOKUP(A6,Flete!$A:$J,10,0),"") | P6: TN | Q6: =IFERROR(IFERROR(VLOOKUP(A6,TRAOPE!$A:$U,21,0),VLOOKUP(B6,TRAOPE!$A:$U,21,0)),"") | R6: =IFERROR(IFERROR(VLOOKUP(A6,TRAOPE!$A:$W,23,0),VLOOKUP(B6,TRAOPE!$A:$W,23,0)),"") | S6: =IF(AND(P6="TN",R6="TN"),N6+N(O6),IF(G6&""="1",N(K6)*N6,(N6+N(O6))*N(K6))) | T6: =IF(Q6="","",Q6-S6)
A7: =CONCATENATE(C7,E7,F7,I7) | B7: =CONCATENATE(C7,E7,I7) | C7: 900000529 | D7: =IFERROR(VLOOKUP(C7,TRAOPE!$G:$H,2,0),"") | E7: DW60 | F7: D041 | G7: =IFERROR(VLOOKUP(A7,Flete!$A:$E,5,0),"") | H7: =IFERROR(VLOOKUP(F7,TRAOPE!$AA:$AB,2,0),"") | I7: 10170258 | J7: =IFERROR(VLOOKUP(I7,Materiales!$A:$H,8,0),"") | K7: =IFERROR(VLOOKUP(I7,Materiales!$A:$G,7,0),"") | L7: 20210620 | M7: 20251031 | N7: 57.37 | O7: =IFERROR(VLOOKUP(A7,Flete!$A:$J,10,0),"") | P7: TN | Q7: =IFERROR(IFERROR(VLOOKUP(A7,TRAOPE!$A:$U,21,0),VLOOKUP(B7,TRAOPE!$A:$U,21,0)),"") | R7: =IFERROR(IFERROR(VLOOKUP(A7,TRAOPE!$A:$W,23,0),VLOOKUP(B7,TRAOPE!$A:$W,23,0)),"") | S7: =IF(AND(P7="TN",R7="TN"),N7+N(O7),IF(G7&""="1",N(K7)*N7,(N7+N(O7))*N(K7))) | T7: =IF(Q7="","",Q7-S7)
A8: =CONCATENATE(C8,E8,F8,I8) | B8: =CONCATENATE(C8,E8,I8) | C8: 900000529 | D8: =IFERROR(VLOOKUP(C8,TRAOPE!$G:$H,2,0),"") | E8: DW60 | F8: D041 | G8: =IFERROR(VLOOKUP(A8,Flete!$A:$E,5,0),"") | H8: =IFERROR(VLOOKUP(F8,TRAOPE!$AA:$AB,2,0),"") | I8: 10170354 | J8: =IFERROR(VLOOKUP(I8,Materiales!$A:$H,8,0),"") | K8: =IFERROR(VLOOKUP(I8,Materiales!$A:$G,7,0),"") | L8: 20210620 | M8: 20251031 | N8: 69.23 | O8: =IFERROR(VLOOKUP(A8,Flete!$A:$J,10,0),"") | P8: TN | Q8: =IFERROR(IFERROR(VLOOKUP(A8,TRAOPE!$A:$U,21,0),VLOOKUP(B8,TRAOPE!$A:$U,21,0)),"") | R8: =IFERROR(IFERROR(VLOOKUP(A8,TRAOPE!$A:$W,23,0),VLOOKUP(B8,TRAOPE!$A:$W,23,0)),"") | S8: =IF(AND(P8="TN",R8="TN"),N8+N(O8),IF(G8&""="1",N(K8)*N8,(N8+N(O8))*N(K8))) | T8: =IF(Q8="","",Q8-S8)
A9: =CONCATENATE(C9,E9,F9,I9) | B9: =CONCATENATE(C9,E9,I9) | C9: 900001005 | D9: =IFERROR(VLOOKUP(C9,TRAOPE!$G:$H,2,0),"") | E9: DW60 | F9: D003 | G9: =IFERROR(VLOOKUP(A9,Flete!$A:$E,5,0),"") | H9: =IFERROR(VLOOKUP(F9,TRAOPE!$AA:$AB,2,0),"") | I9: 10031864 | J9: =IFERROR(VLOOKUP(I9,Materiales!$A:$H,8,0),"") | K9: =IFERROR(VLOOKUP(I9,Materiales!$A:$G,7,0),"") | L9: 20210620 | M9: 20251031 | N9: 68 | O9: =IFERROR(VLOOKUP(A9,Flete!$A:$J,10,0),"") | P9: TN | Q9: =IFERROR(IFERROR(VLOOKUP(A9,TRAOPE!$A:$U,21,0),VLOOKUP(B9,TRAOPE!$A:$U,21,0)),"") | R9: =IFERROR(IFERROR(VLOOKUP(A9,TRAOPE!$A:$W,23,0),VLOOKUP(B9,TRAOPE!$A:$W,23,0)),"") | S9: =IF(AND(P9="TN",R9="TN"),N9+N(O9),IF(G9&""="1",N(K9)*N9,(N9+N(O9))*N(K9))) | T9: =IF(Q9="","",Q9-S9)
A10: =CONCATENATE(C10,E10,F10,I10) | B10: =CONCATENATE(C10,E10,I10) | C10: 900001005 | D10: =IFERROR(VLOOKUP(C10,TRAOPE!$G:$H,2,0),"") | E10: DW60 | F10: D003 | G10: =IFERROR(VLOOKUP(A10,Flete!$A:$E,5,0),"") | H10: =IFERROR(VLOOKUP(F10,TRAOPE!$AA:$AB,2,0),"") | I10: 10145710 | J10: =IFERROR(VLOOKUP(I10,Materiales!$A:$H,8,0),"") | K10: =IFERROR(VLOOKUP(I10,Materiales!$A:$G,7,0),"") | L10: 20210620 | M10: 20251031 | N10: 46.94 | O10: =IFERROR(VLOOKUP(A10,Flete!$A:$J,10,0),"") | P10: TN | Q10: =IFERROR(IFERROR(VLOOKUP(A10,TRAOPE!$A:$U,21,0),VLOOKUP(B10,TRAOPE!$A:$U,21,0)),"") | R10: =IFERROR(IFERROR(VLOOKUP(A10,TRAOPE!$A:$W,23,0),VLOOKUP(B10,TRAOPE!$A:$W,23,0)),"") | S10: =IF(AND(P10="TN",R10="TN"),N10+N(O10),IF(G10&""="1",N(K10)*N10,(N10+N(O10))*N(K10))) | T10: =IF(Q10="","",Q10-S10)
A11: =CONCATENATE(C11,E11,F11,I11) | B11: =CONCATENATE(C11,E11,I11) | C11: 900001005 | D11: =IFERROR(VLOOKUP(C11,TRAOPE!$G:$H,2,0),"") | E11: DW60 | F11: D041 | G11: =IFERROR(VLOOKUP(A11,Flete!$A:$E,5,0),"") | H11: =IFERROR(VLOOKUP(F11,TRAOPE!$AA:$AB,2,0),"") | I11: 10031864 | J11: =IFERROR(VLOOKUP(I11,Materiales!$A:$H,8,0),"") | K11: =IFERROR(VLOOKUP(I11,Materiales!$A:$G,7,0),"") | L11: 20210620 | M11: 20251031 | N11: 83.7 | O11: =IFERROR(VLOOKUP(A11,Flete!$A:$J,10,0),"") | P11: TN | Q11: =IFERROR(IFERROR(VLOOKUP(A11,TRAOPE!$A:$U,21,0),VLOOKUP(B11,TRAOPE!$A:$U,21,0)),"") | R11: =IFERROR(IFERROR(VLOOKUP(A11,TRAOPE!$A:$W,23,0),VLOOKUP(B11,TRAOPE!$A:$W,23,0)),"") | S11: =IF(AND(P11="TN",R11="TN"),N11+N(O11),IF(G11&""="1",N(K11)*N11,(N11+N(O11))*N(K11))) | T11: =IF(Q11="","",Q11-S11)
A12: =CONCATENATE(C12,E12,F12,I12) | B12: =CONCATENATE(C12,E12,I12) | C12: 900001005 | D12: =IFERROR(VLOOKUP(C12,TRAOPE!$G:$H,2,0),"") | E12: DW60 | F12: D041 | G12: =IFERROR(VLOOKUP(A12,Flete!$A:$E,5,0),"") | H12: =IFERROR(VLOOKUP(F12,TRAOPE!$AA:$AB,2,0),"") | I12: 10145710 | J12: =IFERROR(VLOOKUP(I12,Materiales!$A:$H,8,0),"") | K12: =IFERROR(VLOOKUP(I12,Materiales!$A:$G,7,0),"") | L12: 20210620 | M12: 20251031 | N12: 90.62 | O12: =IFERROR(VLOOKUP(A12,Flete!$A:$J,10,0),"") | P12: TN | Q12: =IFERROR(IFERROR(VLOOKUP(A12,TRAOPE!$A:$U,21,0),VLOOKUP(B12,TRAOPE!$A:$U,21,0)),"") | R12: =IFERROR(IFERROR(VLOOKUP(A12,TRAOPE!$A:$W,23,0),VLOOKUP(B12,TRAOPE!$A:$W,23,0)),"") | S12: =IF(AND(P12="TN",R12="TN"),N12+N(O12),IF(G12&""="1",N(K12)*N12,(N12+N(O12))*N(K12))) | T12: =IF(Q12="","",Q12-S12)
A13: =CONCATENATE(C13,E13,F13,I13) | B13: =CONCATENATE(C13,E13,I13) | C13: 900002941 | D13: =IFERROR(VLOOKUP(C13,TRAOPE!$G:$H,2,0),"") | E13: DW60 | F13: D003 | G13: =IFERROR(VLOOKUP(A13,Flete!$A:$E,5,0),"") | H13: =IFERROR(VLOOKUP(F13,TRAOPE!$AA:$AB,2,0),"") | I13: 10048106 | J13: =IFERROR(VLOOKUP(I13,Materiales!$A:$H,8,0),"") | K13: =IFERROR(VLOOKUP(I13,Materiales!$A:$G,7,0),"") | L13: 20210620 | M13: 20251031 | N13: 85.61 | O13: =IFERROR(VLOOKUP(A13,Flete!$A:$J,10,0),"") | P13: TN | Q13: =IFERROR(IFERROR(VLOOKUP(A13,TRAOPE!$A:$U,21,0),VLOOKUP(B13,TRAOPE!$A:$U,21,0)),"") | R13: =IFERROR(IFERROR(VLOOKUP(A13,TRAOPE!$A:$W,23,0),VLOOKUP(B13,TRAOPE!$A:$W,23,0)),"") | S13: =IF(AND(P13="TN",R13="TN"),N13+N(O13),IF(G13&""="1",N(K13)*N13,(N13+N(O13))*N(K13))) | T13: =IF(Q13="","",Q13-S13)
A14: =CONCATENATE(C14,E14,F14,I14) | B14: =CONCATENATE(C14,E14,I14) | C14: 900002941 | D14: =IFERROR(VLOOKUP(C14,TRAOPE!$G:$H,2,0),"") | E14: DW60 | F14: D003 | G14: =IFERROR(VLOOKUP(A14,Flete!$A:$E,5,0),"") | H14: =IFERROR(VLOOKUP(F14,TRAOPE!$AA:$AB,2,0),"") | I14: 10074117 | J14: =IFERROR(VLOOKUP(I14,Materiales!$A:$H,8,0),"") | K14: =IFERROR(VLOOKUP(I14,Materiales!$A:$G,7,0),"") | L14: 20210620 | M14: 20251031 | N14: 71.11 | O14: =IFERROR(VLOOKUP(A14,Flete!$A:$J,10,0),"") | P14: TN | Q14: =IFERROR(IFERROR(VLOOKUP(A14,TRAOPE!$A:$U,21,0),VLOOKUP(B14,TRAOPE!$A:$U,21,0)),"") | R14: =IFERROR(IFERROR(VLOOKUP(A14,TRAOPE!$A:$W,23,0),VLOOKUP(B14,TRAOPE!$A:$W,23,0)),"") | S14: =IF(AND(P14="TN",R14="TN"),N14+N(O14),IF(G14&""="1",N(K14)*N14,(N14+N(O14))*N(K14))) | T14: =IF(Q14="","",Q14-S14)
... A70: =CONCATENATE(C70,E70,F70,I70) | B70: =CONCATENATE(C70,E70,I70) | C70: 900009440 | D70: =IFERROR(VLOOKUP(C70,TRAOPE!$G:$H,2,0),"") | E70: DW60 | F70: D041 | G70: =IFERROR(VLOOKUP(A70,Flete!$A:$E,5,0),"") | H70: =IFERROR(VLOOKUP(F70,TRAOPE!$AA:$AB,2,0),"") | I70: 10188535 | J70: =IFERROR(VLOOKUP(I70,Materiales!$A:$H,8,0),"") | K70: =IFERROR(VLOOKUP(I70,Materiales!$A:$G,7,0),"") | L70: 20260315 | M70: 99991231 | N70: 108.76 | O70: =IFERROR(VLOOKUP(A70,Flete!$A:$J,10,0),"") | P70: TN | Q70: =IFERROR(IFERROR(VLOOKUP(A70,TRAOPE!$A:$U,21,0),VLOOKUP(B70,TRAOPE!$A:$U,21,0)),"") | R70: =IFERROR(IFERROR(VLOOKUP(A70,TRAOPE!$A:$W,23,0),VLOOKUP(B70,TRAOPE!$A:$W,23,0)),"") | S70: =IF(AND(P70="TN",R70="TN"),N70+N(O70),IF(G70&""="1",N(K70)*N70,(N70+N(O70))*N(K70))) | T70: =IF(Q70="","",Q70-S70)

Sheet MP
A1: No. SF | B1: Cedis | C1: Destino | D1: No. Material | E1: Nombre Material | F1: Importe MP | G1: Moneda | H1: Cantidad | I1: UM | J1: C | K1: Inicio Vigencia | L1: Fin Vigencia
A2: 900000529 | B2: DW60 | C2: D006 | D2: 10000531 | F2: 71.43 | I2: TN | K2: 20210620 | L2: 20251031
A3: 900000529 | B3: DW60 | C3: D006 | D3: 10170258 | F3: 57.37 | I3: TN | K3: 20210620 | L3: 20251031
A4: 900000529 | B4: DW60 | C4: D006 | D4: 10170354 | F4: 69.23 | I4: TN | K4: 20210620 | L4: 20251031
A5: 900000529 | B5: DW60 | C5: D006 | D5: 10188535 | F5: 58.66 | I5: TN | K5: 20250513 | L5: 99991231
A6: 900000529 | B6: DW60 | C6: D041 | D6: 10170258 | F6: 57.37 | I6: TN | K6: 20210620 | L6: 20251031
A7: 900000529 | B7: DW60 | C7: D041 | D7: 10170354 | F7: 69.23 | I7: TN | K7: 20210620 | L7: 20251031
A8: 900001005 | B8: DW60 | C8: D003 | D8: 10031864 | F8: 68 | I8: TN | K8: 20210620 | L8: 20251031
A9: 900001005 | B9: DW60 | C9: D003 | D9: 10145710 | F9: 46.94 | I9: TN | K9: 20210620 | L9: 20251031
A10: 900001005 | B10: DW60 | C10: D041 | D10: 10031864 | F10: 83.7 | I10: TN | K10: 20210620 | L10: 20251031
A11: 900001005 | B11: DW60 | C11: D041 | D11: 10145710 | F11: 90.62 | I11: TN | K11: 20210620 | L11: 20251031
A12: 900002941 | B12: DW60 | C12: D003 | D12: 10048106 | F12: 85.61 | I12: TN | K12: 20210620 | L12: 20251031
A13: 900002941 | B13: DW60 | C13: D003 | D13: 10074117 | F13: 71.11 | I13: TN | K13: 20210620 | L13: 20251031
... A69: 900009440 | B69: DW60 | C69: D041 | D69: 10188535 | F69: 108.76 | I69: TN | K69: 20260315 | L69: 99991231

Sheet Flete
A1: Concat1 | B1: No. SF | C1: Cedis | D1: Destino | E1: Cond. Exp. | F1: Material | H1: Nombre Material | J1: Importe Flete | K1: Moneda | L1: Cantidad | M1: UM | N1: C | P1: Inicio Vigencia | Q1: Fin Vigencia
A2: 900000529DW60D00610000531 | B2: 900000529 | C2: DW60 | D2: D006 | E2: 4 | F2: 10000531 | J2: 64.94 | M2: TN | P2: 20210620 | Q2: 20251031
A3: 900000529DW60D00610170258 | B3: 900000529 | C3: DW60 | D3: D006 | E3: 4 | F3: 10170258 | J3: 65.79 | M3: TN | P3: 20210620 | Q3: 20251031
A4: 900000529DW60D00610170354 | B4: 900000529 | C4: DW60 | D4: D006 | E4: 4 | F4: 10170354 | J4: 92.31 | M4: TN | P4: 20210620 | Q4: 20251031
A5: 900000529DW60D00610188535 | B5: 900000529 | C5: DW60 | D5: D006 | E5: 4 | F5: 10188535 | J5: 73.32 | M5: TN | P5: 20250513 | Q5: 99991231
A6: 900000529DW60D04110170258 | B6: 900000529 | C6: DW60 | D6: D041 | E6: 4 | F6: 10170258 | J6: 65.79 | M6: TN | P6: 20210620 | Q6: 20251031
A7: 900000529DW60D04110170354 | B7: 900000529 | C7: DW60 | D7: D041 | E7: 4 | F7: 10170354 | J7: 92.31 | M7: TN | P7: 20210620 | Q7: 20251031
A8: 900001005DW60D00310031864 | B8: 900001005 | C8: DW60 | D8: D003 | E8: 1 | F8: 10031864 | J8: 74.07 | M8: TN | P8: 20210620 | Q8: 20251031
A9: 900001005DW60D00310145710 | B9: 900001005 | C9: DW60 | D9: D003 | E9: 4 | F9: 10145710 | J9: 81.64 | M9: TN | P9: 20210620 | Q9: 20251031
A10: 900001005DW60D04110031864 | B10: 900001005 | C10: DW60 | D10: D041 | E10: 4 | F10: 10031864 | J10: 105.19 | M10: TN | P10: 20210620 | Q10: 20251031
A11: 900001005DW60D04110145710 | B11: 900001005 | C11: DW60 | D11: D041 | E11: 4 | F11: 10145710 | J11: 97.96 | M11: TN | P11: 20210620 | Q11: 20251031
A12: 900002941DW60D00310133158 | B12: 900002941 | C12: DW60 | D12: D003 | E12: 4 | F12: 10133158 | J12: 58.14 | M12: TN | P12: 20210620 | Q12: 20251031
A13: 900002941DW60D04110133158 | B13: 900002941 | C13: DW60 | D13: D041 | E13: 4 | F13: 10133158 | J13: 71.06 | M13: TN | P13: 20210620 | Q13: 20251031
... A68: 900009440DW60D04110188535 | B68: 900009440 | C68: DW60 | D68: D041 | E68: 4 | F68: 10188535 | J68: 78.63 | M68: TN | P68: 20260315 | Q68: 99991231

Sheet Materiales
A1: Material | B1: TpMt | C1: Denom | D1: UMA | E1: Contador | F1: UMB | G1: PV | H1: Nombre Material
A2: 10000001 | B2: ZFER | C2: 1000 | D2: M3 | E2: 1000 | F2: TN | G2: 1262 | H2: GRAVA ANDESITA 10 MM (3/8")
A3: 10000003 | B3: ZFER | C3: 1000 | D3: M3 | E3: 1000 | F3: TN | G3: 1443 | H3: GRAVA CALIZA 10 MM (3/8")
A4: 10000006 | B4: ZFER | C4: 1000 | D4: M3 | E4: 1000 | F4: TN | G4: 1490 | H4: GRAVA RIO 10 MM (3/8")
A5: 10000007 | B5: ZFER | C5: 1000 | D5: M3 | E5: 1000 | F5: TN | G5: 1488 | H5: GRAVA BASALTO 13 MM (1/2")
A6: 10000008 | B6: ZFER | C6: 1000 | D6: M3 | E6: 1000 | F6: TN | G6: 1358 | H6: GRAVA CALIZA 13 MM (1/2")
A7: 10000011 | B7: ZFER | C7: 1000 | D7: M3 | E7: 1000 | F7: TN | G7: 1323 | H7: GRAVA ANDESITA 20 MM (3/4")
A8: 10000013 | B8: ZFER | C8: 1000 | D8: M3 | E8: 1000 | F8: TN | G8: 1514 | H8: GRAVA BASALTO 20 MM (3/4")
A9: 10000014 | B9: ZFER | C9: 1000 | D9: M3 | E9: 1000 | F9: TN | G9: 1400 | H9: GRAVA CALIZA 20 MM (3/4")
A10: 10000015 | B10: ZFER | C10: 1000 | D10: M3 | E10: 1000 | F10: TN | G10: 1410 | H10: GRAVA GRANITO 20 MM (3/4")
A11: 10000017 | B11: ZFER | C11: 1000 | D11: M3 | E11: 1000 | F11: TN | G11: 1475 | H11: GRAVA RIOLITA 20 MM (3/4")
A12: 10000019 | B12: ZFER | C12: 1000 | D12: M3 | E12: 1000 | F12: TN | G12: 1515 | H12: GRAVA RIO 20 MM (3/4")
A13: 10000020 | B13: ZFER | C13: 1000 | D13: M3 | E13: 1 | F13: TN | G13: 1 | H13: GRAVA MAQUILA 40MM (1 1/2")
... A2291: 10268770 | B2291: ZFE3 | C2291: 1000 | D2291: M3 | E2291: 1000 | F2291: TN | G2291: 1240 | H2291: MP GRAVA TRIT CALIZA 40MM 1 1/2" - ESP
A2292: 10268901 | B2292: ZFE3 | C2292: 1000 | D2292: M3 | E2292: 1000 | G2292: 1560 | H2292: MP GRAVA ANDESITA GRIS 3/4" - CAPADA
A2293: 10267983 | C2293: 1000 | G2293: 1800 | H2293: ESCORIA ALTO HORNO 3/4
A2294: 10268996 | C2294: 1000 | G2294: 1329 | H2294: GRAVA TRITURADA CALIZA 40 MM - 11/2"
A2295: 10269072 | C2295: 1000 | G2295: 1700 | H2295: BASE HIDRÁULICA SCREEN
A2296: 10269225 | B2296: ZFE3 | C2296: 1000 | D2296: M3 | E2296: 1000 | G2296: 1289 | H2296: MP ARENA CALIZA LAVADA MALLA 4 - DELTA I
A2297: 10269245 | B2297: ZFE3 | C2297: 1000 | D2297: M3 | E2297: 1000 | G2297: 1410 | H2297: MP GRAVA TRITURADA CALIZA 3/8 - 10MM
A2298: 10269246 | B2298: ZFE3 | C2298: 1000 | D2298: M3 | E2298: 1000 | G2298: 1400 | H2298: MP GRAVA TRITURADA CALIZA 1 1/2 - 40MM
A2299: 10269247 | B2299: ZFE3 | C2299: 1000 | D2299: M3 | E2299: 1000 | G2299: 1560 | H2299: MP ARENA TRIT CALIZA M-4
A2300: 10270431 | B2300: ZFE3 | C2300: 1000 | D2300: M3 | E2300: 1000 | G2300: 1423 | H2300: MP GRAVA RIOLITA 13 MM - 1/2"
A2301: 10270898 | B2301: ZFE3 | C2301: 1000 | D2301: M3 | E2301: 1000 | G2301: 1551 | H2301: MP BASE H. TRIT. BASALTO 1 1/2" A FINOS
A2302: 10270911 | B2302: ZFE3 | C2302: 1000 | D2302: M3 | E2302: 1000 | G2302: 1360 | H2302: MP GRAVA TRIT. BASALTO 40 MM - 1 1/2"
A2303: 10270912 | B2303: ZFE3 | C2303: 1000 | D2303: M3 | E2303: 1000 | G2303: 1589 | H2303: MP ARENA TRIT. BASALTO MALLA 4
A2304: 10270913 | B2304: ZFE3 | C2304: 1000 | D2304: M3 | E2304: 1000 | G2304: 1395 | H2304: MP GRAVA TRIT. BASALTO 20 MM - 3/4
A2305: 10270914 | B2305: ZFE3 | C2305: 1000 | D2305: M3 | E2305: 1000 | G2305: 1623 | H2305: MP ARENA ANDESITA BC
A2306: 10270824 | B2306: M3 | C2306: 1000 | D2306: M3 | E2306: 10007640 | G2306: 1325 | H2306: MP ARENA TRITURADA CALIZA MALLA 5
A2307: 10270825 | B2307: M3 | C2307: 1000 | D2307: M3 | E2307: 10000003 | G2307: 1242 | H2307: MP GRAVA TRITURADA CALIZA 10MM (3/8”)
... A2319: 10272527 | B2319: ZFE3 | C2319: 1000 | D2319: M3 | E2319: 1000 | G2319: 1620 | H2319: CNC - NO CLASIFICADO
A2320: 10000332 | C2320: 1000 | D2320: M3 | E2320: 1000 | G2320: 800 | H2320: Grava Triturada Pomez - Jal 20 mm - 3/4"
A2321: 10273001 | B2321: ZFE3 | C2321: 1000 | D2321: M3 | E2321: 1000 | G2321: 1688 | H2321: MP ARENA TRIT. BASALTO MALLA 4
A2322: 10273002 | B2322: ZFE3 | C2322: 1000 | D2322: M3 | E2322: 1000 | G2322: 1466 | H2322: MP GRAVA TRIT. BASALTO 20 MM - 3/4"
A2323: 10273351 | B2323: ZFE3 | C2323: 1000 | D2323: M3 | E2323: 1000 | G2323: 1612 | H2323: MP ARENA TRIT. CALIZA MALLA 4
A2324: 10273352 | B2324: ZFE3 | C2324: 1000 | D2324: M3 | E2324: 1000 | G2324: 1492 | H2324: MP GRAVA TRIT. CALIZA 20 MM - 3/4"
A2325: 10271724 | B2325: ZFE3 | C2325: 1000 | D2325: M3 | E2325: 1000 | G2325: 1900 | H2325: MP RESIDUO DE CONCRETO
A2326: 10000677 | C2326: 1000 | D2326: M3 | G2326: 1164 | H2326: Grava Triturada Caliza 20 mm - 3/4"
A2327: 10274190 | B2327: ZFE3 | C2327: 1000 | D2327: M3 | E2327: 1000 | G2327: 1800 | H2327: MP BASE HIDRAULICA ANDESITA 70-30
A2328: 10274601 | B2328: ZFE3 | C2328: 1000 | D2328: M3 | E2328: 1000 | G2328: 1447 | H2328: MP ARENA BASALTO N° 4
...

Sheet TRAOPE
A1: Concat1 | B1: Contrato_Pos | C1: Doc. Compras | D1: Pos | E1: Org.compras | F1: Grp-Compr. | G1: Ship From | H1: Nombre SF | I1: Proveedor | J1: Nombre Prov | K1: Cond. Pago | L1: Descr. Cond Pago | M1: Material | N1: Descripción | O1: Centro | P1: Descripción Centro | Q1: In.perído validez | R1: Fin perído validez | S1: Válido de | T1: Validez a | U1: Precio neto pedido | V1: Moneda | W1: UM Precio Pedido | X1: Importe Condición | Y1: Moneda KONP | Z1: UM Ctd Base | AA1: Destino | AB1: Nombre Destino | AC1: Cuenta de mayor | AD1: Centro de costo | AE1: Cond. Exp. | AF1: Descr. Cond. Exp. | AG1: Peso Vol. | AH1: UMB | AI1: Ind. Oblig. Conf. Ped. | AJ1: Ctrl-Conf. | AK1: IVA | AL1: Modif_Date | AM1: Ruta
A2: 900005108DW60D04110062295 | B2: 4600055399-40 | C2: 4600055399 | D2: 40 | E2: MXPO | F2: MXL | G2: 900005108 | H2: TC-ED- LOGISTICA Y CONSTRUCCIONES | I2: 5066603 | J2: LOGÍSTICA Y CONSTRUCCIONES DE SONOR | K2: N90 | L2: (AP) NAFIN 90 Dias | M2: 10062295 | N2: GRAVA TRITURADA BASALTO 10 MM - 3/8" | O2: DW60 | P2: MX-CED. OBREGON | Q2: 20221001 | R2: 20281231 | S2: 20250601 | T2: 20301231 | U2: 250 | V2: MXN | W2: M3 | X2: 110 | Y2: MXN | Z2: M3 | AA2: D041 | AB2: PD0342 CONSTELLATION CD.OBREGON | AC2: 56103637 | AD2: 6644131540 | AE2: 4 | AF2: ENTREGA DIRECTA | AG2: 1.539 | AH2: M3 | AI2: X | AJ2: 4 | AK2: V4 | AL2: 20250619 | AM2: DW60-900005108-D041-10062295-4
A3: 900005108DW60D04110062252 | B3: 4600055399-80 | C3: 4600055399 | D3: 80 | E3: MXPO | F3: MXL | G3: 900005108 | H3: TC-ED- LOGISTICA Y CONSTRUCCIONES | I3: 5066603 | J3: LOGÍSTICA Y CONSTRUCCIONES DE SONOR | K3: N90 | L3: (AP) NAFIN 90 Dias | M3: 10062252 | N3: GRAVA TRITURADA BASALTO 40 MM - 1 1/2" | O3: DW60 | P3: MX-CED. OBREGON | Q3: 20221001 | R3: 20281231 | S3: 20250601 | T3: 20301231 | U3: 249 | V3: MXN | W3: M3 | X3: 110 | Y3: MXN | Z3: M3 | AA3: D041 | AB3: PD0342 CONSTELLATION CD.OBREGON | AC3: 56103637 | AD3: 6644131540 | AE3: 4 | AF3: ENTREGA DIRECTA | AG3: 1.38 | AH3: M3 | AI3: X | AJ3: 4 | AK3: V4 | AL3: 20250619 | AM3: DW60-900005108-D041-10062252-4
A4: 900005108DW60D00610062296 | B4: 4600055399-20 | C4: 4600055399 | D4: 20 | E4: MXPO | F4: MXL | G4: 900005108 | H4: TC-ED- LOGISTICA Y CONSTRUCCIONES | I4: 5066603 | J4: LOGÍSTICA Y CONSTRUCCIONES DE SONOR | K4: N90 | L4: (AP) NAFIN 90 Dias | M4: 10062296 | N4: GRAVA TRITURADA CALIZA 20 MM - 3/4" | O4: DW60 | P4: MX-CED. OBREGON | Q4: 20221001 | R4: 20281231 | S4: 20250601 | T4: 20301231 | U4: 253 | V4: MXN | W4: M3 | X4: 110 | Y4: MXN | Z4: M3 | AA4: D006 | AB4: PD0214 CD.OBREGON | AC4: 56103637 | AD4: 6644131540 | AE4: 4 | AF4: ENTREGA DIRECTA | AG4: 1.517 | AH4: M3 | AI4: X | AJ4: 4 | AK4: V4 | AL4: 20250619 | AM4: DW60-900005108-D006-10062296-4
A5: 900005108DW60D00610062253 | B5: 4600055399-30 | C5: 4600055399 | D5: 30 | E5: MXPO | F5: MXL | G5: 900005108 | H5: TC-ED- LOGISTICA Y CONSTRUCCIONES | I5: 5066603 | J5: LOGÍSTICA Y CONSTRUCCIONES DE SONOR | K5: N90 | L5: (AP) NAFIN 90 Dias | M5: 10062253 | N5: ARENA CLASIFICADA BASALTO MALLA 4 | O5: DW60 | P5: MX-CED. OBREGON | Q5: 20221001 | R5: 20281231 | S5: 20250601 | T5: 20301231 | U5: 260 | V5: MXN | W5: M3 | X5: 110 | Y5: MXN | Z5: M3 | AA5: D006 | AB5: PD0214 CD.OBREGON | AC5: 56103638 | AD5: 6644131540 | AE5: 4 | AF5: ENTREGA DIRECTA | AG5: 1.515 | AH5: M3 | AI5: X | AJ5: 4 | AK5: V4 | AL5: 20250619 | AM5: DW60-900005108-D006-10062253-4
A6: 900005108DW60D04110062253 | B6: 4600055399-60 | C6: 4600055399 | D6: 60 | E6: MXPO | F6: MXL | G6: 900005108 | H6: TC-ED- LOGISTICA Y CONSTRUCCIONES | I6: 5066603 | J6: LOGÍSTICA Y CONSTRUCCIONES DE SONOR | K6: N90 | L6: (AP) NAFIN 90 Dias | M6: 10062253 | N6: ARENA CLASIFICADA BASALTO MALLA 4 | O6: DW60 | P6: MX-CED. OBREGON | Q6: 20221001 | R6: 20281231 | S6: 20250601 | T6: 20301231 | U6: 260 | V6: MXN | W6: M3 | X6: 110 | Y6: MXN | Z6: M3 | AA6: D041 | AB6: PD0342 CONSTELLATION CD.OBREGON | AC6: 56103638 | AD6: 6644131540 | AE6: 4 | AF6: ENTREGA DIRECTA | AG6: 1.515 | AH6: M3 | AI6: X | AJ6: 4 | AK6: V4 | AL6: 20250619 | AM6: DW60-900005108-D041-10062253-4
A7: 900005108DW60D00610062252 | B7: 4600055399-70 | C7: 4600055399 | D7: 70 | E7: MXPO | F7: MXL | G7: 900005108 | H7: TC-ED- LOGISTICA Y CONSTRUCCIONES | I7: 5066603 | J7: LOGÍSTICA Y CONSTRUCCIONES DE SONOR | K7: N90 | L7: (AP) NAFIN 90 Dias | M7: 10062252 | N7: GRAVA TRITURADA BASALTO 40 MM - 1 1/2" | O7: DW60 | P7: MX-CED. OBREGON | Q7: 20221001 | R7: 20281231 | S7: 20250601 | T7: 20301231 | U7: 249 | V7: MXN | W7: M3 | X7: 110 | Y7: MXN | Z7: M3 | AA7: D006 | AB7: PD0214 CD.OBREGON | AC7: 56103637 | AD7: 6644131540 | AE7: 4 | AF7: ENTREGA DIRECTA | AG7: 1.38 | AH7: M3 | AI7: X | AJ7: 4 | AK7: V4 | AL7: 20250619 | AM7: DW60-900005108-D006-10062252-4
A8: 900005108DW60D00610062295 | B8: 4600055399-10 | C8: 4600055399 | D8: 10 | E8: MXPO | F8: MXL | G8: 900005108 | H8: TC-ED- LOGISTICA Y CONSTRUCCIONES | I8: 5066603 | J8: LOGÍSTICA Y CONSTRUCCIONES DE SONOR | K8: N90 | L8: (AP) NAFIN 90 Dias | M8: 10062295 | N8: GRAVA TRITURADA BASALTO 10 MM - 3/8" | O8: DW60 | P8: MX-CED. OBREGON | Q8: 20221001 | R8: 20281231 | S8: 20250601 | T8: 20301231 | U8: 250 | V8: MXN | W8: M3 | X8: 110 | Y8: MXN | Z8: M3 | AA8: D006 | AB8: PD0214 CD.OBREGON | AC8: 56103637 | AD8: 6644131540 | AE8: 4 | AF8: ENTREGA DIRECTA | AG8: 1.539 | AH8: M3 | AI8: X | AJ8: 4 | AK8: V4 | AL8: 20250619 | AM8: DW60-900005108-D006-10062295-4
A9: 900005108DW60D04110062296 | B9: 4600055399-50 | C9: 4600055399 | D9: 50 | E9: MXPO | F9: MXL | G9: 900005108 | H9: TC-ED- LOGISTICA Y CONSTRUCCIONES | I9: 5066603 | J9: LOGÍSTICA Y CONSTRUCCIONES DE SONOR | K9: N90 | L9: (AP) NAFIN 90 Dias | M9: 10062296 | N9: GRAVA TRITURADA CALIZA 20 MM - 3/4" | O9: DW60 | P9: MX-CED. OBREGON | Q9: 20221001 | R9: 20281231 | S9: 20250601 | T9: 20301231 | U9: 253 | V9: MXN | W9: M3 | X9: 110 | Y9: MXN | Z9: M3 | AA9: D041 | AB9: PD0342 CONSTELLATION CD.OBREGON | AC9: 56103637 | AD9: 6644131540 | AE9: 4 | AF9: ENTREGA DIRECTA | AG9: 1.517 | AH9: M3 | AI9: X | AJ9: 4 | AK9: V4 | AL9: 20250619 | AM9: DW60-900005108-D041-10062296-4
A10: 900008178DW60D00310170354 | B10: 4600057683-100 | C10: 4600057683 | D10: 100 | E10: MXPO | F10: MXL | G10: 900008178 | H10: SF TC-ED-JESUS VAZQUEZ | I10: 5087050 | J10: VAZQUEZ AYON JESUS CARLOS | K10: E90 | L10: (AP) E-FACTOR 90 Dias | M10: 10170354 | N10: GRAVA TRITURADA RIO 40 MM - 1 1/2" | O10: DW60 | P10: MX-CED. OBREGON | Q10: 20230602 | R10: 20291231 | S10: 20250416 | T10: 20301231 | U10: 574.34 | V10: MXN | W10: M3 | X10: 400 | Y10: MXN | Z10: M3 | AA10: D003 | AB10: PD0146 GUAYMAS I | AC10: 56103637 | AD10: 6644131540 | AE10: 4 | AF10: ENTREGA DIRECTA | AG10: 1.3 | AH10: M3 | AI10: X | AJ10: 4 | AK10: V4 | AL10: 20250417 | AM10: DW60-900008178-D003-10170354-4
A11: 900008178DW60D00310170258 | B11: 4600057683-90 | C11: 4600057683 | D11: 90 | E11: MXPO | F11: MXL | G11: 900008178 | H11: SF TC-ED-JESUS VAZQUEZ | I11: 5087050 | J11: VAZQUEZ AYON JESUS CARLOS | K11: E90 | L11: (AP) E-FACTOR 90 Dias | M11: 10170258 | N11: GRAVA CLASIFICADA RÍO 20 MM - 3/4" | O11: DW60 | P11: MX-CED. OBREGON | Q11: 20230602 | R11: 20291231 | S11: 20250416 | T11: 20301231 | U11: 546.76 | V11: MXN | W11: M3 | X11: 400 | Y11: MXN | Z11: M3 | AA11: D003 | AB11: PD0146 GUAYMAS I | AC11: 56103637 | AD11: 6644131540 | AE11: 4 | AF11: ENTREGA DIRECTA | AG11: 1.52 | AH11: M3 | AI11: X | AJ11: 4 | AK11: V4 | AL11: 20250417 | AM11: DW60-900008178-D003-10170258-4
A12: 900009440DW60D00310170258 | B12: 4600071865-90 | C12: 4600071865 | D12: 90 | E12: MXPO | F12: MXL | G12: 900009440 | H12: SF TC-ED AYON CARDENAS | I12: 5097343 | J12: AYON CARDENAS KARLA MERCEDES | K12: Z09 | L12: (AP) 90 Dias | M12: 10170258 | N12: GRAVA CLASIFICADA RÍO 20 MM - 3/4" | O12: DW60 | P12: MX-CED. OBREGON | Q12: 20251216 | R12: 20301231 | S12: 20251216 | T12: 20301231 | U12: 546.76 | V12: MXN | W12: M3 | X12: 400 | Y12: MXN | Z12: M3 | AA12: D003 | AB12: PD0146 GUAYMAS I | AC12: 56103637 | AD12: 6644131540 | AE12: 4 | AF12: ENTREGA DIRECTA | AG12: 1.52 | AH12: M3 | AI12: X | AJ12: 4 | AK12: V4 | AL12: 20251219 | AM12: DW60-900009440-D003-10170258-4
A13: 900009440DW60D00610188535 | B13: 4600071865-40 | C13: 4600071865 | D13: 40 | E13: MXPO | F13: MXL | G13: 900009440 | H13: SF TC-ED AYON CARDENAS | I13: 5097343 | J13: AYON CARDENAS KARLA MERCEDES | K13: Z09 | L13: (AP) 90 Dias | M13: 10188535 | N13: ARENA CLASIFICADA BASALTO MALLA 4 | O13: DW60 | P13: MX-CED. OBREGON | Q13: 20251216 | R13: 20301231 | S13: 20251216 | T13: 20301231 | U13: 244.6 | V13: MXN | W13: M3 | X13: 102.63 | Y13: MXN | Z13: M3 | AA13: D006 | AB13: PD0214 CD.OBREGON | AC13: 56103638 | AD13: 6644131540 | AE13: 4 | AF13: ENTREGA DIRECTA | AG13: 1.364 | AH13: M3 | AI13: X | AJ13: 4 | AK13: V4 | AL13: 20251219 | AM13: DW60-900009440-D006-10188535-4
... A46: 900009111DW60D00310017374 | B46: 4600070859-20 | C46: 4600070859 | D46: 20 | E46: MXPO | F46: MXL | G46: 900009111 | H46: SF TC-ED TIZATE AGREGADOS | I46: 5094962 | J46: EL TIZATE AGREGADOS S DE RL | K46: Z09 | L46: (AP) 90 Dias | M46: 10017374 | N46: Grava Triturada Caliza 20 mm - 3/4" | O46: DW60 | P46: MX-CED. OBREGON | Q46: 20250210 | R46: 20301231 | S46: 20250210 | T46: 20301231 | U46: 222 | V46: MXN | W46: M3 | X46: 60.5 | Y46: MXN | Z46: M3 | AA46: D003 | AB46: PD0146 GUAYMAS I | AC46: 56103637 | AD46: 6644131540 | AE46: 4 | AF46: ENTREGA DIRECTA | AG46: 1.379 | AH46: M3 | AI46: X | AJ46: 4 | AK46: V4 | AL46: 20250217 | AM46: DW60-900009111-D003-10017374-4
