Workbook

Sheet Base Cedis DW83
N1: VENTA | Q1: COSTO
A2: CONCAT1 | B2: CONCAT2 | C2: No. SF | D2: Nombre SF | E2: Cedis | F2: Destino | G2: Condicion de Expedicion | H2: Nombre Destino | I2: No. de material | J2: Nombre de material | K2: PV | L2: Inicio de vigencia | M2: Fin de vigencia | N2: Importe MP | O2: Importe Flete | P2: UM Venta | Q2: Importe Costo | R2: UM Costo | S2: Validacion 1 | T2: Validacion 2
A3: =CONCATENATE(C3,E3,F3,I3) | B3: =CONCATENATE(C3,E3,I3) | C3: 900000045 | D3: =IFERROR(VLOOKUP(C3,TRAOPE!$G:$H,2,0),"") | E3: DW83 | F3: D216 | G3: =IFERROR(VLOOKUP(A3,Flete!$A:$E,5,0),"") | H3: =IFERROR(VLOOKUP(F3,TRAOPE!$AA:$AB,2,0),"") | I3: 10000377 | J3: =IFERROR(VLOOKUP(I3,Materiales!$A:$H,8,0),"") | K3: =IFERROR(VLOOKUP(I3,Materiales!$A:$G,7,0),"") | L3: 20210620 | M3: 20251031 | N3: 107.59 | O3: =IFERROR(VLOOKUP(A3,Flete!$A:$J,10,0),"") | P3: TN | Q3: =IFERROR(IFERROR(VLOOKUP(A3,TRAOPE!$A:$U,21,0),VLOOKUP(B3,TRAOPE!$A:$U,21,0)),"") | R3: =IFERROR(IFERROR(VLOOKUP(A3,TRAOPE!$A:$W,23,0),VLOOKUP(B3,TRAOPE!$A:$W,23,0)),"") | S3: =IF(AND(P3="TN",R3="TN"),N3+N(O3),IF(G3&""="1",N(K3)*N3,(N3+N(O3))*N(K3))) | T3: =IF(Q3="","",Q3-S3)
A4: =CONCATENATE(C4,E4,F4,I4) | B4: =CONCATENATE(C4,E4,I4) | C4: 900000045 | D4: =IFERROR(VLOOKUP(C4,TRAOPE!$G:$H,2,0),"") | E4: DW83 | F4: D216 | G4: =IFERROR(VLOOKUP(A4,Flete!$A:$E,5,0),"") | H4: =IFERROR(VLOOKUP(F4,TRAOPE!$AA:$AB,2,0),"") | I4: 10000379 | J4: =IFERROR(VLOOKUP(I4,Materiales!$A:$H,8,0),"") | K4: =IFERROR(VLOOKUP(I4,Materiales!$A:$G,7,0),"") | L4: 20210620 | M4: 20251031 | N4: 119.23 | O4: =IFERROR(VLOOKUP(A4,Flete!$A:$J,10,0),"") | P4: TN | Q4: =IFERROR(IFERROR(VLOOKUP(A4,TRAOPE!$A:$U,21,0),VLOOKUP(B4,TRAOPE!$A:$U,21,0)),"") | R4: =IFERROR(IFERROR(VLOOKUP(A4,TRAOPE!$A:$W,23,0),VLOOKUP(B4,TRAOPE!$A:$W,23,0)),"") | S4: =IF(AND(P4="TN",R4="TN"),N4+N(O4),IF(G4&""="1",N(K4)*N4,(N4+N(O4))*N(K4))) | T4: =IF(Q4="","",Q4-S4)
A5: =CONCATENATE(C5,E5,F5,I5) | B5: =CONCATENATE(C5,E5,I5) | C5: 900000045 | D5: =IFERROR(VLOOKUP(C5,TRAOPE!$G:$H,2,0),"") | E5: DW83 | F5: D216 | G5: =IFERROR(VLOOKUP(A5,Flete!$A:$E,5,0),"") | H5: =IFERROR(VLOOKUP(F5,TRAOPE!$AA:$AB,2,0),"") | I5: 10000381 | J5: =IFERROR(VLOOKUP(I5,Materiales!$A:$H,8,0),"") | K5: =IFERROR(VLOOKUP(I5,Materiales!$A:$G,7,0),"") | L5: 20210620 | M5: 20251031 | N5: 69.97 | O5: =IFERROR(VLOOKUP(A5,Flete!$A:$J,10,0),"") | P5: TN | Q5: =IFERROR(IFERROR(VLOOKUP(A5,TRAOPE!$A:$U,21,0),VLOOKUP(B5,TRAOPE!$A:$U,21,0)),"") | R5: =IFERROR(IFERROR(VLOOKUP(A5,TRAOPE!$A:$W,23,0),VLOOKUP(B5,TRAOPE!$A:$W,23,0)),"") | S5: =IF(AND(P5="TN",R5="TN"),N5+N(O5),IF(G5&""="1",N(K5)*N5,(N5+N(O5))*N(K5))) | T5: =IF(Q5="","",Q5-S5)
A6: =CONCATENATE(C6,E6,F6,I6) | B6: =CONCATENATE(C6,E6,I6) | C6: 900000045 | D6: =IFERROR(VLOOKUP(C6,TRAOPE!$G:$H,2,0),"") | E6: DW83 | F6: D216 | G6: =IFERROR(VLOOKUP(A6,Flete!$A:$E,5,0),"") | H6: =IFERROR(VLOOKUP(F6,TRAOPE!$AA:$AB,2,0),"") | I6: 10000719 | J6: =IFERROR(VLOOKUP(I6,Materiales!$A:$H,8,0),"") | K6: =IFERROR(VLOOKUP(I6,Materiales!$A:$G,7,0),"") | L6: 20210620 | M6: 20251031 | N6: 79.92 | O6: =IFERROR(VLOOKUP(A6,Flete!$A:$J,10,0),"") | P6: TN | Q6: =IFERROR(IFERROR(VLOOKUP(A6,TRAOPE!$A:$U,21,0),VLOOKUP(B6,TRAOPE!$A:$U,21,0)),"") | R6: =IFERROR(IFERROR(VLOOKUP(A6,TRAOPE!$A:$W,23,0),VLOOKUP(B6,TRAOPE!$A:$W,23,0)),"") | S6: =IF(AND(P6="TN",R6="TN"),N6+N(O6),IF(G6&""="1",N(K6)*N6,(N6+N(O6))*N(K6))) | T6: =IF(Q6="","",Q6-S6)
A7: =CONCATENATE(C7,E7,F7,I7) | B7: =CONCATENATE(C7,E7,I7) | C7: 900000045 | D7: =IFERROR(VLOOKUP(C7,TRAOPE!$G:$H,2,0),"") | E7: DW83 | F7: D216 | G7: =IFERROR(VLOOKUP(A7,Flete!$A:$E,5,0),"") | H7: =IFERROR(VLOOKUP(F7,TRAOPE!$AA:$AB,2,0),"") | I7: 10192197 | J7: =IFERROR(VLOOKUP(I7,Materiales!$A:$H,8,0),"") | K7: =IFERROR(VLOOKUP(I7,Materiales!$A:$G,7,0),"") | L7: 20210620 | M7: 20251031 | N7: 76.39 | O7: =IFERROR(VLOOKUP(A7,Flete!$A:$J,10,0),"") | P7: TN | Q7: =IFERROR(IFERROR(VLOOKUP(A7,TRAOPE!$A:$U,21,0),VLOOKUP(B7,TRAOPE!$A:$U,21,0)),"") | R7: =IFERROR(IFERROR(VLOOKUP(A7,TRAOPE!$A:$W,23,0),VLOOKUP(B7,TRAOPE!$A:$W,23,0)),"") | S7: =IF(AND(P7="TN",R7="TN"),N7+N(O7),IF(G7&""="1",N(K7)*N7,(N7+N(O7))*N(K7))) | T7: =IF(Q7="","",Q7-S7)
A8: =CONCATENATE(C8,E8,F8,I8) | B8: =CONCATENATE(C8,E8,I8) | C8: 900000045 | D8: =IFERROR(VLOOKUP(C8,TRAOPE!$G:$H,2,0),"") | E8: DW83 | F8: D243 | G8: =IFERROR(VLOOKUP(A8,Flete!$A:$E,5,0),"") | H8: =IFERROR(VLOOKUP(F8,TRAOPE!$AA:$AB,2,0),"") | I8: 10000379 | J8: =IFERROR(VLOOKUP(I8,Materiales!$A:$H,8,0),"") | K8: =IFERROR(VLOOKUP(I8,Materiales!$A:$G,7,0),"") | L8: 20230301 | M8: 20250129 | N8: 119.23 | O8: =IFERROR(VLOOKUP(A8,Flete!$A:$J,10,0),"") | P8: TN | Q8: =IFERROR(IFERROR(VLOOKUP(A8,TRAOPE!$A:$U,21,0),VLOOKUP(B8,TRAOPE!$A:$U,21,0)),"") | R8: =IFERROR(IFERROR(VLOOKUP(A8,TRAOPE!$A:$W,23,0),VLOOKUP(B8,TRAOPE!$A:$W,23,0)),"") | S8: =IF(AND(P8="TN",R8="TN"),N8+N(O8),IF(G8&""="1",N(K8)*N8,(N8+N(O8))*N(K8))) | T8: =IF(Q8="","",Q8-S8)
A9: =CONCATENATE(C9,E9,F9,I9) | B9: =CONCATENATE(C9,E9,I9) | C9: 900000045 | D9: =IFERROR(VLOOKUP(C9,TRAOPE!$G:$H,2,0),"") | E9: DW83 | F9: D243 | G9: =IFERROR(VLOOKUP(A9,Flete!$A:$E,5,0),"") | H9: =IFERROR(VLOOKUP(F9,TRAOPE!$AA:$AB,2,0),"") | I9: 10000719 | J9: =IFERROR(VLOOKUP(I9,Materiales!$A:$H,8,0),"") | K9: =IFERROR(VLOOKUP(I9,Materiales!$A:$G,7,0),"") | L9: 20230301 | M9: 20250129 | N9: 91.54 | O9: =IFERROR(VLOOKUP(A9,Flete!$A:$J,10,0),"") | P9: TN | Q9: =IFERROR(IFERROR(VLOOKUP(A9,TRAOPE!$A:$U,21,0),VLOOKUP(B9,TRAOPE!$A:$U,21,0)),"") | R9: =IFERROR(IFERROR(VLOOKUP(A9,TRAOPE!$A:$W,23,0),VLOOKUP(B9,TRAOPE!$A:$W,23,0)),"") | S9: =IF(AND(P9="TN",R9="TN"),N9+N(O9),IF(G9&""="1",N(K9)*N9,(N9+N(O9))*N(K9))) | T9: =IF(Q9="","",Q9-S9)
A10: =CONCATENATE(C10,E10,F10,I10) | B10: =CONCATENATE(C10,E10,I10) | C10: 900000045 | D10: =IFERROR(VLOOKUP(C10,TRAOPE!$G:$H,2,0),"") | E10: DW83 | F10: D243 | G10: =IFERROR(VLOOKUP(A10,Flete!$A:$E,5,0),"") | H10: =IFERROR(VLOOKUP(F10,TRAOPE!$AA:$AB,2,0),"") | I10: 10192197 | J10: =IFERROR(VLOOKUP(I10,Materiales!$A:$H,8,0),"") | K10: =IFERROR(VLOOKUP(I10,Materiales!$A:$G,7,0),"") | L10: 20230301 | M10: 20250129 | N10: 76.39 | O10: =IFERROR(VLOOKUP(A10,Flete!$A:$J,10,0),"") | P10: TN | Q10: =IFERROR(IFERROR(VLOOKUP(A10,TRAOPE!$A:$U,21,0),VLOOKUP(B10,TRAOPE!$A:$U,21,0)),"") | R10: =IFERROR(IFERROR(VLOOKUP(A10,TRAOPE!$A:$W,23,0),VLOOKUP(B10,TRAOPE!$A:$W,23,0)),"") | S10: =IF(AND(P10="TN",R10="TN"),N10+N(O10),IF(G10&""="1",N(K10)*N10,(N10+N(O10))*N(K10))) | T10: =IF(Q10="","",Q10-S10)
A11: =CONCATENATE(C11,E11,F11,I11) | B11: =CONCATENATE(C11,E11,I11) | C11: 900000045 | D11: =IFERROR(VLOOKUP(C11,TRAOPE!$G:$H,2,0),"") | E11: DW83 | F11: D269 | G11: =IFERROR(VLOOKUP(A11,Flete!$A:$E,5,0),"") | H11: =IFERROR(VLOOKUP(F11,TRAOPE!$AA:$AB,2,0),"") | I11: 10000332 | J11: =IFERROR(VLOOKUP(I11,Materiales!$A:$H,8,0),"") | K11: =IFERROR(VLOOKUP(I11,Materiales!$A:$G,7,0),"") | L11: 20230203 | M11: 20240201 | N11: 327.5 | O11: =IFERROR(VLOOKUP(A11,Flete!$A:$J,10,0),"") | P11: TN | Q11: =IFERROR(IFERROR(VLOOKUP(A11,TRAOPE!$A:$U,21,0),VLOOKUP(B11,TRAOPE!$A:$U,21,0)),"") | R11: =IFERROR(IFERROR(VLOOKUP(A11,TRAOPE!$A:$W,23,0),VLOOKUP(B11,TRAOPE!$A:$W,23,0)),"") | S11: =IF(AND(P11="TN",R11="TN"),N11+N(O11),IF(G11&""="1",N(K11)*N11,(N11+N(O11))*N(K11))) | T11: =IF(Q11="","",Q11-S11)
A12: =CONCATENATE(C12,E12,F12,I12) | B12: =CONCATENATE(C12,E12,I12) | C12: 900000045 | D12: =IFERROR(VLOOKUP(C12,TRAOPE!$G:$H,2,0),"") | E12: DW83 | F12: D269 | G12: =IFERROR(VLOOKUP(A12,Flete!$A:$E,5,0),"") | H12: =IFERROR(VLOOKUP(F12,TRAOPE!$AA:$AB,2,0),"") | I12: 10000377 | J12: =IFERROR(VLOOKUP(I12,Materiales!$A:$H,8,0),"") | K12: =IFERROR(VLOOKUP(I12,Materiales!$A:$G,7,0),"") | L12: 20260601 | M12: 99991231 | N12: 94.88 | O12: =IFERROR(VLOOKUP(A12,Flete!$A:$J,10,0),"") | P12: TN | Q12: =IFERROR(IFERROR(VLOOKUP(A12,TRAOPE!$A:$U,21,0),VLOOKUP(B12,TRAOPE!$A:$U,21,0)),"") | R12: =IFERROR(IFERROR(VLOOKUP(A12,TRAOPE!$A:$W,23,0),VLOOKUP(B12,TRAOPE!$A:$W,23,0)),"") | S12: =IF(AND(P12="TN",R12="TN"),N12+N(O12),IF(G12&""="1",N(K12)*N12,(N12+N(O12))*N(K12))) | T12: =IF(Q12="","",Q12-S12)
A13: =CONCATENATE(C13,E13,F13,I13) | B13: =CONCATENATE(C13,E13,I13) | C13: 900000045 | D13: =IFERROR(VLOOKUP(C13,TRAOPE!$G:$H,2,0),"") | E13: DW83 | F13: D269 | G13: =IFERROR(VLOOKUP(A13,Flete!$A:$E,5,0),"") | H13: =IFERROR(VLOOKUP(F13,TRAOPE!$AA:$AB,2,0),"") | I13: 10000379 | J13: =IFERROR(VLOOKUP(I13,Materiales!$A:$H,8,0),"") | K13: =IFERROR(VLOOKUP(I13,Materiales!$A:$G,7,0),"") | L13: 20260601 | M13: 99991231 | N13: 144.17 | O13: =IFERROR(VLOOKUP(A13,Flete!$A:$J,10,0),"") | P13: TN | Q13: =IFERROR(IFERROR(VLOOKUP(A13,TRAOPE!$A:$U,21,0),VLOOKUP(B13,TRAOPE!$A:$U,21,0)),"") | R13: =IFERROR(IFERROR(VLOOKUP(A13,TRAOPE!$A:$W,23,0),VLOOKUP(B13,TRAOPE!$A:$W,23,0)),"") | S13: =IF(AND(P13="TN",R13="TN"),N13+N(O13),IF(G13&""="1",N(K13)*N13,(N13+N(O13))*N(K13))) | T13: =IF(Q13="","",Q13-S13)
A14: =CONCATENATE(C14,E14,F14,I14) | B14: =CONCATENATE(C14,E14,I14) | C14: 900000045 | D14: =IFERROR(VLOOKUP(C14,TRAOPE!$G:$H,2,0),"") | E14: DW83 | F14: D269 | G14: =IFERROR(VLOOKUP(A14,Flete!$A:$E,5,0),"") | H14: =IFERROR(VLOOKUP(F14,TRAOPE!$AA:$AB,2,0),"") | I14: 10000381 | J14: =IFERROR(VLOOKUP(I14,Materiales!$A:$H,8,0),"") | K14: =IFERROR(VLOOKUP(I14,Materiales!$A:$G,7,0),"") | L14: 20230203 | M14: 20240201 | N14: 46.17 | O14: =IFERROR(VLOOKUP(A14,Flete!$A:$J,10,0),"") | P14: TN | Q14: =IFERROR(IFERROR(VLOOKUP(A14,TRAOPE!$A:$U,21,0),VLOOKUP(B14,TRAOPE!$A:$U,21,0)),"") | R14: =IFERROR(IFERROR(VLOOKUP(A14,TRAOPE!$A:$W,23,0),VLOOKUP(B14,TRAOPE!$A:$W,23,0)),"") | S14: =IF(AND(P14="TN",R14="TN"),N14+N(O14),IF(G14&""="1",N(K14)*N14,(N14+N(O14))*N(K14))) | T14: =IF(Q14="","",Q14-S14)
... A218: =CONCATENATE(C218,E218,F218,I218) | B218: =CONCATENATE(C218,E218,I218) | C218: 900009275 | D218: =IFERROR(VLOOKUP(C218,TRAOPE!$G:$H,2,0),"") | E218: DW83 | F218: D216 | G218: =IFERROR(VLOOKUP(A218,Flete!$A:$E,5,0),"") | H218: =IFERROR(VLOOKUP(F218,TRAOPE!$AA:$AB,2,0),"") | I218: 10258539 | J218: =IFERROR(VLOOKUP(I218,Materiales!$A:$H,8,0),"") | K218: =IFERROR(VLOOKUP(I218,Materiales!$A:$G,7,0),"") | L218: 20260605 | M218: 99991231 | N218: 277.8 | O218: =IFERROR(VLOOKUP(A218,Flete!$A:$J,10,0),"") | P218: TN | Q218: =IFERROR(IFERROR(VLOOKUP(A218,TRAOPE!$A:$U,21,0),VLOOKUP(B218,TRAOPE!$A:$U,21,0)),"") | R218: =IFERROR(IFERROR(VLOOKUP(A218,TRAOPE!$A:$W,23,0),VLOOKUP(B218,TRAOPE!$A:$W,23,0)),"") | S218: =IF(AND(P218="TN",R218="TN"),N218+N(O218),IF(G218&""="1",N(K218)*N218,(N218+N(O218))*N(K218))) | T218: =IF(Q218="","",Q218-S218)

Sheet MP
A1: No. SF | B1: Cedis | C1: Destino | D1: No. Material | E1: Nombre Material | F1: Importe MP | G1: Moneda | H1: Cantidad | I1: UM | J1: C | K1: Inicio Vigencia | L1: Fin Vigencia
A2: 900000045 | B2: DW83 | C2: D216 | D2: 10000377 | F2: 107.59 | I2: TN | K2: 20210620 | L2: 20251031
A3: 900000045 | B3: DW83 | C3: D216 | D3: 10000379 | F3: 119.23 | I3: TN | K3: 20210620 | L3: 20251031
A4: 900000045 | B4: DW83 | C4: D216 | D4: 10000381 | F4: 69.97 | I4: TN | K4: 20210620 | L4: 20251031
A5: 900000045 | B5: DW83 | C5: D216 | D5: 10000719 | F5: 79.92 | I5: TN | K5: 20210620 | L5: 20251031
A6: 900000045 | B6: DW83 | C6: D216 | D6: 10192197 | F6: 76.39 | I6: TN | K6: 20210620 | L6: 20251031
A7: 900000045 | B7: DW83 | C7: D243 | D7: 10000379 | F7: 119.23 | I7: TN | K7: 20230301 | L7: 20250129
A8: 900000045 | B8: DW83 | C8: D243 | D8: 10000719 | F8: 91.54 | I8: TN | K8: 20230301 | L8: 20250129
A9: 900000045 | B9: DW83 | C9: D243 | D9: 10192197 | F9: 76.39 | I9: TN | K9: 20230301 | L9: 20250129
A10: 900000045 | B10: DW83 | C10: D269 | D10: 10000332 | F10: 327.5 | I10: TN | K10: 20230203 | L10: 20240201
A11: 900000045 | B11: DW83 | C11: D269 | D11: 10000377 | F11: 94.88 | I11: TN | K11: 20260601 | L11: 99991231
A12: 900000045 | B12: DW83 | C12: D269 | D12: 10000379 | F12: 144.17 | I12: TN | K12: 20260601 | L12: 99991231
A13: 900000045 | B13: DW83 | C13: D269 | D13: 10000381 | F13: 46.17 | I13: TN | K13: 20230203 | L13: 20240201
... A217: 900009275 | B217: DW83 | C217: D216 | D217: 10258539 | F217: 277.8 | I217: TN | K217: 20260605 | L217: 99991231

Sheet Flete
A1: Concat1 | B1: No. SF | C1: Cedis | D1: Destino | E1: Cond. Exp. | F1: Material | H1: Nombre Material | J1: Importe Flete | K1: Moneda | L1: Cantidad | M1: UM | N1: C | P1: Inicio Vigencia | Q1: Fin Vigencia
A2: 900000045DW83D21610000377 | B2: 900000045 | C2: DW83 | D2: D216 | E2: 4 | F2: 10000377 | J2: 86.01 | M2: TN | P2: 20210620 | Q2: 20251031
A3: 900000045DW83D21610000379 | B3: 900000045 | C3: DW83 | D3: D216 | E3: 4 | F3: 10000379 | J3: 246.5 | M3: TN | P3: 20210620 | Q3: 20251031
A4: 900000045DW83D21610000381 | B4: 900000045 | C4: DW83 | D4: D216 | E4: 4 | F4: 10000381 | J4: 73.34 | M4: TN | P4: 20210620 | Q4: 20251031
A5: 900000045DW83D21610000719 | B5: 900000045 | C5: DW83 | D5: D216 | E5: 4 | F5: 10000719 | J5: 83.22 | M5: TN | P5: 20210620 | Q5: 20251031
A6: 900000045DW83D21610192197 | B6: 900000045 | C6: DW83 | D6: D216 | E6: 4 | F6: 10192197 | J6: 277.73 | M6: TN | P6: 20210620 | Q6: 20251031
A7: 900000045DW83D24310000379 | B7: 900000045 | C7: DW83 | D7: D243 | E7: 4 | F7: 10000379 | J7: 218.53 | M7: TN | P7: 20230301 | Q7: 20250129
A8: 900000045DW83D24310000719 | B8: 900000045 | C8: DW83 | D8: D243 | E8: 4 | F8: 10000719 | J8: 224.41 | M8: TN | P8: 20230301 | Q8: 20250129
A9: 900000045DW83D24310192197 | B9: 900000045 | C9: DW83 | D9: D243 | E9: 4 | F9: 10192197 | J9: 268.73 | M9: TN | P9: 20230301 | Q9: 20250129
A10: 900000045DW83D26910000332 | B10: 900000045 | C10: DW83 | D10: D269 | E10: 4 | F10: 10000332 | J10: 62.5 | M10: TN | P10: 20230203 | Q10: 20240201
A11: 900000045DW83D26910000377 | B11: 900000045 | C11: DW83 | D11: D269 | E11: 4 | F11: 10000377 | J11: 32.92 | M11: TN | P11: 20260601 | Q11: 99991231
A12: 900000045DW83D26910000379 | B12: 900000045 | C12: DW83 | D12: D269 | E12: 4 | F12: 10000379 | J12: 33.45 | M12: TN | P12: 20260601 | Q12: 99991231
A13: 900000045DW83D26910000381 | B13: 900000045 | C13: DW83 | D13: D269 | E13: 4 | F13: 10000381 | J13: 32.89 | M13: TN | P13: 20230203 | Q13: 20240201
... A213: 900009275DW83D21610258539 | B213: 900009275 | C213: DW83 | D213: D216 | E213: 4 | F213: 10258539 | J213: 110.45 | M213: TN | P213: 20260605 | Q213: 99991231

Sheet Materiales
A1: Material | B1: TpMt | C1: Denom | D1: UMA | E1: Contador | F1: UMB | G1: PV | H1: Nombre Material
A2: 10000001 | B2: ZFER | C2: 1000 | D2: M3 | E2: 1000 | F2: TN | G2: 1262 | H2: GRAVA ANDESITA 10 MM (3/8")
A3: 10000003 | B3: ZFER | C3: 1000 | D3: M3 | E3: 1000 | F3: TN | G3: 1443 | H3: GRAVA CALIZA 10 MM (3/8")
A4: 10000006 | B4: ZFER | C4: 1000 | D4: M3 | E4: 1000 | F4: TN | G4: 1490 | H4: GRAVA RIO 10 MM (3/8")
A5: 10000007 | B5: ZFER | C5: 1000 | D5: M3 | E5: 1000 | F5: TN | G5: 1488 | H5: GRAVA BASALTO 13 MM (1/2")
A6: 10000008 | B6: ZFER | C6: 1000 | D6: M3 | E6: 1000 | F6: TN | G6: 1358 | H6: GRAVA CALIZA 13 MM (1/2")
A7: 10000011 | B7: ZFER | C7: 1000 | D7: M3 | E7: 1000 | F7: TN | G7: 1323 | H7: GRAVA ANDESITA 20 MM (3/4")
A8: 10000013 | B8: ZFER | C8: 1000 | D8: M3 | E8: 1000 | F8: TN | G8: 1514 | H8: GRAVA BASALTO 20 MM (3/4")
A9: 10000014 | B9: ZFER | C9: 1000 | D9: M3 | E9: 1000 | F9: TN | G9: 1400 | H9: GRAVA CALIZA 20 MM (3/4")
A10: 10000015 | B10: ZFER | C10: 1000 | D10: M3 | E10: 1000 | F10: TN | G10: 1410 | H10: GRAVA GRANITO 20 MM (3/4")
A11: 10000017 | B11: ZFER | C11: 1000 | D11: M3 | E11: 1000 | F11: TN | G11: 1475 | H11: GRAVA RIOLITA 20 MM (3/4")
A12: 10000019 | B12: ZFER | C12: 1000 | D12: M3 | E12: 1000 | F12: TN | G12: 1515 | H12: GRAVA RIO 20 MM (3/4")
A13: 10000020 | B13: ZFER | C13: 1000 | D13: M3 | E13: 1 | F13: TN | G13: 1 | H13: GRAVA MAQUILA 40MM (1 1/2")
... A2291: 10268770 | B2291: ZFE3 | C2291: 1000 | D2291: M3 | E2291: 1000 | F2291: TN | G2291: 1240 | H2291: MP GRAVA TRIT CALIZA 40MM 1 1/2" - ESP
A2292: 10268901 | B2292: ZFE3 | C2292: 1000 | D2292: M3 | E2292: 1000 | G2292: 1560 | H2292: MP GRAVA ANDESITA GRIS 3/4" - CAPADA
A2293: 10267983 | C2293: 1000 | G2293: 1800 | H2293: ESCORIA ALTO HORNO 3/4
A2294: 10268996 | C2294: 1000 | G2294: 1329 | H2294: GRAVA TRITURADA CALIZA 40 MM - 11/2"
A2295: 10269072 | C2295: 1000 | G2295: 1700 | H2295: BASE HIDRÁULICA SCREEN
A2296: 10269225 | B2296: ZFE3 | C2296: 1000 | D2296: M3 | E2296: 1000 | G2296: 1289 | H2296: MP ARENA CALIZA LAVADA MALLA 4 - DELTA I
A2297: 10269245 | B2297: ZFE3 | C2297: 1000 | D2297: M3 | E2297: 1000 | G2297: 1410 | H2297: MP GRAVA TRITURADA CALIZA 3/8 - 10MM
A2298: 10269246 | B2298: ZFE3 | C2298: 1000 | D2298: M3 | E2298: 1000 | G2298: 1400 | H2298: MP GRAVA TRITURADA CALIZA 1 1/2 - 40MM
A2299: 10269247 | B2299: ZFE3 | C2299: 1000 | D2299: M3 | E2299: 1000 | G2299: 1560 | H2299: MP ARENA TRIT CALIZA M-4
A2300: 10270431 | B2300: ZFE3 | C2300: 1000 | D2300: M3 | E2300: 1000 | G2300: 1423 | H2300: MP GRAVA RIOLITA 13 MM - 1/2"
A2301: 10270898 | B2301: ZFE3 | C2301: 1000 | D2301: M3 | E2301: 1000 | G2301: 1551 | H2301: MP BASE H. TRIT. BASALTO 1 1/2" A FINOS
A2302: 10270911 | B2302: ZFE3 | C2302: 1000 | D2302: M3 | E2302: 1000 | G2302: 1360 | H2302: MP GRAVA TRIT. BASALTO 40 MM - 1 1/2"
A2303: 10270912 | B2303: ZFE3 | C2303: 1000 | D2303: M3 | E2303: 1000 | G2303: 1589 | H2303: MP ARENA TRIT. BASALTO MALLA 4
A2304: 10270913 | B2304: ZFE3 | C2304: 1000 | D2304: M3 | E2304: 1000 | G2304: 1395 | H2304: MP GRAVA TRIT. BASALTO 20 MM - 3/4
A2305: 10270914 | B2305: ZFE3 | C2305: 1000 | D2305: M3 | E2305: 1000 | G2305: 1623 | H2305: MP ARENA ANDESITA BC
A2306: 10270824 | B2306: M3 | C2306: 1000 | D2306: M3 | E2306: 10007640 | G2306: 1325 | H2306: MP ARENA TRITURADA CALIZA MALLA 5
A2307: 10270825 | B2307: M3 | C2307: 1000 | D2307: M3 | E2307: 10000003 | G2307: 1242 | H2307: MP GRAVA TRITURADA CALIZA 10MM (3/8”)
... A2319: 10272527 | B2319: ZFE3 | C2319: 1000 | D2319: M3 | E2319: 1000 | G2319: 1620 | H2319: CNC - NO CLASIFICADO
A2320: 10000332 | C2320: 1000 | D2320: M3 | E2320: 1000 | G2320: 800 | H2320: Grava Triturada Pomez - Jal 20 mm - 3/4"
A2321: 10273001 | B2321: ZFE3 | C2321: 1000 | D2321: M3 | E2321: 1000 | G2321: 1688 | H2321: MP ARENA TRIT. BASALTO MALLA 4
A2322: 10273002 | B2322: ZFE3 | C2322: 1000 | D2322: M3 | E2322: 1000 | G2322: 1466 | H2322: MP GRAVA TRIT. BASALTO 20 MM - 3/4"
A2323: 10273351 | B2323: ZFE3 | C2323: 1000 | D2323: M3 | E2323: 1000 | G2323: 1612 | H2323: MP ARENA TRIT. CALIZA MALLA 4
A2324: 10273352 | B2324: ZFE3 | C2324: 1000 | D2324: M3 | E2324: 1000 | G2324: 1492 | H2324: MP GRAVA TRIT. CALIZA 20 MM - 3/4"
A2325: 10271724 | B2325: ZFE3 | C2325: 1000 | D2325: M3 | E2325: 1000 | G2325: 1900 | H2325: MP RESIDUO DE CONCRETO
A2326: 10000677 | C2326: 1000 | D2326: M3 | G2326: 1164 | H2326: Grava Triturada Caliza 20 mm - 3/4"
A2327: 10274190 | B2327: ZFE3 | C2327: 1000 | D2327: M3 | E2327: 1000 | G2327: 1800 | H2327: MP BASE HIDRAULICA ANDESITA 70-30
A2328: 10274601 | B2328: ZFE3 | C2328: 1000 | D2328: M3 | E2328: 1000 | G2328: 1447 | H2328: MP ARENA BASALTO N° 4
...

Sheet TRAOPE
A1: Concat1 | B1: Contrato_Pos | C1: Doc. Compras | D1: Pos | E1: Org.compras | F1: Grp-Compr. | G1: Ship From | H1: Nombre SF | I1: Proveedor | J1: Nombre Prov | K1: Cond. Pago | L1: Descr. Cond Pago | M1: Material | N1: Descripción | O1: Centro | P1: Descripción Centro | Q1: In.perído validez | R1: Fin perído validez | S1: Válido de | T1: Validez a | U1: Precio neto pedido | V1: Moneda | W1: UM Precio Pedido | X1: Importe Condición | Y1: Moneda KONP | Z1: UM Ctd Base | AA1: Destino | AB1: Nombre Destino | AC1: Cuenta de mayor | AD1: Centro de costo | AE1: Cond. Exp. | AF1: Descr. Cond. Exp. | AG1: Peso Vol. | AH1: UMB | AI1: Ind. Oblig. Conf. Ped. | AJ1: Ctrl-Conf. | AK1: IVA | AL1: Modif_Date | AM1: Ruta
A2: 900003017DW83D21610049556 | B2: 4600050426-130 | C2: 4600050426 | D2: 130 | E2: MXPO | F2: MXL | G2: 900003017 | H2: TC-ED-SALDAÑA MORONES- LAS VARAS | I2: 5002163 | J2: SALDANA MORONES HERIBERTO | K2: N30 | L2: (AP) NAFIN 30 Dias | M2: 10049556 | N2: Grava Triturada Basalto 10 mm - 3/8" | O2: DW83 | P2: MX-CED. VALLARTA | Q2: 20210801 | R2: 20281231 | S2: 20220121 | T2: 20271231 | U2: 365 | V2: MXN | W2: M3 | X2: 190 | Y2: MXN | Z2: M3 | AA2: D216 | AB2: PD0130 TEPIC | AC2: 56103637 | AD2: 6644411540 | AE2: 4 | AF2: ENTREGA DIRECTA | AG2: 1.328 | AH2: M3 | AI2: X | AJ2: 4 | AK2: V4 | AL2: 20230920 | AM2: DW83-900003017-D216-10049556-4
A3: 900000560DW8310258539 | B3: 4600056862-30 | C3: 4600056862 | D3: 30 | E3: MXPO | F3: MXL | G3: 900000560 | H3: SF TC-TEPYC LA REPISA | I3: 5006993 | J3: TERRACERIAS PAVIMENTOS Y CAMINOS SA | K3: Z04 | L3: (AP) 30 Dias | M3: 10258539 | N3: ARENA TRITURADA BASALTO MALLA 5 | O3: DW83 | P3: MX-CED. VALLARTA | Q3: 20230310 | R3: 20281231 | S3: 20240704 | T3: 20291231 | U3: 350 | V3: MXN | W3: M3 | X3: 0 | Y3: MXN | Z3: M3 | AC3: 56103638 | AD3: 6644411540 | AE3: 1 | AF3: ENTREGADO | AG3: 1.591 | AH3: M3 | AI3: X | AJ3: 4 | AK3: V4 | AL3: 20240711 | AM3: DW83-900000560-10258539
A4: 900003368DW83D21510192197 | B4: 4600050463-60 | C4: 4600050463 | D4: 60 | E4: MXPO | F4: MXL | G4: 900003368 | H4: TC-ED SALDAÑA PORVENIR | I4: 5002163 | J4: SALDANA MORONES HERIBERTO | K4: N30 | L4: (AP) NAFIN 30 Dias | M4: 10192197 | N4: ARENA CLASIFICADA RIO MALLA 5 | O4: DW83 | P4: MX-CED. VALLARTA | Q4: 20210801 | R4: 20291231 | S4: 20260601 | T4: 20301231 | U4: 198.54 | V4: MXN | W4: M3 | X4: 44.04 | Y4: MXN | Z4: M3 | AA4: D215 | AB4: PD0159 PUERTO VALLARTA | AC4: 56103638 | AD4: 6644411540 | AE4: 4 | AF4: ENTREGA DIRECTA | AG4: 1.443 | AH4: M3 | AI4: X | AJ4: 4 | AK4: V4 | AL4: 20260615 | AM4: DW83-900003368-D215-10192197-4
A5: 900004830DW83D38610000379 | B5: 4600050438-130 | C5: 4600050438 | D5: 130 | E5: MXPO | F5: MXL | G5: 900004830 | H5: TC-ED ARMAMPET LAS VARAS | I5: 5061801 | J5: ARMAMPET SA DE CV | K5: N30 | L5: (AP) NAFIN 30 Dias | M5: 10000379 | N5: Grava Triturada Basalto 20 mm - 3/4" | O5: DW83 | P5: MX-CED. VALLARTA | Q5: 20210801 | R5: 20291231 | S5: 20260601 | T5: 20301231 | U5: 367.94 | V5: MXN | W5: M3 | X5: 168.38 | Y5: MXN | Z5: M3 | AA5: D386 | AB5: PD0563 PUNTA DE MITA | AC5: 56103637 | AD5: 6644411540 | AE5: 4 | AF5: ENTREGA DIRECTA | AG5: 1.43 | AH5: M3 | AI5: X | AJ5: 4 | AK5: V4 | AL5: 20260615 | AM5: DW83-900004830-D386-10000379-4
A6: 900000045DW83D26910000377 | B6: 4600050401-50 | C6: 4600050401 | D6: 50 | E6: MXPO | F6: MXL | G6: 900000045 | H6: TC-ED SALDAÑA MORONES | I6: 5002163 | J6: SALDANA MORONES HERIBERTO | K6: N30 | L6: (AP) NAFIN 30 Dias | M6: 10000377 | N6: Grava Triturada Basalto 10 mm - 3/8" | O6: DW83 | P6: MX-CED. VALLARTA | Q6: 20210712 | R6: 20291231 | S6: 20260601 | T6: 20301231 | U6: 186.34 | V6: MXN | W6: M3 | X6: 48 | Y6: MXN | Z6: M3 | AA6: D269 | AB6: PD0434 PLANTA MAYAN | AC6: 56103637 | AD6: 6644411540 | AE6: 4 | AF6: ENTREGA DIRECTA | AG6: 1.458 | AH6: M3 | AI6: X | AJ6: 4 | AK6: V4 | AL6: 20260615 | AM6: DW83-900000045-D269-10000377-4
A7: 900003368DW83D55710000377 | B7: 4600050463-120 | C7: 4600050463 | D7: 120 | E7: MXPO | F7: MXL | G7: 900003368 | H7: TC-ED SALDAÑA PORVENIR | I7: 5002163 | J7: SALDANA MORONES HERIBERTO | K7: N30 | L7: (AP) NAFIN 30 Dias | M7: 10000377 | N7: Grava Triturada Basalto 10 mm - 3/8" | O7: DW83 | P7: MX-CED. VALLARTA | Q7: 20210801 | R7: 20291231 | S7: 20260601 | T7: 20301231 | U7: 402.85 | V7: MXN | W7: M3 | X7: 268.97 | Y7: MXN | Z7: M3 | AA7: D557 | AB7: PD0432 TRONCAL SAN PANCHO | AC7: 56103637 | AD7: 6644411540 | AE7: 4 | AF7: ENTREGA DIRECTA | AG7: 1.458 | AH7: M3 | AI7: X | AJ7: 4 | AK7: V4 | AL7: 20260615 | AM7: DW83-900003368-D557-10000377-4
A8: 900004830DW83D38610000719 | B8: 4600050438-100 | C8: 4600050438 | D8: 100 | E8: MXPO | F8: MXL | G8: 900004830 | H8: TC-ED ARMAMPET LAS VARAS | I8: 5061801 | J8: ARMAMPET SA DE CV | K8: N30 | L8: (AP) NAFIN 30 Dias | M8: 10000719 | N8: Arena Clasificada Río Malla 8 | O8: DW83 | P8: MX-CED. VALLARTA | Q8: 20210801 | R8: 20291231 | S8: 20260601 | T8: 20301231 | U8: 335.89 | V8: MXN | W8: M3 | X8: 181.39 | Y8: MXN | Z8: M3 | AA8: D386 | AB8: PD0563 PUNTA DE MITA | AC8: 56103638 | AD8: 6644411540 | AE8: 4 | AF8: ENTREGA DIRECTA | AG8: 1.442 | AH8: M3 | AI8: X | AJ8: 4 | AK8: V4 | AL8: 20260615 | AM8: DW83-900004830-D386-10000719-4
A9: 900003368DW83D21510000383 | B9: 4600050463-40 | C9: 4600050463 | D9: 40 | E9: MXPO | F9: MXL | G9: 900003368 | H9: TC-ED SALDAÑA PORVENIR | I9: 5002163 | J9: SALDANA MORONES HERIBERTO | K9: N30 | L9: (AP) NAFIN 30 Dias | M9: 10000383 | N9: Grava Triturada Basalto 40 mm - 1 1/2" | O9: DW83 | P9: MX-CED. VALLARTA | Q9: 20210801 | R9: 20291231 | S9: 20260601 | T9: 20301231 | U9: 274.82 | V9: MXN | W9: M3 | X9: 75.27 | Y9: MXN | Z9: M3 | AA9: D215 | AB9: PD0159 PUERTO VALLARTA | AC9: 56103637 | AD9: 6644411540 | AE9: 4 | AF9: ENTREGA DIRECTA | AG9: 1.359 | AH9: M3 | AI9: X | AJ9: 4 | AK9: V4 | AL9: 20260615 | AM9: DW83-900003368-D215-10000383-4
A10: 900003368DW83D55710192197 | B10: 4600050463-150 | C10: 4600050463 | D10: 150 | E10: MXPO | F10: MXL | G10: 900003368 | H10: TC-ED SALDAÑA PORVENIR | I10: 5002163 | J10: SALDANA MORONES HERIBERTO | K10: N30 | L10: (AP) NAFIN 30 Dias | M10: 10192197 | N10: ARENA CLASIFICADA RIO MALLA 5 | O10: DW83 | P10: MX-CED. VALLARTA | Q10: 20210801 | R10: 20291231 | S10: 20260601 | T10: 20301231 | U10: 352.5 | V10: MXN | W10: M3 | X10: 198 | Y10: MXN | Z10: M3 | AA10: D557 | AB10: PD0432 TRONCAL SAN PANCHO | AC10: 56103638 | AD10: 6644411540 | AE10: 4 | AF10: ENTREGA DIRECTA | AG10: 1.443 | AH10: M3 | AI10: X | AJ10: 4 | AK10: V4 | AL10: 20260615 | AM10: DW83-900003368-D557-10192197-4
A11: 900003368DW83D21510000379 | B11: 4600050463-30 | C11: 4600050463 | D11: 30 | E11: MXPO | F11: MXL | G11: 900003368 | H11: TC-ED SALDAÑA PORVENIR | I11: 5002163 | J11: SALDANA MORONES HERIBERTO | K11: N30 | L11: (AP) NAFIN 30 Dias | M11: 10000379 | N11: Grava Triturada Basalto 20 mm - 3/4" | O11: DW83 | P11: MX-CED. VALLARTA | Q11: 20210801 | R11: 20291231 | S11: 20260601 | T11: 20301231 | U11: 274.82 | V11: MXN | W11: M3 | X11: 75.27 | Y11: MXN | Z11: M3 | AA11: D215 | AB11: PD0159 PUERTO VALLARTA | AC11: 56103637 | AD11: 6644411540 | AE11: 4 | AF11: ENTREGA DIRECTA | AG11: 1.43 | AH11: M3 | AI11: X | AJ11: 4 | AK11: V4 | AL11: 20260615 | AM11: DW83-900003368-D215-10000379-4
A12: 900003368DW83D55710000379 | B12: 4600050463-130 | C12: 4600050463 | D12: 130 | E12: MXPO | F12: MXL | G12: 900003368 | H12: TC-ED SALDAÑA PORVENIR | I12: 5002163 | J12: SALDANA MORONES HERIBERTO | K12: N30 | L12: (AP) NAFIN 30 Dias | M12: 10000379 | N12: Grava Triturada Basalto 20 mm - 3/4" | O12: DW83 | P12: MX-CED. VALLARTA | Q12: 20210801 | R12: 20291231 | S12: 20260601 | T12: 20301231 | U12: 424.44 | V12: MXN | W12: M3 | X12: 224.89 | Y12: MXN | Z12: M3 | AA12: D557 | AB12: PD0432 TRONCAL SAN PANCHO | AC12: 56103637 | AD12: 6644411540 | AE12: 4 | AF12: ENTREGA DIRECTA | AG12: 1.43 | AH12: M3 | AI12: X | AJ12: 4 | AK12: V4 | AL12: 20260615 | AM12: DW83-900003368-D557-10000379-4
A13: 900000045DW83D26910000379 | B13: 4600050401-30 | C13: 4600050401 | D13: 30 | E13: MXPO | F13: MXL | G13: 900000045 | H13: TC-ED SALDAÑA MORONES | I13: 5002163 | J13: SALDANA MORONES HERIBERTO | K13: N30 | L13: (AP) NAFIN 30 Dias | M13: 10000379 | N13: Grava Triturada Basalto 20 mm - 3/4" | O13: DW83 | P13: MX-CED. VALLARTA | Q13: 20210712 | R13: 20291231 | S13: 20260601 | T13: 20301231 | U13: 254.01 | V13: MXN | W13: M3 | X13: 47.84 | Y13: MXN | Z13: M3 | AA13: D269 | AB13: PD0434 PLANTA MAYAN | AC13: 56103637 | AD13: 6644411540 | AE13: 4 | AF13: ENTREGA DIRECTA | AG13: 1.43 | AH13: M3 | AI13: X | AJ13: 4 | AK13: V4 | AL13: 20260615 | AM13: DW83-900000045-D269-10000379-4
A14: 900004830DW83D38610000383 | B14: 4600050438-120 | C14: 4600050438 | D14: 120 | E14: MXPO | F14: MXL | G14: 900004830 | H14: TC-ED ARMAMPET LAS VARAS | I14: 5061801 | J14: ARMAMPET SA DE CV | K14: N30 | L14: (AP) NAFIN 30 Dias | M14: 10000383 | N14: Grava Triturada Basalto 40 mm - 1 1/2" | O14: DW83 | P14: MX-CED. VALLARTA | Q14: 20210801 | R14: 20291231 | S14: 20260601 | T14: 20301231 | U14: 367.93 | V14: MXN | W14: M3 | X14: 168.37 | Y14: MXN | Z14: M3 | AA14: D386 | AB14: PD0563 PUNTA DE MITA | AC14: 56103637 | AD14: 6644411540 | AE14: 4 | AF14: ENTREGA DIRECTA | AG14: 1.359 | AH14: M3 | AI14: X | AJ14: 4 | AK14: V4 | AL14: 20260615 | AM14: DW83-900004830-D386-10000383-4
A15: 900004830DW83D38610000377 | B15: 4600050438-110 | C15: 4600050438 | D15: 110 | E15: MXPO | F15: MXL | G15: 900004830 | H15: TC-ED ARMAMPET LAS VARAS | I15: 5061801 | J15: ARMAMPET SA DE CV | K15: N30 | L15: (AP) NAFIN 30 Dias | M15: 10000377 | N15: Grava Triturada Basalto 10 mm - 3/8" | O15: DW83 | P15: MX-CED. VALLARTA | Q15: 20210801 | R15: 20291231 | S15: 20260601 | T15: 20301231 | U15: 334.48 | V15: MXN | W15: M3 | X15: 170.62 | Y15: MXN | Z15: M3 | AA15: D386 | AB15: PD0563 PUNTA DE MITA | AC15: 56103637 | AD15: 6644411540 | AE15: 4 | AF15: ENTREGA DIRECTA | AG15: 1.458 | AH15: M3 | AI15: X | AJ15: 4 | AK15: V4 | AL15: 20260615 | AM15: DW83-900004830-D386-10000377-4
... A20: 900003368DW83D55710000719 | B20: 4600050463-100 | C20: 4600050463 | D20: 100 | E20: MXPO | F20: MXL | G20: 900003368 | H20: TC-ED SALDAÑA PORVENIR | I20: 5002163 | J20: SALDANA MORONES HERIBERTO | K20: N30 | L20: (AP) NAFIN 30 Dias | M20: 10000719 | N20: Arena Clasificada Río Malla 8 | O20: DW83 | P20: MX-CED. VALLARTA | Q20: 20210801 | R20: 20291231 | S20: 20260601 | T20: 20301231 | U20: 431.63 | V20: MXN | W20: M3 | X20: 277.14 | Y20: MXN | Z20: M3 | AA20: D557 | AB20: PD0432 TRONCAL SAN PANCHO | AC20: 56103638 | AD20: 6644411540 | AE20: 4 | AF20: ENTREGA DIRECTA | AG20: 1.442 | AH20: M3 | AI20: X | AJ20: 4 | AK20: V4 | AL20: 20260615 | AM20: DW83-900003368-D557-10000719-4
A21: 900000434DW8310000320 | B21: 4600050409-40 | C21: 4600050409 | D21: 40 | E21: MXPO | F21: MXL | G21: 900000434 | H21: TC-SALDAÑA SANTA FE | I21: 5002163 | J21: SALDANA MORONES HERIBERTO | K21: N30 | L21: (AP) NAFIN 30 Dias | M21: 10000320 | N21: Arena Triturada Caliza Malla 4 | O21: DW83 | P21: MX-CED. VALLARTA | Q21: 20210712 | R21: 20291231 | S21: 20260301 | T21: 20301231 | U21: 132 | V21: MXN | W21: M3 | X21: 0 | Y21: MXN | Z21: M3 | AC21: 56103638 | AD21: 6644411540 | AE21: 1 | AF21: ENTREGADO | AG21: 1.512 | AH21: M3 | AI21: X | AJ21: 4 | AK21: V4 | AL21: 20260619 | AM21: DW83-900000434-10000320
A22: 900000045DW83D26910192197 | B22: 4600050401-10 | C22: 4600050401 | D22: 10 | E22: MXPO | F22: MXL | G22: 900000045 | H22: TC-ED SALDAÑA MORONES | I22: 5002163 | J22: SALDANA MORONES HERIBERTO | K22: N30 | L22: (AP) NAFIN 30 Dias | M22: 10192197 | N22: ARENA CLASIFICADA RIO MALLA 5 | O22: DW83 | P22: MX-CED. VALLARTA | Q22: 20210712 | R22: 20291231 | S22: 20260601 | T22: 20301231 | U22: 195.63 | V22: MXN | W22: M3 | X22: 36.01 | Y22: MXN | Z22: M3 | AA22: D269 | AB22: PD0434 PLANTA MAYAN | AC22: 56103638 | AD22: 6644411540 | AE22: 4 | AF22: ENTREGA DIRECTA | AG22: 1.443 | AH22: M3 | AI22: X | AJ22: 4 | AK22: V4 | AL22: 20260615 | AM22: DW83-900000045-D269-10192197-4
A23: 900000434DW8310000379 | B23: 4600050409-20 | C23: 4600050409 | D23: 20 | E23: MXPO | F23: MXL | G23: 900000434 | H23: TC-SALDAÑA SANTA FE | I23: 5002163 | J23: SALDANA MORONES HERIBERTO | K23: N30 | L23: (AP) NAFIN 30 Dias | M23: 10000379 | N23: Grava Triturada Basalto 20 mm - 3/4" | O23: DW83 | P23: MX-CED. VALLARTA | Q23: 20210712 | R23: 20291231 | S23: 20260601 | T23: 20301231 | U23: 199.56 | V23: MXN | W23: M3 | X23: 0 | Y23: MXN | Z23: M3 | AC23: 56103637 | AD23: 6644411540 | AE23: 1 | AF23: ENTREGADO | AG23: 1.43 | AH23: M3 | AI23: X | AJ23: 4 | AK23: V4 | AL23: 20260619 | AM23: DW83-900000434-10000379
A24: 900000045DW83D26910000719 | B24: 4600050401-60 | C24: 4600050401 | D24: 60 | E24: MXPO | F24: MXL | G24: 900000045 | H24: TC-ED SALDAÑA MORONES | I24: 5002163 | J24: SALDANA MORONES HERIBERTO | K24: N30 | L24: (AP) NAFIN 30 Dias | M24: 10000719 | N24: Arena Clasificada Río Malla 8 | O24: DW83 | P24: MX-CED. VALLARTA | Q24: 20210712 | R24: 20291231 | S24: 20260601 | T24: 20301231 | U24: 192.23 | V24: MXN | W24: M3 | X24: 22.94 | Y24: MXN | Z24: M3 | AA24: D269 | AB24: PD0434 PLANTA MAYAN | AC24: 56103638 | AD24: 6644411540 | AE24: 4 | AF24: ENTREGA DIRECTA | AG24: 1.442 | AH24: M3 | AI24: X | AJ24: 4 | AK24: V4 | AL24: 20260615 | AM24: DW83-900000045-D269-10000719-4
A25: 900000434DW8310000383 | B25: 4600050409-30 | C25: 4600050409 | D25: 30 | E25: MXPO | F25: MXL | G25: 900000434 | H25: TC-SALDAÑA SANTA FE | I25: 5002163 | J25: SALDANA MORONES HERIBERTO | K25: N30 | L25: (AP) NAFIN 30 Dias | M25: 10000383 | N25: Grava Triturada Basalto 40 mm - 1 1/2" | O25: DW83 | P25: MX-CED. VALLARTA | Q25: 20210712 | R25: 20291231 | S25: 20260601 | T25: 20301231 | U25: 199.56 | V25: MXN | W25: M3 | X25: 0 | Y25: MXN | Z25: M3 | AC25: 56103637 | AD25: 6644411540 | AE25: 1 | AF25: ENTREGADO | AG25: 1.359 | AH25: M3 | AI25: X | AJ25: 4 | AK25: V4 | AL25: 20260619 | AM25: DW83-900000434-10000383
A26: 900000434DW8310192197 | B26: 4600050409-50 | C26: 4600050409 | D26: 50 | E26: MXPO | F26: MXL | G26: 900000434 | H26: TC-SALDAÑA SANTA FE | I26: 5002163 | J26: SALDANA MORONES HERIBERTO | K26: N30 | L26: (AP) NAFIN 30 Dias | M26: 10192197 | N26: ARENA CLASIFICADA RIO MALLA 5 | O26: DW83 | P26: MX-CED. VALLARTA | Q26: 20210712 | R26: 20291231 | S26: 20260601 | T26: 20301231 | U26: 154.49 | V26: MXN | W26: M3 | X26: 0 | Y26: MXN | Z26: M3 | AC26: 56103638 | AD26: 6644411540 | AE26: 1 | AF26: ENTREGADO | AG26: 1.443 | AH26: M3 | AI26: X | AJ26: 4 | AK26: V4 | AL26: 20260622 | AM26: DW83-900000434-10192197
A27: 900003368DW83D21510000719 | B27: 4600050463-10 | C27: 4600050463 | D27: 10 | E27: MXPO | F27: MXL | G27: 900003368 | H27: TC-ED SALDAÑA PORVENIR | I27: 5002163 | J27: SALDANA MORONES HERIBERTO | K27: N30 | L27: (AP) NAFIN 30 Dias | M27: 10000719 | N27: Arena Clasificada Río Malla 8 | O27: DW83 | P27: MX-CED. VALLARTA | Q27: 20210801 | R27: 20291231 | S27: 20260601 | T27: 20301231 | U27: 276.02 | V27: MXN | W27: M3 | X27: 121.53 | Y27: MXN | Z27: M3 | AA27: D215 | AB27: PD0159 PUERTO VALLARTA | AC27: 56103638 | AD27: 6644411540 | AE27: 4 | AF27: ENTREGA DIRECTA | AG27: 1.442 | AH27: M3 | AI27: X | AJ27: 4 | AK27: V4 | AL27: 20260615 | AM27: DW83-900003368-D215-10000719-4
A28: 900004830DW83D03310000377 | B28: 4600050438-230 | C28: 4600050438 | D28: 230 | E28: MXPO | F28: MXL | G28: 900004830 | H28: TC-ED ARMAMPET LAS VARAS | I28: 5061801 | J28: ARMAMPET SA DE CV | K28: N30 | L28: (AP) NAFIN 30 Dias | M28: 10000377 | N28: Grava Triturada Basalto 10 mm - 3/8" | O28: DW83 | P28: MX-CED. VALLARTA | Q28: 20210801 | R28: 20291231 | S28: 20260601 | T28: 20301231 | U28: 273.07 | V28: MXN | W28: M3 | X28: 139.19 | Y28: MXN | Z28: M3 | AA28: D033 | AB28: PD0446 TUNELES GUAMUCHIL | AC28: 56103637 | AD28: 6644411540 | AE28: 4 | AF28: ENTREGA DIRECTA | AG28: 1.458 | AH28: M3 | AI28: X | AJ28: 4 | AK28: V4 | AL28: 20260615 | AM28: DW83-900004830-D033-10000377-4
A29: 900004830DW83D03310000379 | B29: 4600050438-30 | C29: 4600050438 | D29: 30 | E29: MXPO | F29: MXL | G29: 900004830 | H29: TC-ED ARMAMPET LAS VARAS | I29: 5061801 | J29: ARMAMPET SA DE CV | K29: N30 | L29: (AP) NAFIN 30 Dias | M29: 10000379 | N29: Grava Triturada Basalto 20 mm - 3/4" | O29: DW83 | P29: MX-CED. VALLARTA | Q29: 20210801 | R29: 20291231 | S29: 20260601 | T29: 20301231 | U29: 303.01 | V29: MXN | W29: M3 | X29: 103.46 | Y29: MXN | Z29: M3 | AA29: D033 | AB29: PD0446 TUNELES GUAMUCHIL | AC29: 56103637 | AD29: 6644411540 | AE29: 4 | AF29: ENTREGA DIRECTA | AG29: 1.43 | AH29: M3 | AI29: X | AJ29: 4 | AK29: V4 | AL29: 20260615 | AM29: DW83-900004830-D033-10000379-4
A30: 900004830DW83D03310000719 | B30: 4600050438-220 | C30: 4600050438 | D30: 220 | E30: MXPO | F30: MXL | G30: 900004830 | H30: TC-ED ARMAMPET LAS VARAS | I30: 5061801 | J30: ARMAMPET SA DE CV | K30: N30 | L30: (AP) NAFIN 30 Dias | M30: 10000719 | N30: Arena Clasificada Río Malla 8 | O30: DW83 | P30: MX-CED. VALLARTA | Q30: 20210801 | R30: 20291231 | S30: 20260601 | T30: 20301231 | U30: 282.27 | V30: MXN | W30: M3 | X30: 127.77 | Y30: MXN | Z30: M3 | AA30: D033 | AB30: PD0446 TUNELES GUAMUCHIL | AC30: 56103638 | AD30: 6644411540 | AE30: 4 | AF30: ENTREGA DIRECTA | AG30: 1.442 | AH30: M3 | AI30: X | AJ30: 4 | AK30: V4 | AL30: 20260615 | AM30: DW83-900004830-D033-10000719-4
A31: 900004830DW83D03310192197 | B31: 4600050438-140 | C31: 4600050438 | D31: 140 | E31: MXPO | F31: MXL | G31: 900004830 | H31: TC-ED ARMAMPET LAS VARAS | I31: 5061801 | J31: ARMAMPET SA DE CV | K31: N30 | L31: (AP) NAFIN 30 Dias | M31: 10192197 | N31: ARENA CLASIFICADA RIO MALLA 5 | O31: DW83 | P31: MX-CED. VALLARTA | Q31: 20210801 | R31: 20291231 | S31: 20260601 | T31: 20301231 | U31: 221.55 | V31: MXN | W31: M3 | X31: 67.04 | Y31: MXN | Z31: M3 | AA31: D033 | AB31: PD0446 TUNELES GUAMUCHIL | AC31: 56103638 | AD31: 6644411540 | AE31: 4 | AF31: ENTREGA DIRECTA | AG31: 1.443 | AH31: M3 | AI31: X | AJ31: 4 | AK31: V4 | AL31: 20260615 | AM31: DW83-900004830-D033-10192197-4
A32: 900003368DW83D21510000377 | B32: 4600050463-20 | C32: 4600050463 | D32: 20 | E32: MXPO | F32: MXL | G32: 900003368 | H32: TC-ED SALDAÑA PORVENIR | I32: 5002163 | J32: SALDANA MORONES HERIBERTO | K32: N30 | L32: (AP) NAFIN 30 Dias | M32: 10000377 | N32: Grava Triturada Basalto 10 mm - 3/8" | O32: DW83 | P32: MX-CED. VALLARTA | Q32: 20210801 | R32: 20291231 | S32: 20260601 | T32: 20301231 | U32: 216.22 | V32: MXN | W32: M3 | X32: 82.33 | Y32: MXN | Z32: M3 | AA32: D215 | AB32: PD0159 PUERTO VALLARTA | AC32: 56103637 | AD32: 6644411540 | AE32: 4 | AF32: ENTREGA DIRECTA | AG32: 1.458 | AH32: M3 | AI32: X | AJ32: 4 | AK32: V4 | AL32: 20260615 | AM32: DW83-900003368-D215-10000377-4
A33: 900007907DW83D21610258539 | B33: 4600056704-30 | C33: 4600056704 | D33: 30 | E33: MXPO | F33: MXL | G33: 900007907 | H33: SF TC-ED- TEPYC LA REPISA | I33: 5006993 | J33: TERRACERIAS PAVIMENTOS Y CAMINOS SA | K33: Z04 | L33: (AP) 30 Dias | M33: 10258539 | N33: ARENA TRITURADA BASALTO MALLA 5 | O33: DW83 | P33: MX-CED. VALLARTA | Q33: 20230227 | R33: 20291231 | S33: 20250301 | T33: 20301231 | U33: 580 | V33: MXN | W33: M3 | X33: 165 | Y33: MXN | Z33: M3 | AA33: D216 | AB33: PD0130 TEPIC | AC33: 56103638 | AD33: 6644411540 | AE33: 4 | AF33: ENTREGA DIRECTA | AG33: 1.591 | AH33: M3 | AI33: X | AJ33: 4 | AK33: V4 | AL33: 20250328 | AM33: DW83-900007907-D216-10258539-4
A34: 900007907DW83D21610000437 | B34: 4600056704-10 | C34: 4600056704 | D34: 10 | E34: MXPO | F34: MXL | G34: 900007907 | H34: SF TC-ED- TEPYC LA REPISA | I34: 5006993 | J34: TERRACERIAS PAVIMENTOS Y CAMINOS SA | K34: Z04 | L34: (AP) 30 Dias | M34: 10000437 | N34: Grava Triturada Basalto 20 mm - 3/4" | O34: DW83 | P34: MX-CED. VALLARTA | Q34: 20230227 | R34: 20291231 | S34: 20250301 | T34: 20301231 | U34: 580 | V34: MXN | W34: M3 | X34: 165 | Y34: MXN | Z34: M3 | AA34: D216 | AB34: PD0130 TEPIC | AC34: 56103637 | AD34: 6644411540 | AE34: 4 | AF34: ENTREGA DIRECTA | AG34: 1.505 | AH34: M3 | AI34: X | AJ34: 4 | AK34: V4 | AL34: 20250328 | AM34: DW83-900007907-D216-10000437-4
A35: 900000434DW8310000719 | B35: 4600050409-60 | C35: 4600050409 | D35: 60 | E35: MXPO | F35: MXL | G35: 900000434 | H35: TC-SALDAÑA SANTA FE | I35: 5002163 | J35: SALDANA MORONES HERIBERTO | K35: N30 | L35: (AP) NAFIN 30 Dias | M35: 10000719 | N35: Arena Clasificada Río Malla 8 | O35: DW83 | P35: MX-CED. VALLARTA | Q35: 20210712 | R35: 20291231 | S35: 20230424 | T35: 20281231 | U35: 165 | V35: MXN | W35: M3 | X35: 0 | Y35: MXN | Z35: M3 | AC35: 56103638 | AD35: 6644411540 | AE35: 1 | AF35: ENTREGADO | AG35: 1.442 | AH35: M3 | AI35: X | AJ35: 4 | AK35: V4 | AL35: 20230920 | AM35: DW83-900000434-10000719
A36: 900000434DW8310000377 | B36: 4600050409-10 | C36: 4600050409 | D36: 10 | E36: MXPO | F36: MXL | G36: 900000434 | H36: TC-SALDAÑA SANTA FE | I36: 5002163 | J36: SALDANA MORONES HERIBERTO | K36: N30 | L36: (AP) NAFIN 30 Dias | M36: 10000377 | N36: Grava Triturada Basalto 10 mm - 3/8" | O36: DW83 | P36: MX-CED. VALLARTA | Q36: 20210712 | R36: 20291231 | S36: 20230301 | T36: 20281231 | U36: 114.4 | V36: MXN | W36: M3 | X36: 0 | Y36: MXN | Z36: M3 | AC36: 56103637 | AD36: 6644411540 | AE36: 1 | AF36: ENTREGADO | AG36: 1.458 | AH36: M3 | AI36: X | AJ36: 4 | AK36: V4 | AL36: 20230920 | AM36: DW83-900000434-10000377
A37: 900007615DW8310049556 | B37: 4600054016-30 | C37: 4600054016 | D37: 30 | E37: MXPO | F37: MXL | G37: 900007615 | H37: SF TC- ARMAMPET LAS VARAS | I37: 5061801 | J37: ARMAMPET SA DE CV | K37: N30 | L37: (AP) NAFIN 30 Dias | M37: 10049556 | N37: Grava Triturada Basalto 10 mm - 3/8" | O37: DW83 | P37: MX-CED. VALLARTA | Q37: 20220523 | R37: 20281231 | S37: 20220523 | T37: 20271231 | U37: 220 | V37: MXN | W37: M3 | X37: 0 | Y37: MXN | Z37: M3 | AC37: 56103637 | AD37: 6644411540 | AE37: 1 | AF37: ENTREGADO | AG37: 1.328 | AH37: M3 | AI37: X | AJ37: 4 | AK37: V4 | AL37: 20230920 | AM37: DW83-900007615-10049556
A38: 900007706DW8310000554 | B38: 4600054398-30 | C38: 4600054398 | D38: 30 | E38: MXPO | F38: MXL | G38: 900007706 | H38: SF TC- CLADIMACO | I38: 5002330 | J38: CLASIFICADORA Y DISTR DE MAT P/CONS | K38: Z03 | L38: (AP) 15 Dias | M38: 10000554 | N38: Grava Triturada Caliza 40 mm - 1 1/2" | O38: DW83 | P38: MX-CED. VALLARTA | Q38: 20220704 | R38: 20271231 | S38: 20220704 | T38: 20271231 | U38: 282.55 | V38: MXN | W38: M3 | X38: 0 | Y38: MXN | Z38: M3 | AC38: 56103637 | AD38: 6644411540 | AE38: 1 | AF38: ENTREGADO | AG38: 1.37 | AH38: M3 | AI38: X | AJ38: 4 | AK38: V4 | AL38: 20230920 | AM38: DW83-900007706-10000554
A39: 900007706DW8310045015 | B39: 4600054398-50 | C39: 4600054398 | D39: 50 | E39: MXPO | F39: MXL | G39: 900007706 | H39: SF TC- CLADIMACO | I39: 5002330 | J39: CLASIFICADORA Y DISTR DE MAT P/CONS | K39: Z03 | L39: (AP) 15 Dias | M39: 10045015 | N39: Sello Triturado Caliza 13 mm - 1/2" | O39: DW83 | P39: MX-CED. VALLARTA | Q39: 20220704 | R39: 20271231 | S39: 20220704 | T39: 20271231 | U39: 420.95 | V39: MXN | W39: M3 | X39: 0 | Y39: MXN | Z39: M3 | AC39: 56103637 | AD39: 6644411540 | AE39: 1 | AF39: ENTREGADO | AG39: 1.43 | AH39: M3 | AI39: X | AJ39: 4 | AK39: V4 | AL39: 20230920 | AM39: DW83-900007706-10045015
A40: 900007706DW8310000332 | B40: 4600054398-60 | C40: 4600054398 | D40: 60 | E40: MXPO | F40: MXL | G40: 900007706 | H40: SF TC- CLADIMACO | I40: 5002330 | J40: CLASIFICADORA Y DISTR DE MAT P/CONS | K40: Z03 | L40: (AP) 15 Dias | M40: 10000332 | N40: Grava Triturada Pomez - Jal 20 mm - 3/4" | O40: DW83 | P40: MX-CED. VALLARTA | Q40: 20220704 | R40: 20271231 | S40: 20220704 | T40: 20271231 | U40: 108.93 | V40: MXN | W40: M3 | X40: 0 | Y40: MXN | Z40: M3 | AC40: 56103637 | AD40: 6644411540 | AE40: 1 | AF40: ENTREGADO | AG40: 0.8 | AH40: M3 | AI40: X | AJ40: 4 | AK40: V4 | AL40: 20230920 | AM40: DW83-900007706-10000332
A41: 900007706DW8310000320 | B41: 4600054398-10 | C41: 4600054398 | D41: 10 | E41: MXPO | F41: MXL | G41: 900007706 | H41: SF TC- CLADIMACO | I41: 5002330 | J41: CLASIFICADORA Y DISTR DE MAT P/CONS | K41: Z03 | L41: (AP) 15 Dias | M41: 10000320 | N41: Arena Triturada Caliza Malla 4 | O41: DW83 | P41: MX-CED. VALLARTA | Q41: 20220704 | R41: 20271231 | S41: 20220704 | T41: 20271231 | U41: 301.38 | V41: MXN | W41: M3 | X41: 0 | Y41: MXN | Z41: M3 | AC41: 56103638 | AD41: 6644411540 | AE41: 1 | AF41: ENTREGADO | AG41: 1.512 | AH41: M3 | AI41: X | AJ41: 4 | AK41: V4 | AL41: 20230920 | AM41: DW83-900007706-10000320
A42: 900007706DW8310000237 | B42: 4600054398-40 | C42: 4600054398 | D42: 40 | E42: MXPO | F42: MXL | G42: 900007706 | H42: SF TC- CLADIMACO | I42: 5002330 | J42: CLASIFICADORA Y DISTR DE MAT P/CONS | K42: Z03 | L42: (AP) 15 Dias | M42: 10000237 | N42: Grava Triturada Caliza 10 mm - 3/8" | O42: DW83 | P42: MX-CED. VALLARTA | Q42: 20220704 | R42: 20271231 | S42: 20220704 | T42: 20271231 | U42: 420.95 | V42: MXN | W42: M3 | X42: 0 | Y42: MXN | Z42: M3 | AC42: 56103637 | AD42: 6644411540 | AE42: 1 | AF42: ENTREGADO | AG42: 1.562 | AH42: M3 | AI42: X | AJ42: 4 | AK42: V4 | AL42: 20230920 | AM42: DW83-900007706-10000237
A43: 900007615DW8310000383 | B43: 4600054016-20 | C43: 4600054016 | D43: 20 | E43: MXPO | F43: MXL | G43: 900007615 | H43: SF TC- ARMAMPET LAS VARAS | I43: 5061801 | J43: ARMAMPET SA DE CV | K43: N30 | L43: (AP) NAFIN 30 Dias | M43: 10000383 | N43: Grava Triturada Basalto 40 mm - 1 1/2" | O43: DW83 | P43: MX-CED. VALLARTA | Q43: 20220523 | R43: 20281231 | S43: 20220523 | T43: 20271231 | U43: 220 | V43: MXN | W43: M3 | X43: 0 | Y43: MXN | Z43: M3 | AC43: 56103637 | AD43: 6644411540 | AE43: 1 | AF43: ENTREGADO | AG43: 1.359 | AH43: M3 | AI43: X | AJ43: 4 | AK43: V4 | AL43: 20230920 | AM43: DW83-900007615-10000383
A44: 900007615DW8310000320 | B44: 4600054016-40 | C44: 4600054016 | D44: 40 | E44: MXPO | F44: MXL | G44: 900007615 | H44: SF TC- ARMAMPET LAS VARAS | I44: 5061801 | J44: ARMAMPET SA DE CV | K44: N30 | L44: (AP) NAFIN 30 Dias | M44: 10000320 | N44: Arena Triturada Caliza Malla 4 | O44: DW83 | P44: MX-CED. VALLARTA | Q44: 20220523 | R44: 20281231 | S44: 20230714 | T44: 20281231 | U44: 386 | V44: MXN | W44: M3 | X44: 0 | Y44: MXN | Z44: M3 | AC44: 56103638 | AD44: 6644411540 | AE44: 1 | AF44: ENTREGADO | AG44: 1.512 | AH44: M3 | AI44: X | AJ44: 4 | AK44: V4 | AL44: 20230920 | AM44: DW83-900007615-10000320
...
