Workbook

Sheet Base Cedis D821
N1: VENTA | Q1: COSTO
A2: CONCAT1 | B2: CONCAT2 | C2: No. SF | D2: Nombre SF | E2: Cedis | F2: Destino | G2: Condicion de Expedicion | H2: Nombre Destino | I2: No. de material | J2: Nombre de material | K2: PV | L2: Inicio de vigencia | M2: Fin de vigencia | N2: Importe MP | O2: Importe Flete | P2: UM Venta | Q2: Importe Costo | R2: UM Costo | S2: Validacion 1 | T2: Validacion 2
A3: =CONCATENATE(C3,E3,F3,I3) | B3: =CONCATENATE(C3,E3,I3) | C3: 900007861 | D3: =IFERROR(VLOOKUP(C3,TRAOPE!$G:$H,2,0),"") | E3: D821 | F3: 66829768 | G3: =IFERROR(VLOOKUP(A3,Flete!$A:$E,5,0),"") | H3: =IFERROR(VLOOKUP(F3,TRAOPE!$AA:$AB,2,0),"") | I3: 10182873 | J3: =IFERROR(VLOOKUP(I3,Materiales!$A:$H,8,0),"") | K3: =IFERROR(VLOOKUP(I3,Materiales!$A:$G,7,0),"") | L3: 20170210 | M3: 20241206 | N3: 310 | O3: =IFERROR(VLOOKUP(A3,Flete!$A:$J,10,0),"") | P3: M3 | Q3: =IFERROR(IFERROR(VLOOKUP(A3,TRAOPE!$A:$U,21,0),VLOOKUP(B3,TRAOPE!$A:$U,21,0)),"") | R3: =IFERROR(IFERROR(VLOOKUP(A3,TRAOPE!$A:$W,23,0),VLOOKUP(B3,TRAOPE!$A:$W,23,0)),"") | S3: =IF(AND(P3="TN",R3="TN"),N3+N(O3),IF(G3&""="1",N(K3)*N3,(N3+N(O3))*N(K3))) | T3: =IF(Q3="","",Q3-S3)
A4: =CONCATENATE(C4,E4,F4,I4) | B4: =CONCATENATE(C4,E4,I4) | C4: 900007861 | D4: =IFERROR(VLOOKUP(C4,TRAOPE!$G:$H,2,0),"") | E4: D821 | F4: 66849697 | G4: =IFERROR(VLOOKUP(A4,Flete!$A:$E,5,0),"") | H4: =IFERROR(VLOOKUP(F4,TRAOPE!$AA:$AB,2,0),"") | I4: 10000861 | J4: =IFERROR(VLOOKUP(I4,Materiales!$A:$H,8,0),"") | K4: =IFERROR(VLOOKUP(I4,Materiales!$A:$G,7,0),"") | L4: 20170210 | M4: 20241206 | N4: 190 | O4: =IFERROR(VLOOKUP(A4,Flete!$A:$J,10,0),"") | P4: M3 | Q4: =IFERROR(IFERROR(VLOOKUP(A4,TRAOPE!$A:$U,21,0),VLOOKUP(B4,TRAOPE!$A:$U,21,0)),"") | R4: =IFERROR(IFERROR(VLOOKUP(A4,TRAOPE!$A:$W,23,0),VLOOKUP(B4,TRAOPE!$A:$W,23,0)),"") | S4: =IF(AND(P4="TN",R4="TN"),N4+N(O4),IF(G4&""="1",N(K4)*N4,(N4+N(O4))*N(K4))) | T4: =IF(Q4="","",Q4-S4)
A5: =CONCATENATE(C5,E5,F5,I5) | B5: =CONCATENATE(C5,E5,I5) | C5: 900007861 | D5: =IFERROR(VLOOKUP(C5,TRAOPE!$G:$H,2,0),"") | E5: D821 | F5: 67045033 | G5: =IFERROR(VLOOKUP(A5,Flete!$A:$E,5,0),"") | H5: =IFERROR(VLOOKUP(F5,TRAOPE!$AA:$AB,2,0),"") | I5: 10182872 | J5: =IFERROR(VLOOKUP(I5,Materiales!$A:$H,8,0),"") | K5: =IFERROR(VLOOKUP(I5,Materiales!$A:$G,7,0),"") | L5: 20170210 | M5: 20241206 | N5: 550 | O5: =IFERROR(VLOOKUP(A5,Flete!$A:$J,10,0),"") | P5: M3 | Q5: =IFERROR(IFERROR(VLOOKUP(A5,TRAOPE!$A:$U,21,0),VLOOKUP(B5,TRAOPE!$A:$U,21,0)),"") | R5: =IFERROR(IFERROR(VLOOKUP(A5,TRAOPE!$A:$W,23,0),VLOOKUP(B5,TRAOPE!$A:$W,23,0)),"") | S5: =IF(AND(P5="TN",R5="TN"),N5+N(O5),IF(G5&""="1",N(K5)*N5,(N5+N(O5))*N(K5))) | T5: =IF(Q5="","",Q5-S5)
A6: =CONCATENATE(C6,E6,F6,I6) | B6: =CONCATENATE(C6,E6,I6) | C6: 900007861 | D6: =IFERROR(VLOOKUP(C6,TRAOPE!$G:$H,2,0),"") | E6: D821 | F6: 67106297 | G6: =IFERROR(VLOOKUP(A6,Flete!$A:$E,5,0),"") | H6: =IFERROR(VLOOKUP(F6,TRAOPE!$AA:$AB,2,0),"") | I6: 10000861 | J6: =IFERROR(VLOOKUP(I6,Materiales!$A:$H,8,0),"") | K6: =IFERROR(VLOOKUP(I6,Materiales!$A:$G,7,0),"") | L6: 20170210 | M6: 20241206 | N6: 216 | O6: =IFERROR(VLOOKUP(A6,Flete!$A:$J,10,0),"") | P6: M3 | Q6: =IFERROR(IFERROR(VLOOKUP(A6,TRAOPE!$A:$U,21,0),VLOOKUP(B6,TRAOPE!$A:$U,21,0)),"") | R6: =IFERROR(IFERROR(VLOOKUP(A6,TRAOPE!$A:$W,23,0),VLOOKUP(B6,TRAOPE!$A:$W,23,0)),"") | S6: =IF(AND(P6="TN",R6="TN"),N6+N(O6),IF(G6&""="1",N(K6)*N6,(N6+N(O6))*N(K6))) | T6: =IF(Q6="","",Q6-S6)
A7: =CONCATENATE(C7,E7,F7,I7) | B7: =CONCATENATE(C7,E7,I7) | C7: 900007861 | D7: =IFERROR(VLOOKUP(C7,TRAOPE!$G:$H,2,0),"") | E7: D821 | F7: 67108560 | G7: =IFERROR(VLOOKUP(A7,Flete!$A:$E,5,0),"") | H7: =IFERROR(VLOOKUP(F7,TRAOPE!$AA:$AB,2,0),"") | I7: 10182872 | J7: =IFERROR(VLOOKUP(I7,Materiales!$A:$H,8,0),"") | K7: =IFERROR(VLOOKUP(I7,Materiales!$A:$G,7,0),"") | L7: 20170210 | M7: 20241206 | N7: 490 | O7: =IFERROR(VLOOKUP(A7,Flete!$A:$J,10,0),"") | P7: M3 | Q7: =IFERROR(IFERROR(VLOOKUP(A7,TRAOPE!$A:$U,21,0),VLOOKUP(B7,TRAOPE!$A:$U,21,0)),"") | R7: =IFERROR(IFERROR(VLOOKUP(A7,TRAOPE!$A:$W,23,0),VLOOKUP(B7,TRAOPE!$A:$W,23,0)),"") | S7: =IF(AND(P7="TN",R7="TN"),N7+N(O7),IF(G7&""="1",N(K7)*N7,(N7+N(O7))*N(K7))) | T7: =IF(Q7="","",Q7-S7)
A8: =CONCATENATE(C8,E8,F8,I8) | B8: =CONCATENATE(C8,E8,I8) | C8: 900007861 | D8: =IFERROR(VLOOKUP(C8,TRAOPE!$G:$H,2,0),"") | E8: D821 | F8: 67108560 | G8: =IFERROR(VLOOKUP(A8,Flete!$A:$E,5,0),"") | H8: =IFERROR(VLOOKUP(F8,TRAOPE!$AA:$AB,2,0),"") | I8: 10182873 | J8: =IFERROR(VLOOKUP(I8,Materiales!$A:$H,8,0),"") | K8: =IFERROR(VLOOKUP(I8,Materiales!$A:$G,7,0),"") | L8: 20170210 | M8: 20241206 | N8: 375 | O8: =IFERROR(VLOOKUP(A8,Flete!$A:$J,10,0),"") | P8: M3 | Q8: =IFERROR(IFERROR(VLOOKUP(A8,TRAOPE!$A:$U,21,0),VLOOKUP(B8,TRAOPE!$A:$U,21,0)),"") | R8: =IFERROR(IFERROR(VLOOKUP(A8,TRAOPE!$A:$W,23,0),VLOOKUP(B8,TRAOPE!$A:$W,23,0)),"") | S8: =IF(AND(P8="TN",R8="TN"),N8+N(O8),IF(G8&""="1",N(K8)*N8,(N8+N(O8))*N(K8))) | T8: =IF(Q8="","",Q8-S8)
A9: =CONCATENATE(C9,E9,F9,I9) | B9: =CONCATENATE(C9,E9,I9) | C9: 900007861 | D9: =IFERROR(VLOOKUP(C9,TRAOPE!$G:$H,2,0),"") | E9: D821 | F9: 67112558 | G9: =IFERROR(VLOOKUP(A9,Flete!$A:$E,5,0),"") | H9: =IFERROR(VLOOKUP(F9,TRAOPE!$AA:$AB,2,0),"") | I9: 10000861 | J9: =IFERROR(VLOOKUP(I9,Materiales!$A:$H,8,0),"") | K9: =IFERROR(VLOOKUP(I9,Materiales!$A:$G,7,0),"") | L9: 20170210 | M9: 20241206 | N9: 155 | O9: =IFERROR(VLOOKUP(A9,Flete!$A:$J,10,0),"") | P9: M3 | Q9: =IFERROR(IFERROR(VLOOKUP(A9,TRAOPE!$A:$U,21,0),VLOOKUP(B9,TRAOPE!$A:$U,21,0)),"") | R9: =IFERROR(IFERROR(VLOOKUP(A9,TRAOPE!$A:$W,23,0),VLOOKUP(B9,TRAOPE!$A:$W,23,0)),"") | S9: =IF(AND(P9="TN",R9="TN"),N9+N(O9),IF(G9&""="1",N(K9)*N9,(N9+N(O9))*N(K9))) | T9: =IF(Q9="","",Q9-S9)
A10: =CONCATENATE(C10,E10,F10,I10) | B10: =CONCATENATE(C10,E10,I10) | C10: 900007861 | D10: =IFERROR(VLOOKUP(C10,TRAOPE!$G:$H,2,0),"") | E10: D821 | F10: 66849697 | G10: =IFERROR(VLOOKUP(A10,Flete!$A:$E,5,0),"") | H10: =IFERROR(VLOOKUP(F10,TRAOPE!$AA:$AB,2,0),"") | I10: 10182872 | J10: =IFERROR(VLOOKUP(I10,Materiales!$A:$H,8,0),"") | K10: =IFERROR(VLOOKUP(I10,Materiales!$A:$G,7,0),"") | L10: 20240308 | M10: 20251031 | N10: 550 | O10: =IFERROR(VLOOKUP(A10,Flete!$A:$J,10,0),"") | P10: M3 | Q10: =IFERROR(IFERROR(VLOOKUP(A10,TRAOPE!$A:$U,21,0),VLOOKUP(B10,TRAOPE!$A:$U,21,0)),"") | R10: =IFERROR(IFERROR(VLOOKUP(A10,TRAOPE!$A:$W,23,0),VLOOKUP(B10,TRAOPE!$A:$W,23,0)),"") | S10: =IF(AND(P10="TN",R10="TN"),N10+N(O10),IF(G10&""="1",N(K10)*N10,(N10+N(O10))*N(K10))) | T10: =IF(Q10="","",Q10-S10)
A11: =CONCATENATE(C11,E11,F11,I11) | B11: =CONCATENATE(C11,E11,I11) | C11: 900007861 | D11: =IFERROR(VLOOKUP(C11,TRAOPE!$G:$H,2,0),"") | E11: D821 | F11: 66849697 | G11: =IFERROR(VLOOKUP(A11,Flete!$A:$E,5,0),"") | H11: =IFERROR(VLOOKUP(F11,TRAOPE!$AA:$AB,2,0),"") | I11: 10182873 | J11: =IFERROR(VLOOKUP(I11,Materiales!$A:$H,8,0),"") | K11: =IFERROR(VLOOKUP(I11,Materiales!$A:$G,7,0),"") | L11: 20230912 | M11: 20251031 | N11: 310 | O11: =IFERROR(VLOOKUP(A11,Flete!$A:$J,10,0),"") | P11: M3 | Q11: =IFERROR(IFERROR(VLOOKUP(A11,TRAOPE!$A:$U,21,0),VLOOKUP(B11,TRAOPE!$A:$U,21,0)),"") | R11: =IFERROR(IFERROR(VLOOKUP(A11,TRAOPE!$A:$W,23,0),VLOOKUP(B11,TRAOPE!$A:$W,23,0)),"") | S11: =IF(AND(P11="TN",R11="TN"),N11+N(O11),IF(G11&""="1",N(K11)*N11,(N11+N(O11))*N(K11))) | T11: =IF(Q11="","",Q11-S11)
A12: =CONCATENATE(C12,E12,F12,I12) | B12: =CONCATENATE(C12,E12,I12) | C12: 900007861 | D12: =IFERROR(VLOOKUP(C12,TRAOPE!$G:$H,2,0),"") | E12: D821 | F12: 67015215 | G12: =IFERROR(VLOOKUP(A12,Flete!$A:$E,5,0),"") | H12: =IFERROR(VLOOKUP(F12,TRAOPE!$AA:$AB,2,0),"") | I12: 10000861 | J12: =IFERROR(VLOOKUP(I12,Materiales!$A:$H,8,0),"") | K12: =IFERROR(VLOOKUP(I12,Materiales!$A:$G,7,0),"") | L12: 20240403 | M12: 20251031 | N12: 205 | O12: =IFERROR(VLOOKUP(A12,Flete!$A:$J,10,0),"") | P12: M3 | Q12: =IFERROR(IFERROR(VLOOKUP(A12,TRAOPE!$A:$U,21,0),VLOOKUP(B12,TRAOPE!$A:$U,21,0)),"") | R12: =IFERROR(IFERROR(VLOOKUP(A12,TRAOPE!$A:$W,23,0),VLOOKUP(B12,TRAOPE!$A:$W,23,0)),"") | S12: =IF(AND(P12="TN",R12="TN"),N12+N(O12),IF(G12&""="1",N(K12)*N12,(N12+N(O12))*N(K12))) | T12: =IF(Q12="","",Q12-S12)
A13: =CONCATENATE(C13,E13,F13,I13) | B13: =CONCATENATE(C13,E13,I13) | C13: 900007861 | D13: =IFERROR(VLOOKUP(C13,TRAOPE!$G:$H,2,0),"") | E13: D821 | F13: 67045033 | G13: =IFERROR(VLOOKUP(A13,Flete!$A:$E,5,0),"") | H13: =IFERROR(VLOOKUP(F13,TRAOPE!$AA:$AB,2,0),"") | I13: 10182873 | J13: =IFERROR(VLOOKUP(I13,Materiales!$A:$H,8,0),"") | K13: =IFERROR(VLOOKUP(I13,Materiales!$A:$G,7,0),"") | L13: 20230912 | M13: 20251031 | N13: 348 | O13: =IFERROR(VLOOKUP(A13,Flete!$A:$J,10,0),"") | P13: M3 | Q13: =IFERROR(IFERROR(VLOOKUP(A13,TRAOPE!$A:$U,21,0),VLOOKUP(B13,TRAOPE!$A:$U,21,0)),"") | R13: =IFERROR(IFERROR(VLOOKUP(A13,TRAOPE!$A:$W,23,0),VLOOKUP(B13,TRAOPE!$A:$W,23,0)),"") | S13: =IF(AND(P13="TN",R13="TN"),N13+N(O13),IF(G13&""="1",N(K13)*N13,(N13+N(O13))*N(K13))) | T13: =IF(Q13="","",Q13-S13)
A14: =CONCATENATE(C14,E14,F14,I14) | B14: =CONCATENATE(C14,E14,I14) | C14: 900007861 | D14: =IFERROR(VLOOKUP(C14,TRAOPE!$G:$H,2,0),"") | E14: D821 | F14: 67161235 | G14: =IFERROR(VLOOKUP(A14,Flete!$A:$E,5,0),"") | H14: =IFERROR(VLOOKUP(F14,TRAOPE!$AA:$AB,2,0),"") | I14: 10182872 | J14: =IFERROR(VLOOKUP(I14,Materiales!$A:$H,8,0),"") | K14: =IFERROR(VLOOKUP(I14,Materiales!$A:$G,7,0),"") | L14: 20240308 | M14: 20251031 | N14: 490 | O14: =IFERROR(VLOOKUP(A14,Flete!$A:$J,10,0),"") | P14: M3 | Q14: =IFERROR(IFERROR(VLOOKUP(A14,TRAOPE!$A:$U,21,0),VLOOKUP(B14,TRAOPE!$A:$U,21,0)),"") | R14: =IFERROR(IFERROR(VLOOKUP(A14,TRAOPE!$A:$W,23,0),VLOOKUP(B14,TRAOPE!$A:$W,23,0)),"") | S14: =IF(AND(P14="TN",R14="TN"),N14+N(O14),IF(G14&""="1",N(K14)*N14,(N14+N(O14))*N(K14))) | T14: =IF(Q14="","",Q14-S14)
... A171: =CONCATENATE(C171,E171,F171,I171) | B171: =CONCATENATE(C171,E171,I171) | C171: 900008803 | D171: =IFERROR(VLOOKUP(C171,TRAOPE!$G:$H,2,0),"") | E171: D821 | F171: 67317945 | G171: =IFERROR(VLOOKUP(A171,Flete!$A:$E,5,0),"") | H171: =IFERROR(VLOOKUP(F171,TRAOPE!$AA:$AB,2,0),"") | I171: 10000861 | J171: =IFERROR(VLOOKUP(I171,Materiales!$A:$H,8,0),"") | K171: =IFERROR(VLOOKUP(I171,Materiales!$A:$G,7,0),"") | L171: 20250528 | M171: 20250710 | N171: 215.52 | O171: =IFERROR(VLOOKUP(A171,Flete!$A:$J,10,0),"") | P171: M3 | Q171: =IFERROR(IFERROR(VLOOKUP(A171,TRAOPE!$A:$U,21,0),VLOOKUP(B171,TRAOPE!$A:$U,21,0)),"") | R171: =IFERROR(IFERROR(VLOOKUP(A171,TRAOPE!$A:$W,23,0),VLOOKUP(B171,TRAOPE!$A:$W,23,0)),"") | S171: =IF(AND(P171="TN",R171="TN"),N171+N(O171),IF(G171&""="1",N(K171)*N171,(N171+N(O171))*N(K171))) | T171: =IF(Q171="","",Q171-S171)

Sheet MP
A1: No. SF | B1: Cedis | C1: Destino | D1: No. Material | E1: Nombre Material | F1: Importe MP | G1: Moneda | H1: Cantidad | I1: UM | J1: C | K1: Inicio Vigencia | L1: Fin Vigencia
A2: 900007861 | B2: D821 | C2: 66829768 | D2: 10182873 | F2: 310 | I2: M3 | K2: 20170210 | L2: 20241206
A3: 900007861 | B3: D821 | C3: 66849697 | D3: 10000861 | F3: 190 | I3: M3 | K3: 20170210 | L3: 20241206
A4: 900007861 | B4: D821 | C4: 67045033 | D4: 10182872 | F4: 550 | I4: M3 | K4: 20170210 | L4: 20241206
A5: 900007861 | B5: D821 | C5: 67106297 | D5: 10000861 | F5: 216 | I5: M3 | K5: 20170210 | L5: 20241206
A6: 900007861 | B6: D821 | C6: 67108560 | D6: 10182872 | F6: 490 | I6: M3 | K6: 20170210 | L6: 20241206
A7: 900007861 | B7: D821 | C7: 67108560 | D7: 10182873 | F7: 375 | I7: M3 | K7: 20170210 | L7: 20241206
A8: 900007861 | B8: D821 | C8: 67112558 | D8: 10000861 | F8: 155 | I8: M3 | K8: 20170210 | L8: 20241206
A9: 900007861 | B9: D821 | C9: 66849697 | D9: 10182872 | F9: 550 | I9: M3 | K9: 20240308 | L9: 20251031
A10: 900007861 | B10: D821 | C10: 66849697 | D10: 10182873 | F10: 310 | I10: M3 | K10: 20230912 | L10: 20251031
A11: 900007861 | B11: D821 | C11: 67015215 | D11: 10000861 | F11: 205 | I11: M3 | K11: 20240403 | L11: 20251031
A12: 900007861 | B12: D821 | C12: 67045033 | D12: 10182873 | F12: 348 | I12: M3 | K12: 20230912 | L12: 20251031
A13: 900007861 | B13: D821 | C13: 67161235 | D13: 10182872 | F13: 490 | I13: M3 | K13: 20240308 | L13: 20251031
... A170: 900008803 | B170: D821 | C170: 67317945 | D170: 10000861 | F170: 215.52 | I170: M3 | K170: 20250528 | L170: 20250710

Sheet Flete
A1: Concat1 | B1: No. SF | C1: Cedis | D1: Destino | E1: Cond. Exp. | F1: Material | H1: Nombre Material | J1: Importe Flete | K1: Moneda | L1: Cantidad | M1: UM | N1: C | P1: Inicio Vigencia | Q1: Fin Vigencia
A2: 900007861D8216701521510000861 | B2: 900007861 | C2: D821 | D2: 67015215 | E2: 1 | F2: 10000861 | J2: 100 | M2: M3 | P2: 20240403 | Q2: 20251031
A3: 900007861D8216704503310182872 | B3: 900007861 | C3: D821 | D3: 67045033 | E3: 1 | F3: 10182872 | J3: 40 | M3: M3 | P3: 20170210 | Q3: 20241206
A4: 900007861D8216704503310182873 | B4: 900007861 | C4: D821 | D4: 67045033 | E4: 1 | F4: 10182873 | J4: 40 | M4: M3 | P4: 20231014 | Q4: 20251031
A5: 900007861D8216710629710000861 | B5: 900007861 | C5: D821 | D5: 67106297 | E5: 1 | F5: 10000861 | J5: 73 | M5: M3 | P5: 20170210 | Q5: 20241206
A6: 900007861D8216710856010182872 | B6: 900007861 | C6: D821 | D6: 67108560 | E6: 1 | F6: 10182872 | J6: 387 | M6: M3 | P6: 20170210 | Q6: 20241206
A7: 900007861D8216710856010182873 | B7: 900007861 | C7: D821 | D7: 67108560 | E7: 1 | F7: 10182873 | J7: 377 | M7: M3 | P7: 20170210 | Q7: 20241206
A8: 900007861D8216712295610000861 | B8: 900007861 | C8: D821 | D8: 67122956 | E8: 1 | F8: 10000861 | J8: 85 | M8: M3 | P8: 20240715 | Q8: 20260215
A9: 900008803D8216697706310182872 | B9: 900008803 | C9: D821 | D9: 66977063 | E9: 1 | F9: 10182872 | J9: 65 | M9: M3 | P9: 20250120 | Q9: 99991231
A10: 900008803D8216697706310182873 | B10: 900008803 | C10: D821 | D10: 66977063 | E10: 1 | F10: 10182873 | J10: 65 | M10: M3 | P10: 20250120 | Q10: 99991231
A11: 900008803D8216701521510000861 | B11: 900008803 | C11: D821 | D11: 67015215 | E11: 1 | F11: 10000861 | J11: 100 | M11: M3 | P11: 20240816 | Q11: 99991231
A12: 900008803D8216704503310182872 | B12: 900008803 | C12: D821 | D12: 67045033 | E12: 1 | F12: 10182872 | J12: 40 | M12: M3 | P12: 20240620 | Q12: 20251031
A13: 900008803D8216704503310182873 | B13: 900008803 | C13: D821 | D13: 67045033 | E13: 1 | F13: 10182873 | J13: 40 | M13: M3 | P13: 20240620 | Q13: 20251031
... A55: 900008803D8216730399510182873 | B55: 900008803 | C55: D821 | D55: 67303995 | E55: 1 | F55: 10182873 | J55: 65 | M55: M3 | P55: 20250304 | Q55: 20250507

Sheet Materiales
A1: Material | B1: TpMt | C1: Denom | D1: UMA | E1: Contador | F1: UMB | G1: PV | H1: Nombre Material
A2: 10000001 | B2: ZFER | C2: 1000 | D2: M3 | E2: 1000 | F2: TN | G2: 1262 | H2: GRAVA ANDESITA 10 MM (3/8")
A3: 10000003 | B3: ZFER | C3: 1000 | D3: M3 | E3: 1000 | F3: TN | G3: 1443 | H3: GRAVA CALIZA 10 MM (3/8")
A4: 10000006 | B4: ZFER | C4: 1000 | D4: M3 | E4: 1000 | F4: TN | G4: 1490 | H4: GRAVA RIO 10 MM (3/8")
A5: 10000007 | B5: ZFER | C5: 1000 | D5: M3 | E5: 1000 | F5: TN | G5: 1488 | H5: GRAVA BASALTO 13 MM (1/2")
A6: 10000008 | B6: ZFER | C6: 1000 | D6: M3 | E6: 1000 | F6: TN | G6: 1358 | H6: GRAVA CALIZA 13 MM (1/2")
A7: 10000011 | B7: ZFER | C7: 1000 | D7: M3 | E7: 1000 | F7: TN | G7: 1323 | H7: GRAVA ANDESITA 20 MM (3/4")
A8: 10000013 | B8: ZFER | C8: 1000 | D8: M3 | E8: 1000 | F8: TN | G8: 1514 | H8: GRAVA BASALTO 20 MM (3/4")
A9: 10000014 | B9: ZFER | C9: 1000 | D9: M3 | E9: 1000 | F9: TN | G9: 1400 | H9: GRAVA CALIZA 20 MM (3/4")
A10: 10000015 | B10: ZFER | C10: 1000 | D10: M3 | E10: 1000 | F10: TN | G10: 1410 | H10: GRAVA GRANITO 20 MM (3/4")
A11: 10000017 | B11: ZFER | C11: 1000 | D11: M3 | E11: 1000 | F11: TN | G11: 1475 | H11: GRAVA RIOLITA 20 MM (3/4")
A12: 10000019 | B12: ZFER | C12: 1000 | D12: M3 | E12: 1000 | F12: TN | G12: 1515 | H12: GRAVA RIO 20 MM (3/4")
A13: 10000020 | B13: ZFER | C13: 1000 | D13: M3 | E13: 1 | F13: TN | G13: 1 | H13: GRAVA MAQUILA 40MM (1 1/2")
... A2291: 10268770 | B2291: ZFE3 | C2291: 1000 | D2291: M3 | E2291: 1000 | F2291: TN | G2291: 1240 | H2291: MP GRAVA TRIT CALIZA 40MM 1 1/2" - ESP
A2292: 10268901 | B2292: ZFE3 | C2292: 1000 | D2292: M3 | E2292: 1000 | G2292: 1560 | H2292: MP GRAVA ANDESITA GRIS 3/4" - CAPADA
A2293: 10267983 | C2293: 1000 | G2293: 1800 | H2293: ESCORIA ALTO HORNO 3/4
A2294: 10268996 | C2294: 1000 | G2294: 1329 | H2294: GRAVA TRITURADA CALIZA 40 MM - 11/2"
A2295: 10269072 | C2295: 1000 | G2295: 1700 | H2295: BASE HIDRÁULICA SCREEN
A2296: 10269225 | B2296: ZFE3 | C2296: 1000 | D2296: M3 | E2296: 1000 | G2296: 1289 | H2296: MP ARENA CALIZA LAVADA MALLA 4 - DELTA I
A2297: 10269245 | B2297: ZFE3 | C2297: 1000 | D2297: M3 | E2297: 1000 | G2297: 1410 | H2297: MP GRAVA TRITURADA CALIZA 3/8 - 10MM
A2298: 10269246 | B2298: ZFE3 | C2298: 1000 | D2298: M3 | E2298: 1000 | G2298: 1400 | H2298: MP GRAVA TRITURADA CALIZA 1 1/2 - 40MM
A2299: 10269247 | B2299: ZFE3 | C2299: 1000 | D2299: M3 | E2299: 1000 | G2299: 1560 | H2299: MP ARENA TRIT CALIZA M-4
A2300: 10270431 | B2300: ZFE3 | C2300: 1000 | D2300: M3 | E2300: 1000 | G2300: 1423 | H2300: MP GRAVA RIOLITA 13 MM - 1/2"
A2301: 10270898 | B2301: ZFE3 | C2301: 1000 | D2301: M3 | E2301: 1000 | G2301: 1551 | H2301: MP BASE H. TRIT. BASALTO 1 1/2" A FINOS
A2302: 10270911 | B2302: ZFE3 | C2302: 1000 | D2302: M3 | E2302: 1000 | G2302: 1360 | H2302: MP GRAVA TRIT. BASALTO 40 MM - 1 1/2"
A2303: 10270912 | B2303: ZFE3 | C2303: 1000 | D2303: M3 | E2303: 1000 | G2303: 1589 | H2303: MP ARENA TRIT. BASALTO MALLA 4
A2304: 10270913 | B2304: ZFE3 | C2304: 1000 | D2304: M3 | E2304: 1000 | G2304: 1395 | H2304: MP GRAVA TRIT. BASALTO 20 MM - 3/4
A2305: 10270914 | B2305: ZFE3 | C2305: 1000 | D2305: M3 | E2305: 1000 | G2305: 1623 | H2305: MP ARENA ANDESITA BC
A2306: 10270824 | B2306: M3 | C2306: 1000 | D2306: M3 | E2306: 10007640 | G2306: 1325 | H2306: MP ARENA TRITURADA CALIZA MALLA 5
A2307: 10270825 | B2307: M3 | C2307: 1000 | D2307: M3 | E2307: 10000003 | G2307: 1242 | H2307: MP GRAVA TRITURADA CALIZA 10MM (3/8”)
... A2319: 10272527 | B2319: ZFE3 | C2319: 1000 | D2319: M3 | E2319: 1000 | G2319: 1620 | H2319: CNC - NO CLASIFICADO
A2320: 10000332 | C2320: 1000 | D2320: M3 | E2320: 1000 | G2320: 800 | H2320: Grava Triturada Pomez - Jal 20 mm - 3/4"
A2321: 10273001 | B2321: ZFE3 | C2321: 1000 | D2321: M3 | E2321: 1000 | G2321: 1688 | H2321: MP ARENA TRIT. BASALTO MALLA 4
A2322: 10273002 | B2322: ZFE3 | C2322: 1000 | D2322: M3 | E2322: 1000 | G2322: 1466 | H2322: MP GRAVA TRIT. BASALTO 20 MM - 3/4"
A2323: 10273351 | B2323: ZFE3 | C2323: 1000 | D2323: M3 | E2323: 1000 | G2323: 1612 | H2323: MP ARENA TRIT. CALIZA MALLA 4
A2324: 10273352 | B2324: ZFE3 | C2324: 1000 | D2324: M3 | E2324: 1000 | G2324: 1492 | H2324: MP GRAVA TRIT. CALIZA 20 MM - 3/4"
A2325: 10271724 | B2325: ZFE3 | C2325: 1000 | D2325: M3 | E2325: 1000 | G2325: 1900 | H2325: MP RESIDUO DE CONCRETO
A2326: 10000677 | C2326: 1000 | D2326: M3 | G2326: 1164 | H2326: Grava Triturada Caliza 20 mm - 3/4"
A2327: 10274190 | B2327: ZFE3 | C2327: 1000 | D2327: M3 | E2327: 1000 | G2327: 1800 | H2327: MP BASE HIDRAULICA ANDESITA 70-30
A2328: 10274601 | B2328: ZFE3 | C2328: 1000 | D2328: M3 | E2328: 1000 | G2328: 1447 | H2328: MP ARENA BASALTO N° 4
...

Sheet TRAOPE
A1: Concat1 | B1: Contrato_Pos | C1: Doc. Compras | D1: Pos | E1: Org.compras | F1: Grp-Compr. | G1: Ship From | H1: Nombre SF | I1: Proveedor | J1: Nombre Prov | K1: Cond. Pago | L1: Descr. Cond Pago | M1: Material | N1: Descripción | O1: Centro | P1: Descripción Centro | Q1: In.perído validez | R1: Fin perído validez | S1: Válido de | T1: Validez a | U1: Precio neto pedido | V1: Moneda | W1: UM Precio Pedido | X1: Importe Condición | Y1: Moneda KONP | Z1: UM Ctd Base | AA1: Destino | AB1: Nombre Destino | AC1: Cuenta de mayor | AD1: Centro de costo | AE1: Cond. Exp. | AF1: Descr. Cond. Exp. | AG1: Peso Vol. | AH1: UMB | AI1: Ind. Oblig. Conf. Ped. | AJ1: Ctrl-Conf. | AK1: IVA | AL1: Modif_Date | AM1: Ruta
A2: 900007861D82110182873 | B2: 4600055599-30 | C2: 4600055599 | D2: 30 | E2: MXPO | F2: MXL | G2: 900007861 | H2: SF TP - IASSO TANKAH | I2: 5086846 | J2: IASSO CONSTRUCCIONES SA DE CV | K2: N90 | L2: (AP) NAFIN 90 Dias | M2: 10182873 | N2: GRAVA TRITURDA CALIZA 20MM 3/4 | O2: D821 | P2: MX-CEDIS TANKAH | Q2: 20231014 | R2: 20281231 | S2: 20231014 | T2: 20281231 | U2: 170 | V2: MXN | W2: M3 | X2: 0 | Y2: MXN | Z2: M3 | AC2: 56103637 | AD2: 6622111540 | AE2: 1 | AF2: ENTREGADO | AG2: 1.146 | AH2: M3 | AI2: X | AJ2: 4 | AK2: V4 | AL2: 20231017 | AM2: D821-900007861-10182873
A3: 900007861D82110182872 | B3: 4600055599-20 | C3: 4600055599 | D3: 20 | E3: MXPO | F3: MXL | G3: 900007861 | H3: SF TP - IASSO TANKAH | I3: 5086846 | J3: IASSO CONSTRUCCIONES SA DE CV | K3: N90 | L3: (AP) NAFIN 90 Dias | M3: 10182872 | N3: ARENA TRITURADA CALIZA MALLA 4 | O3: D821 | P3: MX-CEDIS TANKAH | Q3: 20231014 | R3: 20281231 | S3: 20231014 | T3: 20281231 | U3: 193 | V3: MXN | W3: M3 | X3: 0 | Y3: MXN | Z3: M3 | AC3: 56103638 | AD3: 6622111540 | AE3: 1 | AF3: ENTREGADO | AG3: 1.41 | AH3: M3 | AI3: X | AJ3: 4 | AK3: V4 | AL3: 20231018 | AM3: D821-900007861-10182872
A4: 900007861D82110000861 | B4: 4600055599-10 | C4: 4600055599 | D4: 10 | E4: MXPO | F4: MXL | G4: 900007861 | H4: SF TP - IASSO TANKAH | I4: 5086846 | J4: IASSO CONSTRUCCIONES SA DE CV | K4: N90 | L4: (AP) NAFIN 90 Dias | M4: 10000861 | N4: Base H Triturada Caliza 1 1/2" a Finos | O4: D821 | P4: MX-CEDIS TANKAH | Q4: 20231014 | R4: 20281231 | S4: 20231014 | T4: 20281231 | U4: 68 | V4: MXN | W4: M3 | X4: 0 | Y4: MXN | Z4: M3 | AC4: 56103590 | AD4: 6622111540 | AE4: 1 | AF4: ENTREGADO | AG4: 1.52 | AH4: M3 | AI4: X | AJ4: 4 | AK4: V4 | AL4: 20231018 | AM4: D821-900007861-10000861
A5: 900008803D82110182872 | B5: 4600069726-20 | C5: 4600069726 | D5: 20 | E5: MXPO | F5: MXL | G5: 900008803 | H5: SF TP-ROCK CRUSHERS TANKAH | I5: 5092712 | J5: ROCK CRUSHERS SA DE CV | K5: Z04 | L5: (AP) 30 Dias | M5: 10182872 | N5: ARENA TRITURADA CALIZA MALLA 4 | O5: D821 | P5: MX-CEDIS TANKAH | Q5: 20240620 | R5: 20291231 | S5: 20240620 | T5: 20291231 | U5: 245 | V5: MXN | W5: M3 | X5: 0 | Y5: MXN | Z5: M3 | AC5: 56103638 | AD5: 6622111540 | AE5: 1 | AF5: ENTREGADO | AG5: 1.41 | AH5: M3 | AI5: X | AJ5: 4 | AK5: V4 | AL5: 20240624 | AM5: D821-900008803-10182872
A6: 900008803D82110182873 | B6: 4600069726-10 | C6: 4600069726 | D6: 10 | E6: MXPO | F6: MXL | G6: 900008803 | H6: SF TP-ROCK CRUSHERS TANKAH | I6: 5092712 | J6: ROCK CRUSHERS SA DE CV | K6: Z04 | L6: (AP) 30 Dias | M6: 10182873 | N6: GRAVA TRITURDA CALIZA 20MM 3/4 | O6: D821 | P6: MX-CEDIS TANKAH | Q6: 20240620 | R6: 20291231 | S6: 20240620 | T6: 20291231 | U6: 200 | V6: MXN | W6: M3 | X6: 0 | Y6: MXN | Z6: M3 | AC6: 56103637 | AD6: 6622111540 | AE6: 1 | AF6: ENTREGADO | AG6: 1.146 | AH6: M3 | AI6: X | AJ6: 4 | AK6: V4 | AL6: 20240624 | AM6: D821-900008803-10182873
A7: 900008803D82110261071 | B7: 4600069726-50 | C7: 4600069726 | D7: 50 | E7: MXPO | F7: MXL | G7: 900008803 | H7: SF TP-ROCK CRUSHERS TANKAH | I7: 5092712 | J7: ROCK CRUSHERS SA DE CV | K7: Z04 | L7: (AP) 30 Dias | M7: 10261071 | N7: CRUDO CALIZA - NG | O7: D821 | P7: MX-CEDIS TANKAH | Q7: 20240620 | R7: 20291231 | S7: 20241008 | T7: 20291231 | U7: 15 | V7: MXN | W7: M3 | X7: 0 | Y7: MXN | Z7: M3 | AC7: 56103636 | AD7: 6622111540 | AE7: 1 | AF7: ENTREGADO | AG7: 1.5 | AH7: M3 | AI7: X | AJ7: 4 | AK7: V4 | AL7: 20241205 | AM7: D821-900008803-10261071
A8: 900008803D82110261072 | B8: 4600069726-60 | C8: 4600069726 | D8: 60 | E8: MXPO | F8: MXL | G8: 900008803 | H8: SF TP-ROCK CRUSHERS TANKAH | I8: 5092712 | J8: ROCK CRUSHERS SA DE CV | K8: Z04 | L8: (AP) 30 Dias | M8: 10261072 | N8: SUB BASE CALIZA DE 3” A FINOS - NG | O8: D821 | P8: MX-CEDIS TANKAH | Q8: 20240620 | R8: 20291231 | S8: 20241008 | T8: 20291231 | U8: 25 | V8: MXN | W8: M3 | X8: 0 | Y8: MXN | Z8: M3 | AC8: 56103590 | AD8: 6622111540 | AE8: 1 | AF8: ENTREGADO | AG8: 1.36 | AH8: M3 | AI8: X | AJ8: 4 | AK8: V4 | AL8: 20250204 | AM8: D821-900008803-10261072
A9: 900008803D82110000861 | B9: 4600069726-40 | C9: 4600069726 | D9: 40 | E9: MXPO | F9: MXL | G9: 900008803 | H9: SF TP-ROCK CRUSHERS TANKAH | I9: 5092712 | J9: ROCK CRUSHERS SA DE CV | K9: Z04 | L9: (AP) 30 Dias | M9: 10000861 | N9: Base H Triturada Caliza 1 1/2" a Finos | O9: D821 | P9: MX-CEDIS TANKAH | Q9: 20240620 | R9: 20291231 | S9: 20240816 | T9: 20291231 | U9: 25 | V9: MXN | W9: M3 | X9: 0 | Y9: MXN | Z9: M3 | AC9: 56103590 | AD9: 6622111540 | AE9: 1 | AF9: ENTREGADO | AG9: 1.52 | AH9: M3 | AI9: X | AJ9: 4 | AK9: V4 | AL9: 20240910 | AM9: D821-900008803-10000861
