Workbook

Sheet Base Cedis DW64
N1: VENTA | Q1: COSTO
A2: CONCAT1 | B2: CONCAT2 | C2: No. SF | D2: Nombre SF | E2: Cedis | F2: Destino | G2: Condicion de Expedicion | H2: Nombre Destino | I2: No. de material | J2: Nombre de material | K2: PV | L2: Inicio de vigencia | M2: Fin de vigencia | N2: Importe MP | O2: Importe Flete | P2: UM Venta | Q2: Importe Costo | R2: UM Costo | S2: Validacion 1 | T2: Validacion 2
A3: =CONCATENATE(C3,E3,F3,I3) | B3: =CONCATENATE(C3,E3,I3) | C3: 900000080 | D3: =IFERROR(VLOOKUP(C3,TRAOPE!$G:$H,2,0),"") | E3: DW64 | F3: D087 | G3: =IFERROR(VLOOKUP(A3,Flete!$A:$E,5,0),"") | H3: =IFERROR(VLOOKUP(F3,TRAOPE!$AA:$AB,2,0),"") | I3: 10000651 | J3: =IFERROR(VLOOKUP(I3,Materiales!$A:$H,8,0),"") | K3: =IFERROR(VLOOKUP(I3,Materiales!$A:$G,7,0),"") | L3: 20230501 | M3: 20250131 | N3: 53.21 | O3: =IFERROR(VLOOKUP(A3,Flete!$A:$J,10,0),"") | P3: TN | Q3: =IFERROR(IFERROR(VLOOKUP(A3,TRAOPE!$A:$U,21,0),VLOOKUP(B3,TRAOPE!$A:$U,21,0)),"") | R3: =IFERROR(IFERROR(VLOOKUP(A3,TRAOPE!$A:$W,23,0),VLOOKUP(B3,TRAOPE!$A:$W,23,0)),"") | S3: =IF(AND(P3="TN",R3="TN"),N3+N(O3),IF(G3&""="1",N(K3)*N3,(N3+N(O3))*N(K3))) | T3: =IF(Q3="","",Q3-S3)
A4: =CONCATENATE(C4,E4,F4,I4) | B4: =CONCATENATE(C4,E4,I4) | C4: 900000080 | D4: =IFERROR(VLOOKUP(C4,TRAOPE!$G:$H,2,0),"") | E4: DW64 | F4: D103 | G4: =IFERROR(VLOOKUP(A4,Flete!$A:$E,5,0),"") | H4: =IFERROR(VLOOKUP(F4,TRAOPE!$AA:$AB,2,0),"") | I4: 10000651 | J4: =IFERROR(VLOOKUP(I4,Materiales!$A:$H,8,0),"") | K4: =IFERROR(VLOOKUP(I4,Materiales!$A:$G,7,0),"") | L4: 20230501 | M4: 20250131 | N4: 53.21 | O4: =IFERROR(VLOOKUP(A4,Flete!$A:$J,10,0),"") | P4: TN | Q4: =IFERROR(IFERROR(VLOOKUP(A4,TRAOPE!$A:$U,21,0),VLOOKUP(B4,TRAOPE!$A:$U,21,0)),"") | R4: =IFERROR(IFERROR(VLOOKUP(A4,TRAOPE!$A:$W,23,0),VLOOKUP(B4,TRAOPE!$A:$W,23,0)),"") | S4: =IF(AND(P4="TN",R4="TN"),N4+N(O4),IF(G4&""="1",N(K4)*N4,(N4+N(O4))*N(K4))) | T4: =IF(Q4="","",Q4-S4)
A5: =CONCATENATE(C5,E5,F5,I5) | B5: =CONCATENATE(C5,E5,I5) | C5: 900000080 | D5: =IFERROR(VLOOKUP(C5,TRAOPE!$G:$H,2,0),"") | E5: DW64 | F5: D106 | G5: =IFERROR(VLOOKUP(A5,Flete!$A:$E,5,0),"") | H5: =IFERROR(VLOOKUP(F5,TRAOPE!$AA:$AB,2,0),"") | I5: 10000651 | J5: =IFERROR(VLOOKUP(I5,Materiales!$A:$H,8,0),"") | K5: =IFERROR(VLOOKUP(I5,Materiales!$A:$G,7,0),"") | L5: 20230501 | M5: 20250131 | N5: 53.21 | O5: =IFERROR(VLOOKUP(A5,Flete!$A:$J,10,0),"") | P5: TN | Q5: =IFERROR(IFERROR(VLOOKUP(A5,TRAOPE!$A:$U,21,0),VLOOKUP(B5,TRAOPE!$A:$U,21,0)),"") | R5: =IFERROR(IFERROR(VLOOKUP(A5,TRAOPE!$A:$W,23,0),VLOOKUP(B5,TRAOPE!$A:$W,23,0)),"") | S5: =IF(AND(P5="TN",R5="TN"),N5+N(O5),IF(G5&""="1",N(K5)*N5,(N5+N(O5))*N(K5))) | T5: =IF(Q5="","",Q5-S5)
A6: =CONCATENATE(C6,E6,F6,I6) | B6: =CONCATENATE(C6,E6,I6) | C6: 900000080 | D6: =IFERROR(VLOOKUP(C6,TRAOPE!$G:$H,2,0),"") | E6: DW64 | F6: D107 | G6: =IFERROR(VLOOKUP(A6,Flete!$A:$E,5,0),"") | H6: =IFERROR(VLOOKUP(F6,TRAOPE!$AA:$AB,2,0),"") | I6: 10000651 | J6: =IFERROR(VLOOKUP(I6,Materiales!$A:$H,8,0),"") | K6: =IFERROR(VLOOKUP(I6,Materiales!$A:$G,7,0),"") | L6: 20230501 | M6: 20250131 | N6: 53.21 | O6: =IFERROR(VLOOKUP(A6,Flete!$A:$J,10,0),"") | P6: TN | Q6: =IFERROR(IFERROR(VLOOKUP(A6,TRAOPE!$A:$U,21,0),VLOOKUP(B6,TRAOPE!$A:$U,21,0)),"") | R6: =IFERROR(IFERROR(VLOOKUP(A6,TRAOPE!$A:$W,23,0),VLOOKUP(B6,TRAOPE!$A:$W,23,0)),"") | S6: =IF(AND(P6="TN",R6="TN"),N6+N(O6),IF(G6&""="1",N(K6)*N6,(N6+N(O6))*N(K6))) | T6: =IF(Q6="","",Q6-S6)
A7: =CONCATENATE(C7,E7,F7,I7) | B7: =CONCATENATE(C7,E7,I7) | C7: 900000080 | D7: =IFERROR(VLOOKUP(C7,TRAOPE!$G:$H,2,0),"") | E7: DW64 | F7: D140 | G7: =IFERROR(VLOOKUP(A7,Flete!$A:$E,5,0),"") | H7: =IFERROR(VLOOKUP(F7,TRAOPE!$AA:$AB,2,0),"") | I7: 10000651 | J7: =IFERROR(VLOOKUP(I7,Materiales!$A:$H,8,0),"") | K7: =IFERROR(VLOOKUP(I7,Materiales!$A:$G,7,0),"") | L7: 20230501 | M7: 20250131 | N7: 53.21 | O7: =IFERROR(VLOOKUP(A7,Flete!$A:$J,10,0),"") | P7: TN | Q7: =IFERROR(IFERROR(VLOOKUP(A7,TRAOPE!$A:$U,21,0),VLOOKUP(B7,TRAOPE!$A:$U,21,0)),"") | R7: =IFERROR(IFERROR(VLOOKUP(A7,TRAOPE!$A:$W,23,0),VLOOKUP(B7,TRAOPE!$A:$W,23,0)),"") | S7: =IF(AND(P7="TN",R7="TN"),N7+N(O7),IF(G7&""="1",N(K7)*N7,(N7+N(O7))*N(K7))) | T7: =IF(Q7="","",Q7-S7)
A8: =CONCATENATE(C8,E8,F8,I8) | B8: =CONCATENATE(C8,E8,I8) | C8: 900000118 | D8: =IFERROR(VLOOKUP(C8,TRAOPE!$G:$H,2,0),"") | E8: DW64 | F8: D393 | G8: =IFERROR(VLOOKUP(A8,Flete!$A:$E,5,0),"") | H8: =IFERROR(VLOOKUP(F8,TRAOPE!$AA:$AB,2,0),"") | I8: 10256971 | J8: =IFERROR(VLOOKUP(I8,Materiales!$A:$H,8,0),"") | K8: =IFERROR(VLOOKUP(I8,Materiales!$A:$G,7,0),"") | L8: 20260324 | M8: 99991231 | N8: 147.59 | O8: =IFERROR(VLOOKUP(A8,Flete!$A:$J,10,0),"") | P8: TN | Q8: =IFERROR(IFERROR(VLOOKUP(A8,TRAOPE!$A:$U,21,0),VLOOKUP(B8,TRAOPE!$A:$U,21,0)),"") | R8: =IFERROR(IFERROR(VLOOKUP(A8,TRAOPE!$A:$W,23,0),VLOOKUP(B8,TRAOPE!$A:$W,23,0)),"") | S8: =IF(AND(P8="TN",R8="TN"),N8+N(O8),IF(G8&""="1",N(K8)*N8,(N8+N(O8))*N(K8))) | T8: =IF(Q8="","",Q8-S8)
A9: =CONCATENATE(C9,E9,F9,I9) | B9: =CONCATENATE(C9,E9,I9) | C9: 900000118 | D9: =IFERROR(VLOOKUP(C9,TRAOPE!$G:$H,2,0),"") | E9: DW64 | F9: ENL0 | G9: =IFERROR(VLOOKUP(A9,Flete!$A:$E,5,0),"") | H9: =IFERROR(VLOOKUP(F9,TRAOPE!$AA:$AB,2,0),"") | I9: 10256971 | J9: =IFERROR(VLOOKUP(I9,Materiales!$A:$H,8,0),"") | K9: =IFERROR(VLOOKUP(I9,Materiales!$A:$G,7,0),"") | L9: 20241129 | M9: 99991231 | N9: 147.59 | O9: =IFERROR(VLOOKUP(A9,Flete!$A:$J,10,0),"") | P9: TN | Q9: =IFERROR(IFERROR(VLOOKUP(A9,TRAOPE!$A:$U,21,0),VLOOKUP(B9,TRAOPE!$A:$U,21,0)),"") | R9: =IFERROR(IFERROR(VLOOKUP(A9,TRAOPE!$A:$W,23,0),VLOOKUP(B9,TRAOPE!$A:$W,23,0)),"") | S9: =IF(AND(P9="TN",R9="TN"),N9+N(O9),IF(G9&""="1",N(K9)*N9,(N9+N(O9))*N(K9))) | T9: =IF(Q9="","",Q9-S9)
A10: =CONCATENATE(C10,E10,F10,I10) | B10: =CONCATENATE(C10,E10,I10) | C10: 900000124 | D10: =IFERROR(VLOOKUP(C10,TRAOPE!$G:$H,2,0),"") | E10: DW64 | F10: D087 | G10: =IFERROR(VLOOKUP(A10,Flete!$A:$E,5,0),"") | H10: =IFERROR(VLOOKUP(F10,TRAOPE!$AA:$AB,2,0),"") | I10: 10000651 | J10: =IFERROR(VLOOKUP(I10,Materiales!$A:$H,8,0),"") | K10: =IFERROR(VLOOKUP(I10,Materiales!$A:$G,7,0),"") | L10: 20250701 | M10: 20251031 | N10: 71.11 | O10: =IFERROR(VLOOKUP(A10,Flete!$A:$J,10,0),"") | P10: TN | Q10: =IFERROR(IFERROR(VLOOKUP(A10,TRAOPE!$A:$U,21,0),VLOOKUP(B10,TRAOPE!$A:$U,21,0)),"") | R10: =IFERROR(IFERROR(VLOOKUP(A10,TRAOPE!$A:$W,23,0),VLOOKUP(B10,TRAOPE!$A:$W,23,0)),"") | S10: =IF(AND(P10="TN",R10="TN"),N10+N(O10),IF(G10&""="1",N(K10)*N10,(N10+N(O10))*N(K10))) | T10: =IF(Q10="","",Q10-S10)
A11: =CONCATENATE(C11,E11,F11,I11) | B11: =CONCATENATE(C11,E11,I11) | C11: 900000124 | D11: =IFERROR(VLOOKUP(C11,TRAOPE!$G:$H,2,0),"") | E11: DW64 | F11: D094 | G11: =IFERROR(VLOOKUP(A11,Flete!$A:$E,5,0),"") | H11: =IFERROR(VLOOKUP(F11,TRAOPE!$AA:$AB,2,0),"") | I11: 10000651 | J11: =IFERROR(VLOOKUP(I11,Materiales!$A:$H,8,0),"") | K11: =IFERROR(VLOOKUP(I11,Materiales!$A:$G,7,0),"") | L11: 20250701 | M11: 20251031 | N11: 67.73 | O11: =IFERROR(VLOOKUP(A11,Flete!$A:$J,10,0),"") | P11: TN | Q11: =IFERROR(IFERROR(VLOOKUP(A11,TRAOPE!$A:$U,21,0),VLOOKUP(B11,TRAOPE!$A:$U,21,0)),"") | R11: =IFERROR(IFERROR(VLOOKUP(A11,TRAOPE!$A:$W,23,0),VLOOKUP(B11,TRAOPE!$A:$W,23,0)),"") | S11: =IF(AND(P11="TN",R11="TN"),N11+N(O11),IF(G11&""="1",N(K11)*N11,(N11+N(O11))*N(K11))) | T11: =IF(Q11="","",Q11-S11)
A12: =CONCATENATE(C12,E12,F12,I12) | B12: =CONCATENATE(C12,E12,I12) | C12: 900000124 | D12: =IFERROR(VLOOKUP(C12,TRAOPE!$G:$H,2,0),"") | E12: DW64 | F12: D103 | G12: =IFERROR(VLOOKUP(A12,Flete!$A:$E,5,0),"") | H12: =IFERROR(VLOOKUP(F12,TRAOPE!$AA:$AB,2,0),"") | I12: 10000651 | J12: =IFERROR(VLOOKUP(I12,Materiales!$A:$H,8,0),"") | K12: =IFERROR(VLOOKUP(I12,Materiales!$A:$G,7,0),"") | L12: 20260430 | M12: 99991231 | N12: 74.31 | O12: =IFERROR(VLOOKUP(A12,Flete!$A:$J,10,0),"") | P12: TN | Q12: =IFERROR(IFERROR(VLOOKUP(A12,TRAOPE!$A:$U,21,0),VLOOKUP(B12,TRAOPE!$A:$U,21,0)),"") | R12: =IFERROR(IFERROR(VLOOKUP(A12,TRAOPE!$A:$W,23,0),VLOOKUP(B12,TRAOPE!$A:$W,23,0)),"") | S12: =IF(AND(P12="TN",R12="TN"),N12+N(O12),IF(G12&""="1",N(K12)*N12,(N12+N(O12))*N(K12))) | T12: =IF(Q12="","",Q12-S12)
A13: =CONCATENATE(C13,E13,F13,I13) | B13: =CONCATENATE(C13,E13,I13) | C13: 900000124 | D13: =IFERROR(VLOOKUP(C13,TRAOPE!$G:$H,2,0),"") | E13: DW64 | F13: D106 | G13: =IFERROR(VLOOKUP(A13,Flete!$A:$E,5,0),"") | H13: =IFERROR(VLOOKUP(F13,TRAOPE!$AA:$AB,2,0),"") | I13: 10000651 | J13: =IFERROR(VLOOKUP(I13,Materiales!$A:$H,8,0),"") | K13: =IFERROR(VLOOKUP(I13,Materiales!$A:$G,7,0),"") | L13: 20260430 | M13: 99991231 | N13: 74.31 | O13: =IFERROR(VLOOKUP(A13,Flete!$A:$J,10,0),"") | P13: TN | Q13: =IFERROR(IFERROR(VLOOKUP(A13,TRAOPE!$A:$U,21,0),VLOOKUP(B13,TRAOPE!$A:$U,21,0)),"") | R13: =IFERROR(IFERROR(VLOOKUP(A13,TRAOPE!$A:$W,23,0),VLOOKUP(B13,TRAOPE!$A:$W,23,0)),"") | S13: =IF(AND(P13="TN",R13="TN"),N13+N(O13),IF(G13&""="1",N(K13)*N13,(N13+N(O13))*N(K13))) | T13: =IF(Q13="","",Q13-S13)
A14: =CONCATENATE(C14,E14,F14,I14) | B14: =CONCATENATE(C14,E14,I14) | C14: 900000124 | D14: =IFERROR(VLOOKUP(C14,TRAOPE!$G:$H,2,0),"") | E14: DW64 | F14: D107 | G14: =IFERROR(VLOOKUP(A14,Flete!$A:$E,5,0),"") | H14: =IFERROR(VLOOKUP(F14,TRAOPE!$AA:$AB,2,0),"") | I14: 10000651 | J14: =IFERROR(VLOOKUP(I14,Materiales!$A:$H,8,0),"") | K14: =IFERROR(VLOOKUP(I14,Materiales!$A:$G,7,0),"") | L14: 20260430 | M14: 99991231 | N14: 74.31 | O14: =IFERROR(VLOOKUP(A14,Flete!$A:$J,10,0),"") | P14: TN | Q14: =IFERROR(IFERROR(VLOOKUP(A14,TRAOPE!$A:$U,21,0),VLOOKUP(B14,TRAOPE!$A:$U,21,0)),"") | R14: =IFERROR(IFERROR(VLOOKUP(A14,TRAOPE!$A:$W,23,0),VLOOKUP(B14,TRAOPE!$A:$W,23,0)),"") | S14: =IF(AND(P14="TN",R14="TN"),N14+N(O14),IF(G14&""="1",N(K14)*N14,(N14+N(O14))*N(K14))) | T14: =IF(Q14="","",Q14-S14)
... A213: =CONCATENATE(C213,E213,F213,I213) | B213: =CONCATENATE(C213,E213,I213) | C213: 900009137 | D213: =IFERROR(VLOOKUP(C213,TRAOPE!$G:$H,2,0),"") | E213: DW64 | F213: D059 | G213: =IFERROR(VLOOKUP(A213,Flete!$A:$E,5,0),"") | H213: =IFERROR(VLOOKUP(F213,TRAOPE!$AA:$AB,2,0),"") | I213: 10255320 | J213: =IFERROR(VLOOKUP(I213,Materiales!$A:$H,8,0),"") | K213: =IFERROR(VLOOKUP(I213,Materiales!$A:$G,7,0),"") | L213: 20251016 | M213: 20260215 | N213: 174.05 | O213: =IFERROR(VLOOKUP(A213,Flete!$A:$J,10,0),"") | P213: TN | Q213: =IFERROR(IFERROR(VLOOKUP(A213,TRAOPE!$A:$U,21,0),VLOOKUP(B213,TRAOPE!$A:$U,21,0)),"") | R213: =IFERROR(IFERROR(VLOOKUP(A213,TRAOPE!$A:$W,23,0),VLOOKUP(B213,TRAOPE!$A:$W,23,0)),"") | S213: =IF(AND(P213="TN",R213="TN"),N213+N(O213),IF(G213&""="1",N(K213)*N213,(N213+N(O213))*N(K213))) | T213: =IF(Q213="","",Q213-S213)

Sheet MP
A1: No. SF | B1: Cedis | C1: Destino | D1: No. Material | E1: Nombre Material | F1: Importe MP | G1: Moneda | H1: Cantidad | I1: UM | J1: C | K1: Inicio Vigencia | L1: Fin Vigencia
A2: 900000080 | B2: DW64 | C2: D087 | D2: 10000651 | F2: 53.21 | I2: TN | K2: 20230501 | L2: 20250131
A3: 900000080 | B3: DW64 | C3: D103 | D3: 10000651 | F3: 53.21 | I3: TN | K3: 20230501 | L3: 20250131
A4: 900000080 | B4: DW64 | C4: D106 | D4: 10000651 | F4: 53.21 | I4: TN | K4: 20230501 | L4: 20250131
A5: 900000080 | B5: DW64 | C5: D107 | D5: 10000651 | F5: 53.21 | I5: TN | K5: 20230501 | L5: 20250131
A6: 900000080 | B6: DW64 | C6: D140 | D6: 10000651 | F6: 53.21 | I6: TN | K6: 20230501 | L6: 20250131
A7: 900000118 | B7: DW64 | C7: D393 | D7: 10256971 | F7: 147.59 | I7: TN | K7: 20260324 | L7: 99991231
A8: 900000118 | B8: DW64 | C8: ENL0 | D8: 10256971 | F8: 147.59 | I8: TN | K8: 20241129 | L8: 99991231
A9: 900000124 | B9: DW64 | C9: D087 | D9: 10000651 | F9: 71.11 | I9: TN | K9: 20250701 | L9: 20251031
A10: 900000124 | B10: DW64 | C10: D094 | D10: 10000651 | F10: 67.73 | I10: TN | K10: 20250701 | L10: 20251031
A11: 900000124 | B11: DW64 | C11: D103 | D11: 10000651 | F11: 74.31 | I11: TN | K11: 20260430 | L11: 99991231
A12: 900000124 | B12: DW64 | C12: D106 | D12: 10000651 | F12: 74.31 | I12: TN | K12: 20260430 | L12: 99991231
A13: 900000124 | B13: DW64 | C13: D107 | D13: 10000651 | F13: 74.31 | I13: TN | K13: 20260430 | L13: 99991231
... A212: 900009137 | B212: DW64 | C212: D059 | D212: 10255320 | F212: 174.05 | I212: TN | K212: 20251016 | L212: 20260215

Sheet Flete
A1: Concat1 | B1: No. SF | C1: Cedis | D1: Destino | E1: Cond. Exp. | F1: Material | H1: Nombre Material | J1: Importe Flete | K1: Moneda | L1: Cantidad | M1: UM | N1: C | P1: Inicio Vigencia | Q1: Fin Vigencia
A2: 900000080DW64D08710000651 | B2: 900000080 | C2: DW64 | D2: D087 | E2: 1 | F2: 10000651 | J2: 246.61 | M2: TN | P2: 20220331 | Q2: 20250131
A3: 900000080DW64D10310000651 | B3: 900000080 | C3: DW64 | D3: D103 | E3: 1 | F3: 10000651 | J3: 253.67 | M3: TN | P3: 20220331 | Q3: 20250131
A4: 900000080DW64D10610000651 | B4: 900000080 | C4: DW64 | D4: D106 | E4: 1 | F4: 10000651 | J4: 278.56 | M4: TN | P4: 20220331 | Q4: 20250131
A5: 900000080DW64D10710000651 | B5: 900000080 | C5: DW64 | D5: D107 | E5: 1 | F5: 10000651 | J5: 298.39 | M5: TN | P5: 20220331 | Q5: 20250131
A6: 900000080DW64D14010000651 | B6: 900000080 | C6: DW64 | D6: D140 | E6: 1 | F6: 10000651 | J6: 287.52 | M6: TN | P6: 20220331 | Q6: 20250131
A7: 900000118DW64D39310256971 | B7: 900000118 | C7: DW64 | D7: D393 | E7: 1 | F7: 10256971 | J7: 401.38 | M7: TN | P7: 20260430 | Q7: 99991231
A8: 900000118DW64ENL010256971 | B8: 900000118 | C8: DW64 | D8: ENL0 | E8: 1 | F8: 10256971 | J8: 399.85 | M8: TN | P8: 20241129 | Q8: 99991231
A9: 900000124DW64D08710000651 | B9: 900000124 | C9: DW64 | D9: D087 | E9: 1 | F9: 10000651 | J9: 498.85 | M9: TN | P9: 20250401 | Q9: 20251031
A10: 900000124DW64D09410000651 | B10: 900000124 | C10: DW64 | D10: D094 | E10: 1 | F10: 10000651 | J10: 513.82 | M10: TN | P10: 20250401 | Q10: 20251031
A11: 900000124DW64D10310000651 | B11: 900000124 | C11: DW64 | D11: D103 | E11: 1 | F11: 10000651 | J11: 548.57 | M11: TN | P11: 20260430 | Q11: 99991231
A12: 900000124DW64D10610000651 | B12: 900000124 | C12: DW64 | D12: D106 | E12: 1 | F12: 10000651 | J12: 598.89 | M12: TN | P12: 20260430 | Q12: 99991231
A13: 900000124DW64D10710000651 | B13: 900000124 | C13: DW64 | D13: D107 | E13: 1 | F13: 10000651 | J13: 637.11 | M13: TN | P13: 20260430 | Q13: 99991231
... A204: 900009137DW64D05910255320 | B204: 900009137 | C204: DW64 | D204: D059 | E204: 4 | F204: 10255320 | J204: 87.03 | M204: TN | P204: 20251016 | Q204: 20260215

Sheet Materiales
A1: Material | B1: TpMt | C1: Denom | D1: UMA | E1: Contador | F1: UMB | G1: PV | H1: Nombre Material
A2: 10000001 | B2: ZFER | C2: 1000 | D2: M3 | E2: 1000 | F2: TN | G2: 1262 | H2: GRAVA ANDESITA 10 MM (3/8")
A3: 10000003 | B3: ZFER | C3: 1000 | D3: M3 | E3: 1000 | F3: TN | G3: 1443 | H3: GRAVA CALIZA 10 MM (3/8")
A4: 10000006 | B4: ZFER | C4: 1000 | D4: M3 | E4: 1000 | F4: TN | G4: 1490 | H4: GRAVA RIO 10 MM (3/8")
A5: 10000007 | B5: ZFER | C5: 1000 | D5: M3 | E5: 1000 | F5: TN | G5: 1488 | H5: GRAVA BASALTO 13 MM (1/2")
A6: 10000008 | B6: ZFER | C6: 1000 | D6: M3 | E6: 1000 | F6: TN | G6: 1358 | H6: GRAVA CALIZA 13 MM (1/2")
A7: 10000011 | B7: ZFER | C7: 1000 | D7: M3 | E7: 1000 | F7: TN | G7: 1323 | H7: GRAVA ANDESITA 20 MM (3/4")
A8: 10000013 | B8: ZFER | C8: 1000 | D8: M3 | E8: 1000 | F8: TN | G8: 1514 | H8: GRAVA BASALTO 20 MM (3/4")
A9: 10000014 | B9: ZFER | C9: 1000 | D9: M3 | E9: 1000 | F9: TN | G9: 1400 | H9: GRAVA CALIZA 20 MM (3/4")
A10: 10000015 | B10: ZFER | C10: 1000 | D10: M3 | E10: 1000 | F10: TN | G10: 1410 | H10: GRAVA GRANITO 20 MM (3/4")
A11: 10000017 | B11: ZFER | C11: 1000 | D11: M3 | E11: 1000 | F11: TN | G11: 1475 | H11: GRAVA RIOLITA 20 MM (3/4")
A12: 10000019 | B12: ZFER | C12: 1000 | D12: M3 | E12: 1000 | F12: TN | G12: 1515 | H12: GRAVA RIO 20 MM (3/4")
A13: 10000020 | B13: ZFER | C13: 1000 | D13: M3 | E13: 1 | F13: TN | G13: 1 | H13: GRAVA MAQUILA 40MM (1 1/2")
... A2291: 10268770 | B2291: ZFE3 | C2291: 1000 | D2291: M3 | E2291: 1000 | F2291: TN | G2291: 1240 | H2291: MP GRAVA TRIT CALIZA 40MM 1 1/2" - ESP
A2292: 10268901 | B2292: ZFE3 | C2292: 1000 | D2292: M3 | E2292: 1000 | G2292: 1560 | H2292: MP GRAVA ANDESITA GRIS 3/4" - CAPADA
A2293: 10267983 | C2293: 1000 | G2293: 1800 | H2293: ESCORIA ALTO HORNO 3/4
A2294: 10268996 | C2294: 1000 | G2294: 1329 | H2294: GRAVA TRITURADA CALIZA 40 MM - 11/2"
A2295: 10269072 | C2295: 1000 | G2295: 1700 | H2295: BASE HIDRÁULICA SCREEN
A2296: 10269225 | B2296: ZFE3 | C2296: 1000 | D2296: M3 | E2296: 1000 | G2296: 1289 | H2296: MP ARENA CALIZA LAVADA MALLA 4 - DELTA I
A2297: 10269245 | B2297: ZFE3 | C2297: 1000 | D2297: M3 | E2297: 1000 | G2297: 1410 | H2297: MP GRAVA TRITURADA CALIZA 3/8 - 10MM
A2298: 10269246 | B2298: ZFE3 | C2298: 1000 | D2298: M3 | E2298: 1000 | G2298: 1400 | H2298: MP GRAVA TRITURADA CALIZA 1 1/2 - 40MM
A2299: 10269247 | B2299: ZFE3 | C2299: 1000 | D2299: M3 | E2299: 1000 | G2299: 1560 | H2299: MP ARENA TRIT CALIZA M-4
A2300: 10270431 | B2300: ZFE3 | C2300: 1000 | D2300: M3 | E2300: 1000 | G2300: 1423 | H2300: MP GRAVA RIOLITA 13 MM - 1/2"
A2301: 10270898 | B2301: ZFE3 | C2301: 1000 | D2301: M3 | E2301: 1000 | G2301: 1551 | H2301: MP BASE H. TRIT. BASALTO 1 1/2" A FINOS
A2302: 10270911 | B2302: ZFE3 | C2302: 1000 | D2302: M3 | E2302: 1000 | G2302: 1360 | H2302: MP GRAVA TRIT. BASALTO 40 MM - 1 1/2"
A2303: 10270912 | B2303: ZFE3 | C2303: 1000 | D2303: M3 | E2303: 1000 | G2303: 1589 | H2303: MP ARENA TRIT. BASALTO MALLA 4
A2304: 10270913 | B2304: ZFE3 | C2304: 1000 | D2304: M3 | E2304: 1000 | G2304: 1395 | H2304: MP GRAVA TRIT. BASALTO 20 MM - 3/4
A2305: 10270914 | B2305: ZFE3 | C2305: 1000 | D2305: M3 | E2305: 1000 | G2305: 1623 | H2305: MP ARENA ANDESITA BC
A2306: 10270824 | B2306: M3 | C2306: 1000 | D2306: M3 | E2306: 10007640 | G2306: 1325 | H2306: MP ARENA TRITURADA CALIZA MALLA 5
A2307: 10270825 | B2307: M3 | C2307: 1000 | D2307: M3 | E2307: 10000003 | G2307: 1242 | H2307: MP GRAVA TRITURADA CALIZA 10MM (3/8”)
... A2319: 10272527 | B2319: ZFE3 | C2319: 1000 | D2319: M3 | E2319: 1000 | G2319: 1620 | H2319: CNC - NO CLASIFICADO
A2320: 10000332 | C2320: 1000 | D2320: M3 | E2320: 1000 | G2320: 800 | H2320: Grava Triturada Pomez - Jal 20 mm - 3/4"
A2321: 10273001 | B2321: ZFE3 | C2321: 1000 | D2321: M3 | E2321: 1000 | G2321: 1688 | H2321: MP ARENA TRIT. BASALTO MALLA 4
A2322: 10273002 | B2322: ZFE3 | C2322: 1000 | D2322: M3 | E2322: 1000 | G2322: 1466 | H2322: MP GRAVA TRIT. BASALTO 20 MM - 3/4"
A2323: 10273351 | B2323: ZFE3 | C2323: 1000 | D2323: M3 | E2323: 1000 | G2323: 1612 | H2323: MP ARENA TRIT. CALIZA MALLA 4
A2324: 10273352 | B2324: ZFE3 | C2324: 1000 | D2324: M3 | E2324: 1000 | G2324: 1492 | H2324: MP GRAVA TRIT. CALIZA 20 MM - 3/4"
A2325: 10271724 | B2325: ZFE3 | C2325: 1000 | D2325: M3 | E2325: 1000 | G2325: 1900 | H2325: MP RESIDUO DE CONCRETO
A2326: 10000677 | C2326: 1000 | D2326: M3 | G2326: 1164 | H2326: Grava Triturada Caliza 20 mm - 3/4"
A2327: 10274190 | B2327: ZFE3 | C2327: 1000 | D2327: M3 | E2327: 1000 | G2327: 1800 | H2327: MP BASE HIDRAULICA ANDESITA 70-30
A2328: 10274601 | B2328: ZFE3 | C2328: 1000 | D2328: M3 | E2328: 1000 | G2328: 1447 | H2328: MP ARENA BASALTO N° 4
...

Sheet TRAOPE
A1: Concat1 | B1: Contrato_Pos | C1: Doc. Compras | D1: Pos | E1: Org.compras | F1: Grp-Compr. | G1: Ship From | H1: Nombre SF | I1: Proveedor | J1: Nombre Prov | K1: Cond. Pago | L1: Descr. Cond Pago | M1: Material | N1: Descripción | O1: Centro | P1: Descripción Centro | Q1: In.perído validez | R1: Fin perído validez | S1: Válido de | T1: Validez a | U1: Precio neto pedido | V1: Moneda | W1: UM Precio Pedido | X1: Importe Condición | Y1: Moneda KONP | Z1: UM Ctd Base | AA1: Destino | AB1: Nombre Destino | AC1: Cuenta de mayor | AD1: Centro de costo | AE1: Cond. Exp. | AF1: Descr. Cond. Exp. | AG1: Peso Vol. | AH1: UMB | AI1: Ind. Oblig. Conf. Ped. | AJ1: Ctrl-Conf. | AK1: IVA | AL1: Modif_Date | AM1: Ruta
A2: 900006494DW64D39310220303 | B2: 4600050559-220 | C2: 4600050559 | D2: 220 | E2: MXPO | F2: MXL | G2: 900006494 | H2: TC-ED-COLON | I2: 5069557 | J2: RIVAS ZEIVY DANIELA | K2: N90 | L2: (AP) NAFIN 90 Dias | M2: 10220303 | N2: ARENA CLASIFICADA RÍO MALLA 4 | O2: DW64 | P2: MX-CED. QUERETARO | Q2: 20210712 | R2: 20291231 | S2: 20260812 | T2: 20301231 | U2: 340 | V2: MXN | W2: M3 | X2: 188 | Y2: MXN | Z2: M3 | AA2: D393 | AB2: PD0562 PREFABRICADOS TQI MOTAE | AC2: 56103638 | AD2: 6644201540 | AE2: 4 | AF2: ENTREGA DIRECTA | AG2: 1.229 | AH2: M3 | AI2: X | AJ2: 4 | AK2: V4 | AL2: 20260826 | AM2: DW64-900006494-D393-10220303-4
A3: 900000472DW64D10610000635 | B3: 4600050480-300 | C3: 4600050480 | D3: 300 | E3: MXPO | F3: MXL | G3: 900000472 | H3: TC-ED-TRIMCAV | I3: 5010147 | J3: TRITURACIONES DE MARMOL Y CALCIOS | K3: Z04 | L3: (AP) 30 Dias | M3: 10000635 | N3: Arena Triturada Marmol Malla 4 | O3: DW64 | P3: MX-CED. QUERETARO | Q3: 20210712 | R3: 20291231 | S3: 20260811 | T3: 20301231 | U3: 1633.34 | V3: MXN | W3: TN | X3: 833.34 | Y3: MXN | Z3: TN | AA3: D106 | AB3: PD0499 CASAS ARA | AC3: 56103638 | AD3: 6644201540 | AE3: 4 | AF3: ENTREGA DIRECTA | AG3: 1 | AH3: TO | AI3: X | AJ3: 4 | AK3: V4 | AL3: 20260814 | AM3: DW64-900000472-D106-10000635-4
A4: 900007883DW6410163202 | B4: 4600055908-10 | C4: 4600055908 | D4: 10 | E4: MXPO | F4: MXL | G4: 900007883 | H4: SF TC-AGACEL AEROPUERTO | I4: 5071383 | J4: AGACEL AGREGADOS Y ASFALTOS | K4: Z03 | L4: (AP) 15 Dias | M4: 10163202 | N4: GRAVA TRITURADA BASALTO 20 MM - 3/4" | O4: DW64 | P4: MX-CED. QUERETARO | Q4: 20221207 | R4: 20271231 | S4: 20260709 | T4: 20301231 | U4: 290 | V4: MXN | W4: M3 | X4: 0 | Y4: MXN | Z4: M3 | AC4: 56103637 | AD4: 6644201540 | AE4: 1 | AF4: ENTREGADO | AG4: 1.31 | AH4: M3 | AI4: X | AJ4: 4 | AK4: V4 | AL4: 20260710 | AM4: DW64-900007883-10163202
A5: 900000426DW64D08710000657 | B5: 4600050479-10 | C5: 4600050479 | D5: 10 | E5: MXPO | F5: MXL | G5: 900000426 | H5: TC-ED-QUIJANO | I5: 5004979 | J5: QUIJANO MARTINEZ LORENZO | K5: Z06 | L5: (AP) 45 Dias | M5: 10000657 | N5: Arena Clasificada Río Malla 4 | O5: DW64 | P5: MX-CED. QUERETARO | Q5: 20210712 | R5: 20261231 | S5: 20210712 | T5: 20261231 | U5: 350 | V5: MXN | W5: M3 | X5: 210 | Y5: MXN | Z5: M3 | AA5: D087 | AB5: PD0192 ZUMPANGO 2 | AC5: 56103638 | AD5: 6644201540 | AE5: 4 | AF5: ENTREGA DIRECTA | AG5: 1.294 | AH5: M3 | AI5: X | AJ5: 4 | AK5: V4 | AL5: 20260108 | AM5: DW64-900000426-D087-10000657-4
A6: 900007136DW64D08710000657 | B6: 4600050581-10 | C6: 4600050581 | D6: 10 | E6: MXPO | F6: MXL | G6: 900007136 | H6: SF TC-ED-MINA QUIJANO | I6: 5004979 | J6: QUIJANO MARTINEZ LORENZO | K6: Z07 | L6: (AP) 60 Dias | M6: 10000657 | N6: Arena Clasificada Río Malla 4 | O6: DW64 | P6: MX-CED. QUERETARO | Q6: 20210712 | R6: 20261231 | S6: 20210712 | T6: 20261231 | U6: 350 | V6: MXN | W6: M3 | X6: 210 | Y6: MXN | Z6: M3 | AA6: D087 | AB6: PD0192 ZUMPANGO 2 | AC6: 56103638 | AD6: 6644201540 | AE6: 4 | AF6: ENTREGA DIRECTA | AG6: 1.294 | AH6: M3 | AI6: X | AJ6: 4 | AK6: V4 | AL6: 20260108 | AM6: DW64-900007136-D087-10000657-4
A7: 900007136DW64D08710000669 | B7: 4600050581-20 | C7: 4600050581 | D7: 20 | E7: MXPO | F7: MXL | G7: 900007136 | H7: SF TC-ED-MINA QUIJANO | I7: 5004979 | J7: QUIJANO MARTINEZ LORENZO | K7: Z07 | L7: (AP) 60 Dias | M7: 10000669 | N7: Arena Clasificada Río Malla 4 | O7: DW64 | P7: MX-CED. QUERETARO | Q7: 20210712 | R7: 20261231 | S7: 20210712 | T7: 20261231 | U7: 350 | V7: MXN | W7: M3 | X7: 210 | Y7: MXN | Z7: M3 | AA7: D087 | AB7: PD0192 ZUMPANGO 2 | AC7: 56103638 | AD7: 6644201540 | AE7: 4 | AF7: ENTREGA DIRECTA | AG7: 1.312 | AH7: M3 | AI7: X | AJ7: 4 | AK7: V4 | AL7: 20260108 | AM7: DW64-900007136-D087-10000669-4
A8: 900008018DW64D08710204019 | B8: 4600056442-10 | C8: 4600056442 | D8: 10 | E8: MXPO | F8: MXL | G8: 900008018 | H8: SF TC-ED-COLON-QJ | I8: 5069557 | J8: RIVAS ZEIVY DANIELA | K8: N90 | L8: (AP) NAFIN 90 Dias | M8: 10204019 | N8: ARENA CLASIFICADA RÍO MALLA 4 (Q) | O8: DW64 | P8: MX-CED. QUERETARO | Q8: 20230202 | R8: 20281231 | S8: 20230202 | T8: 20281231 | U8: 530 | V8: MXN | W8: M3 | X8: 350 | Y8: MXN | Z8: M3 | AA8: D087 | AB8: PD0192 ZUMPANGO 2 | AC8: 56103638 | AD8: 6644201540 | AE8: 4 | AF8: ENTREGA DIRECTA | AG8: 1.445 | AH8: M3 | AI8: X | AJ8: 4 | AK8: V4 | AL8: 20230920 | AM8: DW64-900008018-D087-10204019-4
A9: 900008587DW64E66710004380 | B9: 4600068620-10 | C9: 4600068620 | D9: 10 | E9: MXPO | F9: MXL | G9: 900008587 | H9: SF TC-ED TEPETATE TALLER INFRA | I9: 5079714 | J9: AUTOTRANSPORTES DEL VALLE DE OTUMBA | K9: Z03 | L9: (AP) 15 Dias | M9: 10004380 | N9: Tepetate Clasificado Tierra | O9: DW64 | P9: MX-CED. QUERETARO | Q9: 20231016 | R9: 20281231 | S9: 20231016 | T9: 20281231 | U9: 215 | V9: MXN | W9: M3 | X9: 170 | Y9: MXN | Z9: M3 | AA9: E667 | AB9: TALLER CENTRAL | AC9: 56103695 | AD9: 6644201867 | AE9: 4 | AF9: ENTREGA DIRECTA | AG9: 1.5 | AH9: M3 | AI9: X | AJ9: 4 | AK9: V4 | AL9: 20231102 | AM9: DW64-900008587-E667-10004380-4
A10: 900000472DW64D10310211427 | B10: 4600050480-290 | C10: 4600050480 | D10: 290 | E10: MXPO | F10: MXL | G10: 900000472 | H10: TC-ED-TRIMCAV | I10: 5010147 | J10: TRITURACIONES DE MARMOL Y CALCIOS | K10: Z04 | L10: (AP) 30 Dias | M10: 10211427 | N10: ARENA TRITURADA BARITA | O10: DW64 | P10: MX-CED. QUERETARO | Q10: 20210712 | R10: 20291231 | S10: 20240213 | T10: 20291231 | U10: 6000 | V10: MXN | W10: TN | X10: 700 | Y10: MXN | Z10: TN | AA10: D103 | AB10: PD0498 PARQUE INDUSTRIAL | AC10: 56103638 | AD10: 6644201540 | AE10: 4 | AF10: ENTREGA DIRECTA | AG10: 1 | AH10: TO | AI10: X | AJ10: 4 | AK10: V4 | AL10: 20240215 | AM10: DW64-900000472-D103-10211427-4
A11: 900006494DW64D11510220303 | B11: 4600050559-130 | C11: 4600050559 | D11: 130 | E11: MXPO | F11: MXL | G11: 900006494 | H11: TC-ED-COLON | I11: 5069557 | J11: RIVAS ZEIVY DANIELA | K11: N90 | L11: (AP) NAFIN 90 Dias | M11: 10220303 | N11: ARENA CLASIFICADA RÍO MALLA 4 | O11: DW64 | P11: MX-CED. QUERETARO | Q11: 20210712 | R11: 20291231 | S11: 20260301 | T11: 20301231 | U11: 281.87 | V11: MXN | W11: M3 | X11: 129.87 | Y11: MXN | Z11: M3 | AA11: D115 | AB11: PD0505 SAN JUAN DEL RÍO | AC11: 56103638 | AD11: 6644201540 | AE11: 4 | AF11: ENTREGA DIRECTA | AG11: 1.229 | AH11: M3 | AI11: X | AJ11: 4 | AK11: V4 | AL11: 20260616 | AM11: DW64-900006494-D115-10220303-4
A12: 900006494DW64D13410220303 | B12: 4600050559-110 | C12: 4600050559 | D12: 110 | E12: MXPO | F12: MXL | G12: 900006494 | H12: TC-ED-COLON | I12: 5069557 | J12: RIVAS ZEIVY DANIELA | K12: N90 | L12: (AP) NAFIN 90 Dias | M12: 10220303 | N12: ARENA CLASIFICADA RÍO MALLA 4 | O12: DW64 | P12: MX-CED. QUERETARO | Q12: 20210712 | R12: 20291231 | S12: 20260301 | T12: 20301231 | U12: 311.19 | V12: MXN | W12: M3 | X12: 159.19 | Y12: MXN | Z12: M3 | AA12: D134 | AB12: PD0255 CASAS ARA 2 | AC12: 56103638 | AD12: 6644201540 | AE12: 4 | AF12: ENTREGA DIRECTA | AG12: 1.229 | AH12: M3 | AI12: X | AJ12: 4 | AK12: V4 | AL12: 20260616 | AM12: DW64-900006494-D134-10220303-4
A13: 900006494DW64D10310220303 | B13: 4600050559-140 | C13: 4600050559 | D13: 140 | E13: MXPO | F13: MXL | G13: 900006494 | H13: TC-ED-COLON | I13: 5069557 | J13: RIVAS ZEIVY DANIELA | K13: N90 | L13: (AP) NAFIN 90 Dias | M13: 10220303 | N13: ARENA CLASIFICADA RÍO MALLA 4 | O13: DW64 | P13: MX-CED. QUERETARO | Q13: 20210712 | R13: 20291231 | S13: 20260301 | T13: 20301231 | U13: 311.19 | V13: MXN | W13: M3 | X13: 159.19 | Y13: MXN | Z13: M3 | AA13: D103 | AB13: PD0498 PARQUE INDUSTRIAL | AC13: 56103638 | AD13: 6644201540 | AE13: 4 | AF13: ENTREGA DIRECTA | AG13: 1.229 | AH13: M3 | AI13: X | AJ13: 4 | AK13: V4 | AL13: 20260616 | AM13: DW64-900006494-D103-10220303-4
A14: 900006494DW64D10710220303 | B14: 4600050559-90 | C14: 4600050559 | D14: 90 | E14: MXPO | F14: MXL | G14: 900006494 | H14: TC-ED-COLON | I14: 5069557 | J14: RIVAS ZEIVY DANIELA | K14: N90 | L14: (AP) NAFIN 90 Dias | M14: 10220303 | N14: ARENA CLASIFICADA RÍO MALLA 4 | O14: DW64 | P14: MX-CED. QUERETARO | Q14: 20210712 | R14: 20291231 | S14: 20260301 | T14: 20301231 | U14: 362.82 | V14: MXN | W14: M3 | X14: 210.82 | Y14: MXN | Z14: M3 | AA14: D107 | AB14: PD0528 VIVEICA | AC14: 56103638 | AD14: 6644201540 | AE14: 4 | AF14: ENTREGA DIRECTA | AG14: 1.229 | AH14: M3 | AI14: X | AJ14: 4 | AK14: V4 | AL14: 20260616 | AM14: DW64-900006494-D107-10220303-4
A15: 900006494DW64D10610220303 | B15: 4600050559-150 | C15: 4600050559 | D15: 150 | E15: MXPO | F15: MXL | G15: 900006494 | H15: TC-ED-COLON | I15: 5069557 | J15: RIVAS ZEIVY DANIELA | K15: N90 | L15: (AP) NAFIN 90 Dias | M15: 10220303 | N15: ARENA CLASIFICADA RÍO MALLA 4 | O15: DW64 | P15: MX-CED. QUERETARO | Q15: 20210712 | R15: 20291231 | S15: 20260301 | T15: 20301231 | U15: 311.19 | V15: MXN | W15: M3 | X15: 159.19 | Y15: MXN | Z15: M3 | AA15: D106 | AB15: PD0499 CASAS ARA | AC15: 56103638 | AD15: 6644201540 | AE15: 4 | AF15: ENTREGA DIRECTA | AG15: 1.229 | AH15: M3 | AI15: X | AJ15: 4 | AK15: V4 | AL15: 20260616 | AM15: DW64-900006494-D106-10220303-4
A16: 900005737DW6410181901 | B16: 4600050542-50 | C16: 4600050542 | D16: 50 | E16: MXPO | F16: MXL | G16: 900005737 | H16: SF TC-AGREGADOS DE CALIZA | I16: 5072453 | J16: AGREGADOS DE CALIZA SA DE CV | K16: Z04 | L16: (AP) 30 Dias | M16: 10181901 | N16: ARENA TRITURADA CALIZA MALLA 4 | O16: DW64 | P16: MX-CED. QUERETARO | Q16: 20240301 | R16: 20291231 | S16: 20260529 | T16: 20301231 | U16: 205 | V16: MXN | W16: M3 | X16: 0 | Y16: MXN | Z16: M3 | AC16: 56103638 | AD16: 6644201540 | AE16: 1 | AF16: ENTREGADO | AG16: 1.5 | AH16: M3 | AI16: X | AJ16: 4 | AK16: V4 | AL16: 20260604 | AM16: DW64-900005737-10181901
A17: 900006494DW64D14010220303 | B17: 4600050559-100 | C17: 4600050559 | D17: 100 | E17: MXPO | F17: MXL | G17: 900006494 | H17: TC-ED-COLON | I17: 5069557 | J17: RIVAS ZEIVY DANIELA | K17: N90 | L17: (AP) NAFIN 90 Dias | M17: 10220303 | N17: ARENA CLASIFICADA RÍO MALLA 4 | O17: DW64 | P17: MX-CED. QUERETARO | Q17: 20210712 | R17: 20291231 | S17: 20260301 | T17: 20301231 | U17: 348.06 | V17: MXN | W17: M3 | X17: 196.06 | Y17: MXN | Z17: M3 | AA17: D140 | AB17: PD0283 LA ESTANCIA | AC17: 56103638 | AD17: 6644201540 | AE17: 4 | AF17: ENTREGA DIRECTA | AG17: 1.229 | AH17: M3 | AI17: X | AJ17: 4 | AK17: V4 | AL17: 20260616 | AM17: DW64-900006494-D140-10220303-4
A18: 900005554DW6410152583 | B18: 4600050528-10 | C18: 4600050528 | D18: 10 | E18: MXPO | F18: MXL | G18: 900005554 | H18: TC-SAN JOSÉ | I18: 5070683 | J18: COMERCIALIZADORA DE MATERIALES | K18: N90 | L18: (AP) NAFIN 90 Dias | M18: 10152583 | N18: ARENA TRITURADA ANDESITA MALLA 4 | O18: DW64 | P18: MX-CED. QUERETARO | Q18: 20210712 | R18: 20261231 | S18: 20210712 | T18: 20261231 | U18: 103.85 | V18: MXN | W18: M3 | X18: 0 | Y18: MXN | Z18: M3 | AC18: 56103638 | AD18: 6644201540 | AE18: 1 | AF18: ENTREGADO | AG18: 1.419 | AH18: M3 | AI18: X | AJ18: 4 | AK18: V4 | AL18: 20260108 | AM18: DW64-900005554-10152583
A19: 900006111DW6410124134 | B19: 4600050548-10 | C19: 4600050548 | D19: 10 | E19: MXPO | F19: MXL | G19: 900006111 | H19: SF TC-ANA REBECA | I19: 5075312 | J19: GONZALEZ MARTELL ANA REBECA | K19: Z09 | L19: (AP) 90 Dias | M19: 10124134 | N19: GRAVA TRITURADA BASALTO 10MM-3/8" | O19: DW64 | P19: MX-CED. QUERETARO | Q19: 20210712 | R19: 20261231 | S19: 20220201 | T19: 20271231 | U19: 220 | V19: MXN | W19: M3 | X19: 0 | Y19: MXN | Z19: M3 | AC19: 56103637 | AD19: 6644201540 | AE19: 1 | AF19: ENTREGADO | AG19: 1.44 | AH19: M3 | AI19: X | AJ19: 4 | AK19: V4 | AL19: 20230920 | AM19: DW64-900006111-10124134
A20: 900005554DW6410146801 | B20: 4600050529-10 | C20: 4600050529 | D20: 10 | E20: MXPO | F20: MXL | G20: 900005554 | H20: TC-SAN JOSÉ | I20: 5070683 | J20: COMERCIALIZADORA DE MATERIALES | K20: N90 | L20: (AP) NAFIN 90 Dias | M20: 10146801 | N20: GRAVA TRITURADA ANDESITA 20 MM - 3/4" | O20: DW64 | P20: MX-CED. QUERETARO | Q20: 20210712 | R20: 20261231 | S20: 20210712 | T20: 20261231 | U20: 103.85 | V20: MXN | W20: M3 | X20: 0 | Y20: MXN | Z20: M3 | AC20: 56103637 | AD20: 6644201540 | AE20: 1 | AF20: ENTREGADO | AG20: 1.342 | AH20: M3 | AI20: X | AJ20: 4 | AK20: V4 | AL20: 20260108 | AM20: DW64-900005554-10146801
A21: 900005419DW6410000669 | B21: 4600050521-20 | C21: 4600050521 | D21: 20 | E21: MXPO | F21: MXL | G21: 900005419 | H21: TC-GALINDO | I21: 5069557 | J21: RIVAS ZEIVY DANIELA | K21: N90 | L21: (AP) NAFIN 90 Dias | M21: 10000669 | N21: Arena Clasificada Río Malla 4 | O21: DW64 | P21: MX-CED. QUERETARO | Q21: 20210712 | R21: 20261231 | S21: 20210712 | T21: 20261231 | U21: 130 | V21: MXN | W21: M3 | X21: 0 | Y21: MXN | Z21: M3 | AC21: 56103638 | AD21: 6644201540 | AE21: 1 | AF21: ENTREGADO | AG21: 1.312 | AH21: M3 | AI21: X | AJ21: 4 | AK21: V4 | AL21: 20260108 | AM21: DW64-900005419-10000669
A22: 900005419DW6410000175 | B22: 4600050521-10 | C22: 4600050521 | D22: 10 | E22: MXPO | F22: MXL | G22: 900005419 | H22: TC-GALINDO | I22: 5069557 | J22: RIVAS ZEIVY DANIELA | K22: N90 | L22: (AP) NAFIN 90 Dias | M22: 10000175 | N22: Arena Triturada Caliza Malla 4 | O22: DW64 | P22: MX-CED. QUERETARO | Q22: 20210712 | R22: 20261231 | S22: 20210712 | T22: 20261231 | U22: 228.05 | V22: MXN | W22: M3 | X22: 0 | Y22: MXN | Z22: M3 | AC22: 56103638 | AD22: 6644201540 | AE22: 1 | AF22: ENTREGADO | AG22: 1.55 | AH22: M3 | AI22: X | AJ22: 4 | AK22: V4 | AL22: 20260108 | AM22: DW64-900005419-10000175
A23: 900005554DW6410000649 | B23: 4600050530-10 | C23: 4600050530 | D23: 10 | E23: MXPO | F23: MXL | G23: 900005554 | H23: TC-SAN JOSÉ | I23: 5070683 | J23: COMERCIALIZADORA DE MATERIALES | K23: N90 | L23: (AP) NAFIN 90 Dias | M23: 10000649 | N23: Grava Triturada Andesita 10 mm - 3/8" | O23: DW64 | P23: MX-CED. QUERETARO | Q23: 20210712 | R23: 20261231 | S23: 20210712 | T23: 20261231 | U23: 103.85 | V23: MXN | W23: M3 | X23: 0 | Y23: MXN | Z23: M3 | AC23: 56103637 | AD23: 6644201540 | AE23: 1 | AF23: ENTREGADO | AG23: 1.315 | AH23: M3 | AI23: X | AJ23: 4 | AK23: V4 | AL23: 20260108 | AM23: DW64-900005554-10000649
A24: 900006111DW6410163206 | B24: 4600050548-20 | C24: 4600050548 | D24: 20 | E24: MXPO | F24: MXL | G24: 900006111 | H24: SF TC-ANA REBECA | I24: 5075312 | J24: GONZALEZ MARTELL ANA REBECA | K24: Z09 | L24: (AP) 90 Dias | M24: 10163206 | N24: GRAVA TRITURADA BASALTO 20 MM - 3/4" | O24: DW64 | P24: MX-CED. QUERETARO | Q24: 20210712 | R24: 20261231 | S24: 20220201 | T24: 20271231 | U24: 190 | V24: MXN | W24: M3 | X24: 0 | Y24: MXN | Z24: M3 | AC24: 56103637 | AD24: 6644201540 | AE24: 1 | AF24: ENTREGADO | AG24: 1.446 | AH24: M3 | AI24: X | AJ24: 4 | AK24: V4 | AL24: 20230920 | AM24: DW64-900006111-10163206
A25: 900006528DW6410200637 | B25: 4600050560-20 | C25: 4600050560 | D25: 20 | E25: MXPO | F25: MXL | G25: 900006528 | H25: TC-CALERAS DE BERNAL | I25: 5077927 | J25: CALES Y MINAS DE MEXICO SA DE CV | K25: Z09 | L25: (AP) 90 Dias | M25: 10200637 | N25: ARENA TRITURADA CALIZA MALLA 5 | O25: DW64 | P25: MX-CED. QUERETARO | Q25: 20210712 | R25: 20271231 | S25: 20220101 | T25: 20271231 | U25: 157.5 | V25: MXN | W25: M3 | X25: 0 | Y25: MXN | Z25: M3 | AC25: 56103638 | AD25: 6644201540 | AE25: 1 | AF25: ENTREGADO | AG25: 1.49 | AH25: M3 | AI25: X | AJ25: 4 | AK25: V4 | AL25: 20230920 | AM25: DW64-900006528-10200637
A26: 900005817DW6410202070 | B26: 4600050543-20 | C26: 4600050543 | D26: 20 | E26: MXPO | F26: MXL | G26: 900005817 | H26: SF TC-AGACEL | I26: 5071383 | J26: AGACEL AGREGADOS Y ASFALTOS | K26: Z03 | L26: (AP) 15 Dias | M26: 10202070 | N26: GRAVA TRITURADA BASALTO 20 MM - 3/4" - E | O26: DW64 | P26: MX-CED. QUERETARO | Q26: 20210712 | R26: 20261231 | S26: 20221101 | T26: 20271231 | U26: 140 | V26: MXN | W26: M3 | X26: 0 | Y26: MXN | Z26: M3 | AC26: 56103637 | AD26: 6644201540 | AE26: 1 | AF26: ENTREGADO | AG26: 1.446 | AH26: M3 | AI26: X | AJ26: 4 | AK26: V4 | AL26: 20230920 | AM26: DW64-900005817-10202070
A27: 900005835DW6410181901 | B27: 4600050544-10 | C27: 4600050544 | D27: 10 | E27: MXPO | F27: MXL | G27: 900005835 | H27: SF TC-CALERAS DE BERNAL | I27: 5072615 | J27: CALERAS DE BERNAL S.A. DE C.V. | K27: Z09 | L27: (AP) 90 Dias | M27: 10181901 | N27: ARENA TRITURADA CALIZA MALLA 4 | O27: DW64 | P27: MX-CED. QUERETARO | Q27: 20210712 | R27: 20261231 | S27: 20210712 | T27: 20261231 | U27: 82.5 | V27: MXN | W27: M3 | X27: 0 | Y27: MXN | Z27: M3 | AC27: 56103638 | AD27: 6644201540 | AE27: 1 | AF27: ENTREGADO | AG27: 1.5 | AH27: M3 | AI27: X | AJ27: 4 | AK27: V4 | AL27: 20260108 | AM27: DW64-900005835-10181901
A28: 900006528DW6410202113 | B28: 4600050560-30 | C28: 4600050560 | D28: 30 | E28: MXPO | F28: MXL | G28: 900006528 | H28: TC-CALERAS DE BERNAL | I28: 5077927 | J28: CALES Y MINAS DE MEXICO SA DE CV | K28: Z09 | L28: (AP) 90 Dias | M28: 10202113 | N28: GRAVA TRITURADA CALIZA 20 MM - 3/4" | O28: DW64 | P28: MX-CED. QUERETARO | Q28: 20210712 | R28: 20271231 | S28: 20210830 | T28: 20260830 | U28: 112.5 | V28: MXN | W28: M3 | X28: 0 | Y28: MXN | Z28: M3 | AC28: 56103637 | AD28: 6644201540 | AE28: 1 | AF28: ENTREGADO | AG28: 1.446 | AH28: M3 | AI28: X | AJ28: 4 | AK28: V4 | AL28: 20230920 | AM28: DW64-900006528-10202113
A29: 900007078DW6410194465 | B29: 4600050577-10 | C29: 4600050577 | D29: 10 | E29: MXPO | F29: MXL | G29: 900007078 | H29: SF TC-MINA TEXCA | I29: 5076363 | J29: FALCON OMAÑA EVELIA | K29: Z04 | L29: (AP) 30 Dias | M29: 10194465 | N29: ARENA CLASIFICADA RÍO MALLA 4 | O29: DW64 | P29: MX-CED. QUERETARO | Q29: 20210712 | R29: 20261231 | S29: 20210712 | T29: 20261231 | U29: 140 | V29: MXN | W29: M3 | X29: 0 | Y29: MXN | Z29: M3 | AC29: 56103638 | AD29: 6644201540 | AE29: 1 | AF29: ENTREGADO | AG29: 1.44 | AH29: M3 | AI29: X | AJ29: 4 | AK29: V4 | AL29: 20260108 | AM29: DW64-900007078-10194465
... A32: 900006713DW6410194465 | B32: 4600050565-10 | C32: 4600050565 | D32: 10 | E32: MXPO | F32: MXL | G32: 900006713 | H32: SF TC-ALMACEN TEXCA | I32: 5076363 | J32: FALCON OMAÑA EVELIA | K32: Z04 | L32: (AP) 30 Dias | M32: 10194465 | N32: ARENA CLASIFICADA RÍO MALLA 4 | O32: DW64 | P32: MX-CED. QUERETARO | Q32: 20210712 | R32: 20261231 | S32: 20210712 | T32: 20261231 | U32: 210 | V32: MXN | W32: M3 | X32: 0 | Y32: MXN | Z32: M3 | AC32: 56103638 | AD32: 6644201540 | AE32: 1 | AF32: ENTREGADO | AG32: 1.44 | AH32: M3 | AI32: X | AJ32: 4 | AK32: V4 | AL32: 20260108 | AM32: DW64-900006713-10194465
A33: 900006467DW64D11510163202 | B33: 4600050556-10 | C33: 4600050556 | D33: 10 | E33: MXPO | F33: MXL | G33: 900006467 | H33: TC-ED-TRITURADOS MORA | I33: 5033150 | J33: TRITURACIONES LA MORA SA DE CV | K33: Z09 | L33: (AP) 90 Dias | M33: 10163202 | N33: GRAVA TRITURADA BASALTO 20 MM - 3/4" | O33: DW64 | P33: MX-CED. QUERETARO | Q33: 20210712 | R33: 20261231 | S33: 20210712 | T33: 20261231 | U33: 194.5 | V33: MXN | W33: M3 | X33: 42.5 | Y33: MXN | Z33: M3 | AA33: D115 | AB33: PD0505 SAN JUAN DEL RÍO | AC33: 56103637 | AD33: 6644201540 | AE33: 4 | AF33: ENTREGA DIRECTA | AG33: 1.31 | AH33: M3 | AI33: X | AJ33: 4 | AK33: V4 | AL33: 20260108 | AM33: DW64-900006467-D115-10163202-4
A34: 900006467DW64D11510000666 | B34: 4600050556-20 | C34: 4600050556 | D34: 20 | E34: MXPO | F34: MXL | G34: 900006467 | H34: TC-ED-TRITURADOS MORA | I34: 5033150 | J34: TRITURACIONES LA MORA SA DE CV | K34: Z09 | L34: (AP) 90 Dias | M34: 10000666 | N34: Grava Triturada Basalto 40 mm - 1 1/2" | O34: DW64 | P34: MX-CED. QUERETARO | Q34: 20210712 | R34: 20261231 | S34: 20210712 | T34: 20261231 | U34: 194.5 | V34: MXN | W34: M3 | X34: 42.5 | Y34: MXN | Z34: M3 | AA34: D115 | AB34: PD0505 SAN JUAN DEL RÍO | AC34: 56103637 | AD34: 6644201540 | AE34: 4 | AF34: ENTREGA DIRECTA | AG34: 1.33 | AH34: M3 | AI34: X | AJ34: 4 | AK34: V4 | AL34: 20260108 | AM34: DW64-900006467-D115-10000666-4
A35: 900000472DW64D14010000722 | B35: 4600050480-140 | C35: 4600050480 | D35: 140 | E35: MXPO | F35: MXL | G35: 900000472 | H35: TC-ED-TRIMCAV | I35: 5010147 | J35: TRITURACIONES DE MARMOL Y CALCIOS | K35: Z04 | L35: (AP) 30 Dias | M35: 10000722 | N35: Grava Triturada Caliza 20 mm - 3/4" | O35: DW64 | P35: MX-CED. QUERETARO | Q35: 20210712 | R35: 20291231 | S35: 20260215 | T35: 20301231 | U35: 383.91 | V35: MXN | W35: TN | X35: 223.26 | Y35: MXN | Z35: TN | AA35: D140 | AB35: PD0283 LA ESTANCIA | AC35: 56103637 | AD35: 6644201540 | AE35: 4 | AF35: ENTREGA DIRECTA | AG35: 1 | AH35: TO | AI35: X | AJ35: 4 | AK35: V4 | AL35: 20260306 | AM35: DW64-900000472-D140-10000722-4
A36: 900000472DW64D14010000175 | B36: 4600050480-130 | C36: 4600050480 | D36: 130 | E36: MXPO | F36: MXL | G36: 900000472 | H36: TC-ED-TRIMCAV | I36: 5010147 | J36: TRITURACIONES DE MARMOL Y CALCIOS | K36: Z04 | L36: (AP) 30 Dias | M36: 10000175 | N36: Arena Triturada Caliza Malla 4 | O36: DW64 | P36: MX-CED. QUERETARO | Q36: 20210712 | R36: 20291231 | S36: 20260215 | T36: 20301231 | U36: 378.23 | V36: MXN | W36: TN | X36: 223.19 | Y36: MXN | Z36: TN | AA36: D140 | AB36: PD0283 LA ESTANCIA | AC36: 56103638 | AD36: 6644201540 | AE36: 4 | AF36: ENTREGA DIRECTA | AG36: 1 | AH36: TO | AI36: X | AJ36: 4 | AK36: V4 | AL36: 20260306 | AM36: DW64-900000472-D140-10000175-4
A37: 900000472DW64D10710000722 | B37: 4600050480-60 | C37: 4600050480 | D37: 60 | E37: MXPO | F37: MXL | G37: 900000472 | H37: TC-ED-TRIMCAV | I37: 5010147 | J37: TRITURACIONES DE MARMOL Y CALCIOS | K37: Z04 | L37: (AP) 30 Dias | M37: 10000722 | N37: Grava Triturada Caliza 20 mm - 3/4" | O37: DW64 | P37: MX-CED. QUERETARO | Q37: 20210712 | R37: 20291231 | S37: 20260215 | T37: 20301231 | U37: 413.65 | V37: MXN | W37: TN | X37: 252.91 | Y37: MXN | Z37: TN | AA37: D107 | AB37: PD0528 VIVEICA | AC37: 56103637 | AD37: 6644201540 | AE37: 4 | AF37: ENTREGA DIRECTA | AG37: 1 | AH37: TO | AI37: X | AJ37: 4 | AK37: V4 | AL37: 20260306 | AM37: DW64-900000472-D107-10000722-4
A38: 900000472DW64D13410000722 | B38: 4600050480-160 | C38: 4600050480 | D38: 160 | E38: MXPO | F38: MXL | G38: 900000472 | H38: TC-ED-TRIMCAV | I38: 5010147 | J38: TRITURACIONES DE MARMOL Y CALCIOS | K38: Z04 | L38: (AP) 30 Dias | M38: 10000722 | N38: Grava Triturada Caliza 20 mm - 3/4" | O38: DW64 | P38: MX-CED. QUERETARO | Q38: 20210712 | R38: 20291231 | S38: 20260215 | T38: 20301231 | U38: 369.74 | V38: MXN | W38: TN | X38: 208.84 | Y38: MXN | Z38: TN | AA38: D134 | AB38: PD0255 CASAS ARA 2 | AC38: 56103637 | AD38: 6644201540 | AE38: 4 | AF38: ENTREGA DIRECTA | AG38: 1 | AH38: TO | AI38: X | AJ38: 4 | AK38: V4 | AL38: 20260306 | AM38: DW64-900000472-D134-10000722-4
A39: 900000472DW64D10310000175 | B39: 4600050480-100 | C39: 4600050480 | D39: 100 | E39: MXPO | F39: MXL | G39: 900000472 | H39: TC-ED-TRIMCAV | I39: 5010147 | J39: TRITURACIONES DE MARMOL Y CALCIOS | K39: Z04 | L39: (AP) 30 Dias | M39: 10000175 | N39: Arena Triturada Caliza Malla 4 | O39: DW64 | P39: MX-CED. QUERETARO | Q39: 20210712 | R39: 20291231 | S39: 20260215 | T39: 20301231 | U39: 336.05 | V39: MXN | W39: TN | X39: 181.01 | Y39: MXN | Z39: TN | AA39: D103 | AB39: PD0498 PARQUE INDUSTRIAL | AC39: 56103638 | AD39: 6644201540 | AE39: 4 | AF39: ENTREGA DIRECTA | AG39: 1 | AH39: TO | AI39: X | AJ39: 4 | AK39: V4 | AL39: 20260306 | AM39: DW64-900000472-D103-10000175-4
A40: 900009023DW64ENL110261599 | B40: 4600070902-20 | C40: 4600070902 | D40: 20 | E40: MXPO | F40: MXL | G40: 900009023 | H40: SF TC-ED AGACEL BRUJAS | I40: 5071383 | J40: AGACEL AGREGADOS Y ASFALTOS | K40: Z03 | L40: (AP) 15 Dias | M40: 10261599 | N40: GRAVA TRITURADA BASALTO 20MM- ¾” | O40: DW64 | P40: MX-CED. QUERETARO | Q40: 20241104 | R40: 20291231 | S40: 20241104 | T40: 20291231 | U40: 266.16 | V40: MXN | W40: TN | X40: 129.86 | Y40: MXN | Z40: TN | AA40: ENL1 | AB40: MX-PD0681 INFRA APTO GDL | AC40: 56103637 | AD40: 6644201540 | AE40: 4 | AF40: ENTREGA DIRECTA | AG40: 1 | AH40: TO | AI40: X | AJ40: 4 | AK40: V4 | AL40: 20250226 | AM40: DW64-900009023-ENL1-10261599-4
A41: 900000472DW64D10610000722 | B41: 4600050480-70 | C41: 4600050480 | D41: 70 | E41: MXPO | F41: MXL | G41: 900000472 | H41: TC-ED-TRIMCAV | I41: 5010147 | J41: TRITURACIONES DE MARMOL Y CALCIOS | K41: Z04 | L41: (AP) 30 Dias | M41: 10000722 | N41: Grava Triturada Caliza 20 mm - 3/4" | O41: DW64 | P41: MX-CED. QUERETARO | Q41: 20210712 | R41: 20291231 | S41: 20260215 | T41: 20301231 | U41: 369.73 | V41: MXN | W41: TN | X41: 208.99 | Y41: MXN | Z41: TN | AA41: D106 | AB41: PD0499 CASAS ARA | AC41: 56103637 | AD41: 6644201540 | AE41: 4 | AF41: ENTREGA DIRECTA | AG41: 1 | AH41: TO | AI41: X | AJ41: 4 | AK41: V4 | AL41: 20260306 | AM41: DW64-900000472-D106-10000722-4
A42: 900000472DW64D10710000175 | B42: 4600050480-120 | C42: 4600050480 | D42: 120 | E42: MXPO | F42: MXL | G42: 900000472 | H42: TC-ED-TRIMCAV | I42: 5010147 | J42: TRITURACIONES DE MARMOL Y CALCIOS | K42: Z04 | L42: (AP) 30 Dias | M42: 10000175 | N42: Arena Triturada Caliza Malla 4 | O42: DW64 | P42: MX-CED. QUERETARO | Q42: 20210712 | R42: 20291231 | S42: 20260215 | T42: 20301231 | U42: 407.98 | V42: MXN | W42: TN | X42: 252.94 | Y42: MXN | Z42: TN | AA42: D107 | AB42: PD0528 VIVEICA | AC42: 56103638 | AD42: 6644201540 | AE42: 4 | AF42: ENTREGA DIRECTA | AG42: 1 | AH42: TO | AI42: X | AJ42: 4 | AK42: V4 | AL42: 20260306 | AM42: DW64-900000472-D107-10000175-4
...
